2020-05-01 11:40:37,016 - _real_add_job - 262 - INFO - Added job "regulartime_task (trigger: interval[1 day, 0:00:00], next run at: 2020-05-01 11:40:47.014199)" to job store "default"
2020-05-01 11:40:37,017 - _real_add_job - 262 - INFO - Added job "cleanup (trigger: cron[day_of_week='*', hour='3', minute='0', second='0'], next run at: 2020-05-02 03:00:00)" to job store "default"
2020-05-01 11:40:37,017 - _real_add_job - 262 - INFO - Added job "OpenLog (trigger: cron[hour='0'], next run at: 2020-05-02 00:00:00)" to job store "default"
2020-05-01 11:40:37,018 - _main_loop - 574 - INFO - Scheduler started
2020-05-01 11:40:37,018 - _main_loop - 579 - DEBUG - Looking for jobs to run
2020-05-01 11:40:37,019 - _main_loop - 588 - DEBUG - Next wakeup is due at 2020-05-01 11:40:47.014199 (in 9.994980 seconds)
2020-05-01 11:40:37,060 - <module> - 63 - DEBUG - SendBefore_NotRecive : [<CNCProcessStatus: CNCProcessStatus object (2038721)>]
2020-05-01 11:40:37,060 - <module> - 64 - DEBUG - Waitfor_Recive : [2038721]
2020-05-01 11:40:37,480 - shutdown - 111 - INFO - Shutting down thread pool
2020-05-01 11:40:47,987 - _real_add_job - 262 - INFO - Added job "regulartime_task (trigger: interval[1 day, 0:00:00], next run at: 2020-05-01 11:40:57.986777)" to job store "default"
2020-05-01 11:40:47,987 - _real_add_job - 262 - INFO - Added job "cleanup (trigger: cron[day_of_week='*', hour='3', minute='0', second='0'], next run at: 2020-05-02 03:00:00)" to job store "default"
2020-05-01 11:40:47,987 - _real_add_job - 262 - INFO - Added job "OpenLog (trigger: cron[hour='0'], next run at: 2020-05-02 00:00:00)" to job store "default"
2020-05-01 11:40:47,988 - _main_loop - 574 - INFO - Scheduler started
2020-05-01 11:40:47,988 - _main_loop - 579 - DEBUG - Looking for jobs to run
2020-05-01 11:40:47,988 - _main_loop - 588 - DEBUG - Next wakeup is due at 2020-05-01 11:40:57.986777 (in 9.997908 seconds)
2020-05-01 11:40:47,998 - <module> - 63 - DEBUG - SendBefore_NotRecive : [<CNCProcessStatus: CNCProcessStatus object (2038721)>]
2020-05-01 11:40:47,998 - <module> - 64 - DEBUG - Waitfor_Recive : [2038721]
2020-05-01 11:40:51,955 - shutdown - 111 - INFO - Shutting down thread pool
2020-05-01 11:44:56,702 - _real_add_job - 262 - INFO - Added job "regulartime_task (trigger: interval[1 day, 0:00:00], next run at: 2020-05-01 11:45:06.701837)" to job store "default"
2020-05-01 11:44:56,702 - _real_add_job - 262 - INFO - Added job "cleanup (trigger: cron[day_of_week='*', hour='3', minute='0', second='0'], next run at: 2020-05-02 03:00:00)" to job store "default"
2020-05-01 11:44:56,703 - _real_add_job - 262 - INFO - Added job "OpenLog (trigger: cron[hour='0'], next run at: 2020-05-02 00:00:00)" to job store "default"
2020-05-01 11:44:56,704 - _main_loop - 574 - INFO - Scheduler started
2020-05-01 11:44:56,704 - _main_loop - 579 - DEBUG - Looking for jobs to run
2020-05-01 11:44:56,704 - _main_loop - 588 - DEBUG - Next wakeup is due at 2020-05-01 11:45:06.701837 (in 9.997110 seconds)
2020-05-01 11:44:56,719 - <module> - 63 - DEBUG - SendBefore_NotRecive : [<CNCProcessStatus: CNCProcessStatus object (2038721)>]
2020-05-01 11:44:56,719 - <module> - 64 - DEBUG - Waitfor_Recive : [2038721]
2020-05-01 11:45:06,703 - _main_loop - 579 - DEBUG - Looking for jobs to run
2020-05-01 11:45:06,704 - _run_jobs - 69 - DEBUG - Started worker thread
2020-05-01 11:45:06,705 - _run_job - 509 - INFO - Running job "regulartime_task (trigger: interval[1 day, 0:00:00], next run at: 2020-05-01 11:45:06.701837)" (scheduled at 2020-05-01 11:45:06.701837)
2020-05-01 11:45:06,705 - _main_loop - 588 - DEBUG - Next wakeup is due at 2020-05-02 00:00:00 (in 44093.296393 seconds)
2020-05-01 11:45:07,857 - _run_job - 520 - ERROR - Job "regulartime_task (trigger: interval[1 day, 0:00:00], next run at: 2020-05-02 11:45:06.701837)" raised an exception
Traceback (most recent call last):
  File "D:\Program Files\Python37\lib\site-packages\django\db\backends\mysql\base.py", line 71, in execute
    return self.cursor.execute(query, args)
  File "D:\Program Files\Python37\lib\site-packages\MySQLdb\cursors.py", line 209, in execute
    res = self._query(query)
  File "D:\Program Files\Python37\lib\site-packages\MySQLdb\cursors.py", line 315, in _query
    db.query(q)
  File "D:\Program Files\Python37\lib\site-packages\MySQLdb\connections.py", line 239, in query
    _mysql.connection.query(self, query)
MySQLdb._exceptions.OperationalError: (1048, "Column 'laser_power' cannot be null")

During handling of the above exception, another exception occurred:

Traceback (most recent call last):
  File "D:\Program Files\Python37\lib\site-packages\apscheduler\scheduler.py", line 512, in _run_job
    retval = job.func(*job.args, **job.kwargs)
  File "E:\1-program\11-LAMDataServer\lamdataserver\LAMProcessData\views.py", line 4988, in regulartime_task
    RT_FineData.Realtime_FineData.init_Tomorrow_rows()
  File "E:\1-program\11-LAMDataServer\lamdataserver\LAMProcessData\process_realtime_finedata.py", line 193, in init_Tomorrow_rows
    _model.objects.bulk_create(insert_data_list)
  File "D:\Program Files\Python37\lib\site-packages\django\db\models\manager.py", line 82, in manager_method
    return getattr(self.get_queryset(), name)(*args, **kwargs)
  File "D:\Program Files\Python37\lib\site-packages\django\db\models\query.py", line 474, in bulk_create
    ids = self._batched_insert(objs_without_pk, fields, batch_size, ignore_conflicts=ignore_conflicts)
  File "D:\Program Files\Python37\lib\site-packages\django\db\models\query.py", line 1211, in _batched_insert
    self._insert(item, fields=fields, using=self.db, ignore_conflicts=ignore_conflicts)
  File "D:\Program Files\Python37\lib\site-packages\django\db\models\query.py", line 1186, in _insert
    return query.get_compiler(using=using).execute_sql(return_id)
  File "D:\Program Files\Python37\lib\site-packages\django\db\models\sql\compiler.py", line 1332, in execute_sql
    cursor.execute(sql, params)
  File "D:\Program Files\Python37\lib\site-packages\django\db\backends\utils.py", line 99, in execute
    return super().execute(sql, params)
  File "D:\Program Files\Python37\lib\site-packages\django\db\backends\utils.py", line 67, in execute
    return self._execute_with_wrappers(sql, params, many=False, executor=self._execute)
  File "D:\Program Files\Python37\lib\site-packages\django\db\backends\utils.py", line 76, in _execute_with_wrappers
    return executor(sql, params, many, context)
  File "D:\Program Files\Python37\lib\site-packages\django\db\backends\utils.py", line 84, in _execute
    return self.cursor.execute(sql, params)
  File "D:\Program Files\Python37\lib\site-packages\django\db\backends\mysql\base.py", line 76, in execute
    raise utils.IntegrityError(*tuple(e.args))
django.db.utils.IntegrityError: (1048, "Column 'laser_power' cannot be null")
2020-05-01 11:45:08,869 - _run_jobs - 94 - DEBUG - Exiting worker thread
2020-05-01 11:45:12,226 - log_response - 228 - WARNING - Not Found: /favicon.ico
2020-05-01 11:45:12,818 - log_response - 228 - WARNING - Not Found: /favicon.ico
2020-05-01 11:45:13,444 - log_response - 228 - WARNING - Not Found: /favicon.ico
2020-05-01 11:45:14,053 - log_response - 228 - WARNING - Not Found: /favicon.ico
2020-05-01 11:45:14,373 - log_response - 228 - WARNING - Not Found: /
2020-05-01 11:45:14,612 - log_response - 228 - WARNING - Not Found: /favicon.ico
2020-05-01 11:46:55,619 - trigger_reload - 203 - INFO - E:\1-program\11-LAMDataServer\lamdataserver\LAMProcessData\urls.py changed, reloading.
2020-05-01 11:46:55,619 - shutdown - 111 - INFO - Shutting down thread pool
2020-05-01 11:46:58,676 - _real_add_job - 262 - INFO - Added job "regulartime_task (trigger: interval[1 day, 0:00:00], next run at: 2020-05-01 11:47:08.675894)" to job store "default"
2020-05-01 11:46:58,676 - _real_add_job - 262 - INFO - Added job "cleanup (trigger: cron[day_of_week='*', hour='3', minute='0', second='0'], next run at: 2020-05-02 03:00:00)" to job store "default"
2020-05-01 11:46:58,676 - _real_add_job - 262 - INFO - Added job "OpenLog (trigger: cron[hour='0'], next run at: 2020-05-02 00:00:00)" to job store "default"
2020-05-01 11:46:58,677 - _main_loop - 574 - INFO - Scheduler started
2020-05-01 11:46:58,678 - _main_loop - 579 - DEBUG - Looking for jobs to run
2020-05-01 11:46:58,678 - _main_loop - 588 - DEBUG - Next wakeup is due at 2020-05-01 11:47:08.675894 (in 9.997799 seconds)
2020-05-01 11:46:58,688 - <module> - 63 - DEBUG - SendBefore_NotRecive : [<CNCProcessStatus: CNCProcessStatus object (2038721)>]
2020-05-01 11:46:58,688 - <module> - 64 - DEBUG - Waitfor_Recive : [2038721]
2020-05-01 11:47:08,676 - _main_loop - 579 - DEBUG - Looking for jobs to run
2020-05-01 11:47:08,677 - _run_jobs - 69 - DEBUG - Started worker thread
2020-05-01 11:47:08,677 - _run_job - 509 - INFO - Running job "regulartime_task (trigger: interval[1 day, 0:00:00], next run at: 2020-05-01 11:47:08.675894)" (scheduled at 2020-05-01 11:47:08.675894)
2020-05-01 11:47:08,677 - _main_loop - 588 - DEBUG - Next wakeup is due at 2020-05-02 00:00:00 (in 43971.323716 seconds)
2020-05-01 11:47:09,076 - _run_job - 520 - ERROR - Job "regulartime_task (trigger: interval[1 day, 0:00:00], next run at: 2020-05-02 11:47:08.675894)" raised an exception
Traceback (most recent call last):
  File "D:\Program Files\Python37\lib\site-packages\django\db\backends\utils.py", line 84, in _execute
    return self.cursor.execute(sql, params)
  File "D:\Program Files\Python37\lib\site-packages\django\db\backends\mysql\base.py", line 71, in execute
    return self.cursor.execute(query, args)
  File "D:\Program Files\Python37\lib\site-packages\MySQLdb\cursors.py", line 209, in execute
    res = self._query(query)
  File "D:\Program Files\Python37\lib\site-packages\MySQLdb\cursors.py", line 315, in _query
    db.query(q)
  File "D:\Program Files\Python37\lib\site-packages\MySQLdb\connections.py", line 239, in query
    _mysql.connection.query(self, query)
MySQLdb._exceptions.IntegrityError: (1062, "Duplicate entry '1588348800' for key 'LAMProcessData_process_r_acquisition_timestamp_a69ae90c_uniq'")

The above exception was the direct cause of the following exception:

Traceback (most recent call last):
  File "D:\Program Files\Python37\lib\site-packages\apscheduler\scheduler.py", line 512, in _run_job
    retval = job.func(*job.args, **job.kwargs)
  File "E:\1-program\11-LAMDataServer\lamdataserver\LAMProcessData\views.py", line 4988, in regulartime_task
    RT_FineData.Realtime_FineData.init_Tomorrow_rows()
  File "E:\1-program\11-LAMDataServer\lamdataserver\LAMProcessData\process_realtime_finedata.py", line 193, in init_Tomorrow_rows
    _model.objects.bulk_create(insert_data_list)
  File "D:\Program Files\Python37\lib\site-packages\django\db\models\manager.py", line 82, in manager_method
    return getattr(self.get_queryset(), name)(*args, **kwargs)
  File "D:\Program Files\Python37\lib\site-packages\django\db\models\query.py", line 474, in bulk_create
    ids = self._batched_insert(objs_without_pk, fields, batch_size, ignore_conflicts=ignore_conflicts)
  File "D:\Program Files\Python37\lib\site-packages\django\db\models\query.py", line 1211, in _batched_insert
    self._insert(item, fields=fields, using=self.db, ignore_conflicts=ignore_conflicts)
  File "D:\Program Files\Python37\lib\site-packages\django\db\models\query.py", line 1186, in _insert
    return query.get_compiler(using=using).execute_sql(return_id)
  File "D:\Program Files\Python37\lib\site-packages\django\db\models\sql\compiler.py", line 1332, in execute_sql
    cursor.execute(sql, params)
  File "D:\Program Files\Python37\lib\site-packages\django\db\backends\utils.py", line 99, in execute
    return super().execute(sql, params)
  File "D:\Program Files\Python37\lib\site-packages\django\db\backends\utils.py", line 67, in execute
    return self._execute_with_wrappers(sql, params, many=False, executor=self._execute)
  File "D:\Program Files\Python37\lib\site-packages\django\db\backends\utils.py", line 76, in _execute_with_wrappers
    return executor(sql, params, many, context)
  File "D:\Program Files\Python37\lib\site-packages\django\db\backends\utils.py", line 84, in _execute
    return self.cursor.execute(sql, params)
  File "D:\Program Files\Python37\lib\site-packages\django\db\utils.py", line 89, in __exit__
    raise dj_exc_value.with_traceback(traceback) from exc_value
  File "D:\Program Files\Python37\lib\site-packages\django\db\backends\utils.py", line 84, in _execute
    return self.cursor.execute(sql, params)
  File "D:\Program Files\Python37\lib\site-packages\django\db\backends\mysql\base.py", line 71, in execute
    return self.cursor.execute(query, args)
  File "D:\Program Files\Python37\lib\site-packages\MySQLdb\cursors.py", line 209, in execute
    res = self._query(query)
  File "D:\Program Files\Python37\lib\site-packages\MySQLdb\cursors.py", line 315, in _query
    db.query(q)
  File "D:\Program Files\Python37\lib\site-packages\MySQLdb\connections.py", line 239, in query
    _mysql.connection.query(self, query)
django.db.utils.IntegrityError: (1062, "Duplicate entry '1588348800' for key 'LAMProcessData_process_r_acquisition_timestamp_a69ae90c_uniq'")
2020-05-01 11:47:10,085 - _run_jobs - 94 - DEBUG - Exiting worker thread
2020-05-01 11:47:36,029 - trigger_reload - 203 - INFO - E:\1-program\11-LAMDataServer\lamdataserver\LAMProcessData\urls.py changed, reloading.
2020-05-01 11:47:36,030 - shutdown - 111 - INFO - Shutting down thread pool
2020-05-01 11:47:39,930 - _real_add_job - 262 - INFO - Added job "regulartime_task (trigger: interval[1 day, 0:00:00], next run at: 2020-05-01 11:47:49.928304)" to job store "default"
2020-05-01 11:47:39,930 - _real_add_job - 262 - INFO - Added job "cleanup (trigger: cron[day_of_week='*', hour='3', minute='0', second='0'], next run at: 2020-05-02 03:00:00)" to job store "default"
2020-05-01 11:47:39,930 - _real_add_job - 262 - INFO - Added job "OpenLog (trigger: cron[hour='0'], next run at: 2020-05-02 00:00:00)" to job store "default"
2020-05-01 11:47:39,930 - _main_loop - 574 - INFO - Scheduler started
2020-05-01 11:47:39,931 - _main_loop - 579 - DEBUG - Looking for jobs to run
2020-05-01 11:47:39,931 - _main_loop - 588 - DEBUG - Next wakeup is due at 2020-05-01 11:47:49.928304 (in 9.996950 seconds)
2020-05-01 11:47:39,945 - <module> - 63 - DEBUG - SendBefore_NotRecive : [<CNCProcessStatus: CNCProcessStatus object (2038721)>]
2020-05-01 11:47:39,945 - <module> - 64 - DEBUG - Waitfor_Recive : [2038721]
2020-05-01 11:47:49,929 - _main_loop - 579 - DEBUG - Looking for jobs to run
2020-05-01 11:47:49,931 - _run_jobs - 69 - DEBUG - Started worker thread
2020-05-01 11:47:49,931 - _run_job - 509 - INFO - Running job "regulartime_task (trigger: interval[1 day, 0:00:00], next run at: 2020-05-01 11:47:49.928304)" (scheduled at 2020-05-01 11:47:49.928304)
2020-05-01 11:47:49,932 - _main_loop - 588 - DEBUG - Next wakeup is due at 2020-05-02 00:00:00 (in 43930.070251 seconds)
2020-05-01 11:47:50,343 - _run_job - 520 - ERROR - Job "regulartime_task (trigger: interval[1 day, 0:00:00], next run at: 2020-05-02 11:47:49.928304)" raised an exception
Traceback (most recent call last):
  File "D:\Program Files\Python37\lib\site-packages\django\db\backends\utils.py", line 84, in _execute
    return self.cursor.execute(sql, params)
  File "D:\Program Files\Python37\lib\site-packages\django\db\backends\mysql\base.py", line 71, in execute
    return self.cursor.execute(query, args)
  File "D:\Program Files\Python37\lib\site-packages\MySQLdb\cursors.py", line 209, in execute
    res = self._query(query)
  File "D:\Program Files\Python37\lib\site-packages\MySQLdb\cursors.py", line 315, in _query
    db.query(q)
  File "D:\Program Files\Python37\lib\site-packages\MySQLdb\connections.py", line 239, in query
    _mysql.connection.query(self, query)
MySQLdb._exceptions.IntegrityError: (1062, "Duplicate entry '1588348800' for key 'LAMProcessData_process_r_acquisition_timestamp_a69ae90c_uniq'")

The above exception was the direct cause of the following exception:

Traceback (most recent call last):
  File "D:\Program Files\Python37\lib\site-packages\apscheduler\scheduler.py", line 512, in _run_job
    retval = job.func(*job.args, **job.kwargs)
  File "E:\1-program\11-LAMDataServer\lamdataserver\LAMProcessData\views.py", line 4988, in regulartime_task
    RT_FineData.Realtime_FineData.init_Tomorrow_rows()
  File "E:\1-program\11-LAMDataServer\lamdataserver\LAMProcessData\process_realtime_finedata.py", line 193, in init_Tomorrow_rows
    _model.objects.bulk_create(insert_data_list)
  File "D:\Program Files\Python37\lib\site-packages\django\db\models\manager.py", line 82, in manager_method
    return getattr(self.get_queryset(), name)(*args, **kwargs)
  File "D:\Program Files\Python37\lib\site-packages\django\db\models\query.py", line 474, in bulk_create
    ids = self._batched_insert(objs_without_pk, fields, batch_size, ignore_conflicts=ignore_conflicts)
  File "D:\Program Files\Python37\lib\site-packages\django\db\models\query.py", line 1211, in _batched_insert
    self._insert(item, fields=fields, using=self.db, ignore_conflicts=ignore_conflicts)
  File "D:\Program Files\Python37\lib\site-packages\django\db\models\query.py", line 1186, in _insert
    return query.get_compiler(using=using).execute_sql(return_id)
  File "D:\Program Files\Python37\lib\site-packages\django\db\models\sql\compiler.py", line 1332, in execute_sql
    cursor.execute(sql, params)
  File "D:\Program Files\Python37\lib\site-packages\django\db\backends\utils.py", line 99, in execute
    return super().execute(sql, params)
  File "D:\Program Files\Python37\lib\site-packages\django\db\backends\utils.py", line 67, in execute
    return self._execute_with_wrappers(sql, params, many=False, executor=self._execute)
  File "D:\Program Files\Python37\lib\site-packages\django\db\backends\utils.py", line 76, in _execute_with_wrappers
    return executor(sql, params, many, context)
  File "D:\Program Files\Python37\lib\site-packages\django\db\backends\utils.py", line 84, in _execute
    return self.cursor.execute(sql, params)
  File "D:\Program Files\Python37\lib\site-packages\django\db\utils.py", line 89, in __exit__
    raise dj_exc_value.with_traceback(traceback) from exc_value
  File "D:\Program Files\Python37\lib\site-packages\django\db\backends\utils.py", line 84, in _execute
    return self.cursor.execute(sql, params)
  File "D:\Program Files\Python37\lib\site-packages\django\db\backends\mysql\base.py", line 71, in execute
    return self.cursor.execute(query, args)
  File "D:\Program Files\Python37\lib\site-packages\MySQLdb\cursors.py", line 209, in execute
    res = self._query(query)
  File "D:\Program Files\Python37\lib\site-packages\MySQLdb\cursors.py", line 315, in _query
    db.query(q)
  File "D:\Program Files\Python37\lib\site-packages\MySQLdb\connections.py", line 239, in query
    _mysql.connection.query(self, query)
django.db.utils.IntegrityError: (1062, "Duplicate entry '1588348800' for key 'LAMProcessData_process_r_acquisition_timestamp_a69ae90c_uniq'")
2020-05-01 11:47:51,352 - _run_jobs - 94 - DEBUG - Exiting worker thread
2020-05-01 11:48:17,261 - trigger_reload - 203 - INFO - E:\1-program\11-LAMDataServer\lamdataserver\LAMProcessData\urls.py changed, reloading.
2020-05-01 11:48:17,262 - shutdown - 111 - INFO - Shutting down thread pool
2020-05-01 11:48:19,420 - _real_add_job - 262 - INFO - Added job "regulartime_task (trigger: interval[1 day, 0:00:00], next run at: 2020-05-01 11:48:29.419938)" to job store "default"
2020-05-01 11:48:19,420 - _real_add_job - 262 - INFO - Added job "cleanup (trigger: cron[day_of_week='*', hour='3', minute='0', second='0'], next run at: 2020-05-02 03:00:00)" to job store "default"
2020-05-01 11:48:19,420 - _real_add_job - 262 - INFO - Added job "OpenLog (trigger: cron[hour='0'], next run at: 2020-05-02 00:00:00)" to job store "default"
2020-05-01 11:48:19,422 - _main_loop - 574 - INFO - Scheduler started
2020-05-01 11:48:19,422 - _main_loop - 579 - DEBUG - Looking for jobs to run
2020-05-01 11:48:19,422 - _main_loop - 588 - DEBUG - Next wakeup is due at 2020-05-01 11:48:29.419938 (in 9.997809 seconds)
2020-05-01 11:48:19,433 - <module> - 63 - DEBUG - SendBefore_NotRecive : [<CNCProcessStatus: CNCProcessStatus object (2038721)>]
2020-05-01 11:48:19,433 - <module> - 64 - DEBUG - Waitfor_Recive : [2038721]
2020-05-01 11:48:19,455 - shutdown - 111 - INFO - Shutting down thread pool
2020-05-01 11:48:53,574 - _real_add_job - 262 - INFO - Added job "regulartime_task (trigger: interval[1 day, 0:00:00], next run at: 2020-05-01 11:49:03.572609)" to job store "default"
2020-05-01 11:48:53,575 - _real_add_job - 262 - INFO - Added job "cleanup (trigger: cron[day_of_week='*', hour='3', minute='0', second='0'], next run at: 2020-05-02 03:00:00)" to job store "default"
2020-05-01 11:48:53,575 - _real_add_job - 262 - INFO - Added job "OpenLog (trigger: cron[hour='0'], next run at: 2020-05-02 00:00:00)" to job store "default"
2020-05-01 11:48:53,577 - _main_loop - 574 - INFO - Scheduler started
2020-05-01 11:48:53,578 - _main_loop - 579 - DEBUG - Looking for jobs to run
2020-05-01 11:48:53,578 - _main_loop - 588 - DEBUG - Next wakeup is due at 2020-05-01 11:49:03.572609 (in 9.993956 seconds)
2020-05-01 11:48:53,602 - <module> - 63 - DEBUG - SendBefore_NotRecive : [<CNCProcessStatus: CNCProcessStatus object (2038721)>]
2020-05-01 11:48:53,602 - <module> - 64 - DEBUG - Waitfor_Recive : [2038721]
2020-05-01 11:48:53,858 - shutdown - 111 - INFO - Shutting down thread pool
2020-05-01 11:49:08,164 - _real_add_job - 262 - INFO - Added job "regulartime_task (trigger: interval[1 day, 0:00:00], next run at: 2020-05-01 11:49:18.162359)" to job store "default"
2020-05-01 11:49:08,164 - _real_add_job - 262 - INFO - Added job "cleanup (trigger: cron[day_of_week='*', hour='3', minute='0', second='0'], next run at: 2020-05-02 03:00:00)" to job store "default"
2020-05-01 11:49:08,165 - _real_add_job - 262 - INFO - Added job "OpenLog (trigger: cron[hour='0'], next run at: 2020-05-02 00:00:00)" to job store "default"
2020-05-01 11:49:08,166 - _main_loop - 574 - INFO - Scheduler started
2020-05-01 11:49:08,166 - _main_loop - 579 - DEBUG - Looking for jobs to run
2020-05-01 11:49:08,166 - _main_loop - 588 - DEBUG - Next wakeup is due at 2020-05-01 11:49:18.162359 (in 9.995530 seconds)
2020-05-01 11:49:08,182 - <module> - 63 - DEBUG - SendBefore_NotRecive : [<CNCProcessStatus: CNCProcessStatus object (2038721)>]
2020-05-01 11:49:08,182 - <module> - 64 - DEBUG - Waitfor_Recive : [2038721]
2020-05-01 11:49:18,163 - _main_loop - 579 - DEBUG - Looking for jobs to run
2020-05-01 11:49:18,164 - _run_jobs - 69 - DEBUG - Started worker thread
2020-05-01 11:49:18,164 - _run_job - 509 - INFO - Running job "regulartime_task (trigger: interval[1 day, 0:00:00], next run at: 2020-05-01 11:49:18.162359)" (scheduled at 2020-05-01 11:49:18.162359)
2020-05-01 11:49:18,164 - _main_loop - 588 - DEBUG - Next wakeup is due at 2020-05-02 00:00:00 (in 43841.836127 seconds)
2020-05-01 11:49:19,721 - _run_job - 520 - ERROR - Job "regulartime_task (trigger: interval[1 day, 0:00:00], next run at: 2020-05-02 11:49:18.162359)" raised an exception
Traceback (most recent call last):
  File "D:\Program Files\Python37\lib\site-packages\django\db\backends\utils.py", line 84, in _execute
    return self.cursor.execute(sql, params)
  File "D:\Program Files\Python37\lib\site-packages\django\db\backends\mysql\base.py", line 71, in execute
    return self.cursor.execute(query, args)
  File "D:\Program Files\Python37\lib\site-packages\MySQLdb\cursors.py", line 209, in execute
    res = self._query(query)
  File "D:\Program Files\Python37\lib\site-packages\MySQLdb\cursors.py", line 315, in _query
    db.query(q)
  File "D:\Program Files\Python37\lib\site-packages\MySQLdb\connections.py", line 239, in query
    _mysql.connection.query(self, query)
MySQLdb._exceptions.IntegrityError: (1062, "Duplicate entry '1588348800' for key 'LAMProcessData_process_r_acquisition_timestamp_a69ae90c_uniq'")

The above exception was the direct cause of the following exception:

Traceback (most recent call last):
  File "D:\Program Files\Python37\lib\site-packages\apscheduler\scheduler.py", line 512, in _run_job
    retval = job.func(*job.args, **job.kwargs)
  File "E:\1-program\11-LAMDataServer\lamdataserver\LAMProcessData\views.py", line 4988, in regulartime_task
    RT_FineData.Realtime_FineData.init_Tomorrow_rows()
  File "E:\1-program\11-LAMDataServer\lamdataserver\LAMProcessData\process_realtime_finedata.py", line 193, in init_Tomorrow_rows
    _model.objects.bulk_create(insert_data_list)
  File "D:\Program Files\Python37\lib\site-packages\django\db\models\manager.py", line 82, in manager_method
    return getattr(self.get_queryset(), name)(*args, **kwargs)
  File "D:\Program Files\Python37\lib\site-packages\django\db\models\query.py", line 474, in bulk_create
    ids = self._batched_insert(objs_without_pk, fields, batch_size, ignore_conflicts=ignore_conflicts)
  File "D:\Program Files\Python37\lib\site-packages\django\db\models\query.py", line 1211, in _batched_insert
    self._insert(item, fields=fields, using=self.db, ignore_conflicts=ignore_conflicts)
  File "D:\Program Files\Python37\lib\site-packages\django\db\models\query.py", line 1186, in _insert
    return query.get_compiler(using=using).execute_sql(return_id)
  File "D:\Program Files\Python37\lib\site-packages\django\db\models\sql\compiler.py", line 1332, in execute_sql
    cursor.execute(sql, params)
  File "D:\Program Files\Python37\lib\site-packages\django\db\backends\utils.py", line 99, in execute
    return super().execute(sql, params)
  File "D:\Program Files\Python37\lib\site-packages\django\db\backends\utils.py", line 67, in execute
    return self._execute_with_wrappers(sql, params, many=False, executor=self._execute)
  File "D:\Program Files\Python37\lib\site-packages\django\db\backends\utils.py", line 76, in _execute_with_wrappers
    return executor(sql, params, many, context)
  File "D:\Program Files\Python37\lib\site-packages\django\db\backends\utils.py", line 84, in _execute
    return self.cursor.execute(sql, params)
  File "D:\Program Files\Python37\lib\site-packages\django\db\utils.py", line 89, in __exit__
    raise dj_exc_value.with_traceback(traceback) from exc_value
  File "D:\Program Files\Python37\lib\site-packages\django\db\backends\utils.py", line 84, in _execute
    return self.cursor.execute(sql, params)
  File "D:\Program Files\Python37\lib\site-packages\django\db\backends\mysql\base.py", line 71, in execute
    return self.cursor.execute(query, args)
  File "D:\Program Files\Python37\lib\site-packages\MySQLdb\cursors.py", line 209, in execute
    res = self._query(query)
  File "D:\Program Files\Python37\lib\site-packages\MySQLdb\cursors.py", line 315, in _query
    db.query(q)
  File "D:\Program Files\Python37\lib\site-packages\MySQLdb\connections.py", line 239, in query
    _mysql.connection.query(self, query)
django.db.utils.IntegrityError: (1062, "Duplicate entry '1588348800' for key 'LAMProcessData_process_r_acquisition_timestamp_a69ae90c_uniq'")
2020-05-01 11:49:20,732 - _run_jobs - 94 - DEBUG - Exiting worker thread
2020-05-01 11:50:58,061 - trigger_reload - 203 - INFO - E:\1-program\11-LAMDataServer\lamdataserver\LAMProcessData\models.py changed, reloading.
2020-05-01 11:50:58,062 - shutdown - 111 - INFO - Shutting down thread pool
2020-05-01 11:51:01,969 - _real_add_job - 262 - INFO - Added job "regulartime_task (trigger: interval[1 day, 0:00:00], next run at: 2020-05-01 11:51:11.967372)" to job store "default"
2020-05-01 11:51:01,970 - _real_add_job - 262 - INFO - Added job "cleanup (trigger: cron[day_of_week='*', hour='3', minute='0', second='0'], next run at: 2020-05-02 03:00:00)" to job store "default"
2020-05-01 11:51:01,970 - _real_add_job - 262 - INFO - Added job "OpenLog (trigger: cron[hour='0'], next run at: 2020-05-02 00:00:00)" to job store "default"
2020-05-01 11:51:01,971 - _main_loop - 574 - INFO - Scheduler started
2020-05-01 11:51:01,972 - _main_loop - 579 - DEBUG - Looking for jobs to run
2020-05-01 11:51:01,972 - _main_loop - 588 - DEBUG - Next wakeup is due at 2020-05-01 11:51:11.967372 (in 9.995014 seconds)
2020-05-01 11:51:01,986 - <module> - 63 - DEBUG - SendBefore_NotRecive : [<CNCProcessStatus: CNCProcessStatus object (2038721)>]
2020-05-01 11:51:01,986 - <module> - 64 - DEBUG - Waitfor_Recive : [2038721]
2020-05-01 11:51:11,027 - trigger_reload - 203 - INFO - E:\1-program\11-LAMDataServer\lamdataserver\LAMProcessData\models.py changed, reloading.
2020-05-01 11:51:11,029 - shutdown - 111 - INFO - Shutting down thread pool
2020-05-01 11:51:47,403 - _real_add_job - 262 - INFO - Added job "regulartime_task (trigger: interval[1 day, 0:00:00], next run at: 2020-05-01 11:51:57.402222)" to job store "default"
2020-05-01 11:51:47,403 - _real_add_job - 262 - INFO - Added job "cleanup (trigger: cron[day_of_week='*', hour='3', minute='0', second='0'], next run at: 2020-05-02 03:00:00)" to job store "default"
2020-05-01 11:51:47,403 - _real_add_job - 262 - INFO - Added job "OpenLog (trigger: cron[hour='0'], next run at: 2020-05-02 00:00:00)" to job store "default"
2020-05-01 11:51:47,404 - _main_loop - 574 - INFO - Scheduler started
2020-05-01 11:51:47,404 - _main_loop - 579 - DEBUG - Looking for jobs to run
2020-05-01 11:51:47,404 - _main_loop - 588 - DEBUG - Next wakeup is due at 2020-05-01 11:51:57.402222 (in 9.998007 seconds)
2020-05-01 11:51:47,414 - <module> - 63 - DEBUG - SendBefore_NotRecive : [<CNCProcessStatus: CNCProcessStatus object (2038721)>]
2020-05-01 11:51:47,414 - <module> - 64 - DEBUG - Waitfor_Recive : [2038721]
2020-05-01 11:51:47,710 - shutdown - 111 - INFO - Shutting down thread pool
2020-05-01 11:51:51,577 - _real_add_job - 262 - INFO - Added job "regulartime_task (trigger: interval[1 day, 0:00:00], next run at: 2020-05-01 11:52:01.576827)" to job store "default"
2020-05-01 11:51:51,577 - _real_add_job - 262 - INFO - Added job "cleanup (trigger: cron[day_of_week='*', hour='3', minute='0', second='0'], next run at: 2020-05-02 03:00:00)" to job store "default"
2020-05-01 11:51:51,577 - _real_add_job - 262 - INFO - Added job "OpenLog (trigger: cron[hour='0'], next run at: 2020-05-02 00:00:00)" to job store "default"
2020-05-01 11:51:51,577 - _main_loop - 574 - INFO - Scheduler started
2020-05-01 11:51:51,578 - _main_loop - 579 - DEBUG - Looking for jobs to run
2020-05-01 11:51:51,578 - _main_loop - 588 - DEBUG - Next wakeup is due at 2020-05-01 11:52:01.576827 (in 9.998008 seconds)
2020-05-01 11:51:51,588 - <module> - 63 - DEBUG - SendBefore_NotRecive : [<CNCProcessStatus: CNCProcessStatus object (2038721)>]
2020-05-01 11:51:51,588 - <module> - 64 - DEBUG - Waitfor_Recive : [2038721]
2020-05-01 11:51:52,676 - shutdown - 111 - INFO - Shutting down thread pool
2020-05-01 11:51:59,837 - _real_add_job - 262 - INFO - Added job "regulartime_task (trigger: interval[1 day, 0:00:00], next run at: 2020-05-01 11:52:09.831859)" to job store "default"
2020-05-01 11:51:59,838 - _real_add_job - 262 - INFO - Added job "cleanup (trigger: cron[day_of_week='*', hour='3', minute='0', second='0'], next run at: 2020-05-02 03:00:00)" to job store "default"
2020-05-01 11:51:59,838 - _real_add_job - 262 - INFO - Added job "OpenLog (trigger: cron[hour='0'], next run at: 2020-05-02 00:00:00)" to job store "default"
2020-05-01 11:51:59,839 - _main_loop - 574 - INFO - Scheduler started
2020-05-01 11:51:59,840 - _main_loop - 579 - DEBUG - Looking for jobs to run
2020-05-01 11:51:59,840 - _main_loop - 588 - DEBUG - Next wakeup is due at 2020-05-01 11:52:09.831859 (in 9.991498 seconds)
2020-05-01 11:51:59,864 - <module> - 63 - DEBUG - SendBefore_NotRecive : [<CNCProcessStatus: CNCProcessStatus object (2038721)>]
2020-05-01 11:51:59,864 - <module> - 64 - DEBUG - Waitfor_Recive : [2038721]
2020-05-01 11:52:09,840 - _main_loop - 579 - DEBUG - Looking for jobs to run
2020-05-01 11:52:09,842 - _run_jobs - 69 - DEBUG - Started worker thread
2020-05-01 11:52:09,843 - _run_job - 509 - INFO - Running job "regulartime_task (trigger: interval[1 day, 0:00:00], next run at: 2020-05-01 11:52:09.831859)" (scheduled at 2020-05-01 11:52:09.831859)
2020-05-01 11:52:09,844 - _main_loop - 588 - DEBUG - Next wakeup is due at 2020-05-02 00:00:00 (in 43670.158308 seconds)
2020-05-01 11:52:10,634 - _run_job - 520 - ERROR - Job "regulartime_task (trigger: interval[1 day, 0:00:00], next run at: 2020-05-02 11:52:09.831859)" raised an exception
Traceback (most recent call last):
  File "D:\Program Files\Python37\lib\site-packages\django\db\backends\utils.py", line 84, in _execute
    return self.cursor.execute(sql, params)
  File "D:\Program Files\Python37\lib\site-packages\django\db\backends\mysql\base.py", line 71, in execute
    return self.cursor.execute(query, args)
  File "D:\Program Files\Python37\lib\site-packages\MySQLdb\cursors.py", line 209, in execute
    res = self._query(query)
  File "D:\Program Files\Python37\lib\site-packages\MySQLdb\cursors.py", line 315, in _query
    db.query(q)
  File "D:\Program Files\Python37\lib\site-packages\MySQLdb\connections.py", line 239, in query
    _mysql.connection.query(self, query)
MySQLdb._exceptions.IntegrityError: (1062, "Duplicate entry '1588348800' for key 'LAMProcessData_process_r_acquisition_timestamp_a69ae90c_uniq'")

The above exception was the direct cause of the following exception:

Traceback (most recent call last):
  File "D:\Program Files\Python37\lib\site-packages\apscheduler\scheduler.py", line 512, in _run_job
    retval = job.func(*job.args, **job.kwargs)
  File "E:\1-program\11-LAMDataServer\lamdataserver\LAMProcessData\views.py", line 4988, in regulartime_task
    RT_FineData.Realtime_FineData.init_Tomorrow_rows()
  File "E:\1-program\11-LAMDataServer\lamdataserver\LAMProcessData\process_realtime_finedata.py", line 193, in init_Tomorrow_rows
    _model.objects.bulk_create(insert_data_list)
  File "D:\Program Files\Python37\lib\site-packages\django\db\models\manager.py", line 82, in manager_method
    return getattr(self.get_queryset(), name)(*args, **kwargs)
  File "D:\Program Files\Python37\lib\site-packages\django\db\models\query.py", line 474, in bulk_create
    ids = self._batched_insert(objs_without_pk, fields, batch_size, ignore_conflicts=ignore_conflicts)
  File "D:\Program Files\Python37\lib\site-packages\django\db\models\query.py", line 1211, in _batched_insert
    self._insert(item, fields=fields, using=self.db, ignore_conflicts=ignore_conflicts)
  File "D:\Program Files\Python37\lib\site-packages\django\db\models\query.py", line 1186, in _insert
    return query.get_compiler(using=using).execute_sql(return_id)
  File "D:\Program Files\Python37\lib\site-packages\django\db\models\sql\compiler.py", line 1332, in execute_sql
    cursor.execute(sql, params)
  File "D:\Program Files\Python37\lib\site-packages\django\db\backends\utils.py", line 99, in execute
    return super().execute(sql, params)
  File "D:\Program Files\Python37\lib\site-packages\django\db\backends\utils.py", line 67, in execute
    return self._execute_with_wrappers(sql, params, many=False, executor=self._execute)
  File "D:\Program Files\Python37\lib\site-packages\django\db\backends\utils.py", line 76, in _execute_with_wrappers
    return executor(sql, params, many, context)
  File "D:\Program Files\Python37\lib\site-packages\django\db\backends\utils.py", line 84, in _execute
    return self.cursor.execute(sql, params)
  File "D:\Program Files\Python37\lib\site-packages\django\db\utils.py", line 89, in __exit__
    raise dj_exc_value.with_traceback(traceback) from exc_value
  File "D:\Program Files\Python37\lib\site-packages\django\db\backends\utils.py", line 84, in _execute
    return self.cursor.execute(sql, params)
  File "D:\Program Files\Python37\lib\site-packages\django\db\backends\mysql\base.py", line 71, in execute
    return self.cursor.execute(query, args)
  File "D:\Program Files\Python37\lib\site-packages\MySQLdb\cursors.py", line 209, in execute
    res = self._query(query)
  File "D:\Program Files\Python37\lib\site-packages\MySQLdb\cursors.py", line 315, in _query
    db.query(q)
  File "D:\Program Files\Python37\lib\site-packages\MySQLdb\connections.py", line 239, in query
    _mysql.connection.query(self, query)
django.db.utils.IntegrityError: (1062, "Duplicate entry '1588348800' for key 'LAMProcessData_process_r_acquisition_timestamp_a69ae90c_uniq'")
2020-05-01 11:52:11,652 - _run_jobs - 94 - DEBUG - Exiting worker thread
2020-05-01 11:55:37,389 - _real_add_job - 262 - INFO - Added job "regulartime_task (trigger: interval[1 day, 0:00:00], next run at: 2020-05-01 11:55:47.387374)" to job store "default"
2020-05-01 11:55:37,389 - _real_add_job - 262 - INFO - Added job "cleanup (trigger: cron[day_of_week='*', hour='3', minute='0', second='0'], next run at: 2020-05-02 03:00:00)" to job store "default"
2020-05-01 11:55:37,389 - _real_add_job - 262 - INFO - Added job "OpenLog (trigger: cron[hour='0'], next run at: 2020-05-02 00:00:00)" to job store "default"
2020-05-01 11:55:37,391 - _main_loop - 574 - INFO - Scheduler started
2020-05-01 11:55:37,391 - _main_loop - 579 - DEBUG - Looking for jobs to run
2020-05-01 11:55:37,391 - _main_loop - 588 - DEBUG - Next wakeup is due at 2020-05-01 11:55:47.387374 (in 9.996054 seconds)
2020-05-01 11:55:37,411 - <module> - 63 - DEBUG - SendBefore_NotRecive : [<CNCProcessStatus: CNCProcessStatus object (2038721)>]
2020-05-01 11:55:37,411 - <module> - 64 - DEBUG - Waitfor_Recive : [2038721]
2020-05-01 11:55:47,388 - _main_loop - 579 - DEBUG - Looking for jobs to run
2020-05-01 11:55:47,388 - _run_jobs - 69 - DEBUG - Started worker thread
2020-05-01 11:55:47,390 - _run_job - 509 - INFO - Running job "regulartime_task (trigger: interval[1 day, 0:00:00], next run at: 2020-05-01 11:55:47.387374)" (scheduled at 2020-05-01 11:55:47.387374)
2020-05-01 11:55:47,390 - _main_loop - 588 - DEBUG - Next wakeup is due at 2020-05-02 00:00:00 (in 43452.611028 seconds)
2020-05-01 11:55:48,854 - _run_job - 520 - ERROR - Job "regulartime_task (trigger: interval[1 day, 0:00:00], next run at: 2020-05-02 11:55:47.387374)" raised an exception
Traceback (most recent call last):
  File "D:\Program Files\Python37\lib\site-packages\django\db\backends\utils.py", line 84, in _execute
    return self.cursor.execute(sql, params)
  File "D:\Program Files\Python37\lib\site-packages\django\db\backends\mysql\base.py", line 71, in execute
    return self.cursor.execute(query, args)
  File "D:\Program Files\Python37\lib\site-packages\MySQLdb\cursors.py", line 209, in execute
    res = self._query(query)
  File "D:\Program Files\Python37\lib\site-packages\MySQLdb\cursors.py", line 315, in _query
    db.query(q)
  File "D:\Program Files\Python37\lib\site-packages\MySQLdb\connections.py", line 239, in query
    _mysql.connection.query(self, query)
MySQLdb._exceptions.IntegrityError: (1062, "Duplicate entry '1588348800' for key 'LAMProcessData_process_r_acquisition_timestamp_a69ae90c_uniq'")

The above exception was the direct cause of the following exception:

Traceback (most recent call last):
  File "D:\Program Files\Python37\lib\site-packages\apscheduler\scheduler.py", line 512, in _run_job
    retval = job.func(*job.args, **job.kwargs)
  File "E:\1-program\11-LAMDataServer\lamdataserver\LAMProcessData\views.py", line 4988, in regulartime_task
    RT_FineData.Realtime_FineData.init_Tomorrow_rows()
  File "E:\1-program\11-LAMDataServer\lamdataserver\LAMProcessData\process_realtime_finedata.py", line 193, in init_Tomorrow_rows
    _model.objects.bulk_create(insert_data_list)
  File "D:\Program Files\Python37\lib\site-packages\django\db\models\manager.py", line 82, in manager_method
    return getattr(self.get_queryset(), name)(*args, **kwargs)
  File "D:\Program Files\Python37\lib\site-packages\django\db\models\query.py", line 474, in bulk_create
    ids = self._batched_insert(objs_without_pk, fields, batch_size, ignore_conflicts=ignore_conflicts)
  File "D:\Program Files\Python37\lib\site-packages\django\db\models\query.py", line 1211, in _batched_insert
    self._insert(item, fields=fields, using=self.db, ignore_conflicts=ignore_conflicts)
  File "D:\Program Files\Python37\lib\site-packages\django\db\models\query.py", line 1186, in _insert
    return query.get_compiler(using=using).execute_sql(return_id)
  File "D:\Program Files\Python37\lib\site-packages\django\db\models\sql\compiler.py", line 1332, in execute_sql
    cursor.execute(sql, params)
  File "D:\Program Files\Python37\lib\site-packages\django\db\backends\utils.py", line 99, in execute
    return super().execute(sql, params)
  File "D:\Program Files\Python37\lib\site-packages\django\db\backends\utils.py", line 67, in execute
    return self._execute_with_wrappers(sql, params, many=False, executor=self._execute)
  File "D:\Program Files\Python37\lib\site-packages\django\db\backends\utils.py", line 76, in _execute_with_wrappers
    return executor(sql, params, many, context)
  File "D:\Program Files\Python37\lib\site-packages\django\db\backends\utils.py", line 84, in _execute
    return self.cursor.execute(sql, params)
  File "D:\Program Files\Python37\lib\site-packages\django\db\utils.py", line 89, in __exit__
    raise dj_exc_value.with_traceback(traceback) from exc_value
  File "D:\Program Files\Python37\lib\site-packages\django\db\backends\utils.py", line 84, in _execute
    return self.cursor.execute(sql, params)
  File "D:\Program Files\Python37\lib\site-packages\django\db\backends\mysql\base.py", line 71, in execute
    return self.cursor.execute(query, args)
  File "D:\Program Files\Python37\lib\site-packages\MySQLdb\cursors.py", line 209, in execute
    res = self._query(query)
  File "D:\Program Files\Python37\lib\site-packages\MySQLdb\cursors.py", line 315, in _query
    db.query(q)
  File "D:\Program Files\Python37\lib\site-packages\MySQLdb\connections.py", line 239, in query
    _mysql.connection.query(self, query)
django.db.utils.IntegrityError: (1062, "Duplicate entry '1588348800' for key 'LAMProcessData_process_r_acquisition_timestamp_a69ae90c_uniq'")
2020-05-01 11:55:49,863 - _run_jobs - 94 - DEBUG - Exiting worker thread
2020-05-01 11:57:08,737 - _real_add_job - 262 - INFO - Added job "regulartime_task (trigger: interval[1 day, 0:00:00], next run at: 2020-05-01 11:57:18.735663)" to job store "default"
2020-05-01 11:57:08,737 - _real_add_job - 262 - INFO - Added job "cleanup (trigger: cron[day_of_week='*', hour='3', minute='0', second='0'], next run at: 2020-05-02 03:00:00)" to job store "default"
2020-05-01 11:57:08,737 - _real_add_job - 262 - INFO - Added job "OpenLog (trigger: cron[hour='0'], next run at: 2020-05-02 00:00:00)" to job store "default"
2020-05-01 11:57:08,738 - _main_loop - 574 - INFO - Scheduler started
2020-05-01 11:57:08,738 - _main_loop - 579 - DEBUG - Looking for jobs to run
2020-05-01 11:57:08,738 - _main_loop - 588 - DEBUG - Next wakeup is due at 2020-05-01 11:57:18.735663 (in 9.997008 seconds)
2020-05-01 11:57:08,750 - <module> - 63 - DEBUG - SendBefore_NotRecive : [<CNCProcessStatus: CNCProcessStatus object (2038721)>]
2020-05-01 11:57:08,750 - <module> - 64 - DEBUG - Waitfor_Recive : [2038721]
2020-05-01 11:57:18,737 - _main_loop - 579 - DEBUG - Looking for jobs to run
2020-05-01 11:57:18,739 - _run_jobs - 69 - DEBUG - Started worker thread
2020-05-01 11:57:18,739 - _run_job - 509 - INFO - Running job "regulartime_task (trigger: interval[1 day, 0:00:00], next run at: 2020-05-02 11:57:18.735663)" (scheduled at 2020-05-01 11:57:18.735663)
2020-05-01 11:57:18,740 - _main_loop - 588 - DEBUG - Next wakeup is due at 2020-05-02 00:00:00 (in 43361.262658 seconds)
2020-05-01 11:57:19,508 - _run_job - 520 - ERROR - Job "regulartime_task (trigger: interval[1 day, 0:00:00], next run at: 2020-05-02 11:57:18.735663)" raised an exception
Traceback (most recent call last):
  File "D:\Program Files\Python37\lib\site-packages\django\db\backends\utils.py", line 84, in _execute
    return self.cursor.execute(sql, params)
  File "D:\Program Files\Python37\lib\site-packages\django\db\backends\mysql\base.py", line 71, in execute
    return self.cursor.execute(query, args)
  File "D:\Program Files\Python37\lib\site-packages\MySQLdb\cursors.py", line 209, in execute
    res = self._query(query)
  File "D:\Program Files\Python37\lib\site-packages\MySQLdb\cursors.py", line 315, in _query
    db.query(q)
  File "D:\Program Files\Python37\lib\site-packages\MySQLdb\connections.py", line 239, in query
    _mysql.connection.query(self, query)
MySQLdb._exceptions.IntegrityError: (1062, "Duplicate entry '1588348800' for key 'LAMProcessData_process_r_acquisition_timestamp_a69ae90c_uniq'")

The above exception was the direct cause of the following exception:

Traceback (most recent call last):
  File "D:\Program Files\Python37\lib\site-packages\apscheduler\scheduler.py", line 512, in _run_job
    retval = job.func(*job.args, **job.kwargs)
  File "E:\1-program\11-LAMDataServer\lamdataserver\LAMProcessData\views.py", line 4988, in regulartime_task
    RT_FineData.Realtime_FineData.init_Tomorrow_rows()
  File "E:\1-program\11-LAMDataServer\lamdataserver\LAMProcessData\process_realtime_finedata.py", line 193, in init_Tomorrow_rows
    _model.objects.bulk_create(insert_data_list)
  File "D:\Program Files\Python37\lib\site-packages\django\db\models\manager.py", line 82, in manager_method
    return getattr(self.get_queryset(), name)(*args, **kwargs)
  File "D:\Program Files\Python37\lib\site-packages\django\db\models\query.py", line 474, in bulk_create
    ids = self._batched_insert(objs_without_pk, fields, batch_size, ignore_conflicts=ignore_conflicts)
  File "D:\Program Files\Python37\lib\site-packages\django\db\models\query.py", line 1211, in _batched_insert
    self._insert(item, fields=fields, using=self.db, ignore_conflicts=ignore_conflicts)
  File "D:\Program Files\Python37\lib\site-packages\django\db\models\query.py", line 1186, in _insert
    return query.get_compiler(using=using).execute_sql(return_id)
  File "D:\Program Files\Python37\lib\site-packages\django\db\models\sql\compiler.py", line 1332, in execute_sql
    cursor.execute(sql, params)
  File "D:\Program Files\Python37\lib\site-packages\django\db\backends\utils.py", line 99, in execute
    return super().execute(sql, params)
  File "D:\Program Files\Python37\lib\site-packages\django\db\backends\utils.py", line 67, in execute
    return self._execute_with_wrappers(sql, params, many=False, executor=self._execute)
  File "D:\Program Files\Python37\lib\site-packages\django\db\backends\utils.py", line 76, in _execute_with_wrappers
    return executor(sql, params, many, context)
  File "D:\Program Files\Python37\lib\site-packages\django\db\backends\utils.py", line 84, in _execute
    return self.cursor.execute(sql, params)
  File "D:\Program Files\Python37\lib\site-packages\django\db\utils.py", line 89, in __exit__
    raise dj_exc_value.with_traceback(traceback) from exc_value
  File "D:\Program Files\Python37\lib\site-packages\django\db\backends\utils.py", line 84, in _execute
    return self.cursor.execute(sql, params)
  File "D:\Program Files\Python37\lib\site-packages\django\db\backends\mysql\base.py", line 71, in execute
    return self.cursor.execute(query, args)
  File "D:\Program Files\Python37\lib\site-packages\MySQLdb\cursors.py", line 209, in execute
    res = self._query(query)
  File "D:\Program Files\Python37\lib\site-packages\MySQLdb\cursors.py", line 315, in _query
    db.query(q)
  File "D:\Program Files\Python37\lib\site-packages\MySQLdb\connections.py", line 239, in query
    _mysql.connection.query(self, query)
django.db.utils.IntegrityError: (1062, "Duplicate entry '1588348800' for key 'LAMProcessData_process_r_acquisition_timestamp_a69ae90c_uniq'")
2020-05-01 11:57:20,523 - _run_jobs - 94 - DEBUG - Exiting worker thread
2020-05-01 11:59:47,093 - _real_add_job - 262 - INFO - Added job "regulartime_task (trigger: interval[1 day, 0:00:00], next run at: 2020-05-01 11:59:57.091378)" to job store "default"
2020-05-01 11:59:47,093 - _real_add_job - 262 - INFO - Added job "cleanup (trigger: cron[day_of_week='*', hour='3', minute='0', second='0'], next run at: 2020-05-02 03:00:00)" to job store "default"
2020-05-01 11:59:47,094 - _real_add_job - 262 - INFO - Added job "OpenLog (trigger: cron[hour='0'], next run at: 2020-05-02 00:00:00)" to job store "default"
2020-05-01 11:59:47,095 - _main_loop - 574 - INFO - Scheduler started
2020-05-01 11:59:47,095 - _main_loop - 579 - DEBUG - Looking for jobs to run
2020-05-01 11:59:47,095 - _main_loop - 588 - DEBUG - Next wakeup is due at 2020-05-01 11:59:57.091378 (in 9.996098 seconds)
2020-05-01 11:59:47,109 - <module> - 63 - DEBUG - SendBefore_NotRecive : [<CNCProcessStatus: CNCProcessStatus object (2038721)>]
2020-05-01 11:59:47,109 - <module> - 64 - DEBUG - Waitfor_Recive : [2038721]
2020-05-01 11:59:57,092 - _main_loop - 579 - DEBUG - Looking for jobs to run
2020-05-01 11:59:57,093 - _run_jobs - 69 - DEBUG - Started worker thread
2020-05-01 11:59:57,093 - _main_loop - 588 - DEBUG - Next wakeup is due at 2020-05-02 00:00:00 (in 43202.907556 seconds)
2020-05-01 11:59:57,094 - _run_job - 509 - INFO - Running job "regulartime_task (trigger: interval[1 day, 0:00:00], next run at: 2020-05-02 11:59:57.091378)" (scheduled at 2020-05-01 11:59:57.091378)
2020-05-01 11:59:58,242 - _run_job - 520 - ERROR - Job "regulartime_task (trigger: interval[1 day, 0:00:00], next run at: 2020-05-02 11:59:57.091378)" raised an exception
Traceback (most recent call last):
  File "D:\Program Files\Python37\lib\site-packages\django\db\backends\utils.py", line 84, in _execute
    return self.cursor.execute(sql, params)
  File "D:\Program Files\Python37\lib\site-packages\django\db\backends\mysql\base.py", line 71, in execute
    return self.cursor.execute(query, args)
  File "D:\Program Files\Python37\lib\site-packages\MySQLdb\cursors.py", line 209, in execute
    res = self._query(query)
  File "D:\Program Files\Python37\lib\site-packages\MySQLdb\cursors.py", line 315, in _query
    db.query(q)
  File "D:\Program Files\Python37\lib\site-packages\MySQLdb\connections.py", line 239, in query
    _mysql.connection.query(self, query)
MySQLdb._exceptions.IntegrityError: (1062, "Duplicate entry '1588348800' for key 'LAMProcessData_process_r_acquisition_timestamp_a69ae90c_uniq'")

The above exception was the direct cause of the following exception:

Traceback (most recent call last):
  File "D:\Program Files\Python37\lib\site-packages\apscheduler\scheduler.py", line 512, in _run_job
    retval = job.func(*job.args, **job.kwargs)
  File "E:\1-program\11-LAMDataServer\lamdataserver\LAMProcessData\views.py", line 4988, in regulartime_task
    RT_FineData.Realtime_FineData.init_Tomorrow_rows()
  File "E:\1-program\11-LAMDataServer\lamdataserver\LAMProcessData\process_realtime_finedata.py", line 193, in init_Tomorrow_rows
    _model.objects.bulk_create(insert_data_list)
  File "D:\Program Files\Python37\lib\site-packages\django\db\models\manager.py", line 82, in manager_method
    return getattr(self.get_queryset(), name)(*args, **kwargs)
  File "D:\Program Files\Python37\lib\site-packages\django\db\models\query.py", line 474, in bulk_create
    ids = self._batched_insert(objs_without_pk, fields, batch_size, ignore_conflicts=ignore_conflicts)
  File "D:\Program Files\Python37\lib\site-packages\django\db\models\query.py", line 1211, in _batched_insert
    self._insert(item, fields=fields, using=self.db, ignore_conflicts=ignore_conflicts)
  File "D:\Program Files\Python37\lib\site-packages\django\db\models\query.py", line 1186, in _insert
    return query.get_compiler(using=using).execute_sql(return_id)
  File "D:\Program Files\Python37\lib\site-packages\django\db\models\sql\compiler.py", line 1332, in execute_sql
    cursor.execute(sql, params)
  File "D:\Program Files\Python37\lib\site-packages\django\db\backends\utils.py", line 99, in execute
    return super().execute(sql, params)
  File "D:\Program Files\Python37\lib\site-packages\django\db\backends\utils.py", line 67, in execute
    return self._execute_with_wrappers(sql, params, many=False, executor=self._execute)
  File "D:\Program Files\Python37\lib\site-packages\django\db\backends\utils.py", line 76, in _execute_with_wrappers
    return executor(sql, params, many, context)
  File "D:\Program Files\Python37\lib\site-packages\django\db\backends\utils.py", line 84, in _execute
    return self.cursor.execute(sql, params)
  File "D:\Program Files\Python37\lib\site-packages\django\db\utils.py", line 89, in __exit__
    raise dj_exc_value.with_traceback(traceback) from exc_value
  File "D:\Program Files\Python37\lib\site-packages\django\db\backends\utils.py", line 84, in _execute
    return self.cursor.execute(sql, params)
  File "D:\Program Files\Python37\lib\site-packages\django\db\backends\mysql\base.py", line 71, in execute
    return self.cursor.execute(query, args)
  File "D:\Program Files\Python37\lib\site-packages\MySQLdb\cursors.py", line 209, in execute
    res = self._query(query)
  File "D:\Program Files\Python37\lib\site-packages\MySQLdb\cursors.py", line 315, in _query
    db.query(q)
  File "D:\Program Files\Python37\lib\site-packages\MySQLdb\connections.py", line 239, in query
    _mysql.connection.query(self, query)
django.db.utils.IntegrityError: (1062, "Duplicate entry '1588348800' for key 'LAMProcessData_process_r_acquisition_timestamp_a69ae90c_uniq'")
2020-05-01 11:59:59,251 - _run_jobs - 94 - DEBUG - Exiting worker thread
2020-05-01 12:03:14,106 - trigger_reload - 203 - INFO - E:\1-program\11-LAMDataServer\lamdataserver\LAMProcessData\views.py changed, reloading.
2020-05-01 12:03:14,107 - shutdown - 111 - INFO - Shutting down thread pool
2020-05-01 12:03:23,470 - _real_add_job - 262 - INFO - Added job "regulartime_task (trigger: interval[1 day, 0:00:00], next run at: 2020-05-01 12:03:33.469253)" to job store "default"
2020-05-01 12:03:23,470 - _real_add_job - 262 - INFO - Added job "cleanup (trigger: cron[day_of_week='*', hour='3', minute='0', second='0'], next run at: 2020-05-02 03:00:00)" to job store "default"
2020-05-01 12:03:23,471 - _real_add_job - 262 - INFO - Added job "OpenLog (trigger: cron[hour='0'], next run at: 2020-05-02 00:00:00)" to job store "default"
2020-05-01 12:03:23,471 - _main_loop - 574 - INFO - Scheduler started
2020-05-01 12:03:23,471 - _main_loop - 579 - DEBUG - Looking for jobs to run
2020-05-01 12:03:23,471 - _main_loop - 588 - DEBUG - Next wakeup is due at 2020-05-01 12:03:33.469253 (in 9.997565 seconds)
2020-05-01 12:03:23,483 - <module> - 63 - DEBUG - SendBefore_NotRecive : [<CNCProcessStatus: CNCProcessStatus object (2038721)>]
2020-05-01 12:03:23,483 - <module> - 64 - DEBUG - Waitfor_Recive : [2038721]
2020-05-01 12:03:33,470 - _main_loop - 579 - DEBUG - Looking for jobs to run
2020-05-01 12:03:33,471 - _run_jobs - 69 - DEBUG - Started worker thread
2020-05-01 12:03:33,471 - _run_job - 509 - INFO - Running job "regulartime_task (trigger: interval[1 day, 0:00:00], next run at: 2020-05-01 12:03:33.469253)" (scheduled at 2020-05-01 12:03:33.469253)
2020-05-01 12:03:33,471 - _main_loop - 588 - DEBUG - Next wakeup is due at 2020-05-02 00:00:00 (in 42986.528819 seconds)
2020-05-01 12:03:34,214 - _run_job - 520 - ERROR - Job "regulartime_task (trigger: interval[1 day, 0:00:00], next run at: 2020-05-02 12:03:33.469253)" raised an exception
Traceback (most recent call last):
  File "D:\Program Files\Python37\lib\site-packages\django\db\backends\utils.py", line 84, in _execute
    return self.cursor.execute(sql, params)
  File "D:\Program Files\Python37\lib\site-packages\django\db\backends\mysql\base.py", line 71, in execute
    return self.cursor.execute(query, args)
  File "D:\Program Files\Python37\lib\site-packages\MySQLdb\cursors.py", line 209, in execute
    res = self._query(query)
  File "D:\Program Files\Python37\lib\site-packages\MySQLdb\cursors.py", line 315, in _query
    db.query(q)
  File "D:\Program Files\Python37\lib\site-packages\MySQLdb\connections.py", line 239, in query
    _mysql.connection.query(self, query)
MySQLdb._exceptions.IntegrityError: (1062, "Duplicate entry '1588348800' for key 'LAMProcessData_process_r_acquisition_timestamp_a69ae90c_uniq'")

The above exception was the direct cause of the following exception:

Traceback (most recent call last):
  File "D:\Program Files\Python37\lib\site-packages\apscheduler\scheduler.py", line 512, in _run_job
    retval = job.func(*job.args, **job.kwargs)
  File "E:\1-program\11-LAMDataServer\lamdataserver\LAMProcessData\views.py", line 4988, in regulartime_task
    RT_FineData.Realtime_FineData.init_Tomorrow_rows()
  File "E:\1-program\11-LAMDataServer\lamdataserver\LAMProcessData\process_realtime_finedata.py", line 193, in init_Tomorrow_rows
    _model.objects.bulk_create(insert_data_list)
  File "D:\Program Files\Python37\lib\site-packages\django\db\models\manager.py", line 82, in manager_method
    return getattr(self.get_queryset(), name)(*args, **kwargs)
  File "D:\Program Files\Python37\lib\site-packages\django\db\models\query.py", line 474, in bulk_create
    ids = self._batched_insert(objs_without_pk, fields, batch_size, ignore_conflicts=ignore_conflicts)
  File "D:\Program Files\Python37\lib\site-packages\django\db\models\query.py", line 1211, in _batched_insert
    self._insert(item, fields=fields, using=self.db, ignore_conflicts=ignore_conflicts)
  File "D:\Program Files\Python37\lib\site-packages\django\db\models\query.py", line 1186, in _insert
    return query.get_compiler(using=using).execute_sql(return_id)
  File "D:\Program Files\Python37\lib\site-packages\django\db\models\sql\compiler.py", line 1332, in execute_sql
    cursor.execute(sql, params)
  File "D:\Program Files\Python37\lib\site-packages\django\db\backends\utils.py", line 99, in execute
    return super().execute(sql, params)
  File "D:\Program Files\Python37\lib\site-packages\django\db\backends\utils.py", line 67, in execute
    return self._execute_with_wrappers(sql, params, many=False, executor=self._execute)
  File "D:\Program Files\Python37\lib\site-packages\django\db\backends\utils.py", line 76, in _execute_with_wrappers
    return executor(sql, params, many, context)
  File "D:\Program Files\Python37\lib\site-packages\django\db\backends\utils.py", line 84, in _execute
    return self.cursor.execute(sql, params)
  File "D:\Program Files\Python37\lib\site-packages\django\db\utils.py", line 89, in __exit__
    raise dj_exc_value.with_traceback(traceback) from exc_value
  File "D:\Program Files\Python37\lib\site-packages\django\db\backends\utils.py", line 84, in _execute
    return self.cursor.execute(sql, params)
  File "D:\Program Files\Python37\lib\site-packages\django\db\backends\mysql\base.py", line 71, in execute
    return self.cursor.execute(query, args)
  File "D:\Program Files\Python37\lib\site-packages\MySQLdb\cursors.py", line 209, in execute
    res = self._query(query)
  File "D:\Program Files\Python37\lib\site-packages\MySQLdb\cursors.py", line 315, in _query
    db.query(q)
  File "D:\Program Files\Python37\lib\site-packages\MySQLdb\connections.py", line 239, in query
    _mysql.connection.query(self, query)
django.db.utils.IntegrityError: (1062, "Duplicate entry '1588348800' for key 'LAMProcessData_process_r_acquisition_timestamp_a69ae90c_uniq'")
2020-05-01 12:03:35,231 - _run_jobs - 94 - DEBUG - Exiting worker thread
2020-05-01 12:05:24,073 - _real_add_job - 262 - INFO - Added job "regulartime_task (trigger: interval[1 day, 0:00:00], next run at: 2020-05-01 12:05:34.072350)" to job store "default"
2020-05-01 12:05:24,074 - _real_add_job - 262 - INFO - Added job "cleanup (trigger: cron[day_of_week='*', hour='3', minute='0', second='0'], next run at: 2020-05-02 03:00:00)" to job store "default"
2020-05-01 12:05:24,074 - _real_add_job - 262 - INFO - Added job "OpenLog (trigger: cron[hour='0'], next run at: 2020-05-02 00:00:00)" to job store "default"
2020-05-01 12:05:24,074 - _main_loop - 574 - INFO - Scheduler started
2020-05-01 12:05:24,075 - _main_loop - 579 - DEBUG - Looking for jobs to run
2020-05-01 12:05:24,075 - _main_loop - 588 - DEBUG - Next wakeup is due at 2020-05-01 12:05:34.072350 (in 9.996825 seconds)
2020-05-01 12:05:24,087 - <module> - 63 - DEBUG - SendBefore_NotRecive : [<CNCProcessStatus: CNCProcessStatus object (2038721)>]
2020-05-01 12:05:24,087 - <module> - 64 - DEBUG - Waitfor_Recive : [2038721]
2020-05-01 12:05:34,086 - _main_loop - 579 - DEBUG - Looking for jobs to run
2020-05-01 12:05:34,088 - _run_jobs - 69 - DEBUG - Started worker thread
2020-05-01 12:05:34,088 - _run_job - 509 - INFO - Running job "regulartime_task (trigger: interval[1 day, 0:00:00], next run at: 2020-05-01 12:05:34.072350)" (scheduled at 2020-05-01 12:05:34.072350)
2020-05-01 12:05:34,089 - _main_loop - 588 - DEBUG - Next wakeup is due at 2020-05-02 00:00:00 (in 42865.912977 seconds)
2020-05-01 12:05:34,804 - _run_job - 520 - ERROR - Job "regulartime_task (trigger: interval[1 day, 0:00:00], next run at: 2020-05-02 12:05:34.072350)" raised an exception
Traceback (most recent call last):
  File "D:\Program Files\Python37\lib\site-packages\django\db\backends\utils.py", line 84, in _execute
    return self.cursor.execute(sql, params)
  File "D:\Program Files\Python37\lib\site-packages\django\db\backends\mysql\base.py", line 71, in execute
    return self.cursor.execute(query, args)
  File "D:\Program Files\Python37\lib\site-packages\MySQLdb\cursors.py", line 209, in execute
    res = self._query(query)
  File "D:\Program Files\Python37\lib\site-packages\MySQLdb\cursors.py", line 315, in _query
    db.query(q)
  File "D:\Program Files\Python37\lib\site-packages\MySQLdb\connections.py", line 239, in query
    _mysql.connection.query(self, query)
MySQLdb._exceptions.IntegrityError: (1062, "Duplicate entry '1588348800' for key 'LAMProcessData_process_r_acquisition_timestamp_a69ae90c_uniq'")

The above exception was the direct cause of the following exception:

Traceback (most recent call last):
  File "D:\Program Files\Python37\lib\site-packages\apscheduler\scheduler.py", line 512, in _run_job
    retval = job.func(*job.args, **job.kwargs)
  File "E:\1-program\11-LAMDataServer\lamdataserver\LAMProcessData\views.py", line 4988, in regulartime_task
    RT_FineData.Realtime_FineData.init_Tomorrow_rows()
  File "E:\1-program\11-LAMDataServer\lamdataserver\LAMProcessData\process_realtime_finedata.py", line 193, in init_Tomorrow_rows
    _model.objects.bulk_create(insert_data_list)
  File "D:\Program Files\Python37\lib\site-packages\django\db\models\manager.py", line 82, in manager_method
    return getattr(self.get_queryset(), name)(*args, **kwargs)
  File "D:\Program Files\Python37\lib\site-packages\django\db\models\query.py", line 474, in bulk_create
    ids = self._batched_insert(objs_without_pk, fields, batch_size, ignore_conflicts=ignore_conflicts)
  File "D:\Program Files\Python37\lib\site-packages\django\db\models\query.py", line 1211, in _batched_insert
    self._insert(item, fields=fields, using=self.db, ignore_conflicts=ignore_conflicts)
  File "D:\Program Files\Python37\lib\site-packages\django\db\models\query.py", line 1186, in _insert
    return query.get_compiler(using=using).execute_sql(return_id)
  File "D:\Program Files\Python37\lib\site-packages\django\db\models\sql\compiler.py", line 1332, in execute_sql
    cursor.execute(sql, params)
  File "D:\Program Files\Python37\lib\site-packages\django\db\backends\utils.py", line 99, in execute
    return super().execute(sql, params)
  File "D:\Program Files\Python37\lib\site-packages\django\db\backends\utils.py", line 67, in execute
    return self._execute_with_wrappers(sql, params, many=False, executor=self._execute)
  File "D:\Program Files\Python37\lib\site-packages\django\db\backends\utils.py", line 76, in _execute_with_wrappers
    return executor(sql, params, many, context)
  File "D:\Program Files\Python37\lib\site-packages\django\db\backends\utils.py", line 84, in _execute
    return self.cursor.execute(sql, params)
  File "D:\Program Files\Python37\lib\site-packages\django\db\utils.py", line 89, in __exit__
    raise dj_exc_value.with_traceback(traceback) from exc_value
  File "D:\Program Files\Python37\lib\site-packages\django\db\backends\utils.py", line 84, in _execute
    return self.cursor.execute(sql, params)
  File "D:\Program Files\Python37\lib\site-packages\django\db\backends\mysql\base.py", line 71, in execute
    return self.cursor.execute(query, args)
  File "D:\Program Files\Python37\lib\site-packages\MySQLdb\cursors.py", line 209, in execute
    res = self._query(query)
  File "D:\Program Files\Python37\lib\site-packages\MySQLdb\cursors.py", line 315, in _query
    db.query(q)
  File "D:\Program Files\Python37\lib\site-packages\MySQLdb\connections.py", line 239, in query
    _mysql.connection.query(self, query)
django.db.utils.IntegrityError: (1062, "Duplicate entry '1588348800' for key 'LAMProcessData_process_r_acquisition_timestamp_a69ae90c_uniq'")
2020-05-01 12:05:35,835 - _run_jobs - 94 - DEBUG - Exiting worker thread
2020-05-01 12:14:19,469 - _real_add_job - 262 - INFO - Added job "regulartime_task (trigger: interval[1 day, 0:00:00], next run at: 2020-05-01 12:14:29.467820)" to job store "default"
2020-05-01 12:14:19,469 - _real_add_job - 262 - INFO - Added job "cleanup (trigger: cron[day_of_week='*', hour='3', minute='0', second='0'], next run at: 2020-05-02 03:00:00)" to job store "default"
2020-05-01 12:14:19,469 - _real_add_job - 262 - INFO - Added job "OpenLog (trigger: cron[hour='0'], next run at: 2020-05-02 00:00:00)" to job store "default"
2020-05-01 12:14:19,469 - _main_loop - 574 - INFO - Scheduler started
2020-05-01 12:14:19,469 - _main_loop - 579 - DEBUG - Looking for jobs to run
2020-05-01 12:14:19,469 - _main_loop - 588 - DEBUG - Next wakeup is due at 2020-05-01 12:14:29.467820 (in 9.998025 seconds)
2020-05-01 12:14:19,484 - <module> - 63 - DEBUG - SendBefore_NotRecive : [<CNCProcessStatus: CNCProcessStatus object (2038721)>]
2020-05-01 12:14:19,484 - <module> - 64 - DEBUG - Waitfor_Recive : [2038721]
2020-05-01 12:14:29,469 - _main_loop - 579 - DEBUG - Looking for jobs to run
2020-05-01 12:14:29,471 - _run_jobs - 69 - DEBUG - Started worker thread
2020-05-01 12:14:29,472 - _main_loop - 588 - DEBUG - Next wakeup is due at 2020-05-02 00:00:00 (in 42330.529320 seconds)
2020-05-01 12:14:29,473 - _run_job - 509 - INFO - Running job "regulartime_task (trigger: interval[1 day, 0:00:00], next run at: 2020-05-02 12:14:29.467820)" (scheduled at 2020-05-01 12:14:29.467820)
2020-05-01 12:14:29,903 - _run_job - 520 - ERROR - Job "regulartime_task (trigger: interval[1 day, 0:00:00], next run at: 2020-05-02 12:14:29.467820)" raised an exception
Traceback (most recent call last):
  File "D:\Program Files\Python37\lib\site-packages\django\db\backends\utils.py", line 84, in _execute
    return self.cursor.execute(sql, params)
  File "D:\Program Files\Python37\lib\site-packages\django\db\backends\mysql\base.py", line 71, in execute
    return self.cursor.execute(query, args)
  File "D:\Program Files\Python37\lib\site-packages\MySQLdb\cursors.py", line 209, in execute
    res = self._query(query)
  File "D:\Program Files\Python37\lib\site-packages\MySQLdb\cursors.py", line 315, in _query
    db.query(q)
  File "D:\Program Files\Python37\lib\site-packages\MySQLdb\connections.py", line 239, in query
    _mysql.connection.query(self, query)
MySQLdb._exceptions.IntegrityError: (1062, "Duplicate entry '1588348800' for key 'LAMProcessData_process_r_acquisition_timestamp_a69ae90c_uniq'")

The above exception was the direct cause of the following exception:

Traceback (most recent call last):
  File "D:\Program Files\Python37\lib\site-packages\apscheduler\scheduler.py", line 512, in _run_job
    retval = job.func(*job.args, **job.kwargs)
  File "E:\1-program\11-LAMDataServer\lamdataserver\LAMProcessData\views.py", line 4988, in regulartime_task
    RT_FineData.Realtime_FineData.init_Tomorrow_rows()
  File "E:\1-program\11-LAMDataServer\lamdataserver\LAMProcessData\process_realtime_finedata.py", line 193, in init_Tomorrow_rows
    _model.objects.bulk_create(insert_data_list)
  File "D:\Program Files\Python37\lib\site-packages\django\db\models\manager.py", line 82, in manager_method
    return getattr(self.get_queryset(), name)(*args, **kwargs)
  File "D:\Program Files\Python37\lib\site-packages\django\db\models\query.py", line 474, in bulk_create
    ids = self._batched_insert(objs_without_pk, fields, batch_size, ignore_conflicts=ignore_conflicts)
  File "D:\Program Files\Python37\lib\site-packages\django\db\models\query.py", line 1211, in _batched_insert
    self._insert(item, fields=fields, using=self.db, ignore_conflicts=ignore_conflicts)
  File "D:\Program Files\Python37\lib\site-packages\django\db\models\query.py", line 1186, in _insert
    return query.get_compiler(using=using).execute_sql(return_id)
  File "D:\Program Files\Python37\lib\site-packages\django\db\models\sql\compiler.py", line 1332, in execute_sql
    cursor.execute(sql, params)
  File "D:\Program Files\Python37\lib\site-packages\django\db\backends\utils.py", line 99, in execute
    return super().execute(sql, params)
  File "D:\Program Files\Python37\lib\site-packages\django\db\backends\utils.py", line 67, in execute
    return self._execute_with_wrappers(sql, params, many=False, executor=self._execute)
  File "D:\Program Files\Python37\lib\site-packages\django\db\backends\utils.py", line 76, in _execute_with_wrappers
    return executor(sql, params, many, context)
  File "D:\Program Files\Python37\lib\site-packages\django\db\backends\utils.py", line 84, in _execute
    return self.cursor.execute(sql, params)
  File "D:\Program Files\Python37\lib\site-packages\django\db\utils.py", line 89, in __exit__
    raise dj_exc_value.with_traceback(traceback) from exc_value
  File "D:\Program Files\Python37\lib\site-packages\django\db\backends\utils.py", line 84, in _execute
    return self.cursor.execute(sql, params)
  File "D:\Program Files\Python37\lib\site-packages\django\db\backends\mysql\base.py", line 71, in execute
    return self.cursor.execute(query, args)
  File "D:\Program Files\Python37\lib\site-packages\MySQLdb\cursors.py", line 209, in execute
    res = self._query(query)
  File "D:\Program Files\Python37\lib\site-packages\MySQLdb\cursors.py", line 315, in _query
    db.query(q)
  File "D:\Program Files\Python37\lib\site-packages\MySQLdb\connections.py", line 239, in query
    _mysql.connection.query(self, query)
django.db.utils.IntegrityError: (1062, "Duplicate entry '1588348800' for key 'LAMProcessData_process_r_acquisition_timestamp_a69ae90c_uniq'")
2020-05-01 12:14:30,910 - _run_jobs - 94 - DEBUG - Exiting worker thread
2020-05-01 12:14:33,429 - trigger_reload - 203 - INFO - E:\1-program\11-LAMDataServer\lamdataserver\LAMProcessData\forms.py changed, reloading.
2020-05-01 12:14:33,429 - shutdown - 111 - INFO - Shutting down thread pool
2020-05-01 12:14:39,599 - _real_add_job - 262 - INFO - Added job "regulartime_task (trigger: interval[1 day, 0:00:00], next run at: 2020-05-01 12:14:49.597495)" to job store "default"
2020-05-01 12:14:39,599 - _real_add_job - 262 - INFO - Added job "cleanup (trigger: cron[day_of_week='*', hour='3', minute='0', second='0'], next run at: 2020-05-02 03:00:00)" to job store "default"
2020-05-01 12:14:39,599 - _real_add_job - 262 - INFO - Added job "OpenLog (trigger: cron[hour='0'], next run at: 2020-05-02 00:00:00)" to job store "default"
2020-05-01 12:14:39,599 - _main_loop - 574 - INFO - Scheduler started
2020-05-01 12:14:39,601 - _main_loop - 579 - DEBUG - Looking for jobs to run
2020-05-01 12:14:39,601 - _main_loop - 588 - DEBUG - Next wakeup is due at 2020-05-01 12:14:49.597495 (in 9.996456 seconds)
2020-05-01 12:14:39,614 - <module> - 63 - DEBUG - SendBefore_NotRecive : [<CNCProcessStatus: CNCProcessStatus object (2038721)>]
2020-05-01 12:14:39,615 - <module> - 64 - DEBUG - Waitfor_Recive : [2038721]
2020-05-01 12:14:49,599 - _main_loop - 579 - DEBUG - Looking for jobs to run
2020-05-01 12:14:49,601 - _run_jobs - 69 - DEBUG - Started worker thread
2020-05-01 12:14:49,601 - _run_job - 509 - INFO - Running job "regulartime_task (trigger: interval[1 day, 0:00:00], next run at: 2020-05-01 12:14:49.597495)" (scheduled at 2020-05-01 12:14:49.597495)
2020-05-01 12:14:49,602 - _main_loop - 588 - DEBUG - Next wakeup is due at 2020-05-02 00:00:00 (in 42310.400814 seconds)
2020-05-01 12:14:50,374 - _run_job - 520 - ERROR - Job "regulartime_task (trigger: interval[1 day, 0:00:00], next run at: 2020-05-02 12:14:49.597495)" raised an exception
Traceback (most recent call last):
  File "D:\Program Files\Python37\lib\site-packages\django\db\backends\utils.py", line 84, in _execute
    return self.cursor.execute(sql, params)
  File "D:\Program Files\Python37\lib\site-packages\django\db\backends\mysql\base.py", line 71, in execute
    return self.cursor.execute(query, args)
  File "D:\Program Files\Python37\lib\site-packages\MySQLdb\cursors.py", line 209, in execute
    res = self._query(query)
  File "D:\Program Files\Python37\lib\site-packages\MySQLdb\cursors.py", line 315, in _query
    db.query(q)
  File "D:\Program Files\Python37\lib\site-packages\MySQLdb\connections.py", line 239, in query
    _mysql.connection.query(self, query)
MySQLdb._exceptions.IntegrityError: (1062, "Duplicate entry '1588348800' for key 'LAMProcessData_process_r_acquisition_timestamp_a69ae90c_uniq'")

The above exception was the direct cause of the following exception:

Traceback (most recent call last):
  File "D:\Program Files\Python37\lib\site-packages\apscheduler\scheduler.py", line 512, in _run_job
    retval = job.func(*job.args, **job.kwargs)
  File "E:\1-program\11-LAMDataServer\lamdataserver\LAMProcessData\views.py", line 4988, in regulartime_task
    RT_FineData.Realtime_FineData.init_Tomorrow_rows()
  File "E:\1-program\11-LAMDataServer\lamdataserver\LAMProcessData\process_realtime_finedata.py", line 193, in init_Tomorrow_rows
    _model.objects.bulk_create(insert_data_list)
  File "D:\Program Files\Python37\lib\site-packages\django\db\models\manager.py", line 82, in manager_method
    return getattr(self.get_queryset(), name)(*args, **kwargs)
  File "D:\Program Files\Python37\lib\site-packages\django\db\models\query.py", line 474, in bulk_create
    ids = self._batched_insert(objs_without_pk, fields, batch_size, ignore_conflicts=ignore_conflicts)
  File "D:\Program Files\Python37\lib\site-packages\django\db\models\query.py", line 1211, in _batched_insert
    self._insert(item, fields=fields, using=self.db, ignore_conflicts=ignore_conflicts)
  File "D:\Program Files\Python37\lib\site-packages\django\db\models\query.py", line 1186, in _insert
    return query.get_compiler(using=using).execute_sql(return_id)
  File "D:\Program Files\Python37\lib\site-packages\django\db\models\sql\compiler.py", line 1332, in execute_sql
    cursor.execute(sql, params)
  File "D:\Program Files\Python37\lib\site-packages\django\db\backends\utils.py", line 99, in execute
    return super().execute(sql, params)
  File "D:\Program Files\Python37\lib\site-packages\django\db\backends\utils.py", line 67, in execute
    return self._execute_with_wrappers(sql, params, many=False, executor=self._execute)
  File "D:\Program Files\Python37\lib\site-packages\django\db\backends\utils.py", line 76, in _execute_with_wrappers
    return executor(sql, params, many, context)
  File "D:\Program Files\Python37\lib\site-packages\django\db\backends\utils.py", line 84, in _execute
    return self.cursor.execute(sql, params)
  File "D:\Program Files\Python37\lib\site-packages\django\db\utils.py", line 89, in __exit__
    raise dj_exc_value.with_traceback(traceback) from exc_value
  File "D:\Program Files\Python37\lib\site-packages\django\db\backends\utils.py", line 84, in _execute
    return self.cursor.execute(sql, params)
  File "D:\Program Files\Python37\lib\site-packages\django\db\backends\mysql\base.py", line 71, in execute
    return self.cursor.execute(query, args)
  File "D:\Program Files\Python37\lib\site-packages\MySQLdb\cursors.py", line 209, in execute
    res = self._query(query)
  File "D:\Program Files\Python37\lib\site-packages\MySQLdb\cursors.py", line 315, in _query
    db.query(q)
  File "D:\Program Files\Python37\lib\site-packages\MySQLdb\connections.py", line 239, in query
    _mysql.connection.query(self, query)
django.db.utils.IntegrityError: (1062, "Duplicate entry '1588348800' for key 'LAMProcessData_process_r_acquisition_timestamp_a69ae90c_uniq'")
2020-05-01 12:14:51,390 - _run_jobs - 94 - DEBUG - Exiting worker thread
2020-05-01 12:18:11,325 - log_response - 228 - WARNING - Not Found: /LAMProcessData/InspectionRecords/PhysicochemicalTest/AddChemicalElement/1
2020-05-01 12:20:15,814 - _real_add_job - 262 - INFO - Added job "regulartime_task (trigger: interval[1 day, 0:00:00], next run at: 2020-05-01 12:20:25.813741)" to job store "default"
2020-05-01 12:20:15,815 - _real_add_job - 262 - INFO - Added job "cleanup (trigger: cron[day_of_week='*', hour='3', minute='0', second='0'], next run at: 2020-05-02 03:00:00)" to job store "default"
2020-05-01 12:20:15,815 - _real_add_job - 262 - INFO - Added job "OpenLog (trigger: cron[hour='0'], next run at: 2020-05-02 00:00:00)" to job store "default"
2020-05-01 12:20:15,815 - _main_loop - 574 - INFO - Scheduler started
2020-05-01 12:20:15,816 - _main_loop - 579 - DEBUG - Looking for jobs to run
2020-05-01 12:20:15,816 - _main_loop - 588 - DEBUG - Next wakeup is due at 2020-05-01 12:20:25.813741 (in 9.997008 seconds)
2020-05-01 12:20:15,827 - <module> - 63 - DEBUG - SendBefore_NotRecive : [<CNCProcessStatus: CNCProcessStatus object (2038721)>]
2020-05-01 12:20:15,827 - <module> - 64 - DEBUG - Waitfor_Recive : [2038721]
2020-05-01 12:20:25,815 - _main_loop - 579 - DEBUG - Looking for jobs to run
2020-05-01 12:20:25,815 - _run_jobs - 69 - DEBUG - Started worker thread
2020-05-01 12:20:25,816 - _run_job - 509 - INFO - Running job "regulartime_task (trigger: interval[1 day, 0:00:00], next run at: 2020-05-01 12:20:25.813741)" (scheduled at 2020-05-01 12:20:25.813741)
2020-05-01 12:20:25,816 - _main_loop - 588 - DEBUG - Next wakeup is due at 2020-05-02 00:00:00 (in 41974.184554 seconds)
2020-05-01 12:20:26,196 - _run_job - 520 - ERROR - Job "regulartime_task (trigger: interval[1 day, 0:00:00], next run at: 2020-05-02 12:20:25.813741)" raised an exception
Traceback (most recent call last):
  File "D:\Program Files\Python37\lib\site-packages\django\db\backends\utils.py", line 84, in _execute
    return self.cursor.execute(sql, params)
  File "D:\Program Files\Python37\lib\site-packages\django\db\backends\mysql\base.py", line 71, in execute
    return self.cursor.execute(query, args)
  File "D:\Program Files\Python37\lib\site-packages\MySQLdb\cursors.py", line 209, in execute
    res = self._query(query)
  File "D:\Program Files\Python37\lib\site-packages\MySQLdb\cursors.py", line 315, in _query
    db.query(q)
  File "D:\Program Files\Python37\lib\site-packages\MySQLdb\connections.py", line 239, in query
    _mysql.connection.query(self, query)
MySQLdb._exceptions.IntegrityError: (1062, "Duplicate entry '1588348800' for key 'LAMProcessData_process_r_acquisition_timestamp_a69ae90c_uniq'")

The above exception was the direct cause of the following exception:

Traceback (most recent call last):
  File "D:\Program Files\Python37\lib\site-packages\apscheduler\scheduler.py", line 512, in _run_job
    retval = job.func(*job.args, **job.kwargs)
  File "E:\1-program\11-LAMDataServer\lamdataserver\LAMProcessData\views.py", line 4988, in regulartime_task
    RT_FineData.Realtime_FineData.init_Tomorrow_rows()
  File "E:\1-program\11-LAMDataServer\lamdataserver\LAMProcessData\process_realtime_finedata.py", line 193, in init_Tomorrow_rows
    _model.objects.bulk_create(insert_data_list)
  File "D:\Program Files\Python37\lib\site-packages\django\db\models\manager.py", line 82, in manager_method
    return getattr(self.get_queryset(), name)(*args, **kwargs)
  File "D:\Program Files\Python37\lib\site-packages\django\db\models\query.py", line 474, in bulk_create
    ids = self._batched_insert(objs_without_pk, fields, batch_size, ignore_conflicts=ignore_conflicts)
  File "D:\Program Files\Python37\lib\site-packages\django\db\models\query.py", line 1211, in _batched_insert
    self._insert(item, fields=fields, using=self.db, ignore_conflicts=ignore_conflicts)
  File "D:\Program Files\Python37\lib\site-packages\django\db\models\query.py", line 1186, in _insert
    return query.get_compiler(using=using).execute_sql(return_id)
  File "D:\Program Files\Python37\lib\site-packages\django\db\models\sql\compiler.py", line 1332, in execute_sql
    cursor.execute(sql, params)
  File "D:\Program Files\Python37\lib\site-packages\django\db\backends\utils.py", line 99, in execute
    return super().execute(sql, params)
  File "D:\Program Files\Python37\lib\site-packages\django\db\backends\utils.py", line 67, in execute
    return self._execute_with_wrappers(sql, params, many=False, executor=self._execute)
  File "D:\Program Files\Python37\lib\site-packages\django\db\backends\utils.py", line 76, in _execute_with_wrappers
    return executor(sql, params, many, context)
  File "D:\Program Files\Python37\lib\site-packages\django\db\backends\utils.py", line 84, in _execute
    return self.cursor.execute(sql, params)
  File "D:\Program Files\Python37\lib\site-packages\django\db\utils.py", line 89, in __exit__
    raise dj_exc_value.with_traceback(traceback) from exc_value
  File "D:\Program Files\Python37\lib\site-packages\django\db\backends\utils.py", line 84, in _execute
    return self.cursor.execute(sql, params)
  File "D:\Program Files\Python37\lib\site-packages\django\db\backends\mysql\base.py", line 71, in execute
    return self.cursor.execute(query, args)
  File "D:\Program Files\Python37\lib\site-packages\MySQLdb\cursors.py", line 209, in execute
    res = self._query(query)
  File "D:\Program Files\Python37\lib\site-packages\MySQLdb\cursors.py", line 315, in _query
    db.query(q)
  File "D:\Program Files\Python37\lib\site-packages\MySQLdb\connections.py", line 239, in query
    _mysql.connection.query(self, query)
django.db.utils.IntegrityError: (1062, "Duplicate entry '1588348800' for key 'LAMProcessData_process_r_acquisition_timestamp_a69ae90c_uniq'")
2020-05-01 12:20:27,201 - _run_jobs - 94 - DEBUG - Exiting worker thread
2020-05-01 23:10:54,518 - _real_add_job - 262 - INFO - Added job "regulartime_task (trigger: interval[1 day, 0:00:00], next run at: 2020-05-01 23:11:04.515651)" to job store "default"
2020-05-01 23:10:54,518 - _real_add_job - 262 - INFO - Added job "cleanup (trigger: cron[day_of_week='*', hour='3', minute='0', second='0'], next run at: 2020-05-02 03:00:00)" to job store "default"
2020-05-01 23:10:54,518 - _real_add_job - 262 - INFO - Added job "OpenLog (trigger: cron[hour='0'], next run at: 2020-05-02 00:00:00)" to job store "default"
2020-05-01 23:10:54,519 - _main_loop - 574 - INFO - Scheduler started
2020-05-01 23:10:54,520 - _main_loop - 579 - DEBUG - Looking for jobs to run
2020-05-01 23:10:54,520 - _main_loop - 588 - DEBUG - Next wakeup is due at 2020-05-01 23:11:04.515651 (in 9.995014 seconds)
2020-05-01 23:10:54,542 - <module> - 63 - DEBUG - SendBefore_NotRecive : [<CNCProcessStatus: CNCProcessStatus object (2038721)>]
2020-05-01 23:10:54,543 - <module> - 64 - DEBUG - Waitfor_Recive : [2038721]
2020-05-01 23:11:04,516 - _main_loop - 579 - DEBUG - Looking for jobs to run
2020-05-01 23:11:04,516 - _run_jobs - 69 - DEBUG - Started worker thread
2020-05-01 23:11:04,517 - _run_job - 509 - INFO - Running job "regulartime_task (trigger: interval[1 day, 0:00:00], next run at: 2020-05-01 23:11:04.515651)" (scheduled at 2020-05-01 23:11:04.515651)
2020-05-01 23:11:04,517 - _main_loop - 588 - DEBUG - Next wakeup is due at 2020-05-02 00:00:00 (in 2935.483111 seconds)
2020-05-01 23:11:04,843 - _run_job - 520 - ERROR - Job "regulartime_task (trigger: interval[1 day, 0:00:00], next run at: 2020-05-02 23:11:04.515651)" raised an exception
Traceback (most recent call last):
  File "D:\Program Files\Python37\lib\site-packages\django\db\backends\utils.py", line 84, in _execute
    return self.cursor.execute(sql, params)
  File "D:\Program Files\Python37\lib\site-packages\django\db\backends\mysql\base.py", line 71, in execute
    return self.cursor.execute(query, args)
  File "D:\Program Files\Python37\lib\site-packages\MySQLdb\cursors.py", line 209, in execute
    res = self._query(query)
  File "D:\Program Files\Python37\lib\site-packages\MySQLdb\cursors.py", line 315, in _query
    db.query(q)
  File "D:\Program Files\Python37\lib\site-packages\MySQLdb\connections.py", line 239, in query
    _mysql.connection.query(self, query)
MySQLdb._exceptions.IntegrityError: (1062, "Duplicate entry '1588348800' for key 'LAMProcessData_process_r_acquisition_timestamp_a69ae90c_uniq'")

The above exception was the direct cause of the following exception:

Traceback (most recent call last):
  File "D:\Program Files\Python37\lib\site-packages\apscheduler\scheduler.py", line 512, in _run_job
    retval = job.func(*job.args, **job.kwargs)
  File "E:\1-program\11-LAMDataServer\lamdataserver\LAMProcessData\views.py", line 4988, in regulartime_task
    RT_FineData.Realtime_FineData.init_Tomorrow_rows()
  File "E:\1-program\11-LAMDataServer\lamdataserver\LAMProcessData\process_realtime_finedata.py", line 193, in init_Tomorrow_rows
    _model.objects.bulk_create(insert_data_list)
  File "D:\Program Files\Python37\lib\site-packages\django\db\models\manager.py", line 82, in manager_method
    return getattr(self.get_queryset(), name)(*args, **kwargs)
  File "D:\Program Files\Python37\lib\site-packages\django\db\models\query.py", line 474, in bulk_create
    ids = self._batched_insert(objs_without_pk, fields, batch_size, ignore_conflicts=ignore_conflicts)
  File "D:\Program Files\Python37\lib\site-packages\django\db\models\query.py", line 1211, in _batched_insert
    self._insert(item, fields=fields, using=self.db, ignore_conflicts=ignore_conflicts)
  File "D:\Program Files\Python37\lib\site-packages\django\db\models\query.py", line 1186, in _insert
    return query.get_compiler(using=using).execute_sql(return_id)
  File "D:\Program Files\Python37\lib\site-packages\django\db\models\sql\compiler.py", line 1332, in execute_sql
    cursor.execute(sql, params)
  File "D:\Program Files\Python37\lib\site-packages\django\db\backends\utils.py", line 99, in execute
    return super().execute(sql, params)
  File "D:\Program Files\Python37\lib\site-packages\django\db\backends\utils.py", line 67, in execute
    return self._execute_with_wrappers(sql, params, many=False, executor=self._execute)
  File "D:\Program Files\Python37\lib\site-packages\django\db\backends\utils.py", line 76, in _execute_with_wrappers
    return executor(sql, params, many, context)
  File "D:\Program Files\Python37\lib\site-packages\django\db\backends\utils.py", line 84, in _execute
    return self.cursor.execute(sql, params)
  File "D:\Program Files\Python37\lib\site-packages\django\db\utils.py", line 89, in __exit__
    raise dj_exc_value.with_traceback(traceback) from exc_value
  File "D:\Program Files\Python37\lib\site-packages\django\db\backends\utils.py", line 84, in _execute
    return self.cursor.execute(sql, params)
  File "D:\Program Files\Python37\lib\site-packages\django\db\backends\mysql\base.py", line 71, in execute
    return self.cursor.execute(query, args)
  File "D:\Program Files\Python37\lib\site-packages\MySQLdb\cursors.py", line 209, in execute
    res = self._query(query)
  File "D:\Program Files\Python37\lib\site-packages\MySQLdb\cursors.py", line 315, in _query
    db.query(q)
  File "D:\Program Files\Python37\lib\site-packages\MySQLdb\connections.py", line 239, in query
    _mysql.connection.query(self, query)
django.db.utils.IntegrityError: (1062, "Duplicate entry '1588348800' for key 'LAMProcessData_process_r_acquisition_timestamp_a69ae90c_uniq'")
2020-05-01 23:11:05,854 - _run_jobs - 94 - DEBUG - Exiting worker thread
2020-05-01 23:20:19,969 - _real_add_job - 262 - INFO - Added job "regulartime_task (trigger: interval[1 day, 0:00:00], next run at: 2020-05-01 23:20:29.966507)" to job store "default"
2020-05-01 23:20:19,969 - _real_add_job - 262 - INFO - Added job "cleanup (trigger: cron[day_of_week='*', hour='3', minute='0', second='0'], next run at: 2020-05-02 03:00:00)" to job store "default"
2020-05-01 23:20:19,970 - _real_add_job - 262 - INFO - Added job "OpenLog (trigger: cron[hour='0'], next run at: 2020-05-02 00:00:00)" to job store "default"
2020-05-01 23:20:19,971 - _main_loop - 574 - INFO - Scheduler started
2020-05-01 23:20:19,971 - _main_loop - 579 - DEBUG - Looking for jobs to run
2020-05-01 23:20:19,971 - _main_loop - 588 - DEBUG - Next wakeup is due at 2020-05-01 23:20:29.966507 (in 9.995018 seconds)
2020-05-01 23:20:19,984 - <module> - 63 - DEBUG - SendBefore_NotRecive : [<CNCProcessStatus: CNCProcessStatus object (2038721)>]
2020-05-01 23:20:19,984 - <module> - 64 - DEBUG - Waitfor_Recive : [2038721]
2020-05-01 23:20:29,968 - _main_loop - 579 - DEBUG - Looking for jobs to run
2020-05-01 23:20:29,970 - _run_jobs - 69 - DEBUG - Started worker thread
2020-05-01 23:20:29,970 - _main_loop - 588 - DEBUG - Next wakeup is due at 2020-05-02 00:00:00 (in 2370.031016 seconds)
2020-05-01 23:20:29,970 - _run_job - 509 - INFO - Running job "regulartime_task (trigger: interval[1 day, 0:00:00], next run at: 2020-05-02 23:20:29.966507)" (scheduled at 2020-05-01 23:20:29.966507)
2020-05-01 23:20:30,984 - _run_job - 520 - ERROR - Job "regulartime_task (trigger: interval[1 day, 0:00:00], next run at: 2020-05-02 23:20:29.966507)" raised an exception
Traceback (most recent call last):
  File "D:\Program Files\Python37\lib\site-packages\django\db\backends\utils.py", line 84, in _execute
    return self.cursor.execute(sql, params)
  File "D:\Program Files\Python37\lib\site-packages\django\db\backends\mysql\base.py", line 71, in execute
    return self.cursor.execute(query, args)
  File "D:\Program Files\Python37\lib\site-packages\MySQLdb\cursors.py", line 209, in execute
    res = self._query(query)
  File "D:\Program Files\Python37\lib\site-packages\MySQLdb\cursors.py", line 315, in _query
    db.query(q)
  File "D:\Program Files\Python37\lib\site-packages\MySQLdb\connections.py", line 239, in query
    _mysql.connection.query(self, query)
MySQLdb._exceptions.IntegrityError: (1062, "Duplicate entry '1588348800' for key 'LAMProcessData_process_r_acquisition_timestamp_a69ae90c_uniq'")

The above exception was the direct cause of the following exception:

Traceback (most recent call last):
  File "D:\Program Files\Python37\lib\site-packages\apscheduler\scheduler.py", line 512, in _run_job
    retval = job.func(*job.args, **job.kwargs)
  File "E:\1-program\11-LAMDataServer\lamdataserver\LAMProcessData\views.py", line 4988, in regulartime_task
    RT_FineData.Realtime_FineData.init_Tomorrow_rows()
  File "E:\1-program\11-LAMDataServer\lamdataserver\LAMProcessData\process_realtime_finedata.py", line 193, in init_Tomorrow_rows
    _model.objects.bulk_create(insert_data_list)
  File "D:\Program Files\Python37\lib\site-packages\django\db\models\manager.py", line 82, in manager_method
    return getattr(self.get_queryset(), name)(*args, **kwargs)
  File "D:\Program Files\Python37\lib\site-packages\django\db\models\query.py", line 474, in bulk_create
    ids = self._batched_insert(objs_without_pk, fields, batch_size, ignore_conflicts=ignore_conflicts)
  File "D:\Program Files\Python37\lib\site-packages\django\db\models\query.py", line 1211, in _batched_insert
    self._insert(item, fields=fields, using=self.db, ignore_conflicts=ignore_conflicts)
  File "D:\Program Files\Python37\lib\site-packages\django\db\models\query.py", line 1186, in _insert
    return query.get_compiler(using=using).execute_sql(return_id)
  File "D:\Program Files\Python37\lib\site-packages\django\db\models\sql\compiler.py", line 1332, in execute_sql
    cursor.execute(sql, params)
  File "D:\Program Files\Python37\lib\site-packages\django\db\backends\utils.py", line 99, in execute
    return super().execute(sql, params)
  File "D:\Program Files\Python37\lib\site-packages\django\db\backends\utils.py", line 67, in execute
    return self._execute_with_wrappers(sql, params, many=False, executor=self._execute)
  File "D:\Program Files\Python37\lib\site-packages\django\db\backends\utils.py", line 76, in _execute_with_wrappers
    return executor(sql, params, many, context)
  File "D:\Program Files\Python37\lib\site-packages\django\db\backends\utils.py", line 84, in _execute
    return self.cursor.execute(sql, params)
  File "D:\Program Files\Python37\lib\site-packages\django\db\utils.py", line 89, in __exit__
    raise dj_exc_value.with_traceback(traceback) from exc_value
  File "D:\Program Files\Python37\lib\site-packages\django\db\backends\utils.py", line 84, in _execute
    return self.cursor.execute(sql, params)
  File "D:\Program Files\Python37\lib\site-packages\django\db\backends\mysql\base.py", line 71, in execute
    return self.cursor.execute(query, args)
  File "D:\Program Files\Python37\lib\site-packages\MySQLdb\cursors.py", line 209, in execute
    res = self._query(query)
  File "D:\Program Files\Python37\lib\site-packages\MySQLdb\cursors.py", line 315, in _query
    db.query(q)
  File "D:\Program Files\Python37\lib\site-packages\MySQLdb\connections.py", line 239, in query
    _mysql.connection.query(self, query)
django.db.utils.IntegrityError: (1062, "Duplicate entry '1588348800' for key 'LAMProcessData_process_r_acquisition_timestamp_a69ae90c_uniq'")
2020-05-01 23:20:31,995 - _run_jobs - 94 - DEBUG - Exiting worker thread
2020-05-01 23:27:47,013 - _real_add_job - 262 - INFO - Added job "regulartime_task (trigger: interval[1 day, 0:00:00], next run at: 2020-05-01 23:27:57.010036)" to job store "default"
2020-05-01 23:27:47,013 - _real_add_job - 262 - INFO - Added job "cleanup (trigger: cron[day_of_week='*', hour='3', minute='0', second='0'], next run at: 2020-05-02 03:00:00)" to job store "default"
2020-05-01 23:27:47,014 - _real_add_job - 262 - INFO - Added job "OpenLog (trigger: cron[hour='0'], next run at: 2020-05-02 00:00:00)" to job store "default"
2020-05-01 23:27:47,015 - _main_loop - 574 - INFO - Scheduler started
2020-05-01 23:27:47,015 - _main_loop - 579 - DEBUG - Looking for jobs to run
2020-05-01 23:27:47,016 - _main_loop - 588 - DEBUG - Next wakeup is due at 2020-05-01 23:27:57.010036 (in 9.994016 seconds)
2020-05-01 23:27:47,027 - <module> - 63 - DEBUG - SendBefore_NotRecive : [<CNCProcessStatus: CNCProcessStatus object (2038721)>]
2020-05-01 23:27:47,027 - <module> - 64 - DEBUG - Waitfor_Recive : [2038721]
2020-05-01 23:27:57,022 - _main_loop - 579 - DEBUG - Looking for jobs to run
2020-05-01 23:27:57,025 - _run_jobs - 69 - DEBUG - Started worker thread
2020-05-01 23:27:57,026 - _main_loop - 588 - DEBUG - Next wakeup is due at 2020-05-02 00:00:00 (in 1922.977112 seconds)
2020-05-01 23:27:57,027 - _run_job - 509 - INFO - Running job "regulartime_task (trigger: interval[1 day, 0:00:00], next run at: 2020-05-02 23:27:57.010036)" (scheduled at 2020-05-01 23:27:57.010036)
2020-05-01 23:27:58,013 - _run_job - 520 - ERROR - Job "regulartime_task (trigger: interval[1 day, 0:00:00], next run at: 2020-05-02 23:27:57.010036)" raised an exception
Traceback (most recent call last):
  File "D:\Program Files\Python37\lib\site-packages\django\db\backends\utils.py", line 84, in _execute
    return self.cursor.execute(sql, params)
  File "D:\Program Files\Python37\lib\site-packages\django\db\backends\mysql\base.py", line 71, in execute
    return self.cursor.execute(query, args)
  File "D:\Program Files\Python37\lib\site-packages\MySQLdb\cursors.py", line 209, in execute
    res = self._query(query)
  File "D:\Program Files\Python37\lib\site-packages\MySQLdb\cursors.py", line 315, in _query
    db.query(q)
  File "D:\Program Files\Python37\lib\site-packages\MySQLdb\connections.py", line 239, in query
    _mysql.connection.query(self, query)
MySQLdb._exceptions.IntegrityError: (1062, "Duplicate entry '1588348800' for key 'LAMProcessData_process_r_acquisition_timestamp_a69ae90c_uniq'")

The above exception was the direct cause of the following exception:

Traceback (most recent call last):
  File "D:\Program Files\Python37\lib\site-packages\apscheduler\scheduler.py", line 512, in _run_job
    retval = job.func(*job.args, **job.kwargs)
  File "E:\1-program\11-LAMDataServer\lamdataserver\LAMProcessData\views.py", line 4988, in regulartime_task
    RT_FineData.Realtime_FineData.init_Tomorrow_rows()
  File "E:\1-program\11-LAMDataServer\lamdataserver\LAMProcessData\process_realtime_finedata.py", line 193, in init_Tomorrow_rows
    _model.objects.bulk_create(insert_data_list)
  File "D:\Program Files\Python37\lib\site-packages\django\db\models\manager.py", line 82, in manager_method
    return getattr(self.get_queryset(), name)(*args, **kwargs)
  File "D:\Program Files\Python37\lib\site-packages\django\db\models\query.py", line 474, in bulk_create
    ids = self._batched_insert(objs_without_pk, fields, batch_size, ignore_conflicts=ignore_conflicts)
  File "D:\Program Files\Python37\lib\site-packages\django\db\models\query.py", line 1211, in _batched_insert
    self._insert(item, fields=fields, using=self.db, ignore_conflicts=ignore_conflicts)
  File "D:\Program Files\Python37\lib\site-packages\django\db\models\query.py", line 1186, in _insert
    return query.get_compiler(using=using).execute_sql(return_id)
  File "D:\Program Files\Python37\lib\site-packages\django\db\models\sql\compiler.py", line 1332, in execute_sql
    cursor.execute(sql, params)
  File "D:\Program Files\Python37\lib\site-packages\django\db\backends\utils.py", line 99, in execute
    return super().execute(sql, params)
  File "D:\Program Files\Python37\lib\site-packages\django\db\backends\utils.py", line 67, in execute
    return self._execute_with_wrappers(sql, params, many=False, executor=self._execute)
  File "D:\Program Files\Python37\lib\site-packages\django\db\backends\utils.py", line 76, in _execute_with_wrappers
    return executor(sql, params, many, context)
  File "D:\Program Files\Python37\lib\site-packages\django\db\backends\utils.py", line 84, in _execute
    return self.cursor.execute(sql, params)
  File "D:\Program Files\Python37\lib\site-packages\django\db\utils.py", line 89, in __exit__
    raise dj_exc_value.with_traceback(traceback) from exc_value
  File "D:\Program Files\Python37\lib\site-packages\django\db\backends\utils.py", line 84, in _execute
    return self.cursor.execute(sql, params)
  File "D:\Program Files\Python37\lib\site-packages\django\db\backends\mysql\base.py", line 71, in execute
    return self.cursor.execute(query, args)
  File "D:\Program Files\Python37\lib\site-packages\MySQLdb\cursors.py", line 209, in execute
    res = self._query(query)
  File "D:\Program Files\Python37\lib\site-packages\MySQLdb\cursors.py", line 315, in _query
    db.query(q)
  File "D:\Program Files\Python37\lib\site-packages\MySQLdb\connections.py", line 239, in query
    _mysql.connection.query(self, query)
django.db.utils.IntegrityError: (1062, "Duplicate entry '1588348800' for key 'LAMProcessData_process_r_acquisition_timestamp_a69ae90c_uniq'")
2020-05-01 23:27:59,024 - _run_jobs - 94 - DEBUG - Exiting worker thread
