2020-06-11 23:11:39,187 - _real_add_job - 262 - INFO - Added job "regulartime_task (trigger: interval[1 day, 0:00:00], next run at: 2020-06-11 23:11:49.187244)" to job store "default"
2020-06-11 23:11:39,187 - _real_add_job - 262 - INFO - Added job "cleanup (trigger: cron[day_of_week='*', hour='3', minute='0', second='0'], next run at: 2020-06-12 03:00:00)" to job store "default"
2020-06-11 23:11:39,187 - _real_add_job - 262 - INFO - Added job "OpenLog (trigger: cron[hour='0'], next run at: 2020-06-12 00:00:00)" to job store "default"
2020-06-11 23:11:39,187 - _main_loop - 574 - INFO - Scheduler started
2020-06-11 23:11:39,187 - _main_loop - 579 - DEBUG - Looking for jobs to run
2020-06-11 23:11:39,187 - _main_loop - 588 - DEBUG - Next wakeup is due at 2020-06-11 23:11:49.187244 (in 10.000000 seconds)
2020-06-11 23:11:39,217 - <module> - 63 - DEBUG - SendBefore_NotRecive : [<CNCProcessStatus: CNCProcessStatus object (2038721)>]
2020-06-11 23:11:39,217 - <module> - 64 - DEBUG - Waitfor_Recive : [2038721]
2020-06-11 23:11:43,994 - log_response - 228 - WARNING - Not Found: /favicon.ico
2020-06-11 23:11:44,546 - log_response - 228 - WARNING - Not Found: /favicon.ico
2020-06-11 23:11:45,148 - log_response - 228 - WARNING - Not Found: /favicon.ico
2020-06-11 23:11:45,765 - log_response - 228 - WARNING - Not Found: /favicon.ico
2020-06-11 23:11:49,197 - _main_loop - 579 - DEBUG - Looking for jobs to run
2020-06-11 23:11:49,197 - _run_jobs - 69 - DEBUG - Started worker thread
2020-06-11 23:11:49,197 - _main_loop - 588 - DEBUG - Next wakeup is due at 2020-06-12 00:00:00 (in 2890.802433 seconds)
2020-06-11 23:11:49,197 - _run_job - 509 - INFO - Running job "regulartime_task (trigger: interval[1 day, 0:00:00], next run at: 2020-06-12 23:11:49.187244)" (scheduled at 2020-06-11 23:11:49.187244)
2020-06-11 23:11:49,985 - _run_job - 520 - ERROR - Job "regulartime_task (trigger: interval[1 day, 0:00:00], next run at: 2020-06-12 23:11:49.187244)" raised an exception
Traceback (most recent call last):
  File "D:\Program Files\Python37\lib\site-packages\django\db\backends\mysql\base.py", line 71, in execute
    return self.cursor.execute(query, args)
  File "D:\Program Files\Python37\lib\site-packages\MySQLdb\cursors.py", line 209, in execute
    res = self._query(query)
  File "D:\Program Files\Python37\lib\site-packages\MySQLdb\cursors.py", line 315, in _query
    db.query(q)
  File "D:\Program Files\Python37\lib\site-packages\MySQLdb\connections.py", line 239, in query
    _mysql.connection.query(self, query)
MySQLdb._exceptions.OperationalError: (1048, "Column 'laser_power' cannot be null")

During handling of the above exception, another exception occurred:

Traceback (most recent call last):
  File "D:\Program Files\Python37\lib\site-packages\apscheduler\scheduler.py", line 512, in _run_job
    retval = job.func(*job.args, **job.kwargs)
  File "E:\1-program\11-LAMDataServer\lamdataserver\LAMProcessData\views.py", line 5661, in regulartime_task
    RT_FineData.Realtime_FineData.init_Tomorrow_rows()
  File "E:\1-program\11-LAMDataServer\lamdataserver\LAMProcessData\process_realtime_finedata.py", line 193, in init_Tomorrow_rows
    _model.objects.bulk_create(insert_data_list)
  File "D:\Program Files\Python37\lib\site-packages\django\db\models\manager.py", line 82, in manager_method
    return getattr(self.get_queryset(), name)(*args, **kwargs)
  File "D:\Program Files\Python37\lib\site-packages\django\db\models\query.py", line 474, in bulk_create
    ids = self._batched_insert(objs_without_pk, fields, batch_size, ignore_conflicts=ignore_conflicts)
  File "D:\Program Files\Python37\lib\site-packages\django\db\models\query.py", line 1211, in _batched_insert
    self._insert(item, fields=fields, using=self.db, ignore_conflicts=ignore_conflicts)
  File "D:\Program Files\Python37\lib\site-packages\django\db\models\query.py", line 1186, in _insert
    return query.get_compiler(using=using).execute_sql(return_id)
  File "D:\Program Files\Python37\lib\site-packages\django\db\models\sql\compiler.py", line 1332, in execute_sql
    cursor.execute(sql, params)
  File "D:\Program Files\Python37\lib\site-packages\django\db\backends\utils.py", line 99, in execute
    return super().execute(sql, params)
  File "D:\Program Files\Python37\lib\site-packages\django\db\backends\utils.py", line 67, in execute
    return self._execute_with_wrappers(sql, params, many=False, executor=self._execute)
  File "D:\Program Files\Python37\lib\site-packages\django\db\backends\utils.py", line 76, in _execute_with_wrappers
    return executor(sql, params, many, context)
  File "D:\Program Files\Python37\lib\site-packages\django\db\backends\utils.py", line 84, in _execute
    return self.cursor.execute(sql, params)
  File "D:\Program Files\Python37\lib\site-packages\django\db\backends\mysql\base.py", line 76, in execute
    raise utils.IntegrityError(*tuple(e.args))
django.db.utils.IntegrityError: (1048, "Column 'laser_power' cannot be null")
2020-06-11 23:11:51,002 - _run_jobs - 94 - DEBUG - Exiting worker thread
2020-06-11 23:37:18,196 - _real_add_job - 262 - INFO - Added job "regulartime_task (trigger: interval[1 day, 0:00:00], next run at: 2020-06-11 23:37:28.194728)" to job store "default"
2020-06-11 23:37:18,196 - _real_add_job - 262 - INFO - Added job "cleanup (trigger: cron[day_of_week='*', hour='3', minute='0', second='0'], next run at: 2020-06-12 03:00:00)" to job store "default"
2020-06-11 23:37:18,196 - _real_add_job - 262 - INFO - Added job "OpenLog (trigger: cron[hour='0'], next run at: 2020-06-12 00:00:00)" to job store "default"
2020-06-11 23:37:18,197 - _main_loop - 574 - INFO - Scheduler started
2020-06-11 23:37:18,197 - _main_loop - 579 - DEBUG - Looking for jobs to run
2020-06-11 23:37:18,197 - _main_loop - 588 - DEBUG - Next wakeup is due at 2020-06-11 23:37:28.194728 (in 9.997009 seconds)
2020-06-11 23:37:18,207 - <module> - 63 - DEBUG - SendBefore_NotRecive : [<CNCProcessStatus: CNCProcessStatus object (2038721)>]
2020-06-11 23:37:18,207 - <module> - 64 - DEBUG - Waitfor_Recive : [2038721]
2020-06-11 23:37:28,196 - _main_loop - 579 - DEBUG - Looking for jobs to run
2020-06-11 23:37:28,196 - _run_jobs - 69 - DEBUG - Started worker thread
2020-06-11 23:37:28,197 - _main_loop - 588 - DEBUG - Next wakeup is due at 2020-06-12 00:00:00 (in 1351.803524 seconds)
2020-06-11 23:37:28,197 - _run_job - 509 - INFO - Running job "regulartime_task (trigger: interval[1 day, 0:00:00], next run at: 2020-06-12 23:37:28.194728)" (scheduled at 2020-06-11 23:37:28.194728)
2020-06-11 23:37:28,521 - _run_job - 520 - ERROR - Job "regulartime_task (trigger: interval[1 day, 0:00:00], next run at: 2020-06-12 23:37:28.194728)" raised an exception
Traceback (most recent call last):
  File "D:\Program Files\Python37\lib\site-packages\django\db\backends\utils.py", line 84, in _execute
    return self.cursor.execute(sql, params)
  File "D:\Program Files\Python37\lib\site-packages\django\db\backends\mysql\base.py", line 71, in execute
    return self.cursor.execute(query, args)
  File "D:\Program Files\Python37\lib\site-packages\MySQLdb\cursors.py", line 209, in execute
    res = self._query(query)
  File "D:\Program Files\Python37\lib\site-packages\MySQLdb\cursors.py", line 315, in _query
    db.query(q)
  File "D:\Program Files\Python37\lib\site-packages\MySQLdb\connections.py", line 239, in query
    _mysql.connection.query(self, query)
MySQLdb._exceptions.IntegrityError: (1062, "Duplicate entry '1591891200' for key 'LAMProcessData_process_r_acquisition_timestamp_a69ae90c_uniq'")

The above exception was the direct cause of the following exception:

Traceback (most recent call last):
  File "D:\Program Files\Python37\lib\site-packages\apscheduler\scheduler.py", line 512, in _run_job
    retval = job.func(*job.args, **job.kwargs)
  File "E:\1-program\11-LAMDataServer\lamdataserver\LAMProcessData\views.py", line 5662, in regulartime_task
    RT_FineData.Realtime_FineData.init_Tomorrow_rows()
  File "E:\1-program\11-LAMDataServer\lamdataserver\LAMProcessData\process_realtime_finedata.py", line 193, in init_Tomorrow_rows
    _model.objects.bulk_create(insert_data_list)
  File "D:\Program Files\Python37\lib\site-packages\django\db\models\manager.py", line 82, in manager_method
    return getattr(self.get_queryset(), name)(*args, **kwargs)
  File "D:\Program Files\Python37\lib\site-packages\django\db\models\query.py", line 474, in bulk_create
    ids = self._batched_insert(objs_without_pk, fields, batch_size, ignore_conflicts=ignore_conflicts)
  File "D:\Program Files\Python37\lib\site-packages\django\db\models\query.py", line 1211, in _batched_insert
    self._insert(item, fields=fields, using=self.db, ignore_conflicts=ignore_conflicts)
  File "D:\Program Files\Python37\lib\site-packages\django\db\models\query.py", line 1186, in _insert
    return query.get_compiler(using=using).execute_sql(return_id)
  File "D:\Program Files\Python37\lib\site-packages\django\db\models\sql\compiler.py", line 1332, in execute_sql
    cursor.execute(sql, params)
  File "D:\Program Files\Python37\lib\site-packages\django\db\backends\utils.py", line 99, in execute
    return super().execute(sql, params)
  File "D:\Program Files\Python37\lib\site-packages\django\db\backends\utils.py", line 67, in execute
    return self._execute_with_wrappers(sql, params, many=False, executor=self._execute)
  File "D:\Program Files\Python37\lib\site-packages\django\db\backends\utils.py", line 76, in _execute_with_wrappers
    return executor(sql, params, many, context)
  File "D:\Program Files\Python37\lib\site-packages\django\db\backends\utils.py", line 84, in _execute
    return self.cursor.execute(sql, params)
  File "D:\Program Files\Python37\lib\site-packages\django\db\utils.py", line 89, in __exit__
    raise dj_exc_value.with_traceback(traceback) from exc_value
  File "D:\Program Files\Python37\lib\site-packages\django\db\backends\utils.py", line 84, in _execute
    return self.cursor.execute(sql, params)
  File "D:\Program Files\Python37\lib\site-packages\django\db\backends\mysql\base.py", line 71, in execute
    return self.cursor.execute(query, args)
  File "D:\Program Files\Python37\lib\site-packages\MySQLdb\cursors.py", line 209, in execute
    res = self._query(query)
  File "D:\Program Files\Python37\lib\site-packages\MySQLdb\cursors.py", line 315, in _query
    db.query(q)
  File "D:\Program Files\Python37\lib\site-packages\MySQLdb\connections.py", line 239, in query
    _mysql.connection.query(self, query)
django.db.utils.IntegrityError: (1062, "Duplicate entry '1591891200' for key 'LAMProcessData_process_r_acquisition_timestamp_a69ae90c_uniq'")
2020-06-11 23:37:29,528 - _run_jobs - 94 - DEBUG - Exiting worker thread
2020-06-11 23:57:34,422 - trigger_reload - 203 - INFO - E:\1-program\11-LAMDataServer\lamdataserver\LAMProcessData\forms.py changed, reloading.
2020-06-11 23:57:34,423 - shutdown - 111 - INFO - Shutting down thread pool
2020-06-11 23:57:40,233 - _real_add_job - 262 - INFO - Added job "regulartime_task (trigger: interval[1 day, 0:00:00], next run at: 2020-06-11 23:57:50.231244)" to job store "default"
2020-06-11 23:57:40,233 - _real_add_job - 262 - INFO - Added job "cleanup (trigger: cron[day_of_week='*', hour='3', minute='0', second='0'], next run at: 2020-06-12 03:00:00)" to job store "default"
2020-06-11 23:57:40,233 - _real_add_job - 262 - INFO - Added job "OpenLog (trigger: cron[hour='0'], next run at: 2020-06-12 00:00:00)" to job store "default"
2020-06-11 23:57:40,234 - _main_loop - 574 - INFO - Scheduler started
2020-06-11 23:57:40,234 - _main_loop - 579 - DEBUG - Looking for jobs to run
2020-06-11 23:57:40,234 - _main_loop - 588 - DEBUG - Next wakeup is due at 2020-06-11 23:57:50.231244 (in 9.997008 seconds)
2020-06-11 23:57:40,244 - <module> - 63 - DEBUG - SendBefore_NotRecive : [<CNCProcessStatus: CNCProcessStatus object (2038721)>]
2020-06-11 23:57:40,244 - <module> - 64 - DEBUG - Waitfor_Recive : [2038721]
2020-06-11 23:57:41,369 - log_response - 228 - WARNING - Not Found: /LAMProcessData/PracticalTools/MakeMainProgramFile/src/jquery.autocomplete.js
2020-06-11 23:57:41,380 - log_response - 228 - WARNING - Not Found: /LAMProcessData/PracticalTools/MakeMainProgramFile/scripts/demo.js
2020-06-11 23:57:41,391 - log_response - 228 - WARNING - Not Found: /LAMProcessData/PracticalTools/MakeMainProgramFile/scripts/jquery.mockjax.js
2020-06-11 23:57:41,403 - log_response - 228 - WARNING - Not Found: /LAMProcessData/PracticalTools/MakeMainProgramFile/scripts/countries.js
2020-06-11 23:57:41,474 - log_response - 228 - WARNING - Not Found: /LAMProcessData/PracticalTools/MakeMainProgramFile/scripts/jquery.mockjax.js
2020-06-11 23:57:41,495 - log_response - 228 - WARNING - Not Found: /LAMProcessData/PracticalTools/MakeMainProgramFile/src/jquery.autocomplete.js
2020-06-11 23:57:41,513 - log_response - 228 - WARNING - Not Found: /LAMProcessData/PracticalTools/MakeMainProgramFile/scripts/countries.js
2020-06-11 23:57:41,533 - log_response - 228 - WARNING - Not Found: /LAMProcessData/PracticalTools/MakeMainProgramFile/scripts/demo.js
2020-06-11 23:57:50,233 - _main_loop - 579 - DEBUG - Looking for jobs to run
2020-06-11 23:57:50,233 - _run_jobs - 69 - DEBUG - Started worker thread
2020-06-11 23:57:50,233 - _run_job - 509 - INFO - Running job "regulartime_task (trigger: interval[1 day, 0:00:00], next run at: 2020-06-11 23:57:50.231244)" (scheduled at 2020-06-11 23:57:50.231244)
2020-06-11 23:57:50,233 - _main_loop - 588 - DEBUG - Next wakeup is due at 2020-06-12 00:00:00 (in 129.766862 seconds)
2020-06-11 23:57:50,562 - _run_job - 520 - ERROR - Job "regulartime_task (trigger: interval[1 day, 0:00:00], next run at: 2020-06-12 23:57:50.231244)" raised an exception
Traceback (most recent call last):
  File "D:\Program Files\Python37\lib\site-packages\django\db\backends\utils.py", line 84, in _execute
    return self.cursor.execute(sql, params)
  File "D:\Program Files\Python37\lib\site-packages\django\db\backends\mysql\base.py", line 71, in execute
    return self.cursor.execute(query, args)
  File "D:\Program Files\Python37\lib\site-packages\MySQLdb\cursors.py", line 209, in execute
    res = self._query(query)
  File "D:\Program Files\Python37\lib\site-packages\MySQLdb\cursors.py", line 315, in _query
    db.query(q)
  File "D:\Program Files\Python37\lib\site-packages\MySQLdb\connections.py", line 239, in query
    _mysql.connection.query(self, query)
MySQLdb._exceptions.IntegrityError: (1062, "Duplicate entry '1591891200' for key 'LAMProcessData_process_r_acquisition_timestamp_a69ae90c_uniq'")

The above exception was the direct cause of the following exception:

Traceback (most recent call last):
  File "D:\Program Files\Python37\lib\site-packages\apscheduler\scheduler.py", line 512, in _run_job
    retval = job.func(*job.args, **job.kwargs)
  File "E:\1-program\11-LAMDataServer\lamdataserver\LAMProcessData\views.py", line 5662, in regulartime_task
    RT_FineData.Realtime_FineData.init_Tomorrow_rows()
  File "E:\1-program\11-LAMDataServer\lamdataserver\LAMProcessData\process_realtime_finedata.py", line 193, in init_Tomorrow_rows
    _model.objects.bulk_create(insert_data_list)
  File "D:\Program Files\Python37\lib\site-packages\django\db\models\manager.py", line 82, in manager_method
    return getattr(self.get_queryset(), name)(*args, **kwargs)
  File "D:\Program Files\Python37\lib\site-packages\django\db\models\query.py", line 474, in bulk_create
    ids = self._batched_insert(objs_without_pk, fields, batch_size, ignore_conflicts=ignore_conflicts)
  File "D:\Program Files\Python37\lib\site-packages\django\db\models\query.py", line 1211, in _batched_insert
    self._insert(item, fields=fields, using=self.db, ignore_conflicts=ignore_conflicts)
  File "D:\Program Files\Python37\lib\site-packages\django\db\models\query.py", line 1186, in _insert
    return query.get_compiler(using=using).execute_sql(return_id)
  File "D:\Program Files\Python37\lib\site-packages\django\db\models\sql\compiler.py", line 1332, in execute_sql
    cursor.execute(sql, params)
  File "D:\Program Files\Python37\lib\site-packages\django\db\backends\utils.py", line 99, in execute
    return super().execute(sql, params)
  File "D:\Program Files\Python37\lib\site-packages\django\db\backends\utils.py", line 67, in execute
    return self._execute_with_wrappers(sql, params, many=False, executor=self._execute)
  File "D:\Program Files\Python37\lib\site-packages\django\db\backends\utils.py", line 76, in _execute_with_wrappers
    return executor(sql, params, many, context)
  File "D:\Program Files\Python37\lib\site-packages\django\db\backends\utils.py", line 84, in _execute
    return self.cursor.execute(sql, params)
  File "D:\Program Files\Python37\lib\site-packages\django\db\utils.py", line 89, in __exit__
    raise dj_exc_value.with_traceback(traceback) from exc_value
  File "D:\Program Files\Python37\lib\site-packages\django\db\backends\utils.py", line 84, in _execute
    return self.cursor.execute(sql, params)
  File "D:\Program Files\Python37\lib\site-packages\django\db\backends\mysql\base.py", line 71, in execute
    return self.cursor.execute(query, args)
  File "D:\Program Files\Python37\lib\site-packages\MySQLdb\cursors.py", line 209, in execute
    res = self._query(query)
  File "D:\Program Files\Python37\lib\site-packages\MySQLdb\cursors.py", line 315, in _query
    db.query(q)
  File "D:\Program Files\Python37\lib\site-packages\MySQLdb\connections.py", line 239, in query
    _mysql.connection.query(self, query)
django.db.utils.IntegrityError: (1062, "Duplicate entry '1591891200' for key 'LAMProcessData_process_r_acquisition_timestamp_a69ae90c_uniq'")
2020-06-11 23:57:51,567 - _run_jobs - 94 - DEBUG - Exiting worker thread
