2020-04-15 23:14:31,243 - _real_add_job - 262 - INFO - Added job "regulartime_task (trigger: interval[1 day, 0:00:00], next run at: 2020-04-15 23:14:41.242335)" to job store "default"
2020-04-15 23:14:31,243 - _real_add_job - 262 - INFO - Added job "cleanup (trigger: cron[day_of_week='*', hour='3', minute='0', second='0'], next run at: 2020-04-16 03:00:00)" to job store "default"
2020-04-15 23:14:31,244 - _real_add_job - 262 - INFO - Added job "OpenLog (trigger: cron[hour='0'], next run at: 2020-04-16 00:00:00)" to job store "default"
2020-04-15 23:14:31,244 - _main_loop - 574 - INFO - Scheduler started
2020-04-15 23:14:31,244 - _main_loop - 579 - DEBUG - Looking for jobs to run
2020-04-15 23:14:31,244 - _main_loop - 588 - DEBUG - Next wakeup is due at 2020-04-15 23:14:41.242335 (in 9.998006 seconds)
2020-04-15 23:14:31,269 - <module> - 59 - DEBUG - SendBefore_NotRecive : [<CNCProcessStatus: CNCProcessStatus object (2038721)>]
2020-04-15 23:14:31,269 - <module> - 60 - DEBUG - Waitfor_Recive : [2038721]
2020-04-15 23:15:35,822 - _real_add_job - 262 - INFO - Added job "regulartime_task (trigger: interval[1 day, 0:00:00], next run at: 2020-04-15 23:15:45.821266)" to job store "default"
2020-04-15 23:15:35,822 - _real_add_job - 262 - INFO - Added job "cleanup (trigger: cron[day_of_week='*', hour='3', minute='0', second='0'], next run at: 2020-04-16 03:00:00)" to job store "default"
2020-04-15 23:15:35,822 - _real_add_job - 262 - INFO - Added job "OpenLog (trigger: cron[hour='0'], next run at: 2020-04-16 00:00:00)" to job store "default"
2020-04-15 23:15:35,823 - _main_loop - 574 - INFO - Scheduler started
2020-04-15 23:15:35,823 - _main_loop - 579 - DEBUG - Looking for jobs to run
2020-04-15 23:15:35,823 - _main_loop - 588 - DEBUG - Next wakeup is due at 2020-04-15 23:15:45.821266 (in 9.998029 seconds)
2020-04-15 23:15:35,834 - <module> - 59 - DEBUG - SendBefore_NotRecive : [<CNCProcessStatus: CNCProcessStatus object (2038721)>]
2020-04-15 23:15:35,835 - <module> - 60 - DEBUG - Waitfor_Recive : [2038721]
2020-04-15 23:15:45,822 - _main_loop - 579 - DEBUG - Looking for jobs to run
2020-04-15 23:15:45,823 - _run_jobs - 69 - DEBUG - Started worker thread
2020-04-15 23:15:45,823 - _main_loop - 588 - DEBUG - Next wakeup is due at 2020-04-16 00:00:00 (in 2654.177685 seconds)
2020-04-15 23:15:45,823 - _run_job - 509 - INFO - Running job "regulartime_task (trigger: interval[1 day, 0:00:00], next run at: 2020-04-16 23:15:45.821266)" (scheduled at 2020-04-15 23:15:45.821266)
2020-04-15 23:15:46,649 - _run_job - 520 - ERROR - Job "regulartime_task (trigger: interval[1 day, 0:00:00], next run at: 2020-04-16 23:15:45.821266)" raised an exception
Traceback (most recent call last):
  File "D:\Program Files\Python37\lib\site-packages\django\db\backends\mysql\base.py", line 71, in execute
    return self.cursor.execute(query, args)
  File "D:\Program Files\Python37\lib\site-packages\MySQLdb\cursors.py", line 209, in execute
    res = self._query(query)
  File "D:\Program Files\Python37\lib\site-packages\MySQLdb\cursors.py", line 315, in _query
    db.query(q)
  File "D:\Program Files\Python37\lib\site-packages\MySQLdb\connections.py", line 239, in query
    _mysql.connection.query(self, query)
MySQLdb._exceptions.OperationalError: (1048, "Column 'laser_power' cannot be null")

During handling of the above exception, another exception occurred:

Traceback (most recent call last):
  File "D:\Program Files\Python37\lib\site-packages\apscheduler\scheduler.py", line 512, in _run_job
    retval = job.func(*job.args, **job.kwargs)
  File "E:\1-program\11-LAMDataServer\lamdataserver\LAMProcessData\views.py", line 4816, in regulartime_task
    RT_FineData.Realtime_FineData.init_Tomorrow_rows()
  File "E:\1-program\11-LAMDataServer\lamdataserver\LAMProcessData\process_realtime_finedata.py", line 193, in init_Tomorrow_rows
    _model.objects.bulk_create(insert_data_list)
  File "D:\Program Files\Python37\lib\site-packages\django\db\models\manager.py", line 82, in manager_method
    return getattr(self.get_queryset(), name)(*args, **kwargs)
  File "D:\Program Files\Python37\lib\site-packages\django\db\models\query.py", line 474, in bulk_create
    ids = self._batched_insert(objs_without_pk, fields, batch_size, ignore_conflicts=ignore_conflicts)
  File "D:\Program Files\Python37\lib\site-packages\django\db\models\query.py", line 1211, in _batched_insert
    self._insert(item, fields=fields, using=self.db, ignore_conflicts=ignore_conflicts)
  File "D:\Program Files\Python37\lib\site-packages\django\db\models\query.py", line 1186, in _insert
    return query.get_compiler(using=using).execute_sql(return_id)
  File "D:\Program Files\Python37\lib\site-packages\django\db\models\sql\compiler.py", line 1332, in execute_sql
    cursor.execute(sql, params)
  File "D:\Program Files\Python37\lib\site-packages\django\db\backends\utils.py", line 99, in execute
    return super().execute(sql, params)
  File "D:\Program Files\Python37\lib\site-packages\django\db\backends\utils.py", line 67, in execute
    return self._execute_with_wrappers(sql, params, many=False, executor=self._execute)
  File "D:\Program Files\Python37\lib\site-packages\django\db\backends\utils.py", line 76, in _execute_with_wrappers
    return executor(sql, params, many, context)
  File "D:\Program Files\Python37\lib\site-packages\django\db\backends\utils.py", line 84, in _execute
    return self.cursor.execute(sql, params)
  File "D:\Program Files\Python37\lib\site-packages\django\db\backends\mysql\base.py", line 76, in execute
    raise utils.IntegrityError(*tuple(e.args))
django.db.utils.IntegrityError: (1048, "Column 'laser_power' cannot be null")
2020-04-15 23:15:47,663 - _run_jobs - 94 - DEBUG - Exiting worker thread
2020-04-15 23:15:58,144 - trigger_reload - 203 - INFO - E:\1-program\11-LAMDataServer\lamdataserver\lamdataserver\wsgi.py changed, reloading.
2020-04-15 23:15:58,144 - shutdown - 111 - INFO - Shutting down thread pool
2020-04-15 23:16:02,190 - _real_add_job - 262 - INFO - Added job "regulartime_task (trigger: interval[1 day, 0:00:00], next run at: 2020-04-15 23:16:12.188072)" to job store "default"
2020-04-15 23:16:02,190 - _real_add_job - 262 - INFO - Added job "cleanup (trigger: cron[day_of_week='*', hour='3', minute='0', second='0'], next run at: 2020-04-16 03:00:00)" to job store "default"
2020-04-15 23:16:02,190 - _real_add_job - 262 - INFO - Added job "OpenLog (trigger: cron[hour='0'], next run at: 2020-04-16 00:00:00)" to job store "default"
2020-04-15 23:16:02,191 - _main_loop - 574 - INFO - Scheduler started
2020-04-15 23:16:02,191 - _main_loop - 579 - DEBUG - Looking for jobs to run
2020-04-15 23:16:02,191 - _main_loop - 588 - DEBUG - Next wakeup is due at 2020-04-15 23:16:12.188072 (in 9.997034 seconds)
2020-04-15 23:16:02,201 - <module> - 59 - DEBUG - SendBefore_NotRecive : [<CNCProcessStatus: CNCProcessStatus object (2038721)>]
2020-04-15 23:16:02,201 - <module> - 60 - DEBUG - Waitfor_Recive : [2038721]
2020-04-15 23:16:06,590 - log_response - 228 - WARNING - Not Found: /favicon.ico
2020-04-15 23:16:07,160 - log_response - 228 - WARNING - Not Found: /favicon.ico
2020-04-15 23:16:07,776 - log_response - 228 - WARNING - Not Found: /favicon.ico
2020-04-15 23:16:08,377 - log_response - 228 - WARNING - Not Found: /favicon.ico
2020-04-15 23:16:09,004 - log_response - 228 - WARNING - Not Found: /favicon.ico
2020-04-15 23:16:12,204 - _main_loop - 579 - DEBUG - Looking for jobs to run
2020-04-15 23:16:12,204 - _run_jobs - 69 - DEBUG - Started worker thread
2020-04-15 23:16:12,204 - _run_job - 509 - INFO - Running job "regulartime_task (trigger: interval[1 day, 0:00:00], next run at: 2020-04-15 23:16:12.188072)" (scheduled at 2020-04-15 23:16:12.188072)
2020-04-15 23:16:12,204 - _main_loop - 588 - DEBUG - Next wakeup is due at 2020-04-16 00:00:00 (in 2627.795543 seconds)
2020-04-15 23:16:12,517 - _run_job - 520 - ERROR - Job "regulartime_task (trigger: interval[1 day, 0:00:00], next run at: 2020-04-16 23:16:12.188072)" raised an exception
Traceback (most recent call last):
  File "D:\Program Files\Python37\lib\site-packages\django\db\backends\utils.py", line 84, in _execute
    return self.cursor.execute(sql, params)
  File "D:\Program Files\Python37\lib\site-packages\django\db\backends\mysql\base.py", line 71, in execute
    return self.cursor.execute(query, args)
  File "D:\Program Files\Python37\lib\site-packages\MySQLdb\cursors.py", line 209, in execute
    res = self._query(query)
  File "D:\Program Files\Python37\lib\site-packages\MySQLdb\cursors.py", line 315, in _query
    db.query(q)
  File "D:\Program Files\Python37\lib\site-packages\MySQLdb\connections.py", line 239, in query
    _mysql.connection.query(self, query)
MySQLdb._exceptions.IntegrityError: (1062, "Duplicate entry '1586966400' for key 'LAMProcessData_process_r_acquisition_timestamp_a69ae90c_uniq'")

The above exception was the direct cause of the following exception:

Traceback (most recent call last):
  File "D:\Program Files\Python37\lib\site-packages\apscheduler\scheduler.py", line 512, in _run_job
    retval = job.func(*job.args, **job.kwargs)
  File "E:\1-program\11-LAMDataServer\lamdataserver\LAMProcessData\views.py", line 4816, in regulartime_task
    RT_FineData.Realtime_FineData.init_Tomorrow_rows()
  File "E:\1-program\11-LAMDataServer\lamdataserver\LAMProcessData\process_realtime_finedata.py", line 193, in init_Tomorrow_rows
    _model.objects.bulk_create(insert_data_list)
  File "D:\Program Files\Python37\lib\site-packages\django\db\models\manager.py", line 82, in manager_method
    return getattr(self.get_queryset(), name)(*args, **kwargs)
  File "D:\Program Files\Python37\lib\site-packages\django\db\models\query.py", line 474, in bulk_create
    ids = self._batched_insert(objs_without_pk, fields, batch_size, ignore_conflicts=ignore_conflicts)
  File "D:\Program Files\Python37\lib\site-packages\django\db\models\query.py", line 1211, in _batched_insert
    self._insert(item, fields=fields, using=self.db, ignore_conflicts=ignore_conflicts)
  File "D:\Program Files\Python37\lib\site-packages\django\db\models\query.py", line 1186, in _insert
    return query.get_compiler(using=using).execute_sql(return_id)
  File "D:\Program Files\Python37\lib\site-packages\django\db\models\sql\compiler.py", line 1332, in execute_sql
    cursor.execute(sql, params)
  File "D:\Program Files\Python37\lib\site-packages\django\db\backends\utils.py", line 99, in execute
    return super().execute(sql, params)
  File "D:\Program Files\Python37\lib\site-packages\django\db\backends\utils.py", line 67, in execute
    return self._execute_with_wrappers(sql, params, many=False, executor=self._execute)
  File "D:\Program Files\Python37\lib\site-packages\django\db\backends\utils.py", line 76, in _execute_with_wrappers
    return executor(sql, params, many, context)
  File "D:\Program Files\Python37\lib\site-packages\django\db\backends\utils.py", line 84, in _execute
    return self.cursor.execute(sql, params)
  File "D:\Program Files\Python37\lib\site-packages\django\db\utils.py", line 89, in __exit__
    raise dj_exc_value.with_traceback(traceback) from exc_value
  File "D:\Program Files\Python37\lib\site-packages\django\db\backends\utils.py", line 84, in _execute
    return self.cursor.execute(sql, params)
  File "D:\Program Files\Python37\lib\site-packages\django\db\backends\mysql\base.py", line 71, in execute
    return self.cursor.execute(query, args)
  File "D:\Program Files\Python37\lib\site-packages\MySQLdb\cursors.py", line 209, in execute
    res = self._query(query)
  File "D:\Program Files\Python37\lib\site-packages\MySQLdb\cursors.py", line 315, in _query
    db.query(q)
  File "D:\Program Files\Python37\lib\site-packages\MySQLdb\connections.py", line 239, in query
    _mysql.connection.query(self, query)
django.db.utils.IntegrityError: (1062, "Duplicate entry '1586966400' for key 'LAMProcessData_process_r_acquisition_timestamp_a69ae90c_uniq'")
2020-04-15 23:16:12,828 - log_response - 228 - WARNING - Not Found: /favicon.ico
2020-04-15 23:16:13,426 - log_response - 228 - WARNING - Not Found: /favicon.ico
2020-04-15 23:16:13,520 - _run_jobs - 94 - DEBUG - Exiting worker thread
2020-04-15 23:16:14,044 - log_response - 228 - WARNING - Not Found: /favicon.ico
2020-04-15 23:16:14,662 - log_response - 228 - WARNING - Not Found: /favicon.ico
2020-04-15 23:16:15,260 - log_response - 228 - WARNING - Not Found: /favicon.ico
2020-04-15 23:16:15,858 - log_response - 228 - WARNING - Not Found: /favicon.ico
