2020-02-25 01:40:30,944 - _real_add_job - 262 - INFO - Added job "regulartime_task (trigger: interval[1 day, 0:00:00], next run at: 2020-02-25 01:40:40.941659)" to job store "default"
2020-02-25 01:40:30,945 - _real_add_job - 262 - INFO - Added job "OpenLog (trigger: cron[hour='0'], next run at: 2020-02-26 00:00:00)" to job store "default"
2020-02-25 01:40:30,945 - _main_loop - 574 - INFO - Scheduler started
2020-02-25 01:40:30,946 - _main_loop - 579 - DEBUG - Looking for jobs to run
2020-02-25 01:40:30,946 - _main_loop - 588 - DEBUG - Next wakeup is due at 2020-02-25 01:40:40.941659 (in 9.994994 seconds)
2020-02-25 01:40:30,973 - <module> - 58 - DEBUG - SendBefore_NotRecive : [<CNCProcessStatus: CNCProcessStatus object (2038721)>]
2020-02-25 01:40:30,974 - <module> - 59 - DEBUG - Waitfor_Recive : [2038721]
2020-02-25 01:40:40,941 - _main_loop - 579 - DEBUG - Looking for jobs to run
2020-02-25 01:40:40,941 - _run_jobs - 69 - DEBUG - Started worker thread
2020-02-25 01:40:40,941 - _run_job - 509 - INFO - Running job "regulartime_task (trigger: interval[1 day, 0:00:00], next run at: 2020-02-25 01:40:40.941659)" (scheduled at 2020-02-25 01:40:40.941659)
2020-02-25 01:40:40,941 - _main_loop - 588 - DEBUG - Next wakeup is due at 2020-02-26 00:00:00 (in 80359.058041 seconds)
2020-02-25 01:40:41,675 - _run_job - 520 - ERROR - Job "regulartime_task (trigger: interval[1 day, 0:00:00], next run at: 2020-02-26 01:40:40.941659)" raised an exception
Traceback (most recent call last):
  File "D:\Program Files\Python37\lib\site-packages\django\db\backends\mysql\base.py", line 71, in execute
    return self.cursor.execute(query, args)
  File "D:\Program Files\Python37\lib\site-packages\MySQLdb\cursors.py", line 209, in execute
    res = self._query(query)
  File "D:\Program Files\Python37\lib\site-packages\MySQLdb\cursors.py", line 315, in _query
    db.query(q)
  File "D:\Program Files\Python37\lib\site-packages\MySQLdb\connections.py", line 239, in query
    _mysql.connection.query(self, query)
MySQLdb._exceptions.OperationalError: (1048, "Column 'laser_power' cannot be null")

During handling of the above exception, another exception occurred:

Traceback (most recent call last):
  File "D:\Program Files\Python37\lib\site-packages\apscheduler\scheduler.py", line 512, in _run_job
    retval = job.func(*job.args, **job.kwargs)
  File "E:\1-program\11-LAMDataServer\lamdataserver\LAMProcessData\views.py", line 3997, in regulartime_task
    RT_FineData.Realtime_FineData.init_Tomorrow_rows()
  File "E:\1-program\11-LAMDataServer\lamdataserver\LAMProcessData\process_realtime_finedata.py", line 172, in init_Tomorrow_rows
    _model.objects.bulk_create(insert_data_list)
  File "D:\Program Files\Python37\lib\site-packages\django\db\models\manager.py", line 82, in manager_method
    return getattr(self.get_queryset(), name)(*args, **kwargs)
  File "D:\Program Files\Python37\lib\site-packages\django\db\models\query.py", line 474, in bulk_create
    ids = self._batched_insert(objs_without_pk, fields, batch_size, ignore_conflicts=ignore_conflicts)
  File "D:\Program Files\Python37\lib\site-packages\django\db\models\query.py", line 1211, in _batched_insert
    self._insert(item, fields=fields, using=self.db, ignore_conflicts=ignore_conflicts)
  File "D:\Program Files\Python37\lib\site-packages\django\db\models\query.py", line 1186, in _insert
    return query.get_compiler(using=using).execute_sql(return_id)
  File "D:\Program Files\Python37\lib\site-packages\django\db\models\sql\compiler.py", line 1332, in execute_sql
    cursor.execute(sql, params)
  File "D:\Program Files\Python37\lib\site-packages\django\db\backends\utils.py", line 99, in execute
    return super().execute(sql, params)
  File "D:\Program Files\Python37\lib\site-packages\django\db\backends\utils.py", line 67, in execute
    return self._execute_with_wrappers(sql, params, many=False, executor=self._execute)
  File "D:\Program Files\Python37\lib\site-packages\django\db\backends\utils.py", line 76, in _execute_with_wrappers
    return executor(sql, params, many, context)
  File "D:\Program Files\Python37\lib\site-packages\django\db\backends\utils.py", line 84, in _execute
    return self.cursor.execute(sql, params)
  File "D:\Program Files\Python37\lib\site-packages\django\db\backends\mysql\base.py", line 76, in execute
    raise utils.IntegrityError(*tuple(e.args))
django.db.utils.IntegrityError: (1048, "Column 'laser_power' cannot be null")
2020-02-25 01:40:42,683 - _run_jobs - 94 - DEBUG - Exiting worker thread
2020-02-25 01:40:59,824 - _real_add_job - 262 - INFO - Added job "regulartime_task (trigger: interval[1 day, 0:00:00], next run at: 2020-02-25 01:41:09.823424)" to job store "default"
2020-02-25 01:40:59,824 - _real_add_job - 262 - INFO - Added job "OpenLog (trigger: cron[hour='0'], next run at: 2020-02-26 00:00:00)" to job store "default"
2020-02-25 01:40:59,825 - _main_loop - 574 - INFO - Scheduler started
2020-02-25 01:40:59,825 - _main_loop - 579 - DEBUG - Looking for jobs to run
2020-02-25 01:40:59,825 - _main_loop - 588 - DEBUG - Next wakeup is due at 2020-02-25 01:41:09.823424 (in 9.998181 seconds)
2020-02-25 01:40:59,835 - <module> - 58 - DEBUG - SendBefore_NotRecive : [<CNCProcessStatus: CNCProcessStatus object (2038721)>]
2020-02-25 01:40:59,835 - <module> - 59 - DEBUG - Waitfor_Recive : [2038721]
2020-02-25 01:41:09,824 - _main_loop - 579 - DEBUG - Looking for jobs to run
2020-02-25 01:41:09,826 - _run_jobs - 69 - DEBUG - Started worker thread
2020-02-25 01:41:09,827 - _run_job - 509 - INFO - Running job "regulartime_task (trigger: interval[1 day, 0:00:00], next run at: 2020-02-25 01:41:09.823424)" (scheduled at 2020-02-25 01:41:09.823424)
2020-02-25 01:41:09,827 - _main_loop - 588 - DEBUG - Next wakeup is due at 2020-02-26 00:00:00 (in 80330.174631 seconds)
2020-02-25 01:41:10,153 - _run_job - 520 - ERROR - Job "regulartime_task (trigger: interval[1 day, 0:00:00], next run at: 2020-02-26 01:41:09.823424)" raised an exception
Traceback (most recent call last):
  File "D:\Program Files\Python37\lib\site-packages\django\db\backends\utils.py", line 84, in _execute
    return self.cursor.execute(sql, params)
  File "D:\Program Files\Python37\lib\site-packages\django\db\backends\mysql\base.py", line 71, in execute
    return self.cursor.execute(query, args)
  File "D:\Program Files\Python37\lib\site-packages\MySQLdb\cursors.py", line 209, in execute
    res = self._query(query)
  File "D:\Program Files\Python37\lib\site-packages\MySQLdb\cursors.py", line 315, in _query
    db.query(q)
  File "D:\Program Files\Python37\lib\site-packages\MySQLdb\connections.py", line 239, in query
    _mysql.connection.query(self, query)
MySQLdb._exceptions.IntegrityError: (1062, "Duplicate entry '1582646400' for key 'LAMProcessData_process_r_acquisition_timestamp_a69ae90c_uniq'")

The above exception was the direct cause of the following exception:

Traceback (most recent call last):
  File "D:\Program Files\Python37\lib\site-packages\apscheduler\scheduler.py", line 512, in _run_job
    retval = job.func(*job.args, **job.kwargs)
  File "E:\1-program\11-LAMDataServer\lamdataserver\LAMProcessData\views.py", line 3997, in regulartime_task
    RT_FineData.Realtime_FineData.init_Tomorrow_rows()
  File "E:\1-program\11-LAMDataServer\lamdataserver\LAMProcessData\process_realtime_finedata.py", line 172, in init_Tomorrow_rows
    _model.objects.bulk_create(insert_data_list)
  File "D:\Program Files\Python37\lib\site-packages\django\db\models\manager.py", line 82, in manager_method
    return getattr(self.get_queryset(), name)(*args, **kwargs)
  File "D:\Program Files\Python37\lib\site-packages\django\db\models\query.py", line 474, in bulk_create
    ids = self._batched_insert(objs_without_pk, fields, batch_size, ignore_conflicts=ignore_conflicts)
  File "D:\Program Files\Python37\lib\site-packages\django\db\models\query.py", line 1211, in _batched_insert
    self._insert(item, fields=fields, using=self.db, ignore_conflicts=ignore_conflicts)
  File "D:\Program Files\Python37\lib\site-packages\django\db\models\query.py", line 1186, in _insert
    return query.get_compiler(using=using).execute_sql(return_id)
  File "D:\Program Files\Python37\lib\site-packages\django\db\models\sql\compiler.py", line 1332, in execute_sql
    cursor.execute(sql, params)
  File "D:\Program Files\Python37\lib\site-packages\django\db\backends\utils.py", line 99, in execute
    return super().execute(sql, params)
  File "D:\Program Files\Python37\lib\site-packages\django\db\backends\utils.py", line 67, in execute
    return self._execute_with_wrappers(sql, params, many=False, executor=self._execute)
  File "D:\Program Files\Python37\lib\site-packages\django\db\backends\utils.py", line 76, in _execute_with_wrappers
    return executor(sql, params, many, context)
  File "D:\Program Files\Python37\lib\site-packages\django\db\backends\utils.py", line 84, in _execute
    return self.cursor.execute(sql, params)
  File "D:\Program Files\Python37\lib\site-packages\django\db\utils.py", line 89, in __exit__
    raise dj_exc_value.with_traceback(traceback) from exc_value
  File "D:\Program Files\Python37\lib\site-packages\django\db\backends\utils.py", line 84, in _execute
    return self.cursor.execute(sql, params)
  File "D:\Program Files\Python37\lib\site-packages\django\db\backends\mysql\base.py", line 71, in execute
    return self.cursor.execute(query, args)
  File "D:\Program Files\Python37\lib\site-packages\MySQLdb\cursors.py", line 209, in execute
    res = self._query(query)
  File "D:\Program Files\Python37\lib\site-packages\MySQLdb\cursors.py", line 315, in _query
    db.query(q)
  File "D:\Program Files\Python37\lib\site-packages\MySQLdb\connections.py", line 239, in query
    _mysql.connection.query(self, query)
django.db.utils.IntegrityError: (1062, "Duplicate entry '1582646400' for key 'LAMProcessData_process_r_acquisition_timestamp_a69ae90c_uniq'")
2020-02-25 01:41:11,157 - _run_jobs - 94 - DEBUG - Exiting worker thread
2020-02-25 01:41:49,950 - _real_add_job - 262 - INFO - Added job "regulartime_task (trigger: interval[1 day, 0:00:00], next run at: 2020-02-25 01:41:59.948338)" to job store "default"
2020-02-25 01:41:49,951 - _real_add_job - 262 - INFO - Added job "OpenLog (trigger: cron[hour='0'], next run at: 2020-02-26 00:00:00)" to job store "default"
2020-02-25 01:41:49,952 - _main_loop - 574 - INFO - Scheduler started
2020-02-25 01:41:49,952 - _main_loop - 579 - DEBUG - Looking for jobs to run
2020-02-25 01:41:49,952 - _main_loop - 588 - DEBUG - Next wakeup is due at 2020-02-25 01:41:59.948338 (in 9.996010 seconds)
2020-02-25 01:41:49,964 - <module> - 58 - DEBUG - SendBefore_NotRecive : [<CNCProcessStatus: CNCProcessStatus object (2038721)>]
2020-02-25 01:41:49,964 - <module> - 59 - DEBUG - Waitfor_Recive : [2038721]
2020-02-25 01:41:59,949 - _main_loop - 579 - DEBUG - Looking for jobs to run
2020-02-25 01:41:59,949 - _run_jobs - 69 - DEBUG - Started worker thread
2020-02-25 01:41:59,949 - _run_job - 509 - INFO - Running job "regulartime_task (trigger: interval[1 day, 0:00:00], next run at: 2020-02-25 01:41:59.948338)" (scheduled at 2020-02-25 01:41:59.948338)
2020-02-25 01:41:59,950 - _main_loop - 588 - DEBUG - Next wakeup is due at 2020-02-26 00:00:00 (in 80280.050424 seconds)
2020-02-25 01:42:00,300 - _run_job - 520 - ERROR - Job "regulartime_task (trigger: interval[1 day, 0:00:00], next run at: 2020-02-26 01:41:59.948338)" raised an exception
Traceback (most recent call last):
  File "D:\Program Files\Python37\lib\site-packages\django\db\backends\utils.py", line 84, in _execute
    return self.cursor.execute(sql, params)
  File "D:\Program Files\Python37\lib\site-packages\django\db\backends\mysql\base.py", line 71, in execute
    return self.cursor.execute(query, args)
  File "D:\Program Files\Python37\lib\site-packages\MySQLdb\cursors.py", line 209, in execute
    res = self._query(query)
  File "D:\Program Files\Python37\lib\site-packages\MySQLdb\cursors.py", line 315, in _query
    db.query(q)
  File "D:\Program Files\Python37\lib\site-packages\MySQLdb\connections.py", line 239, in query
    _mysql.connection.query(self, query)
MySQLdb._exceptions.IntegrityError: (1062, "Duplicate entry '1582646400' for key 'LAMProcessData_process_r_acquisition_timestamp_a69ae90c_uniq'")

The above exception was the direct cause of the following exception:

Traceback (most recent call last):
  File "D:\Program Files\Python37\lib\site-packages\apscheduler\scheduler.py", line 512, in _run_job
    retval = job.func(*job.args, **job.kwargs)
  File "E:\1-program\11-LAMDataServer\lamdataserver\LAMProcessData\views.py", line 3997, in regulartime_task
    RT_FineData.Realtime_FineData.init_Tomorrow_rows()
  File "E:\1-program\11-LAMDataServer\lamdataserver\LAMProcessData\process_realtime_finedata.py", line 172, in init_Tomorrow_rows
    _model.objects.bulk_create(insert_data_list)
  File "D:\Program Files\Python37\lib\site-packages\django\db\models\manager.py", line 82, in manager_method
    return getattr(self.get_queryset(), name)(*args, **kwargs)
  File "D:\Program Files\Python37\lib\site-packages\django\db\models\query.py", line 474, in bulk_create
    ids = self._batched_insert(objs_without_pk, fields, batch_size, ignore_conflicts=ignore_conflicts)
  File "D:\Program Files\Python37\lib\site-packages\django\db\models\query.py", line 1211, in _batched_insert
    self._insert(item, fields=fields, using=self.db, ignore_conflicts=ignore_conflicts)
  File "D:\Program Files\Python37\lib\site-packages\django\db\models\query.py", line 1186, in _insert
    return query.get_compiler(using=using).execute_sql(return_id)
  File "D:\Program Files\Python37\lib\site-packages\django\db\models\sql\compiler.py", line 1332, in execute_sql
    cursor.execute(sql, params)
  File "D:\Program Files\Python37\lib\site-packages\django\db\backends\utils.py", line 99, in execute
    return super().execute(sql, params)
  File "D:\Program Files\Python37\lib\site-packages\django\db\backends\utils.py", line 67, in execute
    return self._execute_with_wrappers(sql, params, many=False, executor=self._execute)
  File "D:\Program Files\Python37\lib\site-packages\django\db\backends\utils.py", line 76, in _execute_with_wrappers
    return executor(sql, params, many, context)
  File "D:\Program Files\Python37\lib\site-packages\django\db\backends\utils.py", line 84, in _execute
    return self.cursor.execute(sql, params)
  File "D:\Program Files\Python37\lib\site-packages\django\db\utils.py", line 89, in __exit__
    raise dj_exc_value.with_traceback(traceback) from exc_value
  File "D:\Program Files\Python37\lib\site-packages\django\db\backends\utils.py", line 84, in _execute
    return self.cursor.execute(sql, params)
  File "D:\Program Files\Python37\lib\site-packages\django\db\backends\mysql\base.py", line 71, in execute
    return self.cursor.execute(query, args)
  File "D:\Program Files\Python37\lib\site-packages\MySQLdb\cursors.py", line 209, in execute
    res = self._query(query)
  File "D:\Program Files\Python37\lib\site-packages\MySQLdb\cursors.py", line 315, in _query
    db.query(q)
  File "D:\Program Files\Python37\lib\site-packages\MySQLdb\connections.py", line 239, in query
    _mysql.connection.query(self, query)
django.db.utils.IntegrityError: (1062, "Duplicate entry '1582646400' for key 'LAMProcessData_process_r_acquisition_timestamp_a69ae90c_uniq'")
2020-02-25 01:42:01,306 - _run_jobs - 94 - DEBUG - Exiting worker thread
2020-02-25 01:42:12,703 - _real_add_job - 262 - INFO - Added job "regulartime_task (trigger: interval[1 day, 0:00:00], next run at: 2020-02-25 01:42:22.701048)" to job store "default"
2020-02-25 01:42:12,704 - _real_add_job - 262 - INFO - Added job "OpenLog (trigger: cron[hour='0'], next run at: 2020-02-26 00:00:00)" to job store "default"
2020-02-25 01:42:12,705 - _main_loop - 574 - INFO - Scheduler started
2020-02-25 01:42:12,705 - _main_loop - 579 - DEBUG - Looking for jobs to run
2020-02-25 01:42:12,705 - _main_loop - 588 - DEBUG - Next wakeup is due at 2020-02-25 01:42:22.701048 (in 9.995431 seconds)
2020-02-25 01:42:12,717 - <module> - 58 - DEBUG - SendBefore_NotRecive : [<CNCProcessStatus: CNCProcessStatus object (2038721)>]
2020-02-25 01:42:12,717 - <module> - 59 - DEBUG - Waitfor_Recive : [2038721]
2020-02-25 01:42:22,716 - _main_loop - 579 - DEBUG - Looking for jobs to run
2020-02-25 01:42:22,716 - _run_jobs - 69 - DEBUG - Started worker thread
2020-02-25 01:42:22,717 - _run_job - 509 - INFO - Running job "regulartime_task (trigger: interval[1 day, 0:00:00], next run at: 2020-02-25 01:42:22.701048)" (scheduled at 2020-02-25 01:42:22.701048)
2020-02-25 01:42:22,717 - _main_loop - 588 - DEBUG - Next wakeup is due at 2020-02-26 00:00:00 (in 80257.283934 seconds)
2020-02-25 01:42:23,072 - _run_job - 520 - ERROR - Job "regulartime_task (trigger: interval[1 day, 0:00:00], next run at: 2020-02-26 01:42:22.701048)" raised an exception
Traceback (most recent call last):
  File "D:\Program Files\Python37\lib\site-packages\django\db\backends\utils.py", line 84, in _execute
    return self.cursor.execute(sql, params)
  File "D:\Program Files\Python37\lib\site-packages\django\db\backends\mysql\base.py", line 71, in execute
    return self.cursor.execute(query, args)
  File "D:\Program Files\Python37\lib\site-packages\MySQLdb\cursors.py", line 209, in execute
    res = self._query(query)
  File "D:\Program Files\Python37\lib\site-packages\MySQLdb\cursors.py", line 315, in _query
    db.query(q)
  File "D:\Program Files\Python37\lib\site-packages\MySQLdb\connections.py", line 239, in query
    _mysql.connection.query(self, query)
MySQLdb._exceptions.IntegrityError: (1062, "Duplicate entry '1582646400' for key 'LAMProcessData_process_r_acquisition_timestamp_a69ae90c_uniq'")

The above exception was the direct cause of the following exception:

Traceback (most recent call last):
  File "D:\Program Files\Python37\lib\site-packages\apscheduler\scheduler.py", line 512, in _run_job
    retval = job.func(*job.args, **job.kwargs)
  File "E:\1-program\11-LAMDataServer\lamdataserver\LAMProcessData\views.py", line 3997, in regulartime_task
    RT_FineData.Realtime_FineData.init_Tomorrow_rows()
  File "E:\1-program\11-LAMDataServer\lamdataserver\LAMProcessData\process_realtime_finedata.py", line 172, in init_Tomorrow_rows
    _model.objects.bulk_create(insert_data_list)
  File "D:\Program Files\Python37\lib\site-packages\django\db\models\manager.py", line 82, in manager_method
    return getattr(self.get_queryset(), name)(*args, **kwargs)
  File "D:\Program Files\Python37\lib\site-packages\django\db\models\query.py", line 474, in bulk_create
    ids = self._batched_insert(objs_without_pk, fields, batch_size, ignore_conflicts=ignore_conflicts)
  File "D:\Program Files\Python37\lib\site-packages\django\db\models\query.py", line 1211, in _batched_insert
    self._insert(item, fields=fields, using=self.db, ignore_conflicts=ignore_conflicts)
  File "D:\Program Files\Python37\lib\site-packages\django\db\models\query.py", line 1186, in _insert
    return query.get_compiler(using=using).execute_sql(return_id)
  File "D:\Program Files\Python37\lib\site-packages\django\db\models\sql\compiler.py", line 1332, in execute_sql
    cursor.execute(sql, params)
  File "D:\Program Files\Python37\lib\site-packages\django\db\backends\utils.py", line 99, in execute
    return super().execute(sql, params)
  File "D:\Program Files\Python37\lib\site-packages\django\db\backends\utils.py", line 67, in execute
    return self._execute_with_wrappers(sql, params, many=False, executor=self._execute)
  File "D:\Program Files\Python37\lib\site-packages\django\db\backends\utils.py", line 76, in _execute_with_wrappers
    return executor(sql, params, many, context)
  File "D:\Program Files\Python37\lib\site-packages\django\db\backends\utils.py", line 84, in _execute
    return self.cursor.execute(sql, params)
  File "D:\Program Files\Python37\lib\site-packages\django\db\utils.py", line 89, in __exit__
    raise dj_exc_value.with_traceback(traceback) from exc_value
  File "D:\Program Files\Python37\lib\site-packages\django\db\backends\utils.py", line 84, in _execute
    return self.cursor.execute(sql, params)
  File "D:\Program Files\Python37\lib\site-packages\django\db\backends\mysql\base.py", line 71, in execute
    return self.cursor.execute(query, args)
  File "D:\Program Files\Python37\lib\site-packages\MySQLdb\cursors.py", line 209, in execute
    res = self._query(query)
  File "D:\Program Files\Python37\lib\site-packages\MySQLdb\cursors.py", line 315, in _query
    db.query(q)
  File "D:\Program Files\Python37\lib\site-packages\MySQLdb\connections.py", line 239, in query
    _mysql.connection.query(self, query)
django.db.utils.IntegrityError: (1062, "Duplicate entry '1582646400' for key 'LAMProcessData_process_r_acquisition_timestamp_a69ae90c_uniq'")
2020-02-25 01:42:24,075 - _run_jobs - 94 - DEBUG - Exiting worker thread
2020-02-25 01:44:30,955 - _real_add_job - 262 - INFO - Added job "regulartime_task (trigger: interval[1 day, 0:00:00], next run at: 2020-02-25 01:44:40.954296)" to job store "default"
2020-02-25 01:44:30,955 - _real_add_job - 262 - INFO - Added job "OpenLog (trigger: cron[hour='0'], next run at: 2020-02-26 00:00:00)" to job store "default"
2020-02-25 01:44:30,956 - _main_loop - 574 - INFO - Scheduler started
2020-02-25 01:44:30,956 - _main_loop - 579 - DEBUG - Looking for jobs to run
2020-02-25 01:44:30,956 - _main_loop - 588 - DEBUG - Next wakeup is due at 2020-02-25 01:44:40.954296 (in 9.998037 seconds)
2020-02-25 01:44:30,964 - <module> - 58 - DEBUG - SendBefore_NotRecive : [<CNCProcessStatus: CNCProcessStatus object (2038721)>]
2020-02-25 01:44:30,964 - <module> - 59 - DEBUG - Waitfor_Recive : [2038721]
2020-02-25 01:44:40,957 - _main_loop - 579 - DEBUG - Looking for jobs to run
2020-02-25 01:44:40,957 - _run_jobs - 69 - DEBUG - Started worker thread
2020-02-25 01:44:40,958 - _run_job - 509 - INFO - Running job "regulartime_task (trigger: interval[1 day, 0:00:00], next run at: 2020-02-25 01:44:40.954296)" (scheduled at 2020-02-25 01:44:40.954296)
2020-02-25 01:44:40,958 - _main_loop - 588 - DEBUG - Next wakeup is due at 2020-02-26 00:00:00 (in 80119.042615 seconds)
2020-02-25 01:44:41,267 - _run_job - 520 - ERROR - Job "regulartime_task (trigger: interval[1 day, 0:00:00], next run at: 2020-02-26 01:44:40.954296)" raised an exception
Traceback (most recent call last):
  File "D:\Program Files\Python37\lib\site-packages\django\db\backends\utils.py", line 84, in _execute
    return self.cursor.execute(sql, params)
  File "D:\Program Files\Python37\lib\site-packages\django\db\backends\mysql\base.py", line 71, in execute
    return self.cursor.execute(query, args)
  File "D:\Program Files\Python37\lib\site-packages\MySQLdb\cursors.py", line 209, in execute
    res = self._query(query)
  File "D:\Program Files\Python37\lib\site-packages\MySQLdb\cursors.py", line 315, in _query
    db.query(q)
  File "D:\Program Files\Python37\lib\site-packages\MySQLdb\connections.py", line 239, in query
    _mysql.connection.query(self, query)
MySQLdb._exceptions.IntegrityError: (1062, "Duplicate entry '1582646400' for key 'LAMProcessData_process_r_acquisition_timestamp_a69ae90c_uniq'")

The above exception was the direct cause of the following exception:

Traceback (most recent call last):
  File "D:\Program Files\Python37\lib\site-packages\apscheduler\scheduler.py", line 512, in _run_job
    retval = job.func(*job.args, **job.kwargs)
  File "E:\1-program\11-LAMDataServer\lamdataserver\LAMProcessData\views.py", line 3997, in regulartime_task
    RT_FineData.Realtime_FineData.init_Tomorrow_rows()
  File "E:\1-program\11-LAMDataServer\lamdataserver\LAMProcessData\process_realtime_finedata.py", line 172, in init_Tomorrow_rows
    _model.objects.bulk_create(insert_data_list)
  File "D:\Program Files\Python37\lib\site-packages\django\db\models\manager.py", line 82, in manager_method
    return getattr(self.get_queryset(), name)(*args, **kwargs)
  File "D:\Program Files\Python37\lib\site-packages\django\db\models\query.py", line 474, in bulk_create
    ids = self._batched_insert(objs_without_pk, fields, batch_size, ignore_conflicts=ignore_conflicts)
  File "D:\Program Files\Python37\lib\site-packages\django\db\models\query.py", line 1211, in _batched_insert
    self._insert(item, fields=fields, using=self.db, ignore_conflicts=ignore_conflicts)
  File "D:\Program Files\Python37\lib\site-packages\django\db\models\query.py", line 1186, in _insert
    return query.get_compiler(using=using).execute_sql(return_id)
  File "D:\Program Files\Python37\lib\site-packages\django\db\models\sql\compiler.py", line 1332, in execute_sql
    cursor.execute(sql, params)
  File "D:\Program Files\Python37\lib\site-packages\django\db\backends\utils.py", line 99, in execute
    return super().execute(sql, params)
  File "D:\Program Files\Python37\lib\site-packages\django\db\backends\utils.py", line 67, in execute
    return self._execute_with_wrappers(sql, params, many=False, executor=self._execute)
  File "D:\Program Files\Python37\lib\site-packages\django\db\backends\utils.py", line 76, in _execute_with_wrappers
    return executor(sql, params, many, context)
  File "D:\Program Files\Python37\lib\site-packages\django\db\backends\utils.py", line 84, in _execute
    return self.cursor.execute(sql, params)
  File "D:\Program Files\Python37\lib\site-packages\django\db\utils.py", line 89, in __exit__
    raise dj_exc_value.with_traceback(traceback) from exc_value
  File "D:\Program Files\Python37\lib\site-packages\django\db\backends\utils.py", line 84, in _execute
    return self.cursor.execute(sql, params)
  File "D:\Program Files\Python37\lib\site-packages\django\db\backends\mysql\base.py", line 71, in execute
    return self.cursor.execute(query, args)
  File "D:\Program Files\Python37\lib\site-packages\MySQLdb\cursors.py", line 209, in execute
    res = self._query(query)
  File "D:\Program Files\Python37\lib\site-packages\MySQLdb\cursors.py", line 315, in _query
    db.query(q)
  File "D:\Program Files\Python37\lib\site-packages\MySQLdb\connections.py", line 239, in query
    _mysql.connection.query(self, query)
django.db.utils.IntegrityError: (1062, "Duplicate entry '1582646400' for key 'LAMProcessData_process_r_acquisition_timestamp_a69ae90c_uniq'")
2020-02-25 01:44:42,272 - _run_jobs - 94 - DEBUG - Exiting worker thread
2020-02-25 10:50:00,045 - _real_add_job - 262 - INFO - Added job "regulartime_task (trigger: interval[1 day, 0:00:00], next run at: 2020-02-25 10:50:10.042544)" to job store "default"
2020-02-25 10:50:00,046 - _real_add_job - 262 - INFO - Added job "OpenLog (trigger: cron[hour='0'], next run at: 2020-02-26 00:00:00)" to job store "default"
2020-02-25 10:50:00,047 - _main_loop - 574 - INFO - Scheduler started
2020-02-25 10:50:00,047 - _main_loop - 579 - DEBUG - Looking for jobs to run
2020-02-25 10:50:00,048 - _main_loop - 588 - DEBUG - Next wakeup is due at 2020-02-25 10:50:10.042544 (in 9.994019 seconds)
2020-02-25 10:50:00,080 - <module> - 58 - DEBUG - SendBefore_NotRecive : [<CNCProcessStatus: CNCProcessStatus object (2038721)>]
2020-02-25 10:50:00,080 - <module> - 59 - DEBUG - Waitfor_Recive : [2038721]
2020-02-25 10:50:10,054 - _main_loop - 579 - DEBUG - Looking for jobs to run
2020-02-25 10:50:10,055 - _run_jobs - 69 - DEBUG - Started worker thread
2020-02-25 10:50:10,055 - _run_job - 509 - INFO - Running job "regulartime_task (trigger: interval[1 day, 0:00:00], next run at: 2020-02-25 10:50:10.042544)" (scheduled at 2020-02-25 10:50:10.042544)
2020-02-25 10:50:10,055 - _main_loop - 588 - DEBUG - Next wakeup is due at 2020-02-26 00:00:00 (in 47389.945056 seconds)
2020-02-25 10:50:10,364 - _run_job - 520 - ERROR - Job "regulartime_task (trigger: interval[1 day, 0:00:00], next run at: 2020-02-26 10:50:10.042544)" raised an exception
Traceback (most recent call last):
  File "D:\Program Files\Python37\lib\site-packages\django\db\backends\utils.py", line 84, in _execute
    return self.cursor.execute(sql, params)
  File "D:\Program Files\Python37\lib\site-packages\django\db\backends\mysql\base.py", line 71, in execute
    return self.cursor.execute(query, args)
  File "D:\Program Files\Python37\lib\site-packages\MySQLdb\cursors.py", line 209, in execute
    res = self._query(query)
  File "D:\Program Files\Python37\lib\site-packages\MySQLdb\cursors.py", line 315, in _query
    db.query(q)
  File "D:\Program Files\Python37\lib\site-packages\MySQLdb\connections.py", line 239, in query
    _mysql.connection.query(self, query)
MySQLdb._exceptions.IntegrityError: (1062, "Duplicate entry '1582646400' for key 'LAMProcessData_process_r_acquisition_timestamp_a69ae90c_uniq'")

The above exception was the direct cause of the following exception:

Traceback (most recent call last):
  File "D:\Program Files\Python37\lib\site-packages\apscheduler\scheduler.py", line 512, in _run_job
    retval = job.func(*job.args, **job.kwargs)
  File "E:\1-program\11-LAMDataServer\lamdataserver\LAMProcessData\views.py", line 3997, in regulartime_task
    RT_FineData.Realtime_FineData.init_Tomorrow_rows()
  File "E:\1-program\11-LAMDataServer\lamdataserver\LAMProcessData\process_realtime_finedata.py", line 172, in init_Tomorrow_rows
    _model.objects.bulk_create(insert_data_list)
  File "D:\Program Files\Python37\lib\site-packages\django\db\models\manager.py", line 82, in manager_method
    return getattr(self.get_queryset(), name)(*args, **kwargs)
  File "D:\Program Files\Python37\lib\site-packages\django\db\models\query.py", line 474, in bulk_create
    ids = self._batched_insert(objs_without_pk, fields, batch_size, ignore_conflicts=ignore_conflicts)
  File "D:\Program Files\Python37\lib\site-packages\django\db\models\query.py", line 1211, in _batched_insert
    self._insert(item, fields=fields, using=self.db, ignore_conflicts=ignore_conflicts)
  File "D:\Program Files\Python37\lib\site-packages\django\db\models\query.py", line 1186, in _insert
    return query.get_compiler(using=using).execute_sql(return_id)
  File "D:\Program Files\Python37\lib\site-packages\django\db\models\sql\compiler.py", line 1332, in execute_sql
    cursor.execute(sql, params)
  File "D:\Program Files\Python37\lib\site-packages\django\db\backends\utils.py", line 99, in execute
    return super().execute(sql, params)
  File "D:\Program Files\Python37\lib\site-packages\django\db\backends\utils.py", line 67, in execute
    return self._execute_with_wrappers(sql, params, many=False, executor=self._execute)
  File "D:\Program Files\Python37\lib\site-packages\django\db\backends\utils.py", line 76, in _execute_with_wrappers
    return executor(sql, params, many, context)
  File "D:\Program Files\Python37\lib\site-packages\django\db\backends\utils.py", line 84, in _execute
    return self.cursor.execute(sql, params)
  File "D:\Program Files\Python37\lib\site-packages\django\db\utils.py", line 89, in __exit__
    raise dj_exc_value.with_traceback(traceback) from exc_value
  File "D:\Program Files\Python37\lib\site-packages\django\db\backends\utils.py", line 84, in _execute
    return self.cursor.execute(sql, params)
  File "D:\Program Files\Python37\lib\site-packages\django\db\backends\mysql\base.py", line 71, in execute
    return self.cursor.execute(query, args)
  File "D:\Program Files\Python37\lib\site-packages\MySQLdb\cursors.py", line 209, in execute
    res = self._query(query)
  File "D:\Program Files\Python37\lib\site-packages\MySQLdb\cursors.py", line 315, in _query
    db.query(q)
  File "D:\Program Files\Python37\lib\site-packages\MySQLdb\connections.py", line 239, in query
    _mysql.connection.query(self, query)
django.db.utils.IntegrityError: (1062, "Duplicate entry '1582646400' for key 'LAMProcessData_process_r_acquisition_timestamp_a69ae90c_uniq'")
2020-02-25 10:50:11,373 - _run_jobs - 94 - DEBUG - Exiting worker thread
2020-02-25 10:50:21,689 - log_response - 228 - WARNING - Not Found: /favicon.ico
2020-02-25 10:50:22,275 - log_response - 228 - WARNING - Not Found: /favicon.ico
2020-02-25 10:50:22,874 - log_response - 228 - WARNING - Not Found: /favicon.ico
2020-02-25 10:50:23,387 - log_response - 228 - WARNING - Not Found: /favicon.ico
2020-02-25 11:54:39,924 - log_response - 228 - WARNING - Not Found: /favicon.ico
2020-02-25 12:30:34,154 - _real_add_job - 262 - INFO - Added job "regulartime_task (trigger: interval[1 day, 0:00:00], next run at: 2020-02-25 12:30:44.153970)" to job store "default"
2020-02-25 12:30:34,155 - _real_add_job - 262 - INFO - Added job "OpenLog (trigger: cron[hour='0'], next run at: 2020-02-26 00:00:00)" to job store "default"
2020-02-25 12:30:34,155 - _main_loop - 574 - INFO - Scheduler started
2020-02-25 12:30:34,155 - _main_loop - 579 - DEBUG - Looking for jobs to run
2020-02-25 12:30:34,155 - _main_loop - 588 - DEBUG - Next wakeup is due at 2020-02-25 12:30:44.153970 (in 9.998308 seconds)
2020-02-25 12:30:34,175 - <module> - 58 - DEBUG - SendBefore_NotRecive : [<CNCProcessStatus: CNCProcessStatus object (2038721)>]
2020-02-25 12:30:34,176 - <module> - 59 - DEBUG - Waitfor_Recive : [2038721]
2020-02-25 12:30:44,155 - _main_loop - 579 - DEBUG - Looking for jobs to run
2020-02-25 12:30:44,155 - _run_jobs - 69 - DEBUG - Started worker thread
2020-02-25 12:30:44,156 - _run_job - 509 - INFO - Running job "regulartime_task (trigger: interval[1 day, 0:00:00], next run at: 2020-02-25 12:30:44.153970)" (scheduled at 2020-02-25 12:30:44.153970)
2020-02-25 12:30:44,156 - _main_loop - 588 - DEBUG - Next wakeup is due at 2020-02-26 00:00:00 (in 41355.844786 seconds)
2020-02-25 12:30:44,457 - _run_job - 520 - ERROR - Job "regulartime_task (trigger: interval[1 day, 0:00:00], next run at: 2020-02-26 12:30:44.153970)" raised an exception
Traceback (most recent call last):
  File "D:\Program Files\Python37\lib\site-packages\django\db\backends\utils.py", line 84, in _execute
    return self.cursor.execute(sql, params)
  File "D:\Program Files\Python37\lib\site-packages\django\db\backends\mysql\base.py", line 71, in execute
    return self.cursor.execute(query, args)
  File "D:\Program Files\Python37\lib\site-packages\MySQLdb\cursors.py", line 209, in execute
    res = self._query(query)
  File "D:\Program Files\Python37\lib\site-packages\MySQLdb\cursors.py", line 315, in _query
    db.query(q)
  File "D:\Program Files\Python37\lib\site-packages\MySQLdb\connections.py", line 239, in query
    _mysql.connection.query(self, query)
MySQLdb._exceptions.IntegrityError: (1062, "Duplicate entry '1582646400' for key 'LAMProcessData_process_r_acquisition_timestamp_a69ae90c_uniq'")

The above exception was the direct cause of the following exception:

Traceback (most recent call last):
  File "D:\Program Files\Python37\lib\site-packages\apscheduler\scheduler.py", line 512, in _run_job
    retval = job.func(*job.args, **job.kwargs)
  File "E:\1-program\11-LAMDataServer\lamdataserver\LAMProcessData\views.py", line 3997, in regulartime_task
    RT_FineData.Realtime_FineData.init_Tomorrow_rows()
  File "E:\1-program\11-LAMDataServer\lamdataserver\LAMProcessData\process_realtime_finedata.py", line 172, in init_Tomorrow_rows
    _model.objects.bulk_create(insert_data_list)
  File "D:\Program Files\Python37\lib\site-packages\django\db\models\manager.py", line 82, in manager_method
    return getattr(self.get_queryset(), name)(*args, **kwargs)
  File "D:\Program Files\Python37\lib\site-packages\django\db\models\query.py", line 474, in bulk_create
    ids = self._batched_insert(objs_without_pk, fields, batch_size, ignore_conflicts=ignore_conflicts)
  File "D:\Program Files\Python37\lib\site-packages\django\db\models\query.py", line 1211, in _batched_insert
    self._insert(item, fields=fields, using=self.db, ignore_conflicts=ignore_conflicts)
  File "D:\Program Files\Python37\lib\site-packages\django\db\models\query.py", line 1186, in _insert
    return query.get_compiler(using=using).execute_sql(return_id)
  File "D:\Program Files\Python37\lib\site-packages\django\db\models\sql\compiler.py", line 1332, in execute_sql
    cursor.execute(sql, params)
  File "D:\Program Files\Python37\lib\site-packages\django\db\backends\utils.py", line 99, in execute
    return super().execute(sql, params)
  File "D:\Program Files\Python37\lib\site-packages\django\db\backends\utils.py", line 67, in execute
    return self._execute_with_wrappers(sql, params, many=False, executor=self._execute)
  File "D:\Program Files\Python37\lib\site-packages\django\db\backends\utils.py", line 76, in _execute_with_wrappers
    return executor(sql, params, many, context)
  File "D:\Program Files\Python37\lib\site-packages\django\db\backends\utils.py", line 84, in _execute
    return self.cursor.execute(sql, params)
  File "D:\Program Files\Python37\lib\site-packages\django\db\utils.py", line 89, in __exit__
    raise dj_exc_value.with_traceback(traceback) from exc_value
  File "D:\Program Files\Python37\lib\site-packages\django\db\backends\utils.py", line 84, in _execute
    return self.cursor.execute(sql, params)
  File "D:\Program Files\Python37\lib\site-packages\django\db\backends\mysql\base.py", line 71, in execute
    return self.cursor.execute(query, args)
  File "D:\Program Files\Python37\lib\site-packages\MySQLdb\cursors.py", line 209, in execute
    res = self._query(query)
  File "D:\Program Files\Python37\lib\site-packages\MySQLdb\cursors.py", line 315, in _query
    db.query(q)
  File "D:\Program Files\Python37\lib\site-packages\MySQLdb\connections.py", line 239, in query
    _mysql.connection.query(self, query)
django.db.utils.IntegrityError: (1062, "Duplicate entry '1582646400' for key 'LAMProcessData_process_r_acquisition_timestamp_a69ae90c_uniq'")
2020-02-25 12:30:45,459 - _run_jobs - 94 - DEBUG - Exiting worker thread
2020-02-25 12:34:11,921 - _real_add_job - 262 - INFO - Added job "regulartime_task (trigger: interval[1 day, 0:00:00], next run at: 2020-02-25 12:34:21.920606)" to job store "default"
2020-02-25 12:34:11,921 - _real_add_job - 262 - INFO - Added job "OpenLog (trigger: cron[hour='0'], next run at: 2020-02-26 00:00:00)" to job store "default"
2020-02-25 12:34:11,922 - _main_loop - 574 - INFO - Scheduler started
2020-02-25 12:34:11,922 - _main_loop - 579 - DEBUG - Looking for jobs to run
2020-02-25 12:34:11,922 - _main_loop - 588 - DEBUG - Next wakeup is due at 2020-02-25 12:34:21.920606 (in 9.998327 seconds)
2020-02-25 12:34:11,931 - <module> - 58 - DEBUG - SendBefore_NotRecive : [<CNCProcessStatus: CNCProcessStatus object (2038721)>]
2020-02-25 12:34:11,931 - <module> - 59 - DEBUG - Waitfor_Recive : [2038721]
2020-02-25 12:34:21,922 - _main_loop - 579 - DEBUG - Looking for jobs to run
2020-02-25 12:34:21,922 - _run_jobs - 69 - DEBUG - Started worker thread
2020-02-25 12:34:21,922 - _run_job - 509 - INFO - Running job "regulartime_task (trigger: interval[1 day, 0:00:00], next run at: 2020-02-25 12:34:21.920606)" (scheduled at 2020-02-25 12:34:21.920606)
2020-02-25 12:34:21,923 - _main_loop - 588 - DEBUG - Next wakeup is due at 2020-02-26 00:00:00 (in 41138.077917 seconds)
2020-02-25 12:34:22,251 - _run_job - 520 - ERROR - Job "regulartime_task (trigger: interval[1 day, 0:00:00], next run at: 2020-02-26 12:34:21.920606)" raised an exception
Traceback (most recent call last):
  File "D:\Program Files\Python37\lib\site-packages\django\db\backends\utils.py", line 84, in _execute
    return self.cursor.execute(sql, params)
  File "D:\Program Files\Python37\lib\site-packages\django\db\backends\mysql\base.py", line 71, in execute
    return self.cursor.execute(query, args)
  File "D:\Program Files\Python37\lib\site-packages\MySQLdb\cursors.py", line 209, in execute
    res = self._query(query)
  File "D:\Program Files\Python37\lib\site-packages\MySQLdb\cursors.py", line 315, in _query
    db.query(q)
  File "D:\Program Files\Python37\lib\site-packages\MySQLdb\connections.py", line 239, in query
    _mysql.connection.query(self, query)
MySQLdb._exceptions.IntegrityError: (1062, "Duplicate entry '1582646400' for key 'LAMProcessData_process_r_acquisition_timestamp_a69ae90c_uniq'")

The above exception was the direct cause of the following exception:

Traceback (most recent call last):
  File "D:\Program Files\Python37\lib\site-packages\apscheduler\scheduler.py", line 512, in _run_job
    retval = job.func(*job.args, **job.kwargs)
  File "E:\1-program\11-LAMDataServer\lamdataserver\LAMProcessData\views.py", line 3997, in regulartime_task
    RT_FineData.Realtime_FineData.init_Tomorrow_rows()
  File "E:\1-program\11-LAMDataServer\lamdataserver\LAMProcessData\process_realtime_finedata.py", line 172, in init_Tomorrow_rows
    _model.objects.bulk_create(insert_data_list)
  File "D:\Program Files\Python37\lib\site-packages\django\db\models\manager.py", line 82, in manager_method
    return getattr(self.get_queryset(), name)(*args, **kwargs)
  File "D:\Program Files\Python37\lib\site-packages\django\db\models\query.py", line 474, in bulk_create
    ids = self._batched_insert(objs_without_pk, fields, batch_size, ignore_conflicts=ignore_conflicts)
  File "D:\Program Files\Python37\lib\site-packages\django\db\models\query.py", line 1211, in _batched_insert
    self._insert(item, fields=fields, using=self.db, ignore_conflicts=ignore_conflicts)
  File "D:\Program Files\Python37\lib\site-packages\django\db\models\query.py", line 1186, in _insert
    return query.get_compiler(using=using).execute_sql(return_id)
  File "D:\Program Files\Python37\lib\site-packages\django\db\models\sql\compiler.py", line 1332, in execute_sql
    cursor.execute(sql, params)
  File "D:\Program Files\Python37\lib\site-packages\django\db\backends\utils.py", line 99, in execute
    return super().execute(sql, params)
  File "D:\Program Files\Python37\lib\site-packages\django\db\backends\utils.py", line 67, in execute
    return self._execute_with_wrappers(sql, params, many=False, executor=self._execute)
  File "D:\Program Files\Python37\lib\site-packages\django\db\backends\utils.py", line 76, in _execute_with_wrappers
    return executor(sql, params, many, context)
  File "D:\Program Files\Python37\lib\site-packages\django\db\backends\utils.py", line 84, in _execute
    return self.cursor.execute(sql, params)
  File "D:\Program Files\Python37\lib\site-packages\django\db\utils.py", line 89, in __exit__
    raise dj_exc_value.with_traceback(traceback) from exc_value
  File "D:\Program Files\Python37\lib\site-packages\django\db\backends\utils.py", line 84, in _execute
    return self.cursor.execute(sql, params)
  File "D:\Program Files\Python37\lib\site-packages\django\db\backends\mysql\base.py", line 71, in execute
    return self.cursor.execute(query, args)
  File "D:\Program Files\Python37\lib\site-packages\MySQLdb\cursors.py", line 209, in execute
    res = self._query(query)
  File "D:\Program Files\Python37\lib\site-packages\MySQLdb\cursors.py", line 315, in _query
    db.query(q)
  File "D:\Program Files\Python37\lib\site-packages\MySQLdb\connections.py", line 239, in query
    _mysql.connection.query(self, query)
django.db.utils.IntegrityError: (1062, "Duplicate entry '1582646400' for key 'LAMProcessData_process_r_acquisition_timestamp_a69ae90c_uniq'")
2020-02-25 12:34:23,257 - _run_jobs - 94 - DEBUG - Exiting worker thread
2020-02-25 12:47:56,384 - _real_add_job - 262 - INFO - Added job "regulartime_task (trigger: interval[1 day, 0:00:00], next run at: 2020-02-25 12:48:06.383454)" to job store "default"
2020-02-25 12:47:56,384 - _real_add_job - 262 - INFO - Added job "OpenLog (trigger: cron[hour='0'], next run at: 2020-02-26 00:00:00)" to job store "default"
2020-02-25 12:47:56,385 - _main_loop - 574 - INFO - Scheduler started
2020-02-25 12:47:56,385 - _main_loop - 579 - DEBUG - Looking for jobs to run
2020-02-25 12:47:56,385 - _main_loop - 588 - DEBUG - Next wakeup is due at 2020-02-25 12:48:06.383454 (in 9.998005 seconds)
2020-02-25 12:47:56,392 - <module> - 58 - DEBUG - SendBefore_NotRecive : [<CNCProcessStatus: CNCProcessStatus object (2038721)>]
2020-02-25 12:47:56,392 - <module> - 59 - DEBUG - Waitfor_Recive : [2038721]
2020-02-25 12:48:06,384 - _main_loop - 579 - DEBUG - Looking for jobs to run
2020-02-25 12:48:06,386 - _run_jobs - 69 - DEBUG - Started worker thread
2020-02-25 12:48:06,386 - _main_loop - 588 - DEBUG - Next wakeup is due at 2020-02-26 00:00:00 (in 40313.615403 seconds)
2020-02-25 12:48:06,387 - _run_job - 509 - INFO - Running job "regulartime_task (trigger: interval[1 day, 0:00:00], next run at: 2020-02-26 12:48:06.383454)" (scheduled at 2020-02-25 12:48:06.383454)
2020-02-25 12:48:06,707 - _run_job - 520 - ERROR - Job "regulartime_task (trigger: interval[1 day, 0:00:00], next run at: 2020-02-26 12:48:06.383454)" raised an exception
Traceback (most recent call last):
  File "D:\Program Files\Python37\lib\site-packages\django\db\backends\utils.py", line 84, in _execute
    return self.cursor.execute(sql, params)
  File "D:\Program Files\Python37\lib\site-packages\django\db\backends\mysql\base.py", line 71, in execute
    return self.cursor.execute(query, args)
  File "D:\Program Files\Python37\lib\site-packages\MySQLdb\cursors.py", line 209, in execute
    res = self._query(query)
  File "D:\Program Files\Python37\lib\site-packages\MySQLdb\cursors.py", line 315, in _query
    db.query(q)
  File "D:\Program Files\Python37\lib\site-packages\MySQLdb\connections.py", line 239, in query
    _mysql.connection.query(self, query)
MySQLdb._exceptions.IntegrityError: (1062, "Duplicate entry '1582646400' for key 'LAMProcessData_process_r_acquisition_timestamp_a69ae90c_uniq'")

The above exception was the direct cause of the following exception:

Traceback (most recent call last):
  File "D:\Program Files\Python37\lib\site-packages\apscheduler\scheduler.py", line 512, in _run_job
    retval = job.func(*job.args, **job.kwargs)
  File "E:\1-program\11-LAMDataServer\lamdataserver\LAMProcessData\views.py", line 3997, in regulartime_task
    RT_FineData.Realtime_FineData.init_Tomorrow_rows()
  File "E:\1-program\11-LAMDataServer\lamdataserver\LAMProcessData\process_realtime_finedata.py", line 172, in init_Tomorrow_rows
    _model.objects.bulk_create(insert_data_list)
  File "D:\Program Files\Python37\lib\site-packages\django\db\models\manager.py", line 82, in manager_method
    return getattr(self.get_queryset(), name)(*args, **kwargs)
  File "D:\Program Files\Python37\lib\site-packages\django\db\models\query.py", line 474, in bulk_create
    ids = self._batched_insert(objs_without_pk, fields, batch_size, ignore_conflicts=ignore_conflicts)
  File "D:\Program Files\Python37\lib\site-packages\django\db\models\query.py", line 1211, in _batched_insert
    self._insert(item, fields=fields, using=self.db, ignore_conflicts=ignore_conflicts)
  File "D:\Program Files\Python37\lib\site-packages\django\db\models\query.py", line 1186, in _insert
    return query.get_compiler(using=using).execute_sql(return_id)
  File "D:\Program Files\Python37\lib\site-packages\django\db\models\sql\compiler.py", line 1332, in execute_sql
    cursor.execute(sql, params)
  File "D:\Program Files\Python37\lib\site-packages\django\db\backends\utils.py", line 99, in execute
    return super().execute(sql, params)
  File "D:\Program Files\Python37\lib\site-packages\django\db\backends\utils.py", line 67, in execute
    return self._execute_with_wrappers(sql, params, many=False, executor=self._execute)
  File "D:\Program Files\Python37\lib\site-packages\django\db\backends\utils.py", line 76, in _execute_with_wrappers
    return executor(sql, params, many, context)
  File "D:\Program Files\Python37\lib\site-packages\django\db\backends\utils.py", line 84, in _execute
    return self.cursor.execute(sql, params)
  File "D:\Program Files\Python37\lib\site-packages\django\db\utils.py", line 89, in __exit__
    raise dj_exc_value.with_traceback(traceback) from exc_value
  File "D:\Program Files\Python37\lib\site-packages\django\db\backends\utils.py", line 84, in _execute
    return self.cursor.execute(sql, params)
  File "D:\Program Files\Python37\lib\site-packages\django\db\backends\mysql\base.py", line 71, in execute
    return self.cursor.execute(query, args)
  File "D:\Program Files\Python37\lib\site-packages\MySQLdb\cursors.py", line 209, in execute
    res = self._query(query)
  File "D:\Program Files\Python37\lib\site-packages\MySQLdb\cursors.py", line 315, in _query
    db.query(q)
  File "D:\Program Files\Python37\lib\site-packages\MySQLdb\connections.py", line 239, in query
    _mysql.connection.query(self, query)
django.db.utils.IntegrityError: (1062, "Duplicate entry '1582646400' for key 'LAMProcessData_process_r_acquisition_timestamp_a69ae90c_uniq'")
2020-02-25 12:48:07,710 - _run_jobs - 94 - DEBUG - Exiting worker thread
2020-02-25 12:49:21,848 - _real_add_job - 262 - INFO - Added job "regulartime_task (trigger: interval[1 day, 0:00:00], next run at: 2020-02-25 12:49:31.847995)" to job store "default"
2020-02-25 12:49:21,849 - _real_add_job - 262 - INFO - Added job "OpenLog (trigger: cron[hour='0'], next run at: 2020-02-26 00:00:00)" to job store "default"
2020-02-25 12:49:21,850 - _main_loop - 574 - INFO - Scheduler started
2020-02-25 12:49:21,850 - _main_loop - 579 - DEBUG - Looking for jobs to run
2020-02-25 12:49:21,850 - _main_loop - 588 - DEBUG - Next wakeup is due at 2020-02-25 12:49:31.847995 (in 9.997061 seconds)
2020-02-25 12:49:21,862 - <module> - 58 - DEBUG - SendBefore_NotRecive : [<CNCProcessStatus: CNCProcessStatus object (2038721)>]
2020-02-25 12:49:21,862 - <module> - 59 - DEBUG - Waitfor_Recive : [2038721]
2020-02-25 12:49:31,851 - _main_loop - 579 - DEBUG - Looking for jobs to run
2020-02-25 12:49:31,856 - _run_jobs - 69 - DEBUG - Started worker thread
2020-02-25 12:49:31,856 - _run_job - 509 - INFO - Running job "regulartime_task (trigger: interval[1 day, 0:00:00], next run at: 2020-02-25 12:49:31.847995)" (scheduled at 2020-02-25 12:49:31.847995)
2020-02-25 12:49:31,863 - _main_loop - 588 - DEBUG - Next wakeup is due at 2020-02-26 00:00:00 (in 40228.148609 seconds)
2020-02-25 12:49:33,642 - _run_job - 520 - ERROR - Job "regulartime_task (trigger: interval[1 day, 0:00:00], next run at: 2020-02-26 12:49:31.847995)" raised an exception
Traceback (most recent call last):
  File "D:\Program Files\Python37\lib\site-packages\django\db\backends\utils.py", line 84, in _execute
    return self.cursor.execute(sql, params)
  File "D:\Program Files\Python37\lib\site-packages\django\db\backends\mysql\base.py", line 71, in execute
    return self.cursor.execute(query, args)
  File "D:\Program Files\Python37\lib\site-packages\MySQLdb\cursors.py", line 209, in execute
    res = self._query(query)
  File "D:\Program Files\Python37\lib\site-packages\MySQLdb\cursors.py", line 315, in _query
    db.query(q)
  File "D:\Program Files\Python37\lib\site-packages\MySQLdb\connections.py", line 239, in query
    _mysql.connection.query(self, query)
MySQLdb._exceptions.IntegrityError: (1062, "Duplicate entry '1582646400' for key 'LAMProcessData_process_r_acquisition_timestamp_a69ae90c_uniq'")

The above exception was the direct cause of the following exception:

Traceback (most recent call last):
  File "D:\Program Files\Python37\lib\site-packages\apscheduler\scheduler.py", line 512, in _run_job
    retval = job.func(*job.args, **job.kwargs)
  File "E:\1-program\11-LAMDataServer\lamdataserver\LAMProcessData\views.py", line 3999, in regulartime_task
    RT_FineData.Realtime_FineData.init_Tomorrow_rows()
  File "E:\1-program\11-LAMDataServer\lamdataserver\LAMProcessData\process_realtime_finedata.py", line 172, in init_Tomorrow_rows
    _model.objects.bulk_create(insert_data_list)
  File "D:\Program Files\Python37\lib\site-packages\django\db\models\manager.py", line 82, in manager_method
    return getattr(self.get_queryset(), name)(*args, **kwargs)
  File "D:\Program Files\Python37\lib\site-packages\django\db\models\query.py", line 474, in bulk_create
    ids = self._batched_insert(objs_without_pk, fields, batch_size, ignore_conflicts=ignore_conflicts)
  File "D:\Program Files\Python37\lib\site-packages\django\db\models\query.py", line 1211, in _batched_insert
    self._insert(item, fields=fields, using=self.db, ignore_conflicts=ignore_conflicts)
  File "D:\Program Files\Python37\lib\site-packages\django\db\models\query.py", line 1186, in _insert
    return query.get_compiler(using=using).execute_sql(return_id)
  File "D:\Program Files\Python37\lib\site-packages\django\db\models\sql\compiler.py", line 1332, in execute_sql
    cursor.execute(sql, params)
  File "D:\Program Files\Python37\lib\site-packages\django\db\backends\utils.py", line 99, in execute
    return super().execute(sql, params)
  File "D:\Program Files\Python37\lib\site-packages\django\db\backends\utils.py", line 67, in execute
    return self._execute_with_wrappers(sql, params, many=False, executor=self._execute)
  File "D:\Program Files\Python37\lib\site-packages\django\db\backends\utils.py", line 76, in _execute_with_wrappers
    return executor(sql, params, many, context)
  File "D:\Program Files\Python37\lib\site-packages\django\db\backends\utils.py", line 84, in _execute
    return self.cursor.execute(sql, params)
  File "D:\Program Files\Python37\lib\site-packages\django\db\utils.py", line 89, in __exit__
    raise dj_exc_value.with_traceback(traceback) from exc_value
  File "D:\Program Files\Python37\lib\site-packages\django\db\backends\utils.py", line 84, in _execute
    return self.cursor.execute(sql, params)
  File "D:\Program Files\Python37\lib\site-packages\django\db\backends\mysql\base.py", line 71, in execute
    return self.cursor.execute(query, args)
  File "D:\Program Files\Python37\lib\site-packages\MySQLdb\cursors.py", line 209, in execute
    res = self._query(query)
  File "D:\Program Files\Python37\lib\site-packages\MySQLdb\cursors.py", line 315, in _query
    db.query(q)
  File "D:\Program Files\Python37\lib\site-packages\MySQLdb\connections.py", line 239, in query
    _mysql.connection.query(self, query)
django.db.utils.IntegrityError: (1062, "Duplicate entry '1582646400' for key 'LAMProcessData_process_r_acquisition_timestamp_a69ae90c_uniq'")
2020-02-25 12:49:34,893 - _run_jobs - 94 - DEBUG - Exiting worker thread
2020-02-25 12:49:54,745 - _real_add_job - 262 - INFO - Added job "regulartime_task (trigger: interval[1 day, 0:00:00], next run at: 2020-02-25 12:50:04.743827)" to job store "default"
2020-02-25 12:49:54,745 - _real_add_job - 262 - INFO - Added job "OpenLog (trigger: cron[hour='0'], next run at: 2020-02-26 00:00:00)" to job store "default"
2020-02-25 12:49:54,746 - _main_loop - 574 - INFO - Scheduler started
2020-02-25 12:49:54,746 - _main_loop - 579 - DEBUG - Looking for jobs to run
2020-02-25 12:49:54,746 - _main_loop - 588 - DEBUG - Next wakeup is due at 2020-02-25 12:50:04.743827 (in 9.997093 seconds)
2020-02-25 12:49:54,758 - <module> - 58 - DEBUG - SendBefore_NotRecive : [<CNCProcessStatus: CNCProcessStatus object (2038721)>]
2020-02-25 12:49:54,758 - <module> - 59 - DEBUG - Waitfor_Recive : [2038721]
2020-02-25 12:50:04,745 - _main_loop - 579 - DEBUG - Looking for jobs to run
2020-02-25 12:50:04,746 - _run_jobs - 69 - DEBUG - Started worker thread
2020-02-25 12:50:04,747 - _run_job - 509 - INFO - Running job "regulartime_task (trigger: interval[1 day, 0:00:00], next run at: 2020-02-25 12:50:04.743827)" (scheduled at 2020-02-25 12:50:04.743827)
2020-02-25 12:50:04,748 - _main_loop - 588 - DEBUG - Next wakeup is due at 2020-02-26 00:00:00 (in 40195.254846 seconds)
2020-02-25 12:50:05,698 - _run_job - 520 - ERROR - Job "regulartime_task (trigger: interval[1 day, 0:00:00], next run at: 2020-02-26 12:50:04.743827)" raised an exception
Traceback (most recent call last):
  File "D:\Program Files\Python37\lib\site-packages\django\db\backends\utils.py", line 84, in _execute
    return self.cursor.execute(sql, params)
  File "D:\Program Files\Python37\lib\site-packages\django\db\backends\mysql\base.py", line 71, in execute
    return self.cursor.execute(query, args)
  File "D:\Program Files\Python37\lib\site-packages\MySQLdb\cursors.py", line 209, in execute
    res = self._query(query)
  File "D:\Program Files\Python37\lib\site-packages\MySQLdb\cursors.py", line 315, in _query
    db.query(q)
  File "D:\Program Files\Python37\lib\site-packages\MySQLdb\connections.py", line 239, in query
    _mysql.connection.query(self, query)
MySQLdb._exceptions.IntegrityError: (1062, "Duplicate entry '1582646400' for key 'LAMProcessData_process_r_acquisition_timestamp_a69ae90c_uniq'")

The above exception was the direct cause of the following exception:

Traceback (most recent call last):
  File "D:\Program Files\Python37\lib\site-packages\apscheduler\scheduler.py", line 512, in _run_job
    retval = job.func(*job.args, **job.kwargs)
  File "E:\1-program\11-LAMDataServer\lamdataserver\LAMProcessData\views.py", line 3999, in regulartime_task
    RT_FineData.Realtime_FineData.init_Tomorrow_rows()
  File "E:\1-program\11-LAMDataServer\lamdataserver\LAMProcessData\process_realtime_finedata.py", line 172, in init_Tomorrow_rows
    _model.objects.bulk_create(insert_data_list)
  File "D:\Program Files\Python37\lib\site-packages\django\db\models\manager.py", line 82, in manager_method
    return getattr(self.get_queryset(), name)(*args, **kwargs)
  File "D:\Program Files\Python37\lib\site-packages\django\db\models\query.py", line 474, in bulk_create
    ids = self._batched_insert(objs_without_pk, fields, batch_size, ignore_conflicts=ignore_conflicts)
  File "D:\Program Files\Python37\lib\site-packages\django\db\models\query.py", line 1211, in _batched_insert
    self._insert(item, fields=fields, using=self.db, ignore_conflicts=ignore_conflicts)
  File "D:\Program Files\Python37\lib\site-packages\django\db\models\query.py", line 1186, in _insert
    return query.get_compiler(using=using).execute_sql(return_id)
  File "D:\Program Files\Python37\lib\site-packages\django\db\models\sql\compiler.py", line 1332, in execute_sql
    cursor.execute(sql, params)
  File "D:\Program Files\Python37\lib\site-packages\django\db\backends\utils.py", line 99, in execute
    return super().execute(sql, params)
  File "D:\Program Files\Python37\lib\site-packages\django\db\backends\utils.py", line 67, in execute
    return self._execute_with_wrappers(sql, params, many=False, executor=self._execute)
  File "D:\Program Files\Python37\lib\site-packages\django\db\backends\utils.py", line 76, in _execute_with_wrappers
    return executor(sql, params, many, context)
  File "D:\Program Files\Python37\lib\site-packages\django\db\backends\utils.py", line 84, in _execute
    return self.cursor.execute(sql, params)
  File "D:\Program Files\Python37\lib\site-packages\django\db\utils.py", line 89, in __exit__
    raise dj_exc_value.with_traceback(traceback) from exc_value
  File "D:\Program Files\Python37\lib\site-packages\django\db\backends\utils.py", line 84, in _execute
    return self.cursor.execute(sql, params)
  File "D:\Program Files\Python37\lib\site-packages\django\db\backends\mysql\base.py", line 71, in execute
    return self.cursor.execute(query, args)
  File "D:\Program Files\Python37\lib\site-packages\MySQLdb\cursors.py", line 209, in execute
    res = self._query(query)
  File "D:\Program Files\Python37\lib\site-packages\MySQLdb\cursors.py", line 315, in _query
    db.query(q)
  File "D:\Program Files\Python37\lib\site-packages\MySQLdb\connections.py", line 239, in query
    _mysql.connection.query(self, query)
django.db.utils.IntegrityError: (1062, "Duplicate entry '1582646400' for key 'LAMProcessData_process_r_acquisition_timestamp_a69ae90c_uniq'")
2020-02-25 12:50:06,714 - _run_jobs - 94 - DEBUG - Exiting worker thread
2020-02-25 12:54:08,760 - trigger_reload - 203 - INFO - E:\1-program\11-LAMDataServer\lamdataserver\LAMProcessData\views.py changed, reloading.
2020-02-25 12:54:08,762 - shutdown - 111 - INFO - Shutting down thread pool
2020-02-25 12:54:12,440 - _real_add_job - 262 - INFO - Added job "regulartime_task (trigger: interval[1 day, 0:00:00], next run at: 2020-02-25 12:54:22.437708)" to job store "default"
2020-02-25 12:54:12,440 - _real_add_job - 262 - INFO - Added job "OpenLog (trigger: cron[hour='0'], next run at: 2020-02-26 00:00:00)" to job store "default"
2020-02-25 12:54:12,469 - _main_loop - 574 - INFO - Scheduler started
2020-02-25 12:54:12,470 - _main_loop - 579 - DEBUG - Looking for jobs to run
2020-02-25 12:54:12,470 - _main_loop - 588 - DEBUG - Next wakeup is due at 2020-02-25 12:54:22.437708 (in 9.967089 seconds)
2020-02-25 12:54:12,772 - <module> - 58 - DEBUG - SendBefore_NotRecive : [<CNCProcessStatus: CNCProcessStatus object (2038721)>]
2020-02-25 12:54:12,772 - <module> - 59 - DEBUG - Waitfor_Recive : [2038721]
2020-02-25 12:54:22,439 - _main_loop - 579 - DEBUG - Looking for jobs to run
2020-02-25 12:54:22,443 - _run_jobs - 69 - DEBUG - Started worker thread
2020-02-25 12:54:22,444 - _main_loop - 588 - DEBUG - Next wakeup is due at 2020-02-26 00:00:00 (in 39937.559272 seconds)
2020-02-25 12:54:22,445 - _run_job - 509 - INFO - Running job "regulartime_task (trigger: interval[1 day, 0:00:00], next run at: 2020-02-26 12:54:22.437708)" (scheduled at 2020-02-25 12:54:22.437708)
2020-02-25 12:54:23,411 - _run_job - 520 - ERROR - Job "regulartime_task (trigger: interval[1 day, 0:00:00], next run at: 2020-02-26 12:54:22.437708)" raised an exception
Traceback (most recent call last):
  File "D:\Program Files\Python37\lib\site-packages\django\db\backends\utils.py", line 84, in _execute
    return self.cursor.execute(sql, params)
  File "D:\Program Files\Python37\lib\site-packages\django\db\backends\mysql\base.py", line 71, in execute
    return self.cursor.execute(query, args)
  File "D:\Program Files\Python37\lib\site-packages\MySQLdb\cursors.py", line 209, in execute
    res = self._query(query)
  File "D:\Program Files\Python37\lib\site-packages\MySQLdb\cursors.py", line 315, in _query
    db.query(q)
  File "D:\Program Files\Python37\lib\site-packages\MySQLdb\connections.py", line 239, in query
    _mysql.connection.query(self, query)
MySQLdb._exceptions.IntegrityError: (1062, "Duplicate entry '1582646400' for key 'LAMProcessData_process_r_acquisition_timestamp_a69ae90c_uniq'")

The above exception was the direct cause of the following exception:

Traceback (most recent call last):
  File "D:\Program Files\Python37\lib\site-packages\apscheduler\scheduler.py", line 512, in _run_job
    retval = job.func(*job.args, **job.kwargs)
  File "E:\1-program\11-LAMDataServer\lamdataserver\LAMProcessData\views.py", line 4001, in regulartime_task
    RT_FineData.Realtime_FineData.init_Tomorrow_rows()
  File "E:\1-program\11-LAMDataServer\lamdataserver\LAMProcessData\process_realtime_finedata.py", line 172, in init_Tomorrow_rows
    _model.objects.bulk_create(insert_data_list)
  File "D:\Program Files\Python37\lib\site-packages\django\db\models\manager.py", line 82, in manager_method
    return getattr(self.get_queryset(), name)(*args, **kwargs)
  File "D:\Program Files\Python37\lib\site-packages\django\db\models\query.py", line 474, in bulk_create
    ids = self._batched_insert(objs_without_pk, fields, batch_size, ignore_conflicts=ignore_conflicts)
  File "D:\Program Files\Python37\lib\site-packages\django\db\models\query.py", line 1211, in _batched_insert
    self._insert(item, fields=fields, using=self.db, ignore_conflicts=ignore_conflicts)
  File "D:\Program Files\Python37\lib\site-packages\django\db\models\query.py", line 1186, in _insert
    return query.get_compiler(using=using).execute_sql(return_id)
  File "D:\Program Files\Python37\lib\site-packages\django\db\models\sql\compiler.py", line 1332, in execute_sql
    cursor.execute(sql, params)
  File "D:\Program Files\Python37\lib\site-packages\django\db\backends\utils.py", line 99, in execute
    return super().execute(sql, params)
  File "D:\Program Files\Python37\lib\site-packages\django\db\backends\utils.py", line 67, in execute
    return self._execute_with_wrappers(sql, params, many=False, executor=self._execute)
  File "D:\Program Files\Python37\lib\site-packages\django\db\backends\utils.py", line 76, in _execute_with_wrappers
    return executor(sql, params, many, context)
  File "D:\Program Files\Python37\lib\site-packages\django\db\backends\utils.py", line 84, in _execute
    return self.cursor.execute(sql, params)
  File "D:\Program Files\Python37\lib\site-packages\django\db\utils.py", line 89, in __exit__
    raise dj_exc_value.with_traceback(traceback) from exc_value
  File "D:\Program Files\Python37\lib\site-packages\django\db\backends\utils.py", line 84, in _execute
    return self.cursor.execute(sql, params)
  File "D:\Program Files\Python37\lib\site-packages\django\db\backends\mysql\base.py", line 71, in execute
    return self.cursor.execute(query, args)
  File "D:\Program Files\Python37\lib\site-packages\MySQLdb\cursors.py", line 209, in execute
    res = self._query(query)
  File "D:\Program Files\Python37\lib\site-packages\MySQLdb\cursors.py", line 315, in _query
    db.query(q)
  File "D:\Program Files\Python37\lib\site-packages\MySQLdb\connections.py", line 239, in query
    _mysql.connection.query(self, query)
django.db.utils.IntegrityError: (1062, "Duplicate entry '1582646400' for key 'LAMProcessData_process_r_acquisition_timestamp_a69ae90c_uniq'")
2020-02-25 12:54:24,433 - _run_jobs - 94 - DEBUG - Exiting worker thread
2020-02-25 13:01:15,004 - trigger_reload - 203 - INFO - E:\1-program\11-LAMDataServer\lamdataserver\LAMProcessData\views.py changed, reloading.
2020-02-25 13:01:15,007 - shutdown - 111 - INFO - Shutting down thread pool
2020-02-25 13:01:17,817 - _real_add_job - 262 - INFO - Added job "regulartime_task (trigger: interval[1 day, 0:00:00], next run at: 2020-02-25 13:01:27.815899)" to job store "default"
2020-02-25 13:01:17,817 - _real_add_job - 262 - INFO - Added job "OpenLog (trigger: cron[hour='0'], next run at: 2020-02-26 00:00:00)" to job store "default"
2020-02-25 13:01:17,818 - _main_loop - 574 - INFO - Scheduler started
2020-02-25 13:01:17,818 - _main_loop - 579 - DEBUG - Looking for jobs to run
2020-02-25 13:01:17,818 - _main_loop - 588 - DEBUG - Next wakeup is due at 2020-02-25 13:01:27.815899 (in 9.996955 seconds)
2020-02-25 13:01:17,830 - <module> - 58 - DEBUG - SendBefore_NotRecive : [<CNCProcessStatus: CNCProcessStatus object (2038721)>]
2020-02-25 13:01:17,831 - <module> - 59 - DEBUG - Waitfor_Recive : [2038721]
2020-02-25 13:01:27,817 - _main_loop - 579 - DEBUG - Looking for jobs to run
2020-02-25 13:01:27,818 - _run_jobs - 69 - DEBUG - Started worker thread
2020-02-25 13:01:27,818 - _run_job - 509 - INFO - Running job "regulartime_task (trigger: interval[1 day, 0:00:00], next run at: 2020-02-25 13:01:27.815899)" (scheduled at 2020-02-25 13:01:27.815899)
2020-02-25 13:01:27,819 - _main_loop - 588 - DEBUG - Next wakeup is due at 2020-02-26 00:00:00 (in 39512.182221 seconds)
2020-02-25 13:01:28,796 - _run_job - 520 - ERROR - Job "regulartime_task (trigger: interval[1 day, 0:00:00], next run at: 2020-02-26 13:01:27.815899)" raised an exception
Traceback (most recent call last):
  File "D:\Program Files\Python37\lib\site-packages\django\db\backends\utils.py", line 84, in _execute
    return self.cursor.execute(sql, params)
  File "D:\Program Files\Python37\lib\site-packages\django\db\backends\mysql\base.py", line 71, in execute
    return self.cursor.execute(query, args)
  File "D:\Program Files\Python37\lib\site-packages\MySQLdb\cursors.py", line 209, in execute
    res = self._query(query)
  File "D:\Program Files\Python37\lib\site-packages\MySQLdb\cursors.py", line 315, in _query
    db.query(q)
  File "D:\Program Files\Python37\lib\site-packages\MySQLdb\connections.py", line 239, in query
    _mysql.connection.query(self, query)
MySQLdb._exceptions.IntegrityError: (1062, "Duplicate entry '1582646400' for key 'LAMProcessData_process_r_acquisition_timestamp_a69ae90c_uniq'")

The above exception was the direct cause of the following exception:

Traceback (most recent call last):
  File "D:\Program Files\Python37\lib\site-packages\apscheduler\scheduler.py", line 512, in _run_job
    retval = job.func(*job.args, **job.kwargs)
  File "E:\1-program\11-LAMDataServer\lamdataserver\LAMProcessData\views.py", line 4009, in regulartime_task
    RT_FineData.Realtime_FineData.init_Tomorrow_rows()
  File "E:\1-program\11-LAMDataServer\lamdataserver\LAMProcessData\process_realtime_finedata.py", line 172, in init_Tomorrow_rows
    _model.objects.bulk_create(insert_data_list)
  File "D:\Program Files\Python37\lib\site-packages\django\db\models\manager.py", line 82, in manager_method
    return getattr(self.get_queryset(), name)(*args, **kwargs)
  File "D:\Program Files\Python37\lib\site-packages\django\db\models\query.py", line 474, in bulk_create
    ids = self._batched_insert(objs_without_pk, fields, batch_size, ignore_conflicts=ignore_conflicts)
  File "D:\Program Files\Python37\lib\site-packages\django\db\models\query.py", line 1211, in _batched_insert
    self._insert(item, fields=fields, using=self.db, ignore_conflicts=ignore_conflicts)
  File "D:\Program Files\Python37\lib\site-packages\django\db\models\query.py", line 1186, in _insert
    return query.get_compiler(using=using).execute_sql(return_id)
  File "D:\Program Files\Python37\lib\site-packages\django\db\models\sql\compiler.py", line 1332, in execute_sql
    cursor.execute(sql, params)
  File "D:\Program Files\Python37\lib\site-packages\django\db\backends\utils.py", line 99, in execute
    return super().execute(sql, params)
  File "D:\Program Files\Python37\lib\site-packages\django\db\backends\utils.py", line 67, in execute
    return self._execute_with_wrappers(sql, params, many=False, executor=self._execute)
  File "D:\Program Files\Python37\lib\site-packages\django\db\backends\utils.py", line 76, in _execute_with_wrappers
    return executor(sql, params, many, context)
  File "D:\Program Files\Python37\lib\site-packages\django\db\backends\utils.py", line 84, in _execute
    return self.cursor.execute(sql, params)
  File "D:\Program Files\Python37\lib\site-packages\django\db\utils.py", line 89, in __exit__
    raise dj_exc_value.with_traceback(traceback) from exc_value
  File "D:\Program Files\Python37\lib\site-packages\django\db\backends\utils.py", line 84, in _execute
    return self.cursor.execute(sql, params)
  File "D:\Program Files\Python37\lib\site-packages\django\db\backends\mysql\base.py", line 71, in execute
    return self.cursor.execute(query, args)
  File "D:\Program Files\Python37\lib\site-packages\MySQLdb\cursors.py", line 209, in execute
    res = self._query(query)
  File "D:\Program Files\Python37\lib\site-packages\MySQLdb\cursors.py", line 315, in _query
    db.query(q)
  File "D:\Program Files\Python37\lib\site-packages\MySQLdb\connections.py", line 239, in query
    _mysql.connection.query(self, query)
django.db.utils.IntegrityError: (1062, "Duplicate entry '1582646400' for key 'LAMProcessData_process_r_acquisition_timestamp_a69ae90c_uniq'")
2020-02-25 13:01:29,805 - _run_jobs - 94 - DEBUG - Exiting worker thread
2020-02-25 13:02:58,253 - trigger_reload - 203 - INFO - E:\1-program\11-LAMDataServer\lamdataserver\LAMProcessData\views.py changed, reloading.
2020-02-25 13:02:58,254 - shutdown - 111 - INFO - Shutting down thread pool
2020-02-25 13:02:59,953 - _real_add_job - 262 - INFO - Added job "regulartime_task (trigger: interval[1 day, 0:00:00], next run at: 2020-02-25 13:03:09.952592)" to job store "default"
2020-02-25 13:02:59,953 - _real_add_job - 262 - INFO - Added job "OpenLog (trigger: cron[hour='0'], next run at: 2020-02-26 00:00:00)" to job store "default"
2020-02-25 13:02:59,954 - _main_loop - 574 - INFO - Scheduler started
2020-02-25 13:02:59,954 - _main_loop - 579 - DEBUG - Looking for jobs to run
2020-02-25 13:02:59,954 - _main_loop - 588 - DEBUG - Next wakeup is due at 2020-02-25 13:03:09.952592 (in 9.998006 seconds)
2020-02-25 13:02:59,968 - <module> - 58 - DEBUG - SendBefore_NotRecive : [<CNCProcessStatus: CNCProcessStatus object (2038721)>]
2020-02-25 13:02:59,968 - <module> - 59 - DEBUG - Waitfor_Recive : [2038721]
2020-02-25 13:03:09,955 - _main_loop - 579 - DEBUG - Looking for jobs to run
2020-02-25 13:03:09,958 - _run_jobs - 69 - DEBUG - Started worker thread
2020-02-25 13:03:09,959 - _run_job - 509 - INFO - Running job "regulartime_task (trigger: interval[1 day, 0:00:00], next run at: 2020-02-25 13:03:09.952592)" (scheduled at 2020-02-25 13:03:09.952592)
2020-02-25 13:03:09,961 - _main_loop - 588 - DEBUG - Next wakeup is due at 2020-02-26 00:00:00 (in 39410.044192 seconds)
2020-02-25 13:03:10,937 - _run_job - 520 - ERROR - Job "regulartime_task (trigger: interval[1 day, 0:00:00], next run at: 2020-02-26 13:03:09.952592)" raised an exception
Traceback (most recent call last):
  File "D:\Program Files\Python37\lib\site-packages\django\db\backends\utils.py", line 84, in _execute
    return self.cursor.execute(sql, params)
  File "D:\Program Files\Python37\lib\site-packages\django\db\backends\mysql\base.py", line 71, in execute
    return self.cursor.execute(query, args)
  File "D:\Program Files\Python37\lib\site-packages\MySQLdb\cursors.py", line 209, in execute
    res = self._query(query)
  File "D:\Program Files\Python37\lib\site-packages\MySQLdb\cursors.py", line 315, in _query
    db.query(q)
  File "D:\Program Files\Python37\lib\site-packages\MySQLdb\connections.py", line 239, in query
    _mysql.connection.query(self, query)
MySQLdb._exceptions.IntegrityError: (1062, "Duplicate entry '1582646400' for key 'LAMProcessData_process_r_acquisition_timestamp_a69ae90c_uniq'")

The above exception was the direct cause of the following exception:

Traceback (most recent call last):
  File "D:\Program Files\Python37\lib\site-packages\apscheduler\scheduler.py", line 512, in _run_job
    retval = job.func(*job.args, **job.kwargs)
  File "E:\1-program\11-LAMDataServer\lamdataserver\LAMProcessData\views.py", line 4009, in regulartime_task
    RT_FineData.Realtime_FineData.init_Tomorrow_rows()
  File "E:\1-program\11-LAMDataServer\lamdataserver\LAMProcessData\process_realtime_finedata.py", line 172, in init_Tomorrow_rows
    _model.objects.bulk_create(insert_data_list)
  File "D:\Program Files\Python37\lib\site-packages\django\db\models\manager.py", line 82, in manager_method
    return getattr(self.get_queryset(), name)(*args, **kwargs)
  File "D:\Program Files\Python37\lib\site-packages\django\db\models\query.py", line 474, in bulk_create
    ids = self._batched_insert(objs_without_pk, fields, batch_size, ignore_conflicts=ignore_conflicts)
  File "D:\Program Files\Python37\lib\site-packages\django\db\models\query.py", line 1211, in _batched_insert
    self._insert(item, fields=fields, using=self.db, ignore_conflicts=ignore_conflicts)
  File "D:\Program Files\Python37\lib\site-packages\django\db\models\query.py", line 1186, in _insert
    return query.get_compiler(using=using).execute_sql(return_id)
  File "D:\Program Files\Python37\lib\site-packages\django\db\models\sql\compiler.py", line 1332, in execute_sql
    cursor.execute(sql, params)
  File "D:\Program Files\Python37\lib\site-packages\django\db\backends\utils.py", line 99, in execute
    return super().execute(sql, params)
  File "D:\Program Files\Python37\lib\site-packages\django\db\backends\utils.py", line 67, in execute
    return self._execute_with_wrappers(sql, params, many=False, executor=self._execute)
  File "D:\Program Files\Python37\lib\site-packages\django\db\backends\utils.py", line 76, in _execute_with_wrappers
    return executor(sql, params, many, context)
  File "D:\Program Files\Python37\lib\site-packages\django\db\backends\utils.py", line 84, in _execute
    return self.cursor.execute(sql, params)
  File "D:\Program Files\Python37\lib\site-packages\django\db\utils.py", line 89, in __exit__
    raise dj_exc_value.with_traceback(traceback) from exc_value
  File "D:\Program Files\Python37\lib\site-packages\django\db\backends\utils.py", line 84, in _execute
    return self.cursor.execute(sql, params)
  File "D:\Program Files\Python37\lib\site-packages\django\db\backends\mysql\base.py", line 71, in execute
    return self.cursor.execute(query, args)
  File "D:\Program Files\Python37\lib\site-packages\MySQLdb\cursors.py", line 209, in execute
    res = self._query(query)
  File "D:\Program Files\Python37\lib\site-packages\MySQLdb\cursors.py", line 315, in _query
    db.query(q)
  File "D:\Program Files\Python37\lib\site-packages\MySQLdb\connections.py", line 239, in query
    _mysql.connection.query(self, query)
django.db.utils.IntegrityError: (1062, "Duplicate entry '1582646400' for key 'LAMProcessData_process_r_acquisition_timestamp_a69ae90c_uniq'")
2020-02-25 13:03:11,950 - _run_jobs - 94 - DEBUG - Exiting worker thread
2020-02-25 13:04:42,348 - trigger_reload - 203 - INFO - E:\1-program\11-LAMDataServer\lamdataserver\LAMProcessData\views.py changed, reloading.
2020-02-25 13:04:42,349 - shutdown - 111 - INFO - Shutting down thread pool
2020-02-25 13:04:44,445 - _real_add_job - 262 - INFO - Added job "regulartime_task (trigger: interval[1 day, 0:00:00], next run at: 2020-02-25 13:04:54.443177)" to job store "default"
2020-02-25 13:04:44,445 - _real_add_job - 262 - INFO - Added job "OpenLog (trigger: cron[hour='0'], next run at: 2020-02-26 00:00:00)" to job store "default"
2020-02-25 13:04:44,446 - _main_loop - 574 - INFO - Scheduler started
2020-02-25 13:04:44,446 - _main_loop - 579 - DEBUG - Looking for jobs to run
2020-02-25 13:04:44,446 - _main_loop - 588 - DEBUG - Next wakeup is due at 2020-02-25 13:04:54.443177 (in 9.997049 seconds)
2020-02-25 13:04:44,460 - <module> - 58 - DEBUG - SendBefore_NotRecive : [<CNCProcessStatus: CNCProcessStatus object (2038721)>]
2020-02-25 13:04:44,460 - <module> - 59 - DEBUG - Waitfor_Recive : [2038721]
2020-02-25 13:04:54,445 - _main_loop - 579 - DEBUG - Looking for jobs to run
2020-02-25 13:04:54,449 - _run_jobs - 69 - DEBUG - Started worker thread
2020-02-25 13:04:54,450 - _run_job - 509 - INFO - Running job "regulartime_task (trigger: interval[1 day, 0:00:00], next run at: 2020-02-25 13:04:54.443177)" (scheduled at 2020-02-25 13:04:54.443177)
2020-02-25 13:04:54,452 - _main_loop - 588 - DEBUG - Next wakeup is due at 2020-02-26 00:00:00 (in 39305.553951 seconds)
2020-02-25 13:04:55,465 - _run_job - 520 - ERROR - Job "regulartime_task (trigger: interval[1 day, 0:00:00], next run at: 2020-02-26 13:04:54.443177)" raised an exception
Traceback (most recent call last):
  File "D:\Program Files\Python37\lib\site-packages\django\db\backends\utils.py", line 84, in _execute
    return self.cursor.execute(sql, params)
  File "D:\Program Files\Python37\lib\site-packages\django\db\backends\mysql\base.py", line 71, in execute
    return self.cursor.execute(query, args)
  File "D:\Program Files\Python37\lib\site-packages\MySQLdb\cursors.py", line 209, in execute
    res = self._query(query)
  File "D:\Program Files\Python37\lib\site-packages\MySQLdb\cursors.py", line 315, in _query
    db.query(q)
  File "D:\Program Files\Python37\lib\site-packages\MySQLdb\connections.py", line 239, in query
    _mysql.connection.query(self, query)
MySQLdb._exceptions.IntegrityError: (1062, "Duplicate entry '1582646400' for key 'LAMProcessData_process_r_acquisition_timestamp_a69ae90c_uniq'")

The above exception was the direct cause of the following exception:

Traceback (most recent call last):
  File "D:\Program Files\Python37\lib\site-packages\apscheduler\scheduler.py", line 512, in _run_job
    retval = job.func(*job.args, **job.kwargs)
  File "E:\1-program\11-LAMDataServer\lamdataserver\LAMProcessData\views.py", line 4009, in regulartime_task
    RT_FineData.Realtime_FineData.init_Tomorrow_rows()
  File "E:\1-program\11-LAMDataServer\lamdataserver\LAMProcessData\process_realtime_finedata.py", line 172, in init_Tomorrow_rows
    _model.objects.bulk_create(insert_data_list)
  File "D:\Program Files\Python37\lib\site-packages\django\db\models\manager.py", line 82, in manager_method
    return getattr(self.get_queryset(), name)(*args, **kwargs)
  File "D:\Program Files\Python37\lib\site-packages\django\db\models\query.py", line 474, in bulk_create
    ids = self._batched_insert(objs_without_pk, fields, batch_size, ignore_conflicts=ignore_conflicts)
  File "D:\Program Files\Python37\lib\site-packages\django\db\models\query.py", line 1211, in _batched_insert
    self._insert(item, fields=fields, using=self.db, ignore_conflicts=ignore_conflicts)
  File "D:\Program Files\Python37\lib\site-packages\django\db\models\query.py", line 1186, in _insert
    return query.get_compiler(using=using).execute_sql(return_id)
  File "D:\Program Files\Python37\lib\site-packages\django\db\models\sql\compiler.py", line 1332, in execute_sql
    cursor.execute(sql, params)
  File "D:\Program Files\Python37\lib\site-packages\django\db\backends\utils.py", line 99, in execute
    return super().execute(sql, params)
  File "D:\Program Files\Python37\lib\site-packages\django\db\backends\utils.py", line 67, in execute
    return self._execute_with_wrappers(sql, params, many=False, executor=self._execute)
  File "D:\Program Files\Python37\lib\site-packages\django\db\backends\utils.py", line 76, in _execute_with_wrappers
    return executor(sql, params, many, context)
  File "D:\Program Files\Python37\lib\site-packages\django\db\backends\utils.py", line 84, in _execute
    return self.cursor.execute(sql, params)
  File "D:\Program Files\Python37\lib\site-packages\django\db\utils.py", line 89, in __exit__
    raise dj_exc_value.with_traceback(traceback) from exc_value
  File "D:\Program Files\Python37\lib\site-packages\django\db\backends\utils.py", line 84, in _execute
    return self.cursor.execute(sql, params)
  File "D:\Program Files\Python37\lib\site-packages\django\db\backends\mysql\base.py", line 71, in execute
    return self.cursor.execute(query, args)
  File "D:\Program Files\Python37\lib\site-packages\MySQLdb\cursors.py", line 209, in execute
    res = self._query(query)
  File "D:\Program Files\Python37\lib\site-packages\MySQLdb\cursors.py", line 315, in _query
    db.query(q)
  File "D:\Program Files\Python37\lib\site-packages\MySQLdb\connections.py", line 239, in query
    _mysql.connection.query(self, query)
django.db.utils.IntegrityError: (1062, "Duplicate entry '1582646400' for key 'LAMProcessData_process_r_acquisition_timestamp_a69ae90c_uniq'")
2020-02-25 13:04:56,474 - _run_jobs - 94 - DEBUG - Exiting worker thread
2020-02-25 16:16:22,112 - log_response - 228 - WARNING - Not Found: /favicon.ico
2020-02-25 16:16:22,699 - log_response - 228 - WARNING - Not Found: /favicon.ico
2020-02-25 16:20:31,661 - log_response - 228 - WARNING - Not Found: /favicon.ico
2020-02-25 16:35:02,236 - _real_add_job - 262 - INFO - Added job "regulartime_task (trigger: interval[1 day, 0:00:00], next run at: 2020-02-25 16:35:12.234970)" to job store "default"
2020-02-25 16:35:02,237 - _real_add_job - 262 - INFO - Added job "OpenLog (trigger: cron[hour='0'], next run at: 2020-02-26 00:00:00)" to job store "default"
2020-02-25 16:35:02,238 - _main_loop - 574 - INFO - Scheduler started
2020-02-25 16:35:02,239 - _main_loop - 579 - DEBUG - Looking for jobs to run
2020-02-25 16:35:02,239 - _main_loop - 588 - DEBUG - Next wakeup is due at 2020-02-25 16:35:12.234970 (in 9.994985 seconds)
2020-02-25 16:35:02,256 - <module> - 58 - DEBUG - SendBefore_NotRecive : [<CNCProcessStatus: CNCProcessStatus object (2038721)>]
2020-02-25 16:35:02,256 - <module> - 59 - DEBUG - Waitfor_Recive : [2038721]
2020-02-25 16:35:12,235 - _main_loop - 579 - DEBUG - Looking for jobs to run
2020-02-25 16:35:12,237 - _run_jobs - 69 - DEBUG - Started worker thread
2020-02-25 16:35:12,237 - _run_job - 509 - INFO - Running job "regulartime_task (trigger: interval[1 day, 0:00:00], next run at: 2020-02-25 16:35:12.234970)" (scheduled at 2020-02-25 16:35:12.234970)
2020-02-25 16:35:12,237 - _main_loop - 588 - DEBUG - Next wakeup is due at 2020-02-26 00:00:00 (in 26687.764439 seconds)
2020-02-25 16:35:12,603 - _run_job - 520 - ERROR - Job "regulartime_task (trigger: interval[1 day, 0:00:00], next run at: 2020-02-26 16:35:12.234970)" raised an exception
Traceback (most recent call last):
  File "D:\Program Files\Python37\lib\site-packages\django\db\backends\utils.py", line 84, in _execute
    return self.cursor.execute(sql, params)
  File "D:\Program Files\Python37\lib\site-packages\django\db\backends\mysql\base.py", line 71, in execute
    return self.cursor.execute(query, args)
  File "D:\Program Files\Python37\lib\site-packages\MySQLdb\cursors.py", line 209, in execute
    res = self._query(query)
  File "D:\Program Files\Python37\lib\site-packages\MySQLdb\cursors.py", line 315, in _query
    db.query(q)
  File "D:\Program Files\Python37\lib\site-packages\MySQLdb\connections.py", line 239, in query
    _mysql.connection.query(self, query)
MySQLdb._exceptions.IntegrityError: (1062, "Duplicate entry '1582646400' for key 'LAMProcessData_process_r_acquisition_timestamp_a69ae90c_uniq'")

The above exception was the direct cause of the following exception:

Traceback (most recent call last):
  File "D:\Program Files\Python37\lib\site-packages\apscheduler\scheduler.py", line 512, in _run_job
    retval = job.func(*job.args, **job.kwargs)
  File "E:\1-program\11-LAMDataServer\lamdataserver\LAMProcessData\views.py", line 4013, in regulartime_task
    RT_FineData.Realtime_FineData.init_Tomorrow_rows()
  File "E:\1-program\11-LAMDataServer\lamdataserver\LAMProcessData\process_realtime_finedata.py", line 172, in init_Tomorrow_rows
    _model.objects.bulk_create(insert_data_list)
  File "D:\Program Files\Python37\lib\site-packages\django\db\models\manager.py", line 82, in manager_method
    return getattr(self.get_queryset(), name)(*args, **kwargs)
  File "D:\Program Files\Python37\lib\site-packages\django\db\models\query.py", line 474, in bulk_create
    ids = self._batched_insert(objs_without_pk, fields, batch_size, ignore_conflicts=ignore_conflicts)
  File "D:\Program Files\Python37\lib\site-packages\django\db\models\query.py", line 1211, in _batched_insert
    self._insert(item, fields=fields, using=self.db, ignore_conflicts=ignore_conflicts)
  File "D:\Program Files\Python37\lib\site-packages\django\db\models\query.py", line 1186, in _insert
    return query.get_compiler(using=using).execute_sql(return_id)
  File "D:\Program Files\Python37\lib\site-packages\django\db\models\sql\compiler.py", line 1332, in execute_sql
    cursor.execute(sql, params)
  File "D:\Program Files\Python37\lib\site-packages\django\db\backends\utils.py", line 99, in execute
    return super().execute(sql, params)
  File "D:\Program Files\Python37\lib\site-packages\django\db\backends\utils.py", line 67, in execute
    return self._execute_with_wrappers(sql, params, many=False, executor=self._execute)
  File "D:\Program Files\Python37\lib\site-packages\django\db\backends\utils.py", line 76, in _execute_with_wrappers
    return executor(sql, params, many, context)
  File "D:\Program Files\Python37\lib\site-packages\django\db\backends\utils.py", line 84, in _execute
    return self.cursor.execute(sql, params)
  File "D:\Program Files\Python37\lib\site-packages\django\db\utils.py", line 89, in __exit__
    raise dj_exc_value.with_traceback(traceback) from exc_value
  File "D:\Program Files\Python37\lib\site-packages\django\db\backends\utils.py", line 84, in _execute
    return self.cursor.execute(sql, params)
  File "D:\Program Files\Python37\lib\site-packages\django\db\backends\mysql\base.py", line 71, in execute
    return self.cursor.execute(query, args)
  File "D:\Program Files\Python37\lib\site-packages\MySQLdb\cursors.py", line 209, in execute
    res = self._query(query)
  File "D:\Program Files\Python37\lib\site-packages\MySQLdb\cursors.py", line 315, in _query
    db.query(q)
  File "D:\Program Files\Python37\lib\site-packages\MySQLdb\connections.py", line 239, in query
    _mysql.connection.query(self, query)
django.db.utils.IntegrityError: (1062, "Duplicate entry '1582646400' for key 'LAMProcessData_process_r_acquisition_timestamp_a69ae90c_uniq'")
2020-02-25 16:35:13,624 - _run_jobs - 94 - DEBUG - Exiting worker thread
2020-02-25 18:07:51,805 - _real_add_job - 262 - INFO - Added job "regulartime_task (trigger: interval[1 day, 0:00:00], next run at: 2020-02-25 18:08:01.804662)" to job store "default"
2020-02-25 18:07:51,805 - _real_add_job - 262 - INFO - Added job "OpenLog (trigger: cron[hour='0'], next run at: 2020-02-26 00:00:00)" to job store "default"
2020-02-25 18:07:51,806 - _main_loop - 574 - INFO - Scheduler started
2020-02-25 18:07:51,806 - _main_loop - 579 - DEBUG - Looking for jobs to run
2020-02-25 18:07:51,806 - _main_loop - 588 - DEBUG - Next wakeup is due at 2020-02-25 18:08:01.804662 (in 9.998316 seconds)
2020-02-25 18:07:51,815 - <module> - 58 - DEBUG - SendBefore_NotRecive : [<CNCProcessStatus: CNCProcessStatus object (2038721)>]
2020-02-25 18:07:51,815 - <module> - 59 - DEBUG - Waitfor_Recive : [2038721]
2020-02-25 18:08:01,805 - _main_loop - 579 - DEBUG - Looking for jobs to run
2020-02-25 18:08:01,806 - _run_jobs - 69 - DEBUG - Started worker thread
2020-02-25 18:08:01,807 - _run_job - 509 - INFO - Running job "regulartime_task (trigger: interval[1 day, 0:00:00], next run at: 2020-02-25 18:08:01.804662)" (scheduled at 2020-02-25 18:08:01.804662)
2020-02-25 18:08:01,808 - _main_loop - 588 - DEBUG - Next wakeup is due at 2020-02-26 00:00:00 (in 21118.194129 seconds)
2020-02-25 18:08:02,140 - _run_job - 520 - ERROR - Job "regulartime_task (trigger: interval[1 day, 0:00:00], next run at: 2020-02-26 18:08:01.804662)" raised an exception
Traceback (most recent call last):
  File "D:\Program Files\Python37\lib\site-packages\django\db\backends\utils.py", line 84, in _execute
    return self.cursor.execute(sql, params)
  File "D:\Program Files\Python37\lib\site-packages\django\db\backends\mysql\base.py", line 71, in execute
    return self.cursor.execute(query, args)
  File "D:\Program Files\Python37\lib\site-packages\MySQLdb\cursors.py", line 209, in execute
    res = self._query(query)
  File "D:\Program Files\Python37\lib\site-packages\MySQLdb\cursors.py", line 315, in _query
    db.query(q)
  File "D:\Program Files\Python37\lib\site-packages\MySQLdb\connections.py", line 239, in query
    _mysql.connection.query(self, query)
MySQLdb._exceptions.IntegrityError: (1062, "Duplicate entry '1582646400' for key 'LAMProcessData_process_r_acquisition_timestamp_a69ae90c_uniq'")

The above exception was the direct cause of the following exception:

Traceback (most recent call last):
  File "D:\Program Files\Python37\lib\site-packages\apscheduler\scheduler.py", line 512, in _run_job
    retval = job.func(*job.args, **job.kwargs)
  File "E:\1-program\11-LAMDataServer\lamdataserver\LAMProcessData\views.py", line 4013, in regulartime_task
    RT_FineData.Realtime_FineData.init_Tomorrow_rows()
  File "E:\1-program\11-LAMDataServer\lamdataserver\LAMProcessData\process_realtime_finedata.py", line 172, in init_Tomorrow_rows
    _model.objects.bulk_create(insert_data_list)
  File "D:\Program Files\Python37\lib\site-packages\django\db\models\manager.py", line 82, in manager_method
    return getattr(self.get_queryset(), name)(*args, **kwargs)
  File "D:\Program Files\Python37\lib\site-packages\django\db\models\query.py", line 474, in bulk_create
    ids = self._batched_insert(objs_without_pk, fields, batch_size, ignore_conflicts=ignore_conflicts)
  File "D:\Program Files\Python37\lib\site-packages\django\db\models\query.py", line 1211, in _batched_insert
    self._insert(item, fields=fields, using=self.db, ignore_conflicts=ignore_conflicts)
  File "D:\Program Files\Python37\lib\site-packages\django\db\models\query.py", line 1186, in _insert
    return query.get_compiler(using=using).execute_sql(return_id)
  File "D:\Program Files\Python37\lib\site-packages\django\db\models\sql\compiler.py", line 1332, in execute_sql
    cursor.execute(sql, params)
  File "D:\Program Files\Python37\lib\site-packages\django\db\backends\utils.py", line 99, in execute
    return super().execute(sql, params)
  File "D:\Program Files\Python37\lib\site-packages\django\db\backends\utils.py", line 67, in execute
    return self._execute_with_wrappers(sql, params, many=False, executor=self._execute)
  File "D:\Program Files\Python37\lib\site-packages\django\db\backends\utils.py", line 76, in _execute_with_wrappers
    return executor(sql, params, many, context)
  File "D:\Program Files\Python37\lib\site-packages\django\db\backends\utils.py", line 84, in _execute
    return self.cursor.execute(sql, params)
  File "D:\Program Files\Python37\lib\site-packages\django\db\utils.py", line 89, in __exit__
    raise dj_exc_value.with_traceback(traceback) from exc_value
  File "D:\Program Files\Python37\lib\site-packages\django\db\backends\utils.py", line 84, in _execute
    return self.cursor.execute(sql, params)
  File "D:\Program Files\Python37\lib\site-packages\django\db\backends\mysql\base.py", line 71, in execute
    return self.cursor.execute(query, args)
  File "D:\Program Files\Python37\lib\site-packages\MySQLdb\cursors.py", line 209, in execute
    res = self._query(query)
  File "D:\Program Files\Python37\lib\site-packages\MySQLdb\cursors.py", line 315, in _query
    db.query(q)
  File "D:\Program Files\Python37\lib\site-packages\MySQLdb\connections.py", line 239, in query
    _mysql.connection.query(self, query)
django.db.utils.IntegrityError: (1062, "Duplicate entry '1582646400' for key 'LAMProcessData_process_r_acquisition_timestamp_a69ae90c_uniq'")
2020-02-25 18:08:03,145 - _run_jobs - 94 - DEBUG - Exiting worker thread
2020-02-25 18:29:46,048 - trigger_reload - 203 - INFO - E:\1-program\11-LAMDataServer\lamdataserver\LAMProcessData\views.py changed, reloading.
2020-02-25 18:29:46,068 - shutdown - 111 - INFO - Shutting down thread pool
2020-02-25 18:29:48,029 - _real_add_job - 262 - INFO - Added job "regulartime_task (trigger: interval[1 day, 0:00:00], next run at: 2020-02-25 18:29:58.029075)" to job store "default"
2020-02-25 18:29:48,029 - _real_add_job - 262 - INFO - Added job "OpenLog (trigger: cron[hour='0'], next run at: 2020-02-26 00:00:00)" to job store "default"
2020-02-25 18:29:48,029 - _main_loop - 574 - INFO - Scheduler started
2020-02-25 18:29:48,029 - _main_loop - 579 - DEBUG - Looking for jobs to run
2020-02-25 18:29:48,029 - _main_loop - 588 - DEBUG - Next wakeup is due at 2020-02-25 18:29:58.029075 (in 10.000000 seconds)
2020-02-25 18:29:48,038 - <module> - 58 - DEBUG - SendBefore_NotRecive : [<CNCProcessStatus: CNCProcessStatus object (2038721)>]
2020-02-25 18:29:48,038 - <module> - 59 - DEBUG - Waitfor_Recive : [2038721]
2020-02-25 18:29:58,029 - _main_loop - 579 - DEBUG - Looking for jobs to run
2020-02-25 18:29:58,029 - _run_jobs - 69 - DEBUG - Started worker thread
2020-02-25 18:29:58,029 - _main_loop - 588 - DEBUG - Next wakeup is due at 2020-02-26 00:00:00 (in 19801.970230 seconds)
2020-02-25 18:29:58,030 - _run_job - 509 - INFO - Running job "regulartime_task (trigger: interval[1 day, 0:00:00], next run at: 2020-02-26 18:29:58.029075)" (scheduled at 2020-02-25 18:29:58.029075)
2020-02-25 18:29:58,370 - _run_job - 520 - ERROR - Job "regulartime_task (trigger: interval[1 day, 0:00:00], next run at: 2020-02-26 18:29:58.029075)" raised an exception
Traceback (most recent call last):
  File "D:\Program Files\Python37\lib\site-packages\django\db\backends\utils.py", line 84, in _execute
    return self.cursor.execute(sql, params)
  File "D:\Program Files\Python37\lib\site-packages\django\db\backends\mysql\base.py", line 71, in execute
    return self.cursor.execute(query, args)
  File "D:\Program Files\Python37\lib\site-packages\MySQLdb\cursors.py", line 209, in execute
    res = self._query(query)
  File "D:\Program Files\Python37\lib\site-packages\MySQLdb\cursors.py", line 315, in _query
    db.query(q)
  File "D:\Program Files\Python37\lib\site-packages\MySQLdb\connections.py", line 239, in query
    _mysql.connection.query(self, query)
MySQLdb._exceptions.IntegrityError: (1062, "Duplicate entry '1582646400' for key 'LAMProcessData_process_r_acquisition_timestamp_a69ae90c_uniq'")

The above exception was the direct cause of the following exception:

Traceback (most recent call last):
  File "D:\Program Files\Python37\lib\site-packages\apscheduler\scheduler.py", line 512, in _run_job
    retval = job.func(*job.args, **job.kwargs)
  File "E:\1-program\11-LAMDataServer\lamdataserver\LAMProcessData\views.py", line 4016, in regulartime_task
    RT_FineData.Realtime_FineData.init_Tomorrow_rows()
  File "E:\1-program\11-LAMDataServer\lamdataserver\LAMProcessData\process_realtime_finedata.py", line 172, in init_Tomorrow_rows
    _model.objects.bulk_create(insert_data_list)
  File "D:\Program Files\Python37\lib\site-packages\django\db\models\manager.py", line 82, in manager_method
    return getattr(self.get_queryset(), name)(*args, **kwargs)
  File "D:\Program Files\Python37\lib\site-packages\django\db\models\query.py", line 474, in bulk_create
    ids = self._batched_insert(objs_without_pk, fields, batch_size, ignore_conflicts=ignore_conflicts)
  File "D:\Program Files\Python37\lib\site-packages\django\db\models\query.py", line 1211, in _batched_insert
    self._insert(item, fields=fields, using=self.db, ignore_conflicts=ignore_conflicts)
  File "D:\Program Files\Python37\lib\site-packages\django\db\models\query.py", line 1186, in _insert
    return query.get_compiler(using=using).execute_sql(return_id)
  File "D:\Program Files\Python37\lib\site-packages\django\db\models\sql\compiler.py", line 1332, in execute_sql
    cursor.execute(sql, params)
  File "D:\Program Files\Python37\lib\site-packages\django\db\backends\utils.py", line 99, in execute
    return super().execute(sql, params)
  File "D:\Program Files\Python37\lib\site-packages\django\db\backends\utils.py", line 67, in execute
    return self._execute_with_wrappers(sql, params, many=False, executor=self._execute)
  File "D:\Program Files\Python37\lib\site-packages\django\db\backends\utils.py", line 76, in _execute_with_wrappers
    return executor(sql, params, many, context)
  File "D:\Program Files\Python37\lib\site-packages\django\db\backends\utils.py", line 84, in _execute
    return self.cursor.execute(sql, params)
  File "D:\Program Files\Python37\lib\site-packages\django\db\utils.py", line 89, in __exit__
    raise dj_exc_value.with_traceback(traceback) from exc_value
  File "D:\Program Files\Python37\lib\site-packages\django\db\backends\utils.py", line 84, in _execute
    return self.cursor.execute(sql, params)
  File "D:\Program Files\Python37\lib\site-packages\django\db\backends\mysql\base.py", line 71, in execute
    return self.cursor.execute(query, args)
  File "D:\Program Files\Python37\lib\site-packages\MySQLdb\cursors.py", line 209, in execute
    res = self._query(query)
  File "D:\Program Files\Python37\lib\site-packages\MySQLdb\cursors.py", line 315, in _query
    db.query(q)
  File "D:\Program Files\Python37\lib\site-packages\MySQLdb\connections.py", line 239, in query
    _mysql.connection.query(self, query)
django.db.utils.IntegrityError: (1062, "Duplicate entry '1582646400' for key 'LAMProcessData_process_r_acquisition_timestamp_a69ae90c_uniq'")
2020-02-25 18:29:59,374 - _run_jobs - 94 - DEBUG - Exiting worker thread
2020-02-25 18:30:54,474 - _real_add_job - 262 - INFO - Added job "regulartime_task (trigger: interval[1 day, 0:00:00], next run at: 2020-02-25 18:31:04.473529)" to job store "default"
2020-02-25 18:30:54,474 - _real_add_job - 262 - INFO - Added job "OpenLog (trigger: cron[hour='0'], next run at: 2020-02-26 00:00:00)" to job store "default"
2020-02-25 18:30:54,474 - _main_loop - 574 - INFO - Scheduler started
2020-02-25 18:30:54,474 - _main_loop - 579 - DEBUG - Looking for jobs to run
2020-02-25 18:30:54,474 - _main_loop - 588 - DEBUG - Next wakeup is due at 2020-02-25 18:31:04.473529 (in 9.998980 seconds)
2020-02-25 18:30:54,478 - <module> - 58 - DEBUG - SendBefore_NotRecive : [<CNCProcessStatus: CNCProcessStatus object (2038721)>]
2020-02-25 18:30:54,478 - <module> - 59 - DEBUG - Waitfor_Recive : [2038721]
2020-02-25 18:31:04,474 - _main_loop - 579 - DEBUG - Looking for jobs to run
2020-02-25 18:31:04,475 - _run_jobs - 69 - DEBUG - Started worker thread
2020-02-25 18:31:04,475 - _run_job - 509 - INFO - Running job "regulartime_task (trigger: interval[1 day, 0:00:00], next run at: 2020-02-25 18:31:04.473529)" (scheduled at 2020-02-25 18:31:04.473529)
2020-02-25 18:31:04,475 - _main_loop - 588 - DEBUG - Next wakeup is due at 2020-02-26 00:00:00 (in 19735.525539 seconds)
2020-02-25 18:31:04,808 - _run_job - 520 - ERROR - Job "regulartime_task (trigger: interval[1 day, 0:00:00], next run at: 2020-02-26 18:31:04.473529)" raised an exception
Traceback (most recent call last):
  File "D:\Program Files\Python37\lib\site-packages\django\db\backends\utils.py", line 84, in _execute
    return self.cursor.execute(sql, params)
  File "D:\Program Files\Python37\lib\site-packages\django\db\backends\mysql\base.py", line 71, in execute
    return self.cursor.execute(query, args)
  File "D:\Program Files\Python37\lib\site-packages\MySQLdb\cursors.py", line 209, in execute
    res = self._query(query)
  File "D:\Program Files\Python37\lib\site-packages\MySQLdb\cursors.py", line 315, in _query
    db.query(q)
  File "D:\Program Files\Python37\lib\site-packages\MySQLdb\connections.py", line 239, in query
    _mysql.connection.query(self, query)
MySQLdb._exceptions.IntegrityError: (1062, "Duplicate entry '1582646400' for key 'LAMProcessData_process_r_acquisition_timestamp_a69ae90c_uniq'")

The above exception was the direct cause of the following exception:

Traceback (most recent call last):
  File "D:\Program Files\Python37\lib\site-packages\apscheduler\scheduler.py", line 512, in _run_job
    retval = job.func(*job.args, **job.kwargs)
  File "E:\1-program\11-LAMDataServer\lamdataserver\LAMProcessData\views.py", line 4016, in regulartime_task
    RT_FineData.Realtime_FineData.init_Tomorrow_rows()
  File "E:\1-program\11-LAMDataServer\lamdataserver\LAMProcessData\process_realtime_finedata.py", line 172, in init_Tomorrow_rows
    _model.objects.bulk_create(insert_data_list)
  File "D:\Program Files\Python37\lib\site-packages\django\db\models\manager.py", line 82, in manager_method
    return getattr(self.get_queryset(), name)(*args, **kwargs)
  File "D:\Program Files\Python37\lib\site-packages\django\db\models\query.py", line 474, in bulk_create
    ids = self._batched_insert(objs_without_pk, fields, batch_size, ignore_conflicts=ignore_conflicts)
  File "D:\Program Files\Python37\lib\site-packages\django\db\models\query.py", line 1211, in _batched_insert
    self._insert(item, fields=fields, using=self.db, ignore_conflicts=ignore_conflicts)
  File "D:\Program Files\Python37\lib\site-packages\django\db\models\query.py", line 1186, in _insert
    return query.get_compiler(using=using).execute_sql(return_id)
  File "D:\Program Files\Python37\lib\site-packages\django\db\models\sql\compiler.py", line 1332, in execute_sql
    cursor.execute(sql, params)
  File "D:\Program Files\Python37\lib\site-packages\django\db\backends\utils.py", line 99, in execute
    return super().execute(sql, params)
  File "D:\Program Files\Python37\lib\site-packages\django\db\backends\utils.py", line 67, in execute
    return self._execute_with_wrappers(sql, params, many=False, executor=self._execute)
  File "D:\Program Files\Python37\lib\site-packages\django\db\backends\utils.py", line 76, in _execute_with_wrappers
    return executor(sql, params, many, context)
  File "D:\Program Files\Python37\lib\site-packages\django\db\backends\utils.py", line 84, in _execute
    return self.cursor.execute(sql, params)
  File "D:\Program Files\Python37\lib\site-packages\django\db\utils.py", line 89, in __exit__
    raise dj_exc_value.with_traceback(traceback) from exc_value
  File "D:\Program Files\Python37\lib\site-packages\django\db\backends\utils.py", line 84, in _execute
    return self.cursor.execute(sql, params)
  File "D:\Program Files\Python37\lib\site-packages\django\db\backends\mysql\base.py", line 71, in execute
    return self.cursor.execute(query, args)
  File "D:\Program Files\Python37\lib\site-packages\MySQLdb\cursors.py", line 209, in execute
    res = self._query(query)
  File "D:\Program Files\Python37\lib\site-packages\MySQLdb\cursors.py", line 315, in _query
    db.query(q)
  File "D:\Program Files\Python37\lib\site-packages\MySQLdb\connections.py", line 239, in query
    _mysql.connection.query(self, query)
django.db.utils.IntegrityError: (1062, "Duplicate entry '1582646400' for key 'LAMProcessData_process_r_acquisition_timestamp_a69ae90c_uniq'")
2020-02-25 18:31:05,829 - _run_jobs - 94 - DEBUG - Exiting worker thread
2020-02-25 18:32:16,026 - trigger_reload - 203 - INFO - E:\1-program\11-LAMDataServer\lamdataserver\LAMProcessData\views.py changed, reloading.
2020-02-25 18:32:16,026 - shutdown - 111 - INFO - Shutting down thread pool
2020-02-25 18:32:17,152 - _real_add_job - 262 - INFO - Added job "regulartime_task (trigger: interval[1 day, 0:00:00], next run at: 2020-02-25 18:32:27.150222)" to job store "default"
2020-02-25 18:32:17,153 - _real_add_job - 262 - INFO - Added job "OpenLog (trigger: cron[hour='0'], next run at: 2020-02-26 00:00:00)" to job store "default"
2020-02-25 18:32:17,154 - _main_loop - 574 - INFO - Scheduler started
2020-02-25 18:32:17,154 - _main_loop - 579 - DEBUG - Looking for jobs to run
2020-02-25 18:32:17,154 - _main_loop - 588 - DEBUG - Next wakeup is due at 2020-02-25 18:32:27.150222 (in 9.996013 seconds)
2020-02-25 18:32:17,169 - <module> - 58 - DEBUG - SendBefore_NotRecive : [<CNCProcessStatus: CNCProcessStatus object (2038721)>]
2020-02-25 18:32:17,169 - <module> - 59 - DEBUG - Waitfor_Recive : [2038721]
2020-02-25 18:32:27,151 - _main_loop - 579 - DEBUG - Looking for jobs to run
2020-02-25 18:32:27,152 - _run_jobs - 69 - DEBUG - Started worker thread
2020-02-25 18:32:27,152 - _run_job - 509 - INFO - Running job "regulartime_task (trigger: interval[1 day, 0:00:00], next run at: 2020-02-25 18:32:27.150222)" (scheduled at 2020-02-25 18:32:27.150222)
2020-02-25 18:32:27,152 - _main_loop - 588 - DEBUG - Next wakeup is due at 2020-02-26 00:00:00 (in 19652.848579 seconds)
2020-02-25 18:32:27,477 - _run_job - 520 - ERROR - Job "regulartime_task (trigger: interval[1 day, 0:00:00], next run at: 2020-02-26 18:32:27.150222)" raised an exception
Traceback (most recent call last):
  File "D:\Program Files\Python37\lib\site-packages\django\db\backends\utils.py", line 84, in _execute
    return self.cursor.execute(sql, params)
  File "D:\Program Files\Python37\lib\site-packages\django\db\backends\mysql\base.py", line 71, in execute
    return self.cursor.execute(query, args)
  File "D:\Program Files\Python37\lib\site-packages\MySQLdb\cursors.py", line 209, in execute
    res = self._query(query)
  File "D:\Program Files\Python37\lib\site-packages\MySQLdb\cursors.py", line 315, in _query
    db.query(q)
  File "D:\Program Files\Python37\lib\site-packages\MySQLdb\connections.py", line 239, in query
    _mysql.connection.query(self, query)
MySQLdb._exceptions.IntegrityError: (1062, "Duplicate entry '1582646400' for key 'LAMProcessData_process_r_acquisition_timestamp_a69ae90c_uniq'")

The above exception was the direct cause of the following exception:

Traceback (most recent call last):
  File "D:\Program Files\Python37\lib\site-packages\apscheduler\scheduler.py", line 512, in _run_job
    retval = job.func(*job.args, **job.kwargs)
  File "E:\1-program\11-LAMDataServer\lamdataserver\LAMProcessData\views.py", line 4022, in regulartime_task
    RT_FineData.Realtime_FineData.init_Tomorrow_rows()
  File "E:\1-program\11-LAMDataServer\lamdataserver\LAMProcessData\process_realtime_finedata.py", line 172, in init_Tomorrow_rows
    _model.objects.bulk_create(insert_data_list)
  File "D:\Program Files\Python37\lib\site-packages\django\db\models\manager.py", line 82, in manager_method
    return getattr(self.get_queryset(), name)(*args, **kwargs)
  File "D:\Program Files\Python37\lib\site-packages\django\db\models\query.py", line 474, in bulk_create
    ids = self._batched_insert(objs_without_pk, fields, batch_size, ignore_conflicts=ignore_conflicts)
  File "D:\Program Files\Python37\lib\site-packages\django\db\models\query.py", line 1211, in _batched_insert
    self._insert(item, fields=fields, using=self.db, ignore_conflicts=ignore_conflicts)
  File "D:\Program Files\Python37\lib\site-packages\django\db\models\query.py", line 1186, in _insert
    return query.get_compiler(using=using).execute_sql(return_id)
  File "D:\Program Files\Python37\lib\site-packages\django\db\models\sql\compiler.py", line 1332, in execute_sql
    cursor.execute(sql, params)
  File "D:\Program Files\Python37\lib\site-packages\django\db\backends\utils.py", line 99, in execute
    return super().execute(sql, params)
  File "D:\Program Files\Python37\lib\site-packages\django\db\backends\utils.py", line 67, in execute
    return self._execute_with_wrappers(sql, params, many=False, executor=self._execute)
  File "D:\Program Files\Python37\lib\site-packages\django\db\backends\utils.py", line 76, in _execute_with_wrappers
    return executor(sql, params, many, context)
  File "D:\Program Files\Python37\lib\site-packages\django\db\backends\utils.py", line 84, in _execute
    return self.cursor.execute(sql, params)
  File "D:\Program Files\Python37\lib\site-packages\django\db\utils.py", line 89, in __exit__
    raise dj_exc_value.with_traceback(traceback) from exc_value
  File "D:\Program Files\Python37\lib\site-packages\django\db\backends\utils.py", line 84, in _execute
    return self.cursor.execute(sql, params)
  File "D:\Program Files\Python37\lib\site-packages\django\db\backends\mysql\base.py", line 71, in execute
    return self.cursor.execute(query, args)
  File "D:\Program Files\Python37\lib\site-packages\MySQLdb\cursors.py", line 209, in execute
    res = self._query(query)
  File "D:\Program Files\Python37\lib\site-packages\MySQLdb\cursors.py", line 315, in _query
    db.query(q)
  File "D:\Program Files\Python37\lib\site-packages\MySQLdb\connections.py", line 239, in query
    _mysql.connection.query(self, query)
django.db.utils.IntegrityError: (1062, "Duplicate entry '1582646400' for key 'LAMProcessData_process_r_acquisition_timestamp_a69ae90c_uniq'")
2020-02-25 18:32:28,499 - _run_jobs - 94 - DEBUG - Exiting worker thread
2020-02-25 18:35:14,528 - trigger_reload - 203 - INFO - E:\1-program\11-LAMDataServer\lamdataserver\LAMProcessData\views.py changed, reloading.
2020-02-25 18:35:14,528 - shutdown - 111 - INFO - Shutting down thread pool
2020-02-25 18:35:15,789 - _real_add_job - 262 - INFO - Added job "regulartime_task (trigger: interval[1 day, 0:00:00], next run at: 2020-02-25 18:35:25.788396)" to job store "default"
2020-02-25 18:35:15,789 - _real_add_job - 262 - INFO - Added job "OpenLog (trigger: cron[hour='0'], next run at: 2020-02-26 00:00:00)" to job store "default"
2020-02-25 18:35:15,789 - _main_loop - 574 - INFO - Scheduler started
2020-02-25 18:35:15,789 - _main_loop - 579 - DEBUG - Looking for jobs to run
2020-02-25 18:35:15,789 - _main_loop - 588 - DEBUG - Next wakeup is due at 2020-02-25 18:35:25.788396 (in 9.998987 seconds)
2020-02-25 18:35:15,797 - <module> - 58 - DEBUG - SendBefore_NotRecive : [<CNCProcessStatus: CNCProcessStatus object (2038721)>]
2020-02-25 18:35:15,797 - <module> - 59 - DEBUG - Waitfor_Recive : [2038721]
2020-02-25 18:35:25,788 - _main_loop - 579 - DEBUG - Looking for jobs to run
2020-02-25 18:35:25,788 - _run_jobs - 69 - DEBUG - Started worker thread
2020-02-25 18:35:25,788 - _run_job - 509 - INFO - Running job "regulartime_task (trigger: interval[1 day, 0:00:00], next run at: 2020-02-25 18:35:25.788396)" (scheduled at 2020-02-25 18:35:25.788396)
2020-02-25 18:35:25,788 - _main_loop - 588 - DEBUG - Next wakeup is due at 2020-02-26 00:00:00 (in 19474.211328 seconds)
2020-02-25 18:35:26,088 - _run_job - 520 - ERROR - Job "regulartime_task (trigger: interval[1 day, 0:00:00], next run at: 2020-02-26 18:35:25.788396)" raised an exception
Traceback (most recent call last):
  File "D:\Program Files\Python37\lib\site-packages\django\db\backends\utils.py", line 84, in _execute
    return self.cursor.execute(sql, params)
  File "D:\Program Files\Python37\lib\site-packages\django\db\backends\mysql\base.py", line 71, in execute
    return self.cursor.execute(query, args)
  File "D:\Program Files\Python37\lib\site-packages\MySQLdb\cursors.py", line 209, in execute
    res = self._query(query)
  File "D:\Program Files\Python37\lib\site-packages\MySQLdb\cursors.py", line 315, in _query
    db.query(q)
  File "D:\Program Files\Python37\lib\site-packages\MySQLdb\connections.py", line 239, in query
    _mysql.connection.query(self, query)
MySQLdb._exceptions.IntegrityError: (1062, "Duplicate entry '1582646400' for key 'LAMProcessData_process_r_acquisition_timestamp_a69ae90c_uniq'")

The above exception was the direct cause of the following exception:

Traceback (most recent call last):
  File "D:\Program Files\Python37\lib\site-packages\apscheduler\scheduler.py", line 512, in _run_job
    retval = job.func(*job.args, **job.kwargs)
  File "E:\1-program\11-LAMDataServer\lamdataserver\LAMProcessData\views.py", line 4022, in regulartime_task
    RT_FineData.Realtime_FineData.init_Tomorrow_rows()
  File "E:\1-program\11-LAMDataServer\lamdataserver\LAMProcessData\process_realtime_finedata.py", line 172, in init_Tomorrow_rows
    _model.objects.bulk_create(insert_data_list)
  File "D:\Program Files\Python37\lib\site-packages\django\db\models\manager.py", line 82, in manager_method
    return getattr(self.get_queryset(), name)(*args, **kwargs)
  File "D:\Program Files\Python37\lib\site-packages\django\db\models\query.py", line 474, in bulk_create
    ids = self._batched_insert(objs_without_pk, fields, batch_size, ignore_conflicts=ignore_conflicts)
  File "D:\Program Files\Python37\lib\site-packages\django\db\models\query.py", line 1211, in _batched_insert
    self._insert(item, fields=fields, using=self.db, ignore_conflicts=ignore_conflicts)
  File "D:\Program Files\Python37\lib\site-packages\django\db\models\query.py", line 1186, in _insert
    return query.get_compiler(using=using).execute_sql(return_id)
  File "D:\Program Files\Python37\lib\site-packages\django\db\models\sql\compiler.py", line 1332, in execute_sql
    cursor.execute(sql, params)
  File "D:\Program Files\Python37\lib\site-packages\django\db\backends\utils.py", line 99, in execute
    return super().execute(sql, params)
  File "D:\Program Files\Python37\lib\site-packages\django\db\backends\utils.py", line 67, in execute
    return self._execute_with_wrappers(sql, params, many=False, executor=self._execute)
  File "D:\Program Files\Python37\lib\site-packages\django\db\backends\utils.py", line 76, in _execute_with_wrappers
    return executor(sql, params, many, context)
  File "D:\Program Files\Python37\lib\site-packages\django\db\backends\utils.py", line 84, in _execute
    return self.cursor.execute(sql, params)
  File "D:\Program Files\Python37\lib\site-packages\django\db\utils.py", line 89, in __exit__
    raise dj_exc_value.with_traceback(traceback) from exc_value
  File "D:\Program Files\Python37\lib\site-packages\django\db\backends\utils.py", line 84, in _execute
    return self.cursor.execute(sql, params)
  File "D:\Program Files\Python37\lib\site-packages\django\db\backends\mysql\base.py", line 71, in execute
    return self.cursor.execute(query, args)
  File "D:\Program Files\Python37\lib\site-packages\MySQLdb\cursors.py", line 209, in execute
    res = self._query(query)
  File "D:\Program Files\Python37\lib\site-packages\MySQLdb\cursors.py", line 315, in _query
    db.query(q)
  File "D:\Program Files\Python37\lib\site-packages\MySQLdb\connections.py", line 239, in query
    _mysql.connection.query(self, query)
django.db.utils.IntegrityError: (1062, "Duplicate entry '1582646400' for key 'LAMProcessData_process_r_acquisition_timestamp_a69ae90c_uniq'")
2020-02-25 18:35:27,088 - _run_jobs - 94 - DEBUG - Exiting worker thread
2020-02-25 18:37:00,886 - log_response - 228 - WARNING - Not Found: /favicon.ico
2020-02-25 18:37:01,476 - log_response - 228 - WARNING - Not Found: /favicon.ico
2020-02-25 18:37:02,094 - log_response - 228 - WARNING - Not Found: /favicon.ico
2020-02-25 18:37:02,707 - log_response - 228 - WARNING - Not Found: /favicon.ico
2020-02-25 18:37:03,324 - log_response - 228 - WARNING - Not Found: /favicon.ico
2020-02-25 18:37:03,925 - log_response - 228 - WARNING - Not Found: /favicon.ico
2020-02-25 18:37:04,541 - log_response - 228 - WARNING - Not Found: /favicon.ico
2020-02-25 18:37:05,158 - log_response - 228 - WARNING - Not Found: /favicon.ico
2020-02-25 18:37:05,775 - log_response - 228 - WARNING - Not Found: /favicon.ico
2020-02-25 18:37:06,391 - log_response - 228 - WARNING - Not Found: /favicon.ico
2020-02-25 18:37:07,008 - log_response - 228 - WARNING - Not Found: /favicon.ico
2020-02-25 18:37:07,623 - log_response - 228 - WARNING - Not Found: /favicon.ico
2020-02-25 18:37:12,715 - log_response - 228 - WARNING - Not Found: /favicon.ico
2020-02-25 18:37:13,324 - log_response - 228 - WARNING - Not Found: /favicon.ico
2020-02-25 18:37:13,923 - log_response - 228 - WARNING - Not Found: /favicon.ico
2020-02-25 18:37:14,525 - log_response - 228 - WARNING - Not Found: /favicon.ico
2020-02-25 18:37:15,141 - log_response - 228 - WARNING - Not Found: /favicon.ico
2020-02-25 18:37:15,758 - log_response - 228 - WARNING - Not Found: /favicon.ico
2020-02-25 18:37:16,364 - log_response - 228 - WARNING - Not Found: /favicon.ico
2020-02-25 18:37:16,789 - log_response - 228 - WARNING - Not Found: /LAMProcessData/3Dtestdata/
2020-02-25 18:37:21,451 - log_response - 228 - WARNING - Not Found: /favicon.ico
2020-02-25 18:37:22,057 - log_response - 228 - WARNING - Not Found: /favicon.ico
2020-02-25 18:37:22,656 - log_response - 228 - WARNING - Not Found: /favicon.ico
2020-02-25 18:37:23,056 - log_response - 228 - WARNING - Not Found: /3Dtestdata/
2020-02-25 18:37:30,261 - log_response - 228 - WARNING - Not Found: /favicon.ico
2020-02-25 18:37:30,874 - log_response - 228 - WARNING - Not Found: /favicon.ico
2020-02-25 18:37:31,485 - log_response - 228 - WARNING - Not Found: /favicon.ico
2020-02-25 18:37:32,091 - log_response - 228 - WARNING - Not Found: /favicon.ico
2020-02-25 18:37:32,228 - log_response - 228 - WARNING - Not Found: /LAMProcessData/3Dtestdata/
2020-02-25 18:37:47,017 - _real_add_job - 262 - INFO - Added job "regulartime_task (trigger: interval[1 day, 0:00:00], next run at: 2020-02-25 18:37:57.017803)" to job store "default"
2020-02-25 18:37:47,017 - _real_add_job - 262 - INFO - Added job "OpenLog (trigger: cron[hour='0'], next run at: 2020-02-26 00:00:00)" to job store "default"
2020-02-25 18:37:47,017 - _main_loop - 574 - INFO - Scheduler started
2020-02-25 18:37:47,017 - _main_loop - 579 - DEBUG - Looking for jobs to run
2020-02-25 18:37:47,017 - _main_loop - 588 - DEBUG - Next wakeup is due at 2020-02-25 18:37:57.017803 (in 10.000000 seconds)
2020-02-25 18:37:47,017 - <module> - 58 - DEBUG - SendBefore_NotRecive : [<CNCProcessStatus: CNCProcessStatus object (2038721)>]
2020-02-25 18:37:47,017 - <module> - 59 - DEBUG - Waitfor_Recive : [2038721]
2020-02-25 18:37:57,018 - _main_loop - 579 - DEBUG - Looking for jobs to run
2020-02-25 18:37:57,018 - _run_jobs - 69 - DEBUG - Started worker thread
2020-02-25 18:37:57,018 - _run_job - 509 - INFO - Running job "regulartime_task (trigger: interval[1 day, 0:00:00], next run at: 2020-02-25 18:37:57.017803)" (scheduled at 2020-02-25 18:37:57.017803)
2020-02-25 18:37:57,018 - _main_loop - 588 - DEBUG - Next wakeup is due at 2020-02-26 00:00:00 (in 19322.981839 seconds)
2020-02-25 18:37:57,327 - _run_job - 520 - ERROR - Job "regulartime_task (trigger: interval[1 day, 0:00:00], next run at: 2020-02-26 18:37:57.017803)" raised an exception
Traceback (most recent call last):
  File "D:\Program Files\Python37\lib\site-packages\django\db\backends\utils.py", line 84, in _execute
    return self.cursor.execute(sql, params)
  File "D:\Program Files\Python37\lib\site-packages\django\db\backends\mysql\base.py", line 71, in execute
    return self.cursor.execute(query, args)
  File "D:\Program Files\Python37\lib\site-packages\MySQLdb\cursors.py", line 209, in execute
    res = self._query(query)
  File "D:\Program Files\Python37\lib\site-packages\MySQLdb\cursors.py", line 315, in _query
    db.query(q)
  File "D:\Program Files\Python37\lib\site-packages\MySQLdb\connections.py", line 239, in query
    _mysql.connection.query(self, query)
MySQLdb._exceptions.IntegrityError: (1062, "Duplicate entry '1582646400' for key 'LAMProcessData_process_r_acquisition_timestamp_a69ae90c_uniq'")

The above exception was the direct cause of the following exception:

Traceback (most recent call last):
  File "D:\Program Files\Python37\lib\site-packages\apscheduler\scheduler.py", line 512, in _run_job
    retval = job.func(*job.args, **job.kwargs)
  File "E:\1-program\11-LAMDataServer\lamdataserver\LAMProcessData\views.py", line 4022, in regulartime_task
    RT_FineData.Realtime_FineData.init_Tomorrow_rows()
  File "E:\1-program\11-LAMDataServer\lamdataserver\LAMProcessData\process_realtime_finedata.py", line 172, in init_Tomorrow_rows
    _model.objects.bulk_create(insert_data_list)
  File "D:\Program Files\Python37\lib\site-packages\django\db\models\manager.py", line 82, in manager_method
    return getattr(self.get_queryset(), name)(*args, **kwargs)
  File "D:\Program Files\Python37\lib\site-packages\django\db\models\query.py", line 474, in bulk_create
    ids = self._batched_insert(objs_without_pk, fields, batch_size, ignore_conflicts=ignore_conflicts)
  File "D:\Program Files\Python37\lib\site-packages\django\db\models\query.py", line 1211, in _batched_insert
    self._insert(item, fields=fields, using=self.db, ignore_conflicts=ignore_conflicts)
  File "D:\Program Files\Python37\lib\site-packages\django\db\models\query.py", line 1186, in _insert
    return query.get_compiler(using=using).execute_sql(return_id)
  File "D:\Program Files\Python37\lib\site-packages\django\db\models\sql\compiler.py", line 1332, in execute_sql
    cursor.execute(sql, params)
  File "D:\Program Files\Python37\lib\site-packages\django\db\backends\utils.py", line 99, in execute
    return super().execute(sql, params)
  File "D:\Program Files\Python37\lib\site-packages\django\db\backends\utils.py", line 67, in execute
    return self._execute_with_wrappers(sql, params, many=False, executor=self._execute)
  File "D:\Program Files\Python37\lib\site-packages\django\db\backends\utils.py", line 76, in _execute_with_wrappers
    return executor(sql, params, many, context)
  File "D:\Program Files\Python37\lib\site-packages\django\db\backends\utils.py", line 84, in _execute
    return self.cursor.execute(sql, params)
  File "D:\Program Files\Python37\lib\site-packages\django\db\utils.py", line 89, in __exit__
    raise dj_exc_value.with_traceback(traceback) from exc_value
  File "D:\Program Files\Python37\lib\site-packages\django\db\backends\utils.py", line 84, in _execute
    return self.cursor.execute(sql, params)
  File "D:\Program Files\Python37\lib\site-packages\django\db\backends\mysql\base.py", line 71, in execute
    return self.cursor.execute(query, args)
  File "D:\Program Files\Python37\lib\site-packages\MySQLdb\cursors.py", line 209, in execute
    res = self._query(query)
  File "D:\Program Files\Python37\lib\site-packages\MySQLdb\cursors.py", line 315, in _query
    db.query(q)
  File "D:\Program Files\Python37\lib\site-packages\MySQLdb\connections.py", line 239, in query
    _mysql.connection.query(self, query)
django.db.utils.IntegrityError: (1062, "Duplicate entry '1582646400' for key 'LAMProcessData_process_r_acquisition_timestamp_a69ae90c_uniq'")
2020-02-25 18:37:58,347 - _run_jobs - 94 - DEBUG - Exiting worker thread
2020-02-25 18:38:13,183 - _real_add_job - 262 - INFO - Added job "regulartime_task (trigger: interval[1 day, 0:00:00], next run at: 2020-02-25 18:38:23.182261)" to job store "default"
2020-02-25 18:38:13,183 - _real_add_job - 262 - INFO - Added job "OpenLog (trigger: cron[hour='0'], next run at: 2020-02-26 00:00:00)" to job store "default"
2020-02-25 18:38:13,183 - _main_loop - 574 - INFO - Scheduler started
2020-02-25 18:38:13,184 - _main_loop - 579 - DEBUG - Looking for jobs to run
2020-02-25 18:38:13,184 - _main_loop - 588 - DEBUG - Next wakeup is due at 2020-02-25 18:38:23.182261 (in 9.998037 seconds)
2020-02-25 18:38:13,192 - <module> - 58 - DEBUG - SendBefore_NotRecive : [<CNCProcessStatus: CNCProcessStatus object (2038721)>]
2020-02-25 18:38:13,192 - <module> - 59 - DEBUG - Waitfor_Recive : [2038721]
2020-02-25 18:38:25,986 - _real_add_job - 262 - INFO - Added job "regulartime_task (trigger: interval[1 day, 0:00:00], next run at: 2020-02-25 18:38:35.984755)" to job store "default"
2020-02-25 18:38:25,986 - _real_add_job - 262 - INFO - Added job "OpenLog (trigger: cron[hour='0'], next run at: 2020-02-26 00:00:00)" to job store "default"
2020-02-25 18:38:25,987 - _main_loop - 574 - INFO - Scheduler started
2020-02-25 18:38:25,988 - _main_loop - 579 - DEBUG - Looking for jobs to run
2020-02-25 18:38:25,988 - _main_loop - 588 - DEBUG - Next wakeup is due at 2020-02-25 18:38:35.984755 (in 9.996185 seconds)
2020-02-25 18:38:25,999 - <module> - 58 - DEBUG - SendBefore_NotRecive : [<CNCProcessStatus: CNCProcessStatus object (2038721)>]
2020-02-25 18:38:25,999 - <module> - 59 - DEBUG - Waitfor_Recive : [2038721]
2020-02-25 18:38:35,993 - _main_loop - 579 - DEBUG - Looking for jobs to run
2020-02-25 18:38:35,993 - _run_jobs - 69 - DEBUG - Started worker thread
2020-02-25 18:38:35,993 - _main_loop - 588 - DEBUG - Next wakeup is due at 2020-02-26 00:00:00 (in 19284.006907 seconds)
2020-02-25 18:38:35,993 - _run_job - 509 - INFO - Running job "regulartime_task (trigger: interval[1 day, 0:00:00], next run at: 2020-02-26 18:38:35.984755)" (scheduled at 2020-02-25 18:38:35.984755)
2020-02-25 18:38:36,939 - _run_job - 520 - ERROR - Job "regulartime_task (trigger: interval[1 day, 0:00:00], next run at: 2020-02-26 18:38:35.984755)" raised an exception
Traceback (most recent call last):
  File "D:\Program Files\Python37\lib\site-packages\django\db\backends\utils.py", line 84, in _execute
    return self.cursor.execute(sql, params)
  File "D:\Program Files\Python37\lib\site-packages\django\db\backends\mysql\base.py", line 71, in execute
    return self.cursor.execute(query, args)
  File "D:\Program Files\Python37\lib\site-packages\MySQLdb\cursors.py", line 209, in execute
    res = self._query(query)
  File "D:\Program Files\Python37\lib\site-packages\MySQLdb\cursors.py", line 315, in _query
    db.query(q)
  File "D:\Program Files\Python37\lib\site-packages\MySQLdb\connections.py", line 239, in query
    _mysql.connection.query(self, query)
MySQLdb._exceptions.IntegrityError: (1062, "Duplicate entry '1582646400' for key 'LAMProcessData_process_r_acquisition_timestamp_a69ae90c_uniq'")

The above exception was the direct cause of the following exception:

Traceback (most recent call last):
  File "D:\Program Files\Python37\lib\site-packages\apscheduler\scheduler.py", line 512, in _run_job
    retval = job.func(*job.args, **job.kwargs)
  File "E:\1-program\11-LAMDataServer\lamdataserver\LAMProcessData\views.py", line 4022, in regulartime_task
    RT_FineData.Realtime_FineData.init_Tomorrow_rows()
  File "E:\1-program\11-LAMDataServer\lamdataserver\LAMProcessData\process_realtime_finedata.py", line 172, in init_Tomorrow_rows
    _model.objects.bulk_create(insert_data_list)
  File "D:\Program Files\Python37\lib\site-packages\django\db\models\manager.py", line 82, in manager_method
    return getattr(self.get_queryset(), name)(*args, **kwargs)
  File "D:\Program Files\Python37\lib\site-packages\django\db\models\query.py", line 474, in bulk_create
    ids = self._batched_insert(objs_without_pk, fields, batch_size, ignore_conflicts=ignore_conflicts)
  File "D:\Program Files\Python37\lib\site-packages\django\db\models\query.py", line 1211, in _batched_insert
    self._insert(item, fields=fields, using=self.db, ignore_conflicts=ignore_conflicts)
  File "D:\Program Files\Python37\lib\site-packages\django\db\models\query.py", line 1186, in _insert
    return query.get_compiler(using=using).execute_sql(return_id)
  File "D:\Program Files\Python37\lib\site-packages\django\db\models\sql\compiler.py", line 1332, in execute_sql
    cursor.execute(sql, params)
  File "D:\Program Files\Python37\lib\site-packages\django\db\backends\utils.py", line 99, in execute
    return super().execute(sql, params)
  File "D:\Program Files\Python37\lib\site-packages\django\db\backends\utils.py", line 67, in execute
    return self._execute_with_wrappers(sql, params, many=False, executor=self._execute)
  File "D:\Program Files\Python37\lib\site-packages\django\db\backends\utils.py", line 76, in _execute_with_wrappers
    return executor(sql, params, many, context)
  File "D:\Program Files\Python37\lib\site-packages\django\db\backends\utils.py", line 84, in _execute
    return self.cursor.execute(sql, params)
  File "D:\Program Files\Python37\lib\site-packages\django\db\utils.py", line 89, in __exit__
    raise dj_exc_value.with_traceback(traceback) from exc_value
  File "D:\Program Files\Python37\lib\site-packages\django\db\backends\utils.py", line 84, in _execute
    return self.cursor.execute(sql, params)
  File "D:\Program Files\Python37\lib\site-packages\django\db\backends\mysql\base.py", line 71, in execute
    return self.cursor.execute(query, args)
  File "D:\Program Files\Python37\lib\site-packages\MySQLdb\cursors.py", line 209, in execute
    res = self._query(query)
  File "D:\Program Files\Python37\lib\site-packages\MySQLdb\cursors.py", line 315, in _query
    db.query(q)
  File "D:\Program Files\Python37\lib\site-packages\MySQLdb\connections.py", line 239, in query
    _mysql.connection.query(self, query)
django.db.utils.IntegrityError: (1062, "Duplicate entry '1582646400' for key 'LAMProcessData_process_r_acquisition_timestamp_a69ae90c_uniq'")
2020-02-25 18:38:37,958 - _run_jobs - 94 - DEBUG - Exiting worker thread
2020-02-25 18:39:36,777 - _real_add_job - 262 - INFO - Added job "regulartime_task (trigger: interval[1 day, 0:00:00], next run at: 2020-02-25 18:39:46.777687)" to job store "default"
2020-02-25 18:39:36,777 - _real_add_job - 262 - INFO - Added job "OpenLog (trigger: cron[hour='0'], next run at: 2020-02-26 00:00:00)" to job store "default"
2020-02-25 18:39:36,777 - _main_loop - 574 - INFO - Scheduler started
2020-02-25 18:39:36,777 - _main_loop - 579 - DEBUG - Looking for jobs to run
2020-02-25 18:39:36,777 - _main_loop - 588 - DEBUG - Next wakeup is due at 2020-02-25 18:39:46.777687 (in 10.000001 seconds)
2020-02-25 18:39:36,797 - <module> - 58 - DEBUG - SendBefore_NotRecive : [<CNCProcessStatus: CNCProcessStatus object (2038721)>]
2020-02-25 18:39:36,797 - <module> - 59 - DEBUG - Waitfor_Recive : [2038721]
2020-02-25 18:39:46,783 - _main_loop - 579 - DEBUG - Looking for jobs to run
2020-02-25 18:39:46,784 - _run_jobs - 69 - DEBUG - Started worker thread
2020-02-25 18:39:46,784 - _run_job - 509 - INFO - Running job "regulartime_task (trigger: interval[1 day, 0:00:00], next run at: 2020-02-25 18:39:46.777687)" (scheduled at 2020-02-25 18:39:46.777687)
2020-02-25 18:39:46,785 - _main_loop - 588 - DEBUG - Next wakeup is due at 2020-02-26 00:00:00 (in 19213.216422 seconds)
2020-02-25 18:39:47,785 - _run_job - 520 - ERROR - Job "regulartime_task (trigger: interval[1 day, 0:00:00], next run at: 2020-02-26 18:39:46.777687)" raised an exception
Traceback (most recent call last):
  File "D:\Program Files\Python37\lib\site-packages\django\db\backends\utils.py", line 84, in _execute
    return self.cursor.execute(sql, params)
  File "D:\Program Files\Python37\lib\site-packages\django\db\backends\mysql\base.py", line 71, in execute
    return self.cursor.execute(query, args)
  File "D:\Program Files\Python37\lib\site-packages\MySQLdb\cursors.py", line 209, in execute
    res = self._query(query)
  File "D:\Program Files\Python37\lib\site-packages\MySQLdb\cursors.py", line 315, in _query
    db.query(q)
  File "D:\Program Files\Python37\lib\site-packages\MySQLdb\connections.py", line 239, in query
    _mysql.connection.query(self, query)
MySQLdb._exceptions.IntegrityError: (1062, "Duplicate entry '1582646400' for key 'LAMProcessData_process_r_acquisition_timestamp_a69ae90c_uniq'")

The above exception was the direct cause of the following exception:

Traceback (most recent call last):
  File "D:\Program Files\Python37\lib\site-packages\apscheduler\scheduler.py", line 512, in _run_job
    retval = job.func(*job.args, **job.kwargs)
  File "E:\1-program\11-LAMDataServer\lamdataserver\LAMProcessData\views.py", line 4022, in regulartime_task
    RT_FineData.Realtime_FineData.init_Tomorrow_rows()
  File "E:\1-program\11-LAMDataServer\lamdataserver\LAMProcessData\process_realtime_finedata.py", line 172, in init_Tomorrow_rows
    _model.objects.bulk_create(insert_data_list)
  File "D:\Program Files\Python37\lib\site-packages\django\db\models\manager.py", line 82, in manager_method
    return getattr(self.get_queryset(), name)(*args, **kwargs)
  File "D:\Program Files\Python37\lib\site-packages\django\db\models\query.py", line 474, in bulk_create
    ids = self._batched_insert(objs_without_pk, fields, batch_size, ignore_conflicts=ignore_conflicts)
  File "D:\Program Files\Python37\lib\site-packages\django\db\models\query.py", line 1211, in _batched_insert
    self._insert(item, fields=fields, using=self.db, ignore_conflicts=ignore_conflicts)
  File "D:\Program Files\Python37\lib\site-packages\django\db\models\query.py", line 1186, in _insert
    return query.get_compiler(using=using).execute_sql(return_id)
  File "D:\Program Files\Python37\lib\site-packages\django\db\models\sql\compiler.py", line 1332, in execute_sql
    cursor.execute(sql, params)
  File "D:\Program Files\Python37\lib\site-packages\django\db\backends\utils.py", line 99, in execute
    return super().execute(sql, params)
  File "D:\Program Files\Python37\lib\site-packages\django\db\backends\utils.py", line 67, in execute
    return self._execute_with_wrappers(sql, params, many=False, executor=self._execute)
  File "D:\Program Files\Python37\lib\site-packages\django\db\backends\utils.py", line 76, in _execute_with_wrappers
    return executor(sql, params, many, context)
  File "D:\Program Files\Python37\lib\site-packages\django\db\backends\utils.py", line 84, in _execute
    return self.cursor.execute(sql, params)
  File "D:\Program Files\Python37\lib\site-packages\django\db\utils.py", line 89, in __exit__
    raise dj_exc_value.with_traceback(traceback) from exc_value
  File "D:\Program Files\Python37\lib\site-packages\django\db\backends\utils.py", line 84, in _execute
    return self.cursor.execute(sql, params)
  File "D:\Program Files\Python37\lib\site-packages\django\db\backends\mysql\base.py", line 71, in execute
    return self.cursor.execute(query, args)
  File "D:\Program Files\Python37\lib\site-packages\MySQLdb\cursors.py", line 209, in execute
    res = self._query(query)
  File "D:\Program Files\Python37\lib\site-packages\MySQLdb\cursors.py", line 315, in _query
    db.query(q)
  File "D:\Program Files\Python37\lib\site-packages\MySQLdb\connections.py", line 239, in query
    _mysql.connection.query(self, query)
django.db.utils.IntegrityError: (1062, "Duplicate entry '1582646400' for key 'LAMProcessData_process_r_acquisition_timestamp_a69ae90c_uniq'")
2020-02-25 18:39:48,795 - _run_jobs - 94 - DEBUG - Exiting worker thread
2020-02-25 18:42:59,019 - _real_add_job - 262 - INFO - Added job "regulartime_task (trigger: interval[1 day, 0:00:00], next run at: 2020-02-25 18:43:09.017662)" to job store "default"
2020-02-25 18:42:59,019 - _real_add_job - 262 - INFO - Added job "OpenLog (trigger: cron[hour='0'], next run at: 2020-02-26 00:00:00)" to job store "default"
2020-02-25 18:42:59,020 - _main_loop - 574 - INFO - Scheduler started
2020-02-25 18:42:59,020 - _main_loop - 579 - DEBUG - Looking for jobs to run
2020-02-25 18:42:59,020 - _main_loop - 588 - DEBUG - Next wakeup is due at 2020-02-25 18:43:09.017662 (in 9.997008 seconds)
2020-02-25 18:42:59,031 - <module> - 58 - DEBUG - SendBefore_NotRecive : [<CNCProcessStatus: CNCProcessStatus object (2038721)>]
2020-02-25 18:42:59,032 - <module> - 59 - DEBUG - Waitfor_Recive : [2038721]
2020-02-25 18:43:09,019 - _main_loop - 579 - DEBUG - Looking for jobs to run
2020-02-25 18:43:09,021 - _run_jobs - 69 - DEBUG - Started worker thread
2020-02-25 18:43:09,021 - _run_job - 509 - INFO - Running job "regulartime_task (trigger: interval[1 day, 0:00:00], next run at: 2020-02-25 18:43:09.017662)" (scheduled at 2020-02-25 18:43:09.017662)
2020-02-25 18:43:09,022 - _main_loop - 588 - DEBUG - Next wakeup is due at 2020-02-26 00:00:00 (in 19010.980386 seconds)
2020-02-25 18:43:10,046 - _run_job - 520 - ERROR - Job "regulartime_task (trigger: interval[1 day, 0:00:00], next run at: 2020-02-26 18:43:09.017662)" raised an exception
Traceback (most recent call last):
  File "D:\Program Files\Python37\lib\site-packages\django\db\backends\utils.py", line 84, in _execute
    return self.cursor.execute(sql, params)
  File "D:\Program Files\Python37\lib\site-packages\django\db\backends\mysql\base.py", line 71, in execute
    return self.cursor.execute(query, args)
  File "D:\Program Files\Python37\lib\site-packages\MySQLdb\cursors.py", line 209, in execute
    res = self._query(query)
  File "D:\Program Files\Python37\lib\site-packages\MySQLdb\cursors.py", line 315, in _query
    db.query(q)
  File "D:\Program Files\Python37\lib\site-packages\MySQLdb\connections.py", line 239, in query
    _mysql.connection.query(self, query)
MySQLdb._exceptions.IntegrityError: (1062, "Duplicate entry '1582646400' for key 'LAMProcessData_process_r_acquisition_timestamp_a69ae90c_uniq'")

The above exception was the direct cause of the following exception:

Traceback (most recent call last):
  File "D:\Program Files\Python37\lib\site-packages\apscheduler\scheduler.py", line 512, in _run_job
    retval = job.func(*job.args, **job.kwargs)
  File "E:\1-program\11-LAMDataServer\lamdataserver\LAMProcessData\views.py", line 4022, in regulartime_task
    RT_FineData.Realtime_FineData.init_Tomorrow_rows()
  File "E:\1-program\11-LAMDataServer\lamdataserver\LAMProcessData\process_realtime_finedata.py", line 172, in init_Tomorrow_rows
    _model.objects.bulk_create(insert_data_list)
  File "D:\Program Files\Python37\lib\site-packages\django\db\models\manager.py", line 82, in manager_method
    return getattr(self.get_queryset(), name)(*args, **kwargs)
  File "D:\Program Files\Python37\lib\site-packages\django\db\models\query.py", line 474, in bulk_create
    ids = self._batched_insert(objs_without_pk, fields, batch_size, ignore_conflicts=ignore_conflicts)
  File "D:\Program Files\Python37\lib\site-packages\django\db\models\query.py", line 1211, in _batched_insert
    self._insert(item, fields=fields, using=self.db, ignore_conflicts=ignore_conflicts)
  File "D:\Program Files\Python37\lib\site-packages\django\db\models\query.py", line 1186, in _insert
    return query.get_compiler(using=using).execute_sql(return_id)
  File "D:\Program Files\Python37\lib\site-packages\django\db\models\sql\compiler.py", line 1332, in execute_sql
    cursor.execute(sql, params)
  File "D:\Program Files\Python37\lib\site-packages\django\db\backends\utils.py", line 99, in execute
    return super().execute(sql, params)
  File "D:\Program Files\Python37\lib\site-packages\django\db\backends\utils.py", line 67, in execute
    return self._execute_with_wrappers(sql, params, many=False, executor=self._execute)
  File "D:\Program Files\Python37\lib\site-packages\django\db\backends\utils.py", line 76, in _execute_with_wrappers
    return executor(sql, params, many, context)
  File "D:\Program Files\Python37\lib\site-packages\django\db\backends\utils.py", line 84, in _execute
    return self.cursor.execute(sql, params)
  File "D:\Program Files\Python37\lib\site-packages\django\db\utils.py", line 89, in __exit__
    raise dj_exc_value.with_traceback(traceback) from exc_value
  File "D:\Program Files\Python37\lib\site-packages\django\db\backends\utils.py", line 84, in _execute
    return self.cursor.execute(sql, params)
  File "D:\Program Files\Python37\lib\site-packages\django\db\backends\mysql\base.py", line 71, in execute
    return self.cursor.execute(query, args)
  File "D:\Program Files\Python37\lib\site-packages\MySQLdb\cursors.py", line 209, in execute
    res = self._query(query)
  File "D:\Program Files\Python37\lib\site-packages\MySQLdb\cursors.py", line 315, in _query
    db.query(q)
  File "D:\Program Files\Python37\lib\site-packages\MySQLdb\connections.py", line 239, in query
    _mysql.connection.query(self, query)
django.db.utils.IntegrityError: (1062, "Duplicate entry '1582646400' for key 'LAMProcessData_process_r_acquisition_timestamp_a69ae90c_uniq'")
2020-02-25 18:43:11,056 - _run_jobs - 94 - DEBUG - Exiting worker thread
2020-02-25 18:43:44,958 - _real_add_job - 262 - INFO - Added job "regulartime_task (trigger: interval[1 day, 0:00:00], next run at: 2020-02-25 18:43:54.957273)" to job store "default"
2020-02-25 18:43:44,958 - _real_add_job - 262 - INFO - Added job "OpenLog (trigger: cron[hour='0'], next run at: 2020-02-26 00:00:00)" to job store "default"
2020-02-25 18:43:44,958 - _main_loop - 574 - INFO - Scheduler started
2020-02-25 18:43:44,958 - _main_loop - 579 - DEBUG - Looking for jobs to run
2020-02-25 18:43:44,958 - _main_loop - 588 - DEBUG - Next wakeup is due at 2020-02-25 18:43:54.957273 (in 9.998988 seconds)
2020-02-25 18:43:44,966 - <module> - 58 - DEBUG - SendBefore_NotRecive : [<CNCProcessStatus: CNCProcessStatus object (2038721)>]
2020-02-25 18:43:44,966 - <module> - 59 - DEBUG - Waitfor_Recive : [2038721]
2020-02-25 18:43:54,957 - _main_loop - 579 - DEBUG - Looking for jobs to run
2020-02-25 18:43:54,959 - _run_jobs - 69 - DEBUG - Started worker thread
2020-02-25 18:43:54,960 - _run_job - 509 - INFO - Running job "regulartime_task (trigger: interval[1 day, 0:00:00], next run at: 2020-02-25 18:43:54.957273)" (scheduled at 2020-02-25 18:43:54.957273)
2020-02-25 18:43:54,961 - _main_loop - 588 - DEBUG - Next wakeup is due at 2020-02-26 00:00:00 (in 18965.041583 seconds)
2020-02-25 18:43:55,287 - _run_job - 520 - ERROR - Job "regulartime_task (trigger: interval[1 day, 0:00:00], next run at: 2020-02-26 18:43:54.957273)" raised an exception
Traceback (most recent call last):
  File "D:\Program Files\Python37\lib\site-packages\django\db\backends\utils.py", line 84, in _execute
    return self.cursor.execute(sql, params)
  File "D:\Program Files\Python37\lib\site-packages\django\db\backends\mysql\base.py", line 71, in execute
    return self.cursor.execute(query, args)
  File "D:\Program Files\Python37\lib\site-packages\MySQLdb\cursors.py", line 209, in execute
    res = self._query(query)
  File "D:\Program Files\Python37\lib\site-packages\MySQLdb\cursors.py", line 315, in _query
    db.query(q)
  File "D:\Program Files\Python37\lib\site-packages\MySQLdb\connections.py", line 239, in query
    _mysql.connection.query(self, query)
MySQLdb._exceptions.IntegrityError: (1062, "Duplicate entry '1582646400' for key 'LAMProcessData_process_r_acquisition_timestamp_a69ae90c_uniq'")

The above exception was the direct cause of the following exception:

Traceback (most recent call last):
  File "D:\Program Files\Python37\lib\site-packages\apscheduler\scheduler.py", line 512, in _run_job
    retval = job.func(*job.args, **job.kwargs)
  File "E:\1-program\11-LAMDataServer\lamdataserver\LAMProcessData\views.py", line 4022, in regulartime_task
    RT_FineData.Realtime_FineData.init_Tomorrow_rows()
  File "E:\1-program\11-LAMDataServer\lamdataserver\LAMProcessData\process_realtime_finedata.py", line 172, in init_Tomorrow_rows
    _model.objects.bulk_create(insert_data_list)
  File "D:\Program Files\Python37\lib\site-packages\django\db\models\manager.py", line 82, in manager_method
    return getattr(self.get_queryset(), name)(*args, **kwargs)
  File "D:\Program Files\Python37\lib\site-packages\django\db\models\query.py", line 474, in bulk_create
    ids = self._batched_insert(objs_without_pk, fields, batch_size, ignore_conflicts=ignore_conflicts)
  File "D:\Program Files\Python37\lib\site-packages\django\db\models\query.py", line 1211, in _batched_insert
    self._insert(item, fields=fields, using=self.db, ignore_conflicts=ignore_conflicts)
  File "D:\Program Files\Python37\lib\site-packages\django\db\models\query.py", line 1186, in _insert
    return query.get_compiler(using=using).execute_sql(return_id)
  File "D:\Program Files\Python37\lib\site-packages\django\db\models\sql\compiler.py", line 1332, in execute_sql
    cursor.execute(sql, params)
  File "D:\Program Files\Python37\lib\site-packages\django\db\backends\utils.py", line 99, in execute
    return super().execute(sql, params)
  File "D:\Program Files\Python37\lib\site-packages\django\db\backends\utils.py", line 67, in execute
    return self._execute_with_wrappers(sql, params, many=False, executor=self._execute)
  File "D:\Program Files\Python37\lib\site-packages\django\db\backends\utils.py", line 76, in _execute_with_wrappers
    return executor(sql, params, many, context)
  File "D:\Program Files\Python37\lib\site-packages\django\db\backends\utils.py", line 84, in _execute
    return self.cursor.execute(sql, params)
  File "D:\Program Files\Python37\lib\site-packages\django\db\utils.py", line 89, in __exit__
    raise dj_exc_value.with_traceback(traceback) from exc_value
  File "D:\Program Files\Python37\lib\site-packages\django\db\backends\utils.py", line 84, in _execute
    return self.cursor.execute(sql, params)
  File "D:\Program Files\Python37\lib\site-packages\django\db\backends\mysql\base.py", line 71, in execute
    return self.cursor.execute(query, args)
  File "D:\Program Files\Python37\lib\site-packages\MySQLdb\cursors.py", line 209, in execute
    res = self._query(query)
  File "D:\Program Files\Python37\lib\site-packages\MySQLdb\cursors.py", line 315, in _query
    db.query(q)
  File "D:\Program Files\Python37\lib\site-packages\MySQLdb\connections.py", line 239, in query
    _mysql.connection.query(self, query)
django.db.utils.IntegrityError: (1062, "Duplicate entry '1582646400' for key 'LAMProcessData_process_r_acquisition_timestamp_a69ae90c_uniq'")
2020-02-25 18:43:56,291 - _run_jobs - 94 - DEBUG - Exiting worker thread
2020-02-25 18:58:00,164 - trigger_reload - 203 - INFO - E:\1-program\11-LAMDataServer\lamdataserver\LAMProcessData\views.py changed, reloading.
2020-02-25 18:58:00,164 - shutdown - 111 - INFO - Shutting down thread pool
2020-02-25 18:58:01,414 - _real_add_job - 262 - INFO - Added job "regulartime_task (trigger: interval[1 day, 0:00:00], next run at: 2020-02-25 18:58:11.414970)" to job store "default"
2020-02-25 18:58:01,414 - _real_add_job - 262 - INFO - Added job "OpenLog (trigger: cron[hour='0'], next run at: 2020-02-26 00:00:00)" to job store "default"
2020-02-25 18:58:01,414 - _main_loop - 574 - INFO - Scheduler started
2020-02-25 18:58:01,414 - _main_loop - 579 - DEBUG - Looking for jobs to run
2020-02-25 18:58:01,414 - _main_loop - 588 - DEBUG - Next wakeup is due at 2020-02-25 18:58:11.414970 (in 10.000000 seconds)
2020-02-25 18:58:01,424 - <module> - 58 - DEBUG - SendBefore_NotRecive : [<CNCProcessStatus: CNCProcessStatus object (2038721)>]
2020-02-25 18:58:01,424 - <module> - 59 - DEBUG - Waitfor_Recive : [2038721]
2020-02-25 18:58:11,424 - _main_loop - 579 - DEBUG - Looking for jobs to run
2020-02-25 18:58:11,424 - _run_jobs - 69 - DEBUG - Started worker thread
2020-02-25 18:58:11,424 - _run_job - 509 - INFO - Running job "regulartime_task (trigger: interval[1 day, 0:00:00], next run at: 2020-02-25 18:58:11.414970)" (scheduled at 2020-02-25 18:58:11.414970)
2020-02-25 18:58:11,424 - _main_loop - 588 - DEBUG - Next wakeup is due at 2020-02-26 00:00:00 (in 18108.575172 seconds)
2020-02-25 18:58:11,951 - _run_job - 520 - ERROR - Job "regulartime_task (trigger: interval[1 day, 0:00:00], next run at: 2020-02-26 18:58:11.414970)" raised an exception
Traceback (most recent call last):
  File "D:\Program Files\Python37\lib\site-packages\django\db\backends\utils.py", line 84, in _execute
    return self.cursor.execute(sql, params)
  File "D:\Program Files\Python37\lib\site-packages\django\db\backends\mysql\base.py", line 71, in execute
    return self.cursor.execute(query, args)
  File "D:\Program Files\Python37\lib\site-packages\MySQLdb\cursors.py", line 209, in execute
    res = self._query(query)
  File "D:\Program Files\Python37\lib\site-packages\MySQLdb\cursors.py", line 315, in _query
    db.query(q)
  File "D:\Program Files\Python37\lib\site-packages\MySQLdb\connections.py", line 239, in query
    _mysql.connection.query(self, query)
MySQLdb._exceptions.IntegrityError: (1062, "Duplicate entry '1582646400' for key 'LAMProcessData_process_r_acquisition_timestamp_a69ae90c_uniq'")

The above exception was the direct cause of the following exception:

Traceback (most recent call last):
  File "D:\Program Files\Python37\lib\site-packages\apscheduler\scheduler.py", line 512, in _run_job
    retval = job.func(*job.args, **job.kwargs)
  File "E:\1-program\11-LAMDataServer\lamdataserver\LAMProcessData\views.py", line 4030, in regulartime_task
    RT_FineData.Realtime_FineData.init_Tomorrow_rows()
  File "E:\1-program\11-LAMDataServer\lamdataserver\LAMProcessData\process_realtime_finedata.py", line 172, in init_Tomorrow_rows
    _model.objects.bulk_create(insert_data_list)
  File "D:\Program Files\Python37\lib\site-packages\django\db\models\manager.py", line 82, in manager_method
    return getattr(self.get_queryset(), name)(*args, **kwargs)
  File "D:\Program Files\Python37\lib\site-packages\django\db\models\query.py", line 474, in bulk_create
    ids = self._batched_insert(objs_without_pk, fields, batch_size, ignore_conflicts=ignore_conflicts)
  File "D:\Program Files\Python37\lib\site-packages\django\db\models\query.py", line 1211, in _batched_insert
    self._insert(item, fields=fields, using=self.db, ignore_conflicts=ignore_conflicts)
  File "D:\Program Files\Python37\lib\site-packages\django\db\models\query.py", line 1186, in _insert
    return query.get_compiler(using=using).execute_sql(return_id)
  File "D:\Program Files\Python37\lib\site-packages\django\db\models\sql\compiler.py", line 1332, in execute_sql
    cursor.execute(sql, params)
  File "D:\Program Files\Python37\lib\site-packages\django\db\backends\utils.py", line 99, in execute
    return super().execute(sql, params)
  File "D:\Program Files\Python37\lib\site-packages\django\db\backends\utils.py", line 67, in execute
    return self._execute_with_wrappers(sql, params, many=False, executor=self._execute)
  File "D:\Program Files\Python37\lib\site-packages\django\db\backends\utils.py", line 76, in _execute_with_wrappers
    return executor(sql, params, many, context)
  File "D:\Program Files\Python37\lib\site-packages\django\db\backends\utils.py", line 84, in _execute
    return self.cursor.execute(sql, params)
  File "D:\Program Files\Python37\lib\site-packages\django\db\utils.py", line 89, in __exit__
    raise dj_exc_value.with_traceback(traceback) from exc_value
  File "D:\Program Files\Python37\lib\site-packages\django\db\backends\utils.py", line 84, in _execute
    return self.cursor.execute(sql, params)
  File "D:\Program Files\Python37\lib\site-packages\django\db\backends\mysql\base.py", line 71, in execute
    return self.cursor.execute(query, args)
  File "D:\Program Files\Python37\lib\site-packages\MySQLdb\cursors.py", line 209, in execute
    res = self._query(query)
  File "D:\Program Files\Python37\lib\site-packages\MySQLdb\cursors.py", line 315, in _query
    db.query(q)
  File "D:\Program Files\Python37\lib\site-packages\MySQLdb\connections.py", line 239, in query
    _mysql.connection.query(self, query)
django.db.utils.IntegrityError: (1062, "Duplicate entry '1582646400' for key 'LAMProcessData_process_r_acquisition_timestamp_a69ae90c_uniq'")
2020-02-25 18:58:12,764 - trigger_reload - 203 - INFO - E:\1-program\11-LAMDataServer\lamdataserver\LAMProcessData\urls.py changed, reloading.
2020-02-25 18:58:12,764 - shutdown - 111 - INFO - Shutting down thread pool
2020-02-25 18:58:12,764 - _run_jobs - 94 - DEBUG - Exiting worker thread
2020-02-25 18:58:14,034 - _real_add_job - 262 - INFO - Added job "regulartime_task (trigger: interval[1 day, 0:00:00], next run at: 2020-02-25 18:58:24.034923)" to job store "default"
2020-02-25 18:58:14,034 - _real_add_job - 262 - INFO - Added job "OpenLog (trigger: cron[hour='0'], next run at: 2020-02-26 00:00:00)" to job store "default"
2020-02-25 18:58:14,034 - _main_loop - 574 - INFO - Scheduler started
2020-02-25 18:58:14,034 - _main_loop - 579 - DEBUG - Looking for jobs to run
2020-02-25 18:58:14,034 - _main_loop - 588 - DEBUG - Next wakeup is due at 2020-02-25 18:58:24.034923 (in 10.000000 seconds)
2020-02-25 18:58:14,044 - <module> - 58 - DEBUG - SendBefore_NotRecive : [<CNCProcessStatus: CNCProcessStatus object (2038721)>]
2020-02-25 18:58:14,044 - <module> - 59 - DEBUG - Waitfor_Recive : [2038721]
2020-02-25 18:58:24,045 - _main_loop - 579 - DEBUG - Looking for jobs to run
2020-02-25 18:58:24,046 - _run_jobs - 69 - DEBUG - Started worker thread
2020-02-25 18:58:24,046 - _main_loop - 588 - DEBUG - Next wakeup is due at 2020-02-26 00:00:00 (in 18095.954550 seconds)
2020-02-25 18:58:24,046 - _run_job - 509 - INFO - Running job "regulartime_task (trigger: interval[1 day, 0:00:00], next run at: 2020-02-26 18:58:24.034923)" (scheduled at 2020-02-25 18:58:24.034923)
2020-02-25 18:58:24,363 - _run_job - 520 - ERROR - Job "regulartime_task (trigger: interval[1 day, 0:00:00], next run at: 2020-02-26 18:58:24.034923)" raised an exception
Traceback (most recent call last):
  File "D:\Program Files\Python37\lib\site-packages\django\db\backends\utils.py", line 84, in _execute
    return self.cursor.execute(sql, params)
  File "D:\Program Files\Python37\lib\site-packages\django\db\backends\mysql\base.py", line 71, in execute
    return self.cursor.execute(query, args)
  File "D:\Program Files\Python37\lib\site-packages\MySQLdb\cursors.py", line 209, in execute
    res = self._query(query)
  File "D:\Program Files\Python37\lib\site-packages\MySQLdb\cursors.py", line 315, in _query
    db.query(q)
  File "D:\Program Files\Python37\lib\site-packages\MySQLdb\connections.py", line 239, in query
    _mysql.connection.query(self, query)
MySQLdb._exceptions.IntegrityError: (1062, "Duplicate entry '1582646400' for key 'LAMProcessData_process_r_acquisition_timestamp_a69ae90c_uniq'")

The above exception was the direct cause of the following exception:

Traceback (most recent call last):
  File "D:\Program Files\Python37\lib\site-packages\apscheduler\scheduler.py", line 512, in _run_job
    retval = job.func(*job.args, **job.kwargs)
  File "E:\1-program\11-LAMDataServer\lamdataserver\LAMProcessData\views.py", line 4030, in regulartime_task
    RT_FineData.Realtime_FineData.init_Tomorrow_rows()
  File "E:\1-program\11-LAMDataServer\lamdataserver\LAMProcessData\process_realtime_finedata.py", line 172, in init_Tomorrow_rows
    _model.objects.bulk_create(insert_data_list)
  File "D:\Program Files\Python37\lib\site-packages\django\db\models\manager.py", line 82, in manager_method
    return getattr(self.get_queryset(), name)(*args, **kwargs)
  File "D:\Program Files\Python37\lib\site-packages\django\db\models\query.py", line 474, in bulk_create
    ids = self._batched_insert(objs_without_pk, fields, batch_size, ignore_conflicts=ignore_conflicts)
  File "D:\Program Files\Python37\lib\site-packages\django\db\models\query.py", line 1211, in _batched_insert
    self._insert(item, fields=fields, using=self.db, ignore_conflicts=ignore_conflicts)
  File "D:\Program Files\Python37\lib\site-packages\django\db\models\query.py", line 1186, in _insert
    return query.get_compiler(using=using).execute_sql(return_id)
  File "D:\Program Files\Python37\lib\site-packages\django\db\models\sql\compiler.py", line 1332, in execute_sql
    cursor.execute(sql, params)
  File "D:\Program Files\Python37\lib\site-packages\django\db\backends\utils.py", line 99, in execute
    return super().execute(sql, params)
  File "D:\Program Files\Python37\lib\site-packages\django\db\backends\utils.py", line 67, in execute
    return self._execute_with_wrappers(sql, params, many=False, executor=self._execute)
  File "D:\Program Files\Python37\lib\site-packages\django\db\backends\utils.py", line 76, in _execute_with_wrappers
    return executor(sql, params, many, context)
  File "D:\Program Files\Python37\lib\site-packages\django\db\backends\utils.py", line 84, in _execute
    return self.cursor.execute(sql, params)
  File "D:\Program Files\Python37\lib\site-packages\django\db\utils.py", line 89, in __exit__
    raise dj_exc_value.with_traceback(traceback) from exc_value
  File "D:\Program Files\Python37\lib\site-packages\django\db\backends\utils.py", line 84, in _execute
    return self.cursor.execute(sql, params)
  File "D:\Program Files\Python37\lib\site-packages\django\db\backends\mysql\base.py", line 71, in execute
    return self.cursor.execute(query, args)
  File "D:\Program Files\Python37\lib\site-packages\MySQLdb\cursors.py", line 209, in execute
    res = self._query(query)
  File "D:\Program Files\Python37\lib\site-packages\MySQLdb\cursors.py", line 315, in _query
    db.query(q)
  File "D:\Program Files\Python37\lib\site-packages\MySQLdb\connections.py", line 239, in query
    _mysql.connection.query(self, query)
django.db.utils.IntegrityError: (1062, "Duplicate entry '1582646400' for key 'LAMProcessData_process_r_acquisition_timestamp_a69ae90c_uniq'")
2020-02-25 18:58:25,373 - _run_jobs - 94 - DEBUG - Exiting worker thread
2020-02-25 18:58:40,071 - log_response - 228 - WARNING - Not Found: /favicon.ico
2020-02-25 18:58:47,627 - log_response - 228 - WARNING - Not Found: /3Dtestdata2/
2020-02-25 19:12:24,732 - _real_add_job - 262 - INFO - Added job "regulartime_task (trigger: interval[1 day, 0:00:00], next run at: 2020-02-25 19:12:34.731388)" to job store "default"
2020-02-25 19:12:24,732 - _real_add_job - 262 - INFO - Added job "OpenLog (trigger: cron[hour='0'], next run at: 2020-02-26 00:00:00)" to job store "default"
2020-02-25 19:12:24,733 - _main_loop - 574 - INFO - Scheduler started
2020-02-25 19:12:24,733 - _main_loop - 579 - DEBUG - Looking for jobs to run
2020-02-25 19:12:24,733 - _main_loop - 588 - DEBUG - Next wakeup is due at 2020-02-25 19:12:34.731388 (in 9.998007 seconds)
2020-02-25 19:12:24,741 - <module> - 58 - DEBUG - SendBefore_NotRecive : [<CNCProcessStatus: CNCProcessStatus object (2038721)>]
2020-02-25 19:12:24,741 - <module> - 59 - DEBUG - Waitfor_Recive : [2038721]
2020-02-25 19:12:34,732 - _main_loop - 579 - DEBUG - Looking for jobs to run
2020-02-25 19:12:34,732 - _run_jobs - 69 - DEBUG - Started worker thread
2020-02-25 19:12:34,733 - _main_loop - 588 - DEBUG - Next wakeup is due at 2020-02-26 00:00:00 (in 17245.267353 seconds)
2020-02-25 19:12:34,733 - _run_job - 509 - INFO - Running job "regulartime_task (trigger: interval[1 day, 0:00:00], next run at: 2020-02-26 19:12:34.731388)" (scheduled at 2020-02-25 19:12:34.731388)
2020-02-25 19:12:35,078 - _run_job - 520 - ERROR - Job "regulartime_task (trigger: interval[1 day, 0:00:00], next run at: 2020-02-26 19:12:34.731388)" raised an exception
Traceback (most recent call last):
  File "D:\Program Files\Python37\lib\site-packages\django\db\backends\utils.py", line 84, in _execute
    return self.cursor.execute(sql, params)
  File "D:\Program Files\Python37\lib\site-packages\django\db\backends\mysql\base.py", line 71, in execute
    return self.cursor.execute(query, args)
  File "D:\Program Files\Python37\lib\site-packages\MySQLdb\cursors.py", line 209, in execute
    res = self._query(query)
  File "D:\Program Files\Python37\lib\site-packages\MySQLdb\cursors.py", line 315, in _query
    db.query(q)
  File "D:\Program Files\Python37\lib\site-packages\MySQLdb\connections.py", line 239, in query
    _mysql.connection.query(self, query)
MySQLdb._exceptions.IntegrityError: (1062, "Duplicate entry '1582646400' for key 'LAMProcessData_process_r_acquisition_timestamp_a69ae90c_uniq'")

The above exception was the direct cause of the following exception:

Traceback (most recent call last):
  File "D:\Program Files\Python37\lib\site-packages\apscheduler\scheduler.py", line 512, in _run_job
    retval = job.func(*job.args, **job.kwargs)
  File "E:\1-program\11-LAMDataServer\lamdataserver\LAMProcessData\views.py", line 4030, in regulartime_task
    RT_FineData.Realtime_FineData.init_Tomorrow_rows()
  File "E:\1-program\11-LAMDataServer\lamdataserver\LAMProcessData\process_realtime_finedata.py", line 172, in init_Tomorrow_rows
    _model.objects.bulk_create(insert_data_list)
  File "D:\Program Files\Python37\lib\site-packages\django\db\models\manager.py", line 82, in manager_method
    return getattr(self.get_queryset(), name)(*args, **kwargs)
  File "D:\Program Files\Python37\lib\site-packages\django\db\models\query.py", line 474, in bulk_create
    ids = self._batched_insert(objs_without_pk, fields, batch_size, ignore_conflicts=ignore_conflicts)
  File "D:\Program Files\Python37\lib\site-packages\django\db\models\query.py", line 1211, in _batched_insert
    self._insert(item, fields=fields, using=self.db, ignore_conflicts=ignore_conflicts)
  File "D:\Program Files\Python37\lib\site-packages\django\db\models\query.py", line 1186, in _insert
    return query.get_compiler(using=using).execute_sql(return_id)
  File "D:\Program Files\Python37\lib\site-packages\django\db\models\sql\compiler.py", line 1332, in execute_sql
    cursor.execute(sql, params)
  File "D:\Program Files\Python37\lib\site-packages\django\db\backends\utils.py", line 99, in execute
    return super().execute(sql, params)
  File "D:\Program Files\Python37\lib\site-packages\django\db\backends\utils.py", line 67, in execute
    return self._execute_with_wrappers(sql, params, many=False, executor=self._execute)
  File "D:\Program Files\Python37\lib\site-packages\django\db\backends\utils.py", line 76, in _execute_with_wrappers
    return executor(sql, params, many, context)
  File "D:\Program Files\Python37\lib\site-packages\django\db\backends\utils.py", line 84, in _execute
    return self.cursor.execute(sql, params)
  File "D:\Program Files\Python37\lib\site-packages\django\db\utils.py", line 89, in __exit__
    raise dj_exc_value.with_traceback(traceback) from exc_value
  File "D:\Program Files\Python37\lib\site-packages\django\db\backends\utils.py", line 84, in _execute
    return self.cursor.execute(sql, params)
  File "D:\Program Files\Python37\lib\site-packages\django\db\backends\mysql\base.py", line 71, in execute
    return self.cursor.execute(query, args)
  File "D:\Program Files\Python37\lib\site-packages\MySQLdb\cursors.py", line 209, in execute
    res = self._query(query)
  File "D:\Program Files\Python37\lib\site-packages\MySQLdb\cursors.py", line 315, in _query
    db.query(q)
  File "D:\Program Files\Python37\lib\site-packages\MySQLdb\connections.py", line 239, in query
    _mysql.connection.query(self, query)
django.db.utils.IntegrityError: (1062, "Duplicate entry '1582646400' for key 'LAMProcessData_process_r_acquisition_timestamp_a69ae90c_uniq'")
2020-02-25 19:12:36,081 - _run_jobs - 94 - DEBUG - Exiting worker thread
2020-02-25 21:55:22,159 - log_response - 228 - WARNING - Not Found: /favicon.ico
2020-02-25 21:55:22,742 - log_response - 228 - WARNING - Not Found: /favicon.ico
