2020-04-24 00:00:00,017 - _run_job - 527 - INFO - Job "OpenLog (trigger: cron[hour='0'], next run at: 2020-04-25 00:00:00)" executed successfully
2020-04-24 00:00:01,019 - _run_jobs - 94 - DEBUG - Exiting worker thread
2020-04-24 00:00:11,301 - trigger_reload - 203 - INFO - E:\1-program\11-LAMDataServer\lamdataserver\LAMProcessData\query_views.py changed, reloading.
2020-04-24 00:00:11,303 - shutdown - 111 - INFO - Shutting down thread pool
2020-04-24 00:00:16,783 - _real_add_job - 262 - INFO - Added job "regulartime_task (trigger: interval[1 day, 0:00:00], next run at: 2020-04-24 00:00:26.779764)" to job store "default"
2020-04-24 00:00:16,783 - _real_add_job - 262 - INFO - Added job "cleanup (trigger: cron[day_of_week='*', hour='3', minute='0', second='0'], next run at: 2020-04-24 03:00:00)" to job store "default"
2020-04-24 00:00:16,784 - _real_add_job - 262 - INFO - Added job "OpenLog (trigger: cron[hour='0'], next run at: 2020-04-25 00:00:00)" to job store "default"
2020-04-24 00:00:16,786 - _main_loop - 574 - INFO - Scheduler started
2020-04-24 00:00:16,786 - _main_loop - 579 - DEBUG - Looking for jobs to run
2020-04-24 00:00:16,787 - _main_loop - 588 - DEBUG - Next wakeup is due at 2020-04-24 00:00:26.779764 (in 9.993020 seconds)
2020-04-24 00:00:16,821 - <module> - 64 - DEBUG - SendBefore_NotRecive : [<CNCProcessStatus: CNCProcessStatus object (2038721)>]
2020-04-24 00:00:16,821 - <module> - 65 - DEBUG - Waitfor_Recive : [2038721]
2020-04-24 00:00:26,782 - _main_loop - 579 - DEBUG - Looking for jobs to run
2020-04-24 00:00:26,786 - _run_jobs - 69 - DEBUG - Started worker thread
2020-04-24 00:00:26,787 - _run_job - 509 - INFO - Running job "regulartime_task (trigger: interval[1 day, 0:00:00], next run at: 2020-04-24 00:00:26.779764)" (scheduled at 2020-04-24 00:00:26.779764)
2020-04-24 00:00:26,790 - _main_loop - 588 - DEBUG - Next wakeup is due at 2020-04-24 03:00:00 (in 10773.216812 seconds)
2020-04-24 00:00:28,894 - _run_job - 520 - ERROR - Job "regulartime_task (trigger: interval[1 day, 0:00:00], next run at: 2020-04-25 00:00:26.779764)" raised an exception
Traceback (most recent call last):
  File "D:\Program Files\Python37\lib\site-packages\django\db\backends\mysql\base.py", line 71, in execute
    return self.cursor.execute(query, args)
  File "D:\Program Files\Python37\lib\site-packages\MySQLdb\cursors.py", line 209, in execute
    res = self._query(query)
  File "D:\Program Files\Python37\lib\site-packages\MySQLdb\cursors.py", line 315, in _query
    db.query(q)
  File "D:\Program Files\Python37\lib\site-packages\MySQLdb\connections.py", line 239, in query
    _mysql.connection.query(self, query)
MySQLdb._exceptions.OperationalError: (1048, "Column 'laser_power' cannot be null")

During handling of the above exception, another exception occurred:

Traceback (most recent call last):
  File "D:\Program Files\Python37\lib\site-packages\apscheduler\scheduler.py", line 512, in _run_job
    retval = job.func(*job.args, **job.kwargs)
  File "E:\1-program\11-LAMDataServer\lamdataserver\LAMProcessData\views.py", line 4988, in regulartime_task
    RT_FineData.Realtime_FineData.init_Tomorrow_rows()
  File "E:\1-program\11-LAMDataServer\lamdataserver\LAMProcessData\process_realtime_finedata.py", line 193, in init_Tomorrow_rows
    _model.objects.bulk_create(insert_data_list)
  File "D:\Program Files\Python37\lib\site-packages\django\db\models\manager.py", line 82, in manager_method
    return getattr(self.get_queryset(), name)(*args, **kwargs)
  File "D:\Program Files\Python37\lib\site-packages\django\db\models\query.py", line 474, in bulk_create
    ids = self._batched_insert(objs_without_pk, fields, batch_size, ignore_conflicts=ignore_conflicts)
  File "D:\Program Files\Python37\lib\site-packages\django\db\models\query.py", line 1211, in _batched_insert
    self._insert(item, fields=fields, using=self.db, ignore_conflicts=ignore_conflicts)
  File "D:\Program Files\Python37\lib\site-packages\django\db\models\query.py", line 1186, in _insert
    return query.get_compiler(using=using).execute_sql(return_id)
  File "D:\Program Files\Python37\lib\site-packages\django\db\models\sql\compiler.py", line 1332, in execute_sql
    cursor.execute(sql, params)
  File "D:\Program Files\Python37\lib\site-packages\django\db\backends\utils.py", line 99, in execute
    return super().execute(sql, params)
  File "D:\Program Files\Python37\lib\site-packages\django\db\backends\utils.py", line 67, in execute
    return self._execute_with_wrappers(sql, params, many=False, executor=self._execute)
  File "D:\Program Files\Python37\lib\site-packages\django\db\backends\utils.py", line 76, in _execute_with_wrappers
    return executor(sql, params, many, context)
  File "D:\Program Files\Python37\lib\site-packages\django\db\backends\utils.py", line 84, in _execute
    return self.cursor.execute(sql, params)
  File "D:\Program Files\Python37\lib\site-packages\django\db\backends\mysql\base.py", line 76, in execute
    raise utils.IntegrityError(*tuple(e.args))
django.db.utils.IntegrityError: (1048, "Column 'laser_power' cannot be null")
2020-04-24 00:00:29,903 - _run_jobs - 94 - DEBUG - Exiting worker thread
2020-04-24 00:01:53,194 - trigger_reload - 203 - INFO - E:\1-program\11-LAMDataServer\lamdataserver\LAMProcessData\query_views.py changed, reloading.
2020-04-24 00:01:53,196 - shutdown - 111 - INFO - Shutting down thread pool
2020-04-24 00:01:56,295 - _real_add_job - 262 - INFO - Added job "regulartime_task (trigger: interval[1 day, 0:00:00], next run at: 2020-04-24 00:02:06.294873)" to job store "default"
2020-04-24 00:01:56,296 - _real_add_job - 262 - INFO - Added job "cleanup (trigger: cron[day_of_week='*', hour='3', minute='0', second='0'], next run at: 2020-04-24 03:00:00)" to job store "default"
2020-04-24 00:01:56,296 - _real_add_job - 262 - INFO - Added job "OpenLog (trigger: cron[hour='0'], next run at: 2020-04-25 00:00:00)" to job store "default"
2020-04-24 00:01:56,297 - _main_loop - 574 - INFO - Scheduler started
2020-04-24 00:01:56,297 - _main_loop - 579 - DEBUG - Looking for jobs to run
2020-04-24 00:01:56,298 - _main_loop - 588 - DEBUG - Next wakeup is due at 2020-04-24 00:02:06.294873 (in 9.996062 seconds)
2020-04-24 00:01:56,320 - <module> - 64 - DEBUG - SendBefore_NotRecive : [<CNCProcessStatus: CNCProcessStatus object (2038721)>]
2020-04-24 00:01:56,320 - <module> - 65 - DEBUG - Waitfor_Recive : [2038721]
2020-04-24 00:02:06,321 - _main_loop - 579 - DEBUG - Looking for jobs to run
2020-04-24 00:02:06,410 - _run_jobs - 69 - DEBUG - Started worker thread
2020-04-24 00:02:06,413 - _main_loop - 588 - DEBUG - Next wakeup is due at 2020-04-24 03:00:00 (in 10673.678619 seconds)
2020-04-24 00:02:06,446 - _run_job - 509 - INFO - Running job "regulartime_task (trigger: interval[1 day, 0:00:00], next run at: 2020-04-25 00:02:06.294873)" (scheduled at 2020-04-24 00:02:06.294873)
2020-04-24 00:02:07,960 - _run_job - 520 - ERROR - Job "regulartime_task (trigger: interval[1 day, 0:00:00], next run at: 2020-04-25 00:02:06.294873)" raised an exception
Traceback (most recent call last):
  File "D:\Program Files\Python37\lib\site-packages\django\db\backends\utils.py", line 84, in _execute
    return self.cursor.execute(sql, params)
  File "D:\Program Files\Python37\lib\site-packages\django\db\backends\mysql\base.py", line 71, in execute
    return self.cursor.execute(query, args)
  File "D:\Program Files\Python37\lib\site-packages\MySQLdb\cursors.py", line 209, in execute
    res = self._query(query)
  File "D:\Program Files\Python37\lib\site-packages\MySQLdb\cursors.py", line 315, in _query
    db.query(q)
  File "D:\Program Files\Python37\lib\site-packages\MySQLdb\connections.py", line 239, in query
    _mysql.connection.query(self, query)
MySQLdb._exceptions.IntegrityError: (1062, "Duplicate entry '1587744000' for key 'LAMProcessData_process_r_acquisition_timestamp_a69ae90c_uniq'")

The above exception was the direct cause of the following exception:

Traceback (most recent call last):
  File "D:\Program Files\Python37\lib\site-packages\apscheduler\scheduler.py", line 512, in _run_job
    retval = job.func(*job.args, **job.kwargs)
  File "E:\1-program\11-LAMDataServer\lamdataserver\LAMProcessData\views.py", line 4988, in regulartime_task
    RT_FineData.Realtime_FineData.init_Tomorrow_rows()
  File "E:\1-program\11-LAMDataServer\lamdataserver\LAMProcessData\process_realtime_finedata.py", line 193, in init_Tomorrow_rows
    _model.objects.bulk_create(insert_data_list)
  File "D:\Program Files\Python37\lib\site-packages\django\db\models\manager.py", line 82, in manager_method
    return getattr(self.get_queryset(), name)(*args, **kwargs)
  File "D:\Program Files\Python37\lib\site-packages\django\db\models\query.py", line 474, in bulk_create
    ids = self._batched_insert(objs_without_pk, fields, batch_size, ignore_conflicts=ignore_conflicts)
  File "D:\Program Files\Python37\lib\site-packages\django\db\models\query.py", line 1211, in _batched_insert
    self._insert(item, fields=fields, using=self.db, ignore_conflicts=ignore_conflicts)
  File "D:\Program Files\Python37\lib\site-packages\django\db\models\query.py", line 1186, in _insert
    return query.get_compiler(using=using).execute_sql(return_id)
  File "D:\Program Files\Python37\lib\site-packages\django\db\models\sql\compiler.py", line 1332, in execute_sql
    cursor.execute(sql, params)
  File "D:\Program Files\Python37\lib\site-packages\django\db\backends\utils.py", line 99, in execute
    return super().execute(sql, params)
  File "D:\Program Files\Python37\lib\site-packages\django\db\backends\utils.py", line 67, in execute
    return self._execute_with_wrappers(sql, params, many=False, executor=self._execute)
  File "D:\Program Files\Python37\lib\site-packages\django\db\backends\utils.py", line 76, in _execute_with_wrappers
    return executor(sql, params, many, context)
  File "D:\Program Files\Python37\lib\site-packages\django\db\backends\utils.py", line 84, in _execute
    return self.cursor.execute(sql, params)
  File "D:\Program Files\Python37\lib\site-packages\django\db\utils.py", line 89, in __exit__
    raise dj_exc_value.with_traceback(traceback) from exc_value
  File "D:\Program Files\Python37\lib\site-packages\django\db\backends\utils.py", line 84, in _execute
    return self.cursor.execute(sql, params)
  File "D:\Program Files\Python37\lib\site-packages\django\db\backends\mysql\base.py", line 71, in execute
    return self.cursor.execute(query, args)
  File "D:\Program Files\Python37\lib\site-packages\MySQLdb\cursors.py", line 209, in execute
    res = self._query(query)
  File "D:\Program Files\Python37\lib\site-packages\MySQLdb\cursors.py", line 315, in _query
    db.query(q)
  File "D:\Program Files\Python37\lib\site-packages\MySQLdb\connections.py", line 239, in query
    _mysql.connection.query(self, query)
django.db.utils.IntegrityError: (1062, "Duplicate entry '1587744000' for key 'LAMProcessData_process_r_acquisition_timestamp_a69ae90c_uniq'")
2020-04-24 00:02:08,973 - _run_jobs - 94 - DEBUG - Exiting worker thread
2020-04-24 00:02:32,111 - trigger_reload - 203 - INFO - E:\1-program\11-LAMDataServer\lamdataserver\LAMProcessData\query_views.py changed, reloading.
2020-04-24 00:02:32,115 - shutdown - 111 - INFO - Shutting down thread pool
2020-04-24 00:02:35,220 - _real_add_job - 262 - INFO - Added job "regulartime_task (trigger: interval[1 day, 0:00:00], next run at: 2020-04-24 00:02:45.218482)" to job store "default"
2020-04-24 00:02:35,221 - _real_add_job - 262 - INFO - Added job "cleanup (trigger: cron[day_of_week='*', hour='3', minute='0', second='0'], next run at: 2020-04-24 03:00:00)" to job store "default"
2020-04-24 00:02:35,222 - _real_add_job - 262 - INFO - Added job "OpenLog (trigger: cron[hour='0'], next run at: 2020-04-25 00:00:00)" to job store "default"
2020-04-24 00:02:35,223 - _main_loop - 574 - INFO - Scheduler started
2020-04-24 00:02:35,223 - _main_loop - 579 - DEBUG - Looking for jobs to run
2020-04-24 00:02:35,223 - _main_loop - 588 - DEBUG - Next wakeup is due at 2020-04-24 00:02:45.218482 (in 9.995011 seconds)
2020-04-24 00:02:35,245 - <module> - 64 - DEBUG - SendBefore_NotRecive : [<CNCProcessStatus: CNCProcessStatus object (2038721)>]
2020-04-24 00:02:35,246 - <module> - 65 - DEBUG - Waitfor_Recive : [2038721]
2020-04-24 00:02:45,220 - _main_loop - 579 - DEBUG - Looking for jobs to run
2020-04-24 00:02:45,223 - _run_jobs - 69 - DEBUG - Started worker thread
2020-04-24 00:02:45,224 - _run_job - 509 - INFO - Running job "regulartime_task (trigger: interval[1 day, 0:00:00], next run at: 2020-04-24 00:02:45.218482)" (scheduled at 2020-04-24 00:02:45.218482)
2020-04-24 00:02:45,227 - _main_loop - 588 - DEBUG - Next wakeup is due at 2020-04-24 03:00:00 (in 10634.778928 seconds)
2020-04-24 00:02:46,217 - _run_job - 520 - ERROR - Job "regulartime_task (trigger: interval[1 day, 0:00:00], next run at: 2020-04-25 00:02:45.218482)" raised an exception
Traceback (most recent call last):
  File "D:\Program Files\Python37\lib\site-packages\django\db\backends\utils.py", line 84, in _execute
    return self.cursor.execute(sql, params)
  File "D:\Program Files\Python37\lib\site-packages\django\db\backends\mysql\base.py", line 71, in execute
    return self.cursor.execute(query, args)
  File "D:\Program Files\Python37\lib\site-packages\MySQLdb\cursors.py", line 209, in execute
    res = self._query(query)
  File "D:\Program Files\Python37\lib\site-packages\MySQLdb\cursors.py", line 315, in _query
    db.query(q)
  File "D:\Program Files\Python37\lib\site-packages\MySQLdb\connections.py", line 239, in query
    _mysql.connection.query(self, query)
MySQLdb._exceptions.IntegrityError: (1062, "Duplicate entry '1587744000' for key 'LAMProcessData_process_r_acquisition_timestamp_a69ae90c_uniq'")

The above exception was the direct cause of the following exception:

Traceback (most recent call last):
  File "D:\Program Files\Python37\lib\site-packages\apscheduler\scheduler.py", line 512, in _run_job
    retval = job.func(*job.args, **job.kwargs)
  File "E:\1-program\11-LAMDataServer\lamdataserver\LAMProcessData\views.py", line 4988, in regulartime_task
    RT_FineData.Realtime_FineData.init_Tomorrow_rows()
  File "E:\1-program\11-LAMDataServer\lamdataserver\LAMProcessData\process_realtime_finedata.py", line 193, in init_Tomorrow_rows
    _model.objects.bulk_create(insert_data_list)
  File "D:\Program Files\Python37\lib\site-packages\django\db\models\manager.py", line 82, in manager_method
    return getattr(self.get_queryset(), name)(*args, **kwargs)
  File "D:\Program Files\Python37\lib\site-packages\django\db\models\query.py", line 474, in bulk_create
    ids = self._batched_insert(objs_without_pk, fields, batch_size, ignore_conflicts=ignore_conflicts)
  File "D:\Program Files\Python37\lib\site-packages\django\db\models\query.py", line 1211, in _batched_insert
    self._insert(item, fields=fields, using=self.db, ignore_conflicts=ignore_conflicts)
  File "D:\Program Files\Python37\lib\site-packages\django\db\models\query.py", line 1186, in _insert
    return query.get_compiler(using=using).execute_sql(return_id)
  File "D:\Program Files\Python37\lib\site-packages\django\db\models\sql\compiler.py", line 1332, in execute_sql
    cursor.execute(sql, params)
  File "D:\Program Files\Python37\lib\site-packages\django\db\backends\utils.py", line 99, in execute
    return super().execute(sql, params)
  File "D:\Program Files\Python37\lib\site-packages\django\db\backends\utils.py", line 67, in execute
    return self._execute_with_wrappers(sql, params, many=False, executor=self._execute)
  File "D:\Program Files\Python37\lib\site-packages\django\db\backends\utils.py", line 76, in _execute_with_wrappers
    return executor(sql, params, many, context)
  File "D:\Program Files\Python37\lib\site-packages\django\db\backends\utils.py", line 84, in _execute
    return self.cursor.execute(sql, params)
  File "D:\Program Files\Python37\lib\site-packages\django\db\utils.py", line 89, in __exit__
    raise dj_exc_value.with_traceback(traceback) from exc_value
  File "D:\Program Files\Python37\lib\site-packages\django\db\backends\utils.py", line 84, in _execute
    return self.cursor.execute(sql, params)
  File "D:\Program Files\Python37\lib\site-packages\django\db\backends\mysql\base.py", line 71, in execute
    return self.cursor.execute(query, args)
  File "D:\Program Files\Python37\lib\site-packages\MySQLdb\cursors.py", line 209, in execute
    res = self._query(query)
  File "D:\Program Files\Python37\lib\site-packages\MySQLdb\cursors.py", line 315, in _query
    db.query(q)
  File "D:\Program Files\Python37\lib\site-packages\MySQLdb\connections.py", line 239, in query
    _mysql.connection.query(self, query)
django.db.utils.IntegrityError: (1062, "Duplicate entry '1587744000' for key 'LAMProcessData_process_r_acquisition_timestamp_a69ae90c_uniq'")
2020-04-24 00:02:47,226 - _run_jobs - 94 - DEBUG - Exiting worker thread
2020-04-24 00:03:46,359 - trigger_reload - 203 - INFO - E:\1-program\11-LAMDataServer\lamdataserver\LAMProcessData\query_views.py changed, reloading.
2020-04-24 00:03:46,361 - shutdown - 111 - INFO - Shutting down thread pool
2020-04-24 00:03:49,478 - _real_add_job - 262 - INFO - Added job "regulartime_task (trigger: interval[1 day, 0:00:00], next run at: 2020-04-24 00:03:59.476816)" to job store "default"
2020-04-24 00:03:49,478 - _real_add_job - 262 - INFO - Added job "cleanup (trigger: cron[day_of_week='*', hour='3', minute='0', second='0'], next run at: 2020-04-24 03:00:00)" to job store "default"
2020-04-24 00:03:49,479 - _real_add_job - 262 - INFO - Added job "OpenLog (trigger: cron[hour='0'], next run at: 2020-04-25 00:00:00)" to job store "default"
2020-04-24 00:03:49,480 - _main_loop - 574 - INFO - Scheduler started
2020-04-24 00:03:49,480 - _main_loop - 579 - DEBUG - Looking for jobs to run
2020-04-24 00:03:49,480 - _main_loop - 588 - DEBUG - Next wakeup is due at 2020-04-24 00:03:59.476816 (in 9.996011 seconds)
2020-04-24 00:03:49,505 - <module> - 64 - DEBUG - SendBefore_NotRecive : [<CNCProcessStatus: CNCProcessStatus object (2038721)>]
2020-04-24 00:03:49,505 - <module> - 65 - DEBUG - Waitfor_Recive : [2038721]
2020-04-24 00:03:59,485 - _main_loop - 579 - DEBUG - Looking for jobs to run
2020-04-24 00:03:59,542 - _run_jobs - 69 - DEBUG - Started worker thread
2020-04-24 00:03:59,543 - _run_job - 509 - INFO - Running job "regulartime_task (trigger: interval[1 day, 0:00:00], next run at: 2020-04-25 00:03:59.476816)" (scheduled at 2020-04-24 00:03:59.476816)
2020-04-24 00:03:59,594 - _main_loop - 588 - DEBUG - Next wakeup is due at 2020-04-24 03:00:00 (in 10560.511214 seconds)
2020-04-24 00:04:00,697 - _run_job - 520 - ERROR - Job "regulartime_task (trigger: interval[1 day, 0:00:00], next run at: 2020-04-25 00:03:59.476816)" raised an exception
Traceback (most recent call last):
  File "D:\Program Files\Python37\lib\site-packages\django\db\backends\utils.py", line 84, in _execute
    return self.cursor.execute(sql, params)
  File "D:\Program Files\Python37\lib\site-packages\django\db\backends\mysql\base.py", line 71, in execute
    return self.cursor.execute(query, args)
  File "D:\Program Files\Python37\lib\site-packages\MySQLdb\cursors.py", line 209, in execute
    res = self._query(query)
  File "D:\Program Files\Python37\lib\site-packages\MySQLdb\cursors.py", line 315, in _query
    db.query(q)
  File "D:\Program Files\Python37\lib\site-packages\MySQLdb\connections.py", line 239, in query
    _mysql.connection.query(self, query)
MySQLdb._exceptions.IntegrityError: (1062, "Duplicate entry '1587744000' for key 'LAMProcessData_process_r_acquisition_timestamp_a69ae90c_uniq'")

The above exception was the direct cause of the following exception:

Traceback (most recent call last):
  File "D:\Program Files\Python37\lib\site-packages\apscheduler\scheduler.py", line 512, in _run_job
    retval = job.func(*job.args, **job.kwargs)
  File "E:\1-program\11-LAMDataServer\lamdataserver\LAMProcessData\views.py", line 4988, in regulartime_task
    RT_FineData.Realtime_FineData.init_Tomorrow_rows()
  File "E:\1-program\11-LAMDataServer\lamdataserver\LAMProcessData\process_realtime_finedata.py", line 193, in init_Tomorrow_rows
    _model.objects.bulk_create(insert_data_list)
  File "D:\Program Files\Python37\lib\site-packages\django\db\models\manager.py", line 82, in manager_method
    return getattr(self.get_queryset(), name)(*args, **kwargs)
  File "D:\Program Files\Python37\lib\site-packages\django\db\models\query.py", line 474, in bulk_create
    ids = self._batched_insert(objs_without_pk, fields, batch_size, ignore_conflicts=ignore_conflicts)
  File "D:\Program Files\Python37\lib\site-packages\django\db\models\query.py", line 1211, in _batched_insert
    self._insert(item, fields=fields, using=self.db, ignore_conflicts=ignore_conflicts)
  File "D:\Program Files\Python37\lib\site-packages\django\db\models\query.py", line 1186, in _insert
    return query.get_compiler(using=using).execute_sql(return_id)
  File "D:\Program Files\Python37\lib\site-packages\django\db\models\sql\compiler.py", line 1332, in execute_sql
    cursor.execute(sql, params)
  File "D:\Program Files\Python37\lib\site-packages\django\db\backends\utils.py", line 99, in execute
    return super().execute(sql, params)
  File "D:\Program Files\Python37\lib\site-packages\django\db\backends\utils.py", line 67, in execute
    return self._execute_with_wrappers(sql, params, many=False, executor=self._execute)
  File "D:\Program Files\Python37\lib\site-packages\django\db\backends\utils.py", line 76, in _execute_with_wrappers
    return executor(sql, params, many, context)
  File "D:\Program Files\Python37\lib\site-packages\django\db\backends\utils.py", line 84, in _execute
    return self.cursor.execute(sql, params)
  File "D:\Program Files\Python37\lib\site-packages\django\db\utils.py", line 89, in __exit__
    raise dj_exc_value.with_traceback(traceback) from exc_value
  File "D:\Program Files\Python37\lib\site-packages\django\db\backends\utils.py", line 84, in _execute
    return self.cursor.execute(sql, params)
  File "D:\Program Files\Python37\lib\site-packages\django\db\backends\mysql\base.py", line 71, in execute
    return self.cursor.execute(query, args)
  File "D:\Program Files\Python37\lib\site-packages\MySQLdb\cursors.py", line 209, in execute
    res = self._query(query)
  File "D:\Program Files\Python37\lib\site-packages\MySQLdb\cursors.py", line 315, in _query
    db.query(q)
  File "D:\Program Files\Python37\lib\site-packages\MySQLdb\connections.py", line 239, in query
    _mysql.connection.query(self, query)
django.db.utils.IntegrityError: (1062, "Duplicate entry '1587744000' for key 'LAMProcessData_process_r_acquisition_timestamp_a69ae90c_uniq'")
2020-04-24 00:04:01,708 - _run_jobs - 94 - DEBUG - Exiting worker thread
2020-04-24 00:08:46,625 - trigger_reload - 203 - INFO - E:\1-program\11-LAMDataServer\lamdataserver\LAMProcessData\query_views.py changed, reloading.
2020-04-24 00:08:46,628 - shutdown - 111 - INFO - Shutting down thread pool
2020-04-24 00:08:50,033 - _real_add_job - 262 - INFO - Added job "regulartime_task (trigger: interval[1 day, 0:00:00], next run at: 2020-04-24 00:09:00.031726)" to job store "default"
2020-04-24 00:08:50,034 - _real_add_job - 262 - INFO - Added job "cleanup (trigger: cron[day_of_week='*', hour='3', minute='0', second='0'], next run at: 2020-04-24 03:00:00)" to job store "default"
2020-04-24 00:08:50,034 - _real_add_job - 262 - INFO - Added job "OpenLog (trigger: cron[hour='0'], next run at: 2020-04-25 00:00:00)" to job store "default"
2020-04-24 00:08:50,035 - _main_loop - 574 - INFO - Scheduler started
2020-04-24 00:08:50,035 - _main_loop - 579 - DEBUG - Looking for jobs to run
2020-04-24 00:08:50,035 - _main_loop - 588 - DEBUG - Next wakeup is due at 2020-04-24 00:09:00.031726 (in 9.996053 seconds)
2020-04-24 00:19:53,363 - _real_add_job - 262 - INFO - Added job "regulartime_task (trigger: interval[1 day, 0:00:00], next run at: 2020-04-24 00:20:03.362516)" to job store "default"
2020-04-24 00:19:53,364 - _real_add_job - 262 - INFO - Added job "cleanup (trigger: cron[day_of_week='*', hour='3', minute='0', second='0'], next run at: 2020-04-24 03:00:00)" to job store "default"
2020-04-24 00:19:53,364 - _real_add_job - 262 - INFO - Added job "OpenLog (trigger: cron[hour='0'], next run at: 2020-04-25 00:00:00)" to job store "default"
2020-04-24 00:19:53,365 - _main_loop - 574 - INFO - Scheduler started
2020-04-24 00:19:53,365 - _main_loop - 579 - DEBUG - Looking for jobs to run
2020-04-24 00:19:53,366 - _main_loop - 588 - DEBUG - Next wakeup is due at 2020-04-24 00:20:03.362516 (in 9.996041 seconds)
2020-04-24 00:19:53,388 - <module> - 64 - DEBUG - SendBefore_NotRecive : [<CNCProcessStatus: CNCProcessStatus object (2038721)>]
2020-04-24 00:19:53,389 - <module> - 65 - DEBUG - Waitfor_Recive : [2038721]
2020-04-24 00:20:03,364 - _main_loop - 579 - DEBUG - Looking for jobs to run
2020-04-24 00:20:03,368 - _run_jobs - 69 - DEBUG - Started worker thread
2020-04-24 00:20:03,370 - _run_job - 509 - INFO - Running job "regulartime_task (trigger: interval[1 day, 0:00:00], next run at: 2020-04-24 00:20:03.362516)" (scheduled at 2020-04-24 00:20:03.362516)
2020-04-24 00:20:03,372 - _main_loop - 588 - DEBUG - Next wakeup is due at 2020-04-24 03:00:00 (in 9596.634600 seconds)
2020-04-24 00:20:04,351 - _run_job - 520 - ERROR - Job "regulartime_task (trigger: interval[1 day, 0:00:00], next run at: 2020-04-25 00:20:03.362516)" raised an exception
Traceback (most recent call last):
  File "D:\Program Files\Python37\lib\site-packages\django\db\backends\utils.py", line 84, in _execute
    return self.cursor.execute(sql, params)
  File "D:\Program Files\Python37\lib\site-packages\django\db\backends\mysql\base.py", line 71, in execute
    return self.cursor.execute(query, args)
  File "D:\Program Files\Python37\lib\site-packages\MySQLdb\cursors.py", line 209, in execute
    res = self._query(query)
  File "D:\Program Files\Python37\lib\site-packages\MySQLdb\cursors.py", line 315, in _query
    db.query(q)
  File "D:\Program Files\Python37\lib\site-packages\MySQLdb\connections.py", line 239, in query
    _mysql.connection.query(self, query)
MySQLdb._exceptions.IntegrityError: (1062, "Duplicate entry '1587744000' for key 'LAMProcessData_process_r_acquisition_timestamp_a69ae90c_uniq'")

The above exception was the direct cause of the following exception:

Traceback (most recent call last):
  File "D:\Program Files\Python37\lib\site-packages\apscheduler\scheduler.py", line 512, in _run_job
    retval = job.func(*job.args, **job.kwargs)
  File "E:\1-program\11-LAMDataServer\lamdataserver\LAMProcessData\views.py", line 4988, in regulartime_task
    RT_FineData.Realtime_FineData.init_Tomorrow_rows()
  File "E:\1-program\11-LAMDataServer\lamdataserver\LAMProcessData\process_realtime_finedata.py", line 193, in init_Tomorrow_rows
    _model.objects.bulk_create(insert_data_list)
  File "D:\Program Files\Python37\lib\site-packages\django\db\models\manager.py", line 82, in manager_method
    return getattr(self.get_queryset(), name)(*args, **kwargs)
  File "D:\Program Files\Python37\lib\site-packages\django\db\models\query.py", line 474, in bulk_create
    ids = self._batched_insert(objs_without_pk, fields, batch_size, ignore_conflicts=ignore_conflicts)
  File "D:\Program Files\Python37\lib\site-packages\django\db\models\query.py", line 1211, in _batched_insert
    self._insert(item, fields=fields, using=self.db, ignore_conflicts=ignore_conflicts)
  File "D:\Program Files\Python37\lib\site-packages\django\db\models\query.py", line 1186, in _insert
    return query.get_compiler(using=using).execute_sql(return_id)
  File "D:\Program Files\Python37\lib\site-packages\django\db\models\sql\compiler.py", line 1332, in execute_sql
    cursor.execute(sql, params)
  File "D:\Program Files\Python37\lib\site-packages\django\db\backends\utils.py", line 99, in execute
    return super().execute(sql, params)
  File "D:\Program Files\Python37\lib\site-packages\django\db\backends\utils.py", line 67, in execute
    return self._execute_with_wrappers(sql, params, many=False, executor=self._execute)
  File "D:\Program Files\Python37\lib\site-packages\django\db\backends\utils.py", line 76, in _execute_with_wrappers
    return executor(sql, params, many, context)
  File "D:\Program Files\Python37\lib\site-packages\django\db\backends\utils.py", line 84, in _execute
    return self.cursor.execute(sql, params)
  File "D:\Program Files\Python37\lib\site-packages\django\db\utils.py", line 89, in __exit__
    raise dj_exc_value.with_traceback(traceback) from exc_value
  File "D:\Program Files\Python37\lib\site-packages\django\db\backends\utils.py", line 84, in _execute
    return self.cursor.execute(sql, params)
  File "D:\Program Files\Python37\lib\site-packages\django\db\backends\mysql\base.py", line 71, in execute
    return self.cursor.execute(query, args)
  File "D:\Program Files\Python37\lib\site-packages\MySQLdb\cursors.py", line 209, in execute
    res = self._query(query)
  File "D:\Program Files\Python37\lib\site-packages\MySQLdb\cursors.py", line 315, in _query
    db.query(q)
  File "D:\Program Files\Python37\lib\site-packages\MySQLdb\connections.py", line 239, in query
    _mysql.connection.query(self, query)
django.db.utils.IntegrityError: (1062, "Duplicate entry '1587744000' for key 'LAMProcessData_process_r_acquisition_timestamp_a69ae90c_uniq'")
2020-04-24 00:20:05,365 - _run_jobs - 94 - DEBUG - Exiting worker thread
2020-04-24 00:20:09,192 - log_response - 228 - ERROR - Internal Server Error: /LAMProcessData/QueryData/Statistic/RawStockFlow/
Traceback (most recent call last):
  File "D:\Program Files\Python37\lib\site-packages\django\core\handlers\exception.py", line 34, in inner
    response = get_response(request)
  File "D:\Program Files\Python37\lib\site-packages\django\core\handlers\base.py", line 115, in _get_response
    response = self.process_exception_by_middleware(e, request)
  File "D:\Program Files\Python37\lib\site-packages\django\core\handlers\base.py", line 113, in _get_response
    response = wrapped_callback(request, *callback_args, **callback_kwargs)
  File "D:\Program Files\Python37\lib\site-packages\django\contrib\auth\decorators.py", line 21, in _wrapped_view
    return view_func(request, *args, **kwargs)
  File "D:\Program Files\Python37\lib\site-packages\django\views\decorators\csrf.py", line 54, in wrapped_view
    return view_func(*args, **kwargs)
  File "E:\1-program\11-LAMDataServer\lamdataserver\LAMProcessData\query_views.py", line 1435, in queryData_Statistic_RawStockFlow
    key = tuple( item[i] for i in cluster_item_list)
  File "E:\1-program\11-LAMDataServer\lamdataserver\LAMProcessData\query_views.py", line 1435, in <genexpr>
    key = tuple( item[i] for i in cluster_item_list)
KeyError: 'worksection'
2020-04-24 00:20:40,063 - _real_add_job - 262 - INFO - Added job "regulartime_task (trigger: interval[1 day, 0:00:00], next run at: 2020-04-24 00:20:50.061655)" to job store "default"
2020-04-24 00:20:40,063 - _real_add_job - 262 - INFO - Added job "cleanup (trigger: cron[day_of_week='*', hour='3', minute='0', second='0'], next run at: 2020-04-24 03:00:00)" to job store "default"
2020-04-24 00:20:40,063 - _real_add_job - 262 - INFO - Added job "OpenLog (trigger: cron[hour='0'], next run at: 2020-04-25 00:00:00)" to job store "default"
2020-04-24 00:20:40,064 - _main_loop - 574 - INFO - Scheduler started
2020-04-24 00:20:40,064 - _main_loop - 579 - DEBUG - Looking for jobs to run
2020-04-24 00:20:40,064 - _main_loop - 588 - DEBUG - Next wakeup is due at 2020-04-24 00:20:50.061655 (in 9.997008 seconds)
2020-04-24 00:20:40,087 - <module> - 64 - DEBUG - SendBefore_NotRecive : [<CNCProcessStatus: CNCProcessStatus object (2038721)>]
2020-04-24 00:20:40,087 - <module> - 65 - DEBUG - Waitfor_Recive : [2038721]
2020-04-24 00:20:43,600 - log_response - 228 - ERROR - Internal Server Error: /LAMProcessData/QueryData/Statistic/RawStockFlow/
Traceback (most recent call last):
  File "D:\Program Files\Python37\lib\site-packages\django\core\handlers\exception.py", line 34, in inner
    response = get_response(request)
  File "D:\Program Files\Python37\lib\site-packages\django\core\handlers\base.py", line 115, in _get_response
    response = self.process_exception_by_middleware(e, request)
  File "D:\Program Files\Python37\lib\site-packages\django\core\handlers\base.py", line 113, in _get_response
    response = wrapped_callback(request, *callback_args, **callback_kwargs)
  File "D:\Program Files\Python37\lib\site-packages\django\contrib\auth\decorators.py", line 21, in _wrapped_view
    return view_func(request, *args, **kwargs)
  File "D:\Program Files\Python37\lib\site-packages\django\views\decorators\csrf.py", line 54, in wrapped_view
    return view_func(*args, **kwargs)
  File "E:\1-program\11-LAMDataServer\lamdataserver\LAMProcessData\query_views.py", line 1435, in queryData_Statistic_RawStockFlow
    key = tuple( item[i] for i in cluster_fields)
  File "E:\1-program\11-LAMDataServer\lamdataserver\LAMProcessData\query_views.py", line 1435, in <genexpr>
    key = tuple( item[i] for i in cluster_fields)
KeyError: 'LAM_mission__work_section'
2020-04-24 00:20:50,063 - _main_loop - 579 - DEBUG - Looking for jobs to run
2020-04-24 00:20:50,068 - _run_jobs - 69 - DEBUG - Started worker thread
2020-04-24 00:20:50,069 - _run_job - 509 - INFO - Running job "regulartime_task (trigger: interval[1 day, 0:00:00], next run at: 2020-04-24 00:20:50.061655)" (scheduled at 2020-04-24 00:20:50.061655)
2020-04-24 00:20:50,075 - _main_loop - 588 - DEBUG - Next wakeup is due at 2020-04-24 03:00:00 (in 9549.934963 seconds)
2020-04-24 00:20:51,014 - _run_job - 520 - ERROR - Job "regulartime_task (trigger: interval[1 day, 0:00:00], next run at: 2020-04-25 00:20:50.061655)" raised an exception
Traceback (most recent call last):
  File "D:\Program Files\Python37\lib\site-packages\django\db\backends\utils.py", line 84, in _execute
    return self.cursor.execute(sql, params)
  File "D:\Program Files\Python37\lib\site-packages\django\db\backends\mysql\base.py", line 71, in execute
    return self.cursor.execute(query, args)
  File "D:\Program Files\Python37\lib\site-packages\MySQLdb\cursors.py", line 209, in execute
    res = self._query(query)
  File "D:\Program Files\Python37\lib\site-packages\MySQLdb\cursors.py", line 315, in _query
    db.query(q)
  File "D:\Program Files\Python37\lib\site-packages\MySQLdb\connections.py", line 239, in query
    _mysql.connection.query(self, query)
MySQLdb._exceptions.IntegrityError: (1062, "Duplicate entry '1587744000' for key 'LAMProcessData_process_r_acquisition_timestamp_a69ae90c_uniq'")

The above exception was the direct cause of the following exception:

Traceback (most recent call last):
  File "D:\Program Files\Python37\lib\site-packages\apscheduler\scheduler.py", line 512, in _run_job
    retval = job.func(*job.args, **job.kwargs)
  File "E:\1-program\11-LAMDataServer\lamdataserver\LAMProcessData\views.py", line 4988, in regulartime_task
    RT_FineData.Realtime_FineData.init_Tomorrow_rows()
  File "E:\1-program\11-LAMDataServer\lamdataserver\LAMProcessData\process_realtime_finedata.py", line 193, in init_Tomorrow_rows
    _model.objects.bulk_create(insert_data_list)
  File "D:\Program Files\Python37\lib\site-packages\django\db\models\manager.py", line 82, in manager_method
    return getattr(self.get_queryset(), name)(*args, **kwargs)
  File "D:\Program Files\Python37\lib\site-packages\django\db\models\query.py", line 474, in bulk_create
    ids = self._batched_insert(objs_without_pk, fields, batch_size, ignore_conflicts=ignore_conflicts)
  File "D:\Program Files\Python37\lib\site-packages\django\db\models\query.py", line 1211, in _batched_insert
    self._insert(item, fields=fields, using=self.db, ignore_conflicts=ignore_conflicts)
  File "D:\Program Files\Python37\lib\site-packages\django\db\models\query.py", line 1186, in _insert
    return query.get_compiler(using=using).execute_sql(return_id)
  File "D:\Program Files\Python37\lib\site-packages\django\db\models\sql\compiler.py", line 1332, in execute_sql
    cursor.execute(sql, params)
  File "D:\Program Files\Python37\lib\site-packages\django\db\backends\utils.py", line 99, in execute
    return super().execute(sql, params)
  File "D:\Program Files\Python37\lib\site-packages\django\db\backends\utils.py", line 67, in execute
    return self._execute_with_wrappers(sql, params, many=False, executor=self._execute)
  File "D:\Program Files\Python37\lib\site-packages\django\db\backends\utils.py", line 76, in _execute_with_wrappers
    return executor(sql, params, many, context)
  File "D:\Program Files\Python37\lib\site-packages\django\db\backends\utils.py", line 84, in _execute
    return self.cursor.execute(sql, params)
  File "D:\Program Files\Python37\lib\site-packages\django\db\utils.py", line 89, in __exit__
    raise dj_exc_value.with_traceback(traceback) from exc_value
  File "D:\Program Files\Python37\lib\site-packages\django\db\backends\utils.py", line 84, in _execute
    return self.cursor.execute(sql, params)
  File "D:\Program Files\Python37\lib\site-packages\django\db\backends\mysql\base.py", line 71, in execute
    return self.cursor.execute(query, args)
  File "D:\Program Files\Python37\lib\site-packages\MySQLdb\cursors.py", line 209, in execute
    res = self._query(query)
  File "D:\Program Files\Python37\lib\site-packages\MySQLdb\cursors.py", line 315, in _query
    db.query(q)
  File "D:\Program Files\Python37\lib\site-packages\MySQLdb\connections.py", line 239, in query
    _mysql.connection.query(self, query)
django.db.utils.IntegrityError: (1062, "Duplicate entry '1587744000' for key 'LAMProcessData_process_r_acquisition_timestamp_a69ae90c_uniq'")
2020-04-24 00:20:52,022 - _run_jobs - 94 - DEBUG - Exiting worker thread
2020-04-24 00:22:20,035 - trigger_reload - 203 - INFO - E:\1-program\11-LAMDataServer\lamdataserver\LAMProcessData\query_views.py changed, reloading.
2020-04-24 00:22:20,038 - shutdown - 111 - INFO - Shutting down thread pool
2020-04-24 00:22:27,757 - _real_add_job - 262 - INFO - Added job "regulartime_task (trigger: interval[1 day, 0:00:00], next run at: 2020-04-24 00:22:37.755268)" to job store "default"
2020-04-24 00:22:27,757 - _real_add_job - 262 - INFO - Added job "cleanup (trigger: cron[day_of_week='*', hour='3', minute='0', second='0'], next run at: 2020-04-24 03:00:00)" to job store "default"
2020-04-24 00:22:27,758 - _real_add_job - 262 - INFO - Added job "OpenLog (trigger: cron[hour='0'], next run at: 2020-04-25 00:00:00)" to job store "default"
2020-04-24 00:22:27,759 - _main_loop - 574 - INFO - Scheduler started
2020-04-24 00:22:27,759 - _main_loop - 579 - DEBUG - Looking for jobs to run
2020-04-24 00:22:27,759 - _main_loop - 588 - DEBUG - Next wakeup is due at 2020-04-24 00:22:37.755268 (in 9.996011 seconds)
2020-04-24 00:22:27,781 - <module> - 64 - DEBUG - SendBefore_NotRecive : [<CNCProcessStatus: CNCProcessStatus object (2038721)>]
2020-04-24 00:22:27,781 - <module> - 65 - DEBUG - Waitfor_Recive : [2038721]
2020-04-24 00:22:36,449 - log_response - 228 - ERROR - Internal Server Error: /LAMProcessData/QueryData/Statistic/RawStockFlow/
Traceback (most recent call last):
  File "D:\Program Files\Python37\lib\site-packages\django\core\handlers\exception.py", line 34, in inner
    response = get_response(request)
  File "D:\Program Files\Python37\lib\site-packages\django\core\handlers\base.py", line 115, in _get_response
    response = self.process_exception_by_middleware(e, request)
  File "D:\Program Files\Python37\lib\site-packages\django\core\handlers\base.py", line 113, in _get_response
    response = wrapped_callback(request, *callback_args, **callback_kwargs)
  File "D:\Program Files\Python37\lib\site-packages\django\contrib\auth\decorators.py", line 21, in _wrapped_view
    return view_func(request, *args, **kwargs)
  File "D:\Program Files\Python37\lib\site-packages\django\views\decorators\csrf.py", line 54, in wrapped_view
    return view_func(*args, **kwargs)
  File "E:\1-program\11-LAMDataServer\lamdataserver\LAMProcessData\query_views.py", line 1440, in queryData_Statistic_RawStockFlow
    queryset = [key.extend(value) for key,value in cluster_temp_dict.items()]
  File "E:\1-program\11-LAMDataServer\lamdataserver\LAMProcessData\query_views.py", line 1440, in <listcomp>
    queryset = [key.extend(value) for key,value in cluster_temp_dict.items()]
AttributeError: 'tuple' object has no attribute 'extend'
2020-04-24 00:22:37,756 - _main_loop - 579 - DEBUG - Looking for jobs to run
2020-04-24 00:22:37,757 - _run_jobs - 69 - DEBUG - Started worker thread
2020-04-24 00:22:37,757 - _main_loop - 588 - DEBUG - Next wakeup is due at 2020-04-24 03:00:00 (in 9442.243519 seconds)
2020-04-24 00:22:37,757 - _run_job - 509 - INFO - Running job "regulartime_task (trigger: interval[1 day, 0:00:00], next run at: 2020-04-25 00:22:37.755268)" (scheduled at 2020-04-24 00:22:37.755268)
2020-04-24 00:22:38,766 - _run_job - 520 - ERROR - Job "regulartime_task (trigger: interval[1 day, 0:00:00], next run at: 2020-04-25 00:22:37.755268)" raised an exception
Traceback (most recent call last):
  File "D:\Program Files\Python37\lib\site-packages\django\db\backends\utils.py", line 84, in _execute
    return self.cursor.execute(sql, params)
  File "D:\Program Files\Python37\lib\site-packages\django\db\backends\mysql\base.py", line 71, in execute
    return self.cursor.execute(query, args)
  File "D:\Program Files\Python37\lib\site-packages\MySQLdb\cursors.py", line 209, in execute
    res = self._query(query)
  File "D:\Program Files\Python37\lib\site-packages\MySQLdb\cursors.py", line 315, in _query
    db.query(q)
  File "D:\Program Files\Python37\lib\site-packages\MySQLdb\connections.py", line 239, in query
    _mysql.connection.query(self, query)
MySQLdb._exceptions.IntegrityError: (1062, "Duplicate entry '1587744000' for key 'LAMProcessData_process_r_acquisition_timestamp_a69ae90c_uniq'")

The above exception was the direct cause of the following exception:

Traceback (most recent call last):
  File "D:\Program Files\Python37\lib\site-packages\apscheduler\scheduler.py", line 512, in _run_job
    retval = job.func(*job.args, **job.kwargs)
  File "E:\1-program\11-LAMDataServer\lamdataserver\LAMProcessData\views.py", line 4988, in regulartime_task
    RT_FineData.Realtime_FineData.init_Tomorrow_rows()
  File "E:\1-program\11-LAMDataServer\lamdataserver\LAMProcessData\process_realtime_finedata.py", line 193, in init_Tomorrow_rows
    _model.objects.bulk_create(insert_data_list)
  File "D:\Program Files\Python37\lib\site-packages\django\db\models\manager.py", line 82, in manager_method
    return getattr(self.get_queryset(), name)(*args, **kwargs)
  File "D:\Program Files\Python37\lib\site-packages\django\db\models\query.py", line 474, in bulk_create
    ids = self._batched_insert(objs_without_pk, fields, batch_size, ignore_conflicts=ignore_conflicts)
  File "D:\Program Files\Python37\lib\site-packages\django\db\models\query.py", line 1211, in _batched_insert
    self._insert(item, fields=fields, using=self.db, ignore_conflicts=ignore_conflicts)
  File "D:\Program Files\Python37\lib\site-packages\django\db\models\query.py", line 1186, in _insert
    return query.get_compiler(using=using).execute_sql(return_id)
  File "D:\Program Files\Python37\lib\site-packages\django\db\models\sql\compiler.py", line 1332, in execute_sql
    cursor.execute(sql, params)
  File "D:\Program Files\Python37\lib\site-packages\django\db\backends\utils.py", line 99, in execute
    return super().execute(sql, params)
  File "D:\Program Files\Python37\lib\site-packages\django\db\backends\utils.py", line 67, in execute
    return self._execute_with_wrappers(sql, params, many=False, executor=self._execute)
  File "D:\Program Files\Python37\lib\site-packages\django\db\backends\utils.py", line 76, in _execute_with_wrappers
    return executor(sql, params, many, context)
  File "D:\Program Files\Python37\lib\site-packages\django\db\backends\utils.py", line 84, in _execute
    return self.cursor.execute(sql, params)
  File "D:\Program Files\Python37\lib\site-packages\django\db\utils.py", line 89, in __exit__
    raise dj_exc_value.with_traceback(traceback) from exc_value
  File "D:\Program Files\Python37\lib\site-packages\django\db\backends\utils.py", line 84, in _execute
    return self.cursor.execute(sql, params)
  File "D:\Program Files\Python37\lib\site-packages\django\db\backends\mysql\base.py", line 71, in execute
    return self.cursor.execute(query, args)
  File "D:\Program Files\Python37\lib\site-packages\MySQLdb\cursors.py", line 209, in execute
    res = self._query(query)
  File "D:\Program Files\Python37\lib\site-packages\MySQLdb\cursors.py", line 315, in _query
    db.query(q)
  File "D:\Program Files\Python37\lib\site-packages\MySQLdb\connections.py", line 239, in query
    _mysql.connection.query(self, query)
django.db.utils.IntegrityError: (1062, "Duplicate entry '1587744000' for key 'LAMProcessData_process_r_acquisition_timestamp_a69ae90c_uniq'")
2020-04-24 00:22:39,777 - _run_jobs - 94 - DEBUG - Exiting worker thread
2020-04-24 00:23:03,481 - _real_add_job - 262 - INFO - Added job "regulartime_task (trigger: interval[1 day, 0:00:00], next run at: 2020-04-24 00:23:13.479822)" to job store "default"
2020-04-24 00:23:03,482 - _real_add_job - 262 - INFO - Added job "cleanup (trigger: cron[day_of_week='*', hour='3', minute='0', second='0'], next run at: 2020-04-24 03:00:00)" to job store "default"
2020-04-24 00:23:03,482 - _real_add_job - 262 - INFO - Added job "OpenLog (trigger: cron[hour='0'], next run at: 2020-04-25 00:00:00)" to job store "default"
2020-04-24 00:23:03,483 - _main_loop - 574 - INFO - Scheduler started
2020-04-24 00:23:03,484 - _main_loop - 579 - DEBUG - Looking for jobs to run
2020-04-24 00:23:03,484 - _main_loop - 588 - DEBUG - Next wakeup is due at 2020-04-24 00:23:13.479822 (in 9.995014 seconds)
2020-04-24 00:23:03,508 - <module> - 64 - DEBUG - SendBefore_NotRecive : [<CNCProcessStatus: CNCProcessStatus object (2038721)>]
2020-04-24 00:23:03,508 - <module> - 65 - DEBUG - Waitfor_Recive : [2038721]
2020-04-24 00:23:05,847 - log_response - 228 - ERROR - Internal Server Error: /LAMProcessData/QueryData/Statistic/RawStockFlow/
Traceback (most recent call last):
  File "D:\Program Files\Python37\lib\site-packages\django\core\handlers\exception.py", line 34, in inner
    response = get_response(request)
  File "D:\Program Files\Python37\lib\site-packages\django\core\handlers\base.py", line 115, in _get_response
    response = self.process_exception_by_middleware(e, request)
  File "D:\Program Files\Python37\lib\site-packages\django\core\handlers\base.py", line 113, in _get_response
    response = wrapped_callback(request, *callback_args, **callback_kwargs)
  File "D:\Program Files\Python37\lib\site-packages\django\contrib\auth\decorators.py", line 21, in _wrapped_view
    return view_func(request, *args, **kwargs)
  File "D:\Program Files\Python37\lib\site-packages\django\views\decorators\csrf.py", line 54, in wrapped_view
    return view_func(*args, **kwargs)
  File "E:\1-program\11-LAMDataServer\lamdataserver\LAMProcessData\query_views.py", line 1436, in queryData_Statistic_RawStockFlow
    if key not in cluster_temp_dict:
TypeError: unhashable type: 'list'
2020-04-24 00:23:13,481 - _main_loop - 579 - DEBUG - Looking for jobs to run
2020-04-24 00:23:13,486 - _run_jobs - 69 - DEBUG - Started worker thread
2020-04-24 00:23:13,487 - _run_job - 509 - INFO - Running job "regulartime_task (trigger: interval[1 day, 0:00:00], next run at: 2020-04-24 00:23:13.479822)" (scheduled at 2020-04-24 00:23:13.479822)
2020-04-24 00:23:13,492 - _main_loop - 588 - DEBUG - Next wakeup is due at 2020-04-24 03:00:00 (in 9406.517797 seconds)
2020-04-24 00:23:14,449 - _run_job - 520 - ERROR - Job "regulartime_task (trigger: interval[1 day, 0:00:00], next run at: 2020-04-25 00:23:13.479822)" raised an exception
Traceback (most recent call last):
  File "D:\Program Files\Python37\lib\site-packages\django\db\backends\utils.py", line 84, in _execute
    return self.cursor.execute(sql, params)
  File "D:\Program Files\Python37\lib\site-packages\django\db\backends\mysql\base.py", line 71, in execute
    return self.cursor.execute(query, args)
  File "D:\Program Files\Python37\lib\site-packages\MySQLdb\cursors.py", line 209, in execute
    res = self._query(query)
  File "D:\Program Files\Python37\lib\site-packages\MySQLdb\cursors.py", line 315, in _query
    db.query(q)
  File "D:\Program Files\Python37\lib\site-packages\MySQLdb\connections.py", line 239, in query
    _mysql.connection.query(self, query)
MySQLdb._exceptions.IntegrityError: (1062, "Duplicate entry '1587744000' for key 'LAMProcessData_process_r_acquisition_timestamp_a69ae90c_uniq'")

The above exception was the direct cause of the following exception:

Traceback (most recent call last):
  File "D:\Program Files\Python37\lib\site-packages\apscheduler\scheduler.py", line 512, in _run_job
    retval = job.func(*job.args, **job.kwargs)
  File "E:\1-program\11-LAMDataServer\lamdataserver\LAMProcessData\views.py", line 4988, in regulartime_task
    RT_FineData.Realtime_FineData.init_Tomorrow_rows()
  File "E:\1-program\11-LAMDataServer\lamdataserver\LAMProcessData\process_realtime_finedata.py", line 193, in init_Tomorrow_rows
    _model.objects.bulk_create(insert_data_list)
  File "D:\Program Files\Python37\lib\site-packages\django\db\models\manager.py", line 82, in manager_method
    return getattr(self.get_queryset(), name)(*args, **kwargs)
  File "D:\Program Files\Python37\lib\site-packages\django\db\models\query.py", line 474, in bulk_create
    ids = self._batched_insert(objs_without_pk, fields, batch_size, ignore_conflicts=ignore_conflicts)
  File "D:\Program Files\Python37\lib\site-packages\django\db\models\query.py", line 1211, in _batched_insert
    self._insert(item, fields=fields, using=self.db, ignore_conflicts=ignore_conflicts)
  File "D:\Program Files\Python37\lib\site-packages\django\db\models\query.py", line 1186, in _insert
    return query.get_compiler(using=using).execute_sql(return_id)
  File "D:\Program Files\Python37\lib\site-packages\django\db\models\sql\compiler.py", line 1332, in execute_sql
    cursor.execute(sql, params)
  File "D:\Program Files\Python37\lib\site-packages\django\db\backends\utils.py", line 99, in execute
    return super().execute(sql, params)
  File "D:\Program Files\Python37\lib\site-packages\django\db\backends\utils.py", line 67, in execute
    return self._execute_with_wrappers(sql, params, many=False, executor=self._execute)
  File "D:\Program Files\Python37\lib\site-packages\django\db\backends\utils.py", line 76, in _execute_with_wrappers
    return executor(sql, params, many, context)
  File "D:\Program Files\Python37\lib\site-packages\django\db\backends\utils.py", line 84, in _execute
    return self.cursor.execute(sql, params)
  File "D:\Program Files\Python37\lib\site-packages\django\db\utils.py", line 89, in __exit__
    raise dj_exc_value.with_traceback(traceback) from exc_value
  File "D:\Program Files\Python37\lib\site-packages\django\db\backends\utils.py", line 84, in _execute
    return self.cursor.execute(sql, params)
  File "D:\Program Files\Python37\lib\site-packages\django\db\backends\mysql\base.py", line 71, in execute
    return self.cursor.execute(query, args)
  File "D:\Program Files\Python37\lib\site-packages\MySQLdb\cursors.py", line 209, in execute
    res = self._query(query)
  File "D:\Program Files\Python37\lib\site-packages\MySQLdb\cursors.py", line 315, in _query
    db.query(q)
  File "D:\Program Files\Python37\lib\site-packages\MySQLdb\connections.py", line 239, in query
    _mysql.connection.query(self, query)
django.db.utils.IntegrityError: (1062, "Duplicate entry '1587744000' for key 'LAMProcessData_process_r_acquisition_timestamp_a69ae90c_uniq'")
2020-04-24 00:23:15,458 - _run_jobs - 94 - DEBUG - Exiting worker thread
2020-04-24 00:23:46,750 - _real_add_job - 262 - INFO - Added job "regulartime_task (trigger: interval[1 day, 0:00:00], next run at: 2020-04-24 00:23:56.749677)" to job store "default"
2020-04-24 00:23:46,751 - _real_add_job - 262 - INFO - Added job "cleanup (trigger: cron[day_of_week='*', hour='3', minute='0', second='0'], next run at: 2020-04-24 03:00:00)" to job store "default"
2020-04-24 00:23:46,751 - _real_add_job - 262 - INFO - Added job "OpenLog (trigger: cron[hour='0'], next run at: 2020-04-25 00:00:00)" to job store "default"
2020-04-24 00:23:46,752 - _main_loop - 574 - INFO - Scheduler started
2020-04-24 00:23:46,752 - _main_loop - 579 - DEBUG - Looking for jobs to run
2020-04-24 00:23:46,753 - _main_loop - 588 - DEBUG - Next wakeup is due at 2020-04-24 00:23:56.749677 (in 9.997010 seconds)
2020-04-24 00:23:46,775 - <module> - 64 - DEBUG - SendBefore_NotRecive : [<CNCProcessStatus: CNCProcessStatus object (2038721)>]
2020-04-24 00:23:46,776 - <module> - 65 - DEBUG - Waitfor_Recive : [2038721]
2020-04-24 00:23:48,695 - log_response - 228 - ERROR - Internal Server Error: /LAMProcessData/QueryData/Statistic/RawStockFlow/
Traceback (most recent call last):
  File "D:\Program Files\Python37\lib\site-packages\django\core\handlers\exception.py", line 34, in inner
    response = get_response(request)
  File "D:\Program Files\Python37\lib\site-packages\django\core\handlers\base.py", line 115, in _get_response
    response = self.process_exception_by_middleware(e, request)
  File "D:\Program Files\Python37\lib\site-packages\django\core\handlers\base.py", line 113, in _get_response
    response = wrapped_callback(request, *callback_args, **callback_kwargs)
  File "D:\Program Files\Python37\lib\site-packages\django\contrib\auth\decorators.py", line 21, in _wrapped_view
    return view_func(request, *args, **kwargs)
  File "D:\Program Files\Python37\lib\site-packages\django\views\decorators\csrf.py", line 54, in wrapped_view
    return view_func(*args, **kwargs)
  File "E:\1-program\11-LAMDataServer\lamdataserver\LAMProcessData\query_views.py", line 1440, in queryData_Statistic_RawStockFlow
    queryset = [list(key).extend(value) for key,value in cluster_temp_dict.items()]
  File "E:\1-program\11-LAMDataServer\lamdataserver\LAMProcessData\query_views.py", line 1440, in <listcomp>
    queryset = [list(key).extend(value) for key,value in cluster_temp_dict.items()]
TypeError: <lambda>() missing 1 required positional argument: 'b'
2020-04-24 00:23:56,752 - _main_loop - 579 - DEBUG - Looking for jobs to run
2020-04-24 00:23:56,753 - _run_jobs - 69 - DEBUG - Started worker thread
2020-04-24 00:23:56,754 - _run_job - 509 - INFO - Running job "regulartime_task (trigger: interval[1 day, 0:00:00], next run at: 2020-04-24 00:23:56.749677)" (scheduled at 2020-04-24 00:23:56.749677)
2020-04-24 00:23:56,759 - _main_loop - 588 - DEBUG - Next wakeup is due at 2020-04-24 03:00:00 (in 9363.247412 seconds)
2020-04-24 00:23:57,720 - _run_job - 520 - ERROR - Job "regulartime_task (trigger: interval[1 day, 0:00:00], next run at: 2020-04-25 00:23:56.749677)" raised an exception
Traceback (most recent call last):
  File "D:\Program Files\Python37\lib\site-packages\django\db\backends\utils.py", line 84, in _execute
    return self.cursor.execute(sql, params)
  File "D:\Program Files\Python37\lib\site-packages\django\db\backends\mysql\base.py", line 71, in execute
    return self.cursor.execute(query, args)
  File "D:\Program Files\Python37\lib\site-packages\MySQLdb\cursors.py", line 209, in execute
    res = self._query(query)
  File "D:\Program Files\Python37\lib\site-packages\MySQLdb\cursors.py", line 315, in _query
    db.query(q)
  File "D:\Program Files\Python37\lib\site-packages\MySQLdb\connections.py", line 239, in query
    _mysql.connection.query(self, query)
MySQLdb._exceptions.IntegrityError: (1062, "Duplicate entry '1587744000' for key 'LAMProcessData_process_r_acquisition_timestamp_a69ae90c_uniq'")

The above exception was the direct cause of the following exception:

Traceback (most recent call last):
  File "D:\Program Files\Python37\lib\site-packages\apscheduler\scheduler.py", line 512, in _run_job
    retval = job.func(*job.args, **job.kwargs)
  File "E:\1-program\11-LAMDataServer\lamdataserver\LAMProcessData\views.py", line 4988, in regulartime_task
    RT_FineData.Realtime_FineData.init_Tomorrow_rows()
  File "E:\1-program\11-LAMDataServer\lamdataserver\LAMProcessData\process_realtime_finedata.py", line 193, in init_Tomorrow_rows
    _model.objects.bulk_create(insert_data_list)
  File "D:\Program Files\Python37\lib\site-packages\django\db\models\manager.py", line 82, in manager_method
    return getattr(self.get_queryset(), name)(*args, **kwargs)
  File "D:\Program Files\Python37\lib\site-packages\django\db\models\query.py", line 474, in bulk_create
    ids = self._batched_insert(objs_without_pk, fields, batch_size, ignore_conflicts=ignore_conflicts)
  File "D:\Program Files\Python37\lib\site-packages\django\db\models\query.py", line 1211, in _batched_insert
    self._insert(item, fields=fields, using=self.db, ignore_conflicts=ignore_conflicts)
  File "D:\Program Files\Python37\lib\site-packages\django\db\models\query.py", line 1186, in _insert
    return query.get_compiler(using=using).execute_sql(return_id)
  File "D:\Program Files\Python37\lib\site-packages\django\db\models\sql\compiler.py", line 1332, in execute_sql
    cursor.execute(sql, params)
  File "D:\Program Files\Python37\lib\site-packages\django\db\backends\utils.py", line 99, in execute
    return super().execute(sql, params)
  File "D:\Program Files\Python37\lib\site-packages\django\db\backends\utils.py", line 67, in execute
    return self._execute_with_wrappers(sql, params, many=False, executor=self._execute)
  File "D:\Program Files\Python37\lib\site-packages\django\db\backends\utils.py", line 76, in _execute_with_wrappers
    return executor(sql, params, many, context)
  File "D:\Program Files\Python37\lib\site-packages\django\db\backends\utils.py", line 84, in _execute
    return self.cursor.execute(sql, params)
  File "D:\Program Files\Python37\lib\site-packages\django\db\utils.py", line 89, in __exit__
    raise dj_exc_value.with_traceback(traceback) from exc_value
  File "D:\Program Files\Python37\lib\site-packages\django\db\backends\utils.py", line 84, in _execute
    return self.cursor.execute(sql, params)
  File "D:\Program Files\Python37\lib\site-packages\django\db\backends\mysql\base.py", line 71, in execute
    return self.cursor.execute(query, args)
  File "D:\Program Files\Python37\lib\site-packages\MySQLdb\cursors.py", line 209, in execute
    res = self._query(query)
  File "D:\Program Files\Python37\lib\site-packages\MySQLdb\cursors.py", line 315, in _query
    db.query(q)
  File "D:\Program Files\Python37\lib\site-packages\MySQLdb\connections.py", line 239, in query
    _mysql.connection.query(self, query)
django.db.utils.IntegrityError: (1062, "Duplicate entry '1587744000' for key 'LAMProcessData_process_r_acquisition_timestamp_a69ae90c_uniq'")
2020-04-24 00:23:58,730 - _run_jobs - 94 - DEBUG - Exiting worker thread
2020-04-24 00:24:22,339 - _real_add_job - 262 - INFO - Added job "regulartime_task (trigger: interval[1 day, 0:00:00], next run at: 2020-04-24 00:24:32.337718)" to job store "default"
2020-04-24 00:24:22,339 - _real_add_job - 262 - INFO - Added job "cleanup (trigger: cron[day_of_week='*', hour='3', minute='0', second='0'], next run at: 2020-04-24 03:00:00)" to job store "default"
2020-04-24 00:24:22,340 - _real_add_job - 262 - INFO - Added job "OpenLog (trigger: cron[hour='0'], next run at: 2020-04-25 00:00:00)" to job store "default"
2020-04-24 00:24:22,341 - _main_loop - 574 - INFO - Scheduler started
2020-04-24 00:24:22,341 - _main_loop - 579 - DEBUG - Looking for jobs to run
2020-04-24 00:24:22,341 - _main_loop - 588 - DEBUG - Next wakeup is due at 2020-04-24 00:24:32.337718 (in 9.996011 seconds)
2020-04-24 00:24:22,363 - <module> - 64 - DEBUG - SendBefore_NotRecive : [<CNCProcessStatus: CNCProcessStatus object (2038721)>]
2020-04-24 00:24:22,363 - <module> - 65 - DEBUG - Waitfor_Recive : [2038721]
2020-04-24 00:24:32,352 - _main_loop - 579 - DEBUG - Looking for jobs to run
2020-04-24 00:24:32,354 - _run_jobs - 69 - DEBUG - Started worker thread
2020-04-24 00:24:32,354 - _run_job - 509 - INFO - Running job "regulartime_task (trigger: interval[1 day, 0:00:00], next run at: 2020-04-24 00:24:32.337718)" (scheduled at 2020-04-24 00:24:32.337718)
2020-04-24 00:24:32,366 - _main_loop - 588 - DEBUG - Next wakeup is due at 2020-04-24 03:00:00 (in 9327.647357 seconds)
2020-04-24 00:24:33,296 - _run_job - 520 - ERROR - Job "regulartime_task (trigger: interval[1 day, 0:00:00], next run at: 2020-04-25 00:24:32.337718)" raised an exception
Traceback (most recent call last):
  File "D:\Program Files\Python37\lib\site-packages\django\db\backends\utils.py", line 84, in _execute
    return self.cursor.execute(sql, params)
  File "D:\Program Files\Python37\lib\site-packages\django\db\backends\mysql\base.py", line 71, in execute
    return self.cursor.execute(query, args)
  File "D:\Program Files\Python37\lib\site-packages\MySQLdb\cursors.py", line 209, in execute
    res = self._query(query)
  File "D:\Program Files\Python37\lib\site-packages\MySQLdb\cursors.py", line 315, in _query
    db.query(q)
  File "D:\Program Files\Python37\lib\site-packages\MySQLdb\connections.py", line 239, in query
    _mysql.connection.query(self, query)
MySQLdb._exceptions.IntegrityError: (1062, "Duplicate entry '1587744000' for key 'LAMProcessData_process_r_acquisition_timestamp_a69ae90c_uniq'")

The above exception was the direct cause of the following exception:

Traceback (most recent call last):
  File "D:\Program Files\Python37\lib\site-packages\apscheduler\scheduler.py", line 512, in _run_job
    retval = job.func(*job.args, **job.kwargs)
  File "E:\1-program\11-LAMDataServer\lamdataserver\LAMProcessData\views.py", line 4988, in regulartime_task
    RT_FineData.Realtime_FineData.init_Tomorrow_rows()
  File "E:\1-program\11-LAMDataServer\lamdataserver\LAMProcessData\process_realtime_finedata.py", line 193, in init_Tomorrow_rows
    _model.objects.bulk_create(insert_data_list)
  File "D:\Program Files\Python37\lib\site-packages\django\db\models\manager.py", line 82, in manager_method
    return getattr(self.get_queryset(), name)(*args, **kwargs)
  File "D:\Program Files\Python37\lib\site-packages\django\db\models\query.py", line 474, in bulk_create
    ids = self._batched_insert(objs_without_pk, fields, batch_size, ignore_conflicts=ignore_conflicts)
  File "D:\Program Files\Python37\lib\site-packages\django\db\models\query.py", line 1211, in _batched_insert
    self._insert(item, fields=fields, using=self.db, ignore_conflicts=ignore_conflicts)
  File "D:\Program Files\Python37\lib\site-packages\django\db\models\query.py", line 1186, in _insert
    return query.get_compiler(using=using).execute_sql(return_id)
  File "D:\Program Files\Python37\lib\site-packages\django\db\models\sql\compiler.py", line 1332, in execute_sql
    cursor.execute(sql, params)
  File "D:\Program Files\Python37\lib\site-packages\django\db\backends\utils.py", line 99, in execute
    return super().execute(sql, params)
  File "D:\Program Files\Python37\lib\site-packages\django\db\backends\utils.py", line 67, in execute
    return self._execute_with_wrappers(sql, params, many=False, executor=self._execute)
  File "D:\Program Files\Python37\lib\site-packages\django\db\backends\utils.py", line 76, in _execute_with_wrappers
    return executor(sql, params, many, context)
  File "D:\Program Files\Python37\lib\site-packages\django\db\backends\utils.py", line 84, in _execute
    return self.cursor.execute(sql, params)
  File "D:\Program Files\Python37\lib\site-packages\django\db\utils.py", line 89, in __exit__
    raise dj_exc_value.with_traceback(traceback) from exc_value
  File "D:\Program Files\Python37\lib\site-packages\django\db\backends\utils.py", line 84, in _execute
    return self.cursor.execute(sql, params)
  File "D:\Program Files\Python37\lib\site-packages\django\db\backends\mysql\base.py", line 71, in execute
    return self.cursor.execute(query, args)
  File "D:\Program Files\Python37\lib\site-packages\MySQLdb\cursors.py", line 209, in execute
    res = self._query(query)
  File "D:\Program Files\Python37\lib\site-packages\MySQLdb\cursors.py", line 315, in _query
    db.query(q)
  File "D:\Program Files\Python37\lib\site-packages\MySQLdb\connections.py", line 239, in query
    _mysql.connection.query(self, query)
django.db.utils.IntegrityError: (1062, "Duplicate entry '1587744000' for key 'LAMProcessData_process_r_acquisition_timestamp_a69ae90c_uniq'")
2020-04-24 00:24:34,306 - _run_jobs - 94 - DEBUG - Exiting worker thread
2020-04-24 00:24:43,018 - log_response - 228 - ERROR - Internal Server Error: /LAMProcessData/QueryData/Statistic/RawStockFlow/
Traceback (most recent call last):
  File "D:\Program Files\Python37\lib\site-packages\django\core\handlers\exception.py", line 34, in inner
    response = get_response(request)
  File "D:\Program Files\Python37\lib\site-packages\django\core\handlers\base.py", line 115, in _get_response
    response = self.process_exception_by_middleware(e, request)
  File "D:\Program Files\Python37\lib\site-packages\django\core\handlers\base.py", line 113, in _get_response
    response = wrapped_callback(request, *callback_args, **callback_kwargs)
  File "D:\Program Files\Python37\lib\site-packages\django\contrib\auth\decorators.py", line 21, in _wrapped_view
    return view_func(request, *args, **kwargs)
  File "D:\Program Files\Python37\lib\site-packages\django\views\decorators\csrf.py", line 54, in wrapped_view
    return view_func(*args, **kwargs)
  File "E:\1-program\11-LAMDataServer\lamdataserver\LAMProcessData\query_views.py", line 1440, in queryData_Statistic_RawStockFlow
    queryset = [list(key).extend(value) for key,value in cluster_temp_dict.items()]
  File "E:\1-program\11-LAMDataServer\lamdataserver\LAMProcessData\query_views.py", line 1440, in <listcomp>
    queryset = [list(key).extend(value) for key,value in cluster_temp_dict.items()]
TypeError: <lambda>() missing 1 required positional argument: 'b'
2020-04-24 00:27:04,413 - _real_add_job - 262 - INFO - Added job "regulartime_task (trigger: interval[1 day, 0:00:00], next run at: 2020-04-24 00:27:14.411896)" to job store "default"
2020-04-24 00:27:04,413 - _real_add_job - 262 - INFO - Added job "cleanup (trigger: cron[day_of_week='*', hour='3', minute='0', second='0'], next run at: 2020-04-24 03:00:00)" to job store "default"
2020-04-24 00:27:04,414 - _real_add_job - 262 - INFO - Added job "OpenLog (trigger: cron[hour='0'], next run at: 2020-04-25 00:00:00)" to job store "default"
2020-04-24 00:27:04,415 - _main_loop - 574 - INFO - Scheduler started
2020-04-24 00:27:04,415 - _main_loop - 579 - DEBUG - Looking for jobs to run
2020-04-24 00:27:04,415 - _main_loop - 588 - DEBUG - Next wakeup is due at 2020-04-24 00:27:14.411896 (in 9.995987 seconds)
2020-04-24 00:27:04,438 - <module> - 64 - DEBUG - SendBefore_NotRecive : [<CNCProcessStatus: CNCProcessStatus object (2038721)>]
2020-04-24 00:27:04,438 - <module> - 65 - DEBUG - Waitfor_Recive : [2038721]
2020-04-24 00:27:14,412 - _main_loop - 579 - DEBUG - Looking for jobs to run
2020-04-24 00:27:14,412 - _run_jobs - 69 - DEBUG - Started worker thread
2020-04-24 00:27:14,413 - _run_job - 509 - INFO - Running job "regulartime_task (trigger: interval[1 day, 0:00:00], next run at: 2020-04-24 00:27:14.411896)" (scheduled at 2020-04-24 00:27:14.411896)
2020-04-24 00:27:14,437 - _main_loop - 588 - DEBUG - Next wakeup is due at 2020-04-24 03:00:00 (in 9165.587706 seconds)
2020-04-24 00:27:15,431 - _run_job - 520 - ERROR - Job "regulartime_task (trigger: interval[1 day, 0:00:00], next run at: 2020-04-25 00:27:14.411896)" raised an exception
Traceback (most recent call last):
  File "D:\Program Files\Python37\lib\site-packages\django\db\backends\utils.py", line 84, in _execute
    return self.cursor.execute(sql, params)
  File "D:\Program Files\Python37\lib\site-packages\django\db\backends\mysql\base.py", line 71, in execute
    return self.cursor.execute(query, args)
  File "D:\Program Files\Python37\lib\site-packages\MySQLdb\cursors.py", line 209, in execute
    res = self._query(query)
  File "D:\Program Files\Python37\lib\site-packages\MySQLdb\cursors.py", line 315, in _query
    db.query(q)
  File "D:\Program Files\Python37\lib\site-packages\MySQLdb\connections.py", line 239, in query
    _mysql.connection.query(self, query)
MySQLdb._exceptions.IntegrityError: (1062, "Duplicate entry '1587744000' for key 'LAMProcessData_process_r_acquisition_timestamp_a69ae90c_uniq'")

The above exception was the direct cause of the following exception:

Traceback (most recent call last):
  File "D:\Program Files\Python37\lib\site-packages\apscheduler\scheduler.py", line 512, in _run_job
    retval = job.func(*job.args, **job.kwargs)
  File "E:\1-program\11-LAMDataServer\lamdataserver\LAMProcessData\views.py", line 4988, in regulartime_task
    RT_FineData.Realtime_FineData.init_Tomorrow_rows()
  File "E:\1-program\11-LAMDataServer\lamdataserver\LAMProcessData\process_realtime_finedata.py", line 193, in init_Tomorrow_rows
    _model.objects.bulk_create(insert_data_list)
  File "D:\Program Files\Python37\lib\site-packages\django\db\models\manager.py", line 82, in manager_method
    return getattr(self.get_queryset(), name)(*args, **kwargs)
  File "D:\Program Files\Python37\lib\site-packages\django\db\models\query.py", line 474, in bulk_create
    ids = self._batched_insert(objs_without_pk, fields, batch_size, ignore_conflicts=ignore_conflicts)
  File "D:\Program Files\Python37\lib\site-packages\django\db\models\query.py", line 1211, in _batched_insert
    self._insert(item, fields=fields, using=self.db, ignore_conflicts=ignore_conflicts)
  File "D:\Program Files\Python37\lib\site-packages\django\db\models\query.py", line 1186, in _insert
    return query.get_compiler(using=using).execute_sql(return_id)
  File "D:\Program Files\Python37\lib\site-packages\django\db\models\sql\compiler.py", line 1332, in execute_sql
    cursor.execute(sql, params)
  File "D:\Program Files\Python37\lib\site-packages\django\db\backends\utils.py", line 99, in execute
    return super().execute(sql, params)
  File "D:\Program Files\Python37\lib\site-packages\django\db\backends\utils.py", line 67, in execute
    return self._execute_with_wrappers(sql, params, many=False, executor=self._execute)
  File "D:\Program Files\Python37\lib\site-packages\django\db\backends\utils.py", line 76, in _execute_with_wrappers
    return executor(sql, params, many, context)
  File "D:\Program Files\Python37\lib\site-packages\django\db\backends\utils.py", line 84, in _execute
    return self.cursor.execute(sql, params)
  File "D:\Program Files\Python37\lib\site-packages\django\db\utils.py", line 89, in __exit__
    raise dj_exc_value.with_traceback(traceback) from exc_value
  File "D:\Program Files\Python37\lib\site-packages\django\db\backends\utils.py", line 84, in _execute
    return self.cursor.execute(sql, params)
  File "D:\Program Files\Python37\lib\site-packages\django\db\backends\mysql\base.py", line 71, in execute
    return self.cursor.execute(query, args)
  File "D:\Program Files\Python37\lib\site-packages\MySQLdb\cursors.py", line 209, in execute
    res = self._query(query)
  File "D:\Program Files\Python37\lib\site-packages\MySQLdb\cursors.py", line 315, in _query
    db.query(q)
  File "D:\Program Files\Python37\lib\site-packages\MySQLdb\connections.py", line 239, in query
    _mysql.connection.query(self, query)
django.db.utils.IntegrityError: (1062, "Duplicate entry '1587744000' for key 'LAMProcessData_process_r_acquisition_timestamp_a69ae90c_uniq'")
2020-04-24 00:27:16,443 - _run_jobs - 94 - DEBUG - Exiting worker thread
2020-04-24 00:28:10,010 - _real_add_job - 262 - INFO - Added job "regulartime_task (trigger: interval[1 day, 0:00:00], next run at: 2020-04-24 00:28:20.008604)" to job store "default"
2020-04-24 00:28:10,011 - _real_add_job - 262 - INFO - Added job "cleanup (trigger: cron[day_of_week='*', hour='3', minute='0', second='0'], next run at: 2020-04-24 03:00:00)" to job store "default"
2020-04-24 00:28:10,011 - _real_add_job - 262 - INFO - Added job "OpenLog (trigger: cron[hour='0'], next run at: 2020-04-25 00:00:00)" to job store "default"
2020-04-24 00:28:10,012 - _main_loop - 574 - INFO - Scheduler started
2020-04-24 00:28:10,012 - _main_loop - 579 - DEBUG - Looking for jobs to run
2020-04-24 00:28:10,013 - _main_loop - 588 - DEBUG - Next wakeup is due at 2020-04-24 00:28:20.008604 (in 9.995013 seconds)
2020-04-24 00:28:10,034 - <module> - 64 - DEBUG - SendBefore_NotRecive : [<CNCProcessStatus: CNCProcessStatus object (2038721)>]
2020-04-24 00:28:10,034 - <module> - 65 - DEBUG - Waitfor_Recive : [2038721]
2020-04-24 00:28:20,022 - _main_loop - 579 - DEBUG - Looking for jobs to run
2020-04-24 00:28:20,026 - _run_jobs - 69 - DEBUG - Started worker thread
2020-04-24 00:28:20,027 - _run_job - 509 - INFO - Running job "regulartime_task (trigger: interval[1 day, 0:00:00], next run at: 2020-04-24 00:28:20.008604)" (scheduled at 2020-04-24 00:28:20.008604)
2020-04-24 00:28:20,033 - _main_loop - 588 - DEBUG - Next wakeup is due at 2020-04-24 03:00:00 (in 9099.976248 seconds)
2020-04-24 00:28:20,950 - _run_job - 520 - ERROR - Job "regulartime_task (trigger: interval[1 day, 0:00:00], next run at: 2020-04-25 00:28:20.008604)" raised an exception
Traceback (most recent call last):
  File "D:\Program Files\Python37\lib\site-packages\django\db\backends\utils.py", line 84, in _execute
    return self.cursor.execute(sql, params)
  File "D:\Program Files\Python37\lib\site-packages\django\db\backends\mysql\base.py", line 71, in execute
    return self.cursor.execute(query, args)
  File "D:\Program Files\Python37\lib\site-packages\MySQLdb\cursors.py", line 209, in execute
    res = self._query(query)
  File "D:\Program Files\Python37\lib\site-packages\MySQLdb\cursors.py", line 315, in _query
    db.query(q)
  File "D:\Program Files\Python37\lib\site-packages\MySQLdb\connections.py", line 239, in query
    _mysql.connection.query(self, query)
MySQLdb._exceptions.IntegrityError: (1062, "Duplicate entry '1587744000' for key 'LAMProcessData_process_r_acquisition_timestamp_a69ae90c_uniq'")

The above exception was the direct cause of the following exception:

Traceback (most recent call last):
  File "D:\Program Files\Python37\lib\site-packages\apscheduler\scheduler.py", line 512, in _run_job
    retval = job.func(*job.args, **job.kwargs)
  File "E:\1-program\11-LAMDataServer\lamdataserver\LAMProcessData\views.py", line 4988, in regulartime_task
    RT_FineData.Realtime_FineData.init_Tomorrow_rows()
  File "E:\1-program\11-LAMDataServer\lamdataserver\LAMProcessData\process_realtime_finedata.py", line 193, in init_Tomorrow_rows
    _model.objects.bulk_create(insert_data_list)
  File "D:\Program Files\Python37\lib\site-packages\django\db\models\manager.py", line 82, in manager_method
    return getattr(self.get_queryset(), name)(*args, **kwargs)
  File "D:\Program Files\Python37\lib\site-packages\django\db\models\query.py", line 474, in bulk_create
    ids = self._batched_insert(objs_without_pk, fields, batch_size, ignore_conflicts=ignore_conflicts)
  File "D:\Program Files\Python37\lib\site-packages\django\db\models\query.py", line 1211, in _batched_insert
    self._insert(item, fields=fields, using=self.db, ignore_conflicts=ignore_conflicts)
  File "D:\Program Files\Python37\lib\site-packages\django\db\models\query.py", line 1186, in _insert
    return query.get_compiler(using=using).execute_sql(return_id)
  File "D:\Program Files\Python37\lib\site-packages\django\db\models\sql\compiler.py", line 1332, in execute_sql
    cursor.execute(sql, params)
  File "D:\Program Files\Python37\lib\site-packages\django\db\backends\utils.py", line 99, in execute
    return super().execute(sql, params)
  File "D:\Program Files\Python37\lib\site-packages\django\db\backends\utils.py", line 67, in execute
    return self._execute_with_wrappers(sql, params, many=False, executor=self._execute)
  File "D:\Program Files\Python37\lib\site-packages\django\db\backends\utils.py", line 76, in _execute_with_wrappers
    return executor(sql, params, many, context)
  File "D:\Program Files\Python37\lib\site-packages\django\db\backends\utils.py", line 84, in _execute
    return self.cursor.execute(sql, params)
  File "D:\Program Files\Python37\lib\site-packages\django\db\utils.py", line 89, in __exit__
    raise dj_exc_value.with_traceback(traceback) from exc_value
  File "D:\Program Files\Python37\lib\site-packages\django\db\backends\utils.py", line 84, in _execute
    return self.cursor.execute(sql, params)
  File "D:\Program Files\Python37\lib\site-packages\django\db\backends\mysql\base.py", line 71, in execute
    return self.cursor.execute(query, args)
  File "D:\Program Files\Python37\lib\site-packages\MySQLdb\cursors.py", line 209, in execute
    res = self._query(query)
  File "D:\Program Files\Python37\lib\site-packages\MySQLdb\cursors.py", line 315, in _query
    db.query(q)
  File "D:\Program Files\Python37\lib\site-packages\MySQLdb\connections.py", line 239, in query
    _mysql.connection.query(self, query)
django.db.utils.IntegrityError: (1062, "Duplicate entry '1587744000' for key 'LAMProcessData_process_r_acquisition_timestamp_a69ae90c_uniq'")
2020-04-24 00:28:21,958 - _run_jobs - 94 - DEBUG - Exiting worker thread
2020-04-24 00:29:26,782 - trigger_reload - 203 - INFO - E:\1-program\11-LAMDataServer\lamdataserver\LAMProcessData\query_views.py changed, reloading.
2020-04-24 00:29:26,783 - shutdown - 111 - INFO - Shutting down thread pool
2020-04-24 00:29:29,891 - _real_add_job - 262 - INFO - Added job "regulartime_task (trigger: interval[1 day, 0:00:00], next run at: 2020-04-24 00:29:39.889368)" to job store "default"
2020-04-24 00:29:29,891 - _real_add_job - 262 - INFO - Added job "cleanup (trigger: cron[day_of_week='*', hour='3', minute='0', second='0'], next run at: 2020-04-24 03:00:00)" to job store "default"
2020-04-24 00:29:29,892 - _real_add_job - 262 - INFO - Added job "OpenLog (trigger: cron[hour='0'], next run at: 2020-04-25 00:00:00)" to job store "default"
2020-04-24 00:29:29,893 - _main_loop - 574 - INFO - Scheduler started
2020-04-24 00:29:29,893 - _main_loop - 579 - DEBUG - Looking for jobs to run
2020-04-24 00:29:29,894 - _main_loop - 588 - DEBUG - Next wakeup is due at 2020-04-24 00:29:39.889368 (in 9.994986 seconds)
2020-04-24 00:29:29,916 - <module> - 64 - DEBUG - SendBefore_NotRecive : [<CNCProcessStatus: CNCProcessStatus object (2038721)>]
2020-04-24 00:29:29,917 - <module> - 65 - DEBUG - Waitfor_Recive : [2038721]
2020-04-24 00:29:39,889 - _main_loop - 579 - DEBUG - Looking for jobs to run
2020-04-24 00:29:39,893 - _run_jobs - 69 - DEBUG - Started worker thread
2020-04-24 00:29:39,894 - _main_loop - 588 - DEBUG - Next wakeup is due at 2020-04-24 03:00:00 (in 9020.109429 seconds)
2020-04-24 00:29:39,895 - _run_job - 509 - INFO - Running job "regulartime_task (trigger: interval[1 day, 0:00:00], next run at: 2020-04-25 00:29:39.889368)" (scheduled at 2020-04-24 00:29:39.889368)
2020-04-24 00:29:40,848 - _run_job - 520 - ERROR - Job "regulartime_task (trigger: interval[1 day, 0:00:00], next run at: 2020-04-25 00:29:39.889368)" raised an exception
Traceback (most recent call last):
  File "D:\Program Files\Python37\lib\site-packages\django\db\backends\utils.py", line 84, in _execute
    return self.cursor.execute(sql, params)
  File "D:\Program Files\Python37\lib\site-packages\django\db\backends\mysql\base.py", line 71, in execute
    return self.cursor.execute(query, args)
  File "D:\Program Files\Python37\lib\site-packages\MySQLdb\cursors.py", line 209, in execute
    res = self._query(query)
  File "D:\Program Files\Python37\lib\site-packages\MySQLdb\cursors.py", line 315, in _query
    db.query(q)
  File "D:\Program Files\Python37\lib\site-packages\MySQLdb\connections.py", line 239, in query
    _mysql.connection.query(self, query)
MySQLdb._exceptions.IntegrityError: (1062, "Duplicate entry '1587744000' for key 'LAMProcessData_process_r_acquisition_timestamp_a69ae90c_uniq'")

The above exception was the direct cause of the following exception:

Traceback (most recent call last):
  File "D:\Program Files\Python37\lib\site-packages\apscheduler\scheduler.py", line 512, in _run_job
    retval = job.func(*job.args, **job.kwargs)
  File "E:\1-program\11-LAMDataServer\lamdataserver\LAMProcessData\views.py", line 4988, in regulartime_task
    RT_FineData.Realtime_FineData.init_Tomorrow_rows()
  File "E:\1-program\11-LAMDataServer\lamdataserver\LAMProcessData\process_realtime_finedata.py", line 193, in init_Tomorrow_rows
    _model.objects.bulk_create(insert_data_list)
  File "D:\Program Files\Python37\lib\site-packages\django\db\models\manager.py", line 82, in manager_method
    return getattr(self.get_queryset(), name)(*args, **kwargs)
  File "D:\Program Files\Python37\lib\site-packages\django\db\models\query.py", line 474, in bulk_create
    ids = self._batched_insert(objs_without_pk, fields, batch_size, ignore_conflicts=ignore_conflicts)
  File "D:\Program Files\Python37\lib\site-packages\django\db\models\query.py", line 1211, in _batched_insert
    self._insert(item, fields=fields, using=self.db, ignore_conflicts=ignore_conflicts)
  File "D:\Program Files\Python37\lib\site-packages\django\db\models\query.py", line 1186, in _insert
    return query.get_compiler(using=using).execute_sql(return_id)
  File "D:\Program Files\Python37\lib\site-packages\django\db\models\sql\compiler.py", line 1332, in execute_sql
    cursor.execute(sql, params)
  File "D:\Program Files\Python37\lib\site-packages\django\db\backends\utils.py", line 99, in execute
    return super().execute(sql, params)
  File "D:\Program Files\Python37\lib\site-packages\django\db\backends\utils.py", line 67, in execute
    return self._execute_with_wrappers(sql, params, many=False, executor=self._execute)
  File "D:\Program Files\Python37\lib\site-packages\django\db\backends\utils.py", line 76, in _execute_with_wrappers
    return executor(sql, params, many, context)
  File "D:\Program Files\Python37\lib\site-packages\django\db\backends\utils.py", line 84, in _execute
    return self.cursor.execute(sql, params)
  File "D:\Program Files\Python37\lib\site-packages\django\db\utils.py", line 89, in __exit__
    raise dj_exc_value.with_traceback(traceback) from exc_value
  File "D:\Program Files\Python37\lib\site-packages\django\db\backends\utils.py", line 84, in _execute
    return self.cursor.execute(sql, params)
  File "D:\Program Files\Python37\lib\site-packages\django\db\backends\mysql\base.py", line 71, in execute
    return self.cursor.execute(query, args)
  File "D:\Program Files\Python37\lib\site-packages\MySQLdb\cursors.py", line 209, in execute
    res = self._query(query)
  File "D:\Program Files\Python37\lib\site-packages\MySQLdb\cursors.py", line 315, in _query
    db.query(q)
  File "D:\Program Files\Python37\lib\site-packages\MySQLdb\connections.py", line 239, in query
    _mysql.connection.query(self, query)
django.db.utils.IntegrityError: (1062, "Duplicate entry '1587744000' for key 'LAMProcessData_process_r_acquisition_timestamp_a69ae90c_uniq'")
2020-04-24 00:29:41,858 - _run_jobs - 94 - DEBUG - Exiting worker thread
2020-04-24 00:30:01,737 - trigger_reload - 203 - INFO - E:\1-program\11-LAMDataServer\lamdataserver\LAMProcessData\query_views.py changed, reloading.
2020-04-24 00:30:01,738 - shutdown - 111 - INFO - Shutting down thread pool
2020-04-24 00:30:05,060 - _real_add_job - 262 - INFO - Added job "regulartime_task (trigger: interval[1 day, 0:00:00], next run at: 2020-04-24 00:30:15.058828)" to job store "default"
2020-04-24 00:30:05,060 - _real_add_job - 262 - INFO - Added job "cleanup (trigger: cron[day_of_week='*', hour='3', minute='0', second='0'], next run at: 2020-04-24 03:00:00)" to job store "default"
2020-04-24 00:30:05,061 - _real_add_job - 262 - INFO - Added job "OpenLog (trigger: cron[hour='0'], next run at: 2020-04-25 00:00:00)" to job store "default"
2020-04-24 00:30:05,062 - _main_loop - 574 - INFO - Scheduler started
2020-04-24 00:30:05,062 - _main_loop - 579 - DEBUG - Looking for jobs to run
2020-04-24 00:30:05,063 - _main_loop - 588 - DEBUG - Next wakeup is due at 2020-04-24 00:30:15.058828 (in 9.996031 seconds)
2020-04-24 00:30:05,085 - <module> - 64 - DEBUG - SendBefore_NotRecive : [<CNCProcessStatus: CNCProcessStatus object (2038721)>]
2020-04-24 00:30:05,085 - <module> - 65 - DEBUG - Waitfor_Recive : [2038721]
2020-04-24 00:30:16,322 - _real_add_job - 262 - INFO - Added job "regulartime_task (trigger: interval[1 day, 0:00:00], next run at: 2020-04-24 00:30:26.320843)" to job store "default"
2020-04-24 00:30:16,322 - _real_add_job - 262 - INFO - Added job "cleanup (trigger: cron[day_of_week='*', hour='3', minute='0', second='0'], next run at: 2020-04-24 03:00:00)" to job store "default"
2020-04-24 00:30:16,323 - _real_add_job - 262 - INFO - Added job "OpenLog (trigger: cron[hour='0'], next run at: 2020-04-25 00:00:00)" to job store "default"
2020-04-24 00:30:16,324 - _main_loop - 574 - INFO - Scheduler started
2020-04-24 00:30:16,324 - _main_loop - 579 - DEBUG - Looking for jobs to run
2020-04-24 00:30:16,324 - _main_loop - 588 - DEBUG - Next wakeup is due at 2020-04-24 00:30:26.320843 (in 9.996010 seconds)
2020-04-24 00:30:16,347 - <module> - 64 - DEBUG - SendBefore_NotRecive : [<CNCProcessStatus: CNCProcessStatus object (2038721)>]
2020-04-24 00:30:16,348 - <module> - 65 - DEBUG - Waitfor_Recive : [2038721]
2020-04-24 00:30:26,335 - _main_loop - 579 - DEBUG - Looking for jobs to run
2020-04-24 00:30:26,339 - _run_jobs - 69 - DEBUG - Started worker thread
2020-04-24 00:30:26,340 - _run_job - 509 - INFO - Running job "regulartime_task (trigger: interval[1 day, 0:00:00], next run at: 2020-04-24 00:30:26.320843)" (scheduled at 2020-04-24 00:30:26.320843)
2020-04-24 00:30:26,346 - _main_loop - 588 - DEBUG - Next wakeup is due at 2020-04-24 03:00:00 (in 8973.663565 seconds)
2020-04-24 00:30:27,339 - _run_job - 520 - ERROR - Job "regulartime_task (trigger: interval[1 day, 0:00:00], next run at: 2020-04-25 00:30:26.320843)" raised an exception
Traceback (most recent call last):
  File "D:\Program Files\Python37\lib\site-packages\django\db\backends\utils.py", line 84, in _execute
    return self.cursor.execute(sql, params)
  File "D:\Program Files\Python37\lib\site-packages\django\db\backends\mysql\base.py", line 71, in execute
    return self.cursor.execute(query, args)
  File "D:\Program Files\Python37\lib\site-packages\MySQLdb\cursors.py", line 209, in execute
    res = self._query(query)
  File "D:\Program Files\Python37\lib\site-packages\MySQLdb\cursors.py", line 315, in _query
    db.query(q)
  File "D:\Program Files\Python37\lib\site-packages\MySQLdb\connections.py", line 239, in query
    _mysql.connection.query(self, query)
MySQLdb._exceptions.IntegrityError: (1062, "Duplicate entry '1587744000' for key 'LAMProcessData_process_r_acquisition_timestamp_a69ae90c_uniq'")

The above exception was the direct cause of the following exception:

Traceback (most recent call last):
  File "D:\Program Files\Python37\lib\site-packages\apscheduler\scheduler.py", line 512, in _run_job
    retval = job.func(*job.args, **job.kwargs)
  File "E:\1-program\11-LAMDataServer\lamdataserver\LAMProcessData\views.py", line 4988, in regulartime_task
    RT_FineData.Realtime_FineData.init_Tomorrow_rows()
  File "E:\1-program\11-LAMDataServer\lamdataserver\LAMProcessData\process_realtime_finedata.py", line 193, in init_Tomorrow_rows
    _model.objects.bulk_create(insert_data_list)
  File "D:\Program Files\Python37\lib\site-packages\django\db\models\manager.py", line 82, in manager_method
    return getattr(self.get_queryset(), name)(*args, **kwargs)
  File "D:\Program Files\Python37\lib\site-packages\django\db\models\query.py", line 474, in bulk_create
    ids = self._batched_insert(objs_without_pk, fields, batch_size, ignore_conflicts=ignore_conflicts)
  File "D:\Program Files\Python37\lib\site-packages\django\db\models\query.py", line 1211, in _batched_insert
    self._insert(item, fields=fields, using=self.db, ignore_conflicts=ignore_conflicts)
  File "D:\Program Files\Python37\lib\site-packages\django\db\models\query.py", line 1186, in _insert
    return query.get_compiler(using=using).execute_sql(return_id)
  File "D:\Program Files\Python37\lib\site-packages\django\db\models\sql\compiler.py", line 1332, in execute_sql
    cursor.execute(sql, params)
  File "D:\Program Files\Python37\lib\site-packages\django\db\backends\utils.py", line 99, in execute
    return super().execute(sql, params)
  File "D:\Program Files\Python37\lib\site-packages\django\db\backends\utils.py", line 67, in execute
    return self._execute_with_wrappers(sql, params, many=False, executor=self._execute)
  File "D:\Program Files\Python37\lib\site-packages\django\db\backends\utils.py", line 76, in _execute_with_wrappers
    return executor(sql, params, many, context)
  File "D:\Program Files\Python37\lib\site-packages\django\db\backends\utils.py", line 84, in _execute
    return self.cursor.execute(sql, params)
  File "D:\Program Files\Python37\lib\site-packages\django\db\utils.py", line 89, in __exit__
    raise dj_exc_value.with_traceback(traceback) from exc_value
  File "D:\Program Files\Python37\lib\site-packages\django\db\backends\utils.py", line 84, in _execute
    return self.cursor.execute(sql, params)
  File "D:\Program Files\Python37\lib\site-packages\django\db\backends\mysql\base.py", line 71, in execute
    return self.cursor.execute(query, args)
  File "D:\Program Files\Python37\lib\site-packages\MySQLdb\cursors.py", line 209, in execute
    res = self._query(query)
  File "D:\Program Files\Python37\lib\site-packages\MySQLdb\cursors.py", line 315, in _query
    db.query(q)
  File "D:\Program Files\Python37\lib\site-packages\MySQLdb\connections.py", line 239, in query
    _mysql.connection.query(self, query)
django.db.utils.IntegrityError: (1062, "Duplicate entry '1587744000' for key 'LAMProcessData_process_r_acquisition_timestamp_a69ae90c_uniq'")
2020-04-24 00:30:28,348 - _run_jobs - 94 - DEBUG - Exiting worker thread
2020-04-24 00:31:03,586 - _real_add_job - 262 - INFO - Added job "regulartime_task (trigger: interval[1 day, 0:00:00], next run at: 2020-04-24 00:31:13.584415)" to job store "default"
2020-04-24 00:31:03,586 - _real_add_job - 262 - INFO - Added job "cleanup (trigger: cron[day_of_week='*', hour='3', minute='0', second='0'], next run at: 2020-04-24 03:00:00)" to job store "default"
2020-04-24 00:31:03,587 - _real_add_job - 262 - INFO - Added job "OpenLog (trigger: cron[hour='0'], next run at: 2020-04-25 00:00:00)" to job store "default"
2020-04-24 00:31:03,588 - _main_loop - 574 - INFO - Scheduler started
2020-04-24 00:31:03,588 - _main_loop - 579 - DEBUG - Looking for jobs to run
2020-04-24 00:31:03,589 - _main_loop - 588 - DEBUG - Next wakeup is due at 2020-04-24 00:31:13.584415 (in 9.995053 seconds)
2020-04-24 00:31:03,611 - <module> - 64 - DEBUG - SendBefore_NotRecive : [<CNCProcessStatus: CNCProcessStatus object (2038721)>]
2020-04-24 00:31:03,611 - <module> - 65 - DEBUG - Waitfor_Recive : [2038721]
2020-04-24 00:31:13,586 - _main_loop - 579 - DEBUG - Looking for jobs to run
2020-04-24 00:31:13,590 - _run_jobs - 69 - DEBUG - Started worker thread
2020-04-24 00:31:13,591 - _run_job - 509 - INFO - Running job "regulartime_task (trigger: interval[1 day, 0:00:00], next run at: 2020-04-24 00:31:13.584415)" (scheduled at 2020-04-24 00:31:13.584415)
2020-04-24 00:31:13,604 - _main_loop - 588 - DEBUG - Next wakeup is due at 2020-04-24 03:00:00 (in 8926.412712 seconds)
2020-04-24 00:31:14,557 - _run_job - 520 - ERROR - Job "regulartime_task (trigger: interval[1 day, 0:00:00], next run at: 2020-04-25 00:31:13.584415)" raised an exception
Traceback (most recent call last):
  File "D:\Program Files\Python37\lib\site-packages\django\db\backends\utils.py", line 84, in _execute
    return self.cursor.execute(sql, params)
  File "D:\Program Files\Python37\lib\site-packages\django\db\backends\mysql\base.py", line 71, in execute
    return self.cursor.execute(query, args)
  File "D:\Program Files\Python37\lib\site-packages\MySQLdb\cursors.py", line 209, in execute
    res = self._query(query)
  File "D:\Program Files\Python37\lib\site-packages\MySQLdb\cursors.py", line 315, in _query
    db.query(q)
  File "D:\Program Files\Python37\lib\site-packages\MySQLdb\connections.py", line 239, in query
    _mysql.connection.query(self, query)
MySQLdb._exceptions.IntegrityError: (1062, "Duplicate entry '1587744000' for key 'LAMProcessData_process_r_acquisition_timestamp_a69ae90c_uniq'")

The above exception was the direct cause of the following exception:

Traceback (most recent call last):
  File "D:\Program Files\Python37\lib\site-packages\apscheduler\scheduler.py", line 512, in _run_job
    retval = job.func(*job.args, **job.kwargs)
  File "E:\1-program\11-LAMDataServer\lamdataserver\LAMProcessData\views.py", line 4988, in regulartime_task
    RT_FineData.Realtime_FineData.init_Tomorrow_rows()
  File "E:\1-program\11-LAMDataServer\lamdataserver\LAMProcessData\process_realtime_finedata.py", line 193, in init_Tomorrow_rows
    _model.objects.bulk_create(insert_data_list)
  File "D:\Program Files\Python37\lib\site-packages\django\db\models\manager.py", line 82, in manager_method
    return getattr(self.get_queryset(), name)(*args, **kwargs)
  File "D:\Program Files\Python37\lib\site-packages\django\db\models\query.py", line 474, in bulk_create
    ids = self._batched_insert(objs_without_pk, fields, batch_size, ignore_conflicts=ignore_conflicts)
  File "D:\Program Files\Python37\lib\site-packages\django\db\models\query.py", line 1211, in _batched_insert
    self._insert(item, fields=fields, using=self.db, ignore_conflicts=ignore_conflicts)
  File "D:\Program Files\Python37\lib\site-packages\django\db\models\query.py", line 1186, in _insert
    return query.get_compiler(using=using).execute_sql(return_id)
  File "D:\Program Files\Python37\lib\site-packages\django\db\models\sql\compiler.py", line 1332, in execute_sql
    cursor.execute(sql, params)
  File "D:\Program Files\Python37\lib\site-packages\django\db\backends\utils.py", line 99, in execute
    return super().execute(sql, params)
  File "D:\Program Files\Python37\lib\site-packages\django\db\backends\utils.py", line 67, in execute
    return self._execute_with_wrappers(sql, params, many=False, executor=self._execute)
  File "D:\Program Files\Python37\lib\site-packages\django\db\backends\utils.py", line 76, in _execute_with_wrappers
    return executor(sql, params, many, context)
  File "D:\Program Files\Python37\lib\site-packages\django\db\backends\utils.py", line 84, in _execute
    return self.cursor.execute(sql, params)
  File "D:\Program Files\Python37\lib\site-packages\django\db\utils.py", line 89, in __exit__
    raise dj_exc_value.with_traceback(traceback) from exc_value
  File "D:\Program Files\Python37\lib\site-packages\django\db\backends\utils.py", line 84, in _execute
    return self.cursor.execute(sql, params)
  File "D:\Program Files\Python37\lib\site-packages\django\db\backends\mysql\base.py", line 71, in execute
    return self.cursor.execute(query, args)
  File "D:\Program Files\Python37\lib\site-packages\MySQLdb\cursors.py", line 209, in execute
    res = self._query(query)
  File "D:\Program Files\Python37\lib\site-packages\MySQLdb\cursors.py", line 315, in _query
    db.query(q)
  File "D:\Program Files\Python37\lib\site-packages\MySQLdb\connections.py", line 239, in query
    _mysql.connection.query(self, query)
django.db.utils.IntegrityError: (1062, "Duplicate entry '1587744000' for key 'LAMProcessData_process_r_acquisition_timestamp_a69ae90c_uniq'")
2020-04-24 00:31:15,565 - _run_jobs - 94 - DEBUG - Exiting worker thread
2020-04-24 00:33:01,445 - _real_add_job - 262 - INFO - Added job "regulartime_task (trigger: interval[1 day, 0:00:00], next run at: 2020-04-24 00:33:11.443022)" to job store "default"
2020-04-24 00:33:01,446 - _real_add_job - 262 - INFO - Added job "cleanup (trigger: cron[day_of_week='*', hour='3', minute='0', second='0'], next run at: 2020-04-24 03:00:00)" to job store "default"
2020-04-24 00:33:01,446 - _real_add_job - 262 - INFO - Added job "OpenLog (trigger: cron[hour='0'], next run at: 2020-04-25 00:00:00)" to job store "default"
2020-04-24 00:33:01,446 - _main_loop - 574 - INFO - Scheduler started
2020-04-24 00:33:01,446 - _main_loop - 579 - DEBUG - Looking for jobs to run
2020-04-24 00:33:01,447 - _main_loop - 588 - DEBUG - Next wakeup is due at 2020-04-24 00:33:11.443022 (in 9.995066 seconds)
2020-04-24 00:33:01,468 - <module> - 64 - DEBUG - SendBefore_NotRecive : [<CNCProcessStatus: CNCProcessStatus object (2038721)>]
2020-04-24 00:33:01,468 - <module> - 65 - DEBUG - Waitfor_Recive : [2038721]
2020-04-24 00:33:11,444 - _main_loop - 579 - DEBUG - Looking for jobs to run
2020-04-24 00:33:11,448 - _run_jobs - 69 - DEBUG - Started worker thread
2020-04-24 00:33:11,449 - _run_job - 509 - INFO - Running job "regulartime_task (trigger: interval[1 day, 0:00:00], next run at: 2020-04-24 00:33:11.443022)" (scheduled at 2020-04-24 00:33:11.443022)
2020-04-24 00:33:11,456 - _main_loop - 588 - DEBUG - Next wakeup is due at 2020-04-24 03:00:00 (in 8808.554382 seconds)
2020-04-24 00:33:12,419 - _run_job - 520 - ERROR - Job "regulartime_task (trigger: interval[1 day, 0:00:00], next run at: 2020-04-25 00:33:11.443022)" raised an exception
Traceback (most recent call last):
  File "D:\Program Files\Python37\lib\site-packages\django\db\backends\utils.py", line 84, in _execute
    return self.cursor.execute(sql, params)
  File "D:\Program Files\Python37\lib\site-packages\django\db\backends\mysql\base.py", line 71, in execute
    return self.cursor.execute(query, args)
  File "D:\Program Files\Python37\lib\site-packages\MySQLdb\cursors.py", line 209, in execute
    res = self._query(query)
  File "D:\Program Files\Python37\lib\site-packages\MySQLdb\cursors.py", line 315, in _query
    db.query(q)
  File "D:\Program Files\Python37\lib\site-packages\MySQLdb\connections.py", line 239, in query
    _mysql.connection.query(self, query)
MySQLdb._exceptions.IntegrityError: (1062, "Duplicate entry '1587744000' for key 'LAMProcessData_process_r_acquisition_timestamp_a69ae90c_uniq'")

The above exception was the direct cause of the following exception:

Traceback (most recent call last):
  File "D:\Program Files\Python37\lib\site-packages\apscheduler\scheduler.py", line 512, in _run_job
    retval = job.func(*job.args, **job.kwargs)
  File "E:\1-program\11-LAMDataServer\lamdataserver\LAMProcessData\views.py", line 4988, in regulartime_task
    RT_FineData.Realtime_FineData.init_Tomorrow_rows()
  File "E:\1-program\11-LAMDataServer\lamdataserver\LAMProcessData\process_realtime_finedata.py", line 193, in init_Tomorrow_rows
    _model.objects.bulk_create(insert_data_list)
  File "D:\Program Files\Python37\lib\site-packages\django\db\models\manager.py", line 82, in manager_method
    return getattr(self.get_queryset(), name)(*args, **kwargs)
  File "D:\Program Files\Python37\lib\site-packages\django\db\models\query.py", line 474, in bulk_create
    ids = self._batched_insert(objs_without_pk, fields, batch_size, ignore_conflicts=ignore_conflicts)
  File "D:\Program Files\Python37\lib\site-packages\django\db\models\query.py", line 1211, in _batched_insert
    self._insert(item, fields=fields, using=self.db, ignore_conflicts=ignore_conflicts)
  File "D:\Program Files\Python37\lib\site-packages\django\db\models\query.py", line 1186, in _insert
    return query.get_compiler(using=using).execute_sql(return_id)
  File "D:\Program Files\Python37\lib\site-packages\django\db\models\sql\compiler.py", line 1332, in execute_sql
    cursor.execute(sql, params)
  File "D:\Program Files\Python37\lib\site-packages\django\db\backends\utils.py", line 99, in execute
    return super().execute(sql, params)
  File "D:\Program Files\Python37\lib\site-packages\django\db\backends\utils.py", line 67, in execute
    return self._execute_with_wrappers(sql, params, many=False, executor=self._execute)
  File "D:\Program Files\Python37\lib\site-packages\django\db\backends\utils.py", line 76, in _execute_with_wrappers
    return executor(sql, params, many, context)
  File "D:\Program Files\Python37\lib\site-packages\django\db\backends\utils.py", line 84, in _execute
    return self.cursor.execute(sql, params)
  File "D:\Program Files\Python37\lib\site-packages\django\db\utils.py", line 89, in __exit__
    raise dj_exc_value.with_traceback(traceback) from exc_value
  File "D:\Program Files\Python37\lib\site-packages\django\db\backends\utils.py", line 84, in _execute
    return self.cursor.execute(sql, params)
  File "D:\Program Files\Python37\lib\site-packages\django\db\backends\mysql\base.py", line 71, in execute
    return self.cursor.execute(query, args)
  File "D:\Program Files\Python37\lib\site-packages\MySQLdb\cursors.py", line 209, in execute
    res = self._query(query)
  File "D:\Program Files\Python37\lib\site-packages\MySQLdb\cursors.py", line 315, in _query
    db.query(q)
  File "D:\Program Files\Python37\lib\site-packages\MySQLdb\connections.py", line 239, in query
    _mysql.connection.query(self, query)
django.db.utils.IntegrityError: (1062, "Duplicate entry '1587744000' for key 'LAMProcessData_process_r_acquisition_timestamp_a69ae90c_uniq'")
2020-04-24 00:33:13,429 - _run_jobs - 94 - DEBUG - Exiting worker thread
2020-04-24 00:40:28,801 - trigger_reload - 203 - INFO - E:\1-program\11-LAMDataServer\lamdataserver\LAMProcessData\query_views.py changed, reloading.
2020-04-24 00:40:28,803 - shutdown - 111 - INFO - Shutting down thread pool
2020-04-24 00:40:36,105 - _real_add_job - 262 - INFO - Added job "regulartime_task (trigger: interval[1 day, 0:00:00], next run at: 2020-04-24 00:40:46.103716)" to job store "default"
2020-04-24 00:40:36,106 - _real_add_job - 262 - INFO - Added job "cleanup (trigger: cron[day_of_week='*', hour='3', minute='0', second='0'], next run at: 2020-04-24 03:00:00)" to job store "default"
2020-04-24 00:40:36,106 - _real_add_job - 262 - INFO - Added job "OpenLog (trigger: cron[hour='0'], next run at: 2020-04-25 00:00:00)" to job store "default"
2020-04-24 00:40:36,107 - _main_loop - 574 - INFO - Scheduler started
2020-04-24 00:40:36,108 - _main_loop - 579 - DEBUG - Looking for jobs to run
2020-04-24 00:40:36,108 - _main_loop - 588 - DEBUG - Next wakeup is due at 2020-04-24 00:40:46.103716 (in 9.995020 seconds)
2020-04-24 00:40:36,133 - <module> - 64 - DEBUG - SendBefore_NotRecive : [<CNCProcessStatus: CNCProcessStatus object (2038721)>]
2020-04-24 00:40:36,133 - <module> - 65 - DEBUG - Waitfor_Recive : [2038721]
2020-04-24 00:40:46,118 - _main_loop - 579 - DEBUG - Looking for jobs to run
2020-04-24 00:40:46,121 - _run_jobs - 69 - DEBUG - Started worker thread
2020-04-24 00:40:46,122 - _run_job - 509 - INFO - Running job "regulartime_task (trigger: interval[1 day, 0:00:00], next run at: 2020-04-24 00:40:46.103716)" (scheduled at 2020-04-24 00:40:46.103716)
2020-04-24 00:40:46,129 - _main_loop - 588 - DEBUG - Next wakeup is due at 2020-04-24 03:00:00 (in 8353.881565 seconds)
2020-04-24 00:40:47,050 - _run_job - 520 - ERROR - Job "regulartime_task (trigger: interval[1 day, 0:00:00], next run at: 2020-04-25 00:40:46.103716)" raised an exception
Traceback (most recent call last):
  File "D:\Program Files\Python37\lib\site-packages\django\db\backends\utils.py", line 84, in _execute
    return self.cursor.execute(sql, params)
  File "D:\Program Files\Python37\lib\site-packages\django\db\backends\mysql\base.py", line 71, in execute
    return self.cursor.execute(query, args)
  File "D:\Program Files\Python37\lib\site-packages\MySQLdb\cursors.py", line 209, in execute
    res = self._query(query)
  File "D:\Program Files\Python37\lib\site-packages\MySQLdb\cursors.py", line 315, in _query
    db.query(q)
  File "D:\Program Files\Python37\lib\site-packages\MySQLdb\connections.py", line 239, in query
    _mysql.connection.query(self, query)
MySQLdb._exceptions.IntegrityError: (1062, "Duplicate entry '1587744000' for key 'LAMProcessData_process_r_acquisition_timestamp_a69ae90c_uniq'")

The above exception was the direct cause of the following exception:

Traceback (most recent call last):
  File "D:\Program Files\Python37\lib\site-packages\apscheduler\scheduler.py", line 512, in _run_job
    retval = job.func(*job.args, **job.kwargs)
  File "E:\1-program\11-LAMDataServer\lamdataserver\LAMProcessData\views.py", line 4988, in regulartime_task
    RT_FineData.Realtime_FineData.init_Tomorrow_rows()
  File "E:\1-program\11-LAMDataServer\lamdataserver\LAMProcessData\process_realtime_finedata.py", line 193, in init_Tomorrow_rows
    _model.objects.bulk_create(insert_data_list)
  File "D:\Program Files\Python37\lib\site-packages\django\db\models\manager.py", line 82, in manager_method
    return getattr(self.get_queryset(), name)(*args, **kwargs)
  File "D:\Program Files\Python37\lib\site-packages\django\db\models\query.py", line 474, in bulk_create
    ids = self._batched_insert(objs_without_pk, fields, batch_size, ignore_conflicts=ignore_conflicts)
  File "D:\Program Files\Python37\lib\site-packages\django\db\models\query.py", line 1211, in _batched_insert
    self._insert(item, fields=fields, using=self.db, ignore_conflicts=ignore_conflicts)
  File "D:\Program Files\Python37\lib\site-packages\django\db\models\query.py", line 1186, in _insert
    return query.get_compiler(using=using).execute_sql(return_id)
  File "D:\Program Files\Python37\lib\site-packages\django\db\models\sql\compiler.py", line 1332, in execute_sql
    cursor.execute(sql, params)
  File "D:\Program Files\Python37\lib\site-packages\django\db\backends\utils.py", line 99, in execute
    return super().execute(sql, params)
  File "D:\Program Files\Python37\lib\site-packages\django\db\backends\utils.py", line 67, in execute
    return self._execute_with_wrappers(sql, params, many=False, executor=self._execute)
  File "D:\Program Files\Python37\lib\site-packages\django\db\backends\utils.py", line 76, in _execute_with_wrappers
    return executor(sql, params, many, context)
  File "D:\Program Files\Python37\lib\site-packages\django\db\backends\utils.py", line 84, in _execute
    return self.cursor.execute(sql, params)
  File "D:\Program Files\Python37\lib\site-packages\django\db\utils.py", line 89, in __exit__
    raise dj_exc_value.with_traceback(traceback) from exc_value
  File "D:\Program Files\Python37\lib\site-packages\django\db\backends\utils.py", line 84, in _execute
    return self.cursor.execute(sql, params)
  File "D:\Program Files\Python37\lib\site-packages\django\db\backends\mysql\base.py", line 71, in execute
    return self.cursor.execute(query, args)
  File "D:\Program Files\Python37\lib\site-packages\MySQLdb\cursors.py", line 209, in execute
    res = self._query(query)
  File "D:\Program Files\Python37\lib\site-packages\MySQLdb\cursors.py", line 315, in _query
    db.query(q)
  File "D:\Program Files\Python37\lib\site-packages\MySQLdb\connections.py", line 239, in query
    _mysql.connection.query(self, query)
django.db.utils.IntegrityError: (1062, "Duplicate entry '1587744000' for key 'LAMProcessData_process_r_acquisition_timestamp_a69ae90c_uniq'")
2020-04-24 00:40:48,060 - _run_jobs - 94 - DEBUG - Exiting worker thread
2020-04-24 00:43:07,204 - trigger_reload - 203 - INFO - E:\1-program\11-LAMDataServer\lamdataserver\LAMProcessData\query_views.py changed, reloading.
2020-04-24 00:43:07,207 - shutdown - 111 - INFO - Shutting down thread pool
2020-04-24 00:43:10,458 - _real_add_job - 262 - INFO - Added job "regulartime_task (trigger: interval[1 day, 0:00:00], next run at: 2020-04-24 00:43:20.455755)" to job store "default"
2020-04-24 00:43:10,458 - _real_add_job - 262 - INFO - Added job "cleanup (trigger: cron[day_of_week='*', hour='3', minute='0', second='0'], next run at: 2020-04-24 03:00:00)" to job store "default"
2020-04-24 00:43:10,458 - _real_add_job - 262 - INFO - Added job "OpenLog (trigger: cron[hour='0'], next run at: 2020-04-25 00:00:00)" to job store "default"
2020-04-24 00:43:10,460 - _main_loop - 574 - INFO - Scheduler started
2020-04-24 00:43:10,460 - _main_loop - 579 - DEBUG - Looking for jobs to run
2020-04-24 00:43:10,461 - _main_loop - 588 - DEBUG - Next wakeup is due at 2020-04-24 00:43:20.455755 (in 9.994773 seconds)
2020-04-24 00:43:10,484 - <module> - 64 - DEBUG - SendBefore_NotRecive : [<CNCProcessStatus: CNCProcessStatus object (2038721)>]
2020-04-24 00:43:10,484 - <module> - 65 - DEBUG - Waitfor_Recive : [2038721]
2020-04-24 00:43:20,457 - _main_loop - 579 - DEBUG - Looking for jobs to run
2020-04-24 00:43:20,458 - _run_jobs - 69 - DEBUG - Started worker thread
2020-04-24 00:43:20,458 - _main_loop - 588 - DEBUG - Next wakeup is due at 2020-04-24 03:00:00 (in 8199.542718 seconds)
2020-04-24 00:43:20,458 - _run_job - 509 - INFO - Running job "regulartime_task (trigger: interval[1 day, 0:00:00], next run at: 2020-04-25 00:43:20.455755)" (scheduled at 2020-04-24 00:43:20.455755)
2020-04-24 00:43:21,400 - _run_job - 520 - ERROR - Job "regulartime_task (trigger: interval[1 day, 0:00:00], next run at: 2020-04-25 00:43:20.455755)" raised an exception
Traceback (most recent call last):
  File "D:\Program Files\Python37\lib\site-packages\django\db\backends\utils.py", line 84, in _execute
    return self.cursor.execute(sql, params)
  File "D:\Program Files\Python37\lib\site-packages\django\db\backends\mysql\base.py", line 71, in execute
    return self.cursor.execute(query, args)
  File "D:\Program Files\Python37\lib\site-packages\MySQLdb\cursors.py", line 209, in execute
    res = self._query(query)
  File "D:\Program Files\Python37\lib\site-packages\MySQLdb\cursors.py", line 315, in _query
    db.query(q)
  File "D:\Program Files\Python37\lib\site-packages\MySQLdb\connections.py", line 239, in query
    _mysql.connection.query(self, query)
MySQLdb._exceptions.IntegrityError: (1062, "Duplicate entry '1587744000' for key 'LAMProcessData_process_r_acquisition_timestamp_a69ae90c_uniq'")

The above exception was the direct cause of the following exception:

Traceback (most recent call last):
  File "D:\Program Files\Python37\lib\site-packages\apscheduler\scheduler.py", line 512, in _run_job
    retval = job.func(*job.args, **job.kwargs)
  File "E:\1-program\11-LAMDataServer\lamdataserver\LAMProcessData\views.py", line 4988, in regulartime_task
    RT_FineData.Realtime_FineData.init_Tomorrow_rows()
  File "E:\1-program\11-LAMDataServer\lamdataserver\LAMProcessData\process_realtime_finedata.py", line 193, in init_Tomorrow_rows
    _model.objects.bulk_create(insert_data_list)
  File "D:\Program Files\Python37\lib\site-packages\django\db\models\manager.py", line 82, in manager_method
    return getattr(self.get_queryset(), name)(*args, **kwargs)
  File "D:\Program Files\Python37\lib\site-packages\django\db\models\query.py", line 474, in bulk_create
    ids = self._batched_insert(objs_without_pk, fields, batch_size, ignore_conflicts=ignore_conflicts)
  File "D:\Program Files\Python37\lib\site-packages\django\db\models\query.py", line 1211, in _batched_insert
    self._insert(item, fields=fields, using=self.db, ignore_conflicts=ignore_conflicts)
  File "D:\Program Files\Python37\lib\site-packages\django\db\models\query.py", line 1186, in _insert
    return query.get_compiler(using=using).execute_sql(return_id)
  File "D:\Program Files\Python37\lib\site-packages\django\db\models\sql\compiler.py", line 1332, in execute_sql
    cursor.execute(sql, params)
  File "D:\Program Files\Python37\lib\site-packages\django\db\backends\utils.py", line 99, in execute
    return super().execute(sql, params)
  File "D:\Program Files\Python37\lib\site-packages\django\db\backends\utils.py", line 67, in execute
    return self._execute_with_wrappers(sql, params, many=False, executor=self._execute)
  File "D:\Program Files\Python37\lib\site-packages\django\db\backends\utils.py", line 76, in _execute_with_wrappers
    return executor(sql, params, many, context)
  File "D:\Program Files\Python37\lib\site-packages\django\db\backends\utils.py", line 84, in _execute
    return self.cursor.execute(sql, params)
  File "D:\Program Files\Python37\lib\site-packages\django\db\utils.py", line 89, in __exit__
    raise dj_exc_value.with_traceback(traceback) from exc_value
  File "D:\Program Files\Python37\lib\site-packages\django\db\backends\utils.py", line 84, in _execute
    return self.cursor.execute(sql, params)
  File "D:\Program Files\Python37\lib\site-packages\django\db\backends\mysql\base.py", line 71, in execute
    return self.cursor.execute(query, args)
  File "D:\Program Files\Python37\lib\site-packages\MySQLdb\cursors.py", line 209, in execute
    res = self._query(query)
  File "D:\Program Files\Python37\lib\site-packages\MySQLdb\cursors.py", line 315, in _query
    db.query(q)
  File "D:\Program Files\Python37\lib\site-packages\MySQLdb\connections.py", line 239, in query
    _mysql.connection.query(self, query)
django.db.utils.IntegrityError: (1062, "Duplicate entry '1587744000' for key 'LAMProcessData_process_r_acquisition_timestamp_a69ae90c_uniq'")
2020-04-24 00:43:22,408 - _run_jobs - 94 - DEBUG - Exiting worker thread
2020-04-24 00:43:43,770 - trigger_reload - 203 - INFO - E:\1-program\11-LAMDataServer\lamdataserver\LAMProcessData\query_views.py changed, reloading.
2020-04-24 00:43:43,772 - shutdown - 111 - INFO - Shutting down thread pool
2020-04-24 00:43:46,980 - _real_add_job - 262 - INFO - Added job "regulartime_task (trigger: interval[1 day, 0:00:00], next run at: 2020-04-24 00:43:56.978658)" to job store "default"
2020-04-24 00:43:46,981 - _real_add_job - 262 - INFO - Added job "cleanup (trigger: cron[day_of_week='*', hour='3', minute='0', second='0'], next run at: 2020-04-24 03:00:00)" to job store "default"
2020-04-24 00:43:46,981 - _real_add_job - 262 - INFO - Added job "OpenLog (trigger: cron[hour='0'], next run at: 2020-04-25 00:00:00)" to job store "default"
2020-04-24 00:43:46,982 - _main_loop - 574 - INFO - Scheduler started
2020-04-24 00:43:46,982 - _main_loop - 579 - DEBUG - Looking for jobs to run
2020-04-24 00:43:46,982 - _main_loop - 588 - DEBUG - Next wakeup is due at 2020-04-24 00:43:56.978658 (in 9.996053 seconds)
2020-04-24 00:43:47,005 - <module> - 64 - DEBUG - SendBefore_NotRecive : [<CNCProcessStatus: CNCProcessStatus object (2038721)>]
2020-04-24 00:43:47,005 - <module> - 65 - DEBUG - Waitfor_Recive : [2038721]
2020-04-24 00:43:56,981 - _main_loop - 579 - DEBUG - Looking for jobs to run
2020-04-24 00:43:56,984 - _run_jobs - 69 - DEBUG - Started worker thread
2020-04-24 00:43:56,985 - _run_job - 509 - INFO - Running job "regulartime_task (trigger: interval[1 day, 0:00:00], next run at: 2020-04-24 00:43:56.978658)" (scheduled at 2020-04-24 00:43:56.978658)
2020-04-24 00:43:56,987 - _main_loop - 588 - DEBUG - Next wakeup is due at 2020-04-24 03:00:00 (in 8163.018030 seconds)
2020-04-24 00:43:57,936 - _run_job - 520 - ERROR - Job "regulartime_task (trigger: interval[1 day, 0:00:00], next run at: 2020-04-25 00:43:56.978658)" raised an exception
Traceback (most recent call last):
  File "D:\Program Files\Python37\lib\site-packages\django\db\backends\utils.py", line 84, in _execute
    return self.cursor.execute(sql, params)
  File "D:\Program Files\Python37\lib\site-packages\django\db\backends\mysql\base.py", line 71, in execute
    return self.cursor.execute(query, args)
  File "D:\Program Files\Python37\lib\site-packages\MySQLdb\cursors.py", line 209, in execute
    res = self._query(query)
  File "D:\Program Files\Python37\lib\site-packages\MySQLdb\cursors.py", line 315, in _query
    db.query(q)
  File "D:\Program Files\Python37\lib\site-packages\MySQLdb\connections.py", line 239, in query
    _mysql.connection.query(self, query)
MySQLdb._exceptions.IntegrityError: (1062, "Duplicate entry '1587744000' for key 'LAMProcessData_process_r_acquisition_timestamp_a69ae90c_uniq'")

The above exception was the direct cause of the following exception:

Traceback (most recent call last):
  File "D:\Program Files\Python37\lib\site-packages\apscheduler\scheduler.py", line 512, in _run_job
    retval = job.func(*job.args, **job.kwargs)
  File "E:\1-program\11-LAMDataServer\lamdataserver\LAMProcessData\views.py", line 4988, in regulartime_task
    RT_FineData.Realtime_FineData.init_Tomorrow_rows()
  File "E:\1-program\11-LAMDataServer\lamdataserver\LAMProcessData\process_realtime_finedata.py", line 193, in init_Tomorrow_rows
    _model.objects.bulk_create(insert_data_list)
  File "D:\Program Files\Python37\lib\site-packages\django\db\models\manager.py", line 82, in manager_method
    return getattr(self.get_queryset(), name)(*args, **kwargs)
  File "D:\Program Files\Python37\lib\site-packages\django\db\models\query.py", line 474, in bulk_create
    ids = self._batched_insert(objs_without_pk, fields, batch_size, ignore_conflicts=ignore_conflicts)
  File "D:\Program Files\Python37\lib\site-packages\django\db\models\query.py", line 1211, in _batched_insert
    self._insert(item, fields=fields, using=self.db, ignore_conflicts=ignore_conflicts)
  File "D:\Program Files\Python37\lib\site-packages\django\db\models\query.py", line 1186, in _insert
    return query.get_compiler(using=using).execute_sql(return_id)
  File "D:\Program Files\Python37\lib\site-packages\django\db\models\sql\compiler.py", line 1332, in execute_sql
    cursor.execute(sql, params)
  File "D:\Program Files\Python37\lib\site-packages\django\db\backends\utils.py", line 99, in execute
    return super().execute(sql, params)
  File "D:\Program Files\Python37\lib\site-packages\django\db\backends\utils.py", line 67, in execute
    return self._execute_with_wrappers(sql, params, many=False, executor=self._execute)
  File "D:\Program Files\Python37\lib\site-packages\django\db\backends\utils.py", line 76, in _execute_with_wrappers
    return executor(sql, params, many, context)
  File "D:\Program Files\Python37\lib\site-packages\django\db\backends\utils.py", line 84, in _execute
    return self.cursor.execute(sql, params)
  File "D:\Program Files\Python37\lib\site-packages\django\db\utils.py", line 89, in __exit__
    raise dj_exc_value.with_traceback(traceback) from exc_value
  File "D:\Program Files\Python37\lib\site-packages\django\db\backends\utils.py", line 84, in _execute
    return self.cursor.execute(sql, params)
  File "D:\Program Files\Python37\lib\site-packages\django\db\backends\mysql\base.py", line 71, in execute
    return self.cursor.execute(query, args)
  File "D:\Program Files\Python37\lib\site-packages\MySQLdb\cursors.py", line 209, in execute
    res = self._query(query)
  File "D:\Program Files\Python37\lib\site-packages\MySQLdb\cursors.py", line 315, in _query
    db.query(q)
  File "D:\Program Files\Python37\lib\site-packages\MySQLdb\connections.py", line 239, in query
    _mysql.connection.query(self, query)
django.db.utils.IntegrityError: (1062, "Duplicate entry '1587744000' for key 'LAMProcessData_process_r_acquisition_timestamp_a69ae90c_uniq'")
2020-04-24 00:43:58,946 - _run_jobs - 94 - DEBUG - Exiting worker thread
2020-04-24 00:45:36,757 - _real_add_job - 262 - INFO - Added job "regulartime_task (trigger: interval[1 day, 0:00:00], next run at: 2020-04-24 00:45:46.757027)" to job store "default"
2020-04-24 00:45:36,757 - _real_add_job - 262 - INFO - Added job "cleanup (trigger: cron[day_of_week='*', hour='3', minute='0', second='0'], next run at: 2020-04-24 03:00:00)" to job store "default"
2020-04-24 00:45:36,757 - _real_add_job - 262 - INFO - Added job "OpenLog (trigger: cron[hour='0'], next run at: 2020-04-25 00:00:00)" to job store "default"
2020-04-24 00:45:36,759 - _main_loop - 574 - INFO - Scheduler started
2020-04-24 00:45:36,759 - _main_loop - 579 - DEBUG - Looking for jobs to run
2020-04-24 00:45:36,759 - _main_loop - 588 - DEBUG - Next wakeup is due at 2020-04-24 00:45:46.757027 (in 9.998009 seconds)
2020-04-24 00:45:36,781 - <module> - 63 - DEBUG - SendBefore_NotRecive : [<CNCProcessStatus: CNCProcessStatus object (2038721)>]
2020-04-24 00:45:36,781 - <module> - 64 - DEBUG - Waitfor_Recive : [2038721]
2020-04-24 00:45:46,758 - _main_loop - 579 - DEBUG - Looking for jobs to run
2020-04-24 00:45:46,759 - _run_jobs - 69 - DEBUG - Started worker thread
2020-04-24 00:45:46,760 - _run_job - 509 - INFO - Running job "regulartime_task (trigger: interval[1 day, 0:00:00], next run at: 2020-04-24 00:45:46.757027)" (scheduled at 2020-04-24 00:45:46.757027)
2020-04-24 00:45:46,765 - _main_loop - 588 - DEBUG - Next wakeup is due at 2020-04-24 03:00:00 (in 8053.241929 seconds)
2020-04-24 00:45:47,109 - _run_job - 520 - ERROR - Job "regulartime_task (trigger: interval[1 day, 0:00:00], next run at: 2020-04-25 00:45:46.757027)" raised an exception
Traceback (most recent call last):
  File "D:\Program Files\Python37\lib\site-packages\django\db\backends\utils.py", line 84, in _execute
    return self.cursor.execute(sql, params)
  File "D:\Program Files\Python37\lib\site-packages\django\db\backends\mysql\base.py", line 71, in execute
    return self.cursor.execute(query, args)
  File "D:\Program Files\Python37\lib\site-packages\MySQLdb\cursors.py", line 209, in execute
    res = self._query(query)
  File "D:\Program Files\Python37\lib\site-packages\MySQLdb\cursors.py", line 315, in _query
    db.query(q)
  File "D:\Program Files\Python37\lib\site-packages\MySQLdb\connections.py", line 239, in query
    _mysql.connection.query(self, query)
MySQLdb._exceptions.IntegrityError: (1062, "Duplicate entry '1587744000' for key 'LAMProcessData_process_r_acquisition_timestamp_a69ae90c_uniq'")

The above exception was the direct cause of the following exception:

Traceback (most recent call last):
  File "D:\Program Files\Python37\lib\site-packages\apscheduler\scheduler.py", line 512, in _run_job
    retval = job.func(*job.args, **job.kwargs)
  File "E:\1-program\11-LAMDataServer\lamdataserver\LAMProcessData\views.py", line 4988, in regulartime_task
    RT_FineData.Realtime_FineData.init_Tomorrow_rows()
  File "E:\1-program\11-LAMDataServer\lamdataserver\LAMProcessData\process_realtime_finedata.py", line 193, in init_Tomorrow_rows
    _model.objects.bulk_create(insert_data_list)
  File "D:\Program Files\Python37\lib\site-packages\django\db\models\manager.py", line 82, in manager_method
    return getattr(self.get_queryset(), name)(*args, **kwargs)
  File "D:\Program Files\Python37\lib\site-packages\django\db\models\query.py", line 474, in bulk_create
    ids = self._batched_insert(objs_without_pk, fields, batch_size, ignore_conflicts=ignore_conflicts)
  File "D:\Program Files\Python37\lib\site-packages\django\db\models\query.py", line 1211, in _batched_insert
    self._insert(item, fields=fields, using=self.db, ignore_conflicts=ignore_conflicts)
  File "D:\Program Files\Python37\lib\site-packages\django\db\models\query.py", line 1186, in _insert
    return query.get_compiler(using=using).execute_sql(return_id)
  File "D:\Program Files\Python37\lib\site-packages\django\db\models\sql\compiler.py", line 1332, in execute_sql
    cursor.execute(sql, params)
  File "D:\Program Files\Python37\lib\site-packages\django\db\backends\utils.py", line 99, in execute
    return super().execute(sql, params)
  File "D:\Program Files\Python37\lib\site-packages\django\db\backends\utils.py", line 67, in execute
    return self._execute_with_wrappers(sql, params, many=False, executor=self._execute)
  File "D:\Program Files\Python37\lib\site-packages\django\db\backends\utils.py", line 76, in _execute_with_wrappers
    return executor(sql, params, many, context)
  File "D:\Program Files\Python37\lib\site-packages\django\db\backends\utils.py", line 84, in _execute
    return self.cursor.execute(sql, params)
  File "D:\Program Files\Python37\lib\site-packages\django\db\utils.py", line 89, in __exit__
    raise dj_exc_value.with_traceback(traceback) from exc_value
  File "D:\Program Files\Python37\lib\site-packages\django\db\backends\utils.py", line 84, in _execute
    return self.cursor.execute(sql, params)
  File "D:\Program Files\Python37\lib\site-packages\django\db\backends\mysql\base.py", line 71, in execute
    return self.cursor.execute(query, args)
  File "D:\Program Files\Python37\lib\site-packages\MySQLdb\cursors.py", line 209, in execute
    res = self._query(query)
  File "D:\Program Files\Python37\lib\site-packages\MySQLdb\cursors.py", line 315, in _query
    db.query(q)
  File "D:\Program Files\Python37\lib\site-packages\MySQLdb\connections.py", line 239, in query
    _mysql.connection.query(self, query)
django.db.utils.IntegrityError: (1062, "Duplicate entry '1587744000' for key 'LAMProcessData_process_r_acquisition_timestamp_a69ae90c_uniq'")
2020-04-24 00:45:48,126 - _run_jobs - 94 - DEBUG - Exiting worker thread
2020-04-24 00:49:28,729 - trigger_reload - 203 - INFO - E:\1-program\11-LAMDataServer\lamdataserver\LAMProcessData\query_views.py changed, reloading.
2020-04-24 00:49:28,729 - shutdown - 111 - INFO - Shutting down thread pool
2020-04-24 00:49:31,173 - _real_add_job - 262 - INFO - Added job "regulartime_task (trigger: interval[1 day, 0:00:00], next run at: 2020-04-24 00:49:41.172527)" to job store "default"
2020-04-24 00:49:31,174 - _real_add_job - 262 - INFO - Added job "cleanup (trigger: cron[day_of_week='*', hour='3', minute='0', second='0'], next run at: 2020-04-24 03:00:00)" to job store "default"
2020-04-24 00:49:31,174 - _real_add_job - 262 - INFO - Added job "OpenLog (trigger: cron[hour='0'], next run at: 2020-04-25 00:00:00)" to job store "default"
2020-04-24 00:49:31,175 - _main_loop - 574 - INFO - Scheduler started
2020-04-24 00:49:31,175 - _main_loop - 579 - DEBUG - Looking for jobs to run
2020-04-24 00:49:31,175 - _main_loop - 588 - DEBUG - Next wakeup is due at 2020-04-24 00:49:41.172527 (in 9.997518 seconds)
2020-04-24 00:49:31,194 - <module> - 63 - DEBUG - SendBefore_NotRecive : [<CNCProcessStatus: CNCProcessStatus object (2038721)>]
2020-04-24 00:49:31,194 - <module> - 64 - DEBUG - Waitfor_Recive : [2038721]
2020-04-24 00:49:41,173 - _main_loop - 579 - DEBUG - Looking for jobs to run
2020-04-24 00:49:41,175 - _run_jobs - 69 - DEBUG - Started worker thread
2020-04-24 00:49:41,176 - _run_job - 509 - INFO - Running job "regulartime_task (trigger: interval[1 day, 0:00:00], next run at: 2020-04-24 00:49:41.172527)" (scheduled at 2020-04-24 00:49:41.172527)
2020-04-24 00:49:41,177 - _main_loop - 588 - DEBUG - Next wakeup is due at 2020-04-24 03:00:00 (in 7818.825855 seconds)
2020-04-24 00:49:41,505 - _run_job - 520 - ERROR - Job "regulartime_task (trigger: interval[1 day, 0:00:00], next run at: 2020-04-25 00:49:41.172527)" raised an exception
Traceback (most recent call last):
  File "D:\Program Files\Python37\lib\site-packages\django\db\backends\utils.py", line 84, in _execute
    return self.cursor.execute(sql, params)
  File "D:\Program Files\Python37\lib\site-packages\django\db\backends\mysql\base.py", line 71, in execute
    return self.cursor.execute(query, args)
  File "D:\Program Files\Python37\lib\site-packages\MySQLdb\cursors.py", line 209, in execute
    res = self._query(query)
  File "D:\Program Files\Python37\lib\site-packages\MySQLdb\cursors.py", line 315, in _query
    db.query(q)
  File "D:\Program Files\Python37\lib\site-packages\MySQLdb\connections.py", line 239, in query
    _mysql.connection.query(self, query)
MySQLdb._exceptions.IntegrityError: (1062, "Duplicate entry '1587744000' for key 'LAMProcessData_process_r_acquisition_timestamp_a69ae90c_uniq'")

The above exception was the direct cause of the following exception:

Traceback (most recent call last):
  File "D:\Program Files\Python37\lib\site-packages\apscheduler\scheduler.py", line 512, in _run_job
    retval = job.func(*job.args, **job.kwargs)
  File "E:\1-program\11-LAMDataServer\lamdataserver\LAMProcessData\views.py", line 4988, in regulartime_task
    RT_FineData.Realtime_FineData.init_Tomorrow_rows()
  File "E:\1-program\11-LAMDataServer\lamdataserver\LAMProcessData\process_realtime_finedata.py", line 193, in init_Tomorrow_rows
    _model.objects.bulk_create(insert_data_list)
  File "D:\Program Files\Python37\lib\site-packages\django\db\models\manager.py", line 82, in manager_method
    return getattr(self.get_queryset(), name)(*args, **kwargs)
  File "D:\Program Files\Python37\lib\site-packages\django\db\models\query.py", line 474, in bulk_create
    ids = self._batched_insert(objs_without_pk, fields, batch_size, ignore_conflicts=ignore_conflicts)
  File "D:\Program Files\Python37\lib\site-packages\django\db\models\query.py", line 1211, in _batched_insert
    self._insert(item, fields=fields, using=self.db, ignore_conflicts=ignore_conflicts)
  File "D:\Program Files\Python37\lib\site-packages\django\db\models\query.py", line 1186, in _insert
    return query.get_compiler(using=using).execute_sql(return_id)
  File "D:\Program Files\Python37\lib\site-packages\django\db\models\sql\compiler.py", line 1332, in execute_sql
    cursor.execute(sql, params)
  File "D:\Program Files\Python37\lib\site-packages\django\db\backends\utils.py", line 99, in execute
    return super().execute(sql, params)
  File "D:\Program Files\Python37\lib\site-packages\django\db\backends\utils.py", line 67, in execute
    return self._execute_with_wrappers(sql, params, many=False, executor=self._execute)
  File "D:\Program Files\Python37\lib\site-packages\django\db\backends\utils.py", line 76, in _execute_with_wrappers
    return executor(sql, params, many, context)
  File "D:\Program Files\Python37\lib\site-packages\django\db\backends\utils.py", line 84, in _execute
    return self.cursor.execute(sql, params)
  File "D:\Program Files\Python37\lib\site-packages\django\db\utils.py", line 89, in __exit__
    raise dj_exc_value.with_traceback(traceback) from exc_value
  File "D:\Program Files\Python37\lib\site-packages\django\db\backends\utils.py", line 84, in _execute
    return self.cursor.execute(sql, params)
  File "D:\Program Files\Python37\lib\site-packages\django\db\backends\mysql\base.py", line 71, in execute
    return self.cursor.execute(query, args)
  File "D:\Program Files\Python37\lib\site-packages\MySQLdb\cursors.py", line 209, in execute
    res = self._query(query)
  File "D:\Program Files\Python37\lib\site-packages\MySQLdb\cursors.py", line 315, in _query
    db.query(q)
  File "D:\Program Files\Python37\lib\site-packages\MySQLdb\connections.py", line 239, in query
    _mysql.connection.query(self, query)
django.db.utils.IntegrityError: (1062, "Duplicate entry '1587744000' for key 'LAMProcessData_process_r_acquisition_timestamp_a69ae90c_uniq'")
2020-04-24 00:49:42,512 - _run_jobs - 94 - DEBUG - Exiting worker thread
2020-04-24 00:50:01,865 - _real_add_job - 262 - INFO - Added job "regulartime_task (trigger: interval[1 day, 0:00:00], next run at: 2020-04-24 00:50:11.864699)" to job store "default"
2020-04-24 00:50:01,866 - _real_add_job - 262 - INFO - Added job "cleanup (trigger: cron[day_of_week='*', hour='3', minute='0', second='0'], next run at: 2020-04-24 03:00:00)" to job store "default"
2020-04-24 00:50:01,866 - _real_add_job - 262 - INFO - Added job "OpenLog (trigger: cron[hour='0'], next run at: 2020-04-25 00:00:00)" to job store "default"
2020-04-24 00:50:01,866 - _main_loop - 574 - INFO - Scheduler started
2020-04-24 00:50:01,866 - _main_loop - 579 - DEBUG - Looking for jobs to run
2020-04-24 00:50:01,867 - _main_loop - 588 - DEBUG - Next wakeup is due at 2020-04-24 00:50:11.864699 (in 9.997040 seconds)
2020-04-24 00:50:01,879 - <module> - 63 - DEBUG - SendBefore_NotRecive : [<CNCProcessStatus: CNCProcessStatus object (2038721)>]
2020-04-24 00:50:01,879 - <module> - 64 - DEBUG - Waitfor_Recive : [2038721]
2020-04-24 00:50:11,865 - _main_loop - 579 - DEBUG - Looking for jobs to run
2020-04-24 00:50:11,866 - _run_jobs - 69 - DEBUG - Started worker thread
2020-04-24 00:50:11,866 - _run_job - 509 - INFO - Running job "regulartime_task (trigger: interval[1 day, 0:00:00], next run at: 2020-04-24 00:50:11.864699)" (scheduled at 2020-04-24 00:50:11.864699)
2020-04-24 00:50:11,871 - _main_loop - 588 - DEBUG - Next wakeup is due at 2020-04-24 03:00:00 (in 7788.134078 seconds)
2020-04-24 00:50:12,181 - _run_job - 520 - ERROR - Job "regulartime_task (trigger: interval[1 day, 0:00:00], next run at: 2020-04-25 00:50:11.864699)" raised an exception
Traceback (most recent call last):
  File "D:\Program Files\Python37\lib\site-packages\django\db\backends\utils.py", line 84, in _execute
    return self.cursor.execute(sql, params)
  File "D:\Program Files\Python37\lib\site-packages\django\db\backends\mysql\base.py", line 71, in execute
    return self.cursor.execute(query, args)
  File "D:\Program Files\Python37\lib\site-packages\MySQLdb\cursors.py", line 209, in execute
    res = self._query(query)
  File "D:\Program Files\Python37\lib\site-packages\MySQLdb\cursors.py", line 315, in _query
    db.query(q)
  File "D:\Program Files\Python37\lib\site-packages\MySQLdb\connections.py", line 239, in query
    _mysql.connection.query(self, query)
MySQLdb._exceptions.IntegrityError: (1062, "Duplicate entry '1587744000' for key 'LAMProcessData_process_r_acquisition_timestamp_a69ae90c_uniq'")

The above exception was the direct cause of the following exception:

Traceback (most recent call last):
  File "D:\Program Files\Python37\lib\site-packages\apscheduler\scheduler.py", line 512, in _run_job
    retval = job.func(*job.args, **job.kwargs)
  File "E:\1-program\11-LAMDataServer\lamdataserver\LAMProcessData\views.py", line 4988, in regulartime_task
    RT_FineData.Realtime_FineData.init_Tomorrow_rows()
  File "E:\1-program\11-LAMDataServer\lamdataserver\LAMProcessData\process_realtime_finedata.py", line 193, in init_Tomorrow_rows
    _model.objects.bulk_create(insert_data_list)
  File "D:\Program Files\Python37\lib\site-packages\django\db\models\manager.py", line 82, in manager_method
    return getattr(self.get_queryset(), name)(*args, **kwargs)
  File "D:\Program Files\Python37\lib\site-packages\django\db\models\query.py", line 474, in bulk_create
    ids = self._batched_insert(objs_without_pk, fields, batch_size, ignore_conflicts=ignore_conflicts)
  File "D:\Program Files\Python37\lib\site-packages\django\db\models\query.py", line 1211, in _batched_insert
    self._insert(item, fields=fields, using=self.db, ignore_conflicts=ignore_conflicts)
  File "D:\Program Files\Python37\lib\site-packages\django\db\models\query.py", line 1186, in _insert
    return query.get_compiler(using=using).execute_sql(return_id)
  File "D:\Program Files\Python37\lib\site-packages\django\db\models\sql\compiler.py", line 1332, in execute_sql
    cursor.execute(sql, params)
  File "D:\Program Files\Python37\lib\site-packages\django\db\backends\utils.py", line 99, in execute
    return super().execute(sql, params)
  File "D:\Program Files\Python37\lib\site-packages\django\db\backends\utils.py", line 67, in execute
    return self._execute_with_wrappers(sql, params, many=False, executor=self._execute)
  File "D:\Program Files\Python37\lib\site-packages\django\db\backends\utils.py", line 76, in _execute_with_wrappers
    return executor(sql, params, many, context)
  File "D:\Program Files\Python37\lib\site-packages\django\db\backends\utils.py", line 84, in _execute
    return self.cursor.execute(sql, params)
  File "D:\Program Files\Python37\lib\site-packages\django\db\utils.py", line 89, in __exit__
    raise dj_exc_value.with_traceback(traceback) from exc_value
  File "D:\Program Files\Python37\lib\site-packages\django\db\backends\utils.py", line 84, in _execute
    return self.cursor.execute(sql, params)
  File "D:\Program Files\Python37\lib\site-packages\django\db\backends\mysql\base.py", line 71, in execute
    return self.cursor.execute(query, args)
  File "D:\Program Files\Python37\lib\site-packages\MySQLdb\cursors.py", line 209, in execute
    res = self._query(query)
  File "D:\Program Files\Python37\lib\site-packages\MySQLdb\cursors.py", line 315, in _query
    db.query(q)
  File "D:\Program Files\Python37\lib\site-packages\MySQLdb\connections.py", line 239, in query
    _mysql.connection.query(self, query)
django.db.utils.IntegrityError: (1062, "Duplicate entry '1587744000' for key 'LAMProcessData_process_r_acquisition_timestamp_a69ae90c_uniq'")
2020-04-24 00:50:13,187 - _run_jobs - 94 - DEBUG - Exiting worker thread
2020-04-24 00:51:21,063 - trigger_reload - 203 - INFO - E:\1-program\11-LAMDataServer\lamdataserver\LAMProcessData\query_views.py changed, reloading.
2020-04-24 00:51:21,064 - shutdown - 111 - INFO - Shutting down thread pool
2020-04-24 00:51:25,070 - _real_add_job - 262 - INFO - Added job "regulartime_task (trigger: interval[1 day, 0:00:00], next run at: 2020-04-24 00:51:35.069277)" to job store "default"
2020-04-24 00:51:25,070 - _real_add_job - 262 - INFO - Added job "cleanup (trigger: cron[day_of_week='*', hour='3', minute='0', second='0'], next run at: 2020-04-24 03:00:00)" to job store "default"
2020-04-24 00:51:25,070 - _real_add_job - 262 - INFO - Added job "OpenLog (trigger: cron[hour='0'], next run at: 2020-04-25 00:00:00)" to job store "default"
2020-04-24 00:51:25,071 - _main_loop - 574 - INFO - Scheduler started
2020-04-24 00:51:25,071 - _main_loop - 579 - DEBUG - Looking for jobs to run
2020-04-24 00:51:25,071 - _main_loop - 588 - DEBUG - Next wakeup is due at 2020-04-24 00:51:35.069277 (in 9.998004 seconds)
2020-04-24 00:51:25,093 - <module> - 63 - DEBUG - SendBefore_NotRecive : [<CNCProcessStatus: CNCProcessStatus object (2038721)>]
2020-04-24 00:51:25,093 - <module> - 64 - DEBUG - Waitfor_Recive : [2038721]
2020-04-24 00:51:35,071 - _main_loop - 579 - DEBUG - Looking for jobs to run
2020-04-24 00:51:35,071 - _run_jobs - 69 - DEBUG - Started worker thread
2020-04-24 00:51:35,072 - _run_job - 509 - INFO - Running job "regulartime_task (trigger: interval[1 day, 0:00:00], next run at: 2020-04-24 00:51:35.069277)" (scheduled at 2020-04-24 00:51:35.069277)
2020-04-24 00:51:35,078 - _main_loop - 588 - DEBUG - Next wakeup is due at 2020-04-24 03:00:00 (in 7704.928828 seconds)
2020-04-24 00:51:35,389 - _run_job - 520 - ERROR - Job "regulartime_task (trigger: interval[1 day, 0:00:00], next run at: 2020-04-25 00:51:35.069277)" raised an exception
Traceback (most recent call last):
  File "D:\Program Files\Python37\lib\site-packages\django\db\backends\utils.py", line 84, in _execute
    return self.cursor.execute(sql, params)
  File "D:\Program Files\Python37\lib\site-packages\django\db\backends\mysql\base.py", line 71, in execute
    return self.cursor.execute(query, args)
  File "D:\Program Files\Python37\lib\site-packages\MySQLdb\cursors.py", line 209, in execute
    res = self._query(query)
  File "D:\Program Files\Python37\lib\site-packages\MySQLdb\cursors.py", line 315, in _query
    db.query(q)
  File "D:\Program Files\Python37\lib\site-packages\MySQLdb\connections.py", line 239, in query
    _mysql.connection.query(self, query)
MySQLdb._exceptions.IntegrityError: (1062, "Duplicate entry '1587744000' for key 'LAMProcessData_process_r_acquisition_timestamp_a69ae90c_uniq'")

The above exception was the direct cause of the following exception:

Traceback (most recent call last):
  File "D:\Program Files\Python37\lib\site-packages\apscheduler\scheduler.py", line 512, in _run_job
    retval = job.func(*job.args, **job.kwargs)
  File "E:\1-program\11-LAMDataServer\lamdataserver\LAMProcessData\views.py", line 4988, in regulartime_task
    RT_FineData.Realtime_FineData.init_Tomorrow_rows()
  File "E:\1-program\11-LAMDataServer\lamdataserver\LAMProcessData\process_realtime_finedata.py", line 193, in init_Tomorrow_rows
    _model.objects.bulk_create(insert_data_list)
  File "D:\Program Files\Python37\lib\site-packages\django\db\models\manager.py", line 82, in manager_method
    return getattr(self.get_queryset(), name)(*args, **kwargs)
  File "D:\Program Files\Python37\lib\site-packages\django\db\models\query.py", line 474, in bulk_create
    ids = self._batched_insert(objs_without_pk, fields, batch_size, ignore_conflicts=ignore_conflicts)
  File "D:\Program Files\Python37\lib\site-packages\django\db\models\query.py", line 1211, in _batched_insert
    self._insert(item, fields=fields, using=self.db, ignore_conflicts=ignore_conflicts)
  File "D:\Program Files\Python37\lib\site-packages\django\db\models\query.py", line 1186, in _insert
    return query.get_compiler(using=using).execute_sql(return_id)
  File "D:\Program Files\Python37\lib\site-packages\django\db\models\sql\compiler.py", line 1332, in execute_sql
    cursor.execute(sql, params)
  File "D:\Program Files\Python37\lib\site-packages\django\db\backends\utils.py", line 99, in execute
    return super().execute(sql, params)
  File "D:\Program Files\Python37\lib\site-packages\django\db\backends\utils.py", line 67, in execute
    return self._execute_with_wrappers(sql, params, many=False, executor=self._execute)
  File "D:\Program Files\Python37\lib\site-packages\django\db\backends\utils.py", line 76, in _execute_with_wrappers
    return executor(sql, params, many, context)
  File "D:\Program Files\Python37\lib\site-packages\django\db\backends\utils.py", line 84, in _execute
    return self.cursor.execute(sql, params)
  File "D:\Program Files\Python37\lib\site-packages\django\db\utils.py", line 89, in __exit__
    raise dj_exc_value.with_traceback(traceback) from exc_value
  File "D:\Program Files\Python37\lib\site-packages\django\db\backends\utils.py", line 84, in _execute
    return self.cursor.execute(sql, params)
  File "D:\Program Files\Python37\lib\site-packages\django\db\backends\mysql\base.py", line 71, in execute
    return self.cursor.execute(query, args)
  File "D:\Program Files\Python37\lib\site-packages\MySQLdb\cursors.py", line 209, in execute
    res = self._query(query)
  File "D:\Program Files\Python37\lib\site-packages\MySQLdb\cursors.py", line 315, in _query
    db.query(q)
  File "D:\Program Files\Python37\lib\site-packages\MySQLdb\connections.py", line 239, in query
    _mysql.connection.query(self, query)
django.db.utils.IntegrityError: (1062, "Duplicate entry '1587744000' for key 'LAMProcessData_process_r_acquisition_timestamp_a69ae90c_uniq'")
2020-04-24 00:51:36,396 - _run_jobs - 94 - DEBUG - Exiting worker thread
2020-04-24 01:01:59,805 - _real_add_job - 262 - INFO - Added job "regulartime_task (trigger: interval[1 day, 0:00:00], next run at: 2020-04-24 01:02:09.804657)" to job store "default"
2020-04-24 01:01:59,806 - _real_add_job - 262 - INFO - Added job "cleanup (trigger: cron[day_of_week='*', hour='3', minute='0', second='0'], next run at: 2020-04-24 03:00:00)" to job store "default"
2020-04-24 01:01:59,806 - _real_add_job - 262 - INFO - Added job "OpenLog (trigger: cron[hour='0'], next run at: 2020-04-25 00:00:00)" to job store "default"
2020-04-24 01:01:59,806 - _main_loop - 574 - INFO - Scheduler started
2020-04-24 01:01:59,806 - _main_loop - 579 - DEBUG - Looking for jobs to run
2020-04-24 01:01:59,807 - _main_loop - 588 - DEBUG - Next wakeup is due at 2020-04-24 01:02:09.804657 (in 9.997010 seconds)
2020-04-24 01:01:59,818 - <module> - 63 - DEBUG - SendBefore_NotRecive : [<CNCProcessStatus: CNCProcessStatus object (2038721)>]
2020-04-24 01:01:59,818 - <module> - 64 - DEBUG - Waitfor_Recive : [2038721]
2020-04-24 01:02:09,806 - _main_loop - 579 - DEBUG - Looking for jobs to run
2020-04-24 01:02:09,807 - _run_jobs - 69 - DEBUG - Started worker thread
2020-04-24 01:02:09,807 - _run_job - 509 - INFO - Running job "regulartime_task (trigger: interval[1 day, 0:00:00], next run at: 2020-04-24 01:02:09.804657)" (scheduled at 2020-04-24 01:02:09.804657)
2020-04-24 01:02:09,808 - _main_loop - 588 - DEBUG - Next wakeup is due at 2020-04-24 03:00:00 (in 7070.193669 seconds)
2020-04-24 01:02:10,122 - _run_job - 520 - ERROR - Job "regulartime_task (trigger: interval[1 day, 0:00:00], next run at: 2020-04-25 01:02:09.804657)" raised an exception
Traceback (most recent call last):
  File "D:\Program Files\Python37\lib\site-packages\django\db\backends\utils.py", line 84, in _execute
    return self.cursor.execute(sql, params)
  File "D:\Program Files\Python37\lib\site-packages\django\db\backends\mysql\base.py", line 71, in execute
    return self.cursor.execute(query, args)
  File "D:\Program Files\Python37\lib\site-packages\MySQLdb\cursors.py", line 209, in execute
    res = self._query(query)
  File "D:\Program Files\Python37\lib\site-packages\MySQLdb\cursors.py", line 315, in _query
    db.query(q)
  File "D:\Program Files\Python37\lib\site-packages\MySQLdb\connections.py", line 239, in query
    _mysql.connection.query(self, query)
MySQLdb._exceptions.IntegrityError: (1062, "Duplicate entry '1587744000' for key 'LAMProcessData_process_r_acquisition_timestamp_a69ae90c_uniq'")

The above exception was the direct cause of the following exception:

Traceback (most recent call last):
  File "D:\Program Files\Python37\lib\site-packages\apscheduler\scheduler.py", line 512, in _run_job
    retval = job.func(*job.args, **job.kwargs)
  File "E:\1-program\11-LAMDataServer\lamdataserver\LAMProcessData\views.py", line 4988, in regulartime_task
    RT_FineData.Realtime_FineData.init_Tomorrow_rows()
  File "E:\1-program\11-LAMDataServer\lamdataserver\LAMProcessData\process_realtime_finedata.py", line 193, in init_Tomorrow_rows
    _model.objects.bulk_create(insert_data_list)
  File "D:\Program Files\Python37\lib\site-packages\django\db\models\manager.py", line 82, in manager_method
    return getattr(self.get_queryset(), name)(*args, **kwargs)
  File "D:\Program Files\Python37\lib\site-packages\django\db\models\query.py", line 474, in bulk_create
    ids = self._batched_insert(objs_without_pk, fields, batch_size, ignore_conflicts=ignore_conflicts)
  File "D:\Program Files\Python37\lib\site-packages\django\db\models\query.py", line 1211, in _batched_insert
    self._insert(item, fields=fields, using=self.db, ignore_conflicts=ignore_conflicts)
  File "D:\Program Files\Python37\lib\site-packages\django\db\models\query.py", line 1186, in _insert
    return query.get_compiler(using=using).execute_sql(return_id)
  File "D:\Program Files\Python37\lib\site-packages\django\db\models\sql\compiler.py", line 1332, in execute_sql
    cursor.execute(sql, params)
  File "D:\Program Files\Python37\lib\site-packages\django\db\backends\utils.py", line 99, in execute
    return super().execute(sql, params)
  File "D:\Program Files\Python37\lib\site-packages\django\db\backends\utils.py", line 67, in execute
    return self._execute_with_wrappers(sql, params, many=False, executor=self._execute)
  File "D:\Program Files\Python37\lib\site-packages\django\db\backends\utils.py", line 76, in _execute_with_wrappers
    return executor(sql, params, many, context)
  File "D:\Program Files\Python37\lib\site-packages\django\db\backends\utils.py", line 84, in _execute
    return self.cursor.execute(sql, params)
  File "D:\Program Files\Python37\lib\site-packages\django\db\utils.py", line 89, in __exit__
    raise dj_exc_value.with_traceback(traceback) from exc_value
  File "D:\Program Files\Python37\lib\site-packages\django\db\backends\utils.py", line 84, in _execute
    return self.cursor.execute(sql, params)
  File "D:\Program Files\Python37\lib\site-packages\django\db\backends\mysql\base.py", line 71, in execute
    return self.cursor.execute(query, args)
  File "D:\Program Files\Python37\lib\site-packages\MySQLdb\cursors.py", line 209, in execute
    res = self._query(query)
  File "D:\Program Files\Python37\lib\site-packages\MySQLdb\cursors.py", line 315, in _query
    db.query(q)
  File "D:\Program Files\Python37\lib\site-packages\MySQLdb\connections.py", line 239, in query
    _mysql.connection.query(self, query)
django.db.utils.IntegrityError: (1062, "Duplicate entry '1587744000' for key 'LAMProcessData_process_r_acquisition_timestamp_a69ae90c_uniq'")
2020-04-24 01:02:11,129 - _run_jobs - 94 - DEBUG - Exiting worker thread
2020-04-24 01:02:46,936 - _real_add_job - 262 - INFO - Added job "regulartime_task (trigger: interval[1 day, 0:00:00], next run at: 2020-04-24 01:02:56.934567)" to job store "default"
2020-04-24 01:02:46,936 - _real_add_job - 262 - INFO - Added job "cleanup (trigger: cron[day_of_week='*', hour='3', minute='0', second='0'], next run at: 2020-04-24 03:00:00)" to job store "default"
2020-04-24 01:02:46,936 - _real_add_job - 262 - INFO - Added job "OpenLog (trigger: cron[hour='0'], next run at: 2020-04-25 00:00:00)" to job store "default"
2020-04-24 01:02:46,936 - _main_loop - 574 - INFO - Scheduler started
2020-04-24 01:02:46,937 - _main_loop - 579 - DEBUG - Looking for jobs to run
2020-04-24 01:02:46,937 - _main_loop - 588 - DEBUG - Next wakeup is due at 2020-04-24 01:02:56.934567 (in 9.997006 seconds)
2020-04-24 01:02:46,948 - <module> - 63 - DEBUG - SendBefore_NotRecive : [<CNCProcessStatus: CNCProcessStatus object (2038721)>]
2020-04-24 01:02:46,948 - <module> - 64 - DEBUG - Waitfor_Recive : [2038721]
2020-04-24 01:02:56,935 - _main_loop - 579 - DEBUG - Looking for jobs to run
2020-04-24 01:02:56,935 - _run_jobs - 69 - DEBUG - Started worker thread
2020-04-24 01:02:56,936 - _run_job - 509 - INFO - Running job "regulartime_task (trigger: interval[1 day, 0:00:00], next run at: 2020-04-24 01:02:56.934567)" (scheduled at 2020-04-24 01:02:56.934567)
2020-04-24 01:02:56,936 - _main_loop - 588 - DEBUG - Next wakeup is due at 2020-04-24 03:00:00 (in 7023.064132 seconds)
2020-04-24 01:02:57,241 - _run_job - 520 - ERROR - Job "regulartime_task (trigger: interval[1 day, 0:00:00], next run at: 2020-04-25 01:02:56.934567)" raised an exception
Traceback (most recent call last):
  File "D:\Program Files\Python37\lib\site-packages\django\db\backends\utils.py", line 84, in _execute
    return self.cursor.execute(sql, params)
  File "D:\Program Files\Python37\lib\site-packages\django\db\backends\mysql\base.py", line 71, in execute
    return self.cursor.execute(query, args)
  File "D:\Program Files\Python37\lib\site-packages\MySQLdb\cursors.py", line 209, in execute
    res = self._query(query)
  File "D:\Program Files\Python37\lib\site-packages\MySQLdb\cursors.py", line 315, in _query
    db.query(q)
  File "D:\Program Files\Python37\lib\site-packages\MySQLdb\connections.py", line 239, in query
    _mysql.connection.query(self, query)
MySQLdb._exceptions.IntegrityError: (1062, "Duplicate entry '1587744000' for key 'LAMProcessData_process_r_acquisition_timestamp_a69ae90c_uniq'")

The above exception was the direct cause of the following exception:

Traceback (most recent call last):
  File "D:\Program Files\Python37\lib\site-packages\apscheduler\scheduler.py", line 512, in _run_job
    retval = job.func(*job.args, **job.kwargs)
  File "E:\1-program\11-LAMDataServer\lamdataserver\LAMProcessData\views.py", line 4988, in regulartime_task
    RT_FineData.Realtime_FineData.init_Tomorrow_rows()
  File "E:\1-program\11-LAMDataServer\lamdataserver\LAMProcessData\process_realtime_finedata.py", line 193, in init_Tomorrow_rows
    _model.objects.bulk_create(insert_data_list)
  File "D:\Program Files\Python37\lib\site-packages\django\db\models\manager.py", line 82, in manager_method
    return getattr(self.get_queryset(), name)(*args, **kwargs)
  File "D:\Program Files\Python37\lib\site-packages\django\db\models\query.py", line 474, in bulk_create
    ids = self._batched_insert(objs_without_pk, fields, batch_size, ignore_conflicts=ignore_conflicts)
  File "D:\Program Files\Python37\lib\site-packages\django\db\models\query.py", line 1211, in _batched_insert
    self._insert(item, fields=fields, using=self.db, ignore_conflicts=ignore_conflicts)
  File "D:\Program Files\Python37\lib\site-packages\django\db\models\query.py", line 1186, in _insert
    return query.get_compiler(using=using).execute_sql(return_id)
  File "D:\Program Files\Python37\lib\site-packages\django\db\models\sql\compiler.py", line 1332, in execute_sql
    cursor.execute(sql, params)
  File "D:\Program Files\Python37\lib\site-packages\django\db\backends\utils.py", line 99, in execute
    return super().execute(sql, params)
  File "D:\Program Files\Python37\lib\site-packages\django\db\backends\utils.py", line 67, in execute
    return self._execute_with_wrappers(sql, params, many=False, executor=self._execute)
  File "D:\Program Files\Python37\lib\site-packages\django\db\backends\utils.py", line 76, in _execute_with_wrappers
    return executor(sql, params, many, context)
  File "D:\Program Files\Python37\lib\site-packages\django\db\backends\utils.py", line 84, in _execute
    return self.cursor.execute(sql, params)
  File "D:\Program Files\Python37\lib\site-packages\django\db\utils.py", line 89, in __exit__
    raise dj_exc_value.with_traceback(traceback) from exc_value
  File "D:\Program Files\Python37\lib\site-packages\django\db\backends\utils.py", line 84, in _execute
    return self.cursor.execute(sql, params)
  File "D:\Program Files\Python37\lib\site-packages\django\db\backends\mysql\base.py", line 71, in execute
    return self.cursor.execute(query, args)
  File "D:\Program Files\Python37\lib\site-packages\MySQLdb\cursors.py", line 209, in execute
    res = self._query(query)
  File "D:\Program Files\Python37\lib\site-packages\MySQLdb\cursors.py", line 315, in _query
    db.query(q)
  File "D:\Program Files\Python37\lib\site-packages\MySQLdb\connections.py", line 239, in query
    _mysql.connection.query(self, query)
django.db.utils.IntegrityError: (1062, "Duplicate entry '1587744000' for key 'LAMProcessData_process_r_acquisition_timestamp_a69ae90c_uniq'")
2020-04-24 01:02:58,249 - _run_jobs - 94 - DEBUG - Exiting worker thread
2020-04-24 01:09:55,627 - _real_add_job - 262 - INFO - Added job "regulartime_task (trigger: interval[1 day, 0:00:00], next run at: 2020-04-24 01:10:05.625934)" to job store "default"
2020-04-24 01:09:55,628 - _real_add_job - 262 - INFO - Added job "cleanup (trigger: cron[day_of_week='*', hour='3', minute='0', second='0'], next run at: 2020-04-24 03:00:00)" to job store "default"
2020-04-24 01:09:55,628 - _real_add_job - 262 - INFO - Added job "OpenLog (trigger: cron[hour='0'], next run at: 2020-04-25 00:00:00)" to job store "default"
2020-04-24 01:09:55,629 - _main_loop - 574 - INFO - Scheduler started
2020-04-24 01:09:55,629 - _main_loop - 579 - DEBUG - Looking for jobs to run
2020-04-24 01:09:55,629 - _main_loop - 588 - DEBUG - Next wakeup is due at 2020-04-24 01:10:05.625934 (in 9.996053 seconds)
2020-04-24 01:09:55,646 - <module> - 64 - DEBUG - SendBefore_NotRecive : [<CNCProcessStatus: CNCProcessStatus object (2038721)>]
2020-04-24 01:09:55,646 - <module> - 65 - DEBUG - Waitfor_Recive : [2038721]
2020-04-24 01:10:05,629 - _main_loop - 579 - DEBUG - Looking for jobs to run
2020-04-24 01:10:05,633 - _run_jobs - 69 - DEBUG - Started worker thread
2020-04-24 01:10:05,634 - _run_job - 509 - INFO - Running job "regulartime_task (trigger: interval[1 day, 0:00:00], next run at: 2020-04-24 01:10:05.625934)" (scheduled at 2020-04-24 01:10:05.625934)
2020-04-24 01:10:05,640 - _main_loop - 588 - DEBUG - Next wakeup is due at 2020-04-24 03:00:00 (in 6594.369252 seconds)
2020-04-24 01:10:06,574 - _run_job - 520 - ERROR - Job "regulartime_task (trigger: interval[1 day, 0:00:00], next run at: 2020-04-25 01:10:05.625934)" raised an exception
Traceback (most recent call last):
  File "D:\Program Files\Python37\lib\site-packages\django\db\backends\utils.py", line 84, in _execute
    return self.cursor.execute(sql, params)
  File "D:\Program Files\Python37\lib\site-packages\django\db\backends\mysql\base.py", line 71, in execute
    return self.cursor.execute(query, args)
  File "D:\Program Files\Python37\lib\site-packages\MySQLdb\cursors.py", line 209, in execute
    res = self._query(query)
  File "D:\Program Files\Python37\lib\site-packages\MySQLdb\cursors.py", line 315, in _query
    db.query(q)
  File "D:\Program Files\Python37\lib\site-packages\MySQLdb\connections.py", line 239, in query
    _mysql.connection.query(self, query)
MySQLdb._exceptions.IntegrityError: (1062, "Duplicate entry '1587744000' for key 'LAMProcessData_process_r_acquisition_timestamp_a69ae90c_uniq'")

The above exception was the direct cause of the following exception:

Traceback (most recent call last):
  File "D:\Program Files\Python37\lib\site-packages\apscheduler\scheduler.py", line 512, in _run_job
    retval = job.func(*job.args, **job.kwargs)
  File "E:\1-program\11-LAMDataServer\lamdataserver\LAMProcessData\views.py", line 4988, in regulartime_task
    RT_FineData.Realtime_FineData.init_Tomorrow_rows()
  File "E:\1-program\11-LAMDataServer\lamdataserver\LAMProcessData\process_realtime_finedata.py", line 193, in init_Tomorrow_rows
    _model.objects.bulk_create(insert_data_list)
  File "D:\Program Files\Python37\lib\site-packages\django\db\models\manager.py", line 82, in manager_method
    return getattr(self.get_queryset(), name)(*args, **kwargs)
  File "D:\Program Files\Python37\lib\site-packages\django\db\models\query.py", line 474, in bulk_create
    ids = self._batched_insert(objs_without_pk, fields, batch_size, ignore_conflicts=ignore_conflicts)
  File "D:\Program Files\Python37\lib\site-packages\django\db\models\query.py", line 1211, in _batched_insert
    self._insert(item, fields=fields, using=self.db, ignore_conflicts=ignore_conflicts)
  File "D:\Program Files\Python37\lib\site-packages\django\db\models\query.py", line 1186, in _insert
    return query.get_compiler(using=using).execute_sql(return_id)
  File "D:\Program Files\Python37\lib\site-packages\django\db\models\sql\compiler.py", line 1332, in execute_sql
    cursor.execute(sql, params)
  File "D:\Program Files\Python37\lib\site-packages\django\db\backends\utils.py", line 99, in execute
    return super().execute(sql, params)
  File "D:\Program Files\Python37\lib\site-packages\django\db\backends\utils.py", line 67, in execute
    return self._execute_with_wrappers(sql, params, many=False, executor=self._execute)
  File "D:\Program Files\Python37\lib\site-packages\django\db\backends\utils.py", line 76, in _execute_with_wrappers
    return executor(sql, params, many, context)
  File "D:\Program Files\Python37\lib\site-packages\django\db\backends\utils.py", line 84, in _execute
    return self.cursor.execute(sql, params)
  File "D:\Program Files\Python37\lib\site-packages\django\db\utils.py", line 89, in __exit__
    raise dj_exc_value.with_traceback(traceback) from exc_value
  File "D:\Program Files\Python37\lib\site-packages\django\db\backends\utils.py", line 84, in _execute
    return self.cursor.execute(sql, params)
  File "D:\Program Files\Python37\lib\site-packages\django\db\backends\mysql\base.py", line 71, in execute
    return self.cursor.execute(query, args)
  File "D:\Program Files\Python37\lib\site-packages\MySQLdb\cursors.py", line 209, in execute
    res = self._query(query)
  File "D:\Program Files\Python37\lib\site-packages\MySQLdb\cursors.py", line 315, in _query
    db.query(q)
  File "D:\Program Files\Python37\lib\site-packages\MySQLdb\connections.py", line 239, in query
    _mysql.connection.query(self, query)
django.db.utils.IntegrityError: (1062, "Duplicate entry '1587744000' for key 'LAMProcessData_process_r_acquisition_timestamp_a69ae90c_uniq'")
2020-04-24 01:10:07,583 - _run_jobs - 94 - DEBUG - Exiting worker thread
2020-04-24 01:12:05,055 - _real_add_job - 262 - INFO - Added job "regulartime_task (trigger: interval[1 day, 0:00:00], next run at: 2020-04-24 01:12:15.054344)" to job store "default"
2020-04-24 01:12:05,055 - _real_add_job - 262 - INFO - Added job "cleanup (trigger: cron[day_of_week='*', hour='3', minute='0', second='0'], next run at: 2020-04-24 03:00:00)" to job store "default"
2020-04-24 01:12:05,055 - _real_add_job - 262 - INFO - Added job "OpenLog (trigger: cron[hour='0'], next run at: 2020-04-25 00:00:00)" to job store "default"
2020-04-24 01:12:05,056 - _main_loop - 574 - INFO - Scheduler started
2020-04-24 01:12:05,056 - _main_loop - 579 - DEBUG - Looking for jobs to run
2020-04-24 01:12:05,056 - _main_loop - 588 - DEBUG - Next wakeup is due at 2020-04-24 01:12:15.054344 (in 9.998007 seconds)
2020-04-24 01:12:05,067 - <module> - 63 - DEBUG - SendBefore_NotRecive : [<CNCProcessStatus: CNCProcessStatus object (2038721)>]
2020-04-24 01:12:05,067 - <module> - 64 - DEBUG - Waitfor_Recive : [2038721]
2020-04-24 01:12:15,056 - _main_loop - 579 - DEBUG - Looking for jobs to run
2020-04-24 01:12:15,056 - _run_jobs - 69 - DEBUG - Started worker thread
2020-04-24 01:12:15,057 - _run_job - 509 - INFO - Running job "regulartime_task (trigger: interval[1 day, 0:00:00], next run at: 2020-04-24 01:12:15.054344)" (scheduled at 2020-04-24 01:12:15.054344)
2020-04-24 01:12:15,063 - _main_loop - 588 - DEBUG - Next wakeup is due at 2020-04-24 03:00:00 (in 6464.943914 seconds)
2020-04-24 01:12:15,380 - _run_job - 520 - ERROR - Job "regulartime_task (trigger: interval[1 day, 0:00:00], next run at: 2020-04-25 01:12:15.054344)" raised an exception
Traceback (most recent call last):
  File "D:\Program Files\Python37\lib\site-packages\django\db\backends\utils.py", line 84, in _execute
    return self.cursor.execute(sql, params)
  File "D:\Program Files\Python37\lib\site-packages\django\db\backends\mysql\base.py", line 71, in execute
    return self.cursor.execute(query, args)
  File "D:\Program Files\Python37\lib\site-packages\MySQLdb\cursors.py", line 209, in execute
    res = self._query(query)
  File "D:\Program Files\Python37\lib\site-packages\MySQLdb\cursors.py", line 315, in _query
    db.query(q)
  File "D:\Program Files\Python37\lib\site-packages\MySQLdb\connections.py", line 239, in query
    _mysql.connection.query(self, query)
MySQLdb._exceptions.IntegrityError: (1062, "Duplicate entry '1587744000' for key 'LAMProcessData_process_r_acquisition_timestamp_a69ae90c_uniq'")

The above exception was the direct cause of the following exception:

Traceback (most recent call last):
  File "D:\Program Files\Python37\lib\site-packages\apscheduler\scheduler.py", line 512, in _run_job
    retval = job.func(*job.args, **job.kwargs)
  File "E:\1-program\11-LAMDataServer\lamdataserver\LAMProcessData\views.py", line 4988, in regulartime_task
    RT_FineData.Realtime_FineData.init_Tomorrow_rows()
  File "E:\1-program\11-LAMDataServer\lamdataserver\LAMProcessData\process_realtime_finedata.py", line 193, in init_Tomorrow_rows
    _model.objects.bulk_create(insert_data_list)
  File "D:\Program Files\Python37\lib\site-packages\django\db\models\manager.py", line 82, in manager_method
    return getattr(self.get_queryset(), name)(*args, **kwargs)
  File "D:\Program Files\Python37\lib\site-packages\django\db\models\query.py", line 474, in bulk_create
    ids = self._batched_insert(objs_without_pk, fields, batch_size, ignore_conflicts=ignore_conflicts)
  File "D:\Program Files\Python37\lib\site-packages\django\db\models\query.py", line 1211, in _batched_insert
    self._insert(item, fields=fields, using=self.db, ignore_conflicts=ignore_conflicts)
  File "D:\Program Files\Python37\lib\site-packages\django\db\models\query.py", line 1186, in _insert
    return query.get_compiler(using=using).execute_sql(return_id)
  File "D:\Program Files\Python37\lib\site-packages\django\db\models\sql\compiler.py", line 1332, in execute_sql
    cursor.execute(sql, params)
  File "D:\Program Files\Python37\lib\site-packages\django\db\backends\utils.py", line 99, in execute
    return super().execute(sql, params)
  File "D:\Program Files\Python37\lib\site-packages\django\db\backends\utils.py", line 67, in execute
    return self._execute_with_wrappers(sql, params, many=False, executor=self._execute)
  File "D:\Program Files\Python37\lib\site-packages\django\db\backends\utils.py", line 76, in _execute_with_wrappers
    return executor(sql, params, many, context)
  File "D:\Program Files\Python37\lib\site-packages\django\db\backends\utils.py", line 84, in _execute
    return self.cursor.execute(sql, params)
  File "D:\Program Files\Python37\lib\site-packages\django\db\utils.py", line 89, in __exit__
    raise dj_exc_value.with_traceback(traceback) from exc_value
  File "D:\Program Files\Python37\lib\site-packages\django\db\backends\utils.py", line 84, in _execute
    return self.cursor.execute(sql, params)
  File "D:\Program Files\Python37\lib\site-packages\django\db\backends\mysql\base.py", line 71, in execute
    return self.cursor.execute(query, args)
  File "D:\Program Files\Python37\lib\site-packages\MySQLdb\cursors.py", line 209, in execute
    res = self._query(query)
  File "D:\Program Files\Python37\lib\site-packages\MySQLdb\cursors.py", line 315, in _query
    db.query(q)
  File "D:\Program Files\Python37\lib\site-packages\MySQLdb\connections.py", line 239, in query
    _mysql.connection.query(self, query)
django.db.utils.IntegrityError: (1062, "Duplicate entry '1587744000' for key 'LAMProcessData_process_r_acquisition_timestamp_a69ae90c_uniq'")
2020-04-24 01:12:16,388 - _run_jobs - 94 - DEBUG - Exiting worker thread
2020-04-24 01:16:56,149 - log_response - 228 - WARNING - Not Found: /favicon.ico
2020-04-24 01:21:54,998 - _real_add_job - 262 - INFO - Added job "regulartime_task (trigger: interval[1 day, 0:00:00], next run at: 2020-04-24 01:22:04.996055)" to job store "default"
2020-04-24 01:21:54,998 - _real_add_job - 262 - INFO - Added job "cleanup (trigger: cron[day_of_week='*', hour='3', minute='0', second='0'], next run at: 2020-04-24 03:00:00)" to job store "default"
2020-04-24 01:21:54,998 - _real_add_job - 262 - INFO - Added job "OpenLog (trigger: cron[hour='0'], next run at: 2020-04-25 00:00:00)" to job store "default"
2020-04-24 01:21:54,998 - _main_loop - 574 - INFO - Scheduler started
2020-04-24 01:21:54,999 - _main_loop - 579 - DEBUG - Looking for jobs to run
2020-04-24 01:21:54,999 - _main_loop - 588 - DEBUG - Next wakeup is due at 2020-04-24 01:22:04.996055 (in 9.997008 seconds)
2020-04-24 01:21:55,011 - <module> - 63 - DEBUG - SendBefore_NotRecive : [<CNCProcessStatus: CNCProcessStatus object (2038721)>]
2020-04-24 01:21:55,011 - <module> - 64 - DEBUG - Waitfor_Recive : [2038721]
2020-04-24 01:22:04,997 - _main_loop - 579 - DEBUG - Looking for jobs to run
2020-04-24 01:22:04,997 - _run_jobs - 69 - DEBUG - Started worker thread
2020-04-24 01:22:04,998 - _run_job - 509 - INFO - Running job "regulartime_task (trigger: interval[1 day, 0:00:00], next run at: 2020-04-24 01:22:04.996055)" (scheduled at 2020-04-24 01:22:04.996055)
2020-04-24 01:22:05,004 - _main_loop - 588 - DEBUG - Next wakeup is due at 2020-04-24 03:00:00 (in 5875.002104 seconds)
2020-04-24 01:22:05,331 - _run_job - 520 - ERROR - Job "regulartime_task (trigger: interval[1 day, 0:00:00], next run at: 2020-04-25 01:22:04.996055)" raised an exception
Traceback (most recent call last):
  File "D:\Program Files\Python37\lib\site-packages\django\db\backends\utils.py", line 84, in _execute
    return self.cursor.execute(sql, params)
  File "D:\Program Files\Python37\lib\site-packages\django\db\backends\mysql\base.py", line 71, in execute
    return self.cursor.execute(query, args)
  File "D:\Program Files\Python37\lib\site-packages\MySQLdb\cursors.py", line 209, in execute
    res = self._query(query)
  File "D:\Program Files\Python37\lib\site-packages\MySQLdb\cursors.py", line 315, in _query
    db.query(q)
  File "D:\Program Files\Python37\lib\site-packages\MySQLdb\connections.py", line 239, in query
    _mysql.connection.query(self, query)
MySQLdb._exceptions.IntegrityError: (1062, "Duplicate entry '1587744000' for key 'LAMProcessData_process_r_acquisition_timestamp_a69ae90c_uniq'")

The above exception was the direct cause of the following exception:

Traceback (most recent call last):
  File "D:\Program Files\Python37\lib\site-packages\apscheduler\scheduler.py", line 512, in _run_job
    retval = job.func(*job.args, **job.kwargs)
  File "E:\1-program\11-LAMDataServer\lamdataserver\LAMProcessData\views.py", line 4988, in regulartime_task
    RT_FineData.Realtime_FineData.init_Tomorrow_rows()
  File "E:\1-program\11-LAMDataServer\lamdataserver\LAMProcessData\process_realtime_finedata.py", line 193, in init_Tomorrow_rows
    _model.objects.bulk_create(insert_data_list)
  File "D:\Program Files\Python37\lib\site-packages\django\db\models\manager.py", line 82, in manager_method
    return getattr(self.get_queryset(), name)(*args, **kwargs)
  File "D:\Program Files\Python37\lib\site-packages\django\db\models\query.py", line 474, in bulk_create
    ids = self._batched_insert(objs_without_pk, fields, batch_size, ignore_conflicts=ignore_conflicts)
  File "D:\Program Files\Python37\lib\site-packages\django\db\models\query.py", line 1211, in _batched_insert
    self._insert(item, fields=fields, using=self.db, ignore_conflicts=ignore_conflicts)
  File "D:\Program Files\Python37\lib\site-packages\django\db\models\query.py", line 1186, in _insert
    return query.get_compiler(using=using).execute_sql(return_id)
  File "D:\Program Files\Python37\lib\site-packages\django\db\models\sql\compiler.py", line 1332, in execute_sql
    cursor.execute(sql, params)
  File "D:\Program Files\Python37\lib\site-packages\django\db\backends\utils.py", line 99, in execute
    return super().execute(sql, params)
  File "D:\Program Files\Python37\lib\site-packages\django\db\backends\utils.py", line 67, in execute
    return self._execute_with_wrappers(sql, params, many=False, executor=self._execute)
  File "D:\Program Files\Python37\lib\site-packages\django\db\backends\utils.py", line 76, in _execute_with_wrappers
    return executor(sql, params, many, context)
  File "D:\Program Files\Python37\lib\site-packages\django\db\backends\utils.py", line 84, in _execute
    return self.cursor.execute(sql, params)
  File "D:\Program Files\Python37\lib\site-packages\django\db\utils.py", line 89, in __exit__
    raise dj_exc_value.with_traceback(traceback) from exc_value
  File "D:\Program Files\Python37\lib\site-packages\django\db\backends\utils.py", line 84, in _execute
    return self.cursor.execute(sql, params)
  File "D:\Program Files\Python37\lib\site-packages\django\db\backends\mysql\base.py", line 71, in execute
    return self.cursor.execute(query, args)
  File "D:\Program Files\Python37\lib\site-packages\MySQLdb\cursors.py", line 209, in execute
    res = self._query(query)
  File "D:\Program Files\Python37\lib\site-packages\MySQLdb\cursors.py", line 315, in _query
    db.query(q)
  File "D:\Program Files\Python37\lib\site-packages\MySQLdb\connections.py", line 239, in query
    _mysql.connection.query(self, query)
django.db.utils.IntegrityError: (1062, "Duplicate entry '1587744000' for key 'LAMProcessData_process_r_acquisition_timestamp_a69ae90c_uniq'")
2020-04-24 01:22:06,337 - _run_jobs - 94 - DEBUG - Exiting worker thread
2020-04-24 01:25:52,255 - _real_add_job - 262 - INFO - Added job "regulartime_task (trigger: interval[1 day, 0:00:00], next run at: 2020-04-24 01:26:02.254391)" to job store "default"
2020-04-24 01:25:52,255 - _real_add_job - 262 - INFO - Added job "cleanup (trigger: cron[day_of_week='*', hour='3', minute='0', second='0'], next run at: 2020-04-24 03:00:00)" to job store "default"
2020-04-24 01:25:52,255 - _real_add_job - 262 - INFO - Added job "OpenLog (trigger: cron[hour='0'], next run at: 2020-04-25 00:00:00)" to job store "default"
2020-04-24 01:25:52,256 - _main_loop - 574 - INFO - Scheduler started
2020-04-24 01:25:52,256 - _main_loop - 579 - DEBUG - Looking for jobs to run
2020-04-24 01:25:52,256 - _main_loop - 588 - DEBUG - Next wakeup is due at 2020-04-24 01:26:02.254391 (in 9.998016 seconds)
2020-04-24 01:25:52,268 - <module> - 63 - DEBUG - SendBefore_NotRecive : [<CNCProcessStatus: CNCProcessStatus object (2038721)>]
2020-04-24 01:25:52,268 - <module> - 64 - DEBUG - Waitfor_Recive : [2038721]
2020-04-24 01:26:02,255 - _main_loop - 579 - DEBUG - Looking for jobs to run
2020-04-24 01:26:02,257 - _run_jobs - 69 - DEBUG - Started worker thread
2020-04-24 01:26:02,258 - _main_loop - 588 - DEBUG - Next wakeup is due at 2020-04-24 03:00:00 (in 5637.744605 seconds)
2020-04-24 01:26:02,258 - _run_job - 509 - INFO - Running job "regulartime_task (trigger: interval[1 day, 0:00:00], next run at: 2020-04-25 01:26:02.254391)" (scheduled at 2020-04-24 01:26:02.254391)
2020-04-24 01:26:02,574 - _run_job - 520 - ERROR - Job "regulartime_task (trigger: interval[1 day, 0:00:00], next run at: 2020-04-25 01:26:02.254391)" raised an exception
Traceback (most recent call last):
  File "D:\Program Files\Python37\lib\site-packages\django\db\backends\utils.py", line 84, in _execute
    return self.cursor.execute(sql, params)
  File "D:\Program Files\Python37\lib\site-packages\django\db\backends\mysql\base.py", line 71, in execute
    return self.cursor.execute(query, args)
  File "D:\Program Files\Python37\lib\site-packages\MySQLdb\cursors.py", line 209, in execute
    res = self._query(query)
  File "D:\Program Files\Python37\lib\site-packages\MySQLdb\cursors.py", line 315, in _query
    db.query(q)
  File "D:\Program Files\Python37\lib\site-packages\MySQLdb\connections.py", line 239, in query
    _mysql.connection.query(self, query)
MySQLdb._exceptions.IntegrityError: (1062, "Duplicate entry '1587744000' for key 'LAMProcessData_process_r_acquisition_timestamp_a69ae90c_uniq'")

The above exception was the direct cause of the following exception:

Traceback (most recent call last):
  File "D:\Program Files\Python37\lib\site-packages\apscheduler\scheduler.py", line 512, in _run_job
    retval = job.func(*job.args, **job.kwargs)
  File "E:\1-program\11-LAMDataServer\lamdataserver\LAMProcessData\views.py", line 4988, in regulartime_task
    RT_FineData.Realtime_FineData.init_Tomorrow_rows()
  File "E:\1-program\11-LAMDataServer\lamdataserver\LAMProcessData\process_realtime_finedata.py", line 193, in init_Tomorrow_rows
    _model.objects.bulk_create(insert_data_list)
  File "D:\Program Files\Python37\lib\site-packages\django\db\models\manager.py", line 82, in manager_method
    return getattr(self.get_queryset(), name)(*args, **kwargs)
  File "D:\Program Files\Python37\lib\site-packages\django\db\models\query.py", line 474, in bulk_create
    ids = self._batched_insert(objs_without_pk, fields, batch_size, ignore_conflicts=ignore_conflicts)
  File "D:\Program Files\Python37\lib\site-packages\django\db\models\query.py", line 1211, in _batched_insert
    self._insert(item, fields=fields, using=self.db, ignore_conflicts=ignore_conflicts)
  File "D:\Program Files\Python37\lib\site-packages\django\db\models\query.py", line 1186, in _insert
    return query.get_compiler(using=using).execute_sql(return_id)
  File "D:\Program Files\Python37\lib\site-packages\django\db\models\sql\compiler.py", line 1332, in execute_sql
    cursor.execute(sql, params)
  File "D:\Program Files\Python37\lib\site-packages\django\db\backends\utils.py", line 99, in execute
    return super().execute(sql, params)
  File "D:\Program Files\Python37\lib\site-packages\django\db\backends\utils.py", line 67, in execute
    return self._execute_with_wrappers(sql, params, many=False, executor=self._execute)
  File "D:\Program Files\Python37\lib\site-packages\django\db\backends\utils.py", line 76, in _execute_with_wrappers
    return executor(sql, params, many, context)
  File "D:\Program Files\Python37\lib\site-packages\django\db\backends\utils.py", line 84, in _execute
    return self.cursor.execute(sql, params)
  File "D:\Program Files\Python37\lib\site-packages\django\db\utils.py", line 89, in __exit__
    raise dj_exc_value.with_traceback(traceback) from exc_value
  File "D:\Program Files\Python37\lib\site-packages\django\db\backends\utils.py", line 84, in _execute
    return self.cursor.execute(sql, params)
  File "D:\Program Files\Python37\lib\site-packages\django\db\backends\mysql\base.py", line 71, in execute
    return self.cursor.execute(query, args)
  File "D:\Program Files\Python37\lib\site-packages\MySQLdb\cursors.py", line 209, in execute
    res = self._query(query)
  File "D:\Program Files\Python37\lib\site-packages\MySQLdb\cursors.py", line 315, in _query
    db.query(q)
  File "D:\Program Files\Python37\lib\site-packages\MySQLdb\connections.py", line 239, in query
    _mysql.connection.query(self, query)
django.db.utils.IntegrityError: (1062, "Duplicate entry '1587744000' for key 'LAMProcessData_process_r_acquisition_timestamp_a69ae90c_uniq'")
2020-04-24 01:26:03,579 - _run_jobs - 94 - DEBUG - Exiting worker thread
