2020-04-10 00:00:00,054 - _run_job - 527 - INFO - Job "OpenLog (trigger: cron[hour='0'], next run at: 2020-04-11 00:00:00)" executed successfully
2020-04-10 00:00:01,056 - _run_jobs - 94 - DEBUG - Exiting worker thread
2020-04-10 00:15:47,004 - _real_add_job - 262 - INFO - Added job "regulartime_task (trigger: interval[1 day, 0:00:00], next run at: 2020-04-10 00:15:57.002828)" to job store "default"
2020-04-10 00:15:47,040 - _real_add_job - 262 - INFO - Added job "cleanup (trigger: cron[day_of_week='*', hour='3', minute='0', second='0'], next run at: 2020-04-10 03:00:00)" to job store "default"
2020-04-10 00:15:47,040 - _real_add_job - 262 - INFO - Added job "OpenLog (trigger: cron[hour='0'], next run at: 2020-04-11 00:00:00)" to job store "default"
2020-04-10 00:15:47,041 - _main_loop - 574 - INFO - Scheduler started
2020-04-10 00:15:47,041 - _main_loop - 579 - DEBUG - Looking for jobs to run
2020-04-10 00:15:47,041 - _main_loop - 588 - DEBUG - Next wakeup is due at 2020-04-10 00:15:57.002828 (in 9.961003 seconds)
2020-04-10 00:15:47,058 - <module> - 59 - DEBUG - SendBefore_NotRecive : [<CNCProcessStatus: CNCProcessStatus object (2038721)>]
2020-04-10 00:15:47,058 - <module> - 60 - DEBUG - Waitfor_Recive : [2038721]
2020-04-10 00:15:57,005 - _main_loop - 579 - DEBUG - Looking for jobs to run
2020-04-10 00:15:57,007 - _run_jobs - 69 - DEBUG - Started worker thread
2020-04-10 00:15:57,007 - _main_loop - 588 - DEBUG - Next wakeup is due at 2020-04-10 03:00:00 (in 9842.993769 seconds)
2020-04-10 00:15:57,008 - _run_job - 509 - INFO - Running job "regulartime_task (trigger: interval[1 day, 0:00:00], next run at: 2020-04-11 00:15:57.002828)" (scheduled at 2020-04-10 00:15:57.002828)
2020-04-10 00:15:58,752 - _run_job - 520 - ERROR - Job "regulartime_task (trigger: interval[1 day, 0:00:00], next run at: 2020-04-11 00:15:57.002828)" raised an exception
Traceback (most recent call last):
  File "D:\Program Files\Python37\lib\site-packages\django\db\backends\mysql\base.py", line 71, in execute
    return self.cursor.execute(query, args)
  File "D:\Program Files\Python37\lib\site-packages\MySQLdb\cursors.py", line 209, in execute
    res = self._query(query)
  File "D:\Program Files\Python37\lib\site-packages\MySQLdb\cursors.py", line 315, in _query
    db.query(q)
  File "D:\Program Files\Python37\lib\site-packages\MySQLdb\connections.py", line 239, in query
    _mysql.connection.query(self, query)
MySQLdb._exceptions.OperationalError: (1048, "Column 'laser_power' cannot be null")

During handling of the above exception, another exception occurred:

Traceback (most recent call last):
  File "D:\Program Files\Python37\lib\site-packages\apscheduler\scheduler.py", line 512, in _run_job
    retval = job.func(*job.args, **job.kwargs)
  File "E:\1-program\11-LAMDataServer\lamdataserver\LAMProcessData\views.py", line 4817, in regulartime_task
    RT_FineData.Realtime_FineData.init_Tomorrow_rows()
  File "E:\1-program\11-LAMDataServer\lamdataserver\LAMProcessData\process_realtime_finedata.py", line 193, in init_Tomorrow_rows
    _model.objects.bulk_create(insert_data_list)
  File "D:\Program Files\Python37\lib\site-packages\django\db\models\manager.py", line 82, in manager_method
    return getattr(self.get_queryset(), name)(*args, **kwargs)
  File "D:\Program Files\Python37\lib\site-packages\django\db\models\query.py", line 474, in bulk_create
    ids = self._batched_insert(objs_without_pk, fields, batch_size, ignore_conflicts=ignore_conflicts)
  File "D:\Program Files\Python37\lib\site-packages\django\db\models\query.py", line 1211, in _batched_insert
    self._insert(item, fields=fields, using=self.db, ignore_conflicts=ignore_conflicts)
  File "D:\Program Files\Python37\lib\site-packages\django\db\models\query.py", line 1186, in _insert
    return query.get_compiler(using=using).execute_sql(return_id)
  File "D:\Program Files\Python37\lib\site-packages\django\db\models\sql\compiler.py", line 1332, in execute_sql
    cursor.execute(sql, params)
  File "D:\Program Files\Python37\lib\site-packages\django\db\backends\utils.py", line 99, in execute
    return super().execute(sql, params)
  File "D:\Program Files\Python37\lib\site-packages\django\db\backends\utils.py", line 67, in execute
    return self._execute_with_wrappers(sql, params, many=False, executor=self._execute)
  File "D:\Program Files\Python37\lib\site-packages\django\db\backends\utils.py", line 76, in _execute_with_wrappers
    return executor(sql, params, many, context)
  File "D:\Program Files\Python37\lib\site-packages\django\db\backends\utils.py", line 84, in _execute
    return self.cursor.execute(sql, params)
  File "D:\Program Files\Python37\lib\site-packages\django\db\backends\mysql\base.py", line 76, in execute
    raise utils.IntegrityError(*tuple(e.args))
django.db.utils.IntegrityError: (1048, "Column 'laser_power' cannot be null")
2020-04-10 00:15:59,758 - _run_jobs - 94 - DEBUG - Exiting worker thread
2020-04-10 00:23:22,720 - _real_add_job - 262 - INFO - Added job "regulartime_task (trigger: interval[1 day, 0:00:00], next run at: 2020-04-10 00:23:32.718856)" to job store "default"
2020-04-10 00:23:22,720 - _real_add_job - 262 - INFO - Added job "cleanup (trigger: cron[day_of_week='*', hour='3', minute='0', second='0'], next run at: 2020-04-10 03:00:00)" to job store "default"
2020-04-10 00:23:22,720 - _real_add_job - 262 - INFO - Added job "OpenLog (trigger: cron[hour='0'], next run at: 2020-04-11 00:00:00)" to job store "default"
2020-04-10 00:23:22,721 - _main_loop - 574 - INFO - Scheduler started
2020-04-10 00:23:22,721 - _main_loop - 579 - DEBUG - Looking for jobs to run
2020-04-10 00:23:22,721 - _main_loop - 588 - DEBUG - Next wakeup is due at 2020-04-10 00:23:32.718856 (in 9.997033 seconds)
2020-04-10 00:23:22,736 - <module> - 59 - DEBUG - SendBefore_NotRecive : [<CNCProcessStatus: CNCProcessStatus object (2038721)>]
2020-04-10 00:23:22,737 - <module> - 60 - DEBUG - Waitfor_Recive : [2038721]
2020-04-10 00:23:32,720 - _main_loop - 579 - DEBUG - Looking for jobs to run
2020-04-10 00:23:32,720 - _run_jobs - 69 - DEBUG - Started worker thread
2020-04-10 00:23:32,721 - _run_job - 509 - INFO - Running job "regulartime_task (trigger: interval[1 day, 0:00:00], next run at: 2020-04-10 00:23:32.718856)" (scheduled at 2020-04-10 00:23:32.718856)
2020-04-10 00:23:32,721 - _main_loop - 588 - DEBUG - Next wakeup is due at 2020-04-10 03:00:00 (in 9387.279142 seconds)
2020-04-10 00:23:33,428 - _run_job - 520 - ERROR - Job "regulartime_task (trigger: interval[1 day, 0:00:00], next run at: 2020-04-11 00:23:32.718856)" raised an exception
Traceback (most recent call last):
  File "D:\Program Files\Python37\lib\site-packages\django\db\backends\utils.py", line 84, in _execute
    return self.cursor.execute(sql, params)
  File "D:\Program Files\Python37\lib\site-packages\django\db\backends\mysql\base.py", line 71, in execute
    return self.cursor.execute(query, args)
  File "D:\Program Files\Python37\lib\site-packages\MySQLdb\cursors.py", line 209, in execute
    res = self._query(query)
  File "D:\Program Files\Python37\lib\site-packages\MySQLdb\cursors.py", line 315, in _query
    db.query(q)
  File "D:\Program Files\Python37\lib\site-packages\MySQLdb\connections.py", line 239, in query
    _mysql.connection.query(self, query)
MySQLdb._exceptions.IntegrityError: (1062, "Duplicate entry '1586534400' for key 'LAMProcessData_process_r_acquisition_timestamp_a69ae90c_uniq'")

The above exception was the direct cause of the following exception:

Traceback (most recent call last):
  File "D:\Program Files\Python37\lib\site-packages\apscheduler\scheduler.py", line 512, in _run_job
    retval = job.func(*job.args, **job.kwargs)
  File "E:\1-program\11-LAMDataServer\lamdataserver\LAMProcessData\views.py", line 4816, in regulartime_task
    RT_FineData.Realtime_FineData.init_Tomorrow_rows()
  File "E:\1-program\11-LAMDataServer\lamdataserver\LAMProcessData\process_realtime_finedata.py", line 193, in init_Tomorrow_rows
    _model.objects.bulk_create(insert_data_list)
  File "D:\Program Files\Python37\lib\site-packages\django\db\models\manager.py", line 82, in manager_method
    return getattr(self.get_queryset(), name)(*args, **kwargs)
  File "D:\Program Files\Python37\lib\site-packages\django\db\models\query.py", line 474, in bulk_create
    ids = self._batched_insert(objs_without_pk, fields, batch_size, ignore_conflicts=ignore_conflicts)
  File "D:\Program Files\Python37\lib\site-packages\django\db\models\query.py", line 1211, in _batched_insert
    self._insert(item, fields=fields, using=self.db, ignore_conflicts=ignore_conflicts)
  File "D:\Program Files\Python37\lib\site-packages\django\db\models\query.py", line 1186, in _insert
    return query.get_compiler(using=using).execute_sql(return_id)
  File "D:\Program Files\Python37\lib\site-packages\django\db\models\sql\compiler.py", line 1332, in execute_sql
    cursor.execute(sql, params)
  File "D:\Program Files\Python37\lib\site-packages\django\db\backends\utils.py", line 99, in execute
    return super().execute(sql, params)
  File "D:\Program Files\Python37\lib\site-packages\django\db\backends\utils.py", line 67, in execute
    return self._execute_with_wrappers(sql, params, many=False, executor=self._execute)
  File "D:\Program Files\Python37\lib\site-packages\django\db\backends\utils.py", line 76, in _execute_with_wrappers
    return executor(sql, params, many, context)
  File "D:\Program Files\Python37\lib\site-packages\django\db\backends\utils.py", line 84, in _execute
    return self.cursor.execute(sql, params)
  File "D:\Program Files\Python37\lib\site-packages\django\db\utils.py", line 89, in __exit__
    raise dj_exc_value.with_traceback(traceback) from exc_value
  File "D:\Program Files\Python37\lib\site-packages\django\db\backends\utils.py", line 84, in _execute
    return self.cursor.execute(sql, params)
  File "D:\Program Files\Python37\lib\site-packages\django\db\backends\mysql\base.py", line 71, in execute
    return self.cursor.execute(query, args)
  File "D:\Program Files\Python37\lib\site-packages\MySQLdb\cursors.py", line 209, in execute
    res = self._query(query)
  File "D:\Program Files\Python37\lib\site-packages\MySQLdb\cursors.py", line 315, in _query
    db.query(q)
  File "D:\Program Files\Python37\lib\site-packages\MySQLdb\connections.py", line 239, in query
    _mysql.connection.query(self, query)
django.db.utils.IntegrityError: (1062, "Duplicate entry '1586534400' for key 'LAMProcessData_process_r_acquisition_timestamp_a69ae90c_uniq'")
2020-04-10 00:23:34,437 - _run_jobs - 94 - DEBUG - Exiting worker thread
2020-04-10 00:25:14,443 - _real_add_job - 262 - INFO - Added job "regulartime_task (trigger: interval[1 day, 0:00:00], next run at: 2020-04-10 00:25:24.442201)" to job store "default"
2020-04-10 00:25:14,443 - _real_add_job - 262 - INFO - Added job "cleanup (trigger: cron[day_of_week='*', hour='3', minute='0', second='0'], next run at: 2020-04-10 03:00:00)" to job store "default"
2020-04-10 00:25:14,443 - _real_add_job - 262 - INFO - Added job "OpenLog (trigger: cron[hour='0'], next run at: 2020-04-11 00:00:00)" to job store "default"
2020-04-10 00:25:14,444 - _main_loop - 574 - INFO - Scheduler started
2020-04-10 00:25:14,444 - _main_loop - 579 - DEBUG - Looking for jobs to run
2020-04-10 00:25:14,444 - _main_loop - 588 - DEBUG - Next wakeup is due at 2020-04-10 00:25:24.442201 (in 9.998037 seconds)
2020-04-10 00:25:14,458 - <module> - 59 - DEBUG - SendBefore_NotRecive : [<CNCProcessStatus: CNCProcessStatus object (2038721)>]
2020-04-10 00:25:14,458 - <module> - 60 - DEBUG - Waitfor_Recive : [2038721]
2020-04-10 00:25:24,443 - _main_loop - 579 - DEBUG - Looking for jobs to run
2020-04-10 00:25:24,443 - _run_jobs - 69 - DEBUG - Started worker thread
2020-04-10 00:25:24,443 - _main_loop - 588 - DEBUG - Next wakeup is due at 2020-04-10 03:00:00 (in 9275.556006 seconds)
2020-04-10 00:25:24,444 - _run_job - 509 - INFO - Running job "regulartime_task (trigger: interval[1 day, 0:00:00], next run at: 2020-04-11 00:25:24.442201)" (scheduled at 2020-04-10 00:25:24.442201)
2020-04-10 00:25:24,895 - _run_job - 520 - ERROR - Job "regulartime_task (trigger: interval[1 day, 0:00:00], next run at: 2020-04-11 00:25:24.442201)" raised an exception
Traceback (most recent call last):
  File "D:\Program Files\Python37\lib\site-packages\django\db\backends\utils.py", line 84, in _execute
    return self.cursor.execute(sql, params)
  File "D:\Program Files\Python37\lib\site-packages\django\db\backends\mysql\base.py", line 71, in execute
    return self.cursor.execute(query, args)
  File "D:\Program Files\Python37\lib\site-packages\MySQLdb\cursors.py", line 209, in execute
    res = self._query(query)
  File "D:\Program Files\Python37\lib\site-packages\MySQLdb\cursors.py", line 315, in _query
    db.query(q)
  File "D:\Program Files\Python37\lib\site-packages\MySQLdb\connections.py", line 239, in query
    _mysql.connection.query(self, query)
MySQLdb._exceptions.IntegrityError: (1062, "Duplicate entry '1586534400' for key 'LAMProcessData_process_r_acquisition_timestamp_a69ae90c_uniq'")

The above exception was the direct cause of the following exception:

Traceback (most recent call last):
  File "D:\Program Files\Python37\lib\site-packages\apscheduler\scheduler.py", line 512, in _run_job
    retval = job.func(*job.args, **job.kwargs)
  File "E:\1-program\11-LAMDataServer\lamdataserver\LAMProcessData\views.py", line 4816, in regulartime_task
    RT_FineData.Realtime_FineData.init_Tomorrow_rows()
  File "E:\1-program\11-LAMDataServer\lamdataserver\LAMProcessData\process_realtime_finedata.py", line 193, in init_Tomorrow_rows
    _model.objects.bulk_create(insert_data_list)
  File "D:\Program Files\Python37\lib\site-packages\django\db\models\manager.py", line 82, in manager_method
    return getattr(self.get_queryset(), name)(*args, **kwargs)
  File "D:\Program Files\Python37\lib\site-packages\django\db\models\query.py", line 474, in bulk_create
    ids = self._batched_insert(objs_without_pk, fields, batch_size, ignore_conflicts=ignore_conflicts)
  File "D:\Program Files\Python37\lib\site-packages\django\db\models\query.py", line 1211, in _batched_insert
    self._insert(item, fields=fields, using=self.db, ignore_conflicts=ignore_conflicts)
  File "D:\Program Files\Python37\lib\site-packages\django\db\models\query.py", line 1186, in _insert
    return query.get_compiler(using=using).execute_sql(return_id)
  File "D:\Program Files\Python37\lib\site-packages\django\db\models\sql\compiler.py", line 1332, in execute_sql
    cursor.execute(sql, params)
  File "D:\Program Files\Python37\lib\site-packages\django\db\backends\utils.py", line 99, in execute
    return super().execute(sql, params)
  File "D:\Program Files\Python37\lib\site-packages\django\db\backends\utils.py", line 67, in execute
    return self._execute_with_wrappers(sql, params, many=False, executor=self._execute)
  File "D:\Program Files\Python37\lib\site-packages\django\db\backends\utils.py", line 76, in _execute_with_wrappers
    return executor(sql, params, many, context)
  File "D:\Program Files\Python37\lib\site-packages\django\db\backends\utils.py", line 84, in _execute
    return self.cursor.execute(sql, params)
  File "D:\Program Files\Python37\lib\site-packages\django\db\utils.py", line 89, in __exit__
    raise dj_exc_value.with_traceback(traceback) from exc_value
  File "D:\Program Files\Python37\lib\site-packages\django\db\backends\utils.py", line 84, in _execute
    return self.cursor.execute(sql, params)
  File "D:\Program Files\Python37\lib\site-packages\django\db\backends\mysql\base.py", line 71, in execute
    return self.cursor.execute(query, args)
  File "D:\Program Files\Python37\lib\site-packages\MySQLdb\cursors.py", line 209, in execute
    res = self._query(query)
  File "D:\Program Files\Python37\lib\site-packages\MySQLdb\cursors.py", line 315, in _query
    db.query(q)
  File "D:\Program Files\Python37\lib\site-packages\MySQLdb\connections.py", line 239, in query
    _mysql.connection.query(self, query)
django.db.utils.IntegrityError: (1062, "Duplicate entry '1586534400' for key 'LAMProcessData_process_r_acquisition_timestamp_a69ae90c_uniq'")
2020-04-10 00:25:25,902 - _run_jobs - 94 - DEBUG - Exiting worker thread
2020-04-10 00:25:34,522 - trigger_reload - 203 - INFO - E:\1-program\11-LAMDataServer\lamdataserver\LAMProcessData\views.py changed, reloading.
2020-04-10 00:25:34,523 - shutdown - 111 - INFO - Shutting down thread pool
2020-04-10 00:25:38,232 - _real_add_job - 262 - INFO - Added job "regulartime_task (trigger: interval[1 day, 0:00:00], next run at: 2020-04-10 00:25:48.230742)" to job store "default"
2020-04-10 00:25:38,232 - _real_add_job - 262 - INFO - Added job "cleanup (trigger: cron[day_of_week='*', hour='3', minute='0', second='0'], next run at: 2020-04-10 03:00:00)" to job store "default"
2020-04-10 00:25:38,232 - _real_add_job - 262 - INFO - Added job "OpenLog (trigger: cron[hour='0'], next run at: 2020-04-11 00:00:00)" to job store "default"
2020-04-10 00:25:38,233 - _main_loop - 574 - INFO - Scheduler started
2020-04-10 00:25:38,233 - _main_loop - 579 - DEBUG - Looking for jobs to run
2020-04-10 00:25:38,233 - _main_loop - 588 - DEBUG - Next wakeup is due at 2020-04-10 00:25:48.230742 (in 9.996868 seconds)
2020-04-10 00:25:38,249 - <module> - 59 - DEBUG - SendBefore_NotRecive : [<CNCProcessStatus: CNCProcessStatus object (2038721)>]
2020-04-10 00:25:38,249 - <module> - 60 - DEBUG - Waitfor_Recive : [2038721]
2020-04-10 00:25:48,245 - _main_loop - 579 - DEBUG - Looking for jobs to run
2020-04-10 00:25:48,245 - _run_jobs - 69 - DEBUG - Started worker thread
2020-04-10 00:25:48,246 - _run_job - 509 - INFO - Running job "regulartime_task (trigger: interval[1 day, 0:00:00], next run at: 2020-04-11 00:25:48.230742)" (scheduled at 2020-04-10 00:25:48.230742)
2020-04-10 00:25:48,246 - _main_loop - 588 - DEBUG - Next wakeup is due at 2020-04-10 03:00:00 (in 9251.754563 seconds)
2020-04-10 00:25:48,732 - _run_job - 520 - ERROR - Job "regulartime_task (trigger: interval[1 day, 0:00:00], next run at: 2020-04-11 00:25:48.230742)" raised an exception
Traceback (most recent call last):
  File "D:\Program Files\Python37\lib\site-packages\django\db\backends\utils.py", line 84, in _execute
    return self.cursor.execute(sql, params)
  File "D:\Program Files\Python37\lib\site-packages\django\db\backends\mysql\base.py", line 71, in execute
    return self.cursor.execute(query, args)
  File "D:\Program Files\Python37\lib\site-packages\MySQLdb\cursors.py", line 209, in execute
    res = self._query(query)
  File "D:\Program Files\Python37\lib\site-packages\MySQLdb\cursors.py", line 315, in _query
    db.query(q)
  File "D:\Program Files\Python37\lib\site-packages\MySQLdb\connections.py", line 239, in query
    _mysql.connection.query(self, query)
MySQLdb._exceptions.IntegrityError: (1062, "Duplicate entry '1586534400' for key 'LAMProcessData_process_r_acquisition_timestamp_a69ae90c_uniq'")

The above exception was the direct cause of the following exception:

Traceback (most recent call last):
  File "D:\Program Files\Python37\lib\site-packages\apscheduler\scheduler.py", line 512, in _run_job
    retval = job.func(*job.args, **job.kwargs)
  File "E:\1-program\11-LAMDataServer\lamdataserver\LAMProcessData\views.py", line 4817, in regulartime_task
    RT_FineData.Realtime_FineData.init_Tomorrow_rows()
  File "E:\1-program\11-LAMDataServer\lamdataserver\LAMProcessData\process_realtime_finedata.py", line 193, in init_Tomorrow_rows
    _model.objects.bulk_create(insert_data_list)
  File "D:\Program Files\Python37\lib\site-packages\django\db\models\manager.py", line 82, in manager_method
    return getattr(self.get_queryset(), name)(*args, **kwargs)
  File "D:\Program Files\Python37\lib\site-packages\django\db\models\query.py", line 474, in bulk_create
    ids = self._batched_insert(objs_without_pk, fields, batch_size, ignore_conflicts=ignore_conflicts)
  File "D:\Program Files\Python37\lib\site-packages\django\db\models\query.py", line 1211, in _batched_insert
    self._insert(item, fields=fields, using=self.db, ignore_conflicts=ignore_conflicts)
  File "D:\Program Files\Python37\lib\site-packages\django\db\models\query.py", line 1186, in _insert
    return query.get_compiler(using=using).execute_sql(return_id)
  File "D:\Program Files\Python37\lib\site-packages\django\db\models\sql\compiler.py", line 1332, in execute_sql
    cursor.execute(sql, params)
  File "D:\Program Files\Python37\lib\site-packages\django\db\backends\utils.py", line 99, in execute
    return super().execute(sql, params)
  File "D:\Program Files\Python37\lib\site-packages\django\db\backends\utils.py", line 67, in execute
    return self._execute_with_wrappers(sql, params, many=False, executor=self._execute)
  File "D:\Program Files\Python37\lib\site-packages\django\db\backends\utils.py", line 76, in _execute_with_wrappers
    return executor(sql, params, many, context)
  File "D:\Program Files\Python37\lib\site-packages\django\db\backends\utils.py", line 84, in _execute
    return self.cursor.execute(sql, params)
  File "D:\Program Files\Python37\lib\site-packages\django\db\utils.py", line 89, in __exit__
    raise dj_exc_value.with_traceback(traceback) from exc_value
  File "D:\Program Files\Python37\lib\site-packages\django\db\backends\utils.py", line 84, in _execute
    return self.cursor.execute(sql, params)
  File "D:\Program Files\Python37\lib\site-packages\django\db\backends\mysql\base.py", line 71, in execute
    return self.cursor.execute(query, args)
  File "D:\Program Files\Python37\lib\site-packages\MySQLdb\cursors.py", line 209, in execute
    res = self._query(query)
  File "D:\Program Files\Python37\lib\site-packages\MySQLdb\cursors.py", line 315, in _query
    db.query(q)
  File "D:\Program Files\Python37\lib\site-packages\MySQLdb\connections.py", line 239, in query
    _mysql.connection.query(self, query)
django.db.utils.IntegrityError: (1062, "Duplicate entry '1586534400' for key 'LAMProcessData_process_r_acquisition_timestamp_a69ae90c_uniq'")
2020-04-10 00:25:49,742 - _run_jobs - 94 - DEBUG - Exiting worker thread
2020-04-10 00:32:35,125 - trigger_reload - 203 - INFO - E:\1-program\11-LAMDataServer\lamdataserver\LAMProcessData\views.py changed, reloading.
2020-04-10 00:32:35,127 - shutdown - 111 - INFO - Shutting down thread pool
2020-04-10 00:32:39,780 - _real_add_job - 262 - INFO - Added job "regulartime_task (trigger: interval[1 day, 0:00:00], next run at: 2020-04-10 00:32:49.778874)" to job store "default"
2020-04-10 00:32:39,780 - _real_add_job - 262 - INFO - Added job "cleanup (trigger: cron[day_of_week='*', hour='3', minute='0', second='0'], next run at: 2020-04-10 03:00:00)" to job store "default"
2020-04-10 00:32:39,780 - _real_add_job - 262 - INFO - Added job "OpenLog (trigger: cron[hour='0'], next run at: 2020-04-11 00:00:00)" to job store "default"
2020-04-10 00:32:39,781 - _main_loop - 574 - INFO - Scheduler started
2020-04-10 00:32:39,782 - _main_loop - 579 - DEBUG - Looking for jobs to run
2020-04-10 00:32:39,782 - _main_loop - 588 - DEBUG - Next wakeup is due at 2020-04-10 00:32:49.778874 (in 9.996355 seconds)
2020-04-10 00:32:39,796 - <module> - 59 - DEBUG - SendBefore_NotRecive : [<CNCProcessStatus: CNCProcessStatus object (2038721)>]
2020-04-10 00:32:39,796 - <module> - 60 - DEBUG - Waitfor_Recive : [2038721]
2020-04-10 00:32:49,780 - _main_loop - 579 - DEBUG - Looking for jobs to run
2020-04-10 00:32:49,780 - _run_jobs - 69 - DEBUG - Started worker thread
2020-04-10 00:32:49,780 - _run_job - 509 - INFO - Running job "regulartime_task (trigger: interval[1 day, 0:00:00], next run at: 2020-04-10 00:32:49.778874)" (scheduled at 2020-04-10 00:32:49.778874)
2020-04-10 00:32:49,782 - _main_loop - 588 - DEBUG - Next wakeup is due at 2020-04-10 03:00:00 (in 8830.219953 seconds)
2020-04-10 00:32:50,510 - _run_job - 520 - ERROR - Job "regulartime_task (trigger: interval[1 day, 0:00:00], next run at: 2020-04-11 00:32:49.778874)" raised an exception
Traceback (most recent call last):
  File "D:\Program Files\Python37\lib\site-packages\django\db\backends\utils.py", line 84, in _execute
    return self.cursor.execute(sql, params)
  File "D:\Program Files\Python37\lib\site-packages\django\db\backends\mysql\base.py", line 71, in execute
    return self.cursor.execute(query, args)
  File "D:\Program Files\Python37\lib\site-packages\MySQLdb\cursors.py", line 209, in execute
    res = self._query(query)
  File "D:\Program Files\Python37\lib\site-packages\MySQLdb\cursors.py", line 315, in _query
    db.query(q)
  File "D:\Program Files\Python37\lib\site-packages\MySQLdb\connections.py", line 239, in query
    _mysql.connection.query(self, query)
MySQLdb._exceptions.IntegrityError: (1062, "Duplicate entry '1586534400' for key 'LAMProcessData_process_r_acquisition_timestamp_a69ae90c_uniq'")

The above exception was the direct cause of the following exception:

Traceback (most recent call last):
  File "D:\Program Files\Python37\lib\site-packages\apscheduler\scheduler.py", line 512, in _run_job
    retval = job.func(*job.args, **job.kwargs)
  File "E:\1-program\11-LAMDataServer\lamdataserver\LAMProcessData\views.py", line 4818, in regulartime_task
    RT_FineData.Realtime_FineData.init_Tomorrow_rows()
  File "E:\1-program\11-LAMDataServer\lamdataserver\LAMProcessData\process_realtime_finedata.py", line 193, in init_Tomorrow_rows
    _model.objects.bulk_create(insert_data_list)
  File "D:\Program Files\Python37\lib\site-packages\django\db\models\manager.py", line 82, in manager_method
    return getattr(self.get_queryset(), name)(*args, **kwargs)
  File "D:\Program Files\Python37\lib\site-packages\django\db\models\query.py", line 474, in bulk_create
    ids = self._batched_insert(objs_without_pk, fields, batch_size, ignore_conflicts=ignore_conflicts)
  File "D:\Program Files\Python37\lib\site-packages\django\db\models\query.py", line 1211, in _batched_insert
    self._insert(item, fields=fields, using=self.db, ignore_conflicts=ignore_conflicts)
  File "D:\Program Files\Python37\lib\site-packages\django\db\models\query.py", line 1186, in _insert
    return query.get_compiler(using=using).execute_sql(return_id)
  File "D:\Program Files\Python37\lib\site-packages\django\db\models\sql\compiler.py", line 1332, in execute_sql
    cursor.execute(sql, params)
  File "D:\Program Files\Python37\lib\site-packages\django\db\backends\utils.py", line 99, in execute
    return super().execute(sql, params)
  File "D:\Program Files\Python37\lib\site-packages\django\db\backends\utils.py", line 67, in execute
    return self._execute_with_wrappers(sql, params, many=False, executor=self._execute)
  File "D:\Program Files\Python37\lib\site-packages\django\db\backends\utils.py", line 76, in _execute_with_wrappers
    return executor(sql, params, many, context)
  File "D:\Program Files\Python37\lib\site-packages\django\db\backends\utils.py", line 84, in _execute
    return self.cursor.execute(sql, params)
  File "D:\Program Files\Python37\lib\site-packages\django\db\utils.py", line 89, in __exit__
    raise dj_exc_value.with_traceback(traceback) from exc_value
  File "D:\Program Files\Python37\lib\site-packages\django\db\backends\utils.py", line 84, in _execute
    return self.cursor.execute(sql, params)
  File "D:\Program Files\Python37\lib\site-packages\django\db\backends\mysql\base.py", line 71, in execute
    return self.cursor.execute(query, args)
  File "D:\Program Files\Python37\lib\site-packages\MySQLdb\cursors.py", line 209, in execute
    res = self._query(query)
  File "D:\Program Files\Python37\lib\site-packages\MySQLdb\cursors.py", line 315, in _query
    db.query(q)
  File "D:\Program Files\Python37\lib\site-packages\MySQLdb\connections.py", line 239, in query
    _mysql.connection.query(self, query)
django.db.utils.IntegrityError: (1062, "Duplicate entry '1586534400' for key 'LAMProcessData_process_r_acquisition_timestamp_a69ae90c_uniq'")
2020-04-10 00:32:51,524 - _run_jobs - 94 - DEBUG - Exiting worker thread
2020-04-10 00:34:00,496 - trigger_reload - 203 - INFO - E:\1-program\11-LAMDataServer\lamdataserver\LAMProcessData\views.py changed, reloading.
2020-04-10 00:34:00,497 - shutdown - 111 - INFO - Shutting down thread pool
2020-04-10 00:34:03,609 - _real_add_job - 262 - INFO - Added job "regulartime_task (trigger: interval[1 day, 0:00:00], next run at: 2020-04-10 00:34:13.607612)" to job store "default"
2020-04-10 00:34:03,609 - _real_add_job - 262 - INFO - Added job "cleanup (trigger: cron[day_of_week='*', hour='3', minute='0', second='0'], next run at: 2020-04-10 03:00:00)" to job store "default"
2020-04-10 00:34:03,609 - _real_add_job - 262 - INFO - Added job "OpenLog (trigger: cron[hour='0'], next run at: 2020-04-11 00:00:00)" to job store "default"
2020-04-10 00:34:03,609 - _main_loop - 574 - INFO - Scheduler started
2020-04-10 00:34:03,610 - _main_loop - 579 - DEBUG - Looking for jobs to run
2020-04-10 00:34:03,610 - _main_loop - 588 - DEBUG - Next wakeup is due at 2020-04-10 00:34:13.607612 (in 9.997042 seconds)
2020-04-10 00:34:03,624 - <module> - 59 - DEBUG - SendBefore_NotRecive : [<CNCProcessStatus: CNCProcessStatus object (2038721)>]
2020-04-10 00:34:03,624 - <module> - 60 - DEBUG - Waitfor_Recive : [2038721]
2020-04-10 00:34:13,609 - _main_loop - 579 - DEBUG - Looking for jobs to run
2020-04-10 00:34:13,609 - _run_jobs - 69 - DEBUG - Started worker thread
2020-04-10 00:34:13,610 - _main_loop - 588 - DEBUG - Next wakeup is due at 2020-04-10 03:00:00 (in 8746.390612 seconds)
2020-04-10 00:34:13,610 - _run_job - 509 - INFO - Running job "regulartime_task (trigger: interval[1 day, 0:00:00], next run at: 2020-04-11 00:34:13.607612)" (scheduled at 2020-04-10 00:34:13.607612)
2020-04-10 00:34:14,221 - _run_job - 520 - ERROR - Job "regulartime_task (trigger: interval[1 day, 0:00:00], next run at: 2020-04-11 00:34:13.607612)" raised an exception
Traceback (most recent call last):
  File "D:\Program Files\Python37\lib\site-packages\django\db\backends\utils.py", line 84, in _execute
    return self.cursor.execute(sql, params)
  File "D:\Program Files\Python37\lib\site-packages\django\db\backends\mysql\base.py", line 71, in execute
    return self.cursor.execute(query, args)
  File "D:\Program Files\Python37\lib\site-packages\MySQLdb\cursors.py", line 209, in execute
    res = self._query(query)
  File "D:\Program Files\Python37\lib\site-packages\MySQLdb\cursors.py", line 315, in _query
    db.query(q)
  File "D:\Program Files\Python37\lib\site-packages\MySQLdb\connections.py", line 239, in query
    _mysql.connection.query(self, query)
MySQLdb._exceptions.IntegrityError: (1062, "Duplicate entry '1586534400' for key 'LAMProcessData_process_r_acquisition_timestamp_a69ae90c_uniq'")

The above exception was the direct cause of the following exception:

Traceback (most recent call last):
  File "D:\Program Files\Python37\lib\site-packages\apscheduler\scheduler.py", line 512, in _run_job
    retval = job.func(*job.args, **job.kwargs)
  File "E:\1-program\11-LAMDataServer\lamdataserver\LAMProcessData\views.py", line 4818, in regulartime_task
    RT_FineData.Realtime_FineData.init_Tomorrow_rows()
  File "E:\1-program\11-LAMDataServer\lamdataserver\LAMProcessData\process_realtime_finedata.py", line 193, in init_Tomorrow_rows
    _model.objects.bulk_create(insert_data_list)
  File "D:\Program Files\Python37\lib\site-packages\django\db\models\manager.py", line 82, in manager_method
    return getattr(self.get_queryset(), name)(*args, **kwargs)
  File "D:\Program Files\Python37\lib\site-packages\django\db\models\query.py", line 474, in bulk_create
    ids = self._batched_insert(objs_without_pk, fields, batch_size, ignore_conflicts=ignore_conflicts)
  File "D:\Program Files\Python37\lib\site-packages\django\db\models\query.py", line 1211, in _batched_insert
    self._insert(item, fields=fields, using=self.db, ignore_conflicts=ignore_conflicts)
  File "D:\Program Files\Python37\lib\site-packages\django\db\models\query.py", line 1186, in _insert
    return query.get_compiler(using=using).execute_sql(return_id)
  File "D:\Program Files\Python37\lib\site-packages\django\db\models\sql\compiler.py", line 1332, in execute_sql
    cursor.execute(sql, params)
  File "D:\Program Files\Python37\lib\site-packages\django\db\backends\utils.py", line 99, in execute
    return super().execute(sql, params)
  File "D:\Program Files\Python37\lib\site-packages\django\db\backends\utils.py", line 67, in execute
    return self._execute_with_wrappers(sql, params, many=False, executor=self._execute)
  File "D:\Program Files\Python37\lib\site-packages\django\db\backends\utils.py", line 76, in _execute_with_wrappers
    return executor(sql, params, many, context)
  File "D:\Program Files\Python37\lib\site-packages\django\db\backends\utils.py", line 84, in _execute
    return self.cursor.execute(sql, params)
  File "D:\Program Files\Python37\lib\site-packages\django\db\utils.py", line 89, in __exit__
    raise dj_exc_value.with_traceback(traceback) from exc_value
  File "D:\Program Files\Python37\lib\site-packages\django\db\backends\utils.py", line 84, in _execute
    return self.cursor.execute(sql, params)
  File "D:\Program Files\Python37\lib\site-packages\django\db\backends\mysql\base.py", line 71, in execute
    return self.cursor.execute(query, args)
  File "D:\Program Files\Python37\lib\site-packages\MySQLdb\cursors.py", line 209, in execute
    res = self._query(query)
  File "D:\Program Files\Python37\lib\site-packages\MySQLdb\cursors.py", line 315, in _query
    db.query(q)
  File "D:\Program Files\Python37\lib\site-packages\MySQLdb\connections.py", line 239, in query
    _mysql.connection.query(self, query)
django.db.utils.IntegrityError: (1062, "Duplicate entry '1586534400' for key 'LAMProcessData_process_r_acquisition_timestamp_a69ae90c_uniq'")
2020-04-10 00:34:15,239 - _run_jobs - 94 - DEBUG - Exiting worker thread
2020-04-10 00:34:16,268 - trigger_reload - 203 - INFO - E:\1-program\11-LAMDataServer\lamdataserver\LAMProcessData\views.py changed, reloading.
2020-04-10 00:34:16,268 - shutdown - 111 - INFO - Shutting down thread pool
2020-04-10 00:34:19,461 - _real_add_job - 262 - INFO - Added job "regulartime_task (trigger: interval[1 day, 0:00:00], next run at: 2020-04-10 00:34:29.458313)" to job store "default"
2020-04-10 00:34:19,461 - _real_add_job - 262 - INFO - Added job "cleanup (trigger: cron[day_of_week='*', hour='3', minute='0', second='0'], next run at: 2020-04-10 03:00:00)" to job store "default"
2020-04-10 00:34:19,461 - _real_add_job - 262 - INFO - Added job "OpenLog (trigger: cron[hour='0'], next run at: 2020-04-11 00:00:00)" to job store "default"
2020-04-10 00:34:19,487 - _main_loop - 574 - INFO - Scheduler started
2020-04-10 00:34:19,513 - <module> - 59 - DEBUG - SendBefore_NotRecive : [<CNCProcessStatus: CNCProcessStatus object (2038721)>]
2020-04-10 00:34:19,517 - _main_loop - 579 - DEBUG - Looking for jobs to run
2020-04-10 00:34:19,517 - <module> - 60 - DEBUG - Waitfor_Recive : [2038721]
2020-04-10 00:34:19,517 - _main_loop - 588 - DEBUG - Next wakeup is due at 2020-04-10 00:34:29.458313 (in 9.940890 seconds)
2020-04-10 00:34:29,467 - _main_loop - 579 - DEBUG - Looking for jobs to run
2020-04-10 00:34:29,469 - _run_jobs - 69 - DEBUG - Started worker thread
2020-04-10 00:34:29,470 - _run_job - 509 - INFO - Running job "regulartime_task (trigger: interval[1 day, 0:00:00], next run at: 2020-04-10 00:34:29.458313)" (scheduled at 2020-04-10 00:34:29.458313)
2020-04-10 00:34:29,470 - _main_loop - 588 - DEBUG - Next wakeup is due at 2020-04-10 03:00:00 (in 8730.532687 seconds)
2020-04-10 00:34:29,911 - _run_job - 520 - ERROR - Job "regulartime_task (trigger: interval[1 day, 0:00:00], next run at: 2020-04-11 00:34:29.458313)" raised an exception
Traceback (most recent call last):
  File "D:\Program Files\Python37\lib\site-packages\django\db\backends\utils.py", line 84, in _execute
    return self.cursor.execute(sql, params)
  File "D:\Program Files\Python37\lib\site-packages\django\db\backends\mysql\base.py", line 71, in execute
    return self.cursor.execute(query, args)
  File "D:\Program Files\Python37\lib\site-packages\MySQLdb\cursors.py", line 209, in execute
    res = self._query(query)
  File "D:\Program Files\Python37\lib\site-packages\MySQLdb\cursors.py", line 315, in _query
    db.query(q)
  File "D:\Program Files\Python37\lib\site-packages\MySQLdb\connections.py", line 239, in query
    _mysql.connection.query(self, query)
MySQLdb._exceptions.IntegrityError: (1062, "Duplicate entry '1586534400' for key 'LAMProcessData_process_r_acquisition_timestamp_a69ae90c_uniq'")

The above exception was the direct cause of the following exception:

Traceback (most recent call last):
  File "D:\Program Files\Python37\lib\site-packages\apscheduler\scheduler.py", line 512, in _run_job
    retval = job.func(*job.args, **job.kwargs)
  File "E:\1-program\11-LAMDataServer\lamdataserver\LAMProcessData\views.py", line 4818, in regulartime_task
    RT_FineData.Realtime_FineData.init_Tomorrow_rows()
  File "E:\1-program\11-LAMDataServer\lamdataserver\LAMProcessData\process_realtime_finedata.py", line 193, in init_Tomorrow_rows
    _model.objects.bulk_create(insert_data_list)
  File "D:\Program Files\Python37\lib\site-packages\django\db\models\manager.py", line 82, in manager_method
    return getattr(self.get_queryset(), name)(*args, **kwargs)
  File "D:\Program Files\Python37\lib\site-packages\django\db\models\query.py", line 474, in bulk_create
    ids = self._batched_insert(objs_without_pk, fields, batch_size, ignore_conflicts=ignore_conflicts)
  File "D:\Program Files\Python37\lib\site-packages\django\db\models\query.py", line 1211, in _batched_insert
    self._insert(item, fields=fields, using=self.db, ignore_conflicts=ignore_conflicts)
  File "D:\Program Files\Python37\lib\site-packages\django\db\models\query.py", line 1186, in _insert
    return query.get_compiler(using=using).execute_sql(return_id)
  File "D:\Program Files\Python37\lib\site-packages\django\db\models\sql\compiler.py", line 1332, in execute_sql
    cursor.execute(sql, params)
  File "D:\Program Files\Python37\lib\site-packages\django\db\backends\utils.py", line 99, in execute
    return super().execute(sql, params)
  File "D:\Program Files\Python37\lib\site-packages\django\db\backends\utils.py", line 67, in execute
    return self._execute_with_wrappers(sql, params, many=False, executor=self._execute)
  File "D:\Program Files\Python37\lib\site-packages\django\db\backends\utils.py", line 76, in _execute_with_wrappers
    return executor(sql, params, many, context)
  File "D:\Program Files\Python37\lib\site-packages\django\db\backends\utils.py", line 84, in _execute
    return self.cursor.execute(sql, params)
  File "D:\Program Files\Python37\lib\site-packages\django\db\utils.py", line 89, in __exit__
    raise dj_exc_value.with_traceback(traceback) from exc_value
  File "D:\Program Files\Python37\lib\site-packages\django\db\backends\utils.py", line 84, in _execute
    return self.cursor.execute(sql, params)
  File "D:\Program Files\Python37\lib\site-packages\django\db\backends\mysql\base.py", line 71, in execute
    return self.cursor.execute(query, args)
  File "D:\Program Files\Python37\lib\site-packages\MySQLdb\cursors.py", line 209, in execute
    res = self._query(query)
  File "D:\Program Files\Python37\lib\site-packages\MySQLdb\cursors.py", line 315, in _query
    db.query(q)
  File "D:\Program Files\Python37\lib\site-packages\MySQLdb\connections.py", line 239, in query
    _mysql.connection.query(self, query)
django.db.utils.IntegrityError: (1062, "Duplicate entry '1586534400' for key 'LAMProcessData_process_r_acquisition_timestamp_a69ae90c_uniq'")
2020-04-10 00:34:30,926 - _run_jobs - 94 - DEBUG - Exiting worker thread
2020-04-10 22:23:56,144 - _real_add_job - 262 - INFO - Added job "regulartime_task (trigger: interval[1 day, 0:00:00], next run at: 2020-04-10 22:24:06.143084)" to job store "default"
2020-04-10 22:23:56,144 - _real_add_job - 262 - INFO - Added job "cleanup (trigger: cron[day_of_week='*', hour='3', minute='0', second='0'], next run at: 2020-04-11 03:00:00)" to job store "default"
2020-04-10 22:23:56,144 - _real_add_job - 262 - INFO - Added job "OpenLog (trigger: cron[hour='0'], next run at: 2020-04-11 00:00:00)" to job store "default"
2020-04-10 22:23:56,145 - _main_loop - 574 - INFO - Scheduler started
2020-04-10 22:23:56,145 - _main_loop - 579 - DEBUG - Looking for jobs to run
2020-04-10 22:23:56,145 - _main_loop - 588 - DEBUG - Next wakeup is due at 2020-04-10 22:24:06.143084 (in 9.998007 seconds)
2020-04-10 22:23:56,175 - <module> - 59 - DEBUG - SendBefore_NotRecive : [<CNCProcessStatus: CNCProcessStatus object (2038721)>]
2020-04-10 22:23:56,175 - <module> - 60 - DEBUG - Waitfor_Recive : [2038721]
2020-04-10 22:24:06,146 - _main_loop - 579 - DEBUG - Looking for jobs to run
2020-04-10 22:24:06,147 - _run_jobs - 69 - DEBUG - Started worker thread
2020-04-10 22:24:06,147 - _main_loop - 588 - DEBUG - Next wakeup is due at 2020-04-11 00:00:00 (in 5753.853964 seconds)
2020-04-10 22:24:06,147 - _run_job - 509 - INFO - Running job "regulartime_task (trigger: interval[1 day, 0:00:00], next run at: 2020-04-11 22:24:06.143084)" (scheduled at 2020-04-10 22:24:06.143084)
2020-04-10 22:24:06,850 - _run_job - 520 - ERROR - Job "regulartime_task (trigger: interval[1 day, 0:00:00], next run at: 2020-04-11 22:24:06.143084)" raised an exception
Traceback (most recent call last):
  File "D:\Program Files\Python37\lib\site-packages\django\db\backends\utils.py", line 84, in _execute
    return self.cursor.execute(sql, params)
  File "D:\Program Files\Python37\lib\site-packages\django\db\backends\mysql\base.py", line 71, in execute
    return self.cursor.execute(query, args)
  File "D:\Program Files\Python37\lib\site-packages\MySQLdb\cursors.py", line 209, in execute
    res = self._query(query)
  File "D:\Program Files\Python37\lib\site-packages\MySQLdb\cursors.py", line 315, in _query
    db.query(q)
  File "D:\Program Files\Python37\lib\site-packages\MySQLdb\connections.py", line 239, in query
    _mysql.connection.query(self, query)
MySQLdb._exceptions.IntegrityError: (1062, "Duplicate entry '1586534400' for key 'LAMProcessData_process_r_acquisition_timestamp_a69ae90c_uniq'")

The above exception was the direct cause of the following exception:

Traceback (most recent call last):
  File "D:\Program Files\Python37\lib\site-packages\apscheduler\scheduler.py", line 512, in _run_job
    retval = job.func(*job.args, **job.kwargs)
  File "E:\1-program\11-LAMDataServer\lamdataserver\LAMProcessData\views.py", line 4818, in regulartime_task
    RT_FineData.Realtime_FineData.init_Tomorrow_rows()
  File "E:\1-program\11-LAMDataServer\lamdataserver\LAMProcessData\process_realtime_finedata.py", line 193, in init_Tomorrow_rows
    _model.objects.bulk_create(insert_data_list)
  File "D:\Program Files\Python37\lib\site-packages\django\db\models\manager.py", line 82, in manager_method
    return getattr(self.get_queryset(), name)(*args, **kwargs)
  File "D:\Program Files\Python37\lib\site-packages\django\db\models\query.py", line 474, in bulk_create
    ids = self._batched_insert(objs_without_pk, fields, batch_size, ignore_conflicts=ignore_conflicts)
  File "D:\Program Files\Python37\lib\site-packages\django\db\models\query.py", line 1211, in _batched_insert
    self._insert(item, fields=fields, using=self.db, ignore_conflicts=ignore_conflicts)
  File "D:\Program Files\Python37\lib\site-packages\django\db\models\query.py", line 1186, in _insert
    return query.get_compiler(using=using).execute_sql(return_id)
  File "D:\Program Files\Python37\lib\site-packages\django\db\models\sql\compiler.py", line 1332, in execute_sql
    cursor.execute(sql, params)
  File "D:\Program Files\Python37\lib\site-packages\django\db\backends\utils.py", line 99, in execute
    return super().execute(sql, params)
  File "D:\Program Files\Python37\lib\site-packages\django\db\backends\utils.py", line 67, in execute
    return self._execute_with_wrappers(sql, params, many=False, executor=self._execute)
  File "D:\Program Files\Python37\lib\site-packages\django\db\backends\utils.py", line 76, in _execute_with_wrappers
    return executor(sql, params, many, context)
  File "D:\Program Files\Python37\lib\site-packages\django\db\backends\utils.py", line 84, in _execute
    return self.cursor.execute(sql, params)
  File "D:\Program Files\Python37\lib\site-packages\django\db\utils.py", line 89, in __exit__
    raise dj_exc_value.with_traceback(traceback) from exc_value
  File "D:\Program Files\Python37\lib\site-packages\django\db\backends\utils.py", line 84, in _execute
    return self.cursor.execute(sql, params)
  File "D:\Program Files\Python37\lib\site-packages\django\db\backends\mysql\base.py", line 71, in execute
    return self.cursor.execute(query, args)
  File "D:\Program Files\Python37\lib\site-packages\MySQLdb\cursors.py", line 209, in execute
    res = self._query(query)
  File "D:\Program Files\Python37\lib\site-packages\MySQLdb\cursors.py", line 315, in _query
    db.query(q)
  File "D:\Program Files\Python37\lib\site-packages\MySQLdb\connections.py", line 239, in query
    _mysql.connection.query(self, query)
django.db.utils.IntegrityError: (1062, "Duplicate entry '1586534400' for key 'LAMProcessData_process_r_acquisition_timestamp_a69ae90c_uniq'")
2020-04-10 22:24:07,865 - _run_jobs - 94 - DEBUG - Exiting worker thread
2020-04-10 22:24:11,788 - log_response - 228 - WARNING - Not Found: /favicon.ico
2020-04-10 22:24:12,316 - log_response - 228 - WARNING - Not Found: /favicon.ico
2020-04-10 22:24:12,921 - log_response - 228 - WARNING - Not Found: /favicon.ico
2020-04-10 22:24:13,524 - log_response - 228 - WARNING - Not Found: /favicon.ico
2020-04-10 22:24:14,132 - log_response - 228 - WARNING - Not Found: /favicon.ico
2020-04-10 22:24:14,743 - log_response - 228 - WARNING - Not Found: /favicon.ico
2020-04-10 22:24:15,350 - log_response - 228 - WARNING - Not Found: /favicon.ico
2020-04-10 22:24:15,973 - log_response - 228 - WARNING - Not Found: /favicon.ico
2020-04-10 22:24:16,569 - log_response - 228 - WARNING - Not Found: /favicon.ico
2020-04-10 22:24:17,219 - log_response - 228 - WARNING - Not Found: /favicon.ico
2020-04-10 22:24:17,839 - log_response - 228 - WARNING - Not Found: /favicon.ico
2020-04-10 22:24:18,113 - log_response - 228 - WARNING - Not Found: /
2020-04-10 22:24:18,358 - log_response - 228 - WARNING - Not Found: /favicon.ico
2020-04-10 22:24:23,795 - log_response - 228 - WARNING - Not Found: /favicon.ico
2020-04-10 22:24:35,051 - log_response - 228 - WARNING - Not Found: /favicon.ico
2020-04-10 22:24:35,674 - log_response - 228 - WARNING - Not Found: /favicon.ico
2020-04-10 22:24:36,284 - log_response - 228 - WARNING - Not Found: /favicon.ico
2020-04-10 22:24:36,898 - log_response - 228 - WARNING - Not Found: /favicon.ico
2020-04-10 22:24:37,493 - log_response - 228 - WARNING - Not Found: /favicon.ico
2020-04-10 23:23:48,723 - log_response - 228 - WARNING - Not Found: /favicon.ico
2020-04-10 23:23:49,258 - log_response - 228 - WARNING - Not Found: /favicon.ico
2020-04-10 23:23:49,869 - log_response - 228 - WARNING - Not Found: /favicon.ico
2020-04-10 23:23:50,484 - log_response - 228 - WARNING - Not Found: /favicon.ico
2020-04-10 23:23:51,087 - log_response - 228 - WARNING - Not Found: /favicon.ico
2020-04-10 23:23:51,698 - log_response - 228 - WARNING - Not Found: /favicon.ico
2020-04-10 23:23:52,300 - log_response - 228 - WARNING - Not Found: /favicon.ico
2020-04-10 23:23:55,203 - log_response - 228 - WARNING - Not Found: /favicon.ico
2020-04-10 23:23:55,807 - log_response - 228 - WARNING - Not Found: /favicon.ico
2020-04-10 23:23:56,412 - log_response - 228 - WARNING - Not Found: /favicon.ico
2020-04-10 23:23:57,027 - log_response - 228 - WARNING - Not Found: /favicon.ico
2020-04-10 23:23:57,642 - log_response - 228 - WARNING - Not Found: /favicon.ico
2020-04-10 23:23:58,240 - log_response - 228 - WARNING - Not Found: /favicon.ico
2020-04-10 23:23:58,839 - log_response - 228 - WARNING - Not Found: /favicon.ico
2020-04-10 23:23:59,446 - log_response - 228 - WARNING - Not Found: /favicon.ico
2020-04-10 23:24:03,908 - log_response - 228 - WARNING - Not Found: /favicon.ico
2020-04-10 23:24:04,505 - log_response - 228 - WARNING - Not Found: /favicon.ico
2020-04-10 23:24:05,112 - log_response - 228 - WARNING - Not Found: /favicon.ico
2020-04-10 23:24:05,299 - log_response - 228 - WARNING - Not Found: /
2020-04-10 23:24:07,924 - log_response - 228 - WARNING - Not Found: /
2020-04-10 23:37:46,686 - _real_add_job - 262 - INFO - Added job "regulartime_task (trigger: interval[1 day, 0:00:00], next run at: 2020-04-10 23:37:56.685584)" to job store "default"
2020-04-10 23:37:46,686 - _real_add_job - 262 - INFO - Added job "cleanup (trigger: cron[day_of_week='*', hour='3', minute='0', second='0'], next run at: 2020-04-11 03:00:00)" to job store "default"
2020-04-10 23:37:46,686 - _real_add_job - 262 - INFO - Added job "OpenLog (trigger: cron[hour='0'], next run at: 2020-04-11 00:00:00)" to job store "default"
2020-04-10 23:37:46,687 - _main_loop - 574 - INFO - Scheduler started
2020-04-10 23:37:46,687 - _main_loop - 579 - DEBUG - Looking for jobs to run
2020-04-10 23:37:46,688 - _main_loop - 588 - DEBUG - Next wakeup is due at 2020-04-10 23:37:56.685584 (in 9.997709 seconds)
2020-04-10 23:37:46,716 - <module> - 59 - DEBUG - SendBefore_NotRecive : [<CNCProcessStatus: CNCProcessStatus object (2038721)>]
2020-04-10 23:37:46,716 - <module> - 60 - DEBUG - Waitfor_Recive : [2038721]
2020-04-10 23:38:12,182 - _real_add_job - 262 - INFO - Added job "regulartime_task (trigger: interval[1 day, 0:00:00], next run at: 2020-04-10 23:38:22.180082)" to job store "default"
2020-04-10 23:38:12,182 - _real_add_job - 262 - INFO - Added job "cleanup (trigger: cron[day_of_week='*', hour='3', minute='0', second='0'], next run at: 2020-04-11 03:00:00)" to job store "default"
2020-04-10 23:38:12,182 - _real_add_job - 262 - INFO - Added job "OpenLog (trigger: cron[hour='0'], next run at: 2020-04-11 00:00:00)" to job store "default"
2020-04-10 23:38:12,182 - _main_loop - 574 - INFO - Scheduler started
2020-04-10 23:38:12,183 - _main_loop - 579 - DEBUG - Looking for jobs to run
2020-04-10 23:38:12,183 - _main_loop - 588 - DEBUG - Next wakeup is due at 2020-04-10 23:38:22.180082 (in 9.997060 seconds)
2020-04-10 23:38:12,197 - <module> - 59 - DEBUG - SendBefore_NotRecive : [<CNCProcessStatus: CNCProcessStatus object (2038721)>]
2020-04-10 23:38:12,197 - <module> - 60 - DEBUG - Waitfor_Recive : [2038721]
2020-04-10 23:38:27,011 - _real_add_job - 262 - INFO - Added job "regulartime_task (trigger: interval[1 day, 0:00:00], next run at: 2020-04-10 23:38:37.009623)" to job store "default"
2020-04-10 23:38:27,011 - _real_add_job - 262 - INFO - Added job "cleanup (trigger: cron[day_of_week='*', hour='3', minute='0', second='0'], next run at: 2020-04-11 03:00:00)" to job store "default"
2020-04-10 23:38:27,011 - _real_add_job - 262 - INFO - Added job "OpenLog (trigger: cron[hour='0'], next run at: 2020-04-11 00:00:00)" to job store "default"
2020-04-10 23:38:27,012 - _main_loop - 574 - INFO - Scheduler started
2020-04-10 23:38:27,012 - _main_loop - 579 - DEBUG - Looking for jobs to run
2020-04-10 23:38:27,012 - _main_loop - 588 - DEBUG - Next wakeup is due at 2020-04-10 23:38:37.009623 (in 9.997008 seconds)
2020-04-10 23:38:27,023 - <module> - 59 - DEBUG - SendBefore_NotRecive : [<CNCProcessStatus: CNCProcessStatus object (2038721)>]
2020-04-10 23:38:27,023 - <module> - 60 - DEBUG - Waitfor_Recive : [2038721]
2020-04-10 23:38:37,011 - _main_loop - 579 - DEBUG - Looking for jobs to run
2020-04-10 23:38:37,011 - _run_jobs - 69 - DEBUG - Started worker thread
2020-04-10 23:38:37,012 - _main_loop - 588 - DEBUG - Next wakeup is due at 2020-04-11 00:00:00 (in 1282.988048 seconds)
2020-04-10 23:38:37,012 - _run_job - 509 - INFO - Running job "regulartime_task (trigger: interval[1 day, 0:00:00], next run at: 2020-04-11 23:38:37.009623)" (scheduled at 2020-04-10 23:38:37.009623)
2020-04-10 23:38:37,388 - _run_job - 520 - ERROR - Job "regulartime_task (trigger: interval[1 day, 0:00:00], next run at: 2020-04-11 23:38:37.009623)" raised an exception
Traceback (most recent call last):
  File "D:\Program Files\Python37\lib\site-packages\django\db\backends\utils.py", line 84, in _execute
    return self.cursor.execute(sql, params)
  File "D:\Program Files\Python37\lib\site-packages\django\db\backends\mysql\base.py", line 71, in execute
    return self.cursor.execute(query, args)
  File "D:\Program Files\Python37\lib\site-packages\MySQLdb\cursors.py", line 209, in execute
    res = self._query(query)
  File "D:\Program Files\Python37\lib\site-packages\MySQLdb\cursors.py", line 315, in _query
    db.query(q)
  File "D:\Program Files\Python37\lib\site-packages\MySQLdb\connections.py", line 239, in query
    _mysql.connection.query(self, query)
MySQLdb._exceptions.IntegrityError: (1062, "Duplicate entry '1586534400' for key 'LAMProcessData_process_r_acquisition_timestamp_a69ae90c_uniq'")

The above exception was the direct cause of the following exception:

Traceback (most recent call last):
  File "D:\Program Files\Python37\lib\site-packages\apscheduler\scheduler.py", line 512, in _run_job
    retval = job.func(*job.args, **job.kwargs)
  File "E:\1-program\11-LAMDataServer\lamdataserver\LAMProcessData\views.py", line 4818, in regulartime_task
    RT_FineData.Realtime_FineData.init_Tomorrow_rows()
  File "E:\1-program\11-LAMDataServer\lamdataserver\LAMProcessData\process_realtime_finedata.py", line 193, in init_Tomorrow_rows
    _model.objects.bulk_create(insert_data_list)
  File "D:\Program Files\Python37\lib\site-packages\django\db\models\manager.py", line 82, in manager_method
    return getattr(self.get_queryset(), name)(*args, **kwargs)
  File "D:\Program Files\Python37\lib\site-packages\django\db\models\query.py", line 474, in bulk_create
    ids = self._batched_insert(objs_without_pk, fields, batch_size, ignore_conflicts=ignore_conflicts)
  File "D:\Program Files\Python37\lib\site-packages\django\db\models\query.py", line 1211, in _batched_insert
    self._insert(item, fields=fields, using=self.db, ignore_conflicts=ignore_conflicts)
  File "D:\Program Files\Python37\lib\site-packages\django\db\models\query.py", line 1186, in _insert
    return query.get_compiler(using=using).execute_sql(return_id)
  File "D:\Program Files\Python37\lib\site-packages\django\db\models\sql\compiler.py", line 1332, in execute_sql
    cursor.execute(sql, params)
  File "D:\Program Files\Python37\lib\site-packages\django\db\backends\utils.py", line 99, in execute
    return super().execute(sql, params)
  File "D:\Program Files\Python37\lib\site-packages\django\db\backends\utils.py", line 67, in execute
    return self._execute_with_wrappers(sql, params, many=False, executor=self._execute)
  File "D:\Program Files\Python37\lib\site-packages\django\db\backends\utils.py", line 76, in _execute_with_wrappers
    return executor(sql, params, many, context)
  File "D:\Program Files\Python37\lib\site-packages\django\db\backends\utils.py", line 84, in _execute
    return self.cursor.execute(sql, params)
  File "D:\Program Files\Python37\lib\site-packages\django\db\utils.py", line 89, in __exit__
    raise dj_exc_value.with_traceback(traceback) from exc_value
  File "D:\Program Files\Python37\lib\site-packages\django\db\backends\utils.py", line 84, in _execute
    return self.cursor.execute(sql, params)
  File "D:\Program Files\Python37\lib\site-packages\django\db\backends\mysql\base.py", line 71, in execute
    return self.cursor.execute(query, args)
  File "D:\Program Files\Python37\lib\site-packages\MySQLdb\cursors.py", line 209, in execute
    res = self._query(query)
  File "D:\Program Files\Python37\lib\site-packages\MySQLdb\cursors.py", line 315, in _query
    db.query(q)
  File "D:\Program Files\Python37\lib\site-packages\MySQLdb\connections.py", line 239, in query
    _mysql.connection.query(self, query)
django.db.utils.IntegrityError: (1062, "Duplicate entry '1586534400' for key 'LAMProcessData_process_r_acquisition_timestamp_a69ae90c_uniq'")
2020-04-10 23:38:38,395 - _run_jobs - 94 - DEBUG - Exiting worker thread
2020-04-10 23:49:07,250 - log_response - 228 - WARNING - Not Found: /favicon.ico
