2020-04-07 00:00:00,008 - _run_job - 527 - INFO - Job "OpenLog (trigger: cron[hour='0'], next run at: 2020-04-08 00:00:00)" executed successfully
2020-04-07 00:00:01,010 - _run_jobs - 94 - DEBUG - Exiting worker thread
2020-04-07 17:37:52,545 - _real_add_job - 262 - INFO - Added job "regulartime_task (trigger: interval[1 day, 0:00:00], next run at: 2020-04-07 17:38:02.544535)" to job store "default"
2020-04-07 17:37:52,545 - _real_add_job - 262 - INFO - Added job "cleanup (trigger: cron[day_of_week='*', hour='3', minute='0', second='0'], next run at: 2020-04-08 03:00:00)" to job store "default"
2020-04-07 17:37:52,546 - _real_add_job - 262 - INFO - Added job "OpenLog (trigger: cron[hour='0'], next run at: 2020-04-08 00:00:00)" to job store "default"
2020-04-07 17:37:52,546 - _main_loop - 574 - INFO - Scheduler started
2020-04-07 17:37:52,546 - _main_loop - 579 - DEBUG - Looking for jobs to run
2020-04-07 17:37:52,546 - _main_loop - 588 - DEBUG - Next wakeup is due at 2020-04-07 17:38:02.544535 (in 9.998001 seconds)
2020-04-07 17:37:52,566 - <module> - 59 - DEBUG - SendBefore_NotRecive : [<CNCProcessStatus: CNCProcessStatus object (2038721)>]
2020-04-07 17:37:52,567 - <module> - 60 - DEBUG - Waitfor_Recive : [2038721]
2020-04-07 17:38:02,546 - _main_loop - 579 - DEBUG - Looking for jobs to run
2020-04-07 17:38:02,547 - _run_jobs - 69 - DEBUG - Started worker thread
2020-04-07 17:38:02,547 - _main_loop - 588 - DEBUG - Next wakeup is due at 2020-04-08 00:00:00 (in 22917.453425 seconds)
2020-04-07 17:38:02,548 - _run_job - 509 - INFO - Running job "regulartime_task (trigger: interval[1 day, 0:00:00], next run at: 2020-04-08 17:38:02.544535)" (scheduled at 2020-04-07 17:38:02.544535)
2020-04-07 17:38:03,406 - _run_job - 520 - ERROR - Job "regulartime_task (trigger: interval[1 day, 0:00:00], next run at: 2020-04-08 17:38:02.544535)" raised an exception
Traceback (most recent call last):
  File "D:\Program Files\Python37\lib\site-packages\django\db\backends\mysql\base.py", line 71, in execute
    return self.cursor.execute(query, args)
  File "D:\Program Files\Python37\lib\site-packages\MySQLdb\cursors.py", line 209, in execute
    res = self._query(query)
  File "D:\Program Files\Python37\lib\site-packages\MySQLdb\cursors.py", line 315, in _query
    db.query(q)
  File "D:\Program Files\Python37\lib\site-packages\MySQLdb\connections.py", line 239, in query
    _mysql.connection.query(self, query)
MySQLdb._exceptions.OperationalError: (1048, "Column 'laser_power' cannot be null")

During handling of the above exception, another exception occurred:

Traceback (most recent call last):
  File "D:\Program Files\Python37\lib\site-packages\apscheduler\scheduler.py", line 512, in _run_job
    retval = job.func(*job.args, **job.kwargs)
  File "E:\1-program\11-LAMDataServer\lamdataserver\LAMProcessData\views.py", line 4775, in regulartime_task
    RT_FineData.Realtime_FineData.init_Tomorrow_rows()
  File "E:\1-program\11-LAMDataServer\lamdataserver\LAMProcessData\process_realtime_finedata.py", line 191, in init_Tomorrow_rows
    _model.objects.bulk_create(insert_data_list)
  File "D:\Program Files\Python37\lib\site-packages\django\db\models\manager.py", line 82, in manager_method
    return getattr(self.get_queryset(), name)(*args, **kwargs)
  File "D:\Program Files\Python37\lib\site-packages\django\db\models\query.py", line 474, in bulk_create
    ids = self._batched_insert(objs_without_pk, fields, batch_size, ignore_conflicts=ignore_conflicts)
  File "D:\Program Files\Python37\lib\site-packages\django\db\models\query.py", line 1211, in _batched_insert
    self._insert(item, fields=fields, using=self.db, ignore_conflicts=ignore_conflicts)
  File "D:\Program Files\Python37\lib\site-packages\django\db\models\query.py", line 1186, in _insert
    return query.get_compiler(using=using).execute_sql(return_id)
  File "D:\Program Files\Python37\lib\site-packages\django\db\models\sql\compiler.py", line 1332, in execute_sql
    cursor.execute(sql, params)
  File "D:\Program Files\Python37\lib\site-packages\django\db\backends\utils.py", line 99, in execute
    return super().execute(sql, params)
  File "D:\Program Files\Python37\lib\site-packages\django\db\backends\utils.py", line 67, in execute
    return self._execute_with_wrappers(sql, params, many=False, executor=self._execute)
  File "D:\Program Files\Python37\lib\site-packages\django\db\backends\utils.py", line 76, in _execute_with_wrappers
    return executor(sql, params, many, context)
  File "D:\Program Files\Python37\lib\site-packages\django\db\backends\utils.py", line 84, in _execute
    return self.cursor.execute(sql, params)
  File "D:\Program Files\Python37\lib\site-packages\django\db\backends\mysql\base.py", line 76, in execute
    raise utils.IntegrityError(*tuple(e.args))
django.db.utils.IntegrityError: (1048, "Column 'laser_power' cannot be null")
2020-04-07 17:38:04,452 - _run_jobs - 94 - DEBUG - Exiting worker thread
2020-04-07 17:38:28,200 - log_response - 228 - WARNING - Not Found: /favicon.ico
2020-04-07 17:38:28,745 - log_response - 228 - WARNING - Not Found: /favicon.ico
2020-04-07 17:38:29,359 - log_response - 228 - WARNING - Not Found: /favicon.ico
2020-04-07 17:38:30,359 - log_response - 228 - WARNING - Not Found: /favicon.ico
2020-04-07 17:38:33,523 - log_response - 228 - WARNING - Not Found: /favicon.ico
2020-04-07 17:38:34,126 - log_response - 228 - WARNING - Not Found: /favicon.ico
2020-04-07 18:07:34,116 - log_response - 228 - WARNING - Not Found: /favicon.ico
2020-04-07 23:52:01,919 - log_response - 228 - WARNING - Not Found: /favicon.ico
