2020-06-14 00:03:32,174 - _real_add_job - 262 - INFO - Added job "regulartime_task (trigger: interval[1 day, 0:00:00], next run at: 2020-06-14 00:03:42.173920)" to job store "default"
2020-06-14 00:03:32,174 - _real_add_job - 262 - INFO - Added job "cleanup (trigger: cron[day_of_week='*', hour='3', minute='0', second='0'], next run at: 2020-06-14 03:00:00)" to job store "default"
2020-06-14 00:03:32,174 - _real_add_job - 262 - INFO - Added job "OpenLog (trigger: cron[hour='0'], next run at: 2020-06-15 00:00:00)" to job store "default"
2020-06-14 00:03:32,175 - _main_loop - 574 - INFO - Scheduler started
2020-06-14 00:03:32,175 - _main_loop - 579 - DEBUG - Looking for jobs to run
2020-06-14 00:03:32,175 - _main_loop - 588 - DEBUG - Next wakeup is due at 2020-06-14 00:03:42.173920 (in 9.998007 seconds)
2020-06-14 00:03:32,185 - <module> - 63 - DEBUG - SendBefore_NotRecive : [<CNCProcessStatus: CNCProcessStatus object (2038721)>]
2020-06-14 00:03:32,185 - <module> - 64 - DEBUG - Waitfor_Recive : [2038721]
2020-06-14 00:03:42,175 - _main_loop - 579 - DEBUG - Looking for jobs to run
2020-06-14 00:03:42,175 - _run_jobs - 69 - DEBUG - Started worker thread
2020-06-14 00:03:42,175 - _main_loop - 588 - DEBUG - Next wakeup is due at 2020-06-14 03:00:00 (in 10577.824759 seconds)
2020-06-14 00:03:42,176 - _run_job - 509 - INFO - Running job "regulartime_task (trigger: interval[1 day, 0:00:00], next run at: 2020-06-15 00:03:42.173920)" (scheduled at 2020-06-14 00:03:42.173920)
2020-06-14 00:03:42,920 - _run_job - 520 - ERROR - Job "regulartime_task (trigger: interval[1 day, 0:00:00], next run at: 2020-06-15 00:03:42.173920)" raised an exception
Traceback (most recent call last):
  File "D:\Program Files\Python37\lib\site-packages\django\db\backends\mysql\base.py", line 71, in execute
    return self.cursor.execute(query, args)
  File "D:\Program Files\Python37\lib\site-packages\MySQLdb\cursors.py", line 209, in execute
    res = self._query(query)
  File "D:\Program Files\Python37\lib\site-packages\MySQLdb\cursors.py", line 315, in _query
    db.query(q)
  File "D:\Program Files\Python37\lib\site-packages\MySQLdb\connections.py", line 239, in query
    _mysql.connection.query(self, query)
MySQLdb._exceptions.OperationalError: (1048, "Column 'laser_power' cannot be null")

During handling of the above exception, another exception occurred:

Traceback (most recent call last):
  File "D:\Program Files\Python37\lib\site-packages\apscheduler\scheduler.py", line 512, in _run_job
    retval = job.func(*job.args, **job.kwargs)
  File "E:\1-program\11-LAMDataServer\lamdataserver\LAMProcessData\views.py", line 5662, in regulartime_task
    RT_FineData.Realtime_FineData.init_Tomorrow_rows()
  File "E:\1-program\11-LAMDataServer\lamdataserver\LAMProcessData\process_realtime_finedata.py", line 193, in init_Tomorrow_rows
    _model.objects.bulk_create(insert_data_list)
  File "D:\Program Files\Python37\lib\site-packages\django\db\models\manager.py", line 82, in manager_method
    return getattr(self.get_queryset(), name)(*args, **kwargs)
  File "D:\Program Files\Python37\lib\site-packages\django\db\models\query.py", line 474, in bulk_create
    ids = self._batched_insert(objs_without_pk, fields, batch_size, ignore_conflicts=ignore_conflicts)
  File "D:\Program Files\Python37\lib\site-packages\django\db\models\query.py", line 1211, in _batched_insert
    self._insert(item, fields=fields, using=self.db, ignore_conflicts=ignore_conflicts)
  File "D:\Program Files\Python37\lib\site-packages\django\db\models\query.py", line 1186, in _insert
    return query.get_compiler(using=using).execute_sql(return_id)
  File "D:\Program Files\Python37\lib\site-packages\django\db\models\sql\compiler.py", line 1332, in execute_sql
    cursor.execute(sql, params)
  File "D:\Program Files\Python37\lib\site-packages\django\db\backends\utils.py", line 99, in execute
    return super().execute(sql, params)
  File "D:\Program Files\Python37\lib\site-packages\django\db\backends\utils.py", line 67, in execute
    return self._execute_with_wrappers(sql, params, many=False, executor=self._execute)
  File "D:\Program Files\Python37\lib\site-packages\django\db\backends\utils.py", line 76, in _execute_with_wrappers
    return executor(sql, params, many, context)
  File "D:\Program Files\Python37\lib\site-packages\django\db\backends\utils.py", line 84, in _execute
    return self.cursor.execute(sql, params)
  File "D:\Program Files\Python37\lib\site-packages\django\db\backends\mysql\base.py", line 76, in execute
    raise utils.IntegrityError(*tuple(e.args))
django.db.utils.IntegrityError: (1048, "Column 'laser_power' cannot be null")
2020-06-14 00:03:43,925 - _run_jobs - 94 - DEBUG - Exiting worker thread
2020-06-14 00:04:03,279 - trigger_reload - 203 - INFO - E:\1-program\11-LAMDataServer\lamdataserver\LAMProcessData\forms.py changed, reloading.
2020-06-14 00:04:03,279 - shutdown - 111 - INFO - Shutting down thread pool
2020-06-14 00:04:05,505 - _real_add_job - 262 - INFO - Added job "regulartime_task (trigger: interval[1 day, 0:00:00], next run at: 2020-06-14 00:04:15.504964)" to job store "default"
2020-06-14 00:04:05,505 - _real_add_job - 262 - INFO - Added job "cleanup (trigger: cron[day_of_week='*', hour='3', minute='0', second='0'], next run at: 2020-06-14 03:00:00)" to job store "default"
2020-06-14 00:04:05,505 - _real_add_job - 262 - INFO - Added job "OpenLog (trigger: cron[hour='0'], next run at: 2020-06-15 00:00:00)" to job store "default"
2020-06-14 00:04:05,506 - _main_loop - 574 - INFO - Scheduler started
2020-06-14 00:04:05,506 - _main_loop - 579 - DEBUG - Looking for jobs to run
2020-06-14 00:04:05,506 - _main_loop - 588 - DEBUG - Next wakeup is due at 2020-06-14 00:04:15.504964 (in 9.998002 seconds)
2020-06-14 00:04:05,516 - <module> - 63 - DEBUG - SendBefore_NotRecive : [<CNCProcessStatus: CNCProcessStatus object (2038721)>]
2020-06-14 00:04:05,517 - <module> - 64 - DEBUG - Waitfor_Recive : [2038721]
2020-06-14 00:04:15,506 - _main_loop - 579 - DEBUG - Looking for jobs to run
2020-06-14 00:04:15,506 - _run_jobs - 69 - DEBUG - Started worker thread
2020-06-14 00:04:15,507 - _run_job - 509 - INFO - Running job "regulartime_task (trigger: interval[1 day, 0:00:00], next run at: 2020-06-14 00:04:15.504964)" (scheduled at 2020-06-14 00:04:15.504964)
2020-06-14 00:04:15,507 - _main_loop - 588 - DEBUG - Next wakeup is due at 2020-06-14 03:00:00 (in 10544.493135 seconds)
2020-06-14 00:04:15,829 - _run_job - 520 - ERROR - Job "regulartime_task (trigger: interval[1 day, 0:00:00], next run at: 2020-06-15 00:04:15.504964)" raised an exception
Traceback (most recent call last):
  File "D:\Program Files\Python37\lib\site-packages\django\db\backends\utils.py", line 84, in _execute
    return self.cursor.execute(sql, params)
  File "D:\Program Files\Python37\lib\site-packages\django\db\backends\mysql\base.py", line 71, in execute
    return self.cursor.execute(query, args)
  File "D:\Program Files\Python37\lib\site-packages\MySQLdb\cursors.py", line 209, in execute
    res = self._query(query)
  File "D:\Program Files\Python37\lib\site-packages\MySQLdb\cursors.py", line 315, in _query
    db.query(q)
  File "D:\Program Files\Python37\lib\site-packages\MySQLdb\connections.py", line 239, in query
    _mysql.connection.query(self, query)
MySQLdb._exceptions.IntegrityError: (1062, "Duplicate entry '1592150400' for key 'LAMProcessData_process_r_acquisition_timestamp_a69ae90c_uniq'")

The above exception was the direct cause of the following exception:

Traceback (most recent call last):
  File "D:\Program Files\Python37\lib\site-packages\apscheduler\scheduler.py", line 512, in _run_job
    retval = job.func(*job.args, **job.kwargs)
  File "E:\1-program\11-LAMDataServer\lamdataserver\LAMProcessData\views.py", line 5662, in regulartime_task
    RT_FineData.Realtime_FineData.init_Tomorrow_rows()
  File "E:\1-program\11-LAMDataServer\lamdataserver\LAMProcessData\process_realtime_finedata.py", line 193, in init_Tomorrow_rows
    _model.objects.bulk_create(insert_data_list)
  File "D:\Program Files\Python37\lib\site-packages\django\db\models\manager.py", line 82, in manager_method
    return getattr(self.get_queryset(), name)(*args, **kwargs)
  File "D:\Program Files\Python37\lib\site-packages\django\db\models\query.py", line 474, in bulk_create
    ids = self._batched_insert(objs_without_pk, fields, batch_size, ignore_conflicts=ignore_conflicts)
  File "D:\Program Files\Python37\lib\site-packages\django\db\models\query.py", line 1211, in _batched_insert
    self._insert(item, fields=fields, using=self.db, ignore_conflicts=ignore_conflicts)
  File "D:\Program Files\Python37\lib\site-packages\django\db\models\query.py", line 1186, in _insert
    return query.get_compiler(using=using).execute_sql(return_id)
  File "D:\Program Files\Python37\lib\site-packages\django\db\models\sql\compiler.py", line 1332, in execute_sql
    cursor.execute(sql, params)
  File "D:\Program Files\Python37\lib\site-packages\django\db\backends\utils.py", line 99, in execute
    return super().execute(sql, params)
  File "D:\Program Files\Python37\lib\site-packages\django\db\backends\utils.py", line 67, in execute
    return self._execute_with_wrappers(sql, params, many=False, executor=self._execute)
  File "D:\Program Files\Python37\lib\site-packages\django\db\backends\utils.py", line 76, in _execute_with_wrappers
    return executor(sql, params, many, context)
  File "D:\Program Files\Python37\lib\site-packages\django\db\backends\utils.py", line 84, in _execute
    return self.cursor.execute(sql, params)
  File "D:\Program Files\Python37\lib\site-packages\django\db\utils.py", line 89, in __exit__
    raise dj_exc_value.with_traceback(traceback) from exc_value
  File "D:\Program Files\Python37\lib\site-packages\django\db\backends\utils.py", line 84, in _execute
    return self.cursor.execute(sql, params)
  File "D:\Program Files\Python37\lib\site-packages\django\db\backends\mysql\base.py", line 71, in execute
    return self.cursor.execute(query, args)
  File "D:\Program Files\Python37\lib\site-packages\MySQLdb\cursors.py", line 209, in execute
    res = self._query(query)
  File "D:\Program Files\Python37\lib\site-packages\MySQLdb\cursors.py", line 315, in _query
    db.query(q)
  File "D:\Program Files\Python37\lib\site-packages\MySQLdb\connections.py", line 239, in query
    _mysql.connection.query(self, query)
django.db.utils.IntegrityError: (1062, "Duplicate entry '1592150400' for key 'LAMProcessData_process_r_acquisition_timestamp_a69ae90c_uniq'")
2020-06-14 00:04:16,836 - _run_jobs - 94 - DEBUG - Exiting worker thread
2020-06-14 00:04:20,566 - trigger_reload - 203 - INFO - E:\1-program\11-LAMDataServer\lamdataserver\LAMProcessData\forms.py changed, reloading.
2020-06-14 00:04:20,567 - shutdown - 111 - INFO - Shutting down thread pool
2020-06-14 00:04:26,871 - _real_add_job - 262 - INFO - Added job "regulartime_task (trigger: interval[1 day, 0:00:00], next run at: 2020-06-14 00:04:36.870053)" to job store "default"
2020-06-14 00:04:26,871 - _real_add_job - 262 - INFO - Added job "cleanup (trigger: cron[day_of_week='*', hour='3', minute='0', second='0'], next run at: 2020-06-14 03:00:00)" to job store "default"
2020-06-14 00:04:26,872 - _real_add_job - 262 - INFO - Added job "OpenLog (trigger: cron[hour='0'], next run at: 2020-06-15 00:00:00)" to job store "default"
2020-06-14 00:04:26,872 - _main_loop - 574 - INFO - Scheduler started
2020-06-14 00:04:26,872 - _main_loop - 579 - DEBUG - Looking for jobs to run
2020-06-14 00:04:26,872 - _main_loop - 588 - DEBUG - Next wakeup is due at 2020-06-14 00:04:36.870053 (in 9.998014 seconds)
2020-06-14 00:04:26,882 - <module> - 63 - DEBUG - SendBefore_NotRecive : [<CNCProcessStatus: CNCProcessStatus object (2038721)>]
2020-06-14 00:04:26,882 - <module> - 64 - DEBUG - Waitfor_Recive : [2038721]
2020-06-14 00:04:36,888 - _main_loop - 579 - DEBUG - Looking for jobs to run
2020-06-14 00:04:36,895 - _run_jobs - 69 - DEBUG - Started worker thread
2020-06-14 00:04:36,895 - _main_loop - 588 - DEBUG - Next wakeup is due at 2020-06-14 03:00:00 (in 10523.111354 seconds)
2020-06-14 00:04:36,895 - _run_job - 509 - INFO - Running job "regulartime_task (trigger: interval[1 day, 0:00:00], next run at: 2020-06-15 00:04:36.870053)" (scheduled at 2020-06-14 00:04:36.870053)
2020-06-14 00:04:37,290 - _run_job - 520 - ERROR - Job "regulartime_task (trigger: interval[1 day, 0:00:00], next run at: 2020-06-15 00:04:36.870053)" raised an exception
Traceback (most recent call last):
  File "D:\Program Files\Python37\lib\site-packages\django\db\backends\utils.py", line 84, in _execute
    return self.cursor.execute(sql, params)
  File "D:\Program Files\Python37\lib\site-packages\django\db\backends\mysql\base.py", line 71, in execute
    return self.cursor.execute(query, args)
  File "D:\Program Files\Python37\lib\site-packages\MySQLdb\cursors.py", line 209, in execute
    res = self._query(query)
  File "D:\Program Files\Python37\lib\site-packages\MySQLdb\cursors.py", line 315, in _query
    db.query(q)
  File "D:\Program Files\Python37\lib\site-packages\MySQLdb\connections.py", line 239, in query
    _mysql.connection.query(self, query)
MySQLdb._exceptions.IntegrityError: (1062, "Duplicate entry '1592150400' for key 'LAMProcessData_process_r_acquisition_timestamp_a69ae90c_uniq'")

The above exception was the direct cause of the following exception:

Traceback (most recent call last):
  File "D:\Program Files\Python37\lib\site-packages\apscheduler\scheduler.py", line 512, in _run_job
    retval = job.func(*job.args, **job.kwargs)
  File "E:\1-program\11-LAMDataServer\lamdataserver\LAMProcessData\views.py", line 5662, in regulartime_task
    RT_FineData.Realtime_FineData.init_Tomorrow_rows()
  File "E:\1-program\11-LAMDataServer\lamdataserver\LAMProcessData\process_realtime_finedata.py", line 193, in init_Tomorrow_rows
    _model.objects.bulk_create(insert_data_list)
  File "D:\Program Files\Python37\lib\site-packages\django\db\models\manager.py", line 82, in manager_method
    return getattr(self.get_queryset(), name)(*args, **kwargs)
  File "D:\Program Files\Python37\lib\site-packages\django\db\models\query.py", line 474, in bulk_create
    ids = self._batched_insert(objs_without_pk, fields, batch_size, ignore_conflicts=ignore_conflicts)
  File "D:\Program Files\Python37\lib\site-packages\django\db\models\query.py", line 1211, in _batched_insert
    self._insert(item, fields=fields, using=self.db, ignore_conflicts=ignore_conflicts)
  File "D:\Program Files\Python37\lib\site-packages\django\db\models\query.py", line 1186, in _insert
    return query.get_compiler(using=using).execute_sql(return_id)
  File "D:\Program Files\Python37\lib\site-packages\django\db\models\sql\compiler.py", line 1332, in execute_sql
    cursor.execute(sql, params)
  File "D:\Program Files\Python37\lib\site-packages\django\db\backends\utils.py", line 99, in execute
    return super().execute(sql, params)
  File "D:\Program Files\Python37\lib\site-packages\django\db\backends\utils.py", line 67, in execute
    return self._execute_with_wrappers(sql, params, many=False, executor=self._execute)
  File "D:\Program Files\Python37\lib\site-packages\django\db\backends\utils.py", line 76, in _execute_with_wrappers
    return executor(sql, params, many, context)
  File "D:\Program Files\Python37\lib\site-packages\django\db\backends\utils.py", line 84, in _execute
    return self.cursor.execute(sql, params)
  File "D:\Program Files\Python37\lib\site-packages\django\db\utils.py", line 89, in __exit__
    raise dj_exc_value.with_traceback(traceback) from exc_value
  File "D:\Program Files\Python37\lib\site-packages\django\db\backends\utils.py", line 84, in _execute
    return self.cursor.execute(sql, params)
  File "D:\Program Files\Python37\lib\site-packages\django\db\backends\mysql\base.py", line 71, in execute
    return self.cursor.execute(query, args)
  File "D:\Program Files\Python37\lib\site-packages\MySQLdb\cursors.py", line 209, in execute
    res = self._query(query)
  File "D:\Program Files\Python37\lib\site-packages\MySQLdb\cursors.py", line 315, in _query
    db.query(q)
  File "D:\Program Files\Python37\lib\site-packages\MySQLdb\connections.py", line 239, in query
    _mysql.connection.query(self, query)
django.db.utils.IntegrityError: (1062, "Duplicate entry '1592150400' for key 'LAMProcessData_process_r_acquisition_timestamp_a69ae90c_uniq'")
2020-06-14 00:04:38,373 - _run_jobs - 94 - DEBUG - Exiting worker thread
2020-06-14 00:04:40,625 - trigger_reload - 203 - INFO - E:\1-program\11-LAMDataServer\lamdataserver\LAMProcessData\forms.py changed, reloading.
2020-06-14 00:04:40,625 - shutdown - 111 - INFO - Shutting down thread pool
2020-06-14 00:04:44,633 - _real_add_job - 262 - INFO - Added job "regulartime_task (trigger: interval[1 day, 0:00:00], next run at: 2020-06-14 00:04:54.631895)" to job store "default"
2020-06-14 00:04:44,633 - _real_add_job - 262 - INFO - Added job "cleanup (trigger: cron[day_of_week='*', hour='3', minute='0', second='0'], next run at: 2020-06-14 03:00:00)" to job store "default"
2020-06-14 00:04:44,633 - _real_add_job - 262 - INFO - Added job "OpenLog (trigger: cron[hour='0'], next run at: 2020-06-15 00:00:00)" to job store "default"
2020-06-14 00:04:44,634 - _main_loop - 574 - INFO - Scheduler started
2020-06-14 00:04:44,634 - _main_loop - 579 - DEBUG - Looking for jobs to run
2020-06-14 00:04:44,634 - _main_loop - 588 - DEBUG - Next wakeup is due at 2020-06-14 00:04:54.631895 (in 9.997011 seconds)
2020-06-14 00:04:44,645 - <module> - 63 - DEBUG - SendBefore_NotRecive : [<CNCProcessStatus: CNCProcessStatus object (2038721)>]
2020-06-14 00:04:44,645 - <module> - 64 - DEBUG - Waitfor_Recive : [2038721]
2020-06-14 00:04:45,989 - trigger_reload - 203 - INFO - E:\1-program\11-LAMDataServer\lamdataserver\LAMProcessData\forms.py changed, reloading.
2020-06-14 00:04:45,990 - shutdown - 111 - INFO - Shutting down thread pool
2020-06-14 00:04:52,440 - _real_add_job - 262 - INFO - Added job "regulartime_task (trigger: interval[1 day, 0:00:00], next run at: 2020-06-14 00:05:02.439739)" to job store "default"
2020-06-14 00:04:52,441 - _real_add_job - 262 - INFO - Added job "cleanup (trigger: cron[day_of_week='*', hour='3', minute='0', second='0'], next run at: 2020-06-14 03:00:00)" to job store "default"
2020-06-14 00:04:52,441 - _real_add_job - 262 - INFO - Added job "OpenLog (trigger: cron[hour='0'], next run at: 2020-06-15 00:00:00)" to job store "default"
2020-06-14 00:04:52,441 - _main_loop - 574 - INFO - Scheduler started
2020-06-14 00:04:52,442 - _main_loop - 579 - DEBUG - Looking for jobs to run
2020-06-14 00:04:52,442 - _main_loop - 588 - DEBUG - Next wakeup is due at 2020-06-14 00:05:02.439739 (in 9.997008 seconds)
2020-06-14 00:04:52,452 - <module> - 63 - DEBUG - SendBefore_NotRecive : [<CNCProcessStatus: CNCProcessStatus object (2038721)>]
2020-06-14 00:04:52,452 - <module> - 64 - DEBUG - Waitfor_Recive : [2038721]
2020-06-14 00:05:02,440 - _main_loop - 579 - DEBUG - Looking for jobs to run
2020-06-14 00:05:02,441 - _run_jobs - 69 - DEBUG - Started worker thread
2020-06-14 00:05:02,441 - _main_loop - 588 - DEBUG - Next wakeup is due at 2020-06-14 03:00:00 (in 10497.559049 seconds)
2020-06-14 00:05:02,441 - _run_job - 509 - INFO - Running job "regulartime_task (trigger: interval[1 day, 0:00:00], next run at: 2020-06-15 00:05:02.439739)" (scheduled at 2020-06-14 00:05:02.439739)
2020-06-14 00:05:02,774 - _run_job - 520 - ERROR - Job "regulartime_task (trigger: interval[1 day, 0:00:00], next run at: 2020-06-15 00:05:02.439739)" raised an exception
Traceback (most recent call last):
  File "D:\Program Files\Python37\lib\site-packages\django\db\backends\utils.py", line 84, in _execute
    return self.cursor.execute(sql, params)
  File "D:\Program Files\Python37\lib\site-packages\django\db\backends\mysql\base.py", line 71, in execute
    return self.cursor.execute(query, args)
  File "D:\Program Files\Python37\lib\site-packages\MySQLdb\cursors.py", line 209, in execute
    res = self._query(query)
  File "D:\Program Files\Python37\lib\site-packages\MySQLdb\cursors.py", line 315, in _query
    db.query(q)
  File "D:\Program Files\Python37\lib\site-packages\MySQLdb\connections.py", line 239, in query
    _mysql.connection.query(self, query)
MySQLdb._exceptions.IntegrityError: (1062, "Duplicate entry '1592150400' for key 'LAMProcessData_process_r_acquisition_timestamp_a69ae90c_uniq'")

The above exception was the direct cause of the following exception:

Traceback (most recent call last):
  File "D:\Program Files\Python37\lib\site-packages\apscheduler\scheduler.py", line 512, in _run_job
    retval = job.func(*job.args, **job.kwargs)
  File "E:\1-program\11-LAMDataServer\lamdataserver\LAMProcessData\views.py", line 5662, in regulartime_task
    RT_FineData.Realtime_FineData.init_Tomorrow_rows()
  File "E:\1-program\11-LAMDataServer\lamdataserver\LAMProcessData\process_realtime_finedata.py", line 193, in init_Tomorrow_rows
    _model.objects.bulk_create(insert_data_list)
  File "D:\Program Files\Python37\lib\site-packages\django\db\models\manager.py", line 82, in manager_method
    return getattr(self.get_queryset(), name)(*args, **kwargs)
  File "D:\Program Files\Python37\lib\site-packages\django\db\models\query.py", line 474, in bulk_create
    ids = self._batched_insert(objs_without_pk, fields, batch_size, ignore_conflicts=ignore_conflicts)
  File "D:\Program Files\Python37\lib\site-packages\django\db\models\query.py", line 1211, in _batched_insert
    self._insert(item, fields=fields, using=self.db, ignore_conflicts=ignore_conflicts)
  File "D:\Program Files\Python37\lib\site-packages\django\db\models\query.py", line 1186, in _insert
    return query.get_compiler(using=using).execute_sql(return_id)
  File "D:\Program Files\Python37\lib\site-packages\django\db\models\sql\compiler.py", line 1332, in execute_sql
    cursor.execute(sql, params)
  File "D:\Program Files\Python37\lib\site-packages\django\db\backends\utils.py", line 99, in execute
    return super().execute(sql, params)
  File "D:\Program Files\Python37\lib\site-packages\django\db\backends\utils.py", line 67, in execute
    return self._execute_with_wrappers(sql, params, many=False, executor=self._execute)
  File "D:\Program Files\Python37\lib\site-packages\django\db\backends\utils.py", line 76, in _execute_with_wrappers
    return executor(sql, params, many, context)
  File "D:\Program Files\Python37\lib\site-packages\django\db\backends\utils.py", line 84, in _execute
    return self.cursor.execute(sql, params)
  File "D:\Program Files\Python37\lib\site-packages\django\db\utils.py", line 89, in __exit__
    raise dj_exc_value.with_traceback(traceback) from exc_value
  File "D:\Program Files\Python37\lib\site-packages\django\db\backends\utils.py", line 84, in _execute
    return self.cursor.execute(sql, params)
  File "D:\Program Files\Python37\lib\site-packages\django\db\backends\mysql\base.py", line 71, in execute
    return self.cursor.execute(query, args)
  File "D:\Program Files\Python37\lib\site-packages\MySQLdb\cursors.py", line 209, in execute
    res = self._query(query)
  File "D:\Program Files\Python37\lib\site-packages\MySQLdb\cursors.py", line 315, in _query
    db.query(q)
  File "D:\Program Files\Python37\lib\site-packages\MySQLdb\connections.py", line 239, in query
    _mysql.connection.query(self, query)
django.db.utils.IntegrityError: (1062, "Duplicate entry '1592150400' for key 'LAMProcessData_process_r_acquisition_timestamp_a69ae90c_uniq'")
2020-06-14 00:05:03,781 - _run_jobs - 94 - DEBUG - Exiting worker thread
2020-06-14 00:18:26,885 - _real_add_job - 262 - INFO - Added job "regulartime_task (trigger: interval[1 day, 0:00:00], next run at: 2020-06-14 00:18:36.884338)" to job store "default"
2020-06-14 00:18:26,885 - _real_add_job - 262 - INFO - Added job "cleanup (trigger: cron[day_of_week='*', hour='3', minute='0', second='0'], next run at: 2020-06-14 03:00:00)" to job store "default"
2020-06-14 00:18:26,886 - _real_add_job - 262 - INFO - Added job "OpenLog (trigger: cron[hour='0'], next run at: 2020-06-15 00:00:00)" to job store "default"
2020-06-14 00:18:26,886 - _main_loop - 574 - INFO - Scheduler started
2020-06-14 00:18:26,886 - _main_loop - 579 - DEBUG - Looking for jobs to run
2020-06-14 00:18:26,886 - _main_loop - 588 - DEBUG - Next wakeup is due at 2020-06-14 00:18:36.884338 (in 9.998003 seconds)
2020-06-14 00:18:26,896 - <module> - 63 - DEBUG - SendBefore_NotRecive : [<CNCProcessStatus: CNCProcessStatus object (2038721)>]
2020-06-14 00:18:26,896 - <module> - 64 - DEBUG - Waitfor_Recive : [2038721]
2020-06-14 00:18:36,887 - _main_loop - 579 - DEBUG - Looking for jobs to run
2020-06-14 00:18:36,887 - _run_jobs - 69 - DEBUG - Started worker thread
2020-06-14 00:18:36,888 - _main_loop - 588 - DEBUG - Next wakeup is due at 2020-06-14 03:00:00 (in 9683.112738 seconds)
2020-06-14 00:18:36,888 - _run_job - 509 - INFO - Running job "regulartime_task (trigger: interval[1 day, 0:00:00], next run at: 2020-06-15 00:18:36.884338)" (scheduled at 2020-06-14 00:18:36.884338)
2020-06-14 00:18:37,230 - _run_job - 520 - ERROR - Job "regulartime_task (trigger: interval[1 day, 0:00:00], next run at: 2020-06-15 00:18:36.884338)" raised an exception
Traceback (most recent call last):
  File "D:\Program Files\Python37\lib\site-packages\django\db\backends\utils.py", line 84, in _execute
    return self.cursor.execute(sql, params)
  File "D:\Program Files\Python37\lib\site-packages\django\db\backends\mysql\base.py", line 71, in execute
    return self.cursor.execute(query, args)
  File "D:\Program Files\Python37\lib\site-packages\MySQLdb\cursors.py", line 209, in execute
    res = self._query(query)
  File "D:\Program Files\Python37\lib\site-packages\MySQLdb\cursors.py", line 315, in _query
    db.query(q)
  File "D:\Program Files\Python37\lib\site-packages\MySQLdb\connections.py", line 239, in query
    _mysql.connection.query(self, query)
MySQLdb._exceptions.IntegrityError: (1062, "Duplicate entry '1592150400' for key 'LAMProcessData_process_r_acquisition_timestamp_a69ae90c_uniq'")

The above exception was the direct cause of the following exception:

Traceback (most recent call last):
  File "D:\Program Files\Python37\lib\site-packages\apscheduler\scheduler.py", line 512, in _run_job
    retval = job.func(*job.args, **job.kwargs)
  File "E:\1-program\11-LAMDataServer\lamdataserver\LAMProcessData\views.py", line 5662, in regulartime_task
    RT_FineData.Realtime_FineData.init_Tomorrow_rows()
  File "E:\1-program\11-LAMDataServer\lamdataserver\LAMProcessData\process_realtime_finedata.py", line 193, in init_Tomorrow_rows
    _model.objects.bulk_create(insert_data_list)
  File "D:\Program Files\Python37\lib\site-packages\django\db\models\manager.py", line 82, in manager_method
    return getattr(self.get_queryset(), name)(*args, **kwargs)
  File "D:\Program Files\Python37\lib\site-packages\django\db\models\query.py", line 474, in bulk_create
    ids = self._batched_insert(objs_without_pk, fields, batch_size, ignore_conflicts=ignore_conflicts)
  File "D:\Program Files\Python37\lib\site-packages\django\db\models\query.py", line 1211, in _batched_insert
    self._insert(item, fields=fields, using=self.db, ignore_conflicts=ignore_conflicts)
  File "D:\Program Files\Python37\lib\site-packages\django\db\models\query.py", line 1186, in _insert
    return query.get_compiler(using=using).execute_sql(return_id)
  File "D:\Program Files\Python37\lib\site-packages\django\db\models\sql\compiler.py", line 1332, in execute_sql
    cursor.execute(sql, params)
  File "D:\Program Files\Python37\lib\site-packages\django\db\backends\utils.py", line 99, in execute
    return super().execute(sql, params)
  File "D:\Program Files\Python37\lib\site-packages\django\db\backends\utils.py", line 67, in execute
    return self._execute_with_wrappers(sql, params, many=False, executor=self._execute)
  File "D:\Program Files\Python37\lib\site-packages\django\db\backends\utils.py", line 76, in _execute_with_wrappers
    return executor(sql, params, many, context)
  File "D:\Program Files\Python37\lib\site-packages\django\db\backends\utils.py", line 84, in _execute
    return self.cursor.execute(sql, params)
  File "D:\Program Files\Python37\lib\site-packages\django\db\utils.py", line 89, in __exit__
    raise dj_exc_value.with_traceback(traceback) from exc_value
  File "D:\Program Files\Python37\lib\site-packages\django\db\backends\utils.py", line 84, in _execute
    return self.cursor.execute(sql, params)
  File "D:\Program Files\Python37\lib\site-packages\django\db\backends\mysql\base.py", line 71, in execute
    return self.cursor.execute(query, args)
  File "D:\Program Files\Python37\lib\site-packages\MySQLdb\cursors.py", line 209, in execute
    res = self._query(query)
  File "D:\Program Files\Python37\lib\site-packages\MySQLdb\cursors.py", line 315, in _query
    db.query(q)
  File "D:\Program Files\Python37\lib\site-packages\MySQLdb\connections.py", line 239, in query
    _mysql.connection.query(self, query)
django.db.utils.IntegrityError: (1062, "Duplicate entry '1592150400' for key 'LAMProcessData_process_r_acquisition_timestamp_a69ae90c_uniq'")
2020-06-14 00:18:38,234 - _run_jobs - 94 - DEBUG - Exiting worker thread
2020-06-14 00:22:18,755 - trigger_reload - 203 - INFO - E:\1-program\11-LAMDataServer\lamdataserver\LAMProcessData\forms.py changed, reloading.
2020-06-14 00:22:18,756 - shutdown - 111 - INFO - Shutting down thread pool
2020-06-14 00:22:22,191 - _real_add_job - 262 - INFO - Added job "regulartime_task (trigger: interval[1 day, 0:00:00], next run at: 2020-06-14 00:22:32.190211)" to job store "default"
2020-06-14 00:22:22,191 - _real_add_job - 262 - INFO - Added job "cleanup (trigger: cron[day_of_week='*', hour='3', minute='0', second='0'], next run at: 2020-06-14 03:00:00)" to job store "default"
2020-06-14 00:22:22,191 - _real_add_job - 262 - INFO - Added job "OpenLog (trigger: cron[hour='0'], next run at: 2020-06-15 00:00:00)" to job store "default"
2020-06-14 00:22:22,192 - _main_loop - 574 - INFO - Scheduler started
2020-06-14 00:22:22,192 - _main_loop - 579 - DEBUG - Looking for jobs to run
2020-06-14 00:22:22,192 - _main_loop - 588 - DEBUG - Next wakeup is due at 2020-06-14 00:22:32.190211 (in 9.998037 seconds)
2020-06-14 00:22:22,202 - <module> - 63 - DEBUG - SendBefore_NotRecive : [<CNCProcessStatus: CNCProcessStatus object (2038721)>]
2020-06-14 00:22:22,203 - <module> - 64 - DEBUG - Waitfor_Recive : [2038721]
2020-06-14 00:22:32,192 - _main_loop - 579 - DEBUG - Looking for jobs to run
2020-06-14 00:22:32,192 - _run_jobs - 69 - DEBUG - Started worker thread
2020-06-14 00:22:32,192 - _run_job - 509 - INFO - Running job "regulartime_task (trigger: interval[1 day, 0:00:00], next run at: 2020-06-14 00:22:32.190211)" (scheduled at 2020-06-14 00:22:32.190211)
2020-06-14 00:22:32,192 - _main_loop - 588 - DEBUG - Next wakeup is due at 2020-06-14 03:00:00 (in 9447.807917 seconds)
2020-06-14 00:22:32,514 - _run_job - 520 - ERROR - Job "regulartime_task (trigger: interval[1 day, 0:00:00], next run at: 2020-06-15 00:22:32.190211)" raised an exception
Traceback (most recent call last):
  File "D:\Program Files\Python37\lib\site-packages\django\db\backends\utils.py", line 84, in _execute
    return self.cursor.execute(sql, params)
  File "D:\Program Files\Python37\lib\site-packages\django\db\backends\mysql\base.py", line 71, in execute
    return self.cursor.execute(query, args)
  File "D:\Program Files\Python37\lib\site-packages\MySQLdb\cursors.py", line 209, in execute
    res = self._query(query)
  File "D:\Program Files\Python37\lib\site-packages\MySQLdb\cursors.py", line 315, in _query
    db.query(q)
  File "D:\Program Files\Python37\lib\site-packages\MySQLdb\connections.py", line 239, in query
    _mysql.connection.query(self, query)
MySQLdb._exceptions.IntegrityError: (1062, "Duplicate entry '1592150400' for key 'LAMProcessData_process_r_acquisition_timestamp_a69ae90c_uniq'")

The above exception was the direct cause of the following exception:

Traceback (most recent call last):
  File "D:\Program Files\Python37\lib\site-packages\apscheduler\scheduler.py", line 512, in _run_job
    retval = job.func(*job.args, **job.kwargs)
  File "E:\1-program\11-LAMDataServer\lamdataserver\LAMProcessData\views.py", line 5662, in regulartime_task
    RT_FineData.Realtime_FineData.init_Tomorrow_rows()
  File "E:\1-program\11-LAMDataServer\lamdataserver\LAMProcessData\process_realtime_finedata.py", line 193, in init_Tomorrow_rows
    _model.objects.bulk_create(insert_data_list)
  File "D:\Program Files\Python37\lib\site-packages\django\db\models\manager.py", line 82, in manager_method
    return getattr(self.get_queryset(), name)(*args, **kwargs)
  File "D:\Program Files\Python37\lib\site-packages\django\db\models\query.py", line 474, in bulk_create
    ids = self._batched_insert(objs_without_pk, fields, batch_size, ignore_conflicts=ignore_conflicts)
  File "D:\Program Files\Python37\lib\site-packages\django\db\models\query.py", line 1211, in _batched_insert
    self._insert(item, fields=fields, using=self.db, ignore_conflicts=ignore_conflicts)
  File "D:\Program Files\Python37\lib\site-packages\django\db\models\query.py", line 1186, in _insert
    return query.get_compiler(using=using).execute_sql(return_id)
  File "D:\Program Files\Python37\lib\site-packages\django\db\models\sql\compiler.py", line 1332, in execute_sql
    cursor.execute(sql, params)
  File "D:\Program Files\Python37\lib\site-packages\django\db\backends\utils.py", line 99, in execute
    return super().execute(sql, params)
  File "D:\Program Files\Python37\lib\site-packages\django\db\backends\utils.py", line 67, in execute
    return self._execute_with_wrappers(sql, params, many=False, executor=self._execute)
  File "D:\Program Files\Python37\lib\site-packages\django\db\backends\utils.py", line 76, in _execute_with_wrappers
    return executor(sql, params, many, context)
  File "D:\Program Files\Python37\lib\site-packages\django\db\backends\utils.py", line 84, in _execute
    return self.cursor.execute(sql, params)
  File "D:\Program Files\Python37\lib\site-packages\django\db\utils.py", line 89, in __exit__
    raise dj_exc_value.with_traceback(traceback) from exc_value
  File "D:\Program Files\Python37\lib\site-packages\django\db\backends\utils.py", line 84, in _execute
    return self.cursor.execute(sql, params)
  File "D:\Program Files\Python37\lib\site-packages\django\db\backends\mysql\base.py", line 71, in execute
    return self.cursor.execute(query, args)
  File "D:\Program Files\Python37\lib\site-packages\MySQLdb\cursors.py", line 209, in execute
    res = self._query(query)
  File "D:\Program Files\Python37\lib\site-packages\MySQLdb\cursors.py", line 315, in _query
    db.query(q)
  File "D:\Program Files\Python37\lib\site-packages\MySQLdb\connections.py", line 239, in query
    _mysql.connection.query(self, query)
django.db.utils.IntegrityError: (1062, "Duplicate entry '1592150400' for key 'LAMProcessData_process_r_acquisition_timestamp_a69ae90c_uniq'")
2020-06-14 00:22:33,520 - _run_jobs - 94 - DEBUG - Exiting worker thread
2020-06-14 00:24:21,333 - _real_add_job - 262 - INFO - Added job "regulartime_task (trigger: interval[1 day, 0:00:00], next run at: 2020-06-14 00:24:31.332967)" to job store "default"
2020-06-14 00:24:21,333 - _real_add_job - 262 - INFO - Added job "cleanup (trigger: cron[day_of_week='*', hour='3', minute='0', second='0'], next run at: 2020-06-14 03:00:00)" to job store "default"
2020-06-14 00:24:21,333 - _real_add_job - 262 - INFO - Added job "OpenLog (trigger: cron[hour='0'], next run at: 2020-06-15 00:00:00)" to job store "default"
2020-06-14 00:24:21,334 - _main_loop - 574 - INFO - Scheduler started
2020-06-14 00:24:21,334 - _main_loop - 579 - DEBUG - Looking for jobs to run
2020-06-14 00:24:21,334 - _main_loop - 588 - DEBUG - Next wakeup is due at 2020-06-14 00:24:31.332967 (in 9.998006 seconds)
2020-06-14 00:24:21,344 - <module> - 63 - DEBUG - SendBefore_NotRecive : [<CNCProcessStatus: CNCProcessStatus object (2038721)>]
2020-06-14 00:24:21,344 - <module> - 64 - DEBUG - Waitfor_Recive : [2038721]
2020-06-14 00:24:31,335 - _main_loop - 579 - DEBUG - Looking for jobs to run
2020-06-14 00:24:31,335 - _run_jobs - 69 - DEBUG - Started worker thread
2020-06-14 00:24:31,336 - _main_loop - 588 - DEBUG - Next wakeup is due at 2020-06-14 03:00:00 (in 9328.664958 seconds)
2020-06-14 00:24:31,336 - _run_job - 509 - INFO - Running job "regulartime_task (trigger: interval[1 day, 0:00:00], next run at: 2020-06-15 00:24:31.332967)" (scheduled at 2020-06-14 00:24:31.332967)
2020-06-14 00:24:31,667 - _run_job - 520 - ERROR - Job "regulartime_task (trigger: interval[1 day, 0:00:00], next run at: 2020-06-15 00:24:31.332967)" raised an exception
Traceback (most recent call last):
  File "D:\Program Files\Python37\lib\site-packages\django\db\backends\utils.py", line 84, in _execute
    return self.cursor.execute(sql, params)
  File "D:\Program Files\Python37\lib\site-packages\django\db\backends\mysql\base.py", line 71, in execute
    return self.cursor.execute(query, args)
  File "D:\Program Files\Python37\lib\site-packages\MySQLdb\cursors.py", line 209, in execute
    res = self._query(query)
  File "D:\Program Files\Python37\lib\site-packages\MySQLdb\cursors.py", line 315, in _query
    db.query(q)
  File "D:\Program Files\Python37\lib\site-packages\MySQLdb\connections.py", line 239, in query
    _mysql.connection.query(self, query)
MySQLdb._exceptions.IntegrityError: (1062, "Duplicate entry '1592150400' for key 'LAMProcessData_process_r_acquisition_timestamp_a69ae90c_uniq'")

The above exception was the direct cause of the following exception:

Traceback (most recent call last):
  File "D:\Program Files\Python37\lib\site-packages\apscheduler\scheduler.py", line 512, in _run_job
    retval = job.func(*job.args, **job.kwargs)
  File "E:\1-program\11-LAMDataServer\lamdataserver\LAMProcessData\views.py", line 5662, in regulartime_task
    RT_FineData.Realtime_FineData.init_Tomorrow_rows()
  File "E:\1-program\11-LAMDataServer\lamdataserver\LAMProcessData\process_realtime_finedata.py", line 193, in init_Tomorrow_rows
    _model.objects.bulk_create(insert_data_list)
  File "D:\Program Files\Python37\lib\site-packages\django\db\models\manager.py", line 82, in manager_method
    return getattr(self.get_queryset(), name)(*args, **kwargs)
  File "D:\Program Files\Python37\lib\site-packages\django\db\models\query.py", line 474, in bulk_create
    ids = self._batched_insert(objs_without_pk, fields, batch_size, ignore_conflicts=ignore_conflicts)
  File "D:\Program Files\Python37\lib\site-packages\django\db\models\query.py", line 1211, in _batched_insert
    self._insert(item, fields=fields, using=self.db, ignore_conflicts=ignore_conflicts)
  File "D:\Program Files\Python37\lib\site-packages\django\db\models\query.py", line 1186, in _insert
    return query.get_compiler(using=using).execute_sql(return_id)
  File "D:\Program Files\Python37\lib\site-packages\django\db\models\sql\compiler.py", line 1332, in execute_sql
    cursor.execute(sql, params)
  File "D:\Program Files\Python37\lib\site-packages\django\db\backends\utils.py", line 99, in execute
    return super().execute(sql, params)
  File "D:\Program Files\Python37\lib\site-packages\django\db\backends\utils.py", line 67, in execute
    return self._execute_with_wrappers(sql, params, many=False, executor=self._execute)
  File "D:\Program Files\Python37\lib\site-packages\django\db\backends\utils.py", line 76, in _execute_with_wrappers
    return executor(sql, params, many, context)
  File "D:\Program Files\Python37\lib\site-packages\django\db\backends\utils.py", line 84, in _execute
    return self.cursor.execute(sql, params)
  File "D:\Program Files\Python37\lib\site-packages\django\db\utils.py", line 89, in __exit__
    raise dj_exc_value.with_traceback(traceback) from exc_value
  File "D:\Program Files\Python37\lib\site-packages\django\db\backends\utils.py", line 84, in _execute
    return self.cursor.execute(sql, params)
  File "D:\Program Files\Python37\lib\site-packages\django\db\backends\mysql\base.py", line 71, in execute
    return self.cursor.execute(query, args)
  File "D:\Program Files\Python37\lib\site-packages\MySQLdb\cursors.py", line 209, in execute
    res = self._query(query)
  File "D:\Program Files\Python37\lib\site-packages\MySQLdb\cursors.py", line 315, in _query
    db.query(q)
  File "D:\Program Files\Python37\lib\site-packages\MySQLdb\connections.py", line 239, in query
    _mysql.connection.query(self, query)
django.db.utils.IntegrityError: (1062, "Duplicate entry '1592150400' for key 'LAMProcessData_process_r_acquisition_timestamp_a69ae90c_uniq'")
2020-06-14 00:24:32,671 - _run_jobs - 94 - DEBUG - Exiting worker thread
2020-06-14 00:29:54,599 - _real_add_job - 262 - INFO - Added job "regulartime_task (trigger: interval[1 day, 0:00:00], next run at: 2020-06-14 00:30:04.597923)" to job store "default"
2020-06-14 00:29:54,599 - _real_add_job - 262 - INFO - Added job "cleanup (trigger: cron[day_of_week='*', hour='3', minute='0', second='0'], next run at: 2020-06-14 03:00:00)" to job store "default"
2020-06-14 00:29:54,599 - _real_add_job - 262 - INFO - Added job "OpenLog (trigger: cron[hour='0'], next run at: 2020-06-15 00:00:00)" to job store "default"
2020-06-14 00:29:54,600 - _main_loop - 574 - INFO - Scheduler started
2020-06-14 00:29:54,600 - _main_loop - 579 - DEBUG - Looking for jobs to run
2020-06-14 00:29:54,600 - _main_loop - 588 - DEBUG - Next wakeup is due at 2020-06-14 00:30:04.597923 (in 9.997048 seconds)
2020-06-14 00:29:54,609 - <module> - 63 - DEBUG - SendBefore_NotRecive : [<CNCProcessStatus: CNCProcessStatus object (2038721)>]
2020-06-14 00:29:54,609 - <module> - 64 - DEBUG - Waitfor_Recive : [2038721]
2020-06-14 00:30:04,598 - _main_loop - 579 - DEBUG - Looking for jobs to run
2020-06-14 00:30:04,598 - _run_jobs - 69 - DEBUG - Started worker thread
2020-06-14 00:30:04,599 - _main_loop - 588 - DEBUG - Next wakeup is due at 2020-06-14 03:00:00 (in 8995.401009 seconds)
2020-06-14 00:30:04,599 - _run_job - 509 - INFO - Running job "regulartime_task (trigger: interval[1 day, 0:00:00], next run at: 2020-06-15 00:30:04.597923)" (scheduled at 2020-06-14 00:30:04.597923)
2020-06-14 00:30:04,937 - _run_job - 520 - ERROR - Job "regulartime_task (trigger: interval[1 day, 0:00:00], next run at: 2020-06-15 00:30:04.597923)" raised an exception
Traceback (most recent call last):
  File "D:\Program Files\Python37\lib\site-packages\django\db\backends\utils.py", line 84, in _execute
    return self.cursor.execute(sql, params)
  File "D:\Program Files\Python37\lib\site-packages\django\db\backends\mysql\base.py", line 71, in execute
    return self.cursor.execute(query, args)
  File "D:\Program Files\Python37\lib\site-packages\MySQLdb\cursors.py", line 209, in execute
    res = self._query(query)
  File "D:\Program Files\Python37\lib\site-packages\MySQLdb\cursors.py", line 315, in _query
    db.query(q)
  File "D:\Program Files\Python37\lib\site-packages\MySQLdb\connections.py", line 239, in query
    _mysql.connection.query(self, query)
MySQLdb._exceptions.IntegrityError: (1062, "Duplicate entry '1592150400' for key 'LAMProcessData_process_r_acquisition_timestamp_a69ae90c_uniq'")

The above exception was the direct cause of the following exception:

Traceback (most recent call last):
  File "D:\Program Files\Python37\lib\site-packages\apscheduler\scheduler.py", line 512, in _run_job
    retval = job.func(*job.args, **job.kwargs)
  File "E:\1-program\11-LAMDataServer\lamdataserver\LAMProcessData\views.py", line 5662, in regulartime_task
    RT_FineData.Realtime_FineData.init_Tomorrow_rows()
  File "E:\1-program\11-LAMDataServer\lamdataserver\LAMProcessData\process_realtime_finedata.py", line 193, in init_Tomorrow_rows
    _model.objects.bulk_create(insert_data_list)
  File "D:\Program Files\Python37\lib\site-packages\django\db\models\manager.py", line 82, in manager_method
    return getattr(self.get_queryset(), name)(*args, **kwargs)
  File "D:\Program Files\Python37\lib\site-packages\django\db\models\query.py", line 474, in bulk_create
    ids = self._batched_insert(objs_without_pk, fields, batch_size, ignore_conflicts=ignore_conflicts)
  File "D:\Program Files\Python37\lib\site-packages\django\db\models\query.py", line 1211, in _batched_insert
    self._insert(item, fields=fields, using=self.db, ignore_conflicts=ignore_conflicts)
  File "D:\Program Files\Python37\lib\site-packages\django\db\models\query.py", line 1186, in _insert
    return query.get_compiler(using=using).execute_sql(return_id)
  File "D:\Program Files\Python37\lib\site-packages\django\db\models\sql\compiler.py", line 1332, in execute_sql
    cursor.execute(sql, params)
  File "D:\Program Files\Python37\lib\site-packages\django\db\backends\utils.py", line 99, in execute
    return super().execute(sql, params)
  File "D:\Program Files\Python37\lib\site-packages\django\db\backends\utils.py", line 67, in execute
    return self._execute_with_wrappers(sql, params, many=False, executor=self._execute)
  File "D:\Program Files\Python37\lib\site-packages\django\db\backends\utils.py", line 76, in _execute_with_wrappers
    return executor(sql, params, many, context)
  File "D:\Program Files\Python37\lib\site-packages\django\db\backends\utils.py", line 84, in _execute
    return self.cursor.execute(sql, params)
  File "D:\Program Files\Python37\lib\site-packages\django\db\utils.py", line 89, in __exit__
    raise dj_exc_value.with_traceback(traceback) from exc_value
  File "D:\Program Files\Python37\lib\site-packages\django\db\backends\utils.py", line 84, in _execute
    return self.cursor.execute(sql, params)
  File "D:\Program Files\Python37\lib\site-packages\django\db\backends\mysql\base.py", line 71, in execute
    return self.cursor.execute(query, args)
  File "D:\Program Files\Python37\lib\site-packages\MySQLdb\cursors.py", line 209, in execute
    res = self._query(query)
  File "D:\Program Files\Python37\lib\site-packages\MySQLdb\cursors.py", line 315, in _query
    db.query(q)
  File "D:\Program Files\Python37\lib\site-packages\MySQLdb\connections.py", line 239, in query
    _mysql.connection.query(self, query)
django.db.utils.IntegrityError: (1062, "Duplicate entry '1592150400' for key 'LAMProcessData_process_r_acquisition_timestamp_a69ae90c_uniq'")
2020-06-14 00:30:05,944 - _run_jobs - 94 - DEBUG - Exiting worker thread
2020-06-14 00:31:09,193 - trigger_reload - 203 - INFO - E:\1-program\11-LAMDataServer\lamdataserver\LAMProcessData\forms.py changed, reloading.
2020-06-14 00:31:09,194 - shutdown - 111 - INFO - Shutting down thread pool
2020-06-14 00:31:12,636 - _real_add_job - 262 - INFO - Added job "regulartime_task (trigger: interval[1 day, 0:00:00], next run at: 2020-06-14 00:31:22.634523)" to job store "default"
2020-06-14 00:31:12,636 - _real_add_job - 262 - INFO - Added job "cleanup (trigger: cron[day_of_week='*', hour='3', minute='0', second='0'], next run at: 2020-06-14 03:00:00)" to job store "default"
2020-06-14 00:31:12,636 - _real_add_job - 262 - INFO - Added job "OpenLog (trigger: cron[hour='0'], next run at: 2020-06-15 00:00:00)" to job store "default"
2020-06-14 00:31:12,636 - _main_loop - 574 - INFO - Scheduler started
2020-06-14 00:31:12,637 - _main_loop - 579 - DEBUG - Looking for jobs to run
2020-06-14 00:31:12,637 - _main_loop - 588 - DEBUG - Next wakeup is due at 2020-06-14 00:31:22.634523 (in 9.997008 seconds)
2020-06-14 00:31:12,647 - <module> - 63 - DEBUG - SendBefore_NotRecive : [<CNCProcessStatus: CNCProcessStatus object (2038721)>]
2020-06-14 00:31:12,647 - <module> - 64 - DEBUG - Waitfor_Recive : [2038721]
2020-06-14 00:31:22,636 - _main_loop - 579 - DEBUG - Looking for jobs to run
2020-06-14 00:31:22,636 - _run_jobs - 69 - DEBUG - Started worker thread
2020-06-14 00:31:22,637 - _main_loop - 588 - DEBUG - Next wakeup is due at 2020-06-14 03:00:00 (in 8917.363867 seconds)
2020-06-14 00:31:22,637 - _run_job - 509 - INFO - Running job "regulartime_task (trigger: interval[1 day, 0:00:00], next run at: 2020-06-15 00:31:22.634523)" (scheduled at 2020-06-14 00:31:22.634523)
2020-06-14 00:31:22,982 - _run_job - 520 - ERROR - Job "regulartime_task (trigger: interval[1 day, 0:00:00], next run at: 2020-06-15 00:31:22.634523)" raised an exception
Traceback (most recent call last):
  File "D:\Program Files\Python37\lib\site-packages\django\db\backends\utils.py", line 84, in _execute
    return self.cursor.execute(sql, params)
  File "D:\Program Files\Python37\lib\site-packages\django\db\backends\mysql\base.py", line 71, in execute
    return self.cursor.execute(query, args)
  File "D:\Program Files\Python37\lib\site-packages\MySQLdb\cursors.py", line 209, in execute
    res = self._query(query)
  File "D:\Program Files\Python37\lib\site-packages\MySQLdb\cursors.py", line 315, in _query
    db.query(q)
  File "D:\Program Files\Python37\lib\site-packages\MySQLdb\connections.py", line 239, in query
    _mysql.connection.query(self, query)
MySQLdb._exceptions.IntegrityError: (1062, "Duplicate entry '1592150400' for key 'LAMProcessData_process_r_acquisition_timestamp_a69ae90c_uniq'")

The above exception was the direct cause of the following exception:

Traceback (most recent call last):
  File "D:\Program Files\Python37\lib\site-packages\apscheduler\scheduler.py", line 512, in _run_job
    retval = job.func(*job.args, **job.kwargs)
  File "E:\1-program\11-LAMDataServer\lamdataserver\LAMProcessData\views.py", line 5662, in regulartime_task
    RT_FineData.Realtime_FineData.init_Tomorrow_rows()
  File "E:\1-program\11-LAMDataServer\lamdataserver\LAMProcessData\process_realtime_finedata.py", line 193, in init_Tomorrow_rows
    _model.objects.bulk_create(insert_data_list)
  File "D:\Program Files\Python37\lib\site-packages\django\db\models\manager.py", line 82, in manager_method
    return getattr(self.get_queryset(), name)(*args, **kwargs)
  File "D:\Program Files\Python37\lib\site-packages\django\db\models\query.py", line 474, in bulk_create
    ids = self._batched_insert(objs_without_pk, fields, batch_size, ignore_conflicts=ignore_conflicts)
  File "D:\Program Files\Python37\lib\site-packages\django\db\models\query.py", line 1211, in _batched_insert
    self._insert(item, fields=fields, using=self.db, ignore_conflicts=ignore_conflicts)
  File "D:\Program Files\Python37\lib\site-packages\django\db\models\query.py", line 1186, in _insert
    return query.get_compiler(using=using).execute_sql(return_id)
  File "D:\Program Files\Python37\lib\site-packages\django\db\models\sql\compiler.py", line 1332, in execute_sql
    cursor.execute(sql, params)
  File "D:\Program Files\Python37\lib\site-packages\django\db\backends\utils.py", line 99, in execute
    return super().execute(sql, params)
  File "D:\Program Files\Python37\lib\site-packages\django\db\backends\utils.py", line 67, in execute
    return self._execute_with_wrappers(sql, params, many=False, executor=self._execute)
  File "D:\Program Files\Python37\lib\site-packages\django\db\backends\utils.py", line 76, in _execute_with_wrappers
    return executor(sql, params, many, context)
  File "D:\Program Files\Python37\lib\site-packages\django\db\backends\utils.py", line 84, in _execute
    return self.cursor.execute(sql, params)
  File "D:\Program Files\Python37\lib\site-packages\django\db\utils.py", line 89, in __exit__
    raise dj_exc_value.with_traceback(traceback) from exc_value
  File "D:\Program Files\Python37\lib\site-packages\django\db\backends\utils.py", line 84, in _execute
    return self.cursor.execute(sql, params)
  File "D:\Program Files\Python37\lib\site-packages\django\db\backends\mysql\base.py", line 71, in execute
    return self.cursor.execute(query, args)
  File "D:\Program Files\Python37\lib\site-packages\MySQLdb\cursors.py", line 209, in execute
    res = self._query(query)
  File "D:\Program Files\Python37\lib\site-packages\MySQLdb\cursors.py", line 315, in _query
    db.query(q)
  File "D:\Program Files\Python37\lib\site-packages\MySQLdb\connections.py", line 239, in query
    _mysql.connection.query(self, query)
django.db.utils.IntegrityError: (1062, "Duplicate entry '1592150400' for key 'LAMProcessData_process_r_acquisition_timestamp_a69ae90c_uniq'")
2020-06-14 00:31:23,991 - _run_jobs - 94 - DEBUG - Exiting worker thread
2020-06-14 00:31:28,547 - trigger_reload - 203 - INFO - E:\1-program\11-LAMDataServer\lamdataserver\LAMProcessData\forms.py changed, reloading.
2020-06-14 00:31:28,547 - shutdown - 111 - INFO - Shutting down thread pool
2020-06-14 00:31:30,894 - _real_add_job - 262 - INFO - Added job "regulartime_task (trigger: interval[1 day, 0:00:00], next run at: 2020-06-14 00:31:40.893484)" to job store "default"
2020-06-14 00:31:30,895 - _real_add_job - 262 - INFO - Added job "cleanup (trigger: cron[day_of_week='*', hour='3', minute='0', second='0'], next run at: 2020-06-14 03:00:00)" to job store "default"
2020-06-14 00:31:30,895 - _real_add_job - 262 - INFO - Added job "OpenLog (trigger: cron[hour='0'], next run at: 2020-06-15 00:00:00)" to job store "default"
2020-06-14 00:31:30,895 - _main_loop - 574 - INFO - Scheduler started
2020-06-14 00:31:30,895 - _main_loop - 579 - DEBUG - Looking for jobs to run
2020-06-14 00:31:30,896 - _main_loop - 588 - DEBUG - Next wakeup is due at 2020-06-14 00:31:40.893484 (in 9.997010 seconds)
2020-06-14 00:31:30,906 - <module> - 63 - DEBUG - SendBefore_NotRecive : [<CNCProcessStatus: CNCProcessStatus object (2038721)>]
2020-06-14 00:31:30,906 - <module> - 64 - DEBUG - Waitfor_Recive : [2038721]
2020-06-14 00:31:40,894 - _main_loop - 579 - DEBUG - Looking for jobs to run
2020-06-14 00:31:40,894 - _run_jobs - 69 - DEBUG - Started worker thread
2020-06-14 00:31:40,894 - _main_loop - 588 - DEBUG - Next wakeup is due at 2020-06-14 03:00:00 (in 8899.105461 seconds)
2020-06-14 00:31:40,895 - _run_job - 509 - INFO - Running job "regulartime_task (trigger: interval[1 day, 0:00:00], next run at: 2020-06-15 00:31:40.893484)" (scheduled at 2020-06-14 00:31:40.893484)
2020-06-14 00:31:41,256 - _run_job - 520 - ERROR - Job "regulartime_task (trigger: interval[1 day, 0:00:00], next run at: 2020-06-15 00:31:40.893484)" raised an exception
Traceback (most recent call last):
  File "D:\Program Files\Python37\lib\site-packages\django\db\backends\utils.py", line 84, in _execute
    return self.cursor.execute(sql, params)
  File "D:\Program Files\Python37\lib\site-packages\django\db\backends\mysql\base.py", line 71, in execute
    return self.cursor.execute(query, args)
  File "D:\Program Files\Python37\lib\site-packages\MySQLdb\cursors.py", line 209, in execute
    res = self._query(query)
  File "D:\Program Files\Python37\lib\site-packages\MySQLdb\cursors.py", line 315, in _query
    db.query(q)
  File "D:\Program Files\Python37\lib\site-packages\MySQLdb\connections.py", line 239, in query
    _mysql.connection.query(self, query)
MySQLdb._exceptions.IntegrityError: (1062, "Duplicate entry '1592150400' for key 'LAMProcessData_process_r_acquisition_timestamp_a69ae90c_uniq'")

The above exception was the direct cause of the following exception:

Traceback (most recent call last):
  File "D:\Program Files\Python37\lib\site-packages\apscheduler\scheduler.py", line 512, in _run_job
    retval = job.func(*job.args, **job.kwargs)
  File "E:\1-program\11-LAMDataServer\lamdataserver\LAMProcessData\views.py", line 5662, in regulartime_task
    RT_FineData.Realtime_FineData.init_Tomorrow_rows()
  File "E:\1-program\11-LAMDataServer\lamdataserver\LAMProcessData\process_realtime_finedata.py", line 193, in init_Tomorrow_rows
    _model.objects.bulk_create(insert_data_list)
  File "D:\Program Files\Python37\lib\site-packages\django\db\models\manager.py", line 82, in manager_method
    return getattr(self.get_queryset(), name)(*args, **kwargs)
  File "D:\Program Files\Python37\lib\site-packages\django\db\models\query.py", line 474, in bulk_create
    ids = self._batched_insert(objs_without_pk, fields, batch_size, ignore_conflicts=ignore_conflicts)
  File "D:\Program Files\Python37\lib\site-packages\django\db\models\query.py", line 1211, in _batched_insert
    self._insert(item, fields=fields, using=self.db, ignore_conflicts=ignore_conflicts)
  File "D:\Program Files\Python37\lib\site-packages\django\db\models\query.py", line 1186, in _insert
    return query.get_compiler(using=using).execute_sql(return_id)
  File "D:\Program Files\Python37\lib\site-packages\django\db\models\sql\compiler.py", line 1332, in execute_sql
    cursor.execute(sql, params)
  File "D:\Program Files\Python37\lib\site-packages\django\db\backends\utils.py", line 99, in execute
    return super().execute(sql, params)
  File "D:\Program Files\Python37\lib\site-packages\django\db\backends\utils.py", line 67, in execute
    return self._execute_with_wrappers(sql, params, many=False, executor=self._execute)
  File "D:\Program Files\Python37\lib\site-packages\django\db\backends\utils.py", line 76, in _execute_with_wrappers
    return executor(sql, params, many, context)
  File "D:\Program Files\Python37\lib\site-packages\django\db\backends\utils.py", line 84, in _execute
    return self.cursor.execute(sql, params)
  File "D:\Program Files\Python37\lib\site-packages\django\db\utils.py", line 89, in __exit__
    raise dj_exc_value.with_traceback(traceback) from exc_value
  File "D:\Program Files\Python37\lib\site-packages\django\db\backends\utils.py", line 84, in _execute
    return self.cursor.execute(sql, params)
  File "D:\Program Files\Python37\lib\site-packages\django\db\backends\mysql\base.py", line 71, in execute
    return self.cursor.execute(query, args)
  File "D:\Program Files\Python37\lib\site-packages\MySQLdb\cursors.py", line 209, in execute
    res = self._query(query)
  File "D:\Program Files\Python37\lib\site-packages\MySQLdb\cursors.py", line 315, in _query
    db.query(q)
  File "D:\Program Files\Python37\lib\site-packages\MySQLdb\connections.py", line 239, in query
    _mysql.connection.query(self, query)
django.db.utils.IntegrityError: (1062, "Duplicate entry '1592150400' for key 'LAMProcessData_process_r_acquisition_timestamp_a69ae90c_uniq'")
2020-06-14 00:31:42,262 - _run_jobs - 94 - DEBUG - Exiting worker thread
2020-06-14 16:59:29,414 - _real_add_job - 262 - INFO - Added job "regulartime_task (trigger: interval[1 day, 0:00:00], next run at: 2020-06-14 16:59:39.413017)" to job store "default"
2020-06-14 16:59:29,414 - _real_add_job - 262 - INFO - Added job "cleanup (trigger: cron[day_of_week='*', hour='3', minute='0', second='0'], next run at: 2020-06-15 03:00:00)" to job store "default"
2020-06-14 16:59:29,414 - _real_add_job - 262 - INFO - Added job "OpenLog (trigger: cron[hour='0'], next run at: 2020-06-15 00:00:00)" to job store "default"
2020-06-14 16:59:29,414 - _main_loop - 574 - INFO - Scheduler started
2020-06-14 16:59:29,414 - _main_loop - 579 - DEBUG - Looking for jobs to run
2020-06-14 16:59:29,414 - _main_loop - 588 - DEBUG - Next wakeup is due at 2020-06-14 16:59:39.413017 (in 9.998038 seconds)
2020-06-14 16:59:29,454 - <module> - 63 - DEBUG - SendBefore_NotRecive : [<CNCProcessStatus: CNCProcessStatus object (2038721)>]
2020-06-14 16:59:29,454 - <module> - 64 - DEBUG - Waitfor_Recive : [2038721]
2020-06-14 16:59:39,414 - _main_loop - 579 - DEBUG - Looking for jobs to run
2020-06-14 16:59:39,414 - _run_jobs - 69 - DEBUG - Started worker thread
2020-06-14 16:59:39,414 - _run_job - 509 - INFO - Running job "regulartime_task (trigger: interval[1 day, 0:00:00], next run at: 2020-06-14 16:59:39.413017)" (scheduled at 2020-06-14 16:59:39.413017)
2020-06-14 16:59:39,414 - _main_loop - 588 - DEBUG - Next wakeup is due at 2020-06-15 00:00:00 (in 25220.585728 seconds)
2020-06-14 16:59:39,743 - _run_job - 520 - ERROR - Job "regulartime_task (trigger: interval[1 day, 0:00:00], next run at: 2020-06-15 16:59:39.413017)" raised an exception
Traceback (most recent call last):
  File "D:\Program Files\Python37\lib\site-packages\django\db\backends\utils.py", line 84, in _execute
    return self.cursor.execute(sql, params)
  File "D:\Program Files\Python37\lib\site-packages\django\db\backends\mysql\base.py", line 71, in execute
    return self.cursor.execute(query, args)
  File "D:\Program Files\Python37\lib\site-packages\MySQLdb\cursors.py", line 209, in execute
    res = self._query(query)
  File "D:\Program Files\Python37\lib\site-packages\MySQLdb\cursors.py", line 315, in _query
    db.query(q)
  File "D:\Program Files\Python37\lib\site-packages\MySQLdb\connections.py", line 239, in query
    _mysql.connection.query(self, query)
MySQLdb._exceptions.IntegrityError: (1062, "Duplicate entry '1592150400' for key 'LAMProcessData_process_r_acquisition_timestamp_a69ae90c_uniq'")

The above exception was the direct cause of the following exception:

Traceback (most recent call last):
  File "D:\Program Files\Python37\lib\site-packages\apscheduler\scheduler.py", line 512, in _run_job
    retval = job.func(*job.args, **job.kwargs)
  File "E:\1-program\11-LAMDataServer\lamdataserver\LAMProcessData\views.py", line 5662, in regulartime_task
    RT_FineData.Realtime_FineData.init_Tomorrow_rows()
  File "E:\1-program\11-LAMDataServer\lamdataserver\LAMProcessData\process_realtime_finedata.py", line 193, in init_Tomorrow_rows
    _model.objects.bulk_create(insert_data_list)
  File "D:\Program Files\Python37\lib\site-packages\django\db\models\manager.py", line 82, in manager_method
    return getattr(self.get_queryset(), name)(*args, **kwargs)
  File "D:\Program Files\Python37\lib\site-packages\django\db\models\query.py", line 474, in bulk_create
    ids = self._batched_insert(objs_without_pk, fields, batch_size, ignore_conflicts=ignore_conflicts)
  File "D:\Program Files\Python37\lib\site-packages\django\db\models\query.py", line 1211, in _batched_insert
    self._insert(item, fields=fields, using=self.db, ignore_conflicts=ignore_conflicts)
  File "D:\Program Files\Python37\lib\site-packages\django\db\models\query.py", line 1186, in _insert
    return query.get_compiler(using=using).execute_sql(return_id)
  File "D:\Program Files\Python37\lib\site-packages\django\db\models\sql\compiler.py", line 1332, in execute_sql
    cursor.execute(sql, params)
  File "D:\Program Files\Python37\lib\site-packages\django\db\backends\utils.py", line 99, in execute
    return super().execute(sql, params)
  File "D:\Program Files\Python37\lib\site-packages\django\db\backends\utils.py", line 67, in execute
    return self._execute_with_wrappers(sql, params, many=False, executor=self._execute)
  File "D:\Program Files\Python37\lib\site-packages\django\db\backends\utils.py", line 76, in _execute_with_wrappers
    return executor(sql, params, many, context)
  File "D:\Program Files\Python37\lib\site-packages\django\db\backends\utils.py", line 84, in _execute
    return self.cursor.execute(sql, params)
  File "D:\Program Files\Python37\lib\site-packages\django\db\utils.py", line 89, in __exit__
    raise dj_exc_value.with_traceback(traceback) from exc_value
  File "D:\Program Files\Python37\lib\site-packages\django\db\backends\utils.py", line 84, in _execute
    return self.cursor.execute(sql, params)
  File "D:\Program Files\Python37\lib\site-packages\django\db\backends\mysql\base.py", line 71, in execute
    return self.cursor.execute(query, args)
  File "D:\Program Files\Python37\lib\site-packages\MySQLdb\cursors.py", line 209, in execute
    res = self._query(query)
  File "D:\Program Files\Python37\lib\site-packages\MySQLdb\cursors.py", line 315, in _query
    db.query(q)
  File "D:\Program Files\Python37\lib\site-packages\MySQLdb\connections.py", line 239, in query
    _mysql.connection.query(self, query)
django.db.utils.IntegrityError: (1062, "Duplicate entry '1592150400' for key 'LAMProcessData_process_r_acquisition_timestamp_a69ae90c_uniq'")
2020-06-14 16:59:40,755 - _run_jobs - 94 - DEBUG - Exiting worker thread
2020-06-14 17:03:36,677 - trigger_reload - 203 - INFO - E:\1-program\11-LAMDataServer\lamdataserver\LAMProcessData\forms.py changed, reloading.
2020-06-14 17:03:36,677 - shutdown - 111 - INFO - Shutting down thread pool
2020-06-14 17:10:22,536 - _real_add_job - 262 - INFO - Added job "regulartime_task (trigger: interval[1 day, 0:00:00], next run at: 2020-06-14 17:10:32.535251)" to job store "default"
2020-06-14 17:10:22,536 - _real_add_job - 262 - INFO - Added job "cleanup (trigger: cron[day_of_week='*', hour='3', minute='0', second='0'], next run at: 2020-06-15 03:00:00)" to job store "default"
2020-06-14 17:10:22,536 - _real_add_job - 262 - INFO - Added job "OpenLog (trigger: cron[hour='0'], next run at: 2020-06-15 00:00:00)" to job store "default"
2020-06-14 17:10:22,537 - _main_loop - 574 - INFO - Scheduler started
2020-06-14 17:10:22,537 - _main_loop - 579 - DEBUG - Looking for jobs to run
2020-06-14 17:10:22,537 - _main_loop - 588 - DEBUG - Next wakeup is due at 2020-06-14 17:10:32.535251 (in 9.998007 seconds)
2020-06-14 17:10:22,548 - <module> - 63 - DEBUG - SendBefore_NotRecive : [<CNCProcessStatus: CNCProcessStatus object (2038721)>]
2020-06-14 17:10:22,548 - <module> - 64 - DEBUG - Waitfor_Recive : [2038721]
2020-06-14 17:10:32,536 - _main_loop - 579 - DEBUG - Looking for jobs to run
2020-06-14 17:10:32,537 - _run_jobs - 69 - DEBUG - Started worker thread
2020-06-14 17:10:32,537 - _main_loop - 588 - DEBUG - Next wakeup is due at 2020-06-15 00:00:00 (in 24567.463335 seconds)
2020-06-14 17:10:32,537 - _run_job - 509 - INFO - Running job "regulartime_task (trigger: interval[1 day, 0:00:00], next run at: 2020-06-15 17:10:32.535251)" (scheduled at 2020-06-14 17:10:32.535251)
2020-06-14 17:10:32,882 - _run_job - 520 - ERROR - Job "regulartime_task (trigger: interval[1 day, 0:00:00], next run at: 2020-06-15 17:10:32.535251)" raised an exception
Traceback (most recent call last):
  File "D:\Program Files\Python37\lib\site-packages\django\db\backends\utils.py", line 84, in _execute
    return self.cursor.execute(sql, params)
  File "D:\Program Files\Python37\lib\site-packages\django\db\backends\mysql\base.py", line 71, in execute
    return self.cursor.execute(query, args)
  File "D:\Program Files\Python37\lib\site-packages\MySQLdb\cursors.py", line 209, in execute
    res = self._query(query)
  File "D:\Program Files\Python37\lib\site-packages\MySQLdb\cursors.py", line 315, in _query
    db.query(q)
  File "D:\Program Files\Python37\lib\site-packages\MySQLdb\connections.py", line 239, in query
    _mysql.connection.query(self, query)
MySQLdb._exceptions.IntegrityError: (1062, "Duplicate entry '1592150400' for key 'LAMProcessData_process_r_acquisition_timestamp_a69ae90c_uniq'")

The above exception was the direct cause of the following exception:

Traceback (most recent call last):
  File "D:\Program Files\Python37\lib\site-packages\apscheduler\scheduler.py", line 512, in _run_job
    retval = job.func(*job.args, **job.kwargs)
  File "E:\1-program\11-LAMDataServer\lamdataserver\LAMProcessData\views.py", line 5662, in regulartime_task
    RT_FineData.Realtime_FineData.init_Tomorrow_rows()
  File "E:\1-program\11-LAMDataServer\lamdataserver\LAMProcessData\process_realtime_finedata.py", line 193, in init_Tomorrow_rows
    _model.objects.bulk_create(insert_data_list)
  File "D:\Program Files\Python37\lib\site-packages\django\db\models\manager.py", line 82, in manager_method
    return getattr(self.get_queryset(), name)(*args, **kwargs)
  File "D:\Program Files\Python37\lib\site-packages\django\db\models\query.py", line 474, in bulk_create
    ids = self._batched_insert(objs_without_pk, fields, batch_size, ignore_conflicts=ignore_conflicts)
  File "D:\Program Files\Python37\lib\site-packages\django\db\models\query.py", line 1211, in _batched_insert
    self._insert(item, fields=fields, using=self.db, ignore_conflicts=ignore_conflicts)
  File "D:\Program Files\Python37\lib\site-packages\django\db\models\query.py", line 1186, in _insert
    return query.get_compiler(using=using).execute_sql(return_id)
  File "D:\Program Files\Python37\lib\site-packages\django\db\models\sql\compiler.py", line 1332, in execute_sql
    cursor.execute(sql, params)
  File "D:\Program Files\Python37\lib\site-packages\django\db\backends\utils.py", line 99, in execute
    return super().execute(sql, params)
  File "D:\Program Files\Python37\lib\site-packages\django\db\backends\utils.py", line 67, in execute
    return self._execute_with_wrappers(sql, params, many=False, executor=self._execute)
  File "D:\Program Files\Python37\lib\site-packages\django\db\backends\utils.py", line 76, in _execute_with_wrappers
    return executor(sql, params, many, context)
  File "D:\Program Files\Python37\lib\site-packages\django\db\backends\utils.py", line 84, in _execute
    return self.cursor.execute(sql, params)
  File "D:\Program Files\Python37\lib\site-packages\django\db\utils.py", line 89, in __exit__
    raise dj_exc_value.with_traceback(traceback) from exc_value
  File "D:\Program Files\Python37\lib\site-packages\django\db\backends\utils.py", line 84, in _execute
    return self.cursor.execute(sql, params)
  File "D:\Program Files\Python37\lib\site-packages\django\db\backends\mysql\base.py", line 71, in execute
    return self.cursor.execute(query, args)
  File "D:\Program Files\Python37\lib\site-packages\MySQLdb\cursors.py", line 209, in execute
    res = self._query(query)
  File "D:\Program Files\Python37\lib\site-packages\MySQLdb\cursors.py", line 315, in _query
    db.query(q)
  File "D:\Program Files\Python37\lib\site-packages\MySQLdb\connections.py", line 239, in query
    _mysql.connection.query(self, query)
django.db.utils.IntegrityError: (1062, "Duplicate entry '1592150400' for key 'LAMProcessData_process_r_acquisition_timestamp_a69ae90c_uniq'")
2020-06-14 17:10:33,758 - log_response - 228 - WARNING - Not Found: /favicon.ico
2020-06-14 17:10:33,888 - _run_jobs - 94 - DEBUG - Exiting worker thread
2020-06-14 17:10:34,334 - log_response - 228 - WARNING - Not Found: /favicon.ico
2020-06-14 17:10:34,937 - log_response - 228 - WARNING - Not Found: /favicon.ico
2020-06-14 17:10:35,537 - log_response - 228 - WARNING - Not Found: /favicon.ico
2020-06-14 17:11:21,242 - log_response - 228 - WARNING - Not Found: /favicon.ico
2020-06-14 17:11:35,745 - _real_add_job - 262 - INFO - Added job "regulartime_task (trigger: interval[1 day, 0:00:00], next run at: 2020-06-14 17:11:45.729403)" to job store "default"
2020-06-14 17:11:35,745 - _real_add_job - 262 - INFO - Added job "cleanup (trigger: cron[day_of_week='*', hour='3', minute='0', second='0'], next run at: 2020-06-15 03:00:00)" to job store "default"
2020-06-14 17:11:35,745 - _real_add_job - 262 - INFO - Added job "OpenLog (trigger: cron[hour='0'], next run at: 2020-06-15 00:00:00)" to job store "default"
2020-06-14 17:11:35,745 - _main_loop - 574 - INFO - Scheduler started
2020-06-14 17:11:35,745 - _main_loop - 579 - DEBUG - Looking for jobs to run
2020-06-14 17:11:35,745 - _main_loop - 588 - DEBUG - Next wakeup is due at 2020-06-14 17:11:45.729403 (in 9.983521 seconds)
2020-06-14 17:11:35,745 - <module> - 63 - DEBUG - SendBefore_NotRecive : [<CNCProcessStatus: CNCProcessStatus object (2038721)>]
2020-06-14 17:11:35,745 - <module> - 64 - DEBUG - Waitfor_Recive : [2038721]
2020-06-14 17:11:45,730 - _main_loop - 579 - DEBUG - Looking for jobs to run
2020-06-14 17:11:45,731 - _run_jobs - 69 - DEBUG - Started worker thread
2020-06-14 17:11:45,731 - _main_loop - 588 - DEBUG - Next wakeup is due at 2020-06-15 00:00:00 (in 24494.269389 seconds)
2020-06-14 17:11:45,732 - _run_job - 509 - INFO - Running job "regulartime_task (trigger: interval[1 day, 0:00:00], next run at: 2020-06-15 17:11:45.729403)" (scheduled at 2020-06-14 17:11:45.729403)
2020-06-14 17:11:46,061 - _run_job - 520 - ERROR - Job "regulartime_task (trigger: interval[1 day, 0:00:00], next run at: 2020-06-15 17:11:45.729403)" raised an exception
Traceback (most recent call last):
  File "D:\Program Files\Python37\lib\site-packages\django\db\backends\utils.py", line 84, in _execute
    return self.cursor.execute(sql, params)
  File "D:\Program Files\Python37\lib\site-packages\django\db\backends\mysql\base.py", line 71, in execute
    return self.cursor.execute(query, args)
  File "D:\Program Files\Python37\lib\site-packages\MySQLdb\cursors.py", line 209, in execute
    res = self._query(query)
  File "D:\Program Files\Python37\lib\site-packages\MySQLdb\cursors.py", line 315, in _query
    db.query(q)
  File "D:\Program Files\Python37\lib\site-packages\MySQLdb\connections.py", line 239, in query
    _mysql.connection.query(self, query)
MySQLdb._exceptions.IntegrityError: (1062, "Duplicate entry '1592150400' for key 'LAMProcessData_process_r_acquisition_timestamp_a69ae90c_uniq'")

The above exception was the direct cause of the following exception:

Traceback (most recent call last):
  File "D:\Program Files\Python37\lib\site-packages\apscheduler\scheduler.py", line 512, in _run_job
    retval = job.func(*job.args, **job.kwargs)
  File "E:\1-program\11-LAMDataServer\lamdataserver\LAMProcessData\views.py", line 5662, in regulartime_task
    RT_FineData.Realtime_FineData.init_Tomorrow_rows()
  File "E:\1-program\11-LAMDataServer\lamdataserver\LAMProcessData\process_realtime_finedata.py", line 193, in init_Tomorrow_rows
    _model.objects.bulk_create(insert_data_list)
  File "D:\Program Files\Python37\lib\site-packages\django\db\models\manager.py", line 82, in manager_method
    return getattr(self.get_queryset(), name)(*args, **kwargs)
  File "D:\Program Files\Python37\lib\site-packages\django\db\models\query.py", line 474, in bulk_create
    ids = self._batched_insert(objs_without_pk, fields, batch_size, ignore_conflicts=ignore_conflicts)
  File "D:\Program Files\Python37\lib\site-packages\django\db\models\query.py", line 1211, in _batched_insert
    self._insert(item, fields=fields, using=self.db, ignore_conflicts=ignore_conflicts)
  File "D:\Program Files\Python37\lib\site-packages\django\db\models\query.py", line 1186, in _insert
    return query.get_compiler(using=using).execute_sql(return_id)
  File "D:\Program Files\Python37\lib\site-packages\django\db\models\sql\compiler.py", line 1332, in execute_sql
    cursor.execute(sql, params)
  File "D:\Program Files\Python37\lib\site-packages\django\db\backends\utils.py", line 99, in execute
    return super().execute(sql, params)
  File "D:\Program Files\Python37\lib\site-packages\django\db\backends\utils.py", line 67, in execute
    return self._execute_with_wrappers(sql, params, many=False, executor=self._execute)
  File "D:\Program Files\Python37\lib\site-packages\django\db\backends\utils.py", line 76, in _execute_with_wrappers
    return executor(sql, params, many, context)
  File "D:\Program Files\Python37\lib\site-packages\django\db\backends\utils.py", line 84, in _execute
    return self.cursor.execute(sql, params)
  File "D:\Program Files\Python37\lib\site-packages\django\db\utils.py", line 89, in __exit__
    raise dj_exc_value.with_traceback(traceback) from exc_value
  File "D:\Program Files\Python37\lib\site-packages\django\db\backends\utils.py", line 84, in _execute
    return self.cursor.execute(sql, params)
  File "D:\Program Files\Python37\lib\site-packages\django\db\backends\mysql\base.py", line 71, in execute
    return self.cursor.execute(query, args)
  File "D:\Program Files\Python37\lib\site-packages\MySQLdb\cursors.py", line 209, in execute
    res = self._query(query)
  File "D:\Program Files\Python37\lib\site-packages\MySQLdb\cursors.py", line 315, in _query
    db.query(q)
  File "D:\Program Files\Python37\lib\site-packages\MySQLdb\connections.py", line 239, in query
    _mysql.connection.query(self, query)
django.db.utils.IntegrityError: (1062, "Duplicate entry '1592150400' for key 'LAMProcessData_process_r_acquisition_timestamp_a69ae90c_uniq'")
2020-06-14 17:11:47,065 - _run_jobs - 94 - DEBUG - Exiting worker thread
2020-06-14 17:13:20,975 - trigger_reload - 203 - INFO - E:\1-program\11-LAMDataServer\lamdataserver\LAMProcessData\forms.py changed, reloading.
2020-06-14 17:13:20,975 - shutdown - 111 - INFO - Shutting down thread pool
2020-06-14 17:13:23,504 - _real_add_job - 262 - INFO - Added job "regulartime_task (trigger: interval[1 day, 0:00:00], next run at: 2020-06-14 17:13:33.503509)" to job store "default"
2020-06-14 17:13:23,504 - _real_add_job - 262 - INFO - Added job "cleanup (trigger: cron[day_of_week='*', hour='3', minute='0', second='0'], next run at: 2020-06-15 03:00:00)" to job store "default"
2020-06-14 17:13:23,504 - _real_add_job - 262 - INFO - Added job "OpenLog (trigger: cron[hour='0'], next run at: 2020-06-15 00:00:00)" to job store "default"
2020-06-14 17:13:23,505 - _main_loop - 574 - INFO - Scheduler started
2020-06-14 17:13:23,505 - _main_loop - 579 - DEBUG - Looking for jobs to run
2020-06-14 17:13:23,505 - _main_loop - 588 - DEBUG - Next wakeup is due at 2020-06-14 17:13:33.503509 (in 9.997933 seconds)
2020-06-14 17:13:23,508 - <module> - 63 - DEBUG - SendBefore_NotRecive : [<CNCProcessStatus: CNCProcessStatus object (2038721)>]
2020-06-14 17:13:23,508 - <module> - 64 - DEBUG - Waitfor_Recive : [2038721]
2020-06-14 17:13:33,516 - _main_loop - 579 - DEBUG - Looking for jobs to run
2020-06-14 17:13:33,516 - _run_jobs - 69 - DEBUG - Started worker thread
2020-06-14 17:13:33,516 - _main_loop - 588 - DEBUG - Next wakeup is due at 2020-06-15 00:00:00 (in 24386.483728 seconds)
2020-06-14 17:13:33,516 - _run_job - 509 - INFO - Running job "regulartime_task (trigger: interval[1 day, 0:00:00], next run at: 2020-06-15 17:13:33.503509)" (scheduled at 2020-06-14 17:13:33.503509)
2020-06-14 17:13:34,065 - _run_job - 520 - ERROR - Job "regulartime_task (trigger: interval[1 day, 0:00:00], next run at: 2020-06-15 17:13:33.503509)" raised an exception
Traceback (most recent call last):
  File "D:\Program Files\Python37\lib\site-packages\django\db\backends\utils.py", line 84, in _execute
    return self.cursor.execute(sql, params)
  File "D:\Program Files\Python37\lib\site-packages\django\db\backends\mysql\base.py", line 71, in execute
    return self.cursor.execute(query, args)
  File "D:\Program Files\Python37\lib\site-packages\MySQLdb\cursors.py", line 209, in execute
    res = self._query(query)
  File "D:\Program Files\Python37\lib\site-packages\MySQLdb\cursors.py", line 315, in _query
    db.query(q)
  File "D:\Program Files\Python37\lib\site-packages\MySQLdb\connections.py", line 239, in query
    _mysql.connection.query(self, query)
MySQLdb._exceptions.IntegrityError: (1062, "Duplicate entry '1592150400' for key 'LAMProcessData_process_r_acquisition_timestamp_a69ae90c_uniq'")

The above exception was the direct cause of the following exception:

Traceback (most recent call last):
  File "D:\Program Files\Python37\lib\site-packages\apscheduler\scheduler.py", line 512, in _run_job
    retval = job.func(*job.args, **job.kwargs)
  File "E:\1-program\11-LAMDataServer\lamdataserver\LAMProcessData\views.py", line 5662, in regulartime_task
    RT_FineData.Realtime_FineData.init_Tomorrow_rows()
  File "E:\1-program\11-LAMDataServer\lamdataserver\LAMProcessData\process_realtime_finedata.py", line 193, in init_Tomorrow_rows
    _model.objects.bulk_create(insert_data_list)
  File "D:\Program Files\Python37\lib\site-packages\django\db\models\manager.py", line 82, in manager_method
    return getattr(self.get_queryset(), name)(*args, **kwargs)
  File "D:\Program Files\Python37\lib\site-packages\django\db\models\query.py", line 474, in bulk_create
    ids = self._batched_insert(objs_without_pk, fields, batch_size, ignore_conflicts=ignore_conflicts)
  File "D:\Program Files\Python37\lib\site-packages\django\db\models\query.py", line 1211, in _batched_insert
    self._insert(item, fields=fields, using=self.db, ignore_conflicts=ignore_conflicts)
  File "D:\Program Files\Python37\lib\site-packages\django\db\models\query.py", line 1186, in _insert
    return query.get_compiler(using=using).execute_sql(return_id)
  File "D:\Program Files\Python37\lib\site-packages\django\db\models\sql\compiler.py", line 1332, in execute_sql
    cursor.execute(sql, params)
  File "D:\Program Files\Python37\lib\site-packages\django\db\backends\utils.py", line 99, in execute
    return super().execute(sql, params)
  File "D:\Program Files\Python37\lib\site-packages\django\db\backends\utils.py", line 67, in execute
    return self._execute_with_wrappers(sql, params, many=False, executor=self._execute)
  File "D:\Program Files\Python37\lib\site-packages\django\db\backends\utils.py", line 76, in _execute_with_wrappers
    return executor(sql, params, many, context)
  File "D:\Program Files\Python37\lib\site-packages\django\db\backends\utils.py", line 84, in _execute
    return self.cursor.execute(sql, params)
  File "D:\Program Files\Python37\lib\site-packages\django\db\utils.py", line 89, in __exit__
    raise dj_exc_value.with_traceback(traceback) from exc_value
  File "D:\Program Files\Python37\lib\site-packages\django\db\backends\utils.py", line 84, in _execute
    return self.cursor.execute(sql, params)
  File "D:\Program Files\Python37\lib\site-packages\django\db\backends\mysql\base.py", line 71, in execute
    return self.cursor.execute(query, args)
  File "D:\Program Files\Python37\lib\site-packages\MySQLdb\cursors.py", line 209, in execute
    res = self._query(query)
  File "D:\Program Files\Python37\lib\site-packages\MySQLdb\cursors.py", line 315, in _query
    db.query(q)
  File "D:\Program Files\Python37\lib\site-packages\MySQLdb\connections.py", line 239, in query
    _mysql.connection.query(self, query)
django.db.utils.IntegrityError: (1062, "Duplicate entry '1592150400' for key 'LAMProcessData_process_r_acquisition_timestamp_a69ae90c_uniq'")
2020-06-14 17:13:34,708 - trigger_reload - 203 - INFO - E:\1-program\11-LAMDataServer\lamdataserver\LAMProcessData\forms.py changed, reloading.
2020-06-14 17:13:34,708 - shutdown - 111 - INFO - Shutting down thread pool
2020-06-14 17:13:34,708 - _run_jobs - 94 - DEBUG - Exiting worker thread
2020-06-14 17:13:40,207 - _real_add_job - 262 - INFO - Added job "regulartime_task (trigger: interval[1 day, 0:00:00], next run at: 2020-06-14 17:13:50.207614)" to job store "default"
2020-06-14 17:13:40,207 - _real_add_job - 262 - INFO - Added job "cleanup (trigger: cron[day_of_week='*', hour='3', minute='0', second='0'], next run at: 2020-06-15 03:00:00)" to job store "default"
2020-06-14 17:13:40,207 - _real_add_job - 262 - INFO - Added job "OpenLog (trigger: cron[hour='0'], next run at: 2020-06-15 00:00:00)" to job store "default"
2020-06-14 17:13:40,207 - _main_loop - 574 - INFO - Scheduler started
2020-06-14 17:13:40,207 - _main_loop - 579 - DEBUG - Looking for jobs to run
2020-06-14 17:13:40,207 - _main_loop - 588 - DEBUG - Next wakeup is due at 2020-06-14 17:13:50.207614 (in 10.000000 seconds)
2020-06-14 17:13:40,207 - <module> - 63 - DEBUG - SendBefore_NotRecive : [<CNCProcessStatus: CNCProcessStatus object (2038721)>]
2020-06-14 17:13:40,207 - <module> - 64 - DEBUG - Waitfor_Recive : [2038721]
2020-06-14 17:13:50,220 - _main_loop - 579 - DEBUG - Looking for jobs to run
2020-06-14 17:13:50,221 - _run_jobs - 69 - DEBUG - Started worker thread
2020-06-14 17:13:50,221 - _main_loop - 588 - DEBUG - Next wakeup is due at 2020-06-15 00:00:00 (in 24369.779322 seconds)
2020-06-14 17:13:50,221 - _run_job - 509 - INFO - Running job "regulartime_task (trigger: interval[1 day, 0:00:00], next run at: 2020-06-15 17:13:50.207614)" (scheduled at 2020-06-14 17:13:50.207614)
2020-06-14 17:13:50,538 - _run_job - 520 - ERROR - Job "regulartime_task (trigger: interval[1 day, 0:00:00], next run at: 2020-06-15 17:13:50.207614)" raised an exception
Traceback (most recent call last):
  File "D:\Program Files\Python37\lib\site-packages\django\db\backends\utils.py", line 84, in _execute
    return self.cursor.execute(sql, params)
  File "D:\Program Files\Python37\lib\site-packages\django\db\backends\mysql\base.py", line 71, in execute
    return self.cursor.execute(query, args)
  File "D:\Program Files\Python37\lib\site-packages\MySQLdb\cursors.py", line 209, in execute
    res = self._query(query)
  File "D:\Program Files\Python37\lib\site-packages\MySQLdb\cursors.py", line 315, in _query
    db.query(q)
  File "D:\Program Files\Python37\lib\site-packages\MySQLdb\connections.py", line 239, in query
    _mysql.connection.query(self, query)
MySQLdb._exceptions.IntegrityError: (1062, "Duplicate entry '1592150400' for key 'LAMProcessData_process_r_acquisition_timestamp_a69ae90c_uniq'")

The above exception was the direct cause of the following exception:

Traceback (most recent call last):
  File "D:\Program Files\Python37\lib\site-packages\apscheduler\scheduler.py", line 512, in _run_job
    retval = job.func(*job.args, **job.kwargs)
  File "E:\1-program\11-LAMDataServer\lamdataserver\LAMProcessData\views.py", line 5662, in regulartime_task
    RT_FineData.Realtime_FineData.init_Tomorrow_rows()
  File "E:\1-program\11-LAMDataServer\lamdataserver\LAMProcessData\process_realtime_finedata.py", line 193, in init_Tomorrow_rows
    _model.objects.bulk_create(insert_data_list)
  File "D:\Program Files\Python37\lib\site-packages\django\db\models\manager.py", line 82, in manager_method
    return getattr(self.get_queryset(), name)(*args, **kwargs)
  File "D:\Program Files\Python37\lib\site-packages\django\db\models\query.py", line 474, in bulk_create
    ids = self._batched_insert(objs_without_pk, fields, batch_size, ignore_conflicts=ignore_conflicts)
  File "D:\Program Files\Python37\lib\site-packages\django\db\models\query.py", line 1211, in _batched_insert
    self._insert(item, fields=fields, using=self.db, ignore_conflicts=ignore_conflicts)
  File "D:\Program Files\Python37\lib\site-packages\django\db\models\query.py", line 1186, in _insert
    return query.get_compiler(using=using).execute_sql(return_id)
  File "D:\Program Files\Python37\lib\site-packages\django\db\models\sql\compiler.py", line 1332, in execute_sql
    cursor.execute(sql, params)
  File "D:\Program Files\Python37\lib\site-packages\django\db\backends\utils.py", line 99, in execute
    return super().execute(sql, params)
  File "D:\Program Files\Python37\lib\site-packages\django\db\backends\utils.py", line 67, in execute
    return self._execute_with_wrappers(sql, params, many=False, executor=self._execute)
  File "D:\Program Files\Python37\lib\site-packages\django\db\backends\utils.py", line 76, in _execute_with_wrappers
    return executor(sql, params, many, context)
  File "D:\Program Files\Python37\lib\site-packages\django\db\backends\utils.py", line 84, in _execute
    return self.cursor.execute(sql, params)
  File "D:\Program Files\Python37\lib\site-packages\django\db\utils.py", line 89, in __exit__
    raise dj_exc_value.with_traceback(traceback) from exc_value
  File "D:\Program Files\Python37\lib\site-packages\django\db\backends\utils.py", line 84, in _execute
    return self.cursor.execute(sql, params)
  File "D:\Program Files\Python37\lib\site-packages\django\db\backends\mysql\base.py", line 71, in execute
    return self.cursor.execute(query, args)
  File "D:\Program Files\Python37\lib\site-packages\MySQLdb\cursors.py", line 209, in execute
    res = self._query(query)
  File "D:\Program Files\Python37\lib\site-packages\MySQLdb\cursors.py", line 315, in _query
    db.query(q)
  File "D:\Program Files\Python37\lib\site-packages\MySQLdb\connections.py", line 239, in query
    _mysql.connection.query(self, query)
django.db.utils.IntegrityError: (1062, "Duplicate entry '1592150400' for key 'LAMProcessData_process_r_acquisition_timestamp_a69ae90c_uniq'")
2020-06-14 17:13:51,550 - _run_jobs - 94 - DEBUG - Exiting worker thread
2020-06-14 17:16:25,146 - trigger_reload - 203 - INFO - E:\1-program\11-LAMDataServer\lamdataserver\LAMProcessData\forms.py changed, reloading.
2020-06-14 17:16:25,146 - shutdown - 111 - INFO - Shutting down thread pool
2020-06-14 17:16:27,580 - _real_add_job - 262 - INFO - Added job "regulartime_task (trigger: interval[1 day, 0:00:00], next run at: 2020-06-14 17:16:37.580040)" to job store "default"
2020-06-14 17:16:27,580 - _real_add_job - 262 - INFO - Added job "cleanup (trigger: cron[day_of_week='*', hour='3', minute='0', second='0'], next run at: 2020-06-15 03:00:00)" to job store "default"
2020-06-14 17:16:27,595 - _real_add_job - 262 - INFO - Added job "OpenLog (trigger: cron[hour='0'], next run at: 2020-06-15 00:00:00)" to job store "default"
2020-06-14 17:16:27,596 - _main_loop - 574 - INFO - Scheduler started
2020-06-14 17:16:27,596 - _main_loop - 579 - DEBUG - Looking for jobs to run
2020-06-14 17:16:27,597 - _main_loop - 588 - DEBUG - Next wakeup is due at 2020-06-14 17:16:37.580040 (in 9.982949 seconds)
2020-06-14 17:16:27,597 - <module> - 63 - DEBUG - SendBefore_NotRecive : [<CNCProcessStatus: CNCProcessStatus object (2038721)>]
2020-06-14 17:16:27,597 - <module> - 64 - DEBUG - Waitfor_Recive : [2038721]
2020-06-14 17:16:37,594 - _main_loop - 579 - DEBUG - Looking for jobs to run
2020-06-14 17:16:37,595 - _run_jobs - 69 - DEBUG - Started worker thread
2020-06-14 17:16:37,595 - _run_job - 509 - INFO - Running job "regulartime_task (trigger: interval[1 day, 0:00:00], next run at: 2020-06-14 17:16:37.580040)" (scheduled at 2020-06-14 17:16:37.580040)
2020-06-14 17:16:37,595 - _main_loop - 588 - DEBUG - Next wakeup is due at 2020-06-15 00:00:00 (in 24202.404845 seconds)
2020-06-14 17:16:37,912 - _run_job - 520 - ERROR - Job "regulartime_task (trigger: interval[1 day, 0:00:00], next run at: 2020-06-15 17:16:37.580040)" raised an exception
Traceback (most recent call last):
  File "D:\Program Files\Python37\lib\site-packages\django\db\backends\utils.py", line 84, in _execute
    return self.cursor.execute(sql, params)
  File "D:\Program Files\Python37\lib\site-packages\django\db\backends\mysql\base.py", line 71, in execute
    return self.cursor.execute(query, args)
  File "D:\Program Files\Python37\lib\site-packages\MySQLdb\cursors.py", line 209, in execute
    res = self._query(query)
  File "D:\Program Files\Python37\lib\site-packages\MySQLdb\cursors.py", line 315, in _query
    db.query(q)
  File "D:\Program Files\Python37\lib\site-packages\MySQLdb\connections.py", line 239, in query
    _mysql.connection.query(self, query)
MySQLdb._exceptions.IntegrityError: (1062, "Duplicate entry '1592150400' for key 'LAMProcessData_process_r_acquisition_timestamp_a69ae90c_uniq'")

The above exception was the direct cause of the following exception:

Traceback (most recent call last):
  File "D:\Program Files\Python37\lib\site-packages\apscheduler\scheduler.py", line 512, in _run_job
    retval = job.func(*job.args, **job.kwargs)
  File "E:\1-program\11-LAMDataServer\lamdataserver\LAMProcessData\views.py", line 5662, in regulartime_task
    RT_FineData.Realtime_FineData.init_Tomorrow_rows()
  File "E:\1-program\11-LAMDataServer\lamdataserver\LAMProcessData\process_realtime_finedata.py", line 193, in init_Tomorrow_rows
    _model.objects.bulk_create(insert_data_list)
  File "D:\Program Files\Python37\lib\site-packages\django\db\models\manager.py", line 82, in manager_method
    return getattr(self.get_queryset(), name)(*args, **kwargs)
  File "D:\Program Files\Python37\lib\site-packages\django\db\models\query.py", line 474, in bulk_create
    ids = self._batched_insert(objs_without_pk, fields, batch_size, ignore_conflicts=ignore_conflicts)
  File "D:\Program Files\Python37\lib\site-packages\django\db\models\query.py", line 1211, in _batched_insert
    self._insert(item, fields=fields, using=self.db, ignore_conflicts=ignore_conflicts)
  File "D:\Program Files\Python37\lib\site-packages\django\db\models\query.py", line 1186, in _insert
    return query.get_compiler(using=using).execute_sql(return_id)
  File "D:\Program Files\Python37\lib\site-packages\django\db\models\sql\compiler.py", line 1332, in execute_sql
    cursor.execute(sql, params)
  File "D:\Program Files\Python37\lib\site-packages\django\db\backends\utils.py", line 99, in execute
    return super().execute(sql, params)
  File "D:\Program Files\Python37\lib\site-packages\django\db\backends\utils.py", line 67, in execute
    return self._execute_with_wrappers(sql, params, many=False, executor=self._execute)
  File "D:\Program Files\Python37\lib\site-packages\django\db\backends\utils.py", line 76, in _execute_with_wrappers
    return executor(sql, params, many, context)
  File "D:\Program Files\Python37\lib\site-packages\django\db\backends\utils.py", line 84, in _execute
    return self.cursor.execute(sql, params)
  File "D:\Program Files\Python37\lib\site-packages\django\db\utils.py", line 89, in __exit__
    raise dj_exc_value.with_traceback(traceback) from exc_value
  File "D:\Program Files\Python37\lib\site-packages\django\db\backends\utils.py", line 84, in _execute
    return self.cursor.execute(sql, params)
  File "D:\Program Files\Python37\lib\site-packages\django\db\backends\mysql\base.py", line 71, in execute
    return self.cursor.execute(query, args)
  File "D:\Program Files\Python37\lib\site-packages\MySQLdb\cursors.py", line 209, in execute
    res = self._query(query)
  File "D:\Program Files\Python37\lib\site-packages\MySQLdb\cursors.py", line 315, in _query
    db.query(q)
  File "D:\Program Files\Python37\lib\site-packages\MySQLdb\connections.py", line 239, in query
    _mysql.connection.query(self, query)
django.db.utils.IntegrityError: (1062, "Duplicate entry '1592150400' for key 'LAMProcessData_process_r_acquisition_timestamp_a69ae90c_uniq'")
2020-06-14 17:16:38,914 - _run_jobs - 94 - DEBUG - Exiting worker thread
2020-06-14 17:16:39,871 - trigger_reload - 203 - INFO - E:\1-program\11-LAMDataServer\lamdataserver\LAMProcessData\forms.py changed, reloading.
2020-06-14 17:16:39,871 - shutdown - 111 - INFO - Shutting down thread pool
2020-06-14 17:16:42,285 - _real_add_job - 262 - INFO - Added job "regulartime_task (trigger: interval[1 day, 0:00:00], next run at: 2020-06-14 17:16:52.269253)" to job store "default"
2020-06-14 17:16:42,286 - _real_add_job - 262 - INFO - Added job "cleanup (trigger: cron[day_of_week='*', hour='3', minute='0', second='0'], next run at: 2020-06-15 03:00:00)" to job store "default"
2020-06-14 17:16:42,286 - _real_add_job - 262 - INFO - Added job "OpenLog (trigger: cron[hour='0'], next run at: 2020-06-15 00:00:00)" to job store "default"
2020-06-14 17:16:42,286 - _main_loop - 574 - INFO - Scheduler started
2020-06-14 17:16:42,286 - _main_loop - 579 - DEBUG - Looking for jobs to run
2020-06-14 17:16:42,286 - _main_loop - 588 - DEBUG - Next wakeup is due at 2020-06-14 17:16:52.269253 (in 9.983138 seconds)
2020-06-14 17:16:42,286 - <module> - 63 - DEBUG - SendBefore_NotRecive : [<CNCProcessStatus: CNCProcessStatus object (2038721)>]
2020-06-14 17:16:42,286 - <module> - 64 - DEBUG - Waitfor_Recive : [2038721]
2020-06-14 17:16:52,276 - _main_loop - 579 - DEBUG - Looking for jobs to run
2020-06-14 17:16:52,278 - _run_jobs - 69 - DEBUG - Started worker thread
2020-06-14 17:16:52,278 - _run_job - 509 - INFO - Running job "regulartime_task (trigger: interval[1 day, 0:00:00], next run at: 2020-06-14 17:16:52.269253)" (scheduled at 2020-06-14 17:16:52.269253)
2020-06-14 17:16:52,278 - _main_loop - 588 - DEBUG - Next wakeup is due at 2020-06-15 00:00:00 (in 24187.722883 seconds)
2020-06-14 17:16:52,586 - _run_job - 520 - ERROR - Job "regulartime_task (trigger: interval[1 day, 0:00:00], next run at: 2020-06-15 17:16:52.269253)" raised an exception
Traceback (most recent call last):
  File "D:\Program Files\Python37\lib\site-packages\django\db\backends\utils.py", line 84, in _execute
    return self.cursor.execute(sql, params)
  File "D:\Program Files\Python37\lib\site-packages\django\db\backends\mysql\base.py", line 71, in execute
    return self.cursor.execute(query, args)
  File "D:\Program Files\Python37\lib\site-packages\MySQLdb\cursors.py", line 209, in execute
    res = self._query(query)
  File "D:\Program Files\Python37\lib\site-packages\MySQLdb\cursors.py", line 315, in _query
    db.query(q)
  File "D:\Program Files\Python37\lib\site-packages\MySQLdb\connections.py", line 239, in query
    _mysql.connection.query(self, query)
MySQLdb._exceptions.IntegrityError: (1062, "Duplicate entry '1592150400' for key 'LAMProcessData_process_r_acquisition_timestamp_a69ae90c_uniq'")

The above exception was the direct cause of the following exception:

Traceback (most recent call last):
  File "D:\Program Files\Python37\lib\site-packages\apscheduler\scheduler.py", line 512, in _run_job
    retval = job.func(*job.args, **job.kwargs)
  File "E:\1-program\11-LAMDataServer\lamdataserver\LAMProcessData\views.py", line 5662, in regulartime_task
    RT_FineData.Realtime_FineData.init_Tomorrow_rows()
  File "E:\1-program\11-LAMDataServer\lamdataserver\LAMProcessData\process_realtime_finedata.py", line 193, in init_Tomorrow_rows
    _model.objects.bulk_create(insert_data_list)
  File "D:\Program Files\Python37\lib\site-packages\django\db\models\manager.py", line 82, in manager_method
    return getattr(self.get_queryset(), name)(*args, **kwargs)
  File "D:\Program Files\Python37\lib\site-packages\django\db\models\query.py", line 474, in bulk_create
    ids = self._batched_insert(objs_without_pk, fields, batch_size, ignore_conflicts=ignore_conflicts)
  File "D:\Program Files\Python37\lib\site-packages\django\db\models\query.py", line 1211, in _batched_insert
    self._insert(item, fields=fields, using=self.db, ignore_conflicts=ignore_conflicts)
  File "D:\Program Files\Python37\lib\site-packages\django\db\models\query.py", line 1186, in _insert
    return query.get_compiler(using=using).execute_sql(return_id)
  File "D:\Program Files\Python37\lib\site-packages\django\db\models\sql\compiler.py", line 1332, in execute_sql
    cursor.execute(sql, params)
  File "D:\Program Files\Python37\lib\site-packages\django\db\backends\utils.py", line 99, in execute
    return super().execute(sql, params)
  File "D:\Program Files\Python37\lib\site-packages\django\db\backends\utils.py", line 67, in execute
    return self._execute_with_wrappers(sql, params, many=False, executor=self._execute)
  File "D:\Program Files\Python37\lib\site-packages\django\db\backends\utils.py", line 76, in _execute_with_wrappers
    return executor(sql, params, many, context)
  File "D:\Program Files\Python37\lib\site-packages\django\db\backends\utils.py", line 84, in _execute
    return self.cursor.execute(sql, params)
  File "D:\Program Files\Python37\lib\site-packages\django\db\utils.py", line 89, in __exit__
    raise dj_exc_value.with_traceback(traceback) from exc_value
  File "D:\Program Files\Python37\lib\site-packages\django\db\backends\utils.py", line 84, in _execute
    return self.cursor.execute(sql, params)
  File "D:\Program Files\Python37\lib\site-packages\django\db\backends\mysql\base.py", line 71, in execute
    return self.cursor.execute(query, args)
  File "D:\Program Files\Python37\lib\site-packages\MySQLdb\cursors.py", line 209, in execute
    res = self._query(query)
  File "D:\Program Files\Python37\lib\site-packages\MySQLdb\cursors.py", line 315, in _query
    db.query(q)
  File "D:\Program Files\Python37\lib\site-packages\MySQLdb\connections.py", line 239, in query
    _mysql.connection.query(self, query)
django.db.utils.IntegrityError: (1062, "Duplicate entry '1592150400' for key 'LAMProcessData_process_r_acquisition_timestamp_a69ae90c_uniq'")
2020-06-14 17:16:53,594 - _run_jobs - 94 - DEBUG - Exiting worker thread
2020-06-14 17:17:36,936 - trigger_reload - 203 - INFO - E:\1-program\11-LAMDataServer\lamdataserver\LAMProcessData\forms.py changed, reloading.
2020-06-14 17:17:36,936 - shutdown - 111 - INFO - Shutting down thread pool
2020-06-14 17:17:39,473 - _real_add_job - 262 - INFO - Added job "regulartime_task (trigger: interval[1 day, 0:00:00], next run at: 2020-06-14 17:17:49.473209)" to job store "default"
2020-06-14 17:17:39,473 - _real_add_job - 262 - INFO - Added job "cleanup (trigger: cron[day_of_week='*', hour='3', minute='0', second='0'], next run at: 2020-06-15 03:00:00)" to job store "default"
2020-06-14 17:17:39,473 - _real_add_job - 262 - INFO - Added job "OpenLog (trigger: cron[hour='0'], next run at: 2020-06-15 00:00:00)" to job store "default"
2020-06-14 17:17:39,473 - _main_loop - 574 - INFO - Scheduler started
2020-06-14 17:17:39,473 - _main_loop - 579 - DEBUG - Looking for jobs to run
2020-06-14 17:17:39,473 - _main_loop - 588 - DEBUG - Next wakeup is due at 2020-06-14 17:17:49.473209 (in 10.000001 seconds)
2020-06-14 17:17:39,489 - <module> - 63 - DEBUG - SendBefore_NotRecive : [<CNCProcessStatus: CNCProcessStatus object (2038721)>]
2020-06-14 17:17:39,489 - <module> - 64 - DEBUG - Waitfor_Recive : [2038721]
2020-06-14 17:17:49,482 - _main_loop - 579 - DEBUG - Looking for jobs to run
2020-06-14 17:17:49,482 - _run_jobs - 69 - DEBUG - Started worker thread
2020-06-14 17:17:49,482 - _main_loop - 588 - DEBUG - Next wakeup is due at 2020-06-15 00:00:00 (in 24130.517460 seconds)
2020-06-14 17:17:49,483 - _run_job - 509 - INFO - Running job "regulartime_task (trigger: interval[1 day, 0:00:00], next run at: 2020-06-15 17:17:49.473209)" (scheduled at 2020-06-14 17:17:49.473209)
2020-06-14 17:17:49,803 - _run_job - 520 - ERROR - Job "regulartime_task (trigger: interval[1 day, 0:00:00], next run at: 2020-06-15 17:17:49.473209)" raised an exception
Traceback (most recent call last):
  File "D:\Program Files\Python37\lib\site-packages\django\db\backends\utils.py", line 84, in _execute
    return self.cursor.execute(sql, params)
  File "D:\Program Files\Python37\lib\site-packages\django\db\backends\mysql\base.py", line 71, in execute
    return self.cursor.execute(query, args)
  File "D:\Program Files\Python37\lib\site-packages\MySQLdb\cursors.py", line 209, in execute
    res = self._query(query)
  File "D:\Program Files\Python37\lib\site-packages\MySQLdb\cursors.py", line 315, in _query
    db.query(q)
  File "D:\Program Files\Python37\lib\site-packages\MySQLdb\connections.py", line 239, in query
    _mysql.connection.query(self, query)
MySQLdb._exceptions.IntegrityError: (1062, "Duplicate entry '1592150400' for key 'LAMProcessData_process_r_acquisition_timestamp_a69ae90c_uniq'")

The above exception was the direct cause of the following exception:

Traceback (most recent call last):
  File "D:\Program Files\Python37\lib\site-packages\apscheduler\scheduler.py", line 512, in _run_job
    retval = job.func(*job.args, **job.kwargs)
  File "E:\1-program\11-LAMDataServer\lamdataserver\LAMProcessData\views.py", line 5662, in regulartime_task
    RT_FineData.Realtime_FineData.init_Tomorrow_rows()
  File "E:\1-program\11-LAMDataServer\lamdataserver\LAMProcessData\process_realtime_finedata.py", line 193, in init_Tomorrow_rows
    _model.objects.bulk_create(insert_data_list)
  File "D:\Program Files\Python37\lib\site-packages\django\db\models\manager.py", line 82, in manager_method
    return getattr(self.get_queryset(), name)(*args, **kwargs)
  File "D:\Program Files\Python37\lib\site-packages\django\db\models\query.py", line 474, in bulk_create
    ids = self._batched_insert(objs_without_pk, fields, batch_size, ignore_conflicts=ignore_conflicts)
  File "D:\Program Files\Python37\lib\site-packages\django\db\models\query.py", line 1211, in _batched_insert
    self._insert(item, fields=fields, using=self.db, ignore_conflicts=ignore_conflicts)
  File "D:\Program Files\Python37\lib\site-packages\django\db\models\query.py", line 1186, in _insert
    return query.get_compiler(using=using).execute_sql(return_id)
  File "D:\Program Files\Python37\lib\site-packages\django\db\models\sql\compiler.py", line 1332, in execute_sql
    cursor.execute(sql, params)
  File "D:\Program Files\Python37\lib\site-packages\django\db\backends\utils.py", line 99, in execute
    return super().execute(sql, params)
  File "D:\Program Files\Python37\lib\site-packages\django\db\backends\utils.py", line 67, in execute
    return self._execute_with_wrappers(sql, params, many=False, executor=self._execute)
  File "D:\Program Files\Python37\lib\site-packages\django\db\backends\utils.py", line 76, in _execute_with_wrappers
    return executor(sql, params, many, context)
  File "D:\Program Files\Python37\lib\site-packages\django\db\backends\utils.py", line 84, in _execute
    return self.cursor.execute(sql, params)
  File "D:\Program Files\Python37\lib\site-packages\django\db\utils.py", line 89, in __exit__
    raise dj_exc_value.with_traceback(traceback) from exc_value
  File "D:\Program Files\Python37\lib\site-packages\django\db\backends\utils.py", line 84, in _execute
    return self.cursor.execute(sql, params)
  File "D:\Program Files\Python37\lib\site-packages\django\db\backends\mysql\base.py", line 71, in execute
    return self.cursor.execute(query, args)
  File "D:\Program Files\Python37\lib\site-packages\MySQLdb\cursors.py", line 209, in execute
    res = self._query(query)
  File "D:\Program Files\Python37\lib\site-packages\MySQLdb\cursors.py", line 315, in _query
    db.query(q)
  File "D:\Program Files\Python37\lib\site-packages\MySQLdb\connections.py", line 239, in query
    _mysql.connection.query(self, query)
django.db.utils.IntegrityError: (1062, "Duplicate entry '1592150400' for key 'LAMProcessData_process_r_acquisition_timestamp_a69ae90c_uniq'")
2020-06-14 17:17:50,804 - _run_jobs - 94 - DEBUG - Exiting worker thread
2020-06-14 17:25:55,836 - log_response - 228 - WARNING - Not Found: /favicon.ico
2020-06-14 17:25:56,434 - log_response - 228 - WARNING - Not Found: /favicon.ico
2020-06-14 17:25:57,049 - log_response - 228 - WARNING - Not Found: /favicon.ico
2020-06-14 17:25:57,651 - log_response - 228 - WARNING - Not Found: /favicon.ico
2020-06-14 17:25:58,266 - log_response - 228 - WARNING - Not Found: /favicon.ico
2020-06-14 17:27:15,685 - _real_add_job - 262 - INFO - Added job "regulartime_task (trigger: interval[1 day, 0:00:00], next run at: 2020-06-14 17:27:25.685676)" to job store "default"
2020-06-14 17:27:15,685 - _real_add_job - 262 - INFO - Added job "cleanup (trigger: cron[day_of_week='*', hour='3', minute='0', second='0'], next run at: 2020-06-15 03:00:00)" to job store "default"
2020-06-14 17:27:15,685 - _real_add_job - 262 - INFO - Added job "OpenLog (trigger: cron[hour='0'], next run at: 2020-06-15 00:00:00)" to job store "default"
2020-06-14 17:27:15,685 - _main_loop - 574 - INFO - Scheduler started
2020-06-14 17:27:15,685 - _main_loop - 579 - DEBUG - Looking for jobs to run
2020-06-14 17:27:15,685 - _main_loop - 588 - DEBUG - Next wakeup is due at 2020-06-14 17:27:25.685676 (in 10.000000 seconds)
2020-06-14 17:27:15,702 - <module> - 63 - DEBUG - SendBefore_NotRecive : [<CNCProcessStatus: CNCProcessStatus object (2038721)>]
2020-06-14 17:27:15,702 - <module> - 64 - DEBUG - Waitfor_Recive : [2038721]
2020-06-14 17:27:25,709 - _main_loop - 579 - DEBUG - Looking for jobs to run
2020-06-14 17:27:25,710 - _run_jobs - 69 - DEBUG - Started worker thread
2020-06-14 17:27:25,710 - _main_loop - 588 - DEBUG - Next wakeup is due at 2020-06-15 00:00:00 (in 23554.290359 seconds)
2020-06-14 17:27:25,710 - _run_job - 509 - INFO - Running job "regulartime_task (trigger: interval[1 day, 0:00:00], next run at: 2020-06-15 17:27:25.685676)" (scheduled at 2020-06-14 17:27:25.685676)
2020-06-14 17:27:26,017 - _run_job - 520 - ERROR - Job "regulartime_task (trigger: interval[1 day, 0:00:00], next run at: 2020-06-15 17:27:25.685676)" raised an exception
Traceback (most recent call last):
  File "D:\Program Files\Python37\lib\site-packages\django\db\backends\utils.py", line 84, in _execute
    return self.cursor.execute(sql, params)
  File "D:\Program Files\Python37\lib\site-packages\django\db\backends\mysql\base.py", line 71, in execute
    return self.cursor.execute(query, args)
  File "D:\Program Files\Python37\lib\site-packages\MySQLdb\cursors.py", line 209, in execute
    res = self._query(query)
  File "D:\Program Files\Python37\lib\site-packages\MySQLdb\cursors.py", line 315, in _query
    db.query(q)
  File "D:\Program Files\Python37\lib\site-packages\MySQLdb\connections.py", line 239, in query
    _mysql.connection.query(self, query)
MySQLdb._exceptions.IntegrityError: (1062, "Duplicate entry '1592150400' for key 'LAMProcessData_process_r_acquisition_timestamp_a69ae90c_uniq'")

The above exception was the direct cause of the following exception:

Traceback (most recent call last):
  File "D:\Program Files\Python37\lib\site-packages\apscheduler\scheduler.py", line 512, in _run_job
    retval = job.func(*job.args, **job.kwargs)
  File "E:\1-program\11-LAMDataServer\lamdataserver\LAMProcessData\views.py", line 5662, in regulartime_task
    RT_FineData.Realtime_FineData.init_Tomorrow_rows()
  File "E:\1-program\11-LAMDataServer\lamdataserver\LAMProcessData\process_realtime_finedata.py", line 193, in init_Tomorrow_rows
    _model.objects.bulk_create(insert_data_list)
  File "D:\Program Files\Python37\lib\site-packages\django\db\models\manager.py", line 82, in manager_method
    return getattr(self.get_queryset(), name)(*args, **kwargs)
  File "D:\Program Files\Python37\lib\site-packages\django\db\models\query.py", line 474, in bulk_create
    ids = self._batched_insert(objs_without_pk, fields, batch_size, ignore_conflicts=ignore_conflicts)
  File "D:\Program Files\Python37\lib\site-packages\django\db\models\query.py", line 1211, in _batched_insert
    self._insert(item, fields=fields, using=self.db, ignore_conflicts=ignore_conflicts)
  File "D:\Program Files\Python37\lib\site-packages\django\db\models\query.py", line 1186, in _insert
    return query.get_compiler(using=using).execute_sql(return_id)
  File "D:\Program Files\Python37\lib\site-packages\django\db\models\sql\compiler.py", line 1332, in execute_sql
    cursor.execute(sql, params)
  File "D:\Program Files\Python37\lib\site-packages\django\db\backends\utils.py", line 99, in execute
    return super().execute(sql, params)
  File "D:\Program Files\Python37\lib\site-packages\django\db\backends\utils.py", line 67, in execute
    return self._execute_with_wrappers(sql, params, many=False, executor=self._execute)
  File "D:\Program Files\Python37\lib\site-packages\django\db\backends\utils.py", line 76, in _execute_with_wrappers
    return executor(sql, params, many, context)
  File "D:\Program Files\Python37\lib\site-packages\django\db\backends\utils.py", line 84, in _execute
    return self.cursor.execute(sql, params)
  File "D:\Program Files\Python37\lib\site-packages\django\db\utils.py", line 89, in __exit__
    raise dj_exc_value.with_traceback(traceback) from exc_value
  File "D:\Program Files\Python37\lib\site-packages\django\db\backends\utils.py", line 84, in _execute
    return self.cursor.execute(sql, params)
  File "D:\Program Files\Python37\lib\site-packages\django\db\backends\mysql\base.py", line 71, in execute
    return self.cursor.execute(query, args)
  File "D:\Program Files\Python37\lib\site-packages\MySQLdb\cursors.py", line 209, in execute
    res = self._query(query)
  File "D:\Program Files\Python37\lib\site-packages\MySQLdb\cursors.py", line 315, in _query
    db.query(q)
  File "D:\Program Files\Python37\lib\site-packages\MySQLdb\connections.py", line 239, in query
    _mysql.connection.query(self, query)
django.db.utils.IntegrityError: (1062, "Duplicate entry '1592150400' for key 'LAMProcessData_process_r_acquisition_timestamp_a69ae90c_uniq'")
2020-06-14 17:27:27,033 - _run_jobs - 94 - DEBUG - Exiting worker thread
2020-06-14 17:51:24,437 - _real_add_job - 262 - INFO - Added job "regulartime_task (trigger: interval[1 day, 0:00:00], next run at: 2020-06-14 17:51:34.437058)" to job store "default"
2020-06-14 17:51:24,437 - _real_add_job - 262 - INFO - Added job "cleanup (trigger: cron[day_of_week='*', hour='3', minute='0', second='0'], next run at: 2020-06-15 03:00:00)" to job store "default"
2020-06-14 17:51:24,437 - _real_add_job - 262 - INFO - Added job "OpenLog (trigger: cron[hour='0'], next run at: 2020-06-15 00:00:00)" to job store "default"
2020-06-14 17:51:24,437 - _main_loop - 574 - INFO - Scheduler started
2020-06-14 17:51:24,437 - _main_loop - 579 - DEBUG - Looking for jobs to run
2020-06-14 17:51:24,437 - _main_loop - 588 - DEBUG - Next wakeup is due at 2020-06-14 17:51:34.437058 (in 10.000000 seconds)
2020-06-14 17:51:24,449 - <module> - 63 - DEBUG - SendBefore_NotRecive : [<CNCProcessStatus: CNCProcessStatus object (2038721)>]
2020-06-14 17:51:24,449 - <module> - 64 - DEBUG - Waitfor_Recive : [2038721]
2020-06-14 17:51:34,437 - _main_loop - 579 - DEBUG - Looking for jobs to run
2020-06-14 17:51:34,438 - _run_jobs - 69 - DEBUG - Started worker thread
2020-06-14 17:51:34,438 - _run_job - 509 - INFO - Running job "regulartime_task (trigger: interval[1 day, 0:00:00], next run at: 2020-06-14 17:51:34.437058)" (scheduled at 2020-06-14 17:51:34.437058)
2020-06-14 17:51:34,438 - _main_loop - 588 - DEBUG - Next wakeup is due at 2020-06-15 00:00:00 (in 22105.562303 seconds)
2020-06-14 17:51:34,777 - log_response - 228 - WARNING - Not Found: /LAMProcessData/PracticalTools/MakeMainProgramFile/addStructure/1/
2020-06-14 17:51:34,789 - _run_job - 520 - ERROR - Job "regulartime_task (trigger: interval[1 day, 0:00:00], next run at: 2020-06-15 17:51:34.437058)" raised an exception
Traceback (most recent call last):
  File "D:\Program Files\Python37\lib\site-packages\django\db\backends\utils.py", line 84, in _execute
    return self.cursor.execute(sql, params)
  File "D:\Program Files\Python37\lib\site-packages\django\db\backends\mysql\base.py", line 71, in execute
    return self.cursor.execute(query, args)
  File "D:\Program Files\Python37\lib\site-packages\MySQLdb\cursors.py", line 209, in execute
    res = self._query(query)
  File "D:\Program Files\Python37\lib\site-packages\MySQLdb\cursors.py", line 315, in _query
    db.query(q)
  File "D:\Program Files\Python37\lib\site-packages\MySQLdb\connections.py", line 239, in query
    _mysql.connection.query(self, query)
MySQLdb._exceptions.IntegrityError: (1062, "Duplicate entry '1592150400' for key 'LAMProcessData_process_r_acquisition_timestamp_a69ae90c_uniq'")

The above exception was the direct cause of the following exception:

Traceback (most recent call last):
  File "D:\Program Files\Python37\lib\site-packages\apscheduler\scheduler.py", line 512, in _run_job
    retval = job.func(*job.args, **job.kwargs)
  File "E:\1-program\11-LAMDataServer\lamdataserver\LAMProcessData\views.py", line 5662, in regulartime_task
    RT_FineData.Realtime_FineData.init_Tomorrow_rows()
  File "E:\1-program\11-LAMDataServer\lamdataserver\LAMProcessData\process_realtime_finedata.py", line 193, in init_Tomorrow_rows
    _model.objects.bulk_create(insert_data_list)
  File "D:\Program Files\Python37\lib\site-packages\django\db\models\manager.py", line 82, in manager_method
    return getattr(self.get_queryset(), name)(*args, **kwargs)
  File "D:\Program Files\Python37\lib\site-packages\django\db\models\query.py", line 474, in bulk_create
    ids = self._batched_insert(objs_without_pk, fields, batch_size, ignore_conflicts=ignore_conflicts)
  File "D:\Program Files\Python37\lib\site-packages\django\db\models\query.py", line 1211, in _batched_insert
    self._insert(item, fields=fields, using=self.db, ignore_conflicts=ignore_conflicts)
  File "D:\Program Files\Python37\lib\site-packages\django\db\models\query.py", line 1186, in _insert
    return query.get_compiler(using=using).execute_sql(return_id)
  File "D:\Program Files\Python37\lib\site-packages\django\db\models\sql\compiler.py", line 1332, in execute_sql
    cursor.execute(sql, params)
  File "D:\Program Files\Python37\lib\site-packages\django\db\backends\utils.py", line 99, in execute
    return super().execute(sql, params)
  File "D:\Program Files\Python37\lib\site-packages\django\db\backends\utils.py", line 67, in execute
    return self._execute_with_wrappers(sql, params, many=False, executor=self._execute)
  File "D:\Program Files\Python37\lib\site-packages\django\db\backends\utils.py", line 76, in _execute_with_wrappers
    return executor(sql, params, many, context)
  File "D:\Program Files\Python37\lib\site-packages\django\db\backends\utils.py", line 84, in _execute
    return self.cursor.execute(sql, params)
  File "D:\Program Files\Python37\lib\site-packages\django\db\utils.py", line 89, in __exit__
    raise dj_exc_value.with_traceback(traceback) from exc_value
  File "D:\Program Files\Python37\lib\site-packages\django\db\backends\utils.py", line 84, in _execute
    return self.cursor.execute(sql, params)
  File "D:\Program Files\Python37\lib\site-packages\django\db\backends\mysql\base.py", line 71, in execute
    return self.cursor.execute(query, args)
  File "D:\Program Files\Python37\lib\site-packages\MySQLdb\cursors.py", line 209, in execute
    res = self._query(query)
  File "D:\Program Files\Python37\lib\site-packages\MySQLdb\cursors.py", line 315, in _query
    db.query(q)
  File "D:\Program Files\Python37\lib\site-packages\MySQLdb\connections.py", line 239, in query
    _mysql.connection.query(self, query)
django.db.utils.IntegrityError: (1062, "Duplicate entry '1592150400' for key 'LAMProcessData_process_r_acquisition_timestamp_a69ae90c_uniq'")
2020-06-14 17:51:35,796 - _run_jobs - 94 - DEBUG - Exiting worker thread
2020-06-14 17:51:43,396 - log_response - 228 - WARNING - Not Found: /LAMProcessData/PracticalTools/MakeMainProgramFile/addStructure/4/
2020-06-14 17:56:48,124 - trigger_reload - 203 - INFO - E:\1-program\11-LAMDataServer\lamdataserver\LAMProcessData\urls.py changed, reloading.
2020-06-14 17:56:48,127 - shutdown - 111 - INFO - Shutting down thread pool
2020-06-14 17:56:51,574 - _real_add_job - 262 - INFO - Added job "regulartime_task (trigger: interval[1 day, 0:00:00], next run at: 2020-06-14 17:57:01.572269)" to job store "default"
2020-06-14 17:56:51,574 - _real_add_job - 262 - INFO - Added job "cleanup (trigger: cron[day_of_week='*', hour='3', minute='0', second='0'], next run at: 2020-06-15 03:00:00)" to job store "default"
2020-06-14 17:56:51,574 - _real_add_job - 262 - INFO - Added job "OpenLog (trigger: cron[hour='0'], next run at: 2020-06-15 00:00:00)" to job store "default"
2020-06-14 17:56:51,576 - _main_loop - 574 - INFO - Scheduler started
2020-06-14 17:56:51,576 - _main_loop - 579 - DEBUG - Looking for jobs to run
2020-06-14 17:56:51,577 - _main_loop - 588 - DEBUG - Next wakeup is due at 2020-06-14 17:57:01.572269 (in 9.995013 seconds)
2020-06-14 17:56:51,594 - <module> - 63 - DEBUG - SendBefore_NotRecive : [<CNCProcessStatus: CNCProcessStatus object (2038721)>]
2020-06-14 17:56:51,594 - <module> - 64 - DEBUG - Waitfor_Recive : [2038721]
2020-06-14 17:57:01,586 - _main_loop - 579 - DEBUG - Looking for jobs to run
2020-06-14 17:57:01,587 - _run_jobs - 69 - DEBUG - Started worker thread
2020-06-14 17:57:01,587 - _run_job - 509 - INFO - Running job "regulartime_task (trigger: interval[1 day, 0:00:00], next run at: 2020-06-14 17:57:01.572269)" (scheduled at 2020-06-14 17:57:01.572269)
2020-06-14 17:57:01,587 - _main_loop - 588 - DEBUG - Next wakeup is due at 2020-06-15 00:00:00 (in 21778.413671 seconds)
2020-06-14 17:57:01,910 - _run_job - 520 - ERROR - Job "regulartime_task (trigger: interval[1 day, 0:00:00], next run at: 2020-06-15 17:57:01.572269)" raised an exception
Traceback (most recent call last):
  File "D:\Program Files\Python37\lib\site-packages\django\db\backends\utils.py", line 84, in _execute
    return self.cursor.execute(sql, params)
  File "D:\Program Files\Python37\lib\site-packages\django\db\backends\mysql\base.py", line 71, in execute
    return self.cursor.execute(query, args)
  File "D:\Program Files\Python37\lib\site-packages\MySQLdb\cursors.py", line 209, in execute
    res = self._query(query)
  File "D:\Program Files\Python37\lib\site-packages\MySQLdb\cursors.py", line 315, in _query
    db.query(q)
  File "D:\Program Files\Python37\lib\site-packages\MySQLdb\connections.py", line 239, in query
    _mysql.connection.query(self, query)
MySQLdb._exceptions.IntegrityError: (1062, "Duplicate entry '1592150400' for key 'LAMProcessData_process_r_acquisition_timestamp_a69ae90c_uniq'")

The above exception was the direct cause of the following exception:

Traceback (most recent call last):
  File "D:\Program Files\Python37\lib\site-packages\apscheduler\scheduler.py", line 512, in _run_job
    retval = job.func(*job.args, **job.kwargs)
  File "E:\1-program\11-LAMDataServer\lamdataserver\LAMProcessData\views.py", line 5662, in regulartime_task
    RT_FineData.Realtime_FineData.init_Tomorrow_rows()
  File "E:\1-program\11-LAMDataServer\lamdataserver\LAMProcessData\process_realtime_finedata.py", line 193, in init_Tomorrow_rows
    _model.objects.bulk_create(insert_data_list)
  File "D:\Program Files\Python37\lib\site-packages\django\db\models\manager.py", line 82, in manager_method
    return getattr(self.get_queryset(), name)(*args, **kwargs)
  File "D:\Program Files\Python37\lib\site-packages\django\db\models\query.py", line 474, in bulk_create
    ids = self._batched_insert(objs_without_pk, fields, batch_size, ignore_conflicts=ignore_conflicts)
  File "D:\Program Files\Python37\lib\site-packages\django\db\models\query.py", line 1211, in _batched_insert
    self._insert(item, fields=fields, using=self.db, ignore_conflicts=ignore_conflicts)
  File "D:\Program Files\Python37\lib\site-packages\django\db\models\query.py", line 1186, in _insert
    return query.get_compiler(using=using).execute_sql(return_id)
  File "D:\Program Files\Python37\lib\site-packages\django\db\models\sql\compiler.py", line 1332, in execute_sql
    cursor.execute(sql, params)
  File "D:\Program Files\Python37\lib\site-packages\django\db\backends\utils.py", line 99, in execute
    return super().execute(sql, params)
  File "D:\Program Files\Python37\lib\site-packages\django\db\backends\utils.py", line 67, in execute
    return self._execute_with_wrappers(sql, params, many=False, executor=self._execute)
  File "D:\Program Files\Python37\lib\site-packages\django\db\backends\utils.py", line 76, in _execute_with_wrappers
    return executor(sql, params, many, context)
  File "D:\Program Files\Python37\lib\site-packages\django\db\backends\utils.py", line 84, in _execute
    return self.cursor.execute(sql, params)
  File "D:\Program Files\Python37\lib\site-packages\django\db\utils.py", line 89, in __exit__
    raise dj_exc_value.with_traceback(traceback) from exc_value
  File "D:\Program Files\Python37\lib\site-packages\django\db\backends\utils.py", line 84, in _execute
    return self.cursor.execute(sql, params)
  File "D:\Program Files\Python37\lib\site-packages\django\db\backends\mysql\base.py", line 71, in execute
    return self.cursor.execute(query, args)
  File "D:\Program Files\Python37\lib\site-packages\MySQLdb\cursors.py", line 209, in execute
    res = self._query(query)
  File "D:\Program Files\Python37\lib\site-packages\MySQLdb\cursors.py", line 315, in _query
    db.query(q)
  File "D:\Program Files\Python37\lib\site-packages\MySQLdb\connections.py", line 239, in query
    _mysql.connection.query(self, query)
django.db.utils.IntegrityError: (1062, "Duplicate entry '1592150400' for key 'LAMProcessData_process_r_acquisition_timestamp_a69ae90c_uniq'")
2020-06-14 17:57:02,918 - _run_jobs - 94 - DEBUG - Exiting worker thread
2020-06-14 18:01:49,500 - trigger_reload - 203 - INFO - E:\1-program\11-LAMDataServer\lamdataserver\LAMProcessData\views.py changed, reloading.
2020-06-14 18:01:49,501 - shutdown - 111 - INFO - Shutting down thread pool
2020-06-14 19:00:11,621 - _real_add_job - 262 - INFO - Added job "regulartime_task (trigger: interval[1 day, 0:00:00], next run at: 2020-06-14 19:00:21.620660)" to job store "default"
2020-06-14 19:00:11,622 - _real_add_job - 262 - INFO - Added job "cleanup (trigger: cron[day_of_week='*', hour='3', minute='0', second='0'], next run at: 2020-06-15 03:00:00)" to job store "default"
2020-06-14 19:00:11,622 - _real_add_job - 262 - INFO - Added job "OpenLog (trigger: cron[hour='0'], next run at: 2020-06-15 00:00:00)" to job store "default"
2020-06-14 19:00:11,622 - _main_loop - 574 - INFO - Scheduler started
2020-06-14 19:00:11,623 - _main_loop - 579 - DEBUG - Looking for jobs to run
2020-06-14 19:00:11,623 - _main_loop - 588 - DEBUG - Next wakeup is due at 2020-06-14 19:00:21.620660 (in 9.996717 seconds)
2020-06-14 19:00:11,636 - <module> - 63 - DEBUG - SendBefore_NotRecive : [<CNCProcessStatus: CNCProcessStatus object (2038721)>]
2020-06-14 19:00:11,637 - <module> - 64 - DEBUG - Waitfor_Recive : [2038721]
2020-06-14 19:00:21,635 - _main_loop - 579 - DEBUG - Looking for jobs to run
2020-06-14 19:00:21,636 - _run_jobs - 69 - DEBUG - Started worker thread
2020-06-14 19:00:21,636 - _main_loop - 588 - DEBUG - Next wakeup is due at 2020-06-15 00:00:00 (in 17978.364644 seconds)
2020-06-14 19:00:21,636 - _run_job - 509 - INFO - Running job "regulartime_task (trigger: interval[1 day, 0:00:00], next run at: 2020-06-15 19:00:21.620660)" (scheduled at 2020-06-14 19:00:21.620660)
2020-06-14 19:00:21,974 - _run_job - 520 - ERROR - Job "regulartime_task (trigger: interval[1 day, 0:00:00], next run at: 2020-06-15 19:00:21.620660)" raised an exception
Traceback (most recent call last):
  File "D:\Program Files\Python37\lib\site-packages\django\db\backends\utils.py", line 84, in _execute
    return self.cursor.execute(sql, params)
  File "D:\Program Files\Python37\lib\site-packages\django\db\backends\mysql\base.py", line 71, in execute
    return self.cursor.execute(query, args)
  File "D:\Program Files\Python37\lib\site-packages\MySQLdb\cursors.py", line 209, in execute
    res = self._query(query)
  File "D:\Program Files\Python37\lib\site-packages\MySQLdb\cursors.py", line 315, in _query
    db.query(q)
  File "D:\Program Files\Python37\lib\site-packages\MySQLdb\connections.py", line 239, in query
    _mysql.connection.query(self, query)
MySQLdb._exceptions.IntegrityError: (1062, "Duplicate entry '1592150400' for key 'LAMProcessData_process_r_acquisition_timestamp_a69ae90c_uniq'")

The above exception was the direct cause of the following exception:

Traceback (most recent call last):
  File "D:\Program Files\Python37\lib\site-packages\apscheduler\scheduler.py", line 512, in _run_job
    retval = job.func(*job.args, **job.kwargs)
  File "E:\1-program\11-LAMDataServer\lamdataserver\LAMProcessData\views.py", line 5705, in regulartime_task
    RT_FineData.Realtime_FineData.init_Tomorrow_rows()
  File "E:\1-program\11-LAMDataServer\lamdataserver\LAMProcessData\process_realtime_finedata.py", line 193, in init_Tomorrow_rows
    _model.objects.bulk_create(insert_data_list)
  File "D:\Program Files\Python37\lib\site-packages\django\db\models\manager.py", line 82, in manager_method
    return getattr(self.get_queryset(), name)(*args, **kwargs)
  File "D:\Program Files\Python37\lib\site-packages\django\db\models\query.py", line 474, in bulk_create
    ids = self._batched_insert(objs_without_pk, fields, batch_size, ignore_conflicts=ignore_conflicts)
  File "D:\Program Files\Python37\lib\site-packages\django\db\models\query.py", line 1211, in _batched_insert
    self._insert(item, fields=fields, using=self.db, ignore_conflicts=ignore_conflicts)
  File "D:\Program Files\Python37\lib\site-packages\django\db\models\query.py", line 1186, in _insert
    return query.get_compiler(using=using).execute_sql(return_id)
  File "D:\Program Files\Python37\lib\site-packages\django\db\models\sql\compiler.py", line 1332, in execute_sql
    cursor.execute(sql, params)
  File "D:\Program Files\Python37\lib\site-packages\django\db\backends\utils.py", line 99, in execute
    return super().execute(sql, params)
  File "D:\Program Files\Python37\lib\site-packages\django\db\backends\utils.py", line 67, in execute
    return self._execute_with_wrappers(sql, params, many=False, executor=self._execute)
  File "D:\Program Files\Python37\lib\site-packages\django\db\backends\utils.py", line 76, in _execute_with_wrappers
    return executor(sql, params, many, context)
  File "D:\Program Files\Python37\lib\site-packages\django\db\backends\utils.py", line 84, in _execute
    return self.cursor.execute(sql, params)
  File "D:\Program Files\Python37\lib\site-packages\django\db\utils.py", line 89, in __exit__
    raise dj_exc_value.with_traceback(traceback) from exc_value
  File "D:\Program Files\Python37\lib\site-packages\django\db\backends\utils.py", line 84, in _execute
    return self.cursor.execute(sql, params)
  File "D:\Program Files\Python37\lib\site-packages\django\db\backends\mysql\base.py", line 71, in execute
    return self.cursor.execute(query, args)
  File "D:\Program Files\Python37\lib\site-packages\MySQLdb\cursors.py", line 209, in execute
    res = self._query(query)
  File "D:\Program Files\Python37\lib\site-packages\MySQLdb\cursors.py", line 315, in _query
    db.query(q)
  File "D:\Program Files\Python37\lib\site-packages\MySQLdb\connections.py", line 239, in query
    _mysql.connection.query(self, query)
django.db.utils.IntegrityError: (1062, "Duplicate entry '1592150400' for key 'LAMProcessData_process_r_acquisition_timestamp_a69ae90c_uniq'")
2020-06-14 19:00:22,984 - _run_jobs - 94 - DEBUG - Exiting worker thread
2020-06-14 19:09:07,410 - trigger_reload - 203 - INFO - E:\1-program\11-LAMDataServer\lamdataserver\LAMProcessData\forms.py changed, reloading.
2020-06-14 19:09:07,411 - shutdown - 111 - INFO - Shutting down thread pool
2020-06-14 19:09:09,623 - _real_add_job - 262 - INFO - Added job "regulartime_task (trigger: interval[1 day, 0:00:00], next run at: 2020-06-14 19:09:19.622495)" to job store "default"
2020-06-14 19:09:09,623 - _real_add_job - 262 - INFO - Added job "cleanup (trigger: cron[day_of_week='*', hour='3', minute='0', second='0'], next run at: 2020-06-15 03:00:00)" to job store "default"
2020-06-14 19:09:09,624 - _real_add_job - 262 - INFO - Added job "OpenLog (trigger: cron[hour='0'], next run at: 2020-06-15 00:00:00)" to job store "default"
2020-06-14 19:09:09,624 - _main_loop - 574 - INFO - Scheduler started
2020-06-14 19:09:09,624 - _main_loop - 579 - DEBUG - Looking for jobs to run
2020-06-14 19:09:09,624 - _main_loop - 588 - DEBUG - Next wakeup is due at 2020-06-14 19:09:19.622495 (in 9.998421 seconds)
2020-06-14 19:09:09,634 - <module> - 63 - DEBUG - SendBefore_NotRecive : [<CNCProcessStatus: CNCProcessStatus object (2038721)>]
2020-06-14 19:09:09,634 - <module> - 64 - DEBUG - Waitfor_Recive : [2038721]
2020-06-14 19:09:19,624 - _main_loop - 579 - DEBUG - Looking for jobs to run
2020-06-14 19:09:19,624 - _run_jobs - 69 - DEBUG - Started worker thread
2020-06-14 19:09:19,625 - _main_loop - 588 - DEBUG - Next wakeup is due at 2020-06-15 00:00:00 (in 17440.375622 seconds)
2020-06-14 19:09:19,625 - _run_job - 509 - INFO - Running job "regulartime_task (trigger: interval[1 day, 0:00:00], next run at: 2020-06-15 19:09:19.622495)" (scheduled at 2020-06-14 19:09:19.622495)
2020-06-14 19:09:19,958 - _run_job - 520 - ERROR - Job "regulartime_task (trigger: interval[1 day, 0:00:00], next run at: 2020-06-15 19:09:19.622495)" raised an exception
Traceback (most recent call last):
  File "D:\Program Files\Python37\lib\site-packages\django\db\backends\utils.py", line 84, in _execute
    return self.cursor.execute(sql, params)
  File "D:\Program Files\Python37\lib\site-packages\django\db\backends\mysql\base.py", line 71, in execute
    return self.cursor.execute(query, args)
  File "D:\Program Files\Python37\lib\site-packages\MySQLdb\cursors.py", line 209, in execute
    res = self._query(query)
  File "D:\Program Files\Python37\lib\site-packages\MySQLdb\cursors.py", line 315, in _query
    db.query(q)
  File "D:\Program Files\Python37\lib\site-packages\MySQLdb\connections.py", line 239, in query
    _mysql.connection.query(self, query)
MySQLdb._exceptions.IntegrityError: (1062, "Duplicate entry '1592150400' for key 'LAMProcessData_process_r_acquisition_timestamp_a69ae90c_uniq'")

The above exception was the direct cause of the following exception:

Traceback (most recent call last):
  File "D:\Program Files\Python37\lib\site-packages\apscheduler\scheduler.py", line 512, in _run_job
    retval = job.func(*job.args, **job.kwargs)
  File "E:\1-program\11-LAMDataServer\lamdataserver\LAMProcessData\views.py", line 5705, in regulartime_task
    RT_FineData.Realtime_FineData.init_Tomorrow_rows()
  File "E:\1-program\11-LAMDataServer\lamdataserver\LAMProcessData\process_realtime_finedata.py", line 193, in init_Tomorrow_rows
    _model.objects.bulk_create(insert_data_list)
  File "D:\Program Files\Python37\lib\site-packages\django\db\models\manager.py", line 82, in manager_method
    return getattr(self.get_queryset(), name)(*args, **kwargs)
  File "D:\Program Files\Python37\lib\site-packages\django\db\models\query.py", line 474, in bulk_create
    ids = self._batched_insert(objs_without_pk, fields, batch_size, ignore_conflicts=ignore_conflicts)
  File "D:\Program Files\Python37\lib\site-packages\django\db\models\query.py", line 1211, in _batched_insert
    self._insert(item, fields=fields, using=self.db, ignore_conflicts=ignore_conflicts)
  File "D:\Program Files\Python37\lib\site-packages\django\db\models\query.py", line 1186, in _insert
    return query.get_compiler(using=using).execute_sql(return_id)
  File "D:\Program Files\Python37\lib\site-packages\django\db\models\sql\compiler.py", line 1332, in execute_sql
    cursor.execute(sql, params)
  File "D:\Program Files\Python37\lib\site-packages\django\db\backends\utils.py", line 99, in execute
    return super().execute(sql, params)
  File "D:\Program Files\Python37\lib\site-packages\django\db\backends\utils.py", line 67, in execute
    return self._execute_with_wrappers(sql, params, many=False, executor=self._execute)
  File "D:\Program Files\Python37\lib\site-packages\django\db\backends\utils.py", line 76, in _execute_with_wrappers
    return executor(sql, params, many, context)
  File "D:\Program Files\Python37\lib\site-packages\django\db\backends\utils.py", line 84, in _execute
    return self.cursor.execute(sql, params)
  File "D:\Program Files\Python37\lib\site-packages\django\db\utils.py", line 89, in __exit__
    raise dj_exc_value.with_traceback(traceback) from exc_value
  File "D:\Program Files\Python37\lib\site-packages\django\db\backends\utils.py", line 84, in _execute
    return self.cursor.execute(sql, params)
  File "D:\Program Files\Python37\lib\site-packages\django\db\backends\mysql\base.py", line 71, in execute
    return self.cursor.execute(query, args)
  File "D:\Program Files\Python37\lib\site-packages\MySQLdb\cursors.py", line 209, in execute
    res = self._query(query)
  File "D:\Program Files\Python37\lib\site-packages\MySQLdb\cursors.py", line 315, in _query
    db.query(q)
  File "D:\Program Files\Python37\lib\site-packages\MySQLdb\connections.py", line 239, in query
    _mysql.connection.query(self, query)
django.db.utils.IntegrityError: (1062, "Duplicate entry '1592150400' for key 'LAMProcessData_process_r_acquisition_timestamp_a69ae90c_uniq'")
2020-06-14 19:09:20,964 - _run_jobs - 94 - DEBUG - Exiting worker thread
2020-06-14 23:10:14,557 - trigger_reload - 203 - INFO - E:\1-program\11-LAMDataServer\lamdataserver\LAMProcessData\forms.py changed, reloading.
2020-06-14 23:10:14,559 - shutdown - 111 - INFO - Shutting down thread pool
2020-06-14 23:10:16,899 - _real_add_job - 262 - INFO - Added job "regulartime_task (trigger: interval[1 day, 0:00:00], next run at: 2020-06-14 23:10:26.898486)" to job store "default"
2020-06-14 23:10:16,899 - _real_add_job - 262 - INFO - Added job "cleanup (trigger: cron[day_of_week='*', hour='3', minute='0', second='0'], next run at: 2020-06-15 03:00:00)" to job store "default"
2020-06-14 23:10:16,899 - _real_add_job - 262 - INFO - Added job "OpenLog (trigger: cron[hour='0'], next run at: 2020-06-15 00:00:00)" to job store "default"
2020-06-14 23:10:16,900 - _main_loop - 574 - INFO - Scheduler started
2020-06-14 23:10:16,900 - _main_loop - 579 - DEBUG - Looking for jobs to run
2020-06-14 23:10:16,900 - _main_loop - 588 - DEBUG - Next wakeup is due at 2020-06-14 23:10:26.898486 (in 9.998006 seconds)
2020-06-14 23:10:16,911 - <module> - 63 - DEBUG - SendBefore_NotRecive : [<CNCProcessStatus: CNCProcessStatus object (2038721)>]
2020-06-14 23:10:16,911 - <module> - 64 - DEBUG - Waitfor_Recive : [2038721]
2020-06-14 23:10:26,899 - _main_loop - 579 - DEBUG - Looking for jobs to run
2020-06-14 23:10:26,899 - _run_jobs - 69 - DEBUG - Started worker thread
2020-06-14 23:10:26,900 - _main_loop - 588 - DEBUG - Next wakeup is due at 2020-06-15 00:00:00 (in 2973.100247 seconds)
2020-06-14 23:10:26,900 - _run_job - 509 - INFO - Running job "regulartime_task (trigger: interval[1 day, 0:00:00], next run at: 2020-06-15 23:10:26.898486)" (scheduled at 2020-06-14 23:10:26.898486)
2020-06-14 23:10:27,274 - _run_job - 520 - ERROR - Job "regulartime_task (trigger: interval[1 day, 0:00:00], next run at: 2020-06-15 23:10:26.898486)" raised an exception
Traceback (most recent call last):
  File "D:\Program Files\Python37\lib\site-packages\django\db\backends\utils.py", line 84, in _execute
    return self.cursor.execute(sql, params)
  File "D:\Program Files\Python37\lib\site-packages\django\db\backends\mysql\base.py", line 71, in execute
    return self.cursor.execute(query, args)
  File "D:\Program Files\Python37\lib\site-packages\MySQLdb\cursors.py", line 209, in execute
    res = self._query(query)
  File "D:\Program Files\Python37\lib\site-packages\MySQLdb\cursors.py", line 315, in _query
    db.query(q)
  File "D:\Program Files\Python37\lib\site-packages\MySQLdb\connections.py", line 239, in query
    _mysql.connection.query(self, query)
MySQLdb._exceptions.IntegrityError: (1062, "Duplicate entry '1592150400' for key 'LAMProcessData_process_r_acquisition_timestamp_a69ae90c_uniq'")

The above exception was the direct cause of the following exception:

Traceback (most recent call last):
  File "D:\Program Files\Python37\lib\site-packages\apscheduler\scheduler.py", line 512, in _run_job
    retval = job.func(*job.args, **job.kwargs)
  File "E:\1-program\11-LAMDataServer\lamdataserver\LAMProcessData\views.py", line 5705, in regulartime_task
    RT_FineData.Realtime_FineData.init_Tomorrow_rows()
  File "E:\1-program\11-LAMDataServer\lamdataserver\LAMProcessData\process_realtime_finedata.py", line 193, in init_Tomorrow_rows
    _model.objects.bulk_create(insert_data_list)
  File "D:\Program Files\Python37\lib\site-packages\django\db\models\manager.py", line 82, in manager_method
    return getattr(self.get_queryset(), name)(*args, **kwargs)
  File "D:\Program Files\Python37\lib\site-packages\django\db\models\query.py", line 474, in bulk_create
    ids = self._batched_insert(objs_without_pk, fields, batch_size, ignore_conflicts=ignore_conflicts)
  File "D:\Program Files\Python37\lib\site-packages\django\db\models\query.py", line 1211, in _batched_insert
    self._insert(item, fields=fields, using=self.db, ignore_conflicts=ignore_conflicts)
  File "D:\Program Files\Python37\lib\site-packages\django\db\models\query.py", line 1186, in _insert
    return query.get_compiler(using=using).execute_sql(return_id)
  File "D:\Program Files\Python37\lib\site-packages\django\db\models\sql\compiler.py", line 1332, in execute_sql
    cursor.execute(sql, params)
  File "D:\Program Files\Python37\lib\site-packages\django\db\backends\utils.py", line 99, in execute
    return super().execute(sql, params)
  File "D:\Program Files\Python37\lib\site-packages\django\db\backends\utils.py", line 67, in execute
    return self._execute_with_wrappers(sql, params, many=False, executor=self._execute)
  File "D:\Program Files\Python37\lib\site-packages\django\db\backends\utils.py", line 76, in _execute_with_wrappers
    return executor(sql, params, many, context)
  File "D:\Program Files\Python37\lib\site-packages\django\db\backends\utils.py", line 84, in _execute
    return self.cursor.execute(sql, params)
  File "D:\Program Files\Python37\lib\site-packages\django\db\utils.py", line 89, in __exit__
    raise dj_exc_value.with_traceback(traceback) from exc_value
  File "D:\Program Files\Python37\lib\site-packages\django\db\backends\utils.py", line 84, in _execute
    return self.cursor.execute(sql, params)
  File "D:\Program Files\Python37\lib\site-packages\django\db\backends\mysql\base.py", line 71, in execute
    return self.cursor.execute(query, args)
  File "D:\Program Files\Python37\lib\site-packages\MySQLdb\cursors.py", line 209, in execute
    res = self._query(query)
  File "D:\Program Files\Python37\lib\site-packages\MySQLdb\cursors.py", line 315, in _query
    db.query(q)
  File "D:\Program Files\Python37\lib\site-packages\MySQLdb\connections.py", line 239, in query
    _mysql.connection.query(self, query)
django.db.utils.IntegrityError: (1062, "Duplicate entry '1592150400' for key 'LAMProcessData_process_r_acquisition_timestamp_a69ae90c_uniq'")
2020-06-14 23:10:28,281 - _run_jobs - 94 - DEBUG - Exiting worker thread
2020-06-14 23:10:51,753 - trigger_reload - 203 - INFO - E:\1-program\11-LAMDataServer\lamdataserver\LAMProcessData\forms.py changed, reloading.
2020-06-14 23:10:51,753 - shutdown - 111 - INFO - Shutting down thread pool
2020-06-14 23:10:53,957 - _real_add_job - 262 - INFO - Added job "regulartime_task (trigger: interval[1 day, 0:00:00], next run at: 2020-06-14 23:11:03.956301)" to job store "default"
2020-06-14 23:10:53,957 - _real_add_job - 262 - INFO - Added job "cleanup (trigger: cron[day_of_week='*', hour='3', minute='0', second='0'], next run at: 2020-06-15 03:00:00)" to job store "default"
2020-06-14 23:10:53,957 - _real_add_job - 262 - INFO - Added job "OpenLog (trigger: cron[hour='0'], next run at: 2020-06-15 00:00:00)" to job store "default"
2020-06-14 23:10:53,958 - _main_loop - 574 - INFO - Scheduler started
2020-06-14 23:10:53,958 - _main_loop - 579 - DEBUG - Looking for jobs to run
2020-06-14 23:10:53,958 - _main_loop - 588 - DEBUG - Next wakeup is due at 2020-06-14 23:11:03.956301 (in 9.998044 seconds)
2020-06-14 23:10:53,969 - <module> - 63 - DEBUG - SendBefore_NotRecive : [<CNCProcessStatus: CNCProcessStatus object (2038721)>]
2020-06-14 23:10:53,969 - <module> - 64 - DEBUG - Waitfor_Recive : [2038721]
2020-06-14 23:11:03,958 - _main_loop - 579 - DEBUG - Looking for jobs to run
2020-06-14 23:11:03,958 - _run_jobs - 69 - DEBUG - Started worker thread
2020-06-14 23:11:03,958 - _main_loop - 588 - DEBUG - Next wakeup is due at 2020-06-15 00:00:00 (in 2936.041864 seconds)
2020-06-14 23:11:03,958 - _run_job - 509 - INFO - Running job "regulartime_task (trigger: interval[1 day, 0:00:00], next run at: 2020-06-15 23:11:03.956301)" (scheduled at 2020-06-14 23:11:03.956301)
2020-06-14 23:11:04,296 - _run_job - 520 - ERROR - Job "regulartime_task (trigger: interval[1 day, 0:00:00], next run at: 2020-06-15 23:11:03.956301)" raised an exception
Traceback (most recent call last):
  File "D:\Program Files\Python37\lib\site-packages\django\db\backends\utils.py", line 84, in _execute
    return self.cursor.execute(sql, params)
  File "D:\Program Files\Python37\lib\site-packages\django\db\backends\mysql\base.py", line 71, in execute
    return self.cursor.execute(query, args)
  File "D:\Program Files\Python37\lib\site-packages\MySQLdb\cursors.py", line 209, in execute
    res = self._query(query)
  File "D:\Program Files\Python37\lib\site-packages\MySQLdb\cursors.py", line 315, in _query
    db.query(q)
  File "D:\Program Files\Python37\lib\site-packages\MySQLdb\connections.py", line 239, in query
    _mysql.connection.query(self, query)
MySQLdb._exceptions.IntegrityError: (1062, "Duplicate entry '1592150400' for key 'LAMProcessData_process_r_acquisition_timestamp_a69ae90c_uniq'")

The above exception was the direct cause of the following exception:

Traceback (most recent call last):
  File "D:\Program Files\Python37\lib\site-packages\apscheduler\scheduler.py", line 512, in _run_job
    retval = job.func(*job.args, **job.kwargs)
  File "E:\1-program\11-LAMDataServer\lamdataserver\LAMProcessData\views.py", line 5705, in regulartime_task
    RT_FineData.Realtime_FineData.init_Tomorrow_rows()
  File "E:\1-program\11-LAMDataServer\lamdataserver\LAMProcessData\process_realtime_finedata.py", line 193, in init_Tomorrow_rows
    _model.objects.bulk_create(insert_data_list)
  File "D:\Program Files\Python37\lib\site-packages\django\db\models\manager.py", line 82, in manager_method
    return getattr(self.get_queryset(), name)(*args, **kwargs)
  File "D:\Program Files\Python37\lib\site-packages\django\db\models\query.py", line 474, in bulk_create
    ids = self._batched_insert(objs_without_pk, fields, batch_size, ignore_conflicts=ignore_conflicts)
  File "D:\Program Files\Python37\lib\site-packages\django\db\models\query.py", line 1211, in _batched_insert
    self._insert(item, fields=fields, using=self.db, ignore_conflicts=ignore_conflicts)
  File "D:\Program Files\Python37\lib\site-packages\django\db\models\query.py", line 1186, in _insert
    return query.get_compiler(using=using).execute_sql(return_id)
  File "D:\Program Files\Python37\lib\site-packages\django\db\models\sql\compiler.py", line 1332, in execute_sql
    cursor.execute(sql, params)
  File "D:\Program Files\Python37\lib\site-packages\django\db\backends\utils.py", line 99, in execute
    return super().execute(sql, params)
  File "D:\Program Files\Python37\lib\site-packages\django\db\backends\utils.py", line 67, in execute
    return self._execute_with_wrappers(sql, params, many=False, executor=self._execute)
  File "D:\Program Files\Python37\lib\site-packages\django\db\backends\utils.py", line 76, in _execute_with_wrappers
    return executor(sql, params, many, context)
  File "D:\Program Files\Python37\lib\site-packages\django\db\backends\utils.py", line 84, in _execute
    return self.cursor.execute(sql, params)
  File "D:\Program Files\Python37\lib\site-packages\django\db\utils.py", line 89, in __exit__
    raise dj_exc_value.with_traceback(traceback) from exc_value
  File "D:\Program Files\Python37\lib\site-packages\django\db\backends\utils.py", line 84, in _execute
    return self.cursor.execute(sql, params)
  File "D:\Program Files\Python37\lib\site-packages\django\db\backends\mysql\base.py", line 71, in execute
    return self.cursor.execute(query, args)
  File "D:\Program Files\Python37\lib\site-packages\MySQLdb\cursors.py", line 209, in execute
    res = self._query(query)
  File "D:\Program Files\Python37\lib\site-packages\MySQLdb\cursors.py", line 315, in _query
    db.query(q)
  File "D:\Program Files\Python37\lib\site-packages\MySQLdb\connections.py", line 239, in query
    _mysql.connection.query(self, query)
django.db.utils.IntegrityError: (1062, "Duplicate entry '1592150400' for key 'LAMProcessData_process_r_acquisition_timestamp_a69ae90c_uniq'")
2020-06-14 23:11:05,306 - _run_jobs - 94 - DEBUG - Exiting worker thread
2020-06-14 23:12:37,936 - trigger_reload - 203 - INFO - E:\1-program\11-LAMDataServer\lamdataserver\LAMProcessData\views.py changed, reloading.
2020-06-14 23:12:37,936 - shutdown - 111 - INFO - Shutting down thread pool
2020-06-14 23:12:42,862 - _real_add_job - 262 - INFO - Added job "regulartime_task (trigger: interval[1 day, 0:00:00], next run at: 2020-06-14 23:12:52.861831)" to job store "default"
2020-06-14 23:12:42,862 - _real_add_job - 262 - INFO - Added job "cleanup (trigger: cron[day_of_week='*', hour='3', minute='0', second='0'], next run at: 2020-06-15 03:00:00)" to job store "default"
2020-06-14 23:12:42,863 - _real_add_job - 262 - INFO - Added job "OpenLog (trigger: cron[hour='0'], next run at: 2020-06-15 00:00:00)" to job store "default"
2020-06-14 23:12:42,863 - _main_loop - 574 - INFO - Scheduler started
2020-06-14 23:12:42,863 - _main_loop - 579 - DEBUG - Looking for jobs to run
2020-06-14 23:12:42,864 - _main_loop - 588 - DEBUG - Next wakeup is due at 2020-06-14 23:12:52.861831 (in 9.997008 seconds)
2020-06-14 23:12:42,877 - <module> - 63 - DEBUG - SendBefore_NotRecive : [<CNCProcessStatus: CNCProcessStatus object (2038721)>]
2020-06-14 23:12:42,877 - <module> - 64 - DEBUG - Waitfor_Recive : [2038721]
2020-06-14 23:12:52,863 - _main_loop - 579 - DEBUG - Looking for jobs to run
2020-06-14 23:12:52,863 - _run_jobs - 69 - DEBUG - Started worker thread
2020-06-14 23:12:52,863 - _main_loop - 588 - DEBUG - Next wakeup is due at 2020-06-15 00:00:00 (in 2827.136904 seconds)
2020-06-14 23:12:52,863 - _run_job - 509 - INFO - Running job "regulartime_task (trigger: interval[1 day, 0:00:00], next run at: 2020-06-15 23:12:52.861831)" (scheduled at 2020-06-14 23:12:52.861831)
2020-06-14 23:12:53,240 - _run_job - 520 - ERROR - Job "regulartime_task (trigger: interval[1 day, 0:00:00], next run at: 2020-06-15 23:12:52.861831)" raised an exception
Traceback (most recent call last):
  File "D:\Program Files\Python37\lib\site-packages\django\db\backends\utils.py", line 84, in _execute
    return self.cursor.execute(sql, params)
  File "D:\Program Files\Python37\lib\site-packages\django\db\backends\mysql\base.py", line 71, in execute
    return self.cursor.execute(query, args)
  File "D:\Program Files\Python37\lib\site-packages\MySQLdb\cursors.py", line 209, in execute
    res = self._query(query)
  File "D:\Program Files\Python37\lib\site-packages\MySQLdb\cursors.py", line 315, in _query
    db.query(q)
  File "D:\Program Files\Python37\lib\site-packages\MySQLdb\connections.py", line 239, in query
    _mysql.connection.query(self, query)
MySQLdb._exceptions.IntegrityError: (1062, "Duplicate entry '1592150400' for key 'LAMProcessData_process_r_acquisition_timestamp_a69ae90c_uniq'")

The above exception was the direct cause of the following exception:

Traceback (most recent call last):
  File "D:\Program Files\Python37\lib\site-packages\apscheduler\scheduler.py", line 512, in _run_job
    retval = job.func(*job.args, **job.kwargs)
  File "E:\1-program\11-LAMDataServer\lamdataserver\LAMProcessData\views.py", line 5704, in regulartime_task
    RT_FineData.Realtime_FineData.init_Tomorrow_rows()
  File "E:\1-program\11-LAMDataServer\lamdataserver\LAMProcessData\process_realtime_finedata.py", line 193, in init_Tomorrow_rows
    _model.objects.bulk_create(insert_data_list)
  File "D:\Program Files\Python37\lib\site-packages\django\db\models\manager.py", line 82, in manager_method
    return getattr(self.get_queryset(), name)(*args, **kwargs)
  File "D:\Program Files\Python37\lib\site-packages\django\db\models\query.py", line 474, in bulk_create
    ids = self._batched_insert(objs_without_pk, fields, batch_size, ignore_conflicts=ignore_conflicts)
  File "D:\Program Files\Python37\lib\site-packages\django\db\models\query.py", line 1211, in _batched_insert
    self._insert(item, fields=fields, using=self.db, ignore_conflicts=ignore_conflicts)
  File "D:\Program Files\Python37\lib\site-packages\django\db\models\query.py", line 1186, in _insert
    return query.get_compiler(using=using).execute_sql(return_id)
  File "D:\Program Files\Python37\lib\site-packages\django\db\models\sql\compiler.py", line 1332, in execute_sql
    cursor.execute(sql, params)
  File "D:\Program Files\Python37\lib\site-packages\django\db\backends\utils.py", line 99, in execute
    return super().execute(sql, params)
  File "D:\Program Files\Python37\lib\site-packages\django\db\backends\utils.py", line 67, in execute
    return self._execute_with_wrappers(sql, params, many=False, executor=self._execute)
  File "D:\Program Files\Python37\lib\site-packages\django\db\backends\utils.py", line 76, in _execute_with_wrappers
    return executor(sql, params, many, context)
  File "D:\Program Files\Python37\lib\site-packages\django\db\backends\utils.py", line 84, in _execute
    return self.cursor.execute(sql, params)
  File "D:\Program Files\Python37\lib\site-packages\django\db\utils.py", line 89, in __exit__
    raise dj_exc_value.with_traceback(traceback) from exc_value
  File "D:\Program Files\Python37\lib\site-packages\django\db\backends\utils.py", line 84, in _execute
    return self.cursor.execute(sql, params)
  File "D:\Program Files\Python37\lib\site-packages\django\db\backends\mysql\base.py", line 71, in execute
    return self.cursor.execute(query, args)
  File "D:\Program Files\Python37\lib\site-packages\MySQLdb\cursors.py", line 209, in execute
    res = self._query(query)
  File "D:\Program Files\Python37\lib\site-packages\MySQLdb\cursors.py", line 315, in _query
    db.query(q)
  File "D:\Program Files\Python37\lib\site-packages\MySQLdb\connections.py", line 239, in query
    _mysql.connection.query(self, query)
django.db.utils.IntegrityError: (1062, "Duplicate entry '1592150400' for key 'LAMProcessData_process_r_acquisition_timestamp_a69ae90c_uniq'")
2020-06-14 23:12:54,249 - _run_jobs - 94 - DEBUG - Exiting worker thread
2020-06-14 23:16:49,744 - _real_add_job - 262 - INFO - Added job "regulartime_task (trigger: interval[1 day, 0:00:00], next run at: 2020-06-14 23:16:59.743260)" to job store "default"
2020-06-14 23:16:49,744 - _real_add_job - 262 - INFO - Added job "cleanup (trigger: cron[day_of_week='*', hour='3', minute='0', second='0'], next run at: 2020-06-15 03:00:00)" to job store "default"
2020-06-14 23:16:49,744 - _real_add_job - 262 - INFO - Added job "OpenLog (trigger: cron[hour='0'], next run at: 2020-06-15 00:00:00)" to job store "default"
2020-06-14 23:16:49,744 - _main_loop - 574 - INFO - Scheduler started
2020-06-14 23:16:49,745 - _main_loop - 579 - DEBUG - Looking for jobs to run
2020-06-14 23:16:49,745 - _main_loop - 588 - DEBUG - Next wakeup is due at 2020-06-14 23:16:59.743260 (in 9.998010 seconds)
2020-06-14 23:16:49,755 - <module> - 63 - DEBUG - SendBefore_NotRecive : [<CNCProcessStatus: CNCProcessStatus object (2038721)>]
2020-06-14 23:16:49,755 - <module> - 64 - DEBUG - Waitfor_Recive : [2038721]
2020-06-14 23:16:57,338 - log_response - 228 - WARNING - Not Found: /LAMProcessData/PracticalTools/MakeMainProgramFile_8070/addStructure/1/
2020-06-14 23:16:59,744 - _main_loop - 579 - DEBUG - Looking for jobs to run
2020-06-14 23:16:59,744 - _run_jobs - 69 - DEBUG - Started worker thread
2020-06-14 23:16:59,744 - _main_loop - 588 - DEBUG - Next wakeup is due at 2020-06-15 00:00:00 (in 2580.255166 seconds)
2020-06-14 23:16:59,744 - _run_job - 509 - INFO - Running job "regulartime_task (trigger: interval[1 day, 0:00:00], next run at: 2020-06-15 23:16:59.743260)" (scheduled at 2020-06-14 23:16:59.743260)
2020-06-14 23:17:00,070 - _run_job - 520 - ERROR - Job "regulartime_task (trigger: interval[1 day, 0:00:00], next run at: 2020-06-15 23:16:59.743260)" raised an exception
Traceback (most recent call last):
  File "D:\Program Files\Python37\lib\site-packages\django\db\backends\utils.py", line 84, in _execute
    return self.cursor.execute(sql, params)
  File "D:\Program Files\Python37\lib\site-packages\django\db\backends\mysql\base.py", line 71, in execute
    return self.cursor.execute(query, args)
  File "D:\Program Files\Python37\lib\site-packages\MySQLdb\cursors.py", line 209, in execute
    res = self._query(query)
  File "D:\Program Files\Python37\lib\site-packages\MySQLdb\cursors.py", line 315, in _query
    db.query(q)
  File "D:\Program Files\Python37\lib\site-packages\MySQLdb\connections.py", line 239, in query
    _mysql.connection.query(self, query)
MySQLdb._exceptions.IntegrityError: (1062, "Duplicate entry '1592150400' for key 'LAMProcessData_process_r_acquisition_timestamp_a69ae90c_uniq'")

The above exception was the direct cause of the following exception:

Traceback (most recent call last):
  File "D:\Program Files\Python37\lib\site-packages\apscheduler\scheduler.py", line 512, in _run_job
    retval = job.func(*job.args, **job.kwargs)
  File "E:\1-program\11-LAMDataServer\lamdataserver\LAMProcessData\views.py", line 5704, in regulartime_task
    RT_FineData.Realtime_FineData.init_Tomorrow_rows()
  File "E:\1-program\11-LAMDataServer\lamdataserver\LAMProcessData\process_realtime_finedata.py", line 193, in init_Tomorrow_rows
    _model.objects.bulk_create(insert_data_list)
  File "D:\Program Files\Python37\lib\site-packages\django\db\models\manager.py", line 82, in manager_method
    return getattr(self.get_queryset(), name)(*args, **kwargs)
  File "D:\Program Files\Python37\lib\site-packages\django\db\models\query.py", line 474, in bulk_create
    ids = self._batched_insert(objs_without_pk, fields, batch_size, ignore_conflicts=ignore_conflicts)
  File "D:\Program Files\Python37\lib\site-packages\django\db\models\query.py", line 1211, in _batched_insert
    self._insert(item, fields=fields, using=self.db, ignore_conflicts=ignore_conflicts)
  File "D:\Program Files\Python37\lib\site-packages\django\db\models\query.py", line 1186, in _insert
    return query.get_compiler(using=using).execute_sql(return_id)
  File "D:\Program Files\Python37\lib\site-packages\django\db\models\sql\compiler.py", line 1332, in execute_sql
    cursor.execute(sql, params)
  File "D:\Program Files\Python37\lib\site-packages\django\db\backends\utils.py", line 99, in execute
    return super().execute(sql, params)
  File "D:\Program Files\Python37\lib\site-packages\django\db\backends\utils.py", line 67, in execute
    return self._execute_with_wrappers(sql, params, many=False, executor=self._execute)
  File "D:\Program Files\Python37\lib\site-packages\django\db\backends\utils.py", line 76, in _execute_with_wrappers
    return executor(sql, params, many, context)
  File "D:\Program Files\Python37\lib\site-packages\django\db\backends\utils.py", line 84, in _execute
    return self.cursor.execute(sql, params)
  File "D:\Program Files\Python37\lib\site-packages\django\db\utils.py", line 89, in __exit__
    raise dj_exc_value.with_traceback(traceback) from exc_value
  File "D:\Program Files\Python37\lib\site-packages\django\db\backends\utils.py", line 84, in _execute
    return self.cursor.execute(sql, params)
  File "D:\Program Files\Python37\lib\site-packages\django\db\backends\mysql\base.py", line 71, in execute
    return self.cursor.execute(query, args)
  File "D:\Program Files\Python37\lib\site-packages\MySQLdb\cursors.py", line 209, in execute
    res = self._query(query)
  File "D:\Program Files\Python37\lib\site-packages\MySQLdb\cursors.py", line 315, in _query
    db.query(q)
  File "D:\Program Files\Python37\lib\site-packages\MySQLdb\connections.py", line 239, in query
    _mysql.connection.query(self, query)
django.db.utils.IntegrityError: (1062, "Duplicate entry '1592150400' for key 'LAMProcessData_process_r_acquisition_timestamp_a69ae90c_uniq'")
2020-06-14 23:17:01,077 - _run_jobs - 94 - DEBUG - Exiting worker thread
2020-06-14 23:17:02,541 - log_response - 228 - WARNING - Not Found: /LAMProcessData/PracticalTools/MakeMainProgramFile_8070/addStructure/1/
2020-06-14 23:19:45,707 - trigger_reload - 203 - INFO - E:\1-program\11-LAMDataServer\lamdataserver\LAMProcessData\urls.py changed, reloading.
2020-06-14 23:19:45,708 - shutdown - 111 - INFO - Shutting down thread pool
2020-06-14 23:19:50,284 - _real_add_job - 262 - INFO - Added job "regulartime_task (trigger: interval[1 day, 0:00:00], next run at: 2020-06-14 23:20:00.283937)" to job store "default"
2020-06-14 23:19:50,285 - _real_add_job - 262 - INFO - Added job "cleanup (trigger: cron[day_of_week='*', hour='3', minute='0', second='0'], next run at: 2020-06-15 03:00:00)" to job store "default"
2020-06-14 23:19:50,285 - _real_add_job - 262 - INFO - Added job "OpenLog (trigger: cron[hour='0'], next run at: 2020-06-15 00:00:00)" to job store "default"
2020-06-14 23:19:50,285 - _main_loop - 574 - INFO - Scheduler started
2020-06-14 23:19:50,286 - _main_loop - 579 - DEBUG - Looking for jobs to run
2020-06-14 23:19:50,286 - _main_loop - 588 - DEBUG - Next wakeup is due at 2020-06-14 23:20:00.283937 (in 9.996962 seconds)
2020-06-14 23:19:50,295 - <module> - 63 - DEBUG - SendBefore_NotRecive : [<CNCProcessStatus: CNCProcessStatus object (2038721)>]
2020-06-14 23:19:50,296 - <module> - 64 - DEBUG - Waitfor_Recive : [2038721]
2020-06-14 23:20:00,284 - _main_loop - 579 - DEBUG - Looking for jobs to run
2020-06-14 23:20:00,284 - _run_jobs - 69 - DEBUG - Started worker thread
2020-06-14 23:20:00,285 - _run_job - 509 - INFO - Running job "regulartime_task (trigger: interval[1 day, 0:00:00], next run at: 2020-06-14 23:20:00.283937)" (scheduled at 2020-06-14 23:20:00.283937)
2020-06-14 23:20:00,285 - _main_loop - 588 - DEBUG - Next wakeup is due at 2020-06-15 00:00:00 (in 2399.715010 seconds)
2020-06-14 23:20:00,617 - _run_job - 520 - ERROR - Job "regulartime_task (trigger: interval[1 day, 0:00:00], next run at: 2020-06-15 23:20:00.283937)" raised an exception
Traceback (most recent call last):
  File "D:\Program Files\Python37\lib\site-packages\django\db\backends\utils.py", line 84, in _execute
    return self.cursor.execute(sql, params)
  File "D:\Program Files\Python37\lib\site-packages\django\db\backends\mysql\base.py", line 71, in execute
    return self.cursor.execute(query, args)
  File "D:\Program Files\Python37\lib\site-packages\MySQLdb\cursors.py", line 209, in execute
    res = self._query(query)
  File "D:\Program Files\Python37\lib\site-packages\MySQLdb\cursors.py", line 315, in _query
    db.query(q)
  File "D:\Program Files\Python37\lib\site-packages\MySQLdb\connections.py", line 239, in query
    _mysql.connection.query(self, query)
MySQLdb._exceptions.IntegrityError: (1062, "Duplicate entry '1592150400' for key 'LAMProcessData_process_r_acquisition_timestamp_a69ae90c_uniq'")

The above exception was the direct cause of the following exception:

Traceback (most recent call last):
  File "D:\Program Files\Python37\lib\site-packages\apscheduler\scheduler.py", line 512, in _run_job
    retval = job.func(*job.args, **job.kwargs)
  File "E:\1-program\11-LAMDataServer\lamdataserver\LAMProcessData\views.py", line 5704, in regulartime_task
    RT_FineData.Realtime_FineData.init_Tomorrow_rows()
  File "E:\1-program\11-LAMDataServer\lamdataserver\LAMProcessData\process_realtime_finedata.py", line 193, in init_Tomorrow_rows
    _model.objects.bulk_create(insert_data_list)
  File "D:\Program Files\Python37\lib\site-packages\django\db\models\manager.py", line 82, in manager_method
    return getattr(self.get_queryset(), name)(*args, **kwargs)
  File "D:\Program Files\Python37\lib\site-packages\django\db\models\query.py", line 474, in bulk_create
    ids = self._batched_insert(objs_without_pk, fields, batch_size, ignore_conflicts=ignore_conflicts)
  File "D:\Program Files\Python37\lib\site-packages\django\db\models\query.py", line 1211, in _batched_insert
    self._insert(item, fields=fields, using=self.db, ignore_conflicts=ignore_conflicts)
  File "D:\Program Files\Python37\lib\site-packages\django\db\models\query.py", line 1186, in _insert
    return query.get_compiler(using=using).execute_sql(return_id)
  File "D:\Program Files\Python37\lib\site-packages\django\db\models\sql\compiler.py", line 1332, in execute_sql
    cursor.execute(sql, params)
  File "D:\Program Files\Python37\lib\site-packages\django\db\backends\utils.py", line 99, in execute
    return super().execute(sql, params)
  File "D:\Program Files\Python37\lib\site-packages\django\db\backends\utils.py", line 67, in execute
    return self._execute_with_wrappers(sql, params, many=False, executor=self._execute)
  File "D:\Program Files\Python37\lib\site-packages\django\db\backends\utils.py", line 76, in _execute_with_wrappers
    return executor(sql, params, many, context)
  File "D:\Program Files\Python37\lib\site-packages\django\db\backends\utils.py", line 84, in _execute
    return self.cursor.execute(sql, params)
  File "D:\Program Files\Python37\lib\site-packages\django\db\utils.py", line 89, in __exit__
    raise dj_exc_value.with_traceback(traceback) from exc_value
  File "D:\Program Files\Python37\lib\site-packages\django\db\backends\utils.py", line 84, in _execute
    return self.cursor.execute(sql, params)
  File "D:\Program Files\Python37\lib\site-packages\django\db\backends\mysql\base.py", line 71, in execute
    return self.cursor.execute(query, args)
  File "D:\Program Files\Python37\lib\site-packages\MySQLdb\cursors.py", line 209, in execute
    res = self._query(query)
  File "D:\Program Files\Python37\lib\site-packages\MySQLdb\cursors.py", line 315, in _query
    db.query(q)
  File "D:\Program Files\Python37\lib\site-packages\MySQLdb\connections.py", line 239, in query
    _mysql.connection.query(self, query)
django.db.utils.IntegrityError: (1062, "Duplicate entry '1592150400' for key 'LAMProcessData_process_r_acquisition_timestamp_a69ae90c_uniq'")
2020-06-14 23:20:01,622 - _run_jobs - 94 - DEBUG - Exiting worker thread
2020-06-14 23:20:24,440 - trigger_reload - 203 - INFO - E:\1-program\11-LAMDataServer\lamdataserver\LAMProcessData\views.py changed, reloading.
2020-06-14 23:20:24,440 - shutdown - 111 - INFO - Shutting down thread pool
2020-06-14 23:20:31,492 - _real_add_job - 262 - INFO - Added job "regulartime_task (trigger: interval[1 day, 0:00:00], next run at: 2020-06-14 23:20:41.491948)" to job store "default"
2020-06-14 23:20:31,492 - _real_add_job - 262 - INFO - Added job "cleanup (trigger: cron[day_of_week='*', hour='3', minute='0', second='0'], next run at: 2020-06-15 03:00:00)" to job store "default"
2020-06-14 23:20:31,493 - _real_add_job - 262 - INFO - Added job "OpenLog (trigger: cron[hour='0'], next run at: 2020-06-15 00:00:00)" to job store "default"
2020-06-14 23:20:31,493 - _main_loop - 574 - INFO - Scheduler started
2020-06-14 23:20:31,493 - _main_loop - 579 - DEBUG - Looking for jobs to run
2020-06-14 23:20:31,493 - _main_loop - 588 - DEBUG - Next wakeup is due at 2020-06-14 23:20:41.491948 (in 9.998006 seconds)
2020-06-14 23:20:31,504 - <module> - 63 - DEBUG - SendBefore_NotRecive : [<CNCProcessStatus: CNCProcessStatus object (2038721)>]
2020-06-14 23:20:31,504 - <module> - 64 - DEBUG - Waitfor_Recive : [2038721]
2020-06-14 23:20:41,494 - _main_loop - 579 - DEBUG - Looking for jobs to run
2020-06-14 23:20:41,494 - _run_jobs - 69 - DEBUG - Started worker thread
2020-06-14 23:20:41,495 - _main_loop - 588 - DEBUG - Next wakeup is due at 2020-06-15 00:00:00 (in 2358.505578 seconds)
2020-06-14 23:20:41,495 - _run_job - 509 - INFO - Running job "regulartime_task (trigger: interval[1 day, 0:00:00], next run at: 2020-06-15 23:20:41.491948)" (scheduled at 2020-06-14 23:20:41.491948)
2020-06-14 23:20:41,837 - _run_job - 520 - ERROR - Job "regulartime_task (trigger: interval[1 day, 0:00:00], next run at: 2020-06-15 23:20:41.491948)" raised an exception
Traceback (most recent call last):
  File "D:\Program Files\Python37\lib\site-packages\django\db\backends\utils.py", line 84, in _execute
    return self.cursor.execute(sql, params)
  File "D:\Program Files\Python37\lib\site-packages\django\db\backends\mysql\base.py", line 71, in execute
    return self.cursor.execute(query, args)
  File "D:\Program Files\Python37\lib\site-packages\MySQLdb\cursors.py", line 209, in execute
    res = self._query(query)
  File "D:\Program Files\Python37\lib\site-packages\MySQLdb\cursors.py", line 315, in _query
    db.query(q)
  File "D:\Program Files\Python37\lib\site-packages\MySQLdb\connections.py", line 239, in query
    _mysql.connection.query(self, query)
MySQLdb._exceptions.IntegrityError: (1062, "Duplicate entry '1592150400' for key 'LAMProcessData_process_r_acquisition_timestamp_a69ae90c_uniq'")

The above exception was the direct cause of the following exception:

Traceback (most recent call last):
  File "D:\Program Files\Python37\lib\site-packages\apscheduler\scheduler.py", line 512, in _run_job
    retval = job.func(*job.args, **job.kwargs)
  File "E:\1-program\11-LAMDataServer\lamdataserver\LAMProcessData\views.py", line 5704, in regulartime_task
    RT_FineData.Realtime_FineData.init_Tomorrow_rows()
  File "E:\1-program\11-LAMDataServer\lamdataserver\LAMProcessData\process_realtime_finedata.py", line 193, in init_Tomorrow_rows
    _model.objects.bulk_create(insert_data_list)
  File "D:\Program Files\Python37\lib\site-packages\django\db\models\manager.py", line 82, in manager_method
    return getattr(self.get_queryset(), name)(*args, **kwargs)
  File "D:\Program Files\Python37\lib\site-packages\django\db\models\query.py", line 474, in bulk_create
    ids = self._batched_insert(objs_without_pk, fields, batch_size, ignore_conflicts=ignore_conflicts)
  File "D:\Program Files\Python37\lib\site-packages\django\db\models\query.py", line 1211, in _batched_insert
    self._insert(item, fields=fields, using=self.db, ignore_conflicts=ignore_conflicts)
  File "D:\Program Files\Python37\lib\site-packages\django\db\models\query.py", line 1186, in _insert
    return query.get_compiler(using=using).execute_sql(return_id)
  File "D:\Program Files\Python37\lib\site-packages\django\db\models\sql\compiler.py", line 1332, in execute_sql
    cursor.execute(sql, params)
  File "D:\Program Files\Python37\lib\site-packages\django\db\backends\utils.py", line 99, in execute
    return super().execute(sql, params)
  File "D:\Program Files\Python37\lib\site-packages\django\db\backends\utils.py", line 67, in execute
    return self._execute_with_wrappers(sql, params, many=False, executor=self._execute)
  File "D:\Program Files\Python37\lib\site-packages\django\db\backends\utils.py", line 76, in _execute_with_wrappers
    return executor(sql, params, many, context)
  File "D:\Program Files\Python37\lib\site-packages\django\db\backends\utils.py", line 84, in _execute
    return self.cursor.execute(sql, params)
  File "D:\Program Files\Python37\lib\site-packages\django\db\utils.py", line 89, in __exit__
    raise dj_exc_value.with_traceback(traceback) from exc_value
  File "D:\Program Files\Python37\lib\site-packages\django\db\backends\utils.py", line 84, in _execute
    return self.cursor.execute(sql, params)
  File "D:\Program Files\Python37\lib\site-packages\django\db\backends\mysql\base.py", line 71, in execute
    return self.cursor.execute(query, args)
  File "D:\Program Files\Python37\lib\site-packages\MySQLdb\cursors.py", line 209, in execute
    res = self._query(query)
  File "D:\Program Files\Python37\lib\site-packages\MySQLdb\cursors.py", line 315, in _query
    db.query(q)
  File "D:\Program Files\Python37\lib\site-packages\MySQLdb\connections.py", line 239, in query
    _mysql.connection.query(self, query)
django.db.utils.IntegrityError: (1062, "Duplicate entry '1592150400' for key 'LAMProcessData_process_r_acquisition_timestamp_a69ae90c_uniq'")
2020-06-14 23:20:42,843 - _run_jobs - 94 - DEBUG - Exiting worker thread
2020-06-14 23:21:33,798 - _real_add_job - 262 - INFO - Added job "regulartime_task (trigger: interval[1 day, 0:00:00], next run at: 2020-06-14 23:21:43.797499)" to job store "default"
2020-06-14 23:21:33,798 - _real_add_job - 262 - INFO - Added job "cleanup (trigger: cron[day_of_week='*', hour='3', minute='0', second='0'], next run at: 2020-06-15 03:00:00)" to job store "default"
2020-06-14 23:21:33,799 - _real_add_job - 262 - INFO - Added job "OpenLog (trigger: cron[hour='0'], next run at: 2020-06-15 00:00:00)" to job store "default"
2020-06-14 23:21:33,799 - _main_loop - 574 - INFO - Scheduler started
2020-06-14 23:21:33,799 - _main_loop - 579 - DEBUG - Looking for jobs to run
2020-06-14 23:21:33,799 - _main_loop - 588 - DEBUG - Next wakeup is due at 2020-06-14 23:21:43.797499 (in 9.998004 seconds)
2020-06-14 23:21:33,809 - <module> - 63 - DEBUG - SendBefore_NotRecive : [<CNCProcessStatus: CNCProcessStatus object (2038721)>]
2020-06-14 23:21:33,809 - <module> - 64 - DEBUG - Waitfor_Recive : [2038721]
2020-06-14 23:21:43,799 - _main_loop - 579 - DEBUG - Looking for jobs to run
2020-06-14 23:21:43,799 - _run_jobs - 69 - DEBUG - Started worker thread
2020-06-14 23:21:43,799 - _main_loop - 588 - DEBUG - Next wakeup is due at 2020-06-15 00:00:00 (in 2296.200628 seconds)
2020-06-14 23:21:43,799 - _run_job - 509 - INFO - Running job "regulartime_task (trigger: interval[1 day, 0:00:00], next run at: 2020-06-15 23:21:43.797499)" (scheduled at 2020-06-14 23:21:43.797499)
2020-06-14 23:21:44,132 - _run_job - 520 - ERROR - Job "regulartime_task (trigger: interval[1 day, 0:00:00], next run at: 2020-06-15 23:21:43.797499)" raised an exception
Traceback (most recent call last):
  File "D:\Program Files\Python37\lib\site-packages\django\db\backends\utils.py", line 84, in _execute
    return self.cursor.execute(sql, params)
  File "D:\Program Files\Python37\lib\site-packages\django\db\backends\mysql\base.py", line 71, in execute
    return self.cursor.execute(query, args)
  File "D:\Program Files\Python37\lib\site-packages\MySQLdb\cursors.py", line 209, in execute
    res = self._query(query)
  File "D:\Program Files\Python37\lib\site-packages\MySQLdb\cursors.py", line 315, in _query
    db.query(q)
  File "D:\Program Files\Python37\lib\site-packages\MySQLdb\connections.py", line 239, in query
    _mysql.connection.query(self, query)
MySQLdb._exceptions.IntegrityError: (1062, "Duplicate entry '1592150400' for key 'LAMProcessData_process_r_acquisition_timestamp_a69ae90c_uniq'")

The above exception was the direct cause of the following exception:

Traceback (most recent call last):
  File "D:\Program Files\Python37\lib\site-packages\apscheduler\scheduler.py", line 512, in _run_job
    retval = job.func(*job.args, **job.kwargs)
  File "E:\1-program\11-LAMDataServer\lamdataserver\LAMProcessData\views.py", line 5704, in regulartime_task
    RT_FineData.Realtime_FineData.init_Tomorrow_rows()
  File "E:\1-program\11-LAMDataServer\lamdataserver\LAMProcessData\process_realtime_finedata.py", line 193, in init_Tomorrow_rows
    _model.objects.bulk_create(insert_data_list)
  File "D:\Program Files\Python37\lib\site-packages\django\db\models\manager.py", line 82, in manager_method
    return getattr(self.get_queryset(), name)(*args, **kwargs)
  File "D:\Program Files\Python37\lib\site-packages\django\db\models\query.py", line 474, in bulk_create
    ids = self._batched_insert(objs_without_pk, fields, batch_size, ignore_conflicts=ignore_conflicts)
  File "D:\Program Files\Python37\lib\site-packages\django\db\models\query.py", line 1211, in _batched_insert
    self._insert(item, fields=fields, using=self.db, ignore_conflicts=ignore_conflicts)
  File "D:\Program Files\Python37\lib\site-packages\django\db\models\query.py", line 1186, in _insert
    return query.get_compiler(using=using).execute_sql(return_id)
  File "D:\Program Files\Python37\lib\site-packages\django\db\models\sql\compiler.py", line 1332, in execute_sql
    cursor.execute(sql, params)
  File "D:\Program Files\Python37\lib\site-packages\django\db\backends\utils.py", line 99, in execute
    return super().execute(sql, params)
  File "D:\Program Files\Python37\lib\site-packages\django\db\backends\utils.py", line 67, in execute
    return self._execute_with_wrappers(sql, params, many=False, executor=self._execute)
  File "D:\Program Files\Python37\lib\site-packages\django\db\backends\utils.py", line 76, in _execute_with_wrappers
    return executor(sql, params, many, context)
  File "D:\Program Files\Python37\lib\site-packages\django\db\backends\utils.py", line 84, in _execute
    return self.cursor.execute(sql, params)
  File "D:\Program Files\Python37\lib\site-packages\django\db\utils.py", line 89, in __exit__
    raise dj_exc_value.with_traceback(traceback) from exc_value
  File "D:\Program Files\Python37\lib\site-packages\django\db\backends\utils.py", line 84, in _execute
    return self.cursor.execute(sql, params)
  File "D:\Program Files\Python37\lib\site-packages\django\db\backends\mysql\base.py", line 71, in execute
    return self.cursor.execute(query, args)
  File "D:\Program Files\Python37\lib\site-packages\MySQLdb\cursors.py", line 209, in execute
    res = self._query(query)
  File "D:\Program Files\Python37\lib\site-packages\MySQLdb\cursors.py", line 315, in _query
    db.query(q)
  File "D:\Program Files\Python37\lib\site-packages\MySQLdb\connections.py", line 239, in query
    _mysql.connection.query(self, query)
django.db.utils.IntegrityError: (1062, "Duplicate entry '1592150400' for key 'LAMProcessData_process_r_acquisition_timestamp_a69ae90c_uniq'")
2020-06-14 23:21:45,137 - _run_jobs - 94 - DEBUG - Exiting worker thread
