2020-05-24 Sun 07:38:40 threadpool.py __init__ 52 - INFO - Started thread pool with 0 core threads and 20 maximum threads
2020-05-24 Sun 07:38:40 scheduler.py add_job 287 - INFO - Adding job tentatively -- it will be properly scheduled when the scheduler starts
2020-05-24 Sun 07:38:40 scheduler.py add_job 287 - INFO - Adding job tentatively -- it will be properly scheduled when the scheduler starts
2020-05-24 Sun 07:38:40 scheduler.py add_job 287 - INFO - Adding job tentatively -- it will be properly scheduled when the scheduler starts
2020-05-24 Sun 07:38:40 scheduler.py _real_add_job 262 - INFO - Added job "regulartime_task (trigger: interval[1 day, 0:00:00], next run at: 2020-05-24 07:38:50.576449)" to job store "default"
2020-05-24 Sun 07:38:40 scheduler.py _real_add_job 262 - INFO - Added job "cleanup (trigger: cron[day_of_week='*', hour='3', minute='0', second='0'], next run at: 2020-05-25 03:00:00)" to job store "default"
2020-05-24 Sun 07:38:40 scheduler.py _real_add_job 262 - INFO - Added job "OpenLog (trigger: cron[hour='0'], next run at: 2020-05-25 00:00:00)" to job store "default"
2020-05-24 Sun 07:38:40 scheduler.py _main_loop 574 - INFO - Scheduler started
2020-05-24 Sun 07:38:40 scheduler.py _main_loop 579 - DEBUG - Looking for jobs to run
2020-05-24 Sun 07:38:40 scheduler.py _main_loop 588 - DEBUG - Next wakeup is due at 2020-05-24 07:38:50.576449 (in 9.997024 seconds)
2020-05-24 Sun 07:38:40 query_views.py <module> 63 - DEBUG - SendBefore_NotRecive : [<CNCProcessStatus: CNCProcessStatus object (2038721)>]
2020-05-24 Sun 07:38:40 query_views.py <module> 64 - DEBUG - Waitfor_Recive : [2038721]
2020-05-24 Sun 07:38:45 log.py log_response 228 - WARNING - Not Found: /favicon.ico
2020-05-24 Sun 07:38:46 log.py log_response 228 - WARNING - Not Found: /favicon.ico
2020-05-24 Sun 07:38:46 log.py log_response 228 - WARNING - Not Found: /favicon.ico
2020-05-24 Sun 07:38:47 log.py log_response 228 - WARNING - Not Found: /favicon.ico
2020-05-24 Sun 07:38:50 scheduler.py _main_loop 579 - DEBUG - Looking for jobs to run
2020-05-24 Sun 07:38:50 threadpool.py _run_jobs 69 - DEBUG - Started worker thread
2020-05-24 Sun 07:38:50 scheduler.py _run_job 509 - INFO - Running job "regulartime_task (trigger: interval[1 day, 0:00:00], next run at: 2020-05-24 07:38:50.576449)" (scheduled at 2020-05-24 07:38:50.576449)
2020-05-24 Sun 07:38:50 scheduler.py _main_loop 588 - DEBUG - Next wakeup is due at 2020-05-25 00:00:00 (in 58869.420481 seconds)
2020-05-24 Sun 07:38:52 scheduler.py _run_job 520 - ERROR - Job "regulartime_task (trigger: interval[1 day, 0:00:00], next run at: 2020-05-25 07:38:50.576449)" raised an exception
Traceback (most recent call last):
  File "D:\Program Files\Python37\lib\site-packages\django\db\backends\mysql\base.py", line 71, in execute
    return self.cursor.execute(query, args)
  File "D:\Program Files\Python37\lib\site-packages\MySQLdb\cursors.py", line 209, in execute
    res = self._query(query)
  File "D:\Program Files\Python37\lib\site-packages\MySQLdb\cursors.py", line 315, in _query
    db.query(q)
  File "D:\Program Files\Python37\lib\site-packages\MySQLdb\connections.py", line 239, in query
    _mysql.connection.query(self, query)
MySQLdb._exceptions.OperationalError: (1048, "Column 'laser_power' cannot be null")

During handling of the above exception, another exception occurred:

Traceback (most recent call last):
  File "D:\Program Files\Python37\lib\site-packages\apscheduler\scheduler.py", line 512, in _run_job
    retval = job.func(*job.args, **job.kwargs)
  File "E:\1-program\11-LAMDataServer\lamdataserver\LAMProcessData\views.py", line 5437, in regulartime_task
    RT_FineData.Realtime_FineData.init_Tomorrow_rows()
  File "E:\1-program\11-LAMDataServer\lamdataserver\LAMProcessData\process_realtime_finedata.py", line 193, in init_Tomorrow_rows
    _model.objects.bulk_create(insert_data_list)
  File "D:\Program Files\Python37\lib\site-packages\django\db\models\manager.py", line 82, in manager_method
    return getattr(self.get_queryset(), name)(*args, **kwargs)
  File "D:\Program Files\Python37\lib\site-packages\django\db\models\query.py", line 474, in bulk_create
    ids = self._batched_insert(objs_without_pk, fields, batch_size, ignore_conflicts=ignore_conflicts)
  File "D:\Program Files\Python37\lib\site-packages\django\db\models\query.py", line 1211, in _batched_insert
    self._insert(item, fields=fields, using=self.db, ignore_conflicts=ignore_conflicts)
  File "D:\Program Files\Python37\lib\site-packages\django\db\models\query.py", line 1186, in _insert
    return query.get_compiler(using=using).execute_sql(return_id)
  File "D:\Program Files\Python37\lib\site-packages\django\db\models\sql\compiler.py", line 1332, in execute_sql
    cursor.execute(sql, params)
  File "D:\Program Files\Python37\lib\site-packages\django\db\backends\utils.py", line 99, in execute
    return super().execute(sql, params)
  File "D:\Program Files\Python37\lib\site-packages\django\db\backends\utils.py", line 67, in execute
    return self._execute_with_wrappers(sql, params, many=False, executor=self._execute)
  File "D:\Program Files\Python37\lib\site-packages\django\db\backends\utils.py", line 76, in _execute_with_wrappers
    return executor(sql, params, many, context)
  File "D:\Program Files\Python37\lib\site-packages\django\db\backends\utils.py", line 84, in _execute
    return self.cursor.execute(sql, params)
  File "D:\Program Files\Python37\lib\site-packages\django\db\backends\mysql\base.py", line 76, in execute
    raise utils.IntegrityError(*tuple(e.args))
django.db.utils.IntegrityError: (1048, "Column 'laser_power' cannot be null")
2020-05-24 Sun 07:38:53 threadpool.py _run_jobs 94 - DEBUG - Exiting worker thread
2020-05-24 Sun 07:39:20 log.py log_response 228 - WARNING - Not Found: /favicon.ico
2020-05-24 Sun 19:07:54 threadpool.py __init__ 52 - INFO - Started thread pool with 0 core threads and 20 maximum threads
2020-05-24 Sun 19:07:54 scheduler.py add_job 287 - INFO - Adding job tentatively -- it will be properly scheduled when the scheduler starts
2020-05-24 Sun 19:07:54 scheduler.py add_job 287 - INFO - Adding job tentatively -- it will be properly scheduled when the scheduler starts
2020-05-24 Sun 19:07:54 scheduler.py add_job 287 - INFO - Adding job tentatively -- it will be properly scheduled when the scheduler starts
2020-05-24 Sun 19:07:54 scheduler.py _real_add_job 262 - INFO - Added job "regulartime_task (trigger: interval[1 day, 0:00:00], next run at: 2020-05-24 19:08:04.097013)" to job store "default"
2020-05-24 Sun 19:07:54 scheduler.py _real_add_job 262 - INFO - Added job "cleanup (trigger: cron[day_of_week='*', hour='3', minute='0', second='0'], next run at: 2020-05-25 03:00:00)" to job store "default"
2020-05-24 Sun 19:07:54 scheduler.py _real_add_job 262 - INFO - Added job "OpenLog (trigger: cron[hour='0'], next run at: 2020-05-25 00:00:00)" to job store "default"
2020-05-24 Sun 19:07:54 scheduler.py _main_loop 574 - INFO - Scheduler started
2020-05-24 Sun 19:07:54 scheduler.py _main_loop 579 - DEBUG - Looking for jobs to run
2020-05-24 Sun 19:07:54 scheduler.py _main_loop 588 - DEBUG - Next wakeup is due at 2020-05-24 19:08:04.097013 (in 9.997553 seconds)
2020-05-24 Sun 19:07:54 query_views.py <module> 63 - DEBUG - SendBefore_NotRecive : [<CNCProcessStatus: CNCProcessStatus object (2038721)>]
2020-05-24 Sun 19:07:54 query_views.py <module> 64 - DEBUG - Waitfor_Recive : [2038721]
2020-05-24 Sun 19:08:04 scheduler.py _main_loop 579 - DEBUG - Looking for jobs to run
2020-05-24 Sun 19:08:04 threadpool.py _run_jobs 69 - DEBUG - Started worker thread
2020-05-24 Sun 19:08:04 scheduler.py _run_job 509 - INFO - Running job "regulartime_task (trigger: interval[1 day, 0:00:00], next run at: 2020-05-24 19:08:04.097013)" (scheduled at 2020-05-24 19:08:04.097013)
2020-05-24 Sun 19:08:04 scheduler.py _main_loop 588 - DEBUG - Next wakeup is due at 2020-05-25 00:00:00 (in 17515.901220 seconds)
2020-05-24 Sun 19:08:04 scheduler.py _run_job 520 - ERROR - Job "regulartime_task (trigger: interval[1 day, 0:00:00], next run at: 2020-05-25 19:08:04.097013)" raised an exception
Traceback (most recent call last):
  File "D:\Program Files\Python37\lib\site-packages\django\db\backends\utils.py", line 84, in _execute
    return self.cursor.execute(sql, params)
  File "D:\Program Files\Python37\lib\site-packages\django\db\backends\mysql\base.py", line 71, in execute
    return self.cursor.execute(query, args)
  File "D:\Program Files\Python37\lib\site-packages\MySQLdb\cursors.py", line 209, in execute
    res = self._query(query)
  File "D:\Program Files\Python37\lib\site-packages\MySQLdb\cursors.py", line 315, in _query
    db.query(q)
  File "D:\Program Files\Python37\lib\site-packages\MySQLdb\connections.py", line 239, in query
    _mysql.connection.query(self, query)
MySQLdb._exceptions.IntegrityError: (1062, "Duplicate entry '1590336000' for key 'LAMProcessData_process_r_acquisition_timestamp_a69ae90c_uniq'")

The above exception was the direct cause of the following exception:

Traceback (most recent call last):
  File "D:\Program Files\Python37\lib\site-packages\apscheduler\scheduler.py", line 512, in _run_job
    retval = job.func(*job.args, **job.kwargs)
  File "E:\1-program\11-LAMDataServer\lamdataserver\LAMProcessData\views.py", line 5437, in regulartime_task
    RT_FineData.Realtime_FineData.init_Tomorrow_rows()
  File "E:\1-program\11-LAMDataServer\lamdataserver\LAMProcessData\process_realtime_finedata.py", line 193, in init_Tomorrow_rows
    _model.objects.bulk_create(insert_data_list)
  File "D:\Program Files\Python37\lib\site-packages\django\db\models\manager.py", line 82, in manager_method
    return getattr(self.get_queryset(), name)(*args, **kwargs)
  File "D:\Program Files\Python37\lib\site-packages\django\db\models\query.py", line 474, in bulk_create
    ids = self._batched_insert(objs_without_pk, fields, batch_size, ignore_conflicts=ignore_conflicts)
  File "D:\Program Files\Python37\lib\site-packages\django\db\models\query.py", line 1211, in _batched_insert
    self._insert(item, fields=fields, using=self.db, ignore_conflicts=ignore_conflicts)
  File "D:\Program Files\Python37\lib\site-packages\django\db\models\query.py", line 1186, in _insert
    return query.get_compiler(using=using).execute_sql(return_id)
  File "D:\Program Files\Python37\lib\site-packages\django\db\models\sql\compiler.py", line 1332, in execute_sql
    cursor.execute(sql, params)
  File "D:\Program Files\Python37\lib\site-packages\django\db\backends\utils.py", line 99, in execute
    return super().execute(sql, params)
  File "D:\Program Files\Python37\lib\site-packages\django\db\backends\utils.py", line 67, in execute
    return self._execute_with_wrappers(sql, params, many=False, executor=self._execute)
  File "D:\Program Files\Python37\lib\site-packages\django\db\backends\utils.py", line 76, in _execute_with_wrappers
    return executor(sql, params, many, context)
  File "D:\Program Files\Python37\lib\site-packages\django\db\backends\utils.py", line 84, in _execute
    return self.cursor.execute(sql, params)
  File "D:\Program Files\Python37\lib\site-packages\django\db\utils.py", line 89, in __exit__
    raise dj_exc_value.with_traceback(traceback) from exc_value
  File "D:\Program Files\Python37\lib\site-packages\django\db\backends\utils.py", line 84, in _execute
    return self.cursor.execute(sql, params)
  File "D:\Program Files\Python37\lib\site-packages\django\db\backends\mysql\base.py", line 71, in execute
    return self.cursor.execute(query, args)
  File "D:\Program Files\Python37\lib\site-packages\MySQLdb\cursors.py", line 209, in execute
    res = self._query(query)
  File "D:\Program Files\Python37\lib\site-packages\MySQLdb\cursors.py", line 315, in _query
    db.query(q)
  File "D:\Program Files\Python37\lib\site-packages\MySQLdb\connections.py", line 239, in query
    _mysql.connection.query(self, query)
django.db.utils.IntegrityError: (1062, "Duplicate entry '1590336000' for key 'LAMProcessData_process_r_acquisition_timestamp_a69ae90c_uniq'")
2020-05-24 Sun 19:08:05 threadpool.py _run_jobs 94 - DEBUG - Exiting worker thread
2020-05-24 Sun 19:08:24 autoreload.py trigger_reload 203 - INFO - E:\1-program\11-LAMDataServer\lamdataserver\LAMProcessData\forms.py changed, reloading.
2020-05-24 Sun 19:08:24 threadpool.py shutdown 111 - INFO - Shutting down thread pool
2020-05-24 Sun 19:08:26 threadpool.py __init__ 52 - INFO - Started thread pool with 0 core threads and 20 maximum threads
2020-05-24 Sun 19:08:26 scheduler.py add_job 287 - INFO - Adding job tentatively -- it will be properly scheduled when the scheduler starts
2020-05-24 Sun 19:08:26 scheduler.py add_job 287 - INFO - Adding job tentatively -- it will be properly scheduled when the scheduler starts
2020-05-24 Sun 19:08:26 scheduler.py add_job 287 - INFO - Adding job tentatively -- it will be properly scheduled when the scheduler starts
2020-05-24 Sun 19:08:26 scheduler.py _real_add_job 262 - INFO - Added job "regulartime_task (trigger: interval[1 day, 0:00:00], next run at: 2020-05-24 19:08:36.773219)" to job store "default"
2020-05-24 Sun 19:08:26 scheduler.py _real_add_job 262 - INFO - Added job "cleanup (trigger: cron[day_of_week='*', hour='3', minute='0', second='0'], next run at: 2020-05-25 03:00:00)" to job store "default"
2020-05-24 Sun 19:08:26 scheduler.py _real_add_job 262 - INFO - Added job "OpenLog (trigger: cron[hour='0'], next run at: 2020-05-25 00:00:00)" to job store "default"
2020-05-24 Sun 19:08:26 scheduler.py _main_loop 574 - INFO - Scheduler started
2020-05-24 Sun 19:08:26 scheduler.py _main_loop 579 - DEBUG - Looking for jobs to run
2020-05-24 Sun 19:08:26 scheduler.py _main_loop 588 - DEBUG - Next wakeup is due at 2020-05-24 19:08:36.773219 (in 9.997560 seconds)
2020-05-24 Sun 19:08:26 query_views.py <module> 63 - DEBUG - SendBefore_NotRecive : [<CNCProcessStatus: CNCProcessStatus object (2038721)>]
2020-05-24 Sun 19:08:26 query_views.py <module> 64 - DEBUG - Waitfor_Recive : [2038721]
2020-05-24 Sun 19:08:36 scheduler.py _main_loop 579 - DEBUG - Looking for jobs to run
2020-05-24 Sun 19:08:36 threadpool.py _run_jobs 69 - DEBUG - Started worker thread
2020-05-24 Sun 19:08:36 scheduler.py _run_job 509 - INFO - Running job "regulartime_task (trigger: interval[1 day, 0:00:00], next run at: 2020-05-24 19:08:36.773219)" (scheduled at 2020-05-24 19:08:36.773219)
2020-05-24 Sun 19:08:36 scheduler.py _main_loop 588 - DEBUG - Next wakeup is due at 2020-05-25 00:00:00 (in 17483.225555 seconds)
2020-05-24 Sun 19:08:37 scheduler.py _run_job 520 - ERROR - Job "regulartime_task (trigger: interval[1 day, 0:00:00], next run at: 2020-05-25 19:08:36.773219)" raised an exception
Traceback (most recent call last):
  File "D:\Program Files\Python37\lib\site-packages\django\db\backends\utils.py", line 84, in _execute
    return self.cursor.execute(sql, params)
  File "D:\Program Files\Python37\lib\site-packages\django\db\backends\mysql\base.py", line 71, in execute
    return self.cursor.execute(query, args)
  File "D:\Program Files\Python37\lib\site-packages\MySQLdb\cursors.py", line 209, in execute
    res = self._query(query)
  File "D:\Program Files\Python37\lib\site-packages\MySQLdb\cursors.py", line 315, in _query
    db.query(q)
  File "D:\Program Files\Python37\lib\site-packages\MySQLdb\connections.py", line 239, in query
    _mysql.connection.query(self, query)
MySQLdb._exceptions.IntegrityError: (1062, "Duplicate entry '1590336000' for key 'LAMProcessData_process_r_acquisition_timestamp_a69ae90c_uniq'")

The above exception was the direct cause of the following exception:

Traceback (most recent call last):
  File "D:\Program Files\Python37\lib\site-packages\apscheduler\scheduler.py", line 512, in _run_job
    retval = job.func(*job.args, **job.kwargs)
  File "E:\1-program\11-LAMDataServer\lamdataserver\LAMProcessData\views.py", line 5437, in regulartime_task
    RT_FineData.Realtime_FineData.init_Tomorrow_rows()
  File "E:\1-program\11-LAMDataServer\lamdataserver\LAMProcessData\process_realtime_finedata.py", line 193, in init_Tomorrow_rows
    _model.objects.bulk_create(insert_data_list)
  File "D:\Program Files\Python37\lib\site-packages\django\db\models\manager.py", line 82, in manager_method
    return getattr(self.get_queryset(), name)(*args, **kwargs)
  File "D:\Program Files\Python37\lib\site-packages\django\db\models\query.py", line 474, in bulk_create
    ids = self._batched_insert(objs_without_pk, fields, batch_size, ignore_conflicts=ignore_conflicts)
  File "D:\Program Files\Python37\lib\site-packages\django\db\models\query.py", line 1211, in _batched_insert
    self._insert(item, fields=fields, using=self.db, ignore_conflicts=ignore_conflicts)
  File "D:\Program Files\Python37\lib\site-packages\django\db\models\query.py", line 1186, in _insert
    return query.get_compiler(using=using).execute_sql(return_id)
  File "D:\Program Files\Python37\lib\site-packages\django\db\models\sql\compiler.py", line 1332, in execute_sql
    cursor.execute(sql, params)
  File "D:\Program Files\Python37\lib\site-packages\django\db\backends\utils.py", line 99, in execute
    return super().execute(sql, params)
  File "D:\Program Files\Python37\lib\site-packages\django\db\backends\utils.py", line 67, in execute
    return self._execute_with_wrappers(sql, params, many=False, executor=self._execute)
  File "D:\Program Files\Python37\lib\site-packages\django\db\backends\utils.py", line 76, in _execute_with_wrappers
    return executor(sql, params, many, context)
  File "D:\Program Files\Python37\lib\site-packages\django\db\backends\utils.py", line 84, in _execute
    return self.cursor.execute(sql, params)
  File "D:\Program Files\Python37\lib\site-packages\django\db\utils.py", line 89, in __exit__
    raise dj_exc_value.with_traceback(traceback) from exc_value
  File "D:\Program Files\Python37\lib\site-packages\django\db\backends\utils.py", line 84, in _execute
    return self.cursor.execute(sql, params)
  File "D:\Program Files\Python37\lib\site-packages\django\db\backends\mysql\base.py", line 71, in execute
    return self.cursor.execute(query, args)
  File "D:\Program Files\Python37\lib\site-packages\MySQLdb\cursors.py", line 209, in execute
    res = self._query(query)
  File "D:\Program Files\Python37\lib\site-packages\MySQLdb\cursors.py", line 315, in _query
    db.query(q)
  File "D:\Program Files\Python37\lib\site-packages\MySQLdb\connections.py", line 239, in query
    _mysql.connection.query(self, query)
django.db.utils.IntegrityError: (1062, "Duplicate entry '1590336000' for key 'LAMProcessData_process_r_acquisition_timestamp_a69ae90c_uniq'")
2020-05-24 Sun 19:08:38 threadpool.py _run_jobs 94 - DEBUG - Exiting worker thread
2020-05-24 Sun 19:08:47 threadpool.py __init__ 52 - INFO - Started thread pool with 0 core threads and 20 maximum threads
2020-05-24 Sun 19:08:47 scheduler.py add_job 287 - INFO - Adding job tentatively -- it will be properly scheduled when the scheduler starts
2020-05-24 Sun 19:08:47 scheduler.py add_job 287 - INFO - Adding job tentatively -- it will be properly scheduled when the scheduler starts
2020-05-24 Sun 19:08:47 scheduler.py add_job 287 - INFO - Adding job tentatively -- it will be properly scheduled when the scheduler starts
2020-05-24 Sun 19:08:47 scheduler.py _real_add_job 262 - INFO - Added job "regulartime_task (trigger: interval[1 day, 0:00:00], next run at: 2020-05-24 19:08:57.236544)" to job store "default"
2020-05-24 Sun 19:08:47 scheduler.py _real_add_job 262 - INFO - Added job "cleanup (trigger: cron[day_of_week='*', hour='3', minute='0', second='0'], next run at: 2020-05-25 03:00:00)" to job store "default"
2020-05-24 Sun 19:08:47 scheduler.py _real_add_job 262 - INFO - Added job "OpenLog (trigger: cron[hour='0'], next run at: 2020-05-25 00:00:00)" to job store "default"
2020-05-24 Sun 19:08:47 scheduler.py _main_loop 574 - INFO - Scheduler started
2020-05-24 Sun 19:08:47 scheduler.py _main_loop 579 - DEBUG - Looking for jobs to run
2020-05-24 Sun 19:08:47 scheduler.py _main_loop 588 - DEBUG - Next wakeup is due at 2020-05-24 19:08:57.236544 (in 9.997086 seconds)
2020-05-24 Sun 19:08:47 query_views.py <module> 63 - DEBUG - SendBefore_NotRecive : [<CNCProcessStatus: CNCProcessStatus object (2038721)>]
2020-05-24 Sun 19:08:47 query_views.py <module> 64 - DEBUG - Waitfor_Recive : [2038721]
2020-05-24 Sun 19:08:57 scheduler.py _main_loop 579 - DEBUG - Looking for jobs to run
2020-05-24 Sun 19:08:57 threadpool.py _run_jobs 69 - DEBUG - Started worker thread
2020-05-24 Sun 19:08:57 scheduler.py _run_job 509 - INFO - Running job "regulartime_task (trigger: interval[1 day, 0:00:00], next run at: 2020-05-24 19:08:57.236544)" (scheduled at 2020-05-24 19:08:57.236544)
2020-05-24 Sun 19:08:57 scheduler.py _main_loop 588 - DEBUG - Next wakeup is due at 2020-05-25 00:00:00 (in 17462.761838 seconds)
2020-05-24 Sun 19:08:57 scheduler.py _run_job 520 - ERROR - Job "regulartime_task (trigger: interval[1 day, 0:00:00], next run at: 2020-05-25 19:08:57.236544)" raised an exception
Traceback (most recent call last):
  File "D:\Program Files\Python37\lib\site-packages\django\db\backends\utils.py", line 84, in _execute
    return self.cursor.execute(sql, params)
  File "D:\Program Files\Python37\lib\site-packages\django\db\backends\mysql\base.py", line 71, in execute
    return self.cursor.execute(query, args)
  File "D:\Program Files\Python37\lib\site-packages\MySQLdb\cursors.py", line 209, in execute
    res = self._query(query)
  File "D:\Program Files\Python37\lib\site-packages\MySQLdb\cursors.py", line 315, in _query
    db.query(q)
  File "D:\Program Files\Python37\lib\site-packages\MySQLdb\connections.py", line 239, in query
    _mysql.connection.query(self, query)
MySQLdb._exceptions.IntegrityError: (1062, "Duplicate entry '1590336000' for key 'LAMProcessData_process_r_acquisition_timestamp_a69ae90c_uniq'")

The above exception was the direct cause of the following exception:

Traceback (most recent call last):
  File "D:\Program Files\Python37\lib\site-packages\apscheduler\scheduler.py", line 512, in _run_job
    retval = job.func(*job.args, **job.kwargs)
  File "E:\1-program\11-LAMDataServer\lamdataserver\LAMProcessData\views.py", line 5437, in regulartime_task
    RT_FineData.Realtime_FineData.init_Tomorrow_rows()
  File "E:\1-program\11-LAMDataServer\lamdataserver\LAMProcessData\process_realtime_finedata.py", line 193, in init_Tomorrow_rows
    _model.objects.bulk_create(insert_data_list)
  File "D:\Program Files\Python37\lib\site-packages\django\db\models\manager.py", line 82, in manager_method
    return getattr(self.get_queryset(), name)(*args, **kwargs)
  File "D:\Program Files\Python37\lib\site-packages\django\db\models\query.py", line 474, in bulk_create
    ids = self._batched_insert(objs_without_pk, fields, batch_size, ignore_conflicts=ignore_conflicts)
  File "D:\Program Files\Python37\lib\site-packages\django\db\models\query.py", line 1211, in _batched_insert
    self._insert(item, fields=fields, using=self.db, ignore_conflicts=ignore_conflicts)
  File "D:\Program Files\Python37\lib\site-packages\django\db\models\query.py", line 1186, in _insert
    return query.get_compiler(using=using).execute_sql(return_id)
  File "D:\Program Files\Python37\lib\site-packages\django\db\models\sql\compiler.py", line 1332, in execute_sql
    cursor.execute(sql, params)
  File "D:\Program Files\Python37\lib\site-packages\django\db\backends\utils.py", line 99, in execute
    return super().execute(sql, params)
  File "D:\Program Files\Python37\lib\site-packages\django\db\backends\utils.py", line 67, in execute
    return self._execute_with_wrappers(sql, params, many=False, executor=self._execute)
  File "D:\Program Files\Python37\lib\site-packages\django\db\backends\utils.py", line 76, in _execute_with_wrappers
    return executor(sql, params, many, context)
  File "D:\Program Files\Python37\lib\site-packages\django\db\backends\utils.py", line 84, in _execute
    return self.cursor.execute(sql, params)
  File "D:\Program Files\Python37\lib\site-packages\django\db\utils.py", line 89, in __exit__
    raise dj_exc_value.with_traceback(traceback) from exc_value
  File "D:\Program Files\Python37\lib\site-packages\django\db\backends\utils.py", line 84, in _execute
    return self.cursor.execute(sql, params)
  File "D:\Program Files\Python37\lib\site-packages\django\db\backends\mysql\base.py", line 71, in execute
    return self.cursor.execute(query, args)
  File "D:\Program Files\Python37\lib\site-packages\MySQLdb\cursors.py", line 209, in execute
    res = self._query(query)
  File "D:\Program Files\Python37\lib\site-packages\MySQLdb\cursors.py", line 315, in _query
    db.query(q)
  File "D:\Program Files\Python37\lib\site-packages\MySQLdb\connections.py", line 239, in query
    _mysql.connection.query(self, query)
django.db.utils.IntegrityError: (1062, "Duplicate entry '1590336000' for key 'LAMProcessData_process_r_acquisition_timestamp_a69ae90c_uniq'")
2020-05-24 Sun 19:08:58 threadpool.py _run_jobs 94 - DEBUG - Exiting worker thread
2020-05-24 Sun 19:10:23 autoreload.py trigger_reload 203 - INFO - E:\1-program\11-LAMDataServer\lamdataserver\LAMProcessData\views.py changed, reloading.
2020-05-24 Sun 19:10:23 threadpool.py shutdown 111 - INFO - Shutting down thread pool
2020-05-24 Sun 19:10:27 threadpool.py __init__ 52 - INFO - Started thread pool with 0 core threads and 20 maximum threads
2020-05-24 Sun 19:10:27 scheduler.py add_job 287 - INFO - Adding job tentatively -- it will be properly scheduled when the scheduler starts
2020-05-24 Sun 19:10:27 scheduler.py add_job 287 - INFO - Adding job tentatively -- it will be properly scheduled when the scheduler starts
2020-05-24 Sun 19:10:27 scheduler.py add_job 287 - INFO - Adding job tentatively -- it will be properly scheduled when the scheduler starts
2020-05-24 Sun 19:10:27 scheduler.py _real_add_job 262 - INFO - Added job "regulartime_task (trigger: interval[1 day, 0:00:00], next run at: 2020-05-24 19:10:37.642602)" to job store "default"
2020-05-24 Sun 19:10:27 scheduler.py _real_add_job 262 - INFO - Added job "cleanup (trigger: cron[day_of_week='*', hour='3', minute='0', second='0'], next run at: 2020-05-25 03:00:00)" to job store "default"
2020-05-24 Sun 19:10:27 scheduler.py _real_add_job 262 - INFO - Added job "OpenLog (trigger: cron[hour='0'], next run at: 2020-05-25 00:00:00)" to job store "default"
2020-05-24 Sun 19:10:27 scheduler.py _main_loop 574 - INFO - Scheduler started
2020-05-24 Sun 19:10:27 scheduler.py _main_loop 579 - DEBUG - Looking for jobs to run
2020-05-24 Sun 19:10:27 scheduler.py _main_loop 588 - DEBUG - Next wakeup is due at 2020-05-24 19:10:37.642602 (in 9.995084 seconds)
2020-05-24 Sun 19:10:27 query_views.py <module> 63 - DEBUG - SendBefore_NotRecive : [<CNCProcessStatus: CNCProcessStatus object (2038721)>]
2020-05-24 Sun 19:10:27 query_views.py <module> 64 - DEBUG - Waitfor_Recive : [2038721]
2020-05-24 Sun 19:10:37 scheduler.py _main_loop 579 - DEBUG - Looking for jobs to run
2020-05-24 Sun 19:10:37 threadpool.py _run_jobs 69 - DEBUG - Started worker thread
2020-05-24 Sun 19:10:37 scheduler.py _run_job 509 - INFO - Running job "regulartime_task (trigger: interval[1 day, 0:00:00], next run at: 2020-05-24 19:10:37.642602)" (scheduled at 2020-05-24 19:10:37.642602)
2020-05-24 Sun 19:10:37 scheduler.py _main_loop 588 - DEBUG - Next wakeup is due at 2020-05-25 00:00:00 (in 17362.355472 seconds)
2020-05-24 Sun 19:10:38 scheduler.py _run_job 520 - ERROR - Job "regulartime_task (trigger: interval[1 day, 0:00:00], next run at: 2020-05-25 19:10:37.642602)" raised an exception
Traceback (most recent call last):
  File "D:\Program Files\Python37\lib\site-packages\django\db\backends\utils.py", line 84, in _execute
    return self.cursor.execute(sql, params)
  File "D:\Program Files\Python37\lib\site-packages\django\db\backends\mysql\base.py", line 71, in execute
    return self.cursor.execute(query, args)
  File "D:\Program Files\Python37\lib\site-packages\MySQLdb\cursors.py", line 209, in execute
    res = self._query(query)
  File "D:\Program Files\Python37\lib\site-packages\MySQLdb\cursors.py", line 315, in _query
    db.query(q)
  File "D:\Program Files\Python37\lib\site-packages\MySQLdb\connections.py", line 239, in query
    _mysql.connection.query(self, query)
MySQLdb._exceptions.IntegrityError: (1062, "Duplicate entry '1590336000' for key 'LAMProcessData_process_r_acquisition_timestamp_a69ae90c_uniq'")

The above exception was the direct cause of the following exception:

Traceback (most recent call last):
  File "D:\Program Files\Python37\lib\site-packages\apscheduler\scheduler.py", line 512, in _run_job
    retval = job.func(*job.args, **job.kwargs)
  File "E:\1-program\11-LAMDataServer\lamdataserver\LAMProcessData\views.py", line 5437, in regulartime_task
    RT_FineData.Realtime_FineData.init_Tomorrow_rows()
  File "E:\1-program\11-LAMDataServer\lamdataserver\LAMProcessData\process_realtime_finedata.py", line 193, in init_Tomorrow_rows
    _model.objects.bulk_create(insert_data_list)
  File "D:\Program Files\Python37\lib\site-packages\django\db\models\manager.py", line 82, in manager_method
    return getattr(self.get_queryset(), name)(*args, **kwargs)
  File "D:\Program Files\Python37\lib\site-packages\django\db\models\query.py", line 474, in bulk_create
    ids = self._batched_insert(objs_without_pk, fields, batch_size, ignore_conflicts=ignore_conflicts)
  File "D:\Program Files\Python37\lib\site-packages\django\db\models\query.py", line 1211, in _batched_insert
    self._insert(item, fields=fields, using=self.db, ignore_conflicts=ignore_conflicts)
  File "D:\Program Files\Python37\lib\site-packages\django\db\models\query.py", line 1186, in _insert
    return query.get_compiler(using=using).execute_sql(return_id)
  File "D:\Program Files\Python37\lib\site-packages\django\db\models\sql\compiler.py", line 1332, in execute_sql
    cursor.execute(sql, params)
  File "D:\Program Files\Python37\lib\site-packages\django\db\backends\utils.py", line 99, in execute
    return super().execute(sql, params)
  File "D:\Program Files\Python37\lib\site-packages\django\db\backends\utils.py", line 67, in execute
    return self._execute_with_wrappers(sql, params, many=False, executor=self._execute)
  File "D:\Program Files\Python37\lib\site-packages\django\db\backends\utils.py", line 76, in _execute_with_wrappers
    return executor(sql, params, many, context)
  File "D:\Program Files\Python37\lib\site-packages\django\db\backends\utils.py", line 84, in _execute
    return self.cursor.execute(sql, params)
  File "D:\Program Files\Python37\lib\site-packages\django\db\utils.py", line 89, in __exit__
    raise dj_exc_value.with_traceback(traceback) from exc_value
  File "D:\Program Files\Python37\lib\site-packages\django\db\backends\utils.py", line 84, in _execute
    return self.cursor.execute(sql, params)
  File "D:\Program Files\Python37\lib\site-packages\django\db\backends\mysql\base.py", line 71, in execute
    return self.cursor.execute(query, args)
  File "D:\Program Files\Python37\lib\site-packages\MySQLdb\cursors.py", line 209, in execute
    res = self._query(query)
  File "D:\Program Files\Python37\lib\site-packages\MySQLdb\cursors.py", line 315, in _query
    db.query(q)
  File "D:\Program Files\Python37\lib\site-packages\MySQLdb\connections.py", line 239, in query
    _mysql.connection.query(self, query)
django.db.utils.IntegrityError: (1062, "Duplicate entry '1590336000' for key 'LAMProcessData_process_r_acquisition_timestamp_a69ae90c_uniq'")
2020-05-24 Sun 19:10:39 threadpool.py _run_jobs 94 - DEBUG - Exiting worker thread
2020-05-24 Sun 19:10:41 autoreload.py trigger_reload 203 - INFO - E:\1-program\11-LAMDataServer\lamdataserver\LAMProcessData\models.py changed, reloading.
2020-05-24 Sun 19:10:41 threadpool.py shutdown 111 - INFO - Shutting down thread pool
2020-05-24 Sun 19:10:43 threadpool.py __init__ 52 - INFO - Started thread pool with 0 core threads and 20 maximum threads
2020-05-24 Sun 19:10:43 scheduler.py add_job 287 - INFO - Adding job tentatively -- it will be properly scheduled when the scheduler starts
2020-05-24 Sun 19:10:43 scheduler.py add_job 287 - INFO - Adding job tentatively -- it will be properly scheduled when the scheduler starts
2020-05-24 Sun 19:10:43 scheduler.py add_job 287 - INFO - Adding job tentatively -- it will be properly scheduled when the scheduler starts
2020-05-24 Sun 19:10:43 scheduler.py _real_add_job 262 - INFO - Added job "regulartime_task (trigger: interval[1 day, 0:00:00], next run at: 2020-05-24 19:10:53.897898)" to job store "default"
2020-05-24 Sun 19:10:43 scheduler.py _real_add_job 262 - INFO - Added job "cleanup (trigger: cron[day_of_week='*', hour='3', minute='0', second='0'], next run at: 2020-05-25 03:00:00)" to job store "default"
2020-05-24 Sun 19:10:43 scheduler.py _real_add_job 262 - INFO - Added job "OpenLog (trigger: cron[hour='0'], next run at: 2020-05-25 00:00:00)" to job store "default"
2020-05-24 Sun 19:10:43 scheduler.py _main_loop 574 - INFO - Scheduler started
2020-05-24 Sun 19:10:43 scheduler.py _main_loop 579 - DEBUG - Looking for jobs to run
2020-05-24 Sun 19:10:43 scheduler.py _main_loop 588 - DEBUG - Next wakeup is due at 2020-05-24 19:10:53.897898 (in 9.997899 seconds)
2020-05-24 Sun 19:10:43 query_views.py <module> 63 - DEBUG - SendBefore_NotRecive : [<CNCProcessStatus: CNCProcessStatus object (2038721)>]
2020-05-24 Sun 19:10:43 query_views.py <module> 64 - DEBUG - Waitfor_Recive : [2038721]
2020-05-24 Sun 19:10:53 scheduler.py _main_loop 579 - DEBUG - Looking for jobs to run
2020-05-24 Sun 19:10:53 threadpool.py _run_jobs 69 - DEBUG - Started worker thread
2020-05-24 Sun 19:10:53 scheduler.py _main_loop 588 - DEBUG - Next wakeup is due at 2020-05-25 00:00:00 (in 17346.101487 seconds)
2020-05-24 Sun 19:10:53 scheduler.py _run_job 509 - INFO - Running job "regulartime_task (trigger: interval[1 day, 0:00:00], next run at: 2020-05-25 19:10:53.897898)" (scheduled at 2020-05-24 19:10:53.897898)
2020-05-24 Sun 19:10:54 scheduler.py _run_job 520 - ERROR - Job "regulartime_task (trigger: interval[1 day, 0:00:00], next run at: 2020-05-25 19:10:53.897898)" raised an exception
Traceback (most recent call last):
  File "D:\Program Files\Python37\lib\site-packages\django\db\backends\utils.py", line 84, in _execute
    return self.cursor.execute(sql, params)
  File "D:\Program Files\Python37\lib\site-packages\django\db\backends\mysql\base.py", line 71, in execute
    return self.cursor.execute(query, args)
  File "D:\Program Files\Python37\lib\site-packages\MySQLdb\cursors.py", line 209, in execute
    res = self._query(query)
  File "D:\Program Files\Python37\lib\site-packages\MySQLdb\cursors.py", line 315, in _query
    db.query(q)
  File "D:\Program Files\Python37\lib\site-packages\MySQLdb\connections.py", line 239, in query
    _mysql.connection.query(self, query)
MySQLdb._exceptions.IntegrityError: (1062, "Duplicate entry '1590336000' for key 'LAMProcessData_process_r_acquisition_timestamp_a69ae90c_uniq'")

The above exception was the direct cause of the following exception:

Traceback (most recent call last):
  File "D:\Program Files\Python37\lib\site-packages\apscheduler\scheduler.py", line 512, in _run_job
    retval = job.func(*job.args, **job.kwargs)
  File "E:\1-program\11-LAMDataServer\lamdataserver\LAMProcessData\views.py", line 5437, in regulartime_task
    RT_FineData.Realtime_FineData.init_Tomorrow_rows()
  File "E:\1-program\11-LAMDataServer\lamdataserver\LAMProcessData\process_realtime_finedata.py", line 193, in init_Tomorrow_rows
    _model.objects.bulk_create(insert_data_list)
  File "D:\Program Files\Python37\lib\site-packages\django\db\models\manager.py", line 82, in manager_method
    return getattr(self.get_queryset(), name)(*args, **kwargs)
  File "D:\Program Files\Python37\lib\site-packages\django\db\models\query.py", line 474, in bulk_create
    ids = self._batched_insert(objs_without_pk, fields, batch_size, ignore_conflicts=ignore_conflicts)
  File "D:\Program Files\Python37\lib\site-packages\django\db\models\query.py", line 1211, in _batched_insert
    self._insert(item, fields=fields, using=self.db, ignore_conflicts=ignore_conflicts)
  File "D:\Program Files\Python37\lib\site-packages\django\db\models\query.py", line 1186, in _insert
    return query.get_compiler(using=using).execute_sql(return_id)
  File "D:\Program Files\Python37\lib\site-packages\django\db\models\sql\compiler.py", line 1332, in execute_sql
    cursor.execute(sql, params)
  File "D:\Program Files\Python37\lib\site-packages\django\db\backends\utils.py", line 99, in execute
    return super().execute(sql, params)
  File "D:\Program Files\Python37\lib\site-packages\django\db\backends\utils.py", line 67, in execute
    return self._execute_with_wrappers(sql, params, many=False, executor=self._execute)
  File "D:\Program Files\Python37\lib\site-packages\django\db\backends\utils.py", line 76, in _execute_with_wrappers
    return executor(sql, params, many, context)
  File "D:\Program Files\Python37\lib\site-packages\django\db\backends\utils.py", line 84, in _execute
    return self.cursor.execute(sql, params)
  File "D:\Program Files\Python37\lib\site-packages\django\db\utils.py", line 89, in __exit__
    raise dj_exc_value.with_traceback(traceback) from exc_value
  File "D:\Program Files\Python37\lib\site-packages\django\db\backends\utils.py", line 84, in _execute
    return self.cursor.execute(sql, params)
  File "D:\Program Files\Python37\lib\site-packages\django\db\backends\mysql\base.py", line 71, in execute
    return self.cursor.execute(query, args)
  File "D:\Program Files\Python37\lib\site-packages\MySQLdb\cursors.py", line 209, in execute
    res = self._query(query)
  File "D:\Program Files\Python37\lib\site-packages\MySQLdb\cursors.py", line 315, in _query
    db.query(q)
  File "D:\Program Files\Python37\lib\site-packages\MySQLdb\connections.py", line 239, in query
    _mysql.connection.query(self, query)
django.db.utils.IntegrityError: (1062, "Duplicate entry '1590336000' for key 'LAMProcessData_process_r_acquisition_timestamp_a69ae90c_uniq'")
2020-05-24 Sun 19:10:55 threadpool.py _run_jobs 94 - DEBUG - Exiting worker thread
2020-05-24 Sun 19:16:16 autoreload.py trigger_reload 203 - INFO - E:\1-program\11-LAMDataServer\lamdataserver\LAMProcessData\urls.py changed, reloading.
2020-05-24 Sun 19:16:16 threadpool.py shutdown 111 - INFO - Shutting down thread pool
2020-05-24 Sun 19:16:19 threadpool.py __init__ 52 - INFO - Started thread pool with 0 core threads and 20 maximum threads
2020-05-24 Sun 19:16:19 scheduler.py add_job 287 - INFO - Adding job tentatively -- it will be properly scheduled when the scheduler starts
2020-05-24 Sun 19:16:19 scheduler.py add_job 287 - INFO - Adding job tentatively -- it will be properly scheduled when the scheduler starts
2020-05-24 Sun 19:16:19 scheduler.py add_job 287 - INFO - Adding job tentatively -- it will be properly scheduled when the scheduler starts
2020-05-24 Sun 19:16:19 scheduler.py _real_add_job 262 - INFO - Added job "regulartime_task (trigger: interval[1 day, 0:00:00], next run at: 2020-05-24 19:16:29.245590)" to job store "default"
2020-05-24 Sun 19:16:19 scheduler.py _real_add_job 262 - INFO - Added job "cleanup (trigger: cron[day_of_week='*', hour='3', minute='0', second='0'], next run at: 2020-05-25 03:00:00)" to job store "default"
2020-05-24 Sun 19:16:19 scheduler.py _real_add_job 262 - INFO - Added job "OpenLog (trigger: cron[hour='0'], next run at: 2020-05-25 00:00:00)" to job store "default"
2020-05-24 Sun 19:16:19 scheduler.py _main_loop 574 - INFO - Scheduler started
2020-05-24 Sun 19:16:19 scheduler.py _main_loop 579 - DEBUG - Looking for jobs to run
2020-05-24 Sun 19:16:19 scheduler.py _main_loop 588 - DEBUG - Next wakeup is due at 2020-05-24 19:16:29.245590 (in 9.995534 seconds)
2020-05-24 Sun 19:16:19 query_views.py <module> 63 - DEBUG - SendBefore_NotRecive : [<CNCProcessStatus: CNCProcessStatus object (2038721)>]
2020-05-24 Sun 19:16:19 query_views.py <module> 64 - DEBUG - Waitfor_Recive : [2038721]
2020-05-24 Sun 19:16:19 threadpool.py shutdown 111 - INFO - Shutting down thread pool
2020-05-24 Sun 19:19:31 threadpool.py __init__ 52 - INFO - Started thread pool with 0 core threads and 20 maximum threads
2020-05-24 Sun 19:19:31 scheduler.py add_job 287 - INFO - Adding job tentatively -- it will be properly scheduled when the scheduler starts
2020-05-24 Sun 19:19:31 scheduler.py add_job 287 - INFO - Adding job tentatively -- it will be properly scheduled when the scheduler starts
2020-05-24 Sun 19:19:31 scheduler.py add_job 287 - INFO - Adding job tentatively -- it will be properly scheduled when the scheduler starts
2020-05-24 Sun 19:19:31 scheduler.py _real_add_job 262 - INFO - Added job "regulartime_task (trigger: interval[1 day, 0:00:00], next run at: 2020-05-24 19:19:41.217552)" to job store "default"
2020-05-24 Sun 19:19:31 scheduler.py _real_add_job 262 - INFO - Added job "cleanup (trigger: cron[day_of_week='*', hour='3', minute='0', second='0'], next run at: 2020-05-25 03:00:00)" to job store "default"
2020-05-24 Sun 19:19:31 scheduler.py _real_add_job 262 - INFO - Added job "OpenLog (trigger: cron[hour='0'], next run at: 2020-05-25 00:00:00)" to job store "default"
2020-05-24 Sun 19:19:31 scheduler.py _main_loop 574 - INFO - Scheduler started
2020-05-24 Sun 19:19:31 scheduler.py _main_loop 579 - DEBUG - Looking for jobs to run
2020-05-24 Sun 19:19:31 scheduler.py _main_loop 588 - DEBUG - Next wakeup is due at 2020-05-24 19:19:41.217552 (in 9.997521 seconds)
2020-05-24 Sun 19:19:31 query_views.py <module> 63 - DEBUG - SendBefore_NotRecive : [<CNCProcessStatus: CNCProcessStatus object (2038721)>]
2020-05-24 Sun 19:19:31 query_views.py <module> 64 - DEBUG - Waitfor_Recive : [2038721]
2020-05-24 Sun 19:19:41 scheduler.py _main_loop 579 - DEBUG - Looking for jobs to run
2020-05-24 Sun 19:19:41 threadpool.py _run_jobs 69 - DEBUG - Started worker thread
2020-05-24 Sun 19:19:41 scheduler.py _run_job 509 - INFO - Running job "regulartime_task (trigger: interval[1 day, 0:00:00], next run at: 2020-05-24 19:19:41.217552)" (scheduled at 2020-05-24 19:19:41.217552)
2020-05-24 Sun 19:19:41 scheduler.py _main_loop 588 - DEBUG - Next wakeup is due at 2020-05-25 00:00:00 (in 16818.781066 seconds)
2020-05-24 Sun 19:19:41 scheduler.py _run_job 520 - ERROR - Job "regulartime_task (trigger: interval[1 day, 0:00:00], next run at: 2020-05-25 19:19:41.217552)" raised an exception
Traceback (most recent call last):
  File "D:\Program Files\Python37\lib\site-packages\django\db\backends\utils.py", line 84, in _execute
    return self.cursor.execute(sql, params)
  File "D:\Program Files\Python37\lib\site-packages\django\db\backends\mysql\base.py", line 71, in execute
    return self.cursor.execute(query, args)
  File "D:\Program Files\Python37\lib\site-packages\MySQLdb\cursors.py", line 209, in execute
    res = self._query(query)
  File "D:\Program Files\Python37\lib\site-packages\MySQLdb\cursors.py", line 315, in _query
    db.query(q)
  File "D:\Program Files\Python37\lib\site-packages\MySQLdb\connections.py", line 239, in query
    _mysql.connection.query(self, query)
MySQLdb._exceptions.IntegrityError: (1062, "Duplicate entry '1590336000' for key 'LAMProcessData_process_r_acquisition_timestamp_a69ae90c_uniq'")

The above exception was the direct cause of the following exception:

Traceback (most recent call last):
  File "D:\Program Files\Python37\lib\site-packages\apscheduler\scheduler.py", line 512, in _run_job
    retval = job.func(*job.args, **job.kwargs)
  File "E:\1-program\11-LAMDataServer\lamdataserver\LAMProcessData\views.py", line 5479, in regulartime_task
    RT_FineData.Realtime_FineData.init_Tomorrow_rows()
  File "E:\1-program\11-LAMDataServer\lamdataserver\LAMProcessData\process_realtime_finedata.py", line 193, in init_Tomorrow_rows
    _model.objects.bulk_create(insert_data_list)
  File "D:\Program Files\Python37\lib\site-packages\django\db\models\manager.py", line 82, in manager_method
    return getattr(self.get_queryset(), name)(*args, **kwargs)
  File "D:\Program Files\Python37\lib\site-packages\django\db\models\query.py", line 474, in bulk_create
    ids = self._batched_insert(objs_without_pk, fields, batch_size, ignore_conflicts=ignore_conflicts)
  File "D:\Program Files\Python37\lib\site-packages\django\db\models\query.py", line 1211, in _batched_insert
    self._insert(item, fields=fields, using=self.db, ignore_conflicts=ignore_conflicts)
  File "D:\Program Files\Python37\lib\site-packages\django\db\models\query.py", line 1186, in _insert
    return query.get_compiler(using=using).execute_sql(return_id)
  File "D:\Program Files\Python37\lib\site-packages\django\db\models\sql\compiler.py", line 1332, in execute_sql
    cursor.execute(sql, params)
  File "D:\Program Files\Python37\lib\site-packages\django\db\backends\utils.py", line 99, in execute
    return super().execute(sql, params)
  File "D:\Program Files\Python37\lib\site-packages\django\db\backends\utils.py", line 67, in execute
    return self._execute_with_wrappers(sql, params, many=False, executor=self._execute)
  File "D:\Program Files\Python37\lib\site-packages\django\db\backends\utils.py", line 76, in _execute_with_wrappers
    return executor(sql, params, many, context)
  File "D:\Program Files\Python37\lib\site-packages\django\db\backends\utils.py", line 84, in _execute
    return self.cursor.execute(sql, params)
  File "D:\Program Files\Python37\lib\site-packages\django\db\utils.py", line 89, in __exit__
    raise dj_exc_value.with_traceback(traceback) from exc_value
  File "D:\Program Files\Python37\lib\site-packages\django\db\backends\utils.py", line 84, in _execute
    return self.cursor.execute(sql, params)
  File "D:\Program Files\Python37\lib\site-packages\django\db\backends\mysql\base.py", line 71, in execute
    return self.cursor.execute(query, args)
  File "D:\Program Files\Python37\lib\site-packages\MySQLdb\cursors.py", line 209, in execute
    res = self._query(query)
  File "D:\Program Files\Python37\lib\site-packages\MySQLdb\cursors.py", line 315, in _query
    db.query(q)
  File "D:\Program Files\Python37\lib\site-packages\MySQLdb\connections.py", line 239, in query
    _mysql.connection.query(self, query)
django.db.utils.IntegrityError: (1062, "Duplicate entry '1590336000' for key 'LAMProcessData_process_r_acquisition_timestamp_a69ae90c_uniq'")
2020-05-24 Sun 19:19:42 threadpool.py _run_jobs 94 - DEBUG - Exiting worker thread
