2020-04-10 Fri 00:15:47 threadpool.py __init__ 52 - INFO - Started thread pool with 0 core threads and 20 maximum threads
2020-04-10 Fri 00:15:47 scheduler.py add_job 287 - INFO - Adding job tentatively -- it will be properly scheduled when the scheduler starts
2020-04-10 Fri 00:15:47 scheduler.py add_job 287 - INFO - Adding job tentatively -- it will be properly scheduled when the scheduler starts
2020-04-10 Fri 00:15:47 scheduler.py add_job 287 - INFO - Adding job tentatively -- it will be properly scheduled when the scheduler starts
2020-04-10 Fri 00:15:47 scheduler.py _real_add_job 262 - INFO - Added job "regulartime_task (trigger: interval[1 day, 0:00:00], next run at: 2020-04-10 00:15:57.002828)" to job store "default"
2020-04-10 Fri 00:15:47 scheduler.py _real_add_job 262 - INFO - Added job "cleanup (trigger: cron[day_of_week='*', hour='3', minute='0', second='0'], next run at: 2020-04-10 03:00:00)" to job store "default"
2020-04-10 Fri 00:15:47 scheduler.py _real_add_job 262 - INFO - Added job "OpenLog (trigger: cron[hour='0'], next run at: 2020-04-11 00:00:00)" to job store "default"
2020-04-10 Fri 00:15:47 scheduler.py _main_loop 574 - INFO - Scheduler started
2020-04-10 Fri 00:15:47 scheduler.py _main_loop 579 - DEBUG - Looking for jobs to run
2020-04-10 Fri 00:15:47 scheduler.py _main_loop 588 - DEBUG - Next wakeup is due at 2020-04-10 00:15:57.002828 (in 9.961003 seconds)
2020-04-10 Fri 00:15:47 query_views.py <module> 59 - DEBUG - SendBefore_NotRecive : [<CNCProcessStatus: CNCProcessStatus object (2038721)>]
2020-04-10 Fri 00:15:47 query_views.py <module> 60 - DEBUG - Waitfor_Recive : [2038721]
2020-04-10 Fri 00:15:57 scheduler.py _main_loop 579 - DEBUG - Looking for jobs to run
2020-04-10 Fri 00:15:57 threadpool.py _run_jobs 69 - DEBUG - Started worker thread
2020-04-10 Fri 00:15:57 scheduler.py _main_loop 588 - DEBUG - Next wakeup is due at 2020-04-10 03:00:00 (in 9842.993769 seconds)
2020-04-10 Fri 00:15:57 scheduler.py _run_job 509 - INFO - Running job "regulartime_task (trigger: interval[1 day, 0:00:00], next run at: 2020-04-11 00:15:57.002828)" (scheduled at 2020-04-10 00:15:57.002828)
2020-04-10 Fri 00:15:58 scheduler.py _run_job 520 - ERROR - Job "regulartime_task (trigger: interval[1 day, 0:00:00], next run at: 2020-04-11 00:15:57.002828)" raised an exception
Traceback (most recent call last):
  File "D:\Program Files\Python37\lib\site-packages\django\db\backends\mysql\base.py", line 71, in execute
    return self.cursor.execute(query, args)
  File "D:\Program Files\Python37\lib\site-packages\MySQLdb\cursors.py", line 209, in execute
    res = self._query(query)
  File "D:\Program Files\Python37\lib\site-packages\MySQLdb\cursors.py", line 315, in _query
    db.query(q)
  File "D:\Program Files\Python37\lib\site-packages\MySQLdb\connections.py", line 239, in query
    _mysql.connection.query(self, query)
MySQLdb._exceptions.OperationalError: (1048, "Column 'laser_power' cannot be null")

During handling of the above exception, another exception occurred:

Traceback (most recent call last):
  File "D:\Program Files\Python37\lib\site-packages\apscheduler\scheduler.py", line 512, in _run_job
    retval = job.func(*job.args, **job.kwargs)
  File "E:\1-program\11-LAMDataServer\lamdataserver\LAMProcessData\views.py", line 4817, in regulartime_task
    RT_FineData.Realtime_FineData.init_Tomorrow_rows()
  File "E:\1-program\11-LAMDataServer\lamdataserver\LAMProcessData\process_realtime_finedata.py", line 193, in init_Tomorrow_rows
    _model.objects.bulk_create(insert_data_list)
  File "D:\Program Files\Python37\lib\site-packages\django\db\models\manager.py", line 82, in manager_method
    return getattr(self.get_queryset(), name)(*args, **kwargs)
  File "D:\Program Files\Python37\lib\site-packages\django\db\models\query.py", line 474, in bulk_create
    ids = self._batched_insert(objs_without_pk, fields, batch_size, ignore_conflicts=ignore_conflicts)
  File "D:\Program Files\Python37\lib\site-packages\django\db\models\query.py", line 1211, in _batched_insert
    self._insert(item, fields=fields, using=self.db, ignore_conflicts=ignore_conflicts)
  File "D:\Program Files\Python37\lib\site-packages\django\db\models\query.py", line 1186, in _insert
    return query.get_compiler(using=using).execute_sql(return_id)
  File "D:\Program Files\Python37\lib\site-packages\django\db\models\sql\compiler.py", line 1332, in execute_sql
    cursor.execute(sql, params)
  File "D:\Program Files\Python37\lib\site-packages\django\db\backends\utils.py", line 99, in execute
    return super().execute(sql, params)
  File "D:\Program Files\Python37\lib\site-packages\django\db\backends\utils.py", line 67, in execute
    return self._execute_with_wrappers(sql, params, many=False, executor=self._execute)
  File "D:\Program Files\Python37\lib\site-packages\django\db\backends\utils.py", line 76, in _execute_with_wrappers
    return executor(sql, params, many, context)
  File "D:\Program Files\Python37\lib\site-packages\django\db\backends\utils.py", line 84, in _execute
    return self.cursor.execute(sql, params)
  File "D:\Program Files\Python37\lib\site-packages\django\db\backends\mysql\base.py", line 76, in execute
    raise utils.IntegrityError(*tuple(e.args))
django.db.utils.IntegrityError: (1048, "Column 'laser_power' cannot be null")
2020-04-10 Fri 00:15:59 threadpool.py _run_jobs 94 - DEBUG - Exiting worker thread
2020-04-10 Fri 00:23:22 threadpool.py __init__ 52 - INFO - Started thread pool with 0 core threads and 20 maximum threads
2020-04-10 Fri 00:23:22 scheduler.py add_job 287 - INFO - Adding job tentatively -- it will be properly scheduled when the scheduler starts
2020-04-10 Fri 00:23:22 scheduler.py add_job 287 - INFO - Adding job tentatively -- it will be properly scheduled when the scheduler starts
2020-04-10 Fri 00:23:22 scheduler.py add_job 287 - INFO - Adding job tentatively -- it will be properly scheduled when the scheduler starts
2020-04-10 Fri 00:23:22 scheduler.py _real_add_job 262 - INFO - Added job "regulartime_task (trigger: interval[1 day, 0:00:00], next run at: 2020-04-10 00:23:32.718856)" to job store "default"
2020-04-10 Fri 00:23:22 scheduler.py _real_add_job 262 - INFO - Added job "cleanup (trigger: cron[day_of_week='*', hour='3', minute='0', second='0'], next run at: 2020-04-10 03:00:00)" to job store "default"
2020-04-10 Fri 00:23:22 scheduler.py _real_add_job 262 - INFO - Added job "OpenLog (trigger: cron[hour='0'], next run at: 2020-04-11 00:00:00)" to job store "default"
2020-04-10 Fri 00:23:22 scheduler.py _main_loop 574 - INFO - Scheduler started
2020-04-10 Fri 00:23:22 scheduler.py _main_loop 579 - DEBUG - Looking for jobs to run
2020-04-10 Fri 00:23:22 scheduler.py _main_loop 588 - DEBUG - Next wakeup is due at 2020-04-10 00:23:32.718856 (in 9.997033 seconds)
2020-04-10 Fri 00:23:22 query_views.py <module> 59 - DEBUG - SendBefore_NotRecive : [<CNCProcessStatus: CNCProcessStatus object (2038721)>]
2020-04-10 Fri 00:23:22 query_views.py <module> 60 - DEBUG - Waitfor_Recive : [2038721]
2020-04-10 Fri 00:23:32 scheduler.py _main_loop 579 - DEBUG - Looking for jobs to run
2020-04-10 Fri 00:23:32 threadpool.py _run_jobs 69 - DEBUG - Started worker thread
2020-04-10 Fri 00:23:32 scheduler.py _run_job 509 - INFO - Running job "regulartime_task (trigger: interval[1 day, 0:00:00], next run at: 2020-04-10 00:23:32.718856)" (scheduled at 2020-04-10 00:23:32.718856)
2020-04-10 Fri 00:23:32 scheduler.py _main_loop 588 - DEBUG - Next wakeup is due at 2020-04-10 03:00:00 (in 9387.279142 seconds)
2020-04-10 Fri 00:23:33 scheduler.py _run_job 520 - ERROR - Job "regulartime_task (trigger: interval[1 day, 0:00:00], next run at: 2020-04-11 00:23:32.718856)" raised an exception
Traceback (most recent call last):
  File "D:\Program Files\Python37\lib\site-packages\django\db\backends\utils.py", line 84, in _execute
    return self.cursor.execute(sql, params)
  File "D:\Program Files\Python37\lib\site-packages\django\db\backends\mysql\base.py", line 71, in execute
    return self.cursor.execute(query, args)
  File "D:\Program Files\Python37\lib\site-packages\MySQLdb\cursors.py", line 209, in execute
    res = self._query(query)
  File "D:\Program Files\Python37\lib\site-packages\MySQLdb\cursors.py", line 315, in _query
    db.query(q)
  File "D:\Program Files\Python37\lib\site-packages\MySQLdb\connections.py", line 239, in query
    _mysql.connection.query(self, query)
MySQLdb._exceptions.IntegrityError: (1062, "Duplicate entry '1586534400' for key 'LAMProcessData_process_r_acquisition_timestamp_a69ae90c_uniq'")

The above exception was the direct cause of the following exception:

Traceback (most recent call last):
  File "D:\Program Files\Python37\lib\site-packages\apscheduler\scheduler.py", line 512, in _run_job
    retval = job.func(*job.args, **job.kwargs)
  File "E:\1-program\11-LAMDataServer\lamdataserver\LAMProcessData\views.py", line 4816, in regulartime_task
    RT_FineData.Realtime_FineData.init_Tomorrow_rows()
  File "E:\1-program\11-LAMDataServer\lamdataserver\LAMProcessData\process_realtime_finedata.py", line 193, in init_Tomorrow_rows
    _model.objects.bulk_create(insert_data_list)
  File "D:\Program Files\Python37\lib\site-packages\django\db\models\manager.py", line 82, in manager_method
    return getattr(self.get_queryset(), name)(*args, **kwargs)
  File "D:\Program Files\Python37\lib\site-packages\django\db\models\query.py", line 474, in bulk_create
    ids = self._batched_insert(objs_without_pk, fields, batch_size, ignore_conflicts=ignore_conflicts)
  File "D:\Program Files\Python37\lib\site-packages\django\db\models\query.py", line 1211, in _batched_insert
    self._insert(item, fields=fields, using=self.db, ignore_conflicts=ignore_conflicts)
  File "D:\Program Files\Python37\lib\site-packages\django\db\models\query.py", line 1186, in _insert
    return query.get_compiler(using=using).execute_sql(return_id)
  File "D:\Program Files\Python37\lib\site-packages\django\db\models\sql\compiler.py", line 1332, in execute_sql
    cursor.execute(sql, params)
  File "D:\Program Files\Python37\lib\site-packages\django\db\backends\utils.py", line 99, in execute
    return super().execute(sql, params)
  File "D:\Program Files\Python37\lib\site-packages\django\db\backends\utils.py", line 67, in execute
    return self._execute_with_wrappers(sql, params, many=False, executor=self._execute)
  File "D:\Program Files\Python37\lib\site-packages\django\db\backends\utils.py", line 76, in _execute_with_wrappers
    return executor(sql, params, many, context)
  File "D:\Program Files\Python37\lib\site-packages\django\db\backends\utils.py", line 84, in _execute
    return self.cursor.execute(sql, params)
  File "D:\Program Files\Python37\lib\site-packages\django\db\utils.py", line 89, in __exit__
    raise dj_exc_value.with_traceback(traceback) from exc_value
  File "D:\Program Files\Python37\lib\site-packages\django\db\backends\utils.py", line 84, in _execute
    return self.cursor.execute(sql, params)
  File "D:\Program Files\Python37\lib\site-packages\django\db\backends\mysql\base.py", line 71, in execute
    return self.cursor.execute(query, args)
  File "D:\Program Files\Python37\lib\site-packages\MySQLdb\cursors.py", line 209, in execute
    res = self._query(query)
  File "D:\Program Files\Python37\lib\site-packages\MySQLdb\cursors.py", line 315, in _query
    db.query(q)
  File "D:\Program Files\Python37\lib\site-packages\MySQLdb\connections.py", line 239, in query
    _mysql.connection.query(self, query)
django.db.utils.IntegrityError: (1062, "Duplicate entry '1586534400' for key 'LAMProcessData_process_r_acquisition_timestamp_a69ae90c_uniq'")
2020-04-10 Fri 00:23:34 threadpool.py _run_jobs 94 - DEBUG - Exiting worker thread
2020-04-10 Fri 00:25:14 threadpool.py __init__ 52 - INFO - Started thread pool with 0 core threads and 20 maximum threads
2020-04-10 Fri 00:25:14 scheduler.py add_job 287 - INFO - Adding job tentatively -- it will be properly scheduled when the scheduler starts
2020-04-10 Fri 00:25:14 scheduler.py add_job 287 - INFO - Adding job tentatively -- it will be properly scheduled when the scheduler starts
2020-04-10 Fri 00:25:14 scheduler.py add_job 287 - INFO - Adding job tentatively -- it will be properly scheduled when the scheduler starts
2020-04-10 Fri 00:25:14 scheduler.py _real_add_job 262 - INFO - Added job "regulartime_task (trigger: interval[1 day, 0:00:00], next run at: 2020-04-10 00:25:24.442201)" to job store "default"
2020-04-10 Fri 00:25:14 scheduler.py _real_add_job 262 - INFO - Added job "cleanup (trigger: cron[day_of_week='*', hour='3', minute='0', second='0'], next run at: 2020-04-10 03:00:00)" to job store "default"
2020-04-10 Fri 00:25:14 scheduler.py _real_add_job 262 - INFO - Added job "OpenLog (trigger: cron[hour='0'], next run at: 2020-04-11 00:00:00)" to job store "default"
2020-04-10 Fri 00:25:14 scheduler.py _main_loop 574 - INFO - Scheduler started
2020-04-10 Fri 00:25:14 scheduler.py _main_loop 579 - DEBUG - Looking for jobs to run
2020-04-10 Fri 00:25:14 scheduler.py _main_loop 588 - DEBUG - Next wakeup is due at 2020-04-10 00:25:24.442201 (in 9.998037 seconds)
2020-04-10 Fri 00:25:14 query_views.py <module> 59 - DEBUG - SendBefore_NotRecive : [<CNCProcessStatus: CNCProcessStatus object (2038721)>]
2020-04-10 Fri 00:25:14 query_views.py <module> 60 - DEBUG - Waitfor_Recive : [2038721]
2020-04-10 Fri 00:25:24 scheduler.py _main_loop 579 - DEBUG - Looking for jobs to run
2020-04-10 Fri 00:25:24 threadpool.py _run_jobs 69 - DEBUG - Started worker thread
2020-04-10 Fri 00:25:24 scheduler.py _main_loop 588 - DEBUG - Next wakeup is due at 2020-04-10 03:00:00 (in 9275.556006 seconds)
2020-04-10 Fri 00:25:24 scheduler.py _run_job 509 - INFO - Running job "regulartime_task (trigger: interval[1 day, 0:00:00], next run at: 2020-04-11 00:25:24.442201)" (scheduled at 2020-04-10 00:25:24.442201)
2020-04-10 Fri 00:25:24 scheduler.py _run_job 520 - ERROR - Job "regulartime_task (trigger: interval[1 day, 0:00:00], next run at: 2020-04-11 00:25:24.442201)" raised an exception
Traceback (most recent call last):
  File "D:\Program Files\Python37\lib\site-packages\django\db\backends\utils.py", line 84, in _execute
    return self.cursor.execute(sql, params)
  File "D:\Program Files\Python37\lib\site-packages\django\db\backends\mysql\base.py", line 71, in execute
    return self.cursor.execute(query, args)
  File "D:\Program Files\Python37\lib\site-packages\MySQLdb\cursors.py", line 209, in execute
    res = self._query(query)
  File "D:\Program Files\Python37\lib\site-packages\MySQLdb\cursors.py", line 315, in _query
    db.query(q)
  File "D:\Program Files\Python37\lib\site-packages\MySQLdb\connections.py", line 239, in query
    _mysql.connection.query(self, query)
MySQLdb._exceptions.IntegrityError: (1062, "Duplicate entry '1586534400' for key 'LAMProcessData_process_r_acquisition_timestamp_a69ae90c_uniq'")

The above exception was the direct cause of the following exception:

Traceback (most recent call last):
  File "D:\Program Files\Python37\lib\site-packages\apscheduler\scheduler.py", line 512, in _run_job
    retval = job.func(*job.args, **job.kwargs)
  File "E:\1-program\11-LAMDataServer\lamdataserver\LAMProcessData\views.py", line 4816, in regulartime_task
    RT_FineData.Realtime_FineData.init_Tomorrow_rows()
  File "E:\1-program\11-LAMDataServer\lamdataserver\LAMProcessData\process_realtime_finedata.py", line 193, in init_Tomorrow_rows
    _model.objects.bulk_create(insert_data_list)
  File "D:\Program Files\Python37\lib\site-packages\django\db\models\manager.py", line 82, in manager_method
    return getattr(self.get_queryset(), name)(*args, **kwargs)
  File "D:\Program Files\Python37\lib\site-packages\django\db\models\query.py", line 474, in bulk_create
    ids = self._batched_insert(objs_without_pk, fields, batch_size, ignore_conflicts=ignore_conflicts)
  File "D:\Program Files\Python37\lib\site-packages\django\db\models\query.py", line 1211, in _batched_insert
    self._insert(item, fields=fields, using=self.db, ignore_conflicts=ignore_conflicts)
  File "D:\Program Files\Python37\lib\site-packages\django\db\models\query.py", line 1186, in _insert
    return query.get_compiler(using=using).execute_sql(return_id)
  File "D:\Program Files\Python37\lib\site-packages\django\db\models\sql\compiler.py", line 1332, in execute_sql
    cursor.execute(sql, params)
  File "D:\Program Files\Python37\lib\site-packages\django\db\backends\utils.py", line 99, in execute
    return super().execute(sql, params)
  File "D:\Program Files\Python37\lib\site-packages\django\db\backends\utils.py", line 67, in execute
    return self._execute_with_wrappers(sql, params, many=False, executor=self._execute)
  File "D:\Program Files\Python37\lib\site-packages\django\db\backends\utils.py", line 76, in _execute_with_wrappers
    return executor(sql, params, many, context)
  File "D:\Program Files\Python37\lib\site-packages\django\db\backends\utils.py", line 84, in _execute
    return self.cursor.execute(sql, params)
  File "D:\Program Files\Python37\lib\site-packages\django\db\utils.py", line 89, in __exit__
    raise dj_exc_value.with_traceback(traceback) from exc_value
  File "D:\Program Files\Python37\lib\site-packages\django\db\backends\utils.py", line 84, in _execute
    return self.cursor.execute(sql, params)
  File "D:\Program Files\Python37\lib\site-packages\django\db\backends\mysql\base.py", line 71, in execute
    return self.cursor.execute(query, args)
  File "D:\Program Files\Python37\lib\site-packages\MySQLdb\cursors.py", line 209, in execute
    res = self._query(query)
  File "D:\Program Files\Python37\lib\site-packages\MySQLdb\cursors.py", line 315, in _query
    db.query(q)
  File "D:\Program Files\Python37\lib\site-packages\MySQLdb\connections.py", line 239, in query
    _mysql.connection.query(self, query)
django.db.utils.IntegrityError: (1062, "Duplicate entry '1586534400' for key 'LAMProcessData_process_r_acquisition_timestamp_a69ae90c_uniq'")
2020-04-10 Fri 00:25:25 threadpool.py _run_jobs 94 - DEBUG - Exiting worker thread
2020-04-10 Fri 00:25:34 autoreload.py trigger_reload 203 - INFO - E:\1-program\11-LAMDataServer\lamdataserver\LAMProcessData\views.py changed, reloading.
2020-04-10 Fri 00:25:34 threadpool.py shutdown 111 - INFO - Shutting down thread pool
2020-04-10 Fri 00:25:38 threadpool.py __init__ 52 - INFO - Started thread pool with 0 core threads and 20 maximum threads
2020-04-10 Fri 00:25:38 scheduler.py add_job 287 - INFO - Adding job tentatively -- it will be properly scheduled when the scheduler starts
2020-04-10 Fri 00:25:38 scheduler.py add_job 287 - INFO - Adding job tentatively -- it will be properly scheduled when the scheduler starts
2020-04-10 Fri 00:25:38 scheduler.py add_job 287 - INFO - Adding job tentatively -- it will be properly scheduled when the scheduler starts
2020-04-10 Fri 00:25:38 scheduler.py _real_add_job 262 - INFO - Added job "regulartime_task (trigger: interval[1 day, 0:00:00], next run at: 2020-04-10 00:25:48.230742)" to job store "default"
2020-04-10 Fri 00:25:38 scheduler.py _real_add_job 262 - INFO - Added job "cleanup (trigger: cron[day_of_week='*', hour='3', minute='0', second='0'], next run at: 2020-04-10 03:00:00)" to job store "default"
2020-04-10 Fri 00:25:38 scheduler.py _real_add_job 262 - INFO - Added job "OpenLog (trigger: cron[hour='0'], next run at: 2020-04-11 00:00:00)" to job store "default"
2020-04-10 Fri 00:25:38 scheduler.py _main_loop 574 - INFO - Scheduler started
2020-04-10 Fri 00:25:38 scheduler.py _main_loop 579 - DEBUG - Looking for jobs to run
2020-04-10 Fri 00:25:38 scheduler.py _main_loop 588 - DEBUG - Next wakeup is due at 2020-04-10 00:25:48.230742 (in 9.996868 seconds)
2020-04-10 Fri 00:25:38 query_views.py <module> 59 - DEBUG - SendBefore_NotRecive : [<CNCProcessStatus: CNCProcessStatus object (2038721)>]
2020-04-10 Fri 00:25:38 query_views.py <module> 60 - DEBUG - Waitfor_Recive : [2038721]
2020-04-10 Fri 00:25:48 scheduler.py _main_loop 579 - DEBUG - Looking for jobs to run
2020-04-10 Fri 00:25:48 threadpool.py _run_jobs 69 - DEBUG - Started worker thread
2020-04-10 Fri 00:25:48 scheduler.py _run_job 509 - INFO - Running job "regulartime_task (trigger: interval[1 day, 0:00:00], next run at: 2020-04-10 00:25:48.230742)" (scheduled at 2020-04-10 00:25:48.230742)
2020-04-10 Fri 00:25:48 scheduler.py _main_loop 588 - DEBUG - Next wakeup is due at 2020-04-10 03:00:00 (in 9251.754563 seconds)
2020-04-10 Fri 00:25:48 scheduler.py _run_job 520 - ERROR - Job "regulartime_task (trigger: interval[1 day, 0:00:00], next run at: 2020-04-11 00:25:48.230742)" raised an exception
Traceback (most recent call last):
  File "D:\Program Files\Python37\lib\site-packages\django\db\backends\utils.py", line 84, in _execute
    return self.cursor.execute(sql, params)
  File "D:\Program Files\Python37\lib\site-packages\django\db\backends\mysql\base.py", line 71, in execute
    return self.cursor.execute(query, args)
  File "D:\Program Files\Python37\lib\site-packages\MySQLdb\cursors.py", line 209, in execute
    res = self._query(query)
  File "D:\Program Files\Python37\lib\site-packages\MySQLdb\cursors.py", line 315, in _query
    db.query(q)
  File "D:\Program Files\Python37\lib\site-packages\MySQLdb\connections.py", line 239, in query
    _mysql.connection.query(self, query)
MySQLdb._exceptions.IntegrityError: (1062, "Duplicate entry '1586534400' for key 'LAMProcessData_process_r_acquisition_timestamp_a69ae90c_uniq'")

The above exception was the direct cause of the following exception:

Traceback (most recent call last):
  File "D:\Program Files\Python37\lib\site-packages\apscheduler\scheduler.py", line 512, in _run_job
    retval = job.func(*job.args, **job.kwargs)
  File "E:\1-program\11-LAMDataServer\lamdataserver\LAMProcessData\views.py", line 4817, in regulartime_task
    RT_FineData.Realtime_FineData.init_Tomorrow_rows()
  File "E:\1-program\11-LAMDataServer\lamdataserver\LAMProcessData\process_realtime_finedata.py", line 193, in init_Tomorrow_rows
    _model.objects.bulk_create(insert_data_list)
  File "D:\Program Files\Python37\lib\site-packages\django\db\models\manager.py", line 82, in manager_method
    return getattr(self.get_queryset(), name)(*args, **kwargs)
  File "D:\Program Files\Python37\lib\site-packages\django\db\models\query.py", line 474, in bulk_create
    ids = self._batched_insert(objs_without_pk, fields, batch_size, ignore_conflicts=ignore_conflicts)
  File "D:\Program Files\Python37\lib\site-packages\django\db\models\query.py", line 1211, in _batched_insert
    self._insert(item, fields=fields, using=self.db, ignore_conflicts=ignore_conflicts)
  File "D:\Program Files\Python37\lib\site-packages\django\db\models\query.py", line 1186, in _insert
    return query.get_compiler(using=using).execute_sql(return_id)
  File "D:\Program Files\Python37\lib\site-packages\django\db\models\sql\compiler.py", line 1332, in execute_sql
    cursor.execute(sql, params)
  File "D:\Program Files\Python37\lib\site-packages\django\db\backends\utils.py", line 99, in execute
    return super().execute(sql, params)
  File "D:\Program Files\Python37\lib\site-packages\django\db\backends\utils.py", line 67, in execute
    return self._execute_with_wrappers(sql, params, many=False, executor=self._execute)
  File "D:\Program Files\Python37\lib\site-packages\django\db\backends\utils.py", line 76, in _execute_with_wrappers
    return executor(sql, params, many, context)
  File "D:\Program Files\Python37\lib\site-packages\django\db\backends\utils.py", line 84, in _execute
    return self.cursor.execute(sql, params)
  File "D:\Program Files\Python37\lib\site-packages\django\db\utils.py", line 89, in __exit__
    raise dj_exc_value.with_traceback(traceback) from exc_value
  File "D:\Program Files\Python37\lib\site-packages\django\db\backends\utils.py", line 84, in _execute
    return self.cursor.execute(sql, params)
  File "D:\Program Files\Python37\lib\site-packages\django\db\backends\mysql\base.py", line 71, in execute
    return self.cursor.execute(query, args)
  File "D:\Program Files\Python37\lib\site-packages\MySQLdb\cursors.py", line 209, in execute
    res = self._query(query)
  File "D:\Program Files\Python37\lib\site-packages\MySQLdb\cursors.py", line 315, in _query
    db.query(q)
  File "D:\Program Files\Python37\lib\site-packages\MySQLdb\connections.py", line 239, in query
    _mysql.connection.query(self, query)
django.db.utils.IntegrityError: (1062, "Duplicate entry '1586534400' for key 'LAMProcessData_process_r_acquisition_timestamp_a69ae90c_uniq'")
2020-04-10 Fri 00:25:49 threadpool.py _run_jobs 94 - DEBUG - Exiting worker thread
2020-04-10 Fri 00:32:35 autoreload.py trigger_reload 203 - INFO - E:\1-program\11-LAMDataServer\lamdataserver\LAMProcessData\views.py changed, reloading.
2020-04-10 Fri 00:32:35 threadpool.py shutdown 111 - INFO - Shutting down thread pool
2020-04-10 Fri 00:32:39 threadpool.py __init__ 52 - INFO - Started thread pool with 0 core threads and 20 maximum threads
2020-04-10 Fri 00:32:39 scheduler.py add_job 287 - INFO - Adding job tentatively -- it will be properly scheduled when the scheduler starts
2020-04-10 Fri 00:32:39 scheduler.py add_job 287 - INFO - Adding job tentatively -- it will be properly scheduled when the scheduler starts
2020-04-10 Fri 00:32:39 scheduler.py add_job 287 - INFO - Adding job tentatively -- it will be properly scheduled when the scheduler starts
2020-04-10 Fri 00:32:39 scheduler.py _real_add_job 262 - INFO - Added job "regulartime_task (trigger: interval[1 day, 0:00:00], next run at: 2020-04-10 00:32:49.778874)" to job store "default"
2020-04-10 Fri 00:32:39 scheduler.py _real_add_job 262 - INFO - Added job "cleanup (trigger: cron[day_of_week='*', hour='3', minute='0', second='0'], next run at: 2020-04-10 03:00:00)" to job store "default"
2020-04-10 Fri 00:32:39 scheduler.py _real_add_job 262 - INFO - Added job "OpenLog (trigger: cron[hour='0'], next run at: 2020-04-11 00:00:00)" to job store "default"
2020-04-10 Fri 00:32:39 scheduler.py _main_loop 574 - INFO - Scheduler started
2020-04-10 Fri 00:32:39 scheduler.py _main_loop 579 - DEBUG - Looking for jobs to run
2020-04-10 Fri 00:32:39 scheduler.py _main_loop 588 - DEBUG - Next wakeup is due at 2020-04-10 00:32:49.778874 (in 9.996355 seconds)
2020-04-10 Fri 00:32:39 query_views.py <module> 59 - DEBUG - SendBefore_NotRecive : [<CNCProcessStatus: CNCProcessStatus object (2038721)>]
2020-04-10 Fri 00:32:39 query_views.py <module> 60 - DEBUG - Waitfor_Recive : [2038721]
2020-04-10 Fri 00:32:49 scheduler.py _main_loop 579 - DEBUG - Looking for jobs to run
2020-04-10 Fri 00:32:49 threadpool.py _run_jobs 69 - DEBUG - Started worker thread
2020-04-10 Fri 00:32:49 scheduler.py _run_job 509 - INFO - Running job "regulartime_task (trigger: interval[1 day, 0:00:00], next run at: 2020-04-10 00:32:49.778874)" (scheduled at 2020-04-10 00:32:49.778874)
2020-04-10 Fri 00:32:49 scheduler.py _main_loop 588 - DEBUG - Next wakeup is due at 2020-04-10 03:00:00 (in 8830.219953 seconds)
2020-04-10 Fri 00:32:50 scheduler.py _run_job 520 - ERROR - Job "regulartime_task (trigger: interval[1 day, 0:00:00], next run at: 2020-04-11 00:32:49.778874)" raised an exception
Traceback (most recent call last):
  File "D:\Program Files\Python37\lib\site-packages\django\db\backends\utils.py", line 84, in _execute
    return self.cursor.execute(sql, params)
  File "D:\Program Files\Python37\lib\site-packages\django\db\backends\mysql\base.py", line 71, in execute
    return self.cursor.execute(query, args)
  File "D:\Program Files\Python37\lib\site-packages\MySQLdb\cursors.py", line 209, in execute
    res = self._query(query)
  File "D:\Program Files\Python37\lib\site-packages\MySQLdb\cursors.py", line 315, in _query
    db.query(q)
  File "D:\Program Files\Python37\lib\site-packages\MySQLdb\connections.py", line 239, in query
    _mysql.connection.query(self, query)
MySQLdb._exceptions.IntegrityError: (1062, "Duplicate entry '1586534400' for key 'LAMProcessData_process_r_acquisition_timestamp_a69ae90c_uniq'")

The above exception was the direct cause of the following exception:

Traceback (most recent call last):
  File "D:\Program Files\Python37\lib\site-packages\apscheduler\scheduler.py", line 512, in _run_job
    retval = job.func(*job.args, **job.kwargs)
  File "E:\1-program\11-LAMDataServer\lamdataserver\LAMProcessData\views.py", line 4818, in regulartime_task
    RT_FineData.Realtime_FineData.init_Tomorrow_rows()
  File "E:\1-program\11-LAMDataServer\lamdataserver\LAMProcessData\process_realtime_finedata.py", line 193, in init_Tomorrow_rows
    _model.objects.bulk_create(insert_data_list)
  File "D:\Program Files\Python37\lib\site-packages\django\db\models\manager.py", line 82, in manager_method
    return getattr(self.get_queryset(), name)(*args, **kwargs)
  File "D:\Program Files\Python37\lib\site-packages\django\db\models\query.py", line 474, in bulk_create
    ids = self._batched_insert(objs_without_pk, fields, batch_size, ignore_conflicts=ignore_conflicts)
  File "D:\Program Files\Python37\lib\site-packages\django\db\models\query.py", line 1211, in _batched_insert
    self._insert(item, fields=fields, using=self.db, ignore_conflicts=ignore_conflicts)
  File "D:\Program Files\Python37\lib\site-packages\django\db\models\query.py", line 1186, in _insert
    return query.get_compiler(using=using).execute_sql(return_id)
  File "D:\Program Files\Python37\lib\site-packages\django\db\models\sql\compiler.py", line 1332, in execute_sql
    cursor.execute(sql, params)
  File "D:\Program Files\Python37\lib\site-packages\django\db\backends\utils.py", line 99, in execute
    return super().execute(sql, params)
  File "D:\Program Files\Python37\lib\site-packages\django\db\backends\utils.py", line 67, in execute
    return self._execute_with_wrappers(sql, params, many=False, executor=self._execute)
  File "D:\Program Files\Python37\lib\site-packages\django\db\backends\utils.py", line 76, in _execute_with_wrappers
    return executor(sql, params, many, context)
  File "D:\Program Files\Python37\lib\site-packages\django\db\backends\utils.py", line 84, in _execute
    return self.cursor.execute(sql, params)
  File "D:\Program Files\Python37\lib\site-packages\django\db\utils.py", line 89, in __exit__
    raise dj_exc_value.with_traceback(traceback) from exc_value
  File "D:\Program Files\Python37\lib\site-packages\django\db\backends\utils.py", line 84, in _execute
    return self.cursor.execute(sql, params)
  File "D:\Program Files\Python37\lib\site-packages\django\db\backends\mysql\base.py", line 71, in execute
    return self.cursor.execute(query, args)
  File "D:\Program Files\Python37\lib\site-packages\MySQLdb\cursors.py", line 209, in execute
    res = self._query(query)
  File "D:\Program Files\Python37\lib\site-packages\MySQLdb\cursors.py", line 315, in _query
    db.query(q)
  File "D:\Program Files\Python37\lib\site-packages\MySQLdb\connections.py", line 239, in query
    _mysql.connection.query(self, query)
django.db.utils.IntegrityError: (1062, "Duplicate entry '1586534400' for key 'LAMProcessData_process_r_acquisition_timestamp_a69ae90c_uniq'")
2020-04-10 Fri 00:32:51 threadpool.py _run_jobs 94 - DEBUG - Exiting worker thread
2020-04-10 Fri 00:34:00 autoreload.py trigger_reload 203 - INFO - E:\1-program\11-LAMDataServer\lamdataserver\LAMProcessData\views.py changed, reloading.
2020-04-10 Fri 00:34:00 threadpool.py shutdown 111 - INFO - Shutting down thread pool
2020-04-10 Fri 00:34:03 threadpool.py __init__ 52 - INFO - Started thread pool with 0 core threads and 20 maximum threads
2020-04-10 Fri 00:34:03 scheduler.py add_job 287 - INFO - Adding job tentatively -- it will be properly scheduled when the scheduler starts
2020-04-10 Fri 00:34:03 scheduler.py add_job 287 - INFO - Adding job tentatively -- it will be properly scheduled when the scheduler starts
2020-04-10 Fri 00:34:03 scheduler.py add_job 287 - INFO - Adding job tentatively -- it will be properly scheduled when the scheduler starts
2020-04-10 Fri 00:34:03 scheduler.py _real_add_job 262 - INFO - Added job "regulartime_task (trigger: interval[1 day, 0:00:00], next run at: 2020-04-10 00:34:13.607612)" to job store "default"
2020-04-10 Fri 00:34:03 scheduler.py _real_add_job 262 - INFO - Added job "cleanup (trigger: cron[day_of_week='*', hour='3', minute='0', second='0'], next run at: 2020-04-10 03:00:00)" to job store "default"
2020-04-10 Fri 00:34:03 scheduler.py _real_add_job 262 - INFO - Added job "OpenLog (trigger: cron[hour='0'], next run at: 2020-04-11 00:00:00)" to job store "default"
2020-04-10 Fri 00:34:03 scheduler.py _main_loop 574 - INFO - Scheduler started
2020-04-10 Fri 00:34:03 scheduler.py _main_loop 579 - DEBUG - Looking for jobs to run
2020-04-10 Fri 00:34:03 scheduler.py _main_loop 588 - DEBUG - Next wakeup is due at 2020-04-10 00:34:13.607612 (in 9.997042 seconds)
2020-04-10 Fri 00:34:03 query_views.py <module> 59 - DEBUG - SendBefore_NotRecive : [<CNCProcessStatus: CNCProcessStatus object (2038721)>]
2020-04-10 Fri 00:34:03 query_views.py <module> 60 - DEBUG - Waitfor_Recive : [2038721]
2020-04-10 Fri 00:34:13 scheduler.py _main_loop 579 - DEBUG - Looking for jobs to run
2020-04-10 Fri 00:34:13 threadpool.py _run_jobs 69 - DEBUG - Started worker thread
2020-04-10 Fri 00:34:13 scheduler.py _main_loop 588 - DEBUG - Next wakeup is due at 2020-04-10 03:00:00 (in 8746.390612 seconds)
2020-04-10 Fri 00:34:13 scheduler.py _run_job 509 - INFO - Running job "regulartime_task (trigger: interval[1 day, 0:00:00], next run at: 2020-04-11 00:34:13.607612)" (scheduled at 2020-04-10 00:34:13.607612)
2020-04-10 Fri 00:34:14 scheduler.py _run_job 520 - ERROR - Job "regulartime_task (trigger: interval[1 day, 0:00:00], next run at: 2020-04-11 00:34:13.607612)" raised an exception
Traceback (most recent call last):
  File "D:\Program Files\Python37\lib\site-packages\django\db\backends\utils.py", line 84, in _execute
    return self.cursor.execute(sql, params)
  File "D:\Program Files\Python37\lib\site-packages\django\db\backends\mysql\base.py", line 71, in execute
    return self.cursor.execute(query, args)
  File "D:\Program Files\Python37\lib\site-packages\MySQLdb\cursors.py", line 209, in execute
    res = self._query(query)
  File "D:\Program Files\Python37\lib\site-packages\MySQLdb\cursors.py", line 315, in _query
    db.query(q)
  File "D:\Program Files\Python37\lib\site-packages\MySQLdb\connections.py", line 239, in query
    _mysql.connection.query(self, query)
MySQLdb._exceptions.IntegrityError: (1062, "Duplicate entry '1586534400' for key 'LAMProcessData_process_r_acquisition_timestamp_a69ae90c_uniq'")

The above exception was the direct cause of the following exception:

Traceback (most recent call last):
  File "D:\Program Files\Python37\lib\site-packages\apscheduler\scheduler.py", line 512, in _run_job
    retval = job.func(*job.args, **job.kwargs)
  File "E:\1-program\11-LAMDataServer\lamdataserver\LAMProcessData\views.py", line 4818, in regulartime_task
    RT_FineData.Realtime_FineData.init_Tomorrow_rows()
  File "E:\1-program\11-LAMDataServer\lamdataserver\LAMProcessData\process_realtime_finedata.py", line 193, in init_Tomorrow_rows
    _model.objects.bulk_create(insert_data_list)
  File "D:\Program Files\Python37\lib\site-packages\django\db\models\manager.py", line 82, in manager_method
    return getattr(self.get_queryset(), name)(*args, **kwargs)
  File "D:\Program Files\Python37\lib\site-packages\django\db\models\query.py", line 474, in bulk_create
    ids = self._batched_insert(objs_without_pk, fields, batch_size, ignore_conflicts=ignore_conflicts)
  File "D:\Program Files\Python37\lib\site-packages\django\db\models\query.py", line 1211, in _batched_insert
    self._insert(item, fields=fields, using=self.db, ignore_conflicts=ignore_conflicts)
  File "D:\Program Files\Python37\lib\site-packages\django\db\models\query.py", line 1186, in _insert
    return query.get_compiler(using=using).execute_sql(return_id)
  File "D:\Program Files\Python37\lib\site-packages\django\db\models\sql\compiler.py", line 1332, in execute_sql
    cursor.execute(sql, params)
  File "D:\Program Files\Python37\lib\site-packages\django\db\backends\utils.py", line 99, in execute
    return super().execute(sql, params)
  File "D:\Program Files\Python37\lib\site-packages\django\db\backends\utils.py", line 67, in execute
    return self._execute_with_wrappers(sql, params, many=False, executor=self._execute)
  File "D:\Program Files\Python37\lib\site-packages\django\db\backends\utils.py", line 76, in _execute_with_wrappers
    return executor(sql, params, many, context)
  File "D:\Program Files\Python37\lib\site-packages\django\db\backends\utils.py", line 84, in _execute
    return self.cursor.execute(sql, params)
  File "D:\Program Files\Python37\lib\site-packages\django\db\utils.py", line 89, in __exit__
    raise dj_exc_value.with_traceback(traceback) from exc_value
  File "D:\Program Files\Python37\lib\site-packages\django\db\backends\utils.py", line 84, in _execute
    return self.cursor.execute(sql, params)
  File "D:\Program Files\Python37\lib\site-packages\django\db\backends\mysql\base.py", line 71, in execute
    return self.cursor.execute(query, args)
  File "D:\Program Files\Python37\lib\site-packages\MySQLdb\cursors.py", line 209, in execute
    res = self._query(query)
  File "D:\Program Files\Python37\lib\site-packages\MySQLdb\cursors.py", line 315, in _query
    db.query(q)
  File "D:\Program Files\Python37\lib\site-packages\MySQLdb\connections.py", line 239, in query
    _mysql.connection.query(self, query)
django.db.utils.IntegrityError: (1062, "Duplicate entry '1586534400' for key 'LAMProcessData_process_r_acquisition_timestamp_a69ae90c_uniq'")
2020-04-10 Fri 00:34:15 threadpool.py _run_jobs 94 - DEBUG - Exiting worker thread
2020-04-10 Fri 00:34:16 autoreload.py trigger_reload 203 - INFO - E:\1-program\11-LAMDataServer\lamdataserver\LAMProcessData\views.py changed, reloading.
2020-04-10 Fri 00:34:16 threadpool.py shutdown 111 - INFO - Shutting down thread pool
2020-04-10 Fri 00:34:19 threadpool.py __init__ 52 - INFO - Started thread pool with 0 core threads and 20 maximum threads
2020-04-10 Fri 00:34:19 scheduler.py add_job 287 - INFO - Adding job tentatively -- it will be properly scheduled when the scheduler starts
2020-04-10 Fri 00:34:19 scheduler.py add_job 287 - INFO - Adding job tentatively -- it will be properly scheduled when the scheduler starts
2020-04-10 Fri 00:34:19 scheduler.py add_job 287 - INFO - Adding job tentatively -- it will be properly scheduled when the scheduler starts
2020-04-10 Fri 00:34:19 scheduler.py _real_add_job 262 - INFO - Added job "regulartime_task (trigger: interval[1 day, 0:00:00], next run at: 2020-04-10 00:34:29.458313)" to job store "default"
2020-04-10 Fri 00:34:19 scheduler.py _real_add_job 262 - INFO - Added job "cleanup (trigger: cron[day_of_week='*', hour='3', minute='0', second='0'], next run at: 2020-04-10 03:00:00)" to job store "default"
2020-04-10 Fri 00:34:19 scheduler.py _real_add_job 262 - INFO - Added job "OpenLog (trigger: cron[hour='0'], next run at: 2020-04-11 00:00:00)" to job store "default"
2020-04-10 Fri 00:34:19 scheduler.py _main_loop 574 - INFO - Scheduler started
2020-04-10 Fri 00:34:19 query_views.py <module> 59 - DEBUG - SendBefore_NotRecive : [<CNCProcessStatus: CNCProcessStatus object (2038721)>]
2020-04-10 Fri 00:34:19 scheduler.py _main_loop 579 - DEBUG - Looking for jobs to run
2020-04-10 Fri 00:34:19 query_views.py <module> 60 - DEBUG - Waitfor_Recive : [2038721]
2020-04-10 Fri 00:34:19 scheduler.py _main_loop 588 - DEBUG - Next wakeup is due at 2020-04-10 00:34:29.458313 (in 9.940890 seconds)
2020-04-10 Fri 00:34:29 scheduler.py _main_loop 579 - DEBUG - Looking for jobs to run
2020-04-10 Fri 00:34:29 threadpool.py _run_jobs 69 - DEBUG - Started worker thread
2020-04-10 Fri 00:34:29 scheduler.py _run_job 509 - INFO - Running job "regulartime_task (trigger: interval[1 day, 0:00:00], next run at: 2020-04-10 00:34:29.458313)" (scheduled at 2020-04-10 00:34:29.458313)
2020-04-10 Fri 00:34:29 scheduler.py _main_loop 588 - DEBUG - Next wakeup is due at 2020-04-10 03:00:00 (in 8730.532687 seconds)
2020-04-10 Fri 00:34:29 scheduler.py _run_job 520 - ERROR - Job "regulartime_task (trigger: interval[1 day, 0:00:00], next run at: 2020-04-11 00:34:29.458313)" raised an exception
Traceback (most recent call last):
  File "D:\Program Files\Python37\lib\site-packages\django\db\backends\utils.py", line 84, in _execute
    return self.cursor.execute(sql, params)
  File "D:\Program Files\Python37\lib\site-packages\django\db\backends\mysql\base.py", line 71, in execute
    return self.cursor.execute(query, args)
  File "D:\Program Files\Python37\lib\site-packages\MySQLdb\cursors.py", line 209, in execute
    res = self._query(query)
  File "D:\Program Files\Python37\lib\site-packages\MySQLdb\cursors.py", line 315, in _query
    db.query(q)
  File "D:\Program Files\Python37\lib\site-packages\MySQLdb\connections.py", line 239, in query
    _mysql.connection.query(self, query)
MySQLdb._exceptions.IntegrityError: (1062, "Duplicate entry '1586534400' for key 'LAMProcessData_process_r_acquisition_timestamp_a69ae90c_uniq'")

The above exception was the direct cause of the following exception:

Traceback (most recent call last):
  File "D:\Program Files\Python37\lib\site-packages\apscheduler\scheduler.py", line 512, in _run_job
    retval = job.func(*job.args, **job.kwargs)
  File "E:\1-program\11-LAMDataServer\lamdataserver\LAMProcessData\views.py", line 4818, in regulartime_task
    RT_FineData.Realtime_FineData.init_Tomorrow_rows()
  File "E:\1-program\11-LAMDataServer\lamdataserver\LAMProcessData\process_realtime_finedata.py", line 193, in init_Tomorrow_rows
    _model.objects.bulk_create(insert_data_list)
  File "D:\Program Files\Python37\lib\site-packages\django\db\models\manager.py", line 82, in manager_method
    return getattr(self.get_queryset(), name)(*args, **kwargs)
  File "D:\Program Files\Python37\lib\site-packages\django\db\models\query.py", line 474, in bulk_create
    ids = self._batched_insert(objs_without_pk, fields, batch_size, ignore_conflicts=ignore_conflicts)
  File "D:\Program Files\Python37\lib\site-packages\django\db\models\query.py", line 1211, in _batched_insert
    self._insert(item, fields=fields, using=self.db, ignore_conflicts=ignore_conflicts)
  File "D:\Program Files\Python37\lib\site-packages\django\db\models\query.py", line 1186, in _insert
    return query.get_compiler(using=using).execute_sql(return_id)
  File "D:\Program Files\Python37\lib\site-packages\django\db\models\sql\compiler.py", line 1332, in execute_sql
    cursor.execute(sql, params)
  File "D:\Program Files\Python37\lib\site-packages\django\db\backends\utils.py", line 99, in execute
    return super().execute(sql, params)
  File "D:\Program Files\Python37\lib\site-packages\django\db\backends\utils.py", line 67, in execute
    return self._execute_with_wrappers(sql, params, many=False, executor=self._execute)
  File "D:\Program Files\Python37\lib\site-packages\django\db\backends\utils.py", line 76, in _execute_with_wrappers
    return executor(sql, params, many, context)
  File "D:\Program Files\Python37\lib\site-packages\django\db\backends\utils.py", line 84, in _execute
    return self.cursor.execute(sql, params)
  File "D:\Program Files\Python37\lib\site-packages\django\db\utils.py", line 89, in __exit__
    raise dj_exc_value.with_traceback(traceback) from exc_value
  File "D:\Program Files\Python37\lib\site-packages\django\db\backends\utils.py", line 84, in _execute
    return self.cursor.execute(sql, params)
  File "D:\Program Files\Python37\lib\site-packages\django\db\backends\mysql\base.py", line 71, in execute
    return self.cursor.execute(query, args)
  File "D:\Program Files\Python37\lib\site-packages\MySQLdb\cursors.py", line 209, in execute
    res = self._query(query)
  File "D:\Program Files\Python37\lib\site-packages\MySQLdb\cursors.py", line 315, in _query
    db.query(q)
  File "D:\Program Files\Python37\lib\site-packages\MySQLdb\connections.py", line 239, in query
    _mysql.connection.query(self, query)
django.db.utils.IntegrityError: (1062, "Duplicate entry '1586534400' for key 'LAMProcessData_process_r_acquisition_timestamp_a69ae90c_uniq'")
2020-04-10 Fri 00:34:30 threadpool.py _run_jobs 94 - DEBUG - Exiting worker thread
2020-04-10 Fri 22:23:56 threadpool.py __init__ 52 - INFO - Started thread pool with 0 core threads and 20 maximum threads
2020-04-10 Fri 22:23:56 scheduler.py add_job 287 - INFO - Adding job tentatively -- it will be properly scheduled when the scheduler starts
2020-04-10 Fri 22:23:56 scheduler.py add_job 287 - INFO - Adding job tentatively -- it will be properly scheduled when the scheduler starts
2020-04-10 Fri 22:23:56 scheduler.py add_job 287 - INFO - Adding job tentatively -- it will be properly scheduled when the scheduler starts
2020-04-10 Fri 22:23:56 scheduler.py _real_add_job 262 - INFO - Added job "regulartime_task (trigger: interval[1 day, 0:00:00], next run at: 2020-04-10 22:24:06.143084)" to job store "default"
2020-04-10 Fri 22:23:56 scheduler.py _real_add_job 262 - INFO - Added job "cleanup (trigger: cron[day_of_week='*', hour='3', minute='0', second='0'], next run at: 2020-04-11 03:00:00)" to job store "default"
2020-04-10 Fri 22:23:56 scheduler.py _real_add_job 262 - INFO - Added job "OpenLog (trigger: cron[hour='0'], next run at: 2020-04-11 00:00:00)" to job store "default"
2020-04-10 Fri 22:23:56 scheduler.py _main_loop 574 - INFO - Scheduler started
2020-04-10 Fri 22:23:56 scheduler.py _main_loop 579 - DEBUG - Looking for jobs to run
2020-04-10 Fri 22:23:56 scheduler.py _main_loop 588 - DEBUG - Next wakeup is due at 2020-04-10 22:24:06.143084 (in 9.998007 seconds)
2020-04-10 Fri 22:23:56 query_views.py <module> 59 - DEBUG - SendBefore_NotRecive : [<CNCProcessStatus: CNCProcessStatus object (2038721)>]
2020-04-10 Fri 22:23:56 query_views.py <module> 60 - DEBUG - Waitfor_Recive : [2038721]
2020-04-10 Fri 22:24:06 scheduler.py _main_loop 579 - DEBUG - Looking for jobs to run
2020-04-10 Fri 22:24:06 threadpool.py _run_jobs 69 - DEBUG - Started worker thread
2020-04-10 Fri 22:24:06 scheduler.py _main_loop 588 - DEBUG - Next wakeup is due at 2020-04-11 00:00:00 (in 5753.853964 seconds)
2020-04-10 Fri 22:24:06 scheduler.py _run_job 509 - INFO - Running job "regulartime_task (trigger: interval[1 day, 0:00:00], next run at: 2020-04-11 22:24:06.143084)" (scheduled at 2020-04-10 22:24:06.143084)
2020-04-10 Fri 22:24:06 scheduler.py _run_job 520 - ERROR - Job "regulartime_task (trigger: interval[1 day, 0:00:00], next run at: 2020-04-11 22:24:06.143084)" raised an exception
Traceback (most recent call last):
  File "D:\Program Files\Python37\lib\site-packages\django\db\backends\utils.py", line 84, in _execute
    return self.cursor.execute(sql, params)
  File "D:\Program Files\Python37\lib\site-packages\django\db\backends\mysql\base.py", line 71, in execute
    return self.cursor.execute(query, args)
  File "D:\Program Files\Python37\lib\site-packages\MySQLdb\cursors.py", line 209, in execute
    res = self._query(query)
  File "D:\Program Files\Python37\lib\site-packages\MySQLdb\cursors.py", line 315, in _query
    db.query(q)
  File "D:\Program Files\Python37\lib\site-packages\MySQLdb\connections.py", line 239, in query
    _mysql.connection.query(self, query)
MySQLdb._exceptions.IntegrityError: (1062, "Duplicate entry '1586534400' for key 'LAMProcessData_process_r_acquisition_timestamp_a69ae90c_uniq'")

The above exception was the direct cause of the following exception:

Traceback (most recent call last):
  File "D:\Program Files\Python37\lib\site-packages\apscheduler\scheduler.py", line 512, in _run_job
    retval = job.func(*job.args, **job.kwargs)
  File "E:\1-program\11-LAMDataServer\lamdataserver\LAMProcessData\views.py", line 4818, in regulartime_task
    RT_FineData.Realtime_FineData.init_Tomorrow_rows()
  File "E:\1-program\11-LAMDataServer\lamdataserver\LAMProcessData\process_realtime_finedata.py", line 193, in init_Tomorrow_rows
    _model.objects.bulk_create(insert_data_list)
  File "D:\Program Files\Python37\lib\site-packages\django\db\models\manager.py", line 82, in manager_method
    return getattr(self.get_queryset(), name)(*args, **kwargs)
  File "D:\Program Files\Python37\lib\site-packages\django\db\models\query.py", line 474, in bulk_create
    ids = self._batched_insert(objs_without_pk, fields, batch_size, ignore_conflicts=ignore_conflicts)
  File "D:\Program Files\Python37\lib\site-packages\django\db\models\query.py", line 1211, in _batched_insert
    self._insert(item, fields=fields, using=self.db, ignore_conflicts=ignore_conflicts)
  File "D:\Program Files\Python37\lib\site-packages\django\db\models\query.py", line 1186, in _insert
    return query.get_compiler(using=using).execute_sql(return_id)
  File "D:\Program Files\Python37\lib\site-packages\django\db\models\sql\compiler.py", line 1332, in execute_sql
    cursor.execute(sql, params)
  File "D:\Program Files\Python37\lib\site-packages\django\db\backends\utils.py", line 99, in execute
    return super().execute(sql, params)
  File "D:\Program Files\Python37\lib\site-packages\django\db\backends\utils.py", line 67, in execute
    return self._execute_with_wrappers(sql, params, many=False, executor=self._execute)
  File "D:\Program Files\Python37\lib\site-packages\django\db\backends\utils.py", line 76, in _execute_with_wrappers
    return executor(sql, params, many, context)
  File "D:\Program Files\Python37\lib\site-packages\django\db\backends\utils.py", line 84, in _execute
    return self.cursor.execute(sql, params)
  File "D:\Program Files\Python37\lib\site-packages\django\db\utils.py", line 89, in __exit__
    raise dj_exc_value.with_traceback(traceback) from exc_value
  File "D:\Program Files\Python37\lib\site-packages\django\db\backends\utils.py", line 84, in _execute
    return self.cursor.execute(sql, params)
  File "D:\Program Files\Python37\lib\site-packages\django\db\backends\mysql\base.py", line 71, in execute
    return self.cursor.execute(query, args)
  File "D:\Program Files\Python37\lib\site-packages\MySQLdb\cursors.py", line 209, in execute
    res = self._query(query)
  File "D:\Program Files\Python37\lib\site-packages\MySQLdb\cursors.py", line 315, in _query
    db.query(q)
  File "D:\Program Files\Python37\lib\site-packages\MySQLdb\connections.py", line 239, in query
    _mysql.connection.query(self, query)
django.db.utils.IntegrityError: (1062, "Duplicate entry '1586534400' for key 'LAMProcessData_process_r_acquisition_timestamp_a69ae90c_uniq'")
2020-04-10 Fri 22:24:07 threadpool.py _run_jobs 94 - DEBUG - Exiting worker thread
2020-04-10 Fri 22:24:11 log.py log_response 228 - WARNING - Not Found: /favicon.ico
2020-04-10 Fri 22:24:12 log.py log_response 228 - WARNING - Not Found: /favicon.ico
2020-04-10 Fri 22:24:12 log.py log_response 228 - WARNING - Not Found: /favicon.ico
2020-04-10 Fri 22:24:13 log.py log_response 228 - WARNING - Not Found: /favicon.ico
2020-04-10 Fri 22:24:14 log.py log_response 228 - WARNING - Not Found: /favicon.ico
2020-04-10 Fri 22:24:14 log.py log_response 228 - WARNING - Not Found: /favicon.ico
2020-04-10 Fri 22:24:15 log.py log_response 228 - WARNING - Not Found: /favicon.ico
2020-04-10 Fri 22:24:15 log.py log_response 228 - WARNING - Not Found: /favicon.ico
2020-04-10 Fri 22:24:16 log.py log_response 228 - WARNING - Not Found: /favicon.ico
2020-04-10 Fri 22:24:17 log.py log_response 228 - WARNING - Not Found: /favicon.ico
2020-04-10 Fri 22:24:17 log.py log_response 228 - WARNING - Not Found: /favicon.ico
2020-04-10 Fri 22:24:18 log.py log_response 228 - WARNING - Not Found: /
2020-04-10 Fri 22:24:18 log.py log_response 228 - WARNING - Not Found: /favicon.ico
2020-04-10 Fri 22:24:23 log.py log_response 228 - WARNING - Not Found: /favicon.ico
2020-04-10 Fri 22:24:35 log.py log_response 228 - WARNING - Not Found: /favicon.ico
2020-04-10 Fri 22:24:35 log.py log_response 228 - WARNING - Not Found: /favicon.ico
2020-04-10 Fri 22:24:36 log.py log_response 228 - WARNING - Not Found: /favicon.ico
2020-04-10 Fri 22:24:36 log.py log_response 228 - WARNING - Not Found: /favicon.ico
2020-04-10 Fri 22:24:37 log.py log_response 228 - WARNING - Not Found: /favicon.ico
2020-04-10 Fri 23:23:48 log.py log_response 228 - WARNING - Not Found: /favicon.ico
2020-04-10 Fri 23:23:49 log.py log_response 228 - WARNING - Not Found: /favicon.ico
2020-04-10 Fri 23:23:49 log.py log_response 228 - WARNING - Not Found: /favicon.ico
2020-04-10 Fri 23:23:50 log.py log_response 228 - WARNING - Not Found: /favicon.ico
2020-04-10 Fri 23:23:51 log.py log_response 228 - WARNING - Not Found: /favicon.ico
2020-04-10 Fri 23:23:51 log.py log_response 228 - WARNING - Not Found: /favicon.ico
2020-04-10 Fri 23:23:52 log.py log_response 228 - WARNING - Not Found: /favicon.ico
2020-04-10 Fri 23:23:55 log.py log_response 228 - WARNING - Not Found: /favicon.ico
2020-04-10 Fri 23:23:55 log.py log_response 228 - WARNING - Not Found: /favicon.ico
2020-04-10 Fri 23:23:56 log.py log_response 228 - WARNING - Not Found: /favicon.ico
2020-04-10 Fri 23:23:57 log.py log_response 228 - WARNING - Not Found: /favicon.ico
2020-04-10 Fri 23:23:57 log.py log_response 228 - WARNING - Not Found: /favicon.ico
2020-04-10 Fri 23:23:58 log.py log_response 228 - WARNING - Not Found: /favicon.ico
2020-04-10 Fri 23:23:58 log.py log_response 228 - WARNING - Not Found: /favicon.ico
2020-04-10 Fri 23:23:59 log.py log_response 228 - WARNING - Not Found: /favicon.ico
2020-04-10 Fri 23:24:03 log.py log_response 228 - WARNING - Not Found: /favicon.ico
2020-04-10 Fri 23:24:04 log.py log_response 228 - WARNING - Not Found: /favicon.ico
2020-04-10 Fri 23:24:05 log.py log_response 228 - WARNING - Not Found: /favicon.ico
2020-04-10 Fri 23:24:05 log.py log_response 228 - WARNING - Not Found: /
2020-04-10 Fri 23:24:07 log.py log_response 228 - WARNING - Not Found: /
2020-04-10 Fri 23:37:46 threadpool.py __init__ 52 - INFO - Started thread pool with 0 core threads and 20 maximum threads
2020-04-10 Fri 23:37:46 scheduler.py add_job 287 - INFO - Adding job tentatively -- it will be properly scheduled when the scheduler starts
2020-04-10 Fri 23:37:46 scheduler.py add_job 287 - INFO - Adding job tentatively -- it will be properly scheduled when the scheduler starts
2020-04-10 Fri 23:37:46 scheduler.py add_job 287 - INFO - Adding job tentatively -- it will be properly scheduled when the scheduler starts
2020-04-10 Fri 23:37:46 scheduler.py _real_add_job 262 - INFO - Added job "regulartime_task (trigger: interval[1 day, 0:00:00], next run at: 2020-04-10 23:37:56.685584)" to job store "default"
2020-04-10 Fri 23:37:46 scheduler.py _real_add_job 262 - INFO - Added job "cleanup (trigger: cron[day_of_week='*', hour='3', minute='0', second='0'], next run at: 2020-04-11 03:00:00)" to job store "default"
2020-04-10 Fri 23:37:46 scheduler.py _real_add_job 262 - INFO - Added job "OpenLog (trigger: cron[hour='0'], next run at: 2020-04-11 00:00:00)" to job store "default"
2020-04-10 Fri 23:37:46 scheduler.py _main_loop 574 - INFO - Scheduler started
2020-04-10 Fri 23:37:46 scheduler.py _main_loop 579 - DEBUG - Looking for jobs to run
2020-04-10 Fri 23:37:46 scheduler.py _main_loop 588 - DEBUG - Next wakeup is due at 2020-04-10 23:37:56.685584 (in 9.997709 seconds)
2020-04-10 Fri 23:37:46 query_views.py <module> 59 - DEBUG - SendBefore_NotRecive : [<CNCProcessStatus: CNCProcessStatus object (2038721)>]
2020-04-10 Fri 23:37:46 query_views.py <module> 60 - DEBUG - Waitfor_Recive : [2038721]
2020-04-10 Fri 23:38:12 threadpool.py __init__ 52 - INFO - Started thread pool with 0 core threads and 20 maximum threads
2020-04-10 Fri 23:38:12 scheduler.py add_job 287 - INFO - Adding job tentatively -- it will be properly scheduled when the scheduler starts
2020-04-10 Fri 23:38:12 scheduler.py add_job 287 - INFO - Adding job tentatively -- it will be properly scheduled when the scheduler starts
2020-04-10 Fri 23:38:12 scheduler.py add_job 287 - INFO - Adding job tentatively -- it will be properly scheduled when the scheduler starts
2020-04-10 Fri 23:38:12 scheduler.py _real_add_job 262 - INFO - Added job "regulartime_task (trigger: interval[1 day, 0:00:00], next run at: 2020-04-10 23:38:22.180082)" to job store "default"
2020-04-10 Fri 23:38:12 scheduler.py _real_add_job 262 - INFO - Added job "cleanup (trigger: cron[day_of_week='*', hour='3', minute='0', second='0'], next run at: 2020-04-11 03:00:00)" to job store "default"
2020-04-10 Fri 23:38:12 scheduler.py _real_add_job 262 - INFO - Added job "OpenLog (trigger: cron[hour='0'], next run at: 2020-04-11 00:00:00)" to job store "default"
2020-04-10 Fri 23:38:12 scheduler.py _main_loop 574 - INFO - Scheduler started
2020-04-10 Fri 23:38:12 scheduler.py _main_loop 579 - DEBUG - Looking for jobs to run
2020-04-10 Fri 23:38:12 scheduler.py _main_loop 588 - DEBUG - Next wakeup is due at 2020-04-10 23:38:22.180082 (in 9.997060 seconds)
2020-04-10 Fri 23:38:12 query_views.py <module> 59 - DEBUG - SendBefore_NotRecive : [<CNCProcessStatus: CNCProcessStatus object (2038721)>]
2020-04-10 Fri 23:38:12 query_views.py <module> 60 - DEBUG - Waitfor_Recive : [2038721]
2020-04-10 Fri 23:38:27 threadpool.py __init__ 52 - INFO - Started thread pool with 0 core threads and 20 maximum threads
2020-04-10 Fri 23:38:27 scheduler.py add_job 287 - INFO - Adding job tentatively -- it will be properly scheduled when the scheduler starts
2020-04-10 Fri 23:38:27 scheduler.py add_job 287 - INFO - Adding job tentatively -- it will be properly scheduled when the scheduler starts
2020-04-10 Fri 23:38:27 scheduler.py add_job 287 - INFO - Adding job tentatively -- it will be properly scheduled when the scheduler starts
2020-04-10 Fri 23:38:27 scheduler.py _real_add_job 262 - INFO - Added job "regulartime_task (trigger: interval[1 day, 0:00:00], next run at: 2020-04-10 23:38:37.009623)" to job store "default"
2020-04-10 Fri 23:38:27 scheduler.py _real_add_job 262 - INFO - Added job "cleanup (trigger: cron[day_of_week='*', hour='3', minute='0', second='0'], next run at: 2020-04-11 03:00:00)" to job store "default"
2020-04-10 Fri 23:38:27 scheduler.py _real_add_job 262 - INFO - Added job "OpenLog (trigger: cron[hour='0'], next run at: 2020-04-11 00:00:00)" to job store "default"
2020-04-10 Fri 23:38:27 scheduler.py _main_loop 574 - INFO - Scheduler started
2020-04-10 Fri 23:38:27 scheduler.py _main_loop 579 - DEBUG - Looking for jobs to run
2020-04-10 Fri 23:38:27 scheduler.py _main_loop 588 - DEBUG - Next wakeup is due at 2020-04-10 23:38:37.009623 (in 9.997008 seconds)
2020-04-10 Fri 23:38:27 query_views.py <module> 59 - DEBUG - SendBefore_NotRecive : [<CNCProcessStatus: CNCProcessStatus object (2038721)>]
2020-04-10 Fri 23:38:27 query_views.py <module> 60 - DEBUG - Waitfor_Recive : [2038721]
2020-04-10 Fri 23:38:37 scheduler.py _main_loop 579 - DEBUG - Looking for jobs to run
2020-04-10 Fri 23:38:37 threadpool.py _run_jobs 69 - DEBUG - Started worker thread
2020-04-10 Fri 23:38:37 scheduler.py _main_loop 588 - DEBUG - Next wakeup is due at 2020-04-11 00:00:00 (in 1282.988048 seconds)
2020-04-10 Fri 23:38:37 scheduler.py _run_job 509 - INFO - Running job "regulartime_task (trigger: interval[1 day, 0:00:00], next run at: 2020-04-11 23:38:37.009623)" (scheduled at 2020-04-10 23:38:37.009623)
2020-04-10 Fri 23:38:37 scheduler.py _run_job 520 - ERROR - Job "regulartime_task (trigger: interval[1 day, 0:00:00], next run at: 2020-04-11 23:38:37.009623)" raised an exception
Traceback (most recent call last):
  File "D:\Program Files\Python37\lib\site-packages\django\db\backends\utils.py", line 84, in _execute
    return self.cursor.execute(sql, params)
  File "D:\Program Files\Python37\lib\site-packages\django\db\backends\mysql\base.py", line 71, in execute
    return self.cursor.execute(query, args)
  File "D:\Program Files\Python37\lib\site-packages\MySQLdb\cursors.py", line 209, in execute
    res = self._query(query)
  File "D:\Program Files\Python37\lib\site-packages\MySQLdb\cursors.py", line 315, in _query
    db.query(q)
  File "D:\Program Files\Python37\lib\site-packages\MySQLdb\connections.py", line 239, in query
    _mysql.connection.query(self, query)
MySQLdb._exceptions.IntegrityError: (1062, "Duplicate entry '1586534400' for key 'LAMProcessData_process_r_acquisition_timestamp_a69ae90c_uniq'")

The above exception was the direct cause of the following exception:

Traceback (most recent call last):
  File "D:\Program Files\Python37\lib\site-packages\apscheduler\scheduler.py", line 512, in _run_job
    retval = job.func(*job.args, **job.kwargs)
  File "E:\1-program\11-LAMDataServer\lamdataserver\LAMProcessData\views.py", line 4818, in regulartime_task
    RT_FineData.Realtime_FineData.init_Tomorrow_rows()
  File "E:\1-program\11-LAMDataServer\lamdataserver\LAMProcessData\process_realtime_finedata.py", line 193, in init_Tomorrow_rows
    _model.objects.bulk_create(insert_data_list)
  File "D:\Program Files\Python37\lib\site-packages\django\db\models\manager.py", line 82, in manager_method
    return getattr(self.get_queryset(), name)(*args, **kwargs)
  File "D:\Program Files\Python37\lib\site-packages\django\db\models\query.py", line 474, in bulk_create
    ids = self._batched_insert(objs_without_pk, fields, batch_size, ignore_conflicts=ignore_conflicts)
  File "D:\Program Files\Python37\lib\site-packages\django\db\models\query.py", line 1211, in _batched_insert
    self._insert(item, fields=fields, using=self.db, ignore_conflicts=ignore_conflicts)
  File "D:\Program Files\Python37\lib\site-packages\django\db\models\query.py", line 1186, in _insert
    return query.get_compiler(using=using).execute_sql(return_id)
  File "D:\Program Files\Python37\lib\site-packages\django\db\models\sql\compiler.py", line 1332, in execute_sql
    cursor.execute(sql, params)
  File "D:\Program Files\Python37\lib\site-packages\django\db\backends\utils.py", line 99, in execute
    return super().execute(sql, params)
  File "D:\Program Files\Python37\lib\site-packages\django\db\backends\utils.py", line 67, in execute
    return self._execute_with_wrappers(sql, params, many=False, executor=self._execute)
  File "D:\Program Files\Python37\lib\site-packages\django\db\backends\utils.py", line 76, in _execute_with_wrappers
    return executor(sql, params, many, context)
  File "D:\Program Files\Python37\lib\site-packages\django\db\backends\utils.py", line 84, in _execute
    return self.cursor.execute(sql, params)
  File "D:\Program Files\Python37\lib\site-packages\django\db\utils.py", line 89, in __exit__
    raise dj_exc_value.with_traceback(traceback) from exc_value
  File "D:\Program Files\Python37\lib\site-packages\django\db\backends\utils.py", line 84, in _execute
    return self.cursor.execute(sql, params)
  File "D:\Program Files\Python37\lib\site-packages\django\db\backends\mysql\base.py", line 71, in execute
    return self.cursor.execute(query, args)
  File "D:\Program Files\Python37\lib\site-packages\MySQLdb\cursors.py", line 209, in execute
    res = self._query(query)
  File "D:\Program Files\Python37\lib\site-packages\MySQLdb\cursors.py", line 315, in _query
    db.query(q)
  File "D:\Program Files\Python37\lib\site-packages\MySQLdb\connections.py", line 239, in query
    _mysql.connection.query(self, query)
django.db.utils.IntegrityError: (1062, "Duplicate entry '1586534400' for key 'LAMProcessData_process_r_acquisition_timestamp_a69ae90c_uniq'")
2020-04-10 Fri 23:38:38 threadpool.py _run_jobs 94 - DEBUG - Exiting worker thread
2020-04-10 Fri 23:49:07 log.py log_response 228 - WARNING - Not Found: /favicon.ico
