2020-04-12 Sun 18:37:56 threadpool.py __init__ 52 - INFO - Started thread pool with 0 core threads and 20 maximum threads
2020-04-12 Sun 18:37:56 scheduler.py add_job 287 - INFO - Adding job tentatively -- it will be properly scheduled when the scheduler starts
2020-04-12 Sun 18:37:56 scheduler.py add_job 287 - INFO - Adding job tentatively -- it will be properly scheduled when the scheduler starts
2020-04-12 Sun 18:37:56 scheduler.py add_job 287 - INFO - Adding job tentatively -- it will be properly scheduled when the scheduler starts
2020-04-12 Sun 18:37:56 scheduler.py _real_add_job 262 - INFO - Added job "regulartime_task (trigger: interval[1 day, 0:00:00], next run at: 2020-04-12 18:38:06.512336)" to job store "default"
2020-04-12 Sun 18:37:56 scheduler.py _real_add_job 262 - INFO - Added job "cleanup (trigger: cron[day_of_week='*', hour='3', minute='0', second='0'], next run at: 2020-04-13 03:00:00)" to job store "default"
2020-04-12 Sun 18:37:56 scheduler.py _real_add_job 262 - INFO - Added job "OpenLog (trigger: cron[hour='0'], next run at: 2020-04-13 00:00:00)" to job store "default"
2020-04-12 Sun 18:37:56 scheduler.py _main_loop 574 - INFO - Scheduler started
2020-04-12 Sun 18:37:56 scheduler.py _main_loop 579 - DEBUG - Looking for jobs to run
2020-04-12 Sun 18:37:56 scheduler.py _main_loop 588 - DEBUG - Next wakeup is due at 2020-04-12 18:38:06.512336 (in 9.997520 seconds)
2020-04-12 Sun 18:37:56 query_views.py <module> 59 - DEBUG - SendBefore_NotRecive : [<CNCProcessStatus: CNCProcessStatus object (2038721)>]
2020-04-12 Sun 18:37:56 query_views.py <module> 60 - DEBUG - Waitfor_Recive : [2038721]
2020-04-12 Sun 23:43:36 threadpool.py __init__ 52 - INFO - Started thread pool with 0 core threads and 20 maximum threads
2020-04-12 Sun 23:43:36 scheduler.py add_job 287 - INFO - Adding job tentatively -- it will be properly scheduled when the scheduler starts
2020-04-12 Sun 23:43:36 scheduler.py add_job 287 - INFO - Adding job tentatively -- it will be properly scheduled when the scheduler starts
2020-04-12 Sun 23:43:36 scheduler.py add_job 287 - INFO - Adding job tentatively -- it will be properly scheduled when the scheduler starts
2020-04-12 Sun 23:43:36 scheduler.py _real_add_job 262 - INFO - Added job "regulartime_task (trigger: interval[1 day, 0:00:00], next run at: 2020-04-12 23:43:46.044785)" to job store "default"
2020-04-12 Sun 23:43:36 scheduler.py _real_add_job 262 - INFO - Added job "cleanup (trigger: cron[day_of_week='*', hour='3', minute='0', second='0'], next run at: 2020-04-13 03:00:00)" to job store "default"
2020-04-12 Sun 23:43:36 scheduler.py _real_add_job 262 - INFO - Added job "OpenLog (trigger: cron[hour='0'], next run at: 2020-04-13 00:00:00)" to job store "default"
2020-04-12 Sun 23:43:36 scheduler.py _main_loop 574 - INFO - Scheduler started
2020-04-12 Sun 23:43:36 scheduler.py _main_loop 579 - DEBUG - Looking for jobs to run
2020-04-12 Sun 23:43:36 scheduler.py _main_loop 588 - DEBUG - Next wakeup is due at 2020-04-12 23:43:46.044785 (in 9.997048 seconds)
2020-04-12 Sun 23:43:36 query_views.py <module> 59 - DEBUG - SendBefore_NotRecive : [<CNCProcessStatus: CNCProcessStatus object (2038721)>]
2020-04-12 Sun 23:43:36 query_views.py <module> 60 - DEBUG - Waitfor_Recive : [2038721]
2020-04-12 Sun 23:43:39 log.py log_response 228 - WARNING - Not Found: /
2020-04-12 Sun 23:43:46 scheduler.py _main_loop 579 - DEBUG - Looking for jobs to run
2020-04-12 Sun 23:43:46 threadpool.py _run_jobs 69 - DEBUG - Started worker thread
2020-04-12 Sun 23:43:46 scheduler.py _run_job 509 - INFO - Running job "regulartime_task (trigger: interval[1 day, 0:00:00], next run at: 2020-04-12 23:43:46.044785)" (scheduled at 2020-04-12 23:43:46.044785)
2020-04-12 Sun 23:43:46 scheduler.py _main_loop 588 - DEBUG - Next wakeup is due at 2020-04-13 00:00:00 (in 973.953793 seconds)
2020-04-12 Sun 23:43:46 log.py log_response 228 - WARNING - Not Found: /favicon.ico
2020-04-12 Sun 23:43:46 log.py log_response 228 - WARNING - Not Found: /favicon.ico
2020-04-12 Sun 23:43:46 scheduler.py _run_job 520 - ERROR - Job "regulartime_task (trigger: interval[1 day, 0:00:00], next run at: 2020-04-13 23:43:46.044785)" raised an exception
Traceback (most recent call last):
  File "D:\Program Files\Python37\lib\site-packages\django\db\backends\mysql\base.py", line 71, in execute
    return self.cursor.execute(query, args)
  File "D:\Program Files\Python37\lib\site-packages\MySQLdb\cursors.py", line 209, in execute
    res = self._query(query)
  File "D:\Program Files\Python37\lib\site-packages\MySQLdb\cursors.py", line 315, in _query
    db.query(q)
  File "D:\Program Files\Python37\lib\site-packages\MySQLdb\connections.py", line 239, in query
    _mysql.connection.query(self, query)
MySQLdb._exceptions.OperationalError: (1048, "Column 'laser_power' cannot be null")

During handling of the above exception, another exception occurred:

Traceback (most recent call last):
  File "D:\Program Files\Python37\lib\site-packages\apscheduler\scheduler.py", line 512, in _run_job
    retval = job.func(*job.args, **job.kwargs)
  File "E:\1-program\11-LAMDataServer\lamdataserver\LAMProcessData\views.py", line 4818, in regulartime_task
    RT_FineData.Realtime_FineData.init_Tomorrow_rows()
  File "E:\1-program\11-LAMDataServer\lamdataserver\LAMProcessData\process_realtime_finedata.py", line 193, in init_Tomorrow_rows
    _model.objects.bulk_create(insert_data_list)
  File "D:\Program Files\Python37\lib\site-packages\django\db\models\manager.py", line 82, in manager_method
    return getattr(self.get_queryset(), name)(*args, **kwargs)
  File "D:\Program Files\Python37\lib\site-packages\django\db\models\query.py", line 474, in bulk_create
    ids = self._batched_insert(objs_without_pk, fields, batch_size, ignore_conflicts=ignore_conflicts)
  File "D:\Program Files\Python37\lib\site-packages\django\db\models\query.py", line 1211, in _batched_insert
    self._insert(item, fields=fields, using=self.db, ignore_conflicts=ignore_conflicts)
  File "D:\Program Files\Python37\lib\site-packages\django\db\models\query.py", line 1186, in _insert
    return query.get_compiler(using=using).execute_sql(return_id)
  File "D:\Program Files\Python37\lib\site-packages\django\db\models\sql\compiler.py", line 1332, in execute_sql
    cursor.execute(sql, params)
  File "D:\Program Files\Python37\lib\site-packages\django\db\backends\utils.py", line 99, in execute
    return super().execute(sql, params)
  File "D:\Program Files\Python37\lib\site-packages\django\db\backends\utils.py", line 67, in execute
    return self._execute_with_wrappers(sql, params, many=False, executor=self._execute)
  File "D:\Program Files\Python37\lib\site-packages\django\db\backends\utils.py", line 76, in _execute_with_wrappers
    return executor(sql, params, many, context)
  File "D:\Program Files\Python37\lib\site-packages\django\db\backends\utils.py", line 84, in _execute
    return self.cursor.execute(sql, params)
  File "D:\Program Files\Python37\lib\site-packages\django\db\backends\mysql\base.py", line 76, in execute
    raise utils.IntegrityError(*tuple(e.args))
django.db.utils.IntegrityError: (1048, "Column 'laser_power' cannot be null")
2020-04-12 Sun 23:43:47 threadpool.py _run_jobs 94 - DEBUG - Exiting worker thread
