2020-04-13 Mon 00:17:46 threadpool.py __init__ 52 - INFO - Started thread pool with 0 core threads and 20 maximum threads
2020-04-13 Mon 00:17:46 scheduler.py add_job 287 - INFO - Adding job tentatively -- it will be properly scheduled when the scheduler starts
2020-04-13 Mon 00:17:46 scheduler.py add_job 287 - INFO - Adding job tentatively -- it will be properly scheduled when the scheduler starts
2020-04-13 Mon 00:17:46 scheduler.py add_job 287 - INFO - Adding job tentatively -- it will be properly scheduled when the scheduler starts
2020-04-13 Mon 00:17:46 scheduler.py _real_add_job 262 - INFO - Added job "regulartime_task (trigger: interval[1 day, 0:00:00], next run at: 2020-04-13 00:17:56.231433)" to job store "default"
2020-04-13 Mon 00:17:46 scheduler.py _real_add_job 262 - INFO - Added job "cleanup (trigger: cron[day_of_week='*', hour='3', minute='0', second='0'], next run at: 2020-04-13 03:00:00)" to job store "default"
2020-04-13 Mon 00:17:46 scheduler.py _real_add_job 262 - INFO - Added job "OpenLog (trigger: cron[hour='0'], next run at: 2020-04-14 00:00:00)" to job store "default"
2020-04-13 Mon 00:17:46 scheduler.py _main_loop 574 - INFO - Scheduler started
2020-04-13 Mon 00:17:46 scheduler.py _main_loop 579 - DEBUG - Looking for jobs to run
2020-04-13 Mon 00:17:46 scheduler.py _main_loop 588 - DEBUG - Next wakeup is due at 2020-04-13 00:17:56.231433 (in 9.984079 seconds)
2020-04-13 Mon 00:17:46 query_views.py <module> 60 - DEBUG - SendBefore_NotRecive : [<CNCProcessStatus: CNCProcessStatus object (2038721)>]
2020-04-13 Mon 00:17:46 query_views.py <module> 61 - DEBUG - Waitfor_Recive : [2038721]
2020-04-13 Mon 00:18:04 threadpool.py __init__ 52 - INFO - Started thread pool with 0 core threads and 20 maximum threads
2020-04-13 Mon 00:18:04 scheduler.py add_job 287 - INFO - Adding job tentatively -- it will be properly scheduled when the scheduler starts
2020-04-13 Mon 00:18:04 scheduler.py add_job 287 - INFO - Adding job tentatively -- it will be properly scheduled when the scheduler starts
2020-04-13 Mon 00:18:04 scheduler.py add_job 287 - INFO - Adding job tentatively -- it will be properly scheduled when the scheduler starts
2020-04-13 Mon 00:18:04 scheduler.py _real_add_job 262 - INFO - Added job "regulartime_task (trigger: interval[1 day, 0:00:00], next run at: 2020-04-13 00:18:14.549894)" to job store "default"
2020-04-13 Mon 00:18:04 scheduler.py _real_add_job 262 - INFO - Added job "cleanup (trigger: cron[day_of_week='*', hour='3', minute='0', second='0'], next run at: 2020-04-13 03:00:00)" to job store "default"
2020-04-13 Mon 00:18:04 scheduler.py _real_add_job 262 - INFO - Added job "OpenLog (trigger: cron[hour='0'], next run at: 2020-04-14 00:00:00)" to job store "default"
2020-04-13 Mon 00:18:04 scheduler.py _main_loop 574 - INFO - Scheduler started
2020-04-13 Mon 00:18:04 scheduler.py _main_loop 579 - DEBUG - Looking for jobs to run
2020-04-13 Mon 00:18:04 scheduler.py _main_loop 588 - DEBUG - Next wakeup is due at 2020-04-13 00:18:14.549894 (in 9.984396 seconds)
2020-04-13 Mon 00:18:04 query_views.py <module> 60 - DEBUG - SendBefore_NotRecive : [<CNCProcessStatus: CNCProcessStatus object (2038721)>]
2020-04-13 Mon 00:18:04 query_views.py <module> 61 - DEBUG - Waitfor_Recive : [2038721]
2020-04-13 Mon 00:18:13 log.py log_response 228 - WARNING - Not Found: /
2020-04-13 Mon 00:18:14 scheduler.py _main_loop 579 - DEBUG - Looking for jobs to run
2020-04-13 Mon 00:18:14 threadpool.py _run_jobs 69 - DEBUG - Started worker thread
2020-04-13 Mon 00:18:14 scheduler.py _main_loop 588 - DEBUG - Next wakeup is due at 2020-04-13 03:00:00 (in 9705.438979 seconds)
2020-04-13 Mon 00:18:14 scheduler.py _run_job 509 - INFO - Running job "regulartime_task (trigger: interval[1 day, 0:00:00], next run at: 2020-04-14 00:18:14.549894)" (scheduled at 2020-04-13 00:18:14.549894)
2020-04-13 Mon 00:18:16 scheduler.py _run_job 520 - ERROR - Job "regulartime_task (trigger: interval[1 day, 0:00:00], next run at: 2020-04-14 00:18:14.549894)" raised an exception
Traceback (most recent call last):
  File "D:\Program Files\Python37\lib\site-packages\django\db\backends\mysql\base.py", line 71, in execute
    return self.cursor.execute(query, args)
  File "D:\Program Files\Python37\lib\site-packages\MySQLdb\cursors.py", line 209, in execute
    res = self._query(query)
  File "D:\Program Files\Python37\lib\site-packages\MySQLdb\cursors.py", line 315, in _query
    db.query(q)
  File "D:\Program Files\Python37\lib\site-packages\MySQLdb\connections.py", line 239, in query
    _mysql.connection.query(self, query)
MySQLdb._exceptions.OperationalError: (1048, "Column 'laser_power' cannot be null")

During handling of the above exception, another exception occurred:

Traceback (most recent call last):
  File "D:\Program Files\Python37\lib\site-packages\apscheduler\scheduler.py", line 512, in _run_job
    retval = job.func(*job.args, **job.kwargs)
  File "E:\1-program\11-LAMDataServer\lamdataserver\LAMProcessData\views.py", line 4818, in regulartime_task
    RT_FineData.Realtime_FineData.init_Tomorrow_rows()
  File "E:\1-program\11-LAMDataServer\lamdataserver\LAMProcessData\process_realtime_finedata.py", line 193, in init_Tomorrow_rows
    _model.objects.bulk_create(insert_data_list)
  File "D:\Program Files\Python37\lib\site-packages\django\db\models\manager.py", line 82, in manager_method
    return getattr(self.get_queryset(), name)(*args, **kwargs)
  File "D:\Program Files\Python37\lib\site-packages\django\db\models\query.py", line 474, in bulk_create
    ids = self._batched_insert(objs_without_pk, fields, batch_size, ignore_conflicts=ignore_conflicts)
  File "D:\Program Files\Python37\lib\site-packages\django\db\models\query.py", line 1211, in _batched_insert
    self._insert(item, fields=fields, using=self.db, ignore_conflicts=ignore_conflicts)
  File "D:\Program Files\Python37\lib\site-packages\django\db\models\query.py", line 1186, in _insert
    return query.get_compiler(using=using).execute_sql(return_id)
  File "D:\Program Files\Python37\lib\site-packages\django\db\models\sql\compiler.py", line 1332, in execute_sql
    cursor.execute(sql, params)
  File "D:\Program Files\Python37\lib\site-packages\django\db\backends\utils.py", line 99, in execute
    return super().execute(sql, params)
  File "D:\Program Files\Python37\lib\site-packages\django\db\backends\utils.py", line 67, in execute
    return self._execute_with_wrappers(sql, params, many=False, executor=self._execute)
  File "D:\Program Files\Python37\lib\site-packages\django\db\backends\utils.py", line 76, in _execute_with_wrappers
    return executor(sql, params, many, context)
  File "D:\Program Files\Python37\lib\site-packages\django\db\backends\utils.py", line 84, in _execute
    return self.cursor.execute(sql, params)
  File "D:\Program Files\Python37\lib\site-packages\django\db\backends\mysql\base.py", line 76, in execute
    raise utils.IntegrityError(*tuple(e.args))
django.db.utils.IntegrityError: (1048, "Column 'laser_power' cannot be null")
2020-04-13 Mon 00:18:17 log.py log_response 228 - WARNING - Not Found: /favicon.ico
2020-04-13 Mon 00:18:17 threadpool.py _run_jobs 94 - DEBUG - Exiting worker thread
2020-04-13 Mon 00:18:17 log.py log_response 228 - WARNING - Not Found: /favicon.ico
2020-04-13 Mon 00:18:18 log.py log_response 228 - WARNING - Not Found: /favicon.ico
2020-04-13 Mon 00:18:19 log.py log_response 228 - WARNING - Not Found: /favicon.ico
2020-04-13 Mon 00:18:37 threadpool.py __init__ 52 - INFO - Started thread pool with 0 core threads and 20 maximum threads
2020-04-13 Mon 00:18:37 scheduler.py add_job 287 - INFO - Adding job tentatively -- it will be properly scheduled when the scheduler starts
2020-04-13 Mon 00:18:37 scheduler.py add_job 287 - INFO - Adding job tentatively -- it will be properly scheduled when the scheduler starts
2020-04-13 Mon 00:18:37 scheduler.py add_job 287 - INFO - Adding job tentatively -- it will be properly scheduled when the scheduler starts
2020-04-13 Mon 00:18:37 scheduler.py _real_add_job 262 - INFO - Added job "regulartime_task (trigger: interval[1 day, 0:00:00], next run at: 2020-04-13 00:18:47.800215)" to job store "default"
2020-04-13 Mon 00:18:37 scheduler.py _real_add_job 262 - INFO - Added job "cleanup (trigger: cron[day_of_week='*', hour='3', minute='0', second='0'], next run at: 2020-04-13 03:00:00)" to job store "default"
2020-04-13 Mon 00:18:37 scheduler.py _real_add_job 262 - INFO - Added job "OpenLog (trigger: cron[hour='0'], next run at: 2020-04-14 00:00:00)" to job store "default"
2020-04-13 Mon 00:18:37 scheduler.py _main_loop 574 - INFO - Scheduler started
2020-04-13 Mon 00:18:37 scheduler.py _main_loop 579 - DEBUG - Looking for jobs to run
2020-04-13 Mon 00:18:37 scheduler.py _main_loop 588 - DEBUG - Next wakeup is due at 2020-04-13 00:18:47.800215 (in 9.996404 seconds)
2020-04-13 Mon 00:18:37 query_views.py <module> 60 - DEBUG - SendBefore_NotRecive : [<CNCProcessStatus: CNCProcessStatus object (2038721)>]
2020-04-13 Mon 00:18:37 query_views.py <module> 61 - DEBUG - Waitfor_Recive : [2038721]
2020-04-13 Mon 00:18:47 scheduler.py _main_loop 579 - DEBUG - Looking for jobs to run
2020-04-13 Mon 00:18:47 threadpool.py _run_jobs 69 - DEBUG - Started worker thread
2020-04-13 Mon 00:18:47 scheduler.py _run_job 509 - INFO - Running job "regulartime_task (trigger: interval[1 day, 0:00:00], next run at: 2020-04-13 00:18:47.800215)" (scheduled at 2020-04-13 00:18:47.800215)
2020-04-13 Mon 00:18:47 scheduler.py _main_loop 588 - DEBUG - Next wakeup is due at 2020-04-13 03:00:00 (in 9672.197965 seconds)
2020-04-13 Mon 00:18:48 scheduler.py _run_job 520 - ERROR - Job "regulartime_task (trigger: interval[1 day, 0:00:00], next run at: 2020-04-14 00:18:47.800215)" raised an exception
Traceback (most recent call last):
  File "D:\Program Files\Python37\lib\site-packages\django\db\backends\utils.py", line 84, in _execute
    return self.cursor.execute(sql, params)
  File "D:\Program Files\Python37\lib\site-packages\django\db\backends\mysql\base.py", line 71, in execute
    return self.cursor.execute(query, args)
  File "D:\Program Files\Python37\lib\site-packages\MySQLdb\cursors.py", line 209, in execute
    res = self._query(query)
  File "D:\Program Files\Python37\lib\site-packages\MySQLdb\cursors.py", line 315, in _query
    db.query(q)
  File "D:\Program Files\Python37\lib\site-packages\MySQLdb\connections.py", line 239, in query
    _mysql.connection.query(self, query)
MySQLdb._exceptions.IntegrityError: (1062, "Duplicate entry '1586793600' for key 'LAMProcessData_process_r_acquisition_timestamp_a69ae90c_uniq'")

The above exception was the direct cause of the following exception:

Traceback (most recent call last):
  File "D:\Program Files\Python37\lib\site-packages\apscheduler\scheduler.py", line 512, in _run_job
    retval = job.func(*job.args, **job.kwargs)
  File "E:\1-program\11-LAMDataServer\lamdataserver\LAMProcessData\views.py", line 4818, in regulartime_task
    RT_FineData.Realtime_FineData.init_Tomorrow_rows()
  File "E:\1-program\11-LAMDataServer\lamdataserver\LAMProcessData\process_realtime_finedata.py", line 193, in init_Tomorrow_rows
    _model.objects.bulk_create(insert_data_list)
  File "D:\Program Files\Python37\lib\site-packages\django\db\models\manager.py", line 82, in manager_method
    return getattr(self.get_queryset(), name)(*args, **kwargs)
  File "D:\Program Files\Python37\lib\site-packages\django\db\models\query.py", line 474, in bulk_create
    ids = self._batched_insert(objs_without_pk, fields, batch_size, ignore_conflicts=ignore_conflicts)
  File "D:\Program Files\Python37\lib\site-packages\django\db\models\query.py", line 1211, in _batched_insert
    self._insert(item, fields=fields, using=self.db, ignore_conflicts=ignore_conflicts)
  File "D:\Program Files\Python37\lib\site-packages\django\db\models\query.py", line 1186, in _insert
    return query.get_compiler(using=using).execute_sql(return_id)
  File "D:\Program Files\Python37\lib\site-packages\django\db\models\sql\compiler.py", line 1332, in execute_sql
    cursor.execute(sql, params)
  File "D:\Program Files\Python37\lib\site-packages\django\db\backends\utils.py", line 99, in execute
    return super().execute(sql, params)
  File "D:\Program Files\Python37\lib\site-packages\django\db\backends\utils.py", line 67, in execute
    return self._execute_with_wrappers(sql, params, many=False, executor=self._execute)
  File "D:\Program Files\Python37\lib\site-packages\django\db\backends\utils.py", line 76, in _execute_with_wrappers
    return executor(sql, params, many, context)
  File "D:\Program Files\Python37\lib\site-packages\django\db\backends\utils.py", line 84, in _execute
    return self.cursor.execute(sql, params)
  File "D:\Program Files\Python37\lib\site-packages\django\db\utils.py", line 89, in __exit__
    raise dj_exc_value.with_traceback(traceback) from exc_value
  File "D:\Program Files\Python37\lib\site-packages\django\db\backends\utils.py", line 84, in _execute
    return self.cursor.execute(sql, params)
  File "D:\Program Files\Python37\lib\site-packages\django\db\backends\mysql\base.py", line 71, in execute
    return self.cursor.execute(query, args)
  File "D:\Program Files\Python37\lib\site-packages\MySQLdb\cursors.py", line 209, in execute
    res = self._query(query)
  File "D:\Program Files\Python37\lib\site-packages\MySQLdb\cursors.py", line 315, in _query
    db.query(q)
  File "D:\Program Files\Python37\lib\site-packages\MySQLdb\connections.py", line 239, in query
    _mysql.connection.query(self, query)
django.db.utils.IntegrityError: (1062, "Duplicate entry '1586793600' for key 'LAMProcessData_process_r_acquisition_timestamp_a69ae90c_uniq'")
2020-04-13 Mon 00:18:49 threadpool.py _run_jobs 94 - DEBUG - Exiting worker thread
2020-04-13 Mon 00:24:13 threadpool.py __init__ 52 - INFO - Started thread pool with 0 core threads and 20 maximum threads
2020-04-13 Mon 00:24:13 scheduler.py add_job 287 - INFO - Adding job tentatively -- it will be properly scheduled when the scheduler starts
2020-04-13 Mon 00:24:13 scheduler.py add_job 287 - INFO - Adding job tentatively -- it will be properly scheduled when the scheduler starts
2020-04-13 Mon 00:24:13 scheduler.py add_job 287 - INFO - Adding job tentatively -- it will be properly scheduled when the scheduler starts
2020-04-13 Mon 00:24:13 scheduler.py _real_add_job 262 - INFO - Added job "regulartime_task (trigger: interval[1 day, 0:00:00], next run at: 2020-04-13 00:24:23.948130)" to job store "default"
2020-04-13 Mon 00:24:13 scheduler.py _real_add_job 262 - INFO - Added job "cleanup (trigger: cron[day_of_week='*', hour='3', minute='0', second='0'], next run at: 2020-04-13 03:00:00)" to job store "default"
2020-04-13 Mon 00:24:13 scheduler.py _real_add_job 262 - INFO - Added job "OpenLog (trigger: cron[hour='0'], next run at: 2020-04-14 00:00:00)" to job store "default"
2020-04-13 Mon 00:24:13 scheduler.py _main_loop 574 - INFO - Scheduler started
2020-04-13 Mon 00:24:13 scheduler.py _main_loop 579 - DEBUG - Looking for jobs to run
2020-04-13 Mon 00:24:13 scheduler.py _main_loop 588 - DEBUG - Next wakeup is due at 2020-04-13 00:24:23.948130 (in 10.000000 seconds)
2020-04-13 Mon 00:24:13 query_views.py <module> 59 - DEBUG - SendBefore_NotRecive : [<CNCProcessStatus: CNCProcessStatus object (2038721)>]
2020-04-13 Mon 00:24:13 query_views.py <module> 60 - DEBUG - Waitfor_Recive : [2038721]
2020-04-13 Mon 00:24:23 scheduler.py _main_loop 579 - DEBUG - Looking for jobs to run
2020-04-13 Mon 00:24:23 threadpool.py _run_jobs 69 - DEBUG - Started worker thread
2020-04-13 Mon 00:24:23 scheduler.py _main_loop 588 - DEBUG - Next wakeup is due at 2020-04-13 03:00:00 (in 9336.051509 seconds)
2020-04-13 Mon 00:24:23 scheduler.py _run_job 509 - INFO - Running job "regulartime_task (trigger: interval[1 day, 0:00:00], next run at: 2020-04-14 00:24:23.948130)" (scheduled at 2020-04-13 00:24:23.948130)
2020-04-13 Mon 00:24:24 scheduler.py _run_job 520 - ERROR - Job "regulartime_task (trigger: interval[1 day, 0:00:00], next run at: 2020-04-14 00:24:23.948130)" raised an exception
Traceback (most recent call last):
  File "D:\Program Files\Python37\lib\site-packages\django\db\backends\utils.py", line 84, in _execute
    return self.cursor.execute(sql, params)
  File "D:\Program Files\Python37\lib\site-packages\django\db\backends\mysql\base.py", line 71, in execute
    return self.cursor.execute(query, args)
  File "D:\Program Files\Python37\lib\site-packages\MySQLdb\cursors.py", line 209, in execute
    res = self._query(query)
  File "D:\Program Files\Python37\lib\site-packages\MySQLdb\cursors.py", line 315, in _query
    db.query(q)
  File "D:\Program Files\Python37\lib\site-packages\MySQLdb\connections.py", line 239, in query
    _mysql.connection.query(self, query)
MySQLdb._exceptions.IntegrityError: (1062, "Duplicate entry '1586793600' for key 'LAMProcessData_process_r_acquisition_timestamp_a69ae90c_uniq'")

The above exception was the direct cause of the following exception:

Traceback (most recent call last):
  File "D:\Program Files\Python37\lib\site-packages\apscheduler\scheduler.py", line 512, in _run_job
    retval = job.func(*job.args, **job.kwargs)
  File "E:\1-program\11-LAMDataServer\lamdataserver\LAMProcessData\views.py", line 4818, in regulartime_task
    RT_FineData.Realtime_FineData.init_Tomorrow_rows()
  File "E:\1-program\11-LAMDataServer\lamdataserver\LAMProcessData\process_realtime_finedata.py", line 193, in init_Tomorrow_rows
    _model.objects.bulk_create(insert_data_list)
  File "D:\Program Files\Python37\lib\site-packages\django\db\models\manager.py", line 82, in manager_method
    return getattr(self.get_queryset(), name)(*args, **kwargs)
  File "D:\Program Files\Python37\lib\site-packages\django\db\models\query.py", line 474, in bulk_create
    ids = self._batched_insert(objs_without_pk, fields, batch_size, ignore_conflicts=ignore_conflicts)
  File "D:\Program Files\Python37\lib\site-packages\django\db\models\query.py", line 1211, in _batched_insert
    self._insert(item, fields=fields, using=self.db, ignore_conflicts=ignore_conflicts)
  File "D:\Program Files\Python37\lib\site-packages\django\db\models\query.py", line 1186, in _insert
    return query.get_compiler(using=using).execute_sql(return_id)
  File "D:\Program Files\Python37\lib\site-packages\django\db\models\sql\compiler.py", line 1332, in execute_sql
    cursor.execute(sql, params)
  File "D:\Program Files\Python37\lib\site-packages\django\db\backends\utils.py", line 99, in execute
    return super().execute(sql, params)
  File "D:\Program Files\Python37\lib\site-packages\django\db\backends\utils.py", line 67, in execute
    return self._execute_with_wrappers(sql, params, many=False, executor=self._execute)
  File "D:\Program Files\Python37\lib\site-packages\django\db\backends\utils.py", line 76, in _execute_with_wrappers
    return executor(sql, params, many, context)
  File "D:\Program Files\Python37\lib\site-packages\django\db\backends\utils.py", line 84, in _execute
    return self.cursor.execute(sql, params)
  File "D:\Program Files\Python37\lib\site-packages\django\db\utils.py", line 89, in __exit__
    raise dj_exc_value.with_traceback(traceback) from exc_value
  File "D:\Program Files\Python37\lib\site-packages\django\db\backends\utils.py", line 84, in _execute
    return self.cursor.execute(sql, params)
  File "D:\Program Files\Python37\lib\site-packages\django\db\backends\mysql\base.py", line 71, in execute
    return self.cursor.execute(query, args)
  File "D:\Program Files\Python37\lib\site-packages\MySQLdb\cursors.py", line 209, in execute
    res = self._query(query)
  File "D:\Program Files\Python37\lib\site-packages\MySQLdb\cursors.py", line 315, in _query
    db.query(q)
  File "D:\Program Files\Python37\lib\site-packages\MySQLdb\connections.py", line 239, in query
    _mysql.connection.query(self, query)
django.db.utils.IntegrityError: (1062, "Duplicate entry '1586793600' for key 'LAMProcessData_process_r_acquisition_timestamp_a69ae90c_uniq'")
2020-04-13 Mon 00:24:25 threadpool.py _run_jobs 94 - DEBUG - Exiting worker thread
2020-04-13 Mon 00:29:23 threadpool.py __init__ 52 - INFO - Started thread pool with 0 core threads and 20 maximum threads
2020-04-13 Mon 00:29:23 scheduler.py add_job 287 - INFO - Adding job tentatively -- it will be properly scheduled when the scheduler starts
2020-04-13 Mon 00:29:23 scheduler.py add_job 287 - INFO - Adding job tentatively -- it will be properly scheduled when the scheduler starts
2020-04-13 Mon 00:29:23 scheduler.py add_job 287 - INFO - Adding job tentatively -- it will be properly scheduled when the scheduler starts
2020-04-13 Mon 00:29:23 scheduler.py _real_add_job 262 - INFO - Added job "regulartime_task (trigger: interval[1 day, 0:00:00], next run at: 2020-04-13 00:29:33.726818)" to job store "default"
2020-04-13 Mon 00:29:23 scheduler.py _real_add_job 262 - INFO - Added job "cleanup (trigger: cron[day_of_week='*', hour='3', minute='0', second='0'], next run at: 2020-04-13 03:00:00)" to job store "default"
2020-04-13 Mon 00:29:23 scheduler.py _real_add_job 262 - INFO - Added job "OpenLog (trigger: cron[hour='0'], next run at: 2020-04-14 00:00:00)" to job store "default"
2020-04-13 Mon 00:29:23 scheduler.py _main_loop 574 - INFO - Scheduler started
2020-04-13 Mon 00:29:23 scheduler.py _main_loop 579 - DEBUG - Looking for jobs to run
2020-04-13 Mon 00:29:23 scheduler.py _main_loop 588 - DEBUG - Next wakeup is due at 2020-04-13 00:29:33.726818 (in 9.997008 seconds)
2020-04-13 Mon 00:29:23 query_views.py <module> 59 - DEBUG - SendBefore_NotRecive : [<CNCProcessStatus: CNCProcessStatus object (2038721)>]
2020-04-13 Mon 00:29:23 query_views.py <module> 60 - DEBUG - Waitfor_Recive : [2038721]
2020-04-13 Mon 00:29:38 threadpool.py __init__ 52 - INFO - Started thread pool with 0 core threads and 20 maximum threads
2020-04-13 Mon 00:29:38 scheduler.py add_job 287 - INFO - Adding job tentatively -- it will be properly scheduled when the scheduler starts
2020-04-13 Mon 00:29:38 scheduler.py add_job 287 - INFO - Adding job tentatively -- it will be properly scheduled when the scheduler starts
2020-04-13 Mon 00:29:38 scheduler.py add_job 287 - INFO - Adding job tentatively -- it will be properly scheduled when the scheduler starts
2020-04-13 Mon 00:29:38 scheduler.py _real_add_job 262 - INFO - Added job "regulartime_task (trigger: interval[1 day, 0:00:00], next run at: 2020-04-13 00:29:48.396076)" to job store "default"
2020-04-13 Mon 00:29:38 scheduler.py _real_add_job 262 - INFO - Added job "cleanup (trigger: cron[day_of_week='*', hour='3', minute='0', second='0'], next run at: 2020-04-13 03:00:00)" to job store "default"
2020-04-13 Mon 00:29:38 scheduler.py _real_add_job 262 - INFO - Added job "OpenLog (trigger: cron[hour='0'], next run at: 2020-04-14 00:00:00)" to job store "default"
2020-04-13 Mon 00:29:38 scheduler.py _main_loop 574 - INFO - Scheduler started
2020-04-13 Mon 00:29:38 scheduler.py _main_loop 579 - DEBUG - Looking for jobs to run
2020-04-13 Mon 00:29:38 scheduler.py _main_loop 588 - DEBUG - Next wakeup is due at 2020-04-13 00:29:48.396076 (in 9.997038 seconds)
2020-04-13 Mon 00:29:38 query_views.py <module> 59 - DEBUG - SendBefore_NotRecive : [<CNCProcessStatus: CNCProcessStatus object (2038721)>]
2020-04-13 Mon 00:29:38 query_views.py <module> 60 - DEBUG - Waitfor_Recive : [2038721]
2020-04-13 Mon 00:30:04 threadpool.py __init__ 52 - INFO - Started thread pool with 0 core threads and 20 maximum threads
2020-04-13 Mon 00:30:04 scheduler.py add_job 287 - INFO - Adding job tentatively -- it will be properly scheduled when the scheduler starts
2020-04-13 Mon 00:30:04 scheduler.py add_job 287 - INFO - Adding job tentatively -- it will be properly scheduled when the scheduler starts
2020-04-13 Mon 00:30:04 scheduler.py add_job 287 - INFO - Adding job tentatively -- it will be properly scheduled when the scheduler starts
2020-04-13 Mon 00:30:04 scheduler.py _real_add_job 262 - INFO - Added job "regulartime_task (trigger: interval[1 day, 0:00:00], next run at: 2020-04-13 00:30:14.787482)" to job store "default"
2020-04-13 Mon 00:30:04 scheduler.py _real_add_job 262 - INFO - Added job "cleanup (trigger: cron[day_of_week='*', hour='3', minute='0', second='0'], next run at: 2020-04-13 03:00:00)" to job store "default"
2020-04-13 Mon 00:30:04 scheduler.py _real_add_job 262 - INFO - Added job "OpenLog (trigger: cron[hour='0'], next run at: 2020-04-14 00:00:00)" to job store "default"
2020-04-13 Mon 00:30:04 scheduler.py _main_loop 574 - INFO - Scheduler started
2020-04-13 Mon 00:30:04 scheduler.py _main_loop 579 - DEBUG - Looking for jobs to run
2020-04-13 Mon 00:30:04 scheduler.py _main_loop 588 - DEBUG - Next wakeup is due at 2020-04-13 00:30:14.787482 (in 9.997166 seconds)
2020-04-13 Mon 00:30:04 query_views.py <module> 59 - DEBUG - SendBefore_NotRecive : [<CNCProcessStatus: CNCProcessStatus object (2038721)>]
2020-04-13 Mon 00:30:04 query_views.py <module> 60 - DEBUG - Waitfor_Recive : [2038721]
2020-04-13 Mon 00:30:14 scheduler.py _main_loop 579 - DEBUG - Looking for jobs to run
2020-04-13 Mon 00:30:14 threadpool.py _run_jobs 69 - DEBUG - Started worker thread
2020-04-13 Mon 00:30:14 scheduler.py _run_job 509 - INFO - Running job "regulartime_task (trigger: interval[1 day, 0:00:00], next run at: 2020-04-13 00:30:14.787482)" (scheduled at 2020-04-13 00:30:14.787482)
2020-04-13 Mon 00:30:14 scheduler.py _main_loop 588 - DEBUG - Next wakeup is due at 2020-04-13 03:00:00 (in 8985.211209 seconds)
2020-04-13 Mon 00:30:15 scheduler.py _run_job 520 - ERROR - Job "regulartime_task (trigger: interval[1 day, 0:00:00], next run at: 2020-04-14 00:30:14.787482)" raised an exception
Traceback (most recent call last):
  File "D:\Program Files\Python37\lib\site-packages\django\db\backends\utils.py", line 84, in _execute
    return self.cursor.execute(sql, params)
  File "D:\Program Files\Python37\lib\site-packages\django\db\backends\mysql\base.py", line 71, in execute
    return self.cursor.execute(query, args)
  File "D:\Program Files\Python37\lib\site-packages\MySQLdb\cursors.py", line 209, in execute
    res = self._query(query)
  File "D:\Program Files\Python37\lib\site-packages\MySQLdb\cursors.py", line 315, in _query
    db.query(q)
  File "D:\Program Files\Python37\lib\site-packages\MySQLdb\connections.py", line 239, in query
    _mysql.connection.query(self, query)
MySQLdb._exceptions.IntegrityError: (1062, "Duplicate entry '1586793600' for key 'LAMProcessData_process_r_acquisition_timestamp_a69ae90c_uniq'")

The above exception was the direct cause of the following exception:

Traceback (most recent call last):
  File "D:\Program Files\Python37\lib\site-packages\apscheduler\scheduler.py", line 512, in _run_job
    retval = job.func(*job.args, **job.kwargs)
  File "E:\1-program\11-LAMDataServer\lamdataserver\LAMProcessData\views.py", line 4818, in regulartime_task
    RT_FineData.Realtime_FineData.init_Tomorrow_rows()
  File "E:\1-program\11-LAMDataServer\lamdataserver\LAMProcessData\process_realtime_finedata.py", line 193, in init_Tomorrow_rows
    _model.objects.bulk_create(insert_data_list)
  File "D:\Program Files\Python37\lib\site-packages\django\db\models\manager.py", line 82, in manager_method
    return getattr(self.get_queryset(), name)(*args, **kwargs)
  File "D:\Program Files\Python37\lib\site-packages\django\db\models\query.py", line 474, in bulk_create
    ids = self._batched_insert(objs_without_pk, fields, batch_size, ignore_conflicts=ignore_conflicts)
  File "D:\Program Files\Python37\lib\site-packages\django\db\models\query.py", line 1211, in _batched_insert
    self._insert(item, fields=fields, using=self.db, ignore_conflicts=ignore_conflicts)
  File "D:\Program Files\Python37\lib\site-packages\django\db\models\query.py", line 1186, in _insert
    return query.get_compiler(using=using).execute_sql(return_id)
  File "D:\Program Files\Python37\lib\site-packages\django\db\models\sql\compiler.py", line 1332, in execute_sql
    cursor.execute(sql, params)
  File "D:\Program Files\Python37\lib\site-packages\django\db\backends\utils.py", line 99, in execute
    return super().execute(sql, params)
  File "D:\Program Files\Python37\lib\site-packages\django\db\backends\utils.py", line 67, in execute
    return self._execute_with_wrappers(sql, params, many=False, executor=self._execute)
  File "D:\Program Files\Python37\lib\site-packages\django\db\backends\utils.py", line 76, in _execute_with_wrappers
    return executor(sql, params, many, context)
  File "D:\Program Files\Python37\lib\site-packages\django\db\backends\utils.py", line 84, in _execute
    return self.cursor.execute(sql, params)
  File "D:\Program Files\Python37\lib\site-packages\django\db\utils.py", line 89, in __exit__
    raise dj_exc_value.with_traceback(traceback) from exc_value
  File "D:\Program Files\Python37\lib\site-packages\django\db\backends\utils.py", line 84, in _execute
    return self.cursor.execute(sql, params)
  File "D:\Program Files\Python37\lib\site-packages\django\db\backends\mysql\base.py", line 71, in execute
    return self.cursor.execute(query, args)
  File "D:\Program Files\Python37\lib\site-packages\MySQLdb\cursors.py", line 209, in execute
    res = self._query(query)
  File "D:\Program Files\Python37\lib\site-packages\MySQLdb\cursors.py", line 315, in _query
    db.query(q)
  File "D:\Program Files\Python37\lib\site-packages\MySQLdb\connections.py", line 239, in query
    _mysql.connection.query(self, query)
django.db.utils.IntegrityError: (1062, "Duplicate entry '1586793600' for key 'LAMProcessData_process_r_acquisition_timestamp_a69ae90c_uniq'")
2020-04-13 Mon 00:30:16 threadpool.py _run_jobs 94 - DEBUG - Exiting worker thread
2020-04-13 Mon 00:48:40 threadpool.py __init__ 52 - INFO - Started thread pool with 0 core threads and 20 maximum threads
2020-04-13 Mon 00:48:40 scheduler.py add_job 287 - INFO - Adding job tentatively -- it will be properly scheduled when the scheduler starts
2020-04-13 Mon 00:48:40 scheduler.py add_job 287 - INFO - Adding job tentatively -- it will be properly scheduled when the scheduler starts
2020-04-13 Mon 00:48:40 scheduler.py add_job 287 - INFO - Adding job tentatively -- it will be properly scheduled when the scheduler starts
2020-04-13 Mon 00:48:40 scheduler.py _real_add_job 262 - INFO - Added job "regulartime_task (trigger: interval[1 day, 0:00:00], next run at: 2020-04-13 00:48:50.646088)" to job store "default"
2020-04-13 Mon 00:48:40 scheduler.py _real_add_job 262 - INFO - Added job "cleanup (trigger: cron[day_of_week='*', hour='3', minute='0', second='0'], next run at: 2020-04-13 03:00:00)" to job store "default"
2020-04-13 Mon 00:48:40 scheduler.py _real_add_job 262 - INFO - Added job "OpenLog (trigger: cron[hour='0'], next run at: 2020-04-14 00:00:00)" to job store "default"
2020-04-13 Mon 00:48:40 scheduler.py _main_loop 574 - INFO - Scheduler started
2020-04-13 Mon 00:48:40 scheduler.py _main_loop 579 - DEBUG - Looking for jobs to run
2020-04-13 Mon 00:48:40 scheduler.py _main_loop 588 - DEBUG - Next wakeup is due at 2020-04-13 00:48:50.646088 (in 9.998008 seconds)
2020-04-13 Mon 00:48:40 query_views.py <module> 59 - DEBUG - SendBefore_NotRecive : [<CNCProcessStatus: CNCProcessStatus object (2038721)>]
2020-04-13 Mon 00:48:40 query_views.py <module> 60 - DEBUG - Waitfor_Recive : [2038721]
2020-04-13 Mon 00:48:40 threadpool.py shutdown 111 - INFO - Shutting down thread pool
2020-04-13 Mon 00:48:59 threadpool.py __init__ 52 - INFO - Started thread pool with 0 core threads and 20 maximum threads
2020-04-13 Mon 00:48:59 scheduler.py add_job 287 - INFO - Adding job tentatively -- it will be properly scheduled when the scheduler starts
2020-04-13 Mon 00:48:59 scheduler.py add_job 287 - INFO - Adding job tentatively -- it will be properly scheduled when the scheduler starts
2020-04-13 Mon 00:48:59 scheduler.py add_job 287 - INFO - Adding job tentatively -- it will be properly scheduled when the scheduler starts
2020-04-13 Mon 00:48:59 scheduler.py _real_add_job 262 - INFO - Added job "regulartime_task (trigger: interval[1 day, 0:00:00], next run at: 2020-04-13 00:49:09.486816)" to job store "default"
2020-04-13 Mon 00:48:59 scheduler.py _real_add_job 262 - INFO - Added job "cleanup (trigger: cron[day_of_week='*', hour='3', minute='0', second='0'], next run at: 2020-04-13 03:00:00)" to job store "default"
2020-04-13 Mon 00:48:59 scheduler.py _real_add_job 262 - INFO - Added job "OpenLog (trigger: cron[hour='0'], next run at: 2020-04-14 00:00:00)" to job store "default"
2020-04-13 Mon 00:48:59 scheduler.py _main_loop 574 - INFO - Scheduler started
2020-04-13 Mon 00:48:59 scheduler.py _main_loop 579 - DEBUG - Looking for jobs to run
2020-04-13 Mon 00:48:59 scheduler.py _main_loop 588 - DEBUG - Next wakeup is due at 2020-04-13 00:49:09.486816 (in 9.996999 seconds)
2020-04-13 Mon 00:48:59 query_views.py <module> 59 - DEBUG - SendBefore_NotRecive : [<CNCProcessStatus: CNCProcessStatus object (2038721)>]
2020-04-13 Mon 00:48:59 query_views.py <module> 60 - DEBUG - Waitfor_Recive : [2038721]
2020-04-13 Mon 00:48:59 threadpool.py shutdown 111 - INFO - Shutting down thread pool
2020-04-13 Mon 00:49:19 threadpool.py __init__ 52 - INFO - Started thread pool with 0 core threads and 20 maximum threads
2020-04-13 Mon 00:49:19 scheduler.py add_job 287 - INFO - Adding job tentatively -- it will be properly scheduled when the scheduler starts
2020-04-13 Mon 00:49:19 scheduler.py add_job 287 - INFO - Adding job tentatively -- it will be properly scheduled when the scheduler starts
2020-04-13 Mon 00:49:19 scheduler.py add_job 287 - INFO - Adding job tentatively -- it will be properly scheduled when the scheduler starts
2020-04-13 Mon 00:49:19 scheduler.py _real_add_job 262 - INFO - Added job "regulartime_task (trigger: interval[1 day, 0:00:00], next run at: 2020-04-13 00:49:29.590842)" to job store "default"
2020-04-13 Mon 00:49:19 scheduler.py _real_add_job 262 - INFO - Added job "cleanup (trigger: cron[day_of_week='*', hour='3', minute='0', second='0'], next run at: 2020-04-13 03:00:00)" to job store "default"
2020-04-13 Mon 00:49:19 scheduler.py _real_add_job 262 - INFO - Added job "OpenLog (trigger: cron[hour='0'], next run at: 2020-04-14 00:00:00)" to job store "default"
2020-04-13 Mon 00:49:19 scheduler.py _main_loop 574 - INFO - Scheduler started
2020-04-13 Mon 00:49:19 scheduler.py _main_loop 579 - DEBUG - Looking for jobs to run
2020-04-13 Mon 00:49:19 scheduler.py _main_loop 588 - DEBUG - Next wakeup is due at 2020-04-13 00:49:29.590842 (in 9.998008 seconds)
2020-04-13 Mon 00:49:19 query_views.py <module> 59 - DEBUG - SendBefore_NotRecive : [<CNCProcessStatus: CNCProcessStatus object (2038721)>]
2020-04-13 Mon 00:49:19 query_views.py <module> 60 - DEBUG - Waitfor_Recive : [2038721]
2020-04-13 Mon 00:49:19 threadpool.py shutdown 111 - INFO - Shutting down thread pool
2020-04-13 Mon 00:49:56 threadpool.py __init__ 52 - INFO - Started thread pool with 0 core threads and 20 maximum threads
2020-04-13 Mon 00:49:56 scheduler.py add_job 287 - INFO - Adding job tentatively -- it will be properly scheduled when the scheduler starts
2020-04-13 Mon 00:49:56 scheduler.py add_job 287 - INFO - Adding job tentatively -- it will be properly scheduled when the scheduler starts
2020-04-13 Mon 00:49:56 scheduler.py add_job 287 - INFO - Adding job tentatively -- it will be properly scheduled when the scheduler starts
2020-04-13 Mon 00:49:56 scheduler.py _real_add_job 262 - INFO - Added job "regulartime_task (trigger: interval[1 day, 0:00:00], next run at: 2020-04-13 00:50:06.063437)" to job store "default"
2020-04-13 Mon 00:49:56 scheduler.py _real_add_job 262 - INFO - Added job "cleanup (trigger: cron[day_of_week='*', hour='3', minute='0', second='0'], next run at: 2020-04-13 03:00:00)" to job store "default"
2020-04-13 Mon 00:49:56 scheduler.py _real_add_job 262 - INFO - Added job "OpenLog (trigger: cron[hour='0'], next run at: 2020-04-14 00:00:00)" to job store "default"
2020-04-13 Mon 00:49:56 scheduler.py _main_loop 574 - INFO - Scheduler started
2020-04-13 Mon 00:49:56 scheduler.py _main_loop 579 - DEBUG - Looking for jobs to run
2020-04-13 Mon 00:49:56 scheduler.py _main_loop 588 - DEBUG - Next wakeup is due at 2020-04-13 00:50:06.063437 (in 9.997048 seconds)
2020-04-13 Mon 00:49:56 query_views.py <module> 59 - DEBUG - SendBefore_NotRecive : [<CNCProcessStatus: CNCProcessStatus object (2038721)>]
2020-04-13 Mon 00:49:56 query_views.py <module> 60 - DEBUG - Waitfor_Recive : [2038721]
2020-04-13 Mon 00:50:06 scheduler.py _main_loop 579 - DEBUG - Looking for jobs to run
2020-04-13 Mon 00:50:06 threadpool.py _run_jobs 69 - DEBUG - Started worker thread
2020-04-13 Mon 00:50:06 scheduler.py _run_job 509 - INFO - Running job "regulartime_task (trigger: interval[1 day, 0:00:00], next run at: 2020-04-13 00:50:06.063437)" (scheduled at 2020-04-13 00:50:06.063437)
2020-04-13 Mon 00:50:06 scheduler.py _main_loop 588 - DEBUG - Next wakeup is due at 2020-04-13 03:00:00 (in 7793.935109 seconds)
2020-04-13 Mon 00:50:06 scheduler.py _run_job 520 - ERROR - Job "regulartime_task (trigger: interval[1 day, 0:00:00], next run at: 2020-04-14 00:50:06.063437)" raised an exception
Traceback (most recent call last):
  File "D:\Program Files\Python37\lib\site-packages\django\db\backends\utils.py", line 84, in _execute
    return self.cursor.execute(sql, params)
  File "D:\Program Files\Python37\lib\site-packages\django\db\backends\mysql\base.py", line 71, in execute
    return self.cursor.execute(query, args)
  File "D:\Program Files\Python37\lib\site-packages\MySQLdb\cursors.py", line 209, in execute
    res = self._query(query)
  File "D:\Program Files\Python37\lib\site-packages\MySQLdb\cursors.py", line 315, in _query
    db.query(q)
  File "D:\Program Files\Python37\lib\site-packages\MySQLdb\connections.py", line 239, in query
    _mysql.connection.query(self, query)
MySQLdb._exceptions.IntegrityError: (1062, "Duplicate entry '1586793600' for key 'LAMProcessData_process_r_acquisition_timestamp_a69ae90c_uniq'")

The above exception was the direct cause of the following exception:

Traceback (most recent call last):
  File "D:\Program Files\Python37\lib\site-packages\apscheduler\scheduler.py", line 512, in _run_job
    retval = job.func(*job.args, **job.kwargs)
  File "E:\1-program\11-LAMDataServer\lamdataserver\LAMProcessData\views.py", line 4818, in regulartime_task
    RT_FineData.Realtime_FineData.init_Tomorrow_rows()
  File "E:\1-program\11-LAMDataServer\lamdataserver\LAMProcessData\process_realtime_finedata.py", line 193, in init_Tomorrow_rows
    _model.objects.bulk_create(insert_data_list)
  File "D:\Program Files\Python37\lib\site-packages\django\db\models\manager.py", line 82, in manager_method
    return getattr(self.get_queryset(), name)(*args, **kwargs)
  File "D:\Program Files\Python37\lib\site-packages\django\db\models\query.py", line 474, in bulk_create
    ids = self._batched_insert(objs_without_pk, fields, batch_size, ignore_conflicts=ignore_conflicts)
  File "D:\Program Files\Python37\lib\site-packages\django\db\models\query.py", line 1211, in _batched_insert
    self._insert(item, fields=fields, using=self.db, ignore_conflicts=ignore_conflicts)
  File "D:\Program Files\Python37\lib\site-packages\django\db\models\query.py", line 1186, in _insert
    return query.get_compiler(using=using).execute_sql(return_id)
  File "D:\Program Files\Python37\lib\site-packages\django\db\models\sql\compiler.py", line 1332, in execute_sql
    cursor.execute(sql, params)
  File "D:\Program Files\Python37\lib\site-packages\django\db\backends\utils.py", line 99, in execute
    return super().execute(sql, params)
  File "D:\Program Files\Python37\lib\site-packages\django\db\backends\utils.py", line 67, in execute
    return self._execute_with_wrappers(sql, params, many=False, executor=self._execute)
  File "D:\Program Files\Python37\lib\site-packages\django\db\backends\utils.py", line 76, in _execute_with_wrappers
    return executor(sql, params, many, context)
  File "D:\Program Files\Python37\lib\site-packages\django\db\backends\utils.py", line 84, in _execute
    return self.cursor.execute(sql, params)
  File "D:\Program Files\Python37\lib\site-packages\django\db\utils.py", line 89, in __exit__
    raise dj_exc_value.with_traceback(traceback) from exc_value
  File "D:\Program Files\Python37\lib\site-packages\django\db\backends\utils.py", line 84, in _execute
    return self.cursor.execute(sql, params)
  File "D:\Program Files\Python37\lib\site-packages\django\db\backends\mysql\base.py", line 71, in execute
    return self.cursor.execute(query, args)
  File "D:\Program Files\Python37\lib\site-packages\MySQLdb\cursors.py", line 209, in execute
    res = self._query(query)
  File "D:\Program Files\Python37\lib\site-packages\MySQLdb\cursors.py", line 315, in _query
    db.query(q)
  File "D:\Program Files\Python37\lib\site-packages\MySQLdb\connections.py", line 239, in query
    _mysql.connection.query(self, query)
django.db.utils.IntegrityError: (1062, "Duplicate entry '1586793600' for key 'LAMProcessData_process_r_acquisition_timestamp_a69ae90c_uniq'")
2020-04-13 Mon 00:50:07 threadpool.py _run_jobs 94 - DEBUG - Exiting worker thread
