2020-05-21 Thu 00:04:12 threadpool.py __init__ 52 - INFO - Started thread pool with 0 core threads and 20 maximum threads
2020-05-21 Thu 00:04:12 scheduler.py add_job 287 - INFO - Adding job tentatively -- it will be properly scheduled when the scheduler starts
2020-05-21 Thu 00:04:12 scheduler.py add_job 287 - INFO - Adding job tentatively -- it will be properly scheduled when the scheduler starts
2020-05-21 Thu 00:04:12 scheduler.py add_job 287 - INFO - Adding job tentatively -- it will be properly scheduled when the scheduler starts
2020-05-21 Thu 00:04:12 scheduler.py _real_add_job 262 - INFO - Added job "regulartime_task (trigger: interval[1 day, 0:00:00], next run at: 2020-05-21 00:04:22.047034)" to job store "default"
2020-05-21 Thu 00:04:12 scheduler.py _real_add_job 262 - INFO - Added job "cleanup (trigger: cron[day_of_week='*', hour='3', minute='0', second='0'], next run at: 2020-05-21 03:00:00)" to job store "default"
2020-05-21 Thu 00:04:12 scheduler.py _real_add_job 262 - INFO - Added job "OpenLog (trigger: cron[hour='0'], next run at: 2020-05-22 00:00:00)" to job store "default"
2020-05-21 Thu 00:04:12 scheduler.py _main_loop 574 - INFO - Scheduler started
2020-05-21 Thu 00:04:12 scheduler.py _main_loop 579 - DEBUG - Looking for jobs to run
2020-05-21 Thu 00:04:12 scheduler.py _main_loop 588 - DEBUG - Next wakeup is due at 2020-05-21 00:04:22.047034 (in 9.997025 seconds)
2020-05-21 Thu 00:04:12 query_views.py <module> 63 - DEBUG - SendBefore_NotRecive : [<CNCProcessStatus: CNCProcessStatus object (2038721)>]
2020-05-21 Thu 00:04:12 query_views.py <module> 64 - DEBUG - Waitfor_Recive : [2038721]
2020-05-21 Thu 00:04:22 scheduler.py _main_loop 579 - DEBUG - Looking for jobs to run
2020-05-21 Thu 00:04:22 threadpool.py _run_jobs 69 - DEBUG - Started worker thread
2020-05-21 Thu 00:04:22 scheduler.py _run_job 509 - INFO - Running job "regulartime_task (trigger: interval[1 day, 0:00:00], next run at: 2020-05-21 00:04:22.047034)" (scheduled at 2020-05-21 00:04:22.047034)
2020-05-21 Thu 00:04:22 scheduler.py _main_loop 588 - DEBUG - Next wakeup is due at 2020-05-21 03:00:00 (in 10537.951603 seconds)
2020-05-21 Thu 00:04:22 scheduler.py _run_job 520 - ERROR - Job "regulartime_task (trigger: interval[1 day, 0:00:00], next run at: 2020-05-22 00:04:22.047034)" raised an exception
Traceback (most recent call last):
  File "D:\Program Files\Python37\lib\site-packages\django\db\backends\mysql\base.py", line 71, in execute
    return self.cursor.execute(query, args)
  File "D:\Program Files\Python37\lib\site-packages\MySQLdb\cursors.py", line 209, in execute
    res = self._query(query)
  File "D:\Program Files\Python37\lib\site-packages\MySQLdb\cursors.py", line 315, in _query
    db.query(q)
  File "D:\Program Files\Python37\lib\site-packages\MySQLdb\connections.py", line 239, in query
    _mysql.connection.query(self, query)
MySQLdb._exceptions.OperationalError: (1048, "Column 'laser_power' cannot be null")

During handling of the above exception, another exception occurred:

Traceback (most recent call last):
  File "D:\Program Files\Python37\lib\site-packages\apscheduler\scheduler.py", line 512, in _run_job
    retval = job.func(*job.args, **job.kwargs)
  File "E:\1-program\11-LAMDataServer\lamdataserver\LAMProcessData\views.py", line 5244, in regulartime_task
    RT_FineData.Realtime_FineData.init_Tomorrow_rows()
  File "E:\1-program\11-LAMDataServer\lamdataserver\LAMProcessData\process_realtime_finedata.py", line 193, in init_Tomorrow_rows
    _model.objects.bulk_create(insert_data_list)
  File "D:\Program Files\Python37\lib\site-packages\django\db\models\manager.py", line 82, in manager_method
    return getattr(self.get_queryset(), name)(*args, **kwargs)
  File "D:\Program Files\Python37\lib\site-packages\django\db\models\query.py", line 474, in bulk_create
    ids = self._batched_insert(objs_without_pk, fields, batch_size, ignore_conflicts=ignore_conflicts)
  File "D:\Program Files\Python37\lib\site-packages\django\db\models\query.py", line 1211, in _batched_insert
    self._insert(item, fields=fields, using=self.db, ignore_conflicts=ignore_conflicts)
  File "D:\Program Files\Python37\lib\site-packages\django\db\models\query.py", line 1186, in _insert
    return query.get_compiler(using=using).execute_sql(return_id)
  File "D:\Program Files\Python37\lib\site-packages\django\db\models\sql\compiler.py", line 1332, in execute_sql
    cursor.execute(sql, params)
  File "D:\Program Files\Python37\lib\site-packages\django\db\backends\utils.py", line 99, in execute
    return super().execute(sql, params)
  File "D:\Program Files\Python37\lib\site-packages\django\db\backends\utils.py", line 67, in execute
    return self._execute_with_wrappers(sql, params, many=False, executor=self._execute)
  File "D:\Program Files\Python37\lib\site-packages\django\db\backends\utils.py", line 76, in _execute_with_wrappers
    return executor(sql, params, many, context)
  File "D:\Program Files\Python37\lib\site-packages\django\db\backends\utils.py", line 84, in _execute
    return self.cursor.execute(sql, params)
  File "D:\Program Files\Python37\lib\site-packages\django\db\backends\mysql\base.py", line 76, in execute
    raise utils.IntegrityError(*tuple(e.args))
django.db.utils.IntegrityError: (1048, "Column 'laser_power' cannot be null")
2020-05-21 Thu 00:04:23 threadpool.py _run_jobs 94 - DEBUG - Exiting worker thread
2020-05-21 Thu 00:16:31 threadpool.py __init__ 52 - INFO - Started thread pool with 0 core threads and 20 maximum threads
2020-05-21 Thu 00:16:31 scheduler.py add_job 287 - INFO - Adding job tentatively -- it will be properly scheduled when the scheduler starts
2020-05-21 Thu 00:16:31 scheduler.py add_job 287 - INFO - Adding job tentatively -- it will be properly scheduled when the scheduler starts
2020-05-21 Thu 00:16:31 scheduler.py add_job 287 - INFO - Adding job tentatively -- it will be properly scheduled when the scheduler starts
2020-05-21 Thu 00:16:31 scheduler.py _real_add_job 262 - INFO - Added job "regulartime_task (trigger: interval[1 day, 0:00:00], next run at: 2020-05-21 00:16:41.357566)" to job store "default"
2020-05-21 Thu 00:16:31 scheduler.py _real_add_job 262 - INFO - Added job "cleanup (trigger: cron[day_of_week='*', hour='3', minute='0', second='0'], next run at: 2020-05-21 03:00:00)" to job store "default"
2020-05-21 Thu 00:16:31 scheduler.py _real_add_job 262 - INFO - Added job "OpenLog (trigger: cron[hour='0'], next run at: 2020-05-22 00:00:00)" to job store "default"
2020-05-21 Thu 00:16:31 scheduler.py _main_loop 574 - INFO - Scheduler started
2020-05-21 Thu 00:16:31 scheduler.py _main_loop 579 - DEBUG - Looking for jobs to run
2020-05-21 Thu 00:16:31 scheduler.py _main_loop 588 - DEBUG - Next wakeup is due at 2020-05-21 00:16:41.357566 (in 9.995536 seconds)
2020-05-21 Thu 00:16:31 query_views.py <module> 64 - DEBUG - SendBefore_NotRecive : [<CNCProcessStatus: CNCProcessStatus object (2038721)>]
2020-05-21 Thu 00:16:31 query_views.py <module> 65 - DEBUG - Waitfor_Recive : [2038721]
2020-05-21 Thu 00:16:41 scheduler.py _main_loop 579 - DEBUG - Looking for jobs to run
2020-05-21 Thu 00:16:41 threadpool.py _run_jobs 69 - DEBUG - Started worker thread
2020-05-21 Thu 00:16:41 scheduler.py _main_loop 588 - DEBUG - Next wakeup is due at 2020-05-21 03:00:00 (in 9798.634750 seconds)
2020-05-21 Thu 00:16:41 scheduler.py _run_job 509 - INFO - Running job "regulartime_task (trigger: interval[1 day, 0:00:00], next run at: 2020-05-22 00:16:41.357566)" (scheduled at 2020-05-21 00:16:41.357566)
2020-05-21 Thu 00:16:42 scheduler.py _run_job 520 - ERROR - Job "regulartime_task (trigger: interval[1 day, 0:00:00], next run at: 2020-05-22 00:16:41.357566)" raised an exception
Traceback (most recent call last):
  File "D:\Program Files\Python37\lib\site-packages\django\db\backends\utils.py", line 84, in _execute
    return self.cursor.execute(sql, params)
  File "D:\Program Files\Python37\lib\site-packages\django\db\backends\mysql\base.py", line 71, in execute
    return self.cursor.execute(query, args)
  File "D:\Program Files\Python37\lib\site-packages\MySQLdb\cursors.py", line 209, in execute
    res = self._query(query)
  File "D:\Program Files\Python37\lib\site-packages\MySQLdb\cursors.py", line 315, in _query
    db.query(q)
  File "D:\Program Files\Python37\lib\site-packages\MySQLdb\connections.py", line 239, in query
    _mysql.connection.query(self, query)
MySQLdb._exceptions.IntegrityError: (1062, "Duplicate entry '1590076800' for key 'LAMProcessData_process_r_acquisition_timestamp_a69ae90c_uniq'")

The above exception was the direct cause of the following exception:

Traceback (most recent call last):
  File "D:\Program Files\Python37\lib\site-packages\apscheduler\scheduler.py", line 512, in _run_job
    retval = job.func(*job.args, **job.kwargs)
  File "E:\1-program\11-LAMDataServer\lamdataserver\LAMProcessData\views.py", line 5244, in regulartime_task
    RT_FineData.Realtime_FineData.init_Tomorrow_rows()
  File "E:\1-program\11-LAMDataServer\lamdataserver\LAMProcessData\process_realtime_finedata.py", line 193, in init_Tomorrow_rows
    _model.objects.bulk_create(insert_data_list)
  File "D:\Program Files\Python37\lib\site-packages\django\db\models\manager.py", line 82, in manager_method
    return getattr(self.get_queryset(), name)(*args, **kwargs)
  File "D:\Program Files\Python37\lib\site-packages\django\db\models\query.py", line 474, in bulk_create
    ids = self._batched_insert(objs_without_pk, fields, batch_size, ignore_conflicts=ignore_conflicts)
  File "D:\Program Files\Python37\lib\site-packages\django\db\models\query.py", line 1211, in _batched_insert
    self._insert(item, fields=fields, using=self.db, ignore_conflicts=ignore_conflicts)
  File "D:\Program Files\Python37\lib\site-packages\django\db\models\query.py", line 1186, in _insert
    return query.get_compiler(using=using).execute_sql(return_id)
  File "D:\Program Files\Python37\lib\site-packages\django\db\models\sql\compiler.py", line 1332, in execute_sql
    cursor.execute(sql, params)
  File "D:\Program Files\Python37\lib\site-packages\django\db\backends\utils.py", line 99, in execute
    return super().execute(sql, params)
  File "D:\Program Files\Python37\lib\site-packages\django\db\backends\utils.py", line 67, in execute
    return self._execute_with_wrappers(sql, params, many=False, executor=self._execute)
  File "D:\Program Files\Python37\lib\site-packages\django\db\backends\utils.py", line 76, in _execute_with_wrappers
    return executor(sql, params, many, context)
  File "D:\Program Files\Python37\lib\site-packages\django\db\backends\utils.py", line 84, in _execute
    return self.cursor.execute(sql, params)
  File "D:\Program Files\Python37\lib\site-packages\django\db\utils.py", line 89, in __exit__
    raise dj_exc_value.with_traceback(traceback) from exc_value
  File "D:\Program Files\Python37\lib\site-packages\django\db\backends\utils.py", line 84, in _execute
    return self.cursor.execute(sql, params)
  File "D:\Program Files\Python37\lib\site-packages\django\db\backends\mysql\base.py", line 71, in execute
    return self.cursor.execute(query, args)
  File "D:\Program Files\Python37\lib\site-packages\MySQLdb\cursors.py", line 209, in execute
    res = self._query(query)
  File "D:\Program Files\Python37\lib\site-packages\MySQLdb\cursors.py", line 315, in _query
    db.query(q)
  File "D:\Program Files\Python37\lib\site-packages\MySQLdb\connections.py", line 239, in query
    _mysql.connection.query(self, query)
django.db.utils.IntegrityError: (1062, "Duplicate entry '1590076800' for key 'LAMProcessData_process_r_acquisition_timestamp_a69ae90c_uniq'")
2020-05-21 Thu 00:16:43 threadpool.py _run_jobs 94 - DEBUG - Exiting worker thread
2020-05-21 Thu 00:17:29 threadpool.py __init__ 52 - INFO - Started thread pool with 0 core threads and 20 maximum threads
2020-05-21 Thu 00:17:29 scheduler.py add_job 287 - INFO - Adding job tentatively -- it will be properly scheduled when the scheduler starts
2020-05-21 Thu 00:17:29 scheduler.py add_job 287 - INFO - Adding job tentatively -- it will be properly scheduled when the scheduler starts
2020-05-21 Thu 00:17:29 scheduler.py add_job 287 - INFO - Adding job tentatively -- it will be properly scheduled when the scheduler starts
2020-05-21 Thu 00:17:29 scheduler.py _real_add_job 262 - INFO - Added job "regulartime_task (trigger: interval[1 day, 0:00:00], next run at: 2020-05-21 00:17:39.060586)" to job store "default"
2020-05-21 Thu 00:17:29 scheduler.py _real_add_job 262 - INFO - Added job "cleanup (trigger: cron[day_of_week='*', hour='3', minute='0', second='0'], next run at: 2020-05-21 03:00:00)" to job store "default"
2020-05-21 Thu 00:17:29 scheduler.py _real_add_job 262 - INFO - Added job "OpenLog (trigger: cron[hour='0'], next run at: 2020-05-22 00:00:00)" to job store "default"
2020-05-21 Thu 00:17:29 scheduler.py _main_loop 574 - INFO - Scheduler started
2020-05-21 Thu 00:17:29 scheduler.py _main_loop 579 - DEBUG - Looking for jobs to run
2020-05-21 Thu 00:17:29 scheduler.py _main_loop 588 - DEBUG - Next wakeup is due at 2020-05-21 00:17:39.060586 (in 9.996032 seconds)
2020-05-21 Thu 00:17:29 query_views.py <module> 64 - DEBUG - SendBefore_NotRecive : [<CNCProcessStatus: CNCProcessStatus object (2038721)>]
2020-05-21 Thu 00:17:29 query_views.py <module> 65 - DEBUG - Waitfor_Recive : [2038721]
2020-05-21 Thu 00:17:39 scheduler.py _main_loop 579 - DEBUG - Looking for jobs to run
2020-05-21 Thu 00:17:39 threadpool.py _run_jobs 69 - DEBUG - Started worker thread
2020-05-21 Thu 00:17:39 scheduler.py _main_loop 588 - DEBUG - Next wakeup is due at 2020-05-21 03:00:00 (in 9740.936459 seconds)
2020-05-21 Thu 00:17:39 scheduler.py _run_job 509 - INFO - Running job "regulartime_task (trigger: interval[1 day, 0:00:00], next run at: 2020-05-22 00:17:39.060586)" (scheduled at 2020-05-21 00:17:39.060586)
2020-05-21 Thu 00:17:40 scheduler.py _run_job 520 - ERROR - Job "regulartime_task (trigger: interval[1 day, 0:00:00], next run at: 2020-05-22 00:17:39.060586)" raised an exception
Traceback (most recent call last):
  File "D:\Program Files\Python37\lib\site-packages\django\db\backends\utils.py", line 84, in _execute
    return self.cursor.execute(sql, params)
  File "D:\Program Files\Python37\lib\site-packages\django\db\backends\mysql\base.py", line 71, in execute
    return self.cursor.execute(query, args)
  File "D:\Program Files\Python37\lib\site-packages\MySQLdb\cursors.py", line 209, in execute
    res = self._query(query)
  File "D:\Program Files\Python37\lib\site-packages\MySQLdb\cursors.py", line 315, in _query
    db.query(q)
  File "D:\Program Files\Python37\lib\site-packages\MySQLdb\connections.py", line 239, in query
    _mysql.connection.query(self, query)
MySQLdb._exceptions.IntegrityError: (1062, "Duplicate entry '1590076800' for key 'LAMProcessData_process_r_acquisition_timestamp_a69ae90c_uniq'")

The above exception was the direct cause of the following exception:

Traceback (most recent call last):
  File "D:\Program Files\Python37\lib\site-packages\apscheduler\scheduler.py", line 512, in _run_job
    retval = job.func(*job.args, **job.kwargs)
  File "E:\1-program\11-LAMDataServer\lamdataserver\LAMProcessData\views.py", line 5244, in regulartime_task
    RT_FineData.Realtime_FineData.init_Tomorrow_rows()
  File "E:\1-program\11-LAMDataServer\lamdataserver\LAMProcessData\process_realtime_finedata.py", line 193, in init_Tomorrow_rows
    _model.objects.bulk_create(insert_data_list)
  File "D:\Program Files\Python37\lib\site-packages\django\db\models\manager.py", line 82, in manager_method
    return getattr(self.get_queryset(), name)(*args, **kwargs)
  File "D:\Program Files\Python37\lib\site-packages\django\db\models\query.py", line 474, in bulk_create
    ids = self._batched_insert(objs_without_pk, fields, batch_size, ignore_conflicts=ignore_conflicts)
  File "D:\Program Files\Python37\lib\site-packages\django\db\models\query.py", line 1211, in _batched_insert
    self._insert(item, fields=fields, using=self.db, ignore_conflicts=ignore_conflicts)
  File "D:\Program Files\Python37\lib\site-packages\django\db\models\query.py", line 1186, in _insert
    return query.get_compiler(using=using).execute_sql(return_id)
  File "D:\Program Files\Python37\lib\site-packages\django\db\models\sql\compiler.py", line 1332, in execute_sql
    cursor.execute(sql, params)
  File "D:\Program Files\Python37\lib\site-packages\django\db\backends\utils.py", line 99, in execute
    return super().execute(sql, params)
  File "D:\Program Files\Python37\lib\site-packages\django\db\backends\utils.py", line 67, in execute
    return self._execute_with_wrappers(sql, params, many=False, executor=self._execute)
  File "D:\Program Files\Python37\lib\site-packages\django\db\backends\utils.py", line 76, in _execute_with_wrappers
    return executor(sql, params, many, context)
  File "D:\Program Files\Python37\lib\site-packages\django\db\backends\utils.py", line 84, in _execute
    return self.cursor.execute(sql, params)
  File "D:\Program Files\Python37\lib\site-packages\django\db\utils.py", line 89, in __exit__
    raise dj_exc_value.with_traceback(traceback) from exc_value
  File "D:\Program Files\Python37\lib\site-packages\django\db\backends\utils.py", line 84, in _execute
    return self.cursor.execute(sql, params)
  File "D:\Program Files\Python37\lib\site-packages\django\db\backends\mysql\base.py", line 71, in execute
    return self.cursor.execute(query, args)
  File "D:\Program Files\Python37\lib\site-packages\MySQLdb\cursors.py", line 209, in execute
    res = self._query(query)
  File "D:\Program Files\Python37\lib\site-packages\MySQLdb\cursors.py", line 315, in _query
    db.query(q)
  File "D:\Program Files\Python37\lib\site-packages\MySQLdb\connections.py", line 239, in query
    _mysql.connection.query(self, query)
django.db.utils.IntegrityError: (1062, "Duplicate entry '1590076800' for key 'LAMProcessData_process_r_acquisition_timestamp_a69ae90c_uniq'")
2020-05-21 Thu 00:17:41 threadpool.py _run_jobs 94 - DEBUG - Exiting worker thread
2020-05-21 Thu 00:17:52 PngImagePlugin.py call 141 - DEBUG - STREAM b'IHDR' 16 13
2020-05-21 Thu 00:17:52 PngImagePlugin.py call 141 - DEBUG - STREAM b'sRGB' 41 1
2020-05-21 Thu 00:17:52 PngImagePlugin.py call 141 - DEBUG - STREAM b'gAMA' 54 4
2020-05-21 Thu 00:17:52 PngImagePlugin.py call 141 - DEBUG - STREAM b'pHYs' 70 9
2020-05-21 Thu 00:17:52 PngImagePlugin.py call 141 - DEBUG - STREAM b'IDAT' 91 65445
2020-05-21 Thu 00:19:04 threadpool.py __init__ 52 - INFO - Started thread pool with 0 core threads and 20 maximum threads
2020-05-21 Thu 00:19:04 scheduler.py add_job 287 - INFO - Adding job tentatively -- it will be properly scheduled when the scheduler starts
2020-05-21 Thu 00:19:04 scheduler.py add_job 287 - INFO - Adding job tentatively -- it will be properly scheduled when the scheduler starts
2020-05-21 Thu 00:19:04 scheduler.py add_job 287 - INFO - Adding job tentatively -- it will be properly scheduled when the scheduler starts
2020-05-21 Thu 00:19:04 scheduler.py _real_add_job 262 - INFO - Added job "regulartime_task (trigger: interval[1 day, 0:00:00], next run at: 2020-05-21 00:19:14.526061)" to job store "default"
2020-05-21 Thu 00:19:04 scheduler.py _real_add_job 262 - INFO - Added job "cleanup (trigger: cron[day_of_week='*', hour='3', minute='0', second='0'], next run at: 2020-05-21 03:00:00)" to job store "default"
2020-05-21 Thu 00:19:04 scheduler.py _real_add_job 262 - INFO - Added job "OpenLog (trigger: cron[hour='0'], next run at: 2020-05-22 00:00:00)" to job store "default"
2020-05-21 Thu 00:19:04 scheduler.py _main_loop 574 - INFO - Scheduler started
2020-05-21 Thu 00:19:04 scheduler.py _main_loop 579 - DEBUG - Looking for jobs to run
2020-05-21 Thu 00:19:04 scheduler.py _main_loop 588 - DEBUG - Next wakeup is due at 2020-05-21 00:19:14.526061 (in 9.995038 seconds)
2020-05-21 Thu 00:19:04 query_views.py <module> 64 - DEBUG - SendBefore_NotRecive : [<CNCProcessStatus: CNCProcessStatus object (2038721)>]
2020-05-21 Thu 00:19:04 query_views.py <module> 65 - DEBUG - Waitfor_Recive : [2038721]
2020-05-21 Thu 00:19:14 scheduler.py _main_loop 579 - DEBUG - Looking for jobs to run
2020-05-21 Thu 00:19:14 threadpool.py _run_jobs 69 - DEBUG - Started worker thread
2020-05-21 Thu 00:19:14 scheduler.py _run_job 509 - INFO - Running job "regulartime_task (trigger: interval[1 day, 0:00:00], next run at: 2020-05-21 00:19:14.526061)" (scheduled at 2020-05-21 00:19:14.526061)
2020-05-21 Thu 00:19:14 scheduler.py _main_loop 588 - DEBUG - Next wakeup is due at 2020-05-21 03:00:00 (in 9645.456491 seconds)
2020-05-21 Thu 00:19:15 scheduler.py _run_job 520 - ERROR - Job "regulartime_task (trigger: interval[1 day, 0:00:00], next run at: 2020-05-22 00:19:14.526061)" raised an exception
Traceback (most recent call last):
  File "D:\Program Files\Python37\lib\site-packages\django\db\backends\utils.py", line 84, in _execute
    return self.cursor.execute(sql, params)
  File "D:\Program Files\Python37\lib\site-packages\django\db\backends\mysql\base.py", line 71, in execute
    return self.cursor.execute(query, args)
  File "D:\Program Files\Python37\lib\site-packages\MySQLdb\cursors.py", line 209, in execute
    res = self._query(query)
  File "D:\Program Files\Python37\lib\site-packages\MySQLdb\cursors.py", line 315, in _query
    db.query(q)
  File "D:\Program Files\Python37\lib\site-packages\MySQLdb\connections.py", line 239, in query
    _mysql.connection.query(self, query)
MySQLdb._exceptions.IntegrityError: (1062, "Duplicate entry '1590076800' for key 'LAMProcessData_process_r_acquisition_timestamp_a69ae90c_uniq'")

The above exception was the direct cause of the following exception:

Traceback (most recent call last):
  File "D:\Program Files\Python37\lib\site-packages\apscheduler\scheduler.py", line 512, in _run_job
    retval = job.func(*job.args, **job.kwargs)
  File "E:\1-program\11-LAMDataServer\lamdataserver\LAMProcessData\views.py", line 5244, in regulartime_task
    RT_FineData.Realtime_FineData.init_Tomorrow_rows()
  File "E:\1-program\11-LAMDataServer\lamdataserver\LAMProcessData\process_realtime_finedata.py", line 193, in init_Tomorrow_rows
    _model.objects.bulk_create(insert_data_list)
  File "D:\Program Files\Python37\lib\site-packages\django\db\models\manager.py", line 82, in manager_method
    return getattr(self.get_queryset(), name)(*args, **kwargs)
  File "D:\Program Files\Python37\lib\site-packages\django\db\models\query.py", line 474, in bulk_create
    ids = self._batched_insert(objs_without_pk, fields, batch_size, ignore_conflicts=ignore_conflicts)
  File "D:\Program Files\Python37\lib\site-packages\django\db\models\query.py", line 1211, in _batched_insert
    self._insert(item, fields=fields, using=self.db, ignore_conflicts=ignore_conflicts)
  File "D:\Program Files\Python37\lib\site-packages\django\db\models\query.py", line 1186, in _insert
    return query.get_compiler(using=using).execute_sql(return_id)
  File "D:\Program Files\Python37\lib\site-packages\django\db\models\sql\compiler.py", line 1332, in execute_sql
    cursor.execute(sql, params)
  File "D:\Program Files\Python37\lib\site-packages\django\db\backends\utils.py", line 99, in execute
    return super().execute(sql, params)
  File "D:\Program Files\Python37\lib\site-packages\django\db\backends\utils.py", line 67, in execute
    return self._execute_with_wrappers(sql, params, many=False, executor=self._execute)
  File "D:\Program Files\Python37\lib\site-packages\django\db\backends\utils.py", line 76, in _execute_with_wrappers
    return executor(sql, params, many, context)
  File "D:\Program Files\Python37\lib\site-packages\django\db\backends\utils.py", line 84, in _execute
    return self.cursor.execute(sql, params)
  File "D:\Program Files\Python37\lib\site-packages\django\db\utils.py", line 89, in __exit__
    raise dj_exc_value.with_traceback(traceback) from exc_value
  File "D:\Program Files\Python37\lib\site-packages\django\db\backends\utils.py", line 84, in _execute
    return self.cursor.execute(sql, params)
  File "D:\Program Files\Python37\lib\site-packages\django\db\backends\mysql\base.py", line 71, in execute
    return self.cursor.execute(query, args)
  File "D:\Program Files\Python37\lib\site-packages\MySQLdb\cursors.py", line 209, in execute
    res = self._query(query)
  File "D:\Program Files\Python37\lib\site-packages\MySQLdb\cursors.py", line 315, in _query
    db.query(q)
  File "D:\Program Files\Python37\lib\site-packages\MySQLdb\connections.py", line 239, in query
    _mysql.connection.query(self, query)
django.db.utils.IntegrityError: (1062, "Duplicate entry '1590076800' for key 'LAMProcessData_process_r_acquisition_timestamp_a69ae90c_uniq'")
2020-05-21 Thu 00:19:16 threadpool.py _run_jobs 94 - DEBUG - Exiting worker thread
2020-05-21 Thu 00:20:21 PngImagePlugin.py call 141 - DEBUG - STREAM b'IHDR' 16 13
2020-05-21 Thu 00:20:21 PngImagePlugin.py call 141 - DEBUG - STREAM b'IDAT' 41 63411
2020-05-21 Thu 00:37:06 autoreload.py trigger_reload 203 - INFO - E:\1-program\11-LAMDataServer\lamdataserver\LAMProcessData\views.py changed, reloading.
2020-05-21 Thu 00:37:06 threadpool.py shutdown 111 - INFO - Shutting down thread pool
2020-05-21 Thu 00:37:09 threadpool.py __init__ 52 - INFO - Started thread pool with 0 core threads and 20 maximum threads
2020-05-21 Thu 00:37:09 scheduler.py add_job 287 - INFO - Adding job tentatively -- it will be properly scheduled when the scheduler starts
2020-05-21 Thu 00:37:09 scheduler.py add_job 287 - INFO - Adding job tentatively -- it will be properly scheduled when the scheduler starts
2020-05-21 Thu 00:37:09 scheduler.py add_job 287 - INFO - Adding job tentatively -- it will be properly scheduled when the scheduler starts
2020-05-21 Thu 00:37:09 scheduler.py _real_add_job 262 - INFO - Added job "regulartime_task (trigger: interval[1 day, 0:00:00], next run at: 2020-05-21 00:37:19.730332)" to job store "default"
2020-05-21 Thu 00:37:09 scheduler.py _real_add_job 262 - INFO - Added job "cleanup (trigger: cron[day_of_week='*', hour='3', minute='0', second='0'], next run at: 2020-05-21 03:00:00)" to job store "default"
2020-05-21 Thu 00:37:09 scheduler.py _real_add_job 262 - INFO - Added job "OpenLog (trigger: cron[hour='0'], next run at: 2020-05-22 00:00:00)" to job store "default"
2020-05-21 Thu 00:37:09 scheduler.py _main_loop 574 - INFO - Scheduler started
2020-05-21 Thu 00:37:09 scheduler.py _main_loop 579 - DEBUG - Looking for jobs to run
2020-05-21 Thu 00:37:09 scheduler.py _main_loop 588 - DEBUG - Next wakeup is due at 2020-05-21 00:37:19.730332 (in 9.996528 seconds)
2020-05-21 Thu 00:37:09 query_views.py <module> 64 - DEBUG - SendBefore_NotRecive : [<CNCProcessStatus: CNCProcessStatus object (2038721)>]
2020-05-21 Thu 00:37:09 query_views.py <module> 65 - DEBUG - Waitfor_Recive : [2038721]
2020-05-21 Thu 00:37:19 scheduler.py _main_loop 579 - DEBUG - Looking for jobs to run
2020-05-21 Thu 00:37:19 threadpool.py _run_jobs 69 - DEBUG - Started worker thread
2020-05-21 Thu 00:37:19 scheduler.py _run_job 509 - INFO - Running job "regulartime_task (trigger: interval[1 day, 0:00:00], next run at: 2020-05-21 00:37:19.730332)" (scheduled at 2020-05-21 00:37:19.730332)
2020-05-21 Thu 00:37:19 scheduler.py _main_loop 588 - DEBUG - Next wakeup is due at 2020-05-21 03:00:00 (in 8560.267904 seconds)
2020-05-21 Thu 00:37:20 scheduler.py _run_job 520 - ERROR - Job "regulartime_task (trigger: interval[1 day, 0:00:00], next run at: 2020-05-22 00:37:19.730332)" raised an exception
Traceback (most recent call last):
  File "D:\Program Files\Python37\lib\site-packages\django\db\backends\utils.py", line 84, in _execute
    return self.cursor.execute(sql, params)
  File "D:\Program Files\Python37\lib\site-packages\django\db\backends\mysql\base.py", line 71, in execute
    return self.cursor.execute(query, args)
  File "D:\Program Files\Python37\lib\site-packages\MySQLdb\cursors.py", line 209, in execute
    res = self._query(query)
  File "D:\Program Files\Python37\lib\site-packages\MySQLdb\cursors.py", line 315, in _query
    db.query(q)
  File "D:\Program Files\Python37\lib\site-packages\MySQLdb\connections.py", line 239, in query
    _mysql.connection.query(self, query)
MySQLdb._exceptions.IntegrityError: (1062, "Duplicate entry '1590076800' for key 'LAMProcessData_process_r_acquisition_timestamp_a69ae90c_uniq'")

The above exception was the direct cause of the following exception:

Traceback (most recent call last):
  File "D:\Program Files\Python37\lib\site-packages\apscheduler\scheduler.py", line 512, in _run_job
    retval = job.func(*job.args, **job.kwargs)
  File "E:\1-program\11-LAMDataServer\lamdataserver\LAMProcessData\views.py", line 5246, in regulartime_task
    RT_FineData.Realtime_FineData.init_Tomorrow_rows()
  File "E:\1-program\11-LAMDataServer\lamdataserver\LAMProcessData\process_realtime_finedata.py", line 193, in init_Tomorrow_rows
    _model.objects.bulk_create(insert_data_list)
  File "D:\Program Files\Python37\lib\site-packages\django\db\models\manager.py", line 82, in manager_method
    return getattr(self.get_queryset(), name)(*args, **kwargs)
  File "D:\Program Files\Python37\lib\site-packages\django\db\models\query.py", line 474, in bulk_create
    ids = self._batched_insert(objs_without_pk, fields, batch_size, ignore_conflicts=ignore_conflicts)
  File "D:\Program Files\Python37\lib\site-packages\django\db\models\query.py", line 1211, in _batched_insert
    self._insert(item, fields=fields, using=self.db, ignore_conflicts=ignore_conflicts)
  File "D:\Program Files\Python37\lib\site-packages\django\db\models\query.py", line 1186, in _insert
    return query.get_compiler(using=using).execute_sql(return_id)
  File "D:\Program Files\Python37\lib\site-packages\django\db\models\sql\compiler.py", line 1332, in execute_sql
    cursor.execute(sql, params)
  File "D:\Program Files\Python37\lib\site-packages\django\db\backends\utils.py", line 99, in execute
    return super().execute(sql, params)
  File "D:\Program Files\Python37\lib\site-packages\django\db\backends\utils.py", line 67, in execute
    return self._execute_with_wrappers(sql, params, many=False, executor=self._execute)
  File "D:\Program Files\Python37\lib\site-packages\django\db\backends\utils.py", line 76, in _execute_with_wrappers
    return executor(sql, params, many, context)
  File "D:\Program Files\Python37\lib\site-packages\django\db\backends\utils.py", line 84, in _execute
    return self.cursor.execute(sql, params)
  File "D:\Program Files\Python37\lib\site-packages\django\db\utils.py", line 89, in __exit__
    raise dj_exc_value.with_traceback(traceback) from exc_value
  File "D:\Program Files\Python37\lib\site-packages\django\db\backends\utils.py", line 84, in _execute
    return self.cursor.execute(sql, params)
  File "D:\Program Files\Python37\lib\site-packages\django\db\backends\mysql\base.py", line 71, in execute
    return self.cursor.execute(query, args)
  File "D:\Program Files\Python37\lib\site-packages\MySQLdb\cursors.py", line 209, in execute
    res = self._query(query)
  File "D:\Program Files\Python37\lib\site-packages\MySQLdb\cursors.py", line 315, in _query
    db.query(q)
  File "D:\Program Files\Python37\lib\site-packages\MySQLdb\connections.py", line 239, in query
    _mysql.connection.query(self, query)
django.db.utils.IntegrityError: (1062, "Duplicate entry '1590076800' for key 'LAMProcessData_process_r_acquisition_timestamp_a69ae90c_uniq'")
2020-05-21 Thu 00:37:21 threadpool.py _run_jobs 94 - DEBUG - Exiting worker thread
2020-05-21 Thu 00:44:38 autoreload.py trigger_reload 203 - INFO - E:\1-program\11-LAMDataServer\lamdataserver\LAMProcessData\views.py changed, reloading.
2020-05-21 Thu 00:44:38 threadpool.py shutdown 111 - INFO - Shutting down thread pool
2020-05-21 Thu 00:44:43 threadpool.py __init__ 52 - INFO - Started thread pool with 0 core threads and 20 maximum threads
2020-05-21 Thu 00:44:43 scheduler.py add_job 287 - INFO - Adding job tentatively -- it will be properly scheduled when the scheduler starts
2020-05-21 Thu 00:44:43 scheduler.py add_job 287 - INFO - Adding job tentatively -- it will be properly scheduled when the scheduler starts
2020-05-21 Thu 00:44:43 scheduler.py add_job 287 - INFO - Adding job tentatively -- it will be properly scheduled when the scheduler starts
2020-05-21 Thu 00:44:43 scheduler.py _real_add_job 262 - INFO - Added job "regulartime_task (trigger: interval[1 day, 0:00:00], next run at: 2020-05-21 00:44:53.087770)" to job store "default"
2020-05-21 Thu 00:44:43 scheduler.py _real_add_job 262 - INFO - Added job "cleanup (trigger: cron[day_of_week='*', hour='3', minute='0', second='0'], next run at: 2020-05-21 03:00:00)" to job store "default"
2020-05-21 Thu 00:44:43 scheduler.py _real_add_job 262 - INFO - Added job "OpenLog (trigger: cron[hour='0'], next run at: 2020-05-22 00:00:00)" to job store "default"
2020-05-21 Thu 00:44:43 scheduler.py _main_loop 574 - INFO - Scheduler started
2020-05-21 Thu 00:44:43 scheduler.py _main_loop 579 - DEBUG - Looking for jobs to run
2020-05-21 Thu 00:44:43 scheduler.py _main_loop 588 - DEBUG - Next wakeup is due at 2020-05-21 00:44:53.087770 (in 9.994544 seconds)
2020-05-21 Thu 00:44:43 query_views.py <module> 64 - DEBUG - SendBefore_NotRecive : [<CNCProcessStatus: CNCProcessStatus object (2038721)>]
2020-05-21 Thu 00:44:43 query_views.py <module> 65 - DEBUG - Waitfor_Recive : [2038721]
2020-05-21 Thu 00:44:53 scheduler.py _main_loop 579 - DEBUG - Looking for jobs to run
2020-05-21 Thu 00:44:53 threadpool.py _run_jobs 69 - DEBUG - Started worker thread
2020-05-21 Thu 00:44:53 scheduler.py _run_job 509 - INFO - Running job "regulartime_task (trigger: interval[1 day, 0:00:00], next run at: 2020-05-21 00:44:53.087770)" (scheduled at 2020-05-21 00:44:53.087770)
2020-05-21 Thu 00:44:53 scheduler.py _main_loop 588 - DEBUG - Next wakeup is due at 2020-05-21 03:00:00 (in 8106.895882 seconds)
2020-05-21 Thu 00:44:54 scheduler.py _run_job 520 - ERROR - Job "regulartime_task (trigger: interval[1 day, 0:00:00], next run at: 2020-05-22 00:44:53.087770)" raised an exception
Traceback (most recent call last):
  File "D:\Program Files\Python37\lib\site-packages\django\db\backends\utils.py", line 84, in _execute
    return self.cursor.execute(sql, params)
  File "D:\Program Files\Python37\lib\site-packages\django\db\backends\mysql\base.py", line 71, in execute
    return self.cursor.execute(query, args)
  File "D:\Program Files\Python37\lib\site-packages\MySQLdb\cursors.py", line 209, in execute
    res = self._query(query)
  File "D:\Program Files\Python37\lib\site-packages\MySQLdb\cursors.py", line 315, in _query
    db.query(q)
  File "D:\Program Files\Python37\lib\site-packages\MySQLdb\connections.py", line 239, in query
    _mysql.connection.query(self, query)
MySQLdb._exceptions.IntegrityError: (1062, "Duplicate entry '1590076800' for key 'LAMProcessData_process_r_acquisition_timestamp_a69ae90c_uniq'")

The above exception was the direct cause of the following exception:

Traceback (most recent call last):
  File "D:\Program Files\Python37\lib\site-packages\apscheduler\scheduler.py", line 512, in _run_job
    retval = job.func(*job.args, **job.kwargs)
  File "E:\1-program\11-LAMDataServer\lamdataserver\LAMProcessData\views.py", line 5247, in regulartime_task
    RT_FineData.Realtime_FineData.init_Tomorrow_rows()
  File "E:\1-program\11-LAMDataServer\lamdataserver\LAMProcessData\process_realtime_finedata.py", line 193, in init_Tomorrow_rows
    _model.objects.bulk_create(insert_data_list)
  File "D:\Program Files\Python37\lib\site-packages\django\db\models\manager.py", line 82, in manager_method
    return getattr(self.get_queryset(), name)(*args, **kwargs)
  File "D:\Program Files\Python37\lib\site-packages\django\db\models\query.py", line 474, in bulk_create
    ids = self._batched_insert(objs_without_pk, fields, batch_size, ignore_conflicts=ignore_conflicts)
  File "D:\Program Files\Python37\lib\site-packages\django\db\models\query.py", line 1211, in _batched_insert
    self._insert(item, fields=fields, using=self.db, ignore_conflicts=ignore_conflicts)
  File "D:\Program Files\Python37\lib\site-packages\django\db\models\query.py", line 1186, in _insert
    return query.get_compiler(using=using).execute_sql(return_id)
  File "D:\Program Files\Python37\lib\site-packages\django\db\models\sql\compiler.py", line 1332, in execute_sql
    cursor.execute(sql, params)
  File "D:\Program Files\Python37\lib\site-packages\django\db\backends\utils.py", line 99, in execute
    return super().execute(sql, params)
  File "D:\Program Files\Python37\lib\site-packages\django\db\backends\utils.py", line 67, in execute
    return self._execute_with_wrappers(sql, params, many=False, executor=self._execute)
  File "D:\Program Files\Python37\lib\site-packages\django\db\backends\utils.py", line 76, in _execute_with_wrappers
    return executor(sql, params, many, context)
  File "D:\Program Files\Python37\lib\site-packages\django\db\backends\utils.py", line 84, in _execute
    return self.cursor.execute(sql, params)
  File "D:\Program Files\Python37\lib\site-packages\django\db\utils.py", line 89, in __exit__
    raise dj_exc_value.with_traceback(traceback) from exc_value
  File "D:\Program Files\Python37\lib\site-packages\django\db\backends\utils.py", line 84, in _execute
    return self.cursor.execute(sql, params)
  File "D:\Program Files\Python37\lib\site-packages\django\db\backends\mysql\base.py", line 71, in execute
    return self.cursor.execute(query, args)
  File "D:\Program Files\Python37\lib\site-packages\MySQLdb\cursors.py", line 209, in execute
    res = self._query(query)
  File "D:\Program Files\Python37\lib\site-packages\MySQLdb\cursors.py", line 315, in _query
    db.query(q)
  File "D:\Program Files\Python37\lib\site-packages\MySQLdb\connections.py", line 239, in query
    _mysql.connection.query(self, query)
django.db.utils.IntegrityError: (1062, "Duplicate entry '1590076800' for key 'LAMProcessData_process_r_acquisition_timestamp_a69ae90c_uniq'")
2020-05-21 Thu 00:44:55 threadpool.py _run_jobs 94 - DEBUG - Exiting worker thread
2020-05-21 Thu 00:55:08 threadpool.py __init__ 52 - INFO - Started thread pool with 0 core threads and 20 maximum threads
2020-05-21 Thu 00:55:08 scheduler.py add_job 287 - INFO - Adding job tentatively -- it will be properly scheduled when the scheduler starts
2020-05-21 Thu 00:55:08 scheduler.py add_job 287 - INFO - Adding job tentatively -- it will be properly scheduled when the scheduler starts
2020-05-21 Thu 00:55:08 scheduler.py add_job 287 - INFO - Adding job tentatively -- it will be properly scheduled when the scheduler starts
2020-05-21 Thu 00:55:08 scheduler.py _real_add_job 262 - INFO - Added job "regulartime_task (trigger: interval[1 day, 0:00:00], next run at: 2020-05-21 00:55:18.599996)" to job store "default"
2020-05-21 Thu 00:55:08 scheduler.py _real_add_job 262 - INFO - Added job "cleanup (trigger: cron[day_of_week='*', hour='3', minute='0', second='0'], next run at: 2020-05-21 03:00:00)" to job store "default"
2020-05-21 Thu 00:55:08 scheduler.py _real_add_job 262 - INFO - Added job "OpenLog (trigger: cron[hour='0'], next run at: 2020-05-22 00:00:00)" to job store "default"
2020-05-21 Thu 00:55:08 scheduler.py _main_loop 574 - INFO - Scheduler started
2020-05-21 Thu 00:55:08 scheduler.py _main_loop 579 - DEBUG - Looking for jobs to run
2020-05-21 Thu 00:55:08 scheduler.py _main_loop 588 - DEBUG - Next wakeup is due at 2020-05-21 00:55:18.599996 (in 9.997556 seconds)
2020-05-21 Thu 00:55:08 query_views.py <module> 63 - DEBUG - SendBefore_NotRecive : [<CNCProcessStatus: CNCProcessStatus object (2038721)>]
2020-05-21 Thu 00:55:08 query_views.py <module> 64 - DEBUG - Waitfor_Recive : [2038721]
2020-05-21 Thu 00:55:18 scheduler.py _main_loop 579 - DEBUG - Looking for jobs to run
2020-05-21 Thu 00:55:18 threadpool.py _run_jobs 69 - DEBUG - Started worker thread
2020-05-21 Thu 00:55:18 scheduler.py _main_loop 588 - DEBUG - Next wakeup is due at 2020-05-21 03:00:00 (in 7481.397420 seconds)
2020-05-21 Thu 00:55:18 scheduler.py _run_job 509 - INFO - Running job "regulartime_task (trigger: interval[1 day, 0:00:00], next run at: 2020-05-22 00:55:18.599996)" (scheduled at 2020-05-21 00:55:18.599996)
2020-05-21 Thu 00:55:18 scheduler.py _run_job 520 - ERROR - Job "regulartime_task (trigger: interval[1 day, 0:00:00], next run at: 2020-05-22 00:55:18.599996)" raised an exception
Traceback (most recent call last):
  File "D:\Program Files\Python37\lib\site-packages\django\db\backends\utils.py", line 84, in _execute
    return self.cursor.execute(sql, params)
  File "D:\Program Files\Python37\lib\site-packages\django\db\backends\mysql\base.py", line 71, in execute
    return self.cursor.execute(query, args)
  File "D:\Program Files\Python37\lib\site-packages\MySQLdb\cursors.py", line 209, in execute
    res = self._query(query)
  File "D:\Program Files\Python37\lib\site-packages\MySQLdb\cursors.py", line 315, in _query
    db.query(q)
  File "D:\Program Files\Python37\lib\site-packages\MySQLdb\connections.py", line 239, in query
    _mysql.connection.query(self, query)
MySQLdb._exceptions.IntegrityError: (1062, "Duplicate entry '1590076800' for key 'LAMProcessData_process_r_acquisition_timestamp_a69ae90c_uniq'")

The above exception was the direct cause of the following exception:

Traceback (most recent call last):
  File "D:\Program Files\Python37\lib\site-packages\apscheduler\scheduler.py", line 512, in _run_job
    retval = job.func(*job.args, **job.kwargs)
  File "E:\1-program\11-LAMDataServer\lamdataserver\LAMProcessData\views.py", line 5249, in regulartime_task
    RT_FineData.Realtime_FineData.init_Tomorrow_rows()
  File "E:\1-program\11-LAMDataServer\lamdataserver\LAMProcessData\process_realtime_finedata.py", line 193, in init_Tomorrow_rows
    _model.objects.bulk_create(insert_data_list)
  File "D:\Program Files\Python37\lib\site-packages\django\db\models\manager.py", line 82, in manager_method
    return getattr(self.get_queryset(), name)(*args, **kwargs)
  File "D:\Program Files\Python37\lib\site-packages\django\db\models\query.py", line 474, in bulk_create
    ids = self._batched_insert(objs_without_pk, fields, batch_size, ignore_conflicts=ignore_conflicts)
  File "D:\Program Files\Python37\lib\site-packages\django\db\models\query.py", line 1211, in _batched_insert
    self._insert(item, fields=fields, using=self.db, ignore_conflicts=ignore_conflicts)
  File "D:\Program Files\Python37\lib\site-packages\django\db\models\query.py", line 1186, in _insert
    return query.get_compiler(using=using).execute_sql(return_id)
  File "D:\Program Files\Python37\lib\site-packages\django\db\models\sql\compiler.py", line 1332, in execute_sql
    cursor.execute(sql, params)
  File "D:\Program Files\Python37\lib\site-packages\django\db\backends\utils.py", line 99, in execute
    return super().execute(sql, params)
  File "D:\Program Files\Python37\lib\site-packages\django\db\backends\utils.py", line 67, in execute
    return self._execute_with_wrappers(sql, params, many=False, executor=self._execute)
  File "D:\Program Files\Python37\lib\site-packages\django\db\backends\utils.py", line 76, in _execute_with_wrappers
    return executor(sql, params, many, context)
  File "D:\Program Files\Python37\lib\site-packages\django\db\backends\utils.py", line 84, in _execute
    return self.cursor.execute(sql, params)
  File "D:\Program Files\Python37\lib\site-packages\django\db\utils.py", line 89, in __exit__
    raise dj_exc_value.with_traceback(traceback) from exc_value
  File "D:\Program Files\Python37\lib\site-packages\django\db\backends\utils.py", line 84, in _execute
    return self.cursor.execute(sql, params)
  File "D:\Program Files\Python37\lib\site-packages\django\db\backends\mysql\base.py", line 71, in execute
    return self.cursor.execute(query, args)
  File "D:\Program Files\Python37\lib\site-packages\MySQLdb\cursors.py", line 209, in execute
    res = self._query(query)
  File "D:\Program Files\Python37\lib\site-packages\MySQLdb\cursors.py", line 315, in _query
    db.query(q)
  File "D:\Program Files\Python37\lib\site-packages\MySQLdb\connections.py", line 239, in query
    _mysql.connection.query(self, query)
django.db.utils.IntegrityError: (1062, "Duplicate entry '1590076800' for key 'LAMProcessData_process_r_acquisition_timestamp_a69ae90c_uniq'")
2020-05-21 Thu 00:55:19 threadpool.py _run_jobs 94 - DEBUG - Exiting worker thread
2020-05-21 Thu 00:57:50 threadpool.py __init__ 52 - INFO - Started thread pool with 0 core threads and 20 maximum threads
2020-05-21 Thu 00:57:50 scheduler.py add_job 287 - INFO - Adding job tentatively -- it will be properly scheduled when the scheduler starts
2020-05-21 Thu 00:57:50 scheduler.py add_job 287 - INFO - Adding job tentatively -- it will be properly scheduled when the scheduler starts
2020-05-21 Thu 00:57:50 scheduler.py add_job 287 - INFO - Adding job tentatively -- it will be properly scheduled when the scheduler starts
2020-05-21 Thu 00:57:50 scheduler.py _real_add_job 262 - INFO - Added job "regulartime_task (trigger: interval[1 day, 0:00:00], next run at: 2020-05-21 00:58:00.200481)" to job store "default"
2020-05-21 Thu 00:57:50 scheduler.py _real_add_job 262 - INFO - Added job "cleanup (trigger: cron[day_of_week='*', hour='3', minute='0', second='0'], next run at: 2020-05-21 03:00:00)" to job store "default"
2020-05-21 Thu 00:57:50 scheduler.py _real_add_job 262 - INFO - Added job "OpenLog (trigger: cron[hour='0'], next run at: 2020-05-22 00:00:00)" to job store "default"
2020-05-21 Thu 00:57:50 scheduler.py _main_loop 574 - INFO - Scheduler started
2020-05-21 Thu 00:57:50 scheduler.py _main_loop 579 - DEBUG - Looking for jobs to run
2020-05-21 Thu 00:57:50 scheduler.py _main_loop 588 - DEBUG - Next wakeup is due at 2020-05-21 00:58:00.200481 (in 9.995561 seconds)
2020-05-21 Thu 00:57:50 query_views.py <module> 64 - DEBUG - SendBefore_NotRecive : [<CNCProcessStatus: CNCProcessStatus object (2038721)>]
2020-05-21 Thu 00:57:50 query_views.py <module> 65 - DEBUG - Waitfor_Recive : [2038721]
2020-05-21 Thu 00:58:00 scheduler.py _main_loop 579 - DEBUG - Looking for jobs to run
2020-05-21 Thu 00:58:00 threadpool.py _run_jobs 69 - DEBUG - Started worker thread
2020-05-21 Thu 00:58:00 scheduler.py _main_loop 588 - DEBUG - Next wakeup is due at 2020-05-21 03:00:00 (in 7319.788638 seconds)
2020-05-21 Thu 00:58:00 scheduler.py _run_job 509 - INFO - Running job "regulartime_task (trigger: interval[1 day, 0:00:00], next run at: 2020-05-22 00:58:00.200481)" (scheduled at 2020-05-21 00:58:00.200481)
2020-05-21 Thu 00:58:01 scheduler.py _run_job 520 - ERROR - Job "regulartime_task (trigger: interval[1 day, 0:00:00], next run at: 2020-05-22 00:58:00.200481)" raised an exception
Traceback (most recent call last):
  File "D:\Program Files\Python37\lib\site-packages\django\db\backends\utils.py", line 84, in _execute
    return self.cursor.execute(sql, params)
  File "D:\Program Files\Python37\lib\site-packages\django\db\backends\mysql\base.py", line 71, in execute
    return self.cursor.execute(query, args)
  File "D:\Program Files\Python37\lib\site-packages\MySQLdb\cursors.py", line 209, in execute
    res = self._query(query)
  File "D:\Program Files\Python37\lib\site-packages\MySQLdb\cursors.py", line 315, in _query
    db.query(q)
  File "D:\Program Files\Python37\lib\site-packages\MySQLdb\connections.py", line 239, in query
    _mysql.connection.query(self, query)
MySQLdb._exceptions.IntegrityError: (1062, "Duplicate entry '1590076800' for key 'LAMProcessData_process_r_acquisition_timestamp_a69ae90c_uniq'")

The above exception was the direct cause of the following exception:

Traceback (most recent call last):
  File "D:\Program Files\Python37\lib\site-packages\apscheduler\scheduler.py", line 512, in _run_job
    retval = job.func(*job.args, **job.kwargs)
  File "E:\1-program\11-LAMDataServer\lamdataserver\LAMProcessData\views.py", line 5249, in regulartime_task
    RT_FineData.Realtime_FineData.init_Tomorrow_rows()
  File "E:\1-program\11-LAMDataServer\lamdataserver\LAMProcessData\process_realtime_finedata.py", line 193, in init_Tomorrow_rows
    _model.objects.bulk_create(insert_data_list)
  File "D:\Program Files\Python37\lib\site-packages\django\db\models\manager.py", line 82, in manager_method
    return getattr(self.get_queryset(), name)(*args, **kwargs)
  File "D:\Program Files\Python37\lib\site-packages\django\db\models\query.py", line 474, in bulk_create
    ids = self._batched_insert(objs_without_pk, fields, batch_size, ignore_conflicts=ignore_conflicts)
  File "D:\Program Files\Python37\lib\site-packages\django\db\models\query.py", line 1211, in _batched_insert
    self._insert(item, fields=fields, using=self.db, ignore_conflicts=ignore_conflicts)
  File "D:\Program Files\Python37\lib\site-packages\django\db\models\query.py", line 1186, in _insert
    return query.get_compiler(using=using).execute_sql(return_id)
  File "D:\Program Files\Python37\lib\site-packages\django\db\models\sql\compiler.py", line 1332, in execute_sql
    cursor.execute(sql, params)
  File "D:\Program Files\Python37\lib\site-packages\django\db\backends\utils.py", line 99, in execute
    return super().execute(sql, params)
  File "D:\Program Files\Python37\lib\site-packages\django\db\backends\utils.py", line 67, in execute
    return self._execute_with_wrappers(sql, params, many=False, executor=self._execute)
  File "D:\Program Files\Python37\lib\site-packages\django\db\backends\utils.py", line 76, in _execute_with_wrappers
    return executor(sql, params, many, context)
  File "D:\Program Files\Python37\lib\site-packages\django\db\backends\utils.py", line 84, in _execute
    return self.cursor.execute(sql, params)
  File "D:\Program Files\Python37\lib\site-packages\django\db\utils.py", line 89, in __exit__
    raise dj_exc_value.with_traceback(traceback) from exc_value
  File "D:\Program Files\Python37\lib\site-packages\django\db\backends\utils.py", line 84, in _execute
    return self.cursor.execute(sql, params)
  File "D:\Program Files\Python37\lib\site-packages\django\db\backends\mysql\base.py", line 71, in execute
    return self.cursor.execute(query, args)
  File "D:\Program Files\Python37\lib\site-packages\MySQLdb\cursors.py", line 209, in execute
    res = self._query(query)
  File "D:\Program Files\Python37\lib\site-packages\MySQLdb\cursors.py", line 315, in _query
    db.query(q)
  File "D:\Program Files\Python37\lib\site-packages\MySQLdb\connections.py", line 239, in query
    _mysql.connection.query(self, query)
django.db.utils.IntegrityError: (1062, "Duplicate entry '1590076800' for key 'LAMProcessData_process_r_acquisition_timestamp_a69ae90c_uniq'")
2020-05-21 Thu 00:58:02 threadpool.py _run_jobs 94 - DEBUG - Exiting worker thread
2020-05-21 Thu 00:58:05 PngImagePlugin.py call 141 - DEBUG - STREAM b'IHDR' 16 13
2020-05-21 Thu 00:58:05 PngImagePlugin.py call 141 - DEBUG - STREAM b'sRGB' 41 1
2020-05-21 Thu 00:58:05 PngImagePlugin.py call 141 - DEBUG - STREAM b'gAMA' 54 4
2020-05-21 Thu 00:58:05 PngImagePlugin.py call 141 - DEBUG - STREAM b'pHYs' 70 9
2020-05-21 Thu 00:58:05 PngImagePlugin.py call 141 - DEBUG - STREAM b'IDAT' 91 65445
2020-05-21 Thu 00:59:05 threadpool.py __init__ 52 - INFO - Started thread pool with 0 core threads and 20 maximum threads
2020-05-21 Thu 00:59:05 scheduler.py add_job 287 - INFO - Adding job tentatively -- it will be properly scheduled when the scheduler starts
2020-05-21 Thu 00:59:05 scheduler.py add_job 287 - INFO - Adding job tentatively -- it will be properly scheduled when the scheduler starts
2020-05-21 Thu 00:59:05 scheduler.py add_job 287 - INFO - Adding job tentatively -- it will be properly scheduled when the scheduler starts
2020-05-21 Thu 00:59:05 scheduler.py _real_add_job 262 - INFO - Added job "regulartime_task (trigger: interval[1 day, 0:00:00], next run at: 2020-05-21 00:59:15.085505)" to job store "default"
2020-05-21 Thu 00:59:05 scheduler.py _real_add_job 262 - INFO - Added job "cleanup (trigger: cron[day_of_week='*', hour='3', minute='0', second='0'], next run at: 2020-05-21 03:00:00)" to job store "default"
2020-05-21 Thu 00:59:05 scheduler.py _real_add_job 262 - INFO - Added job "OpenLog (trigger: cron[hour='0'], next run at: 2020-05-22 00:00:00)" to job store "default"
2020-05-21 Thu 00:59:05 scheduler.py _main_loop 574 - INFO - Scheduler started
2020-05-21 Thu 00:59:05 scheduler.py _main_loop 579 - DEBUG - Looking for jobs to run
2020-05-21 Thu 00:59:05 scheduler.py _main_loop 588 - DEBUG - Next wakeup is due at 2020-05-21 00:59:15.085505 (in 9.997516 seconds)
2020-05-21 Thu 00:59:05 query_views.py <module> 63 - DEBUG - SendBefore_NotRecive : [<CNCProcessStatus: CNCProcessStatus object (2038721)>]
2020-05-21 Thu 00:59:05 query_views.py <module> 64 - DEBUG - Waitfor_Recive : [2038721]
2020-05-21 Thu 00:59:15 scheduler.py _main_loop 579 - DEBUG - Looking for jobs to run
2020-05-21 Thu 00:59:15 threadpool.py _run_jobs 69 - DEBUG - Started worker thread
2020-05-21 Thu 00:59:15 scheduler.py _run_job 509 - INFO - Running job "regulartime_task (trigger: interval[1 day, 0:00:00], next run at: 2020-05-21 00:59:15.085505)" (scheduled at 2020-05-21 00:59:15.085505)
2020-05-21 Thu 00:59:15 scheduler.py _main_loop 588 - DEBUG - Next wakeup is due at 2020-05-21 03:00:00 (in 7244.901645 seconds)
2020-05-21 Thu 00:59:15 scheduler.py _run_job 520 - ERROR - Job "regulartime_task (trigger: interval[1 day, 0:00:00], next run at: 2020-05-22 00:59:15.085505)" raised an exception
Traceback (most recent call last):
  File "D:\Program Files\Python37\lib\site-packages\django\db\backends\utils.py", line 84, in _execute
    return self.cursor.execute(sql, params)
  File "D:\Program Files\Python37\lib\site-packages\django\db\backends\mysql\base.py", line 71, in execute
    return self.cursor.execute(query, args)
  File "D:\Program Files\Python37\lib\site-packages\MySQLdb\cursors.py", line 209, in execute
    res = self._query(query)
  File "D:\Program Files\Python37\lib\site-packages\MySQLdb\cursors.py", line 315, in _query
    db.query(q)
  File "D:\Program Files\Python37\lib\site-packages\MySQLdb\connections.py", line 239, in query
    _mysql.connection.query(self, query)
MySQLdb._exceptions.IntegrityError: (1062, "Duplicate entry '1590076800' for key 'LAMProcessData_process_r_acquisition_timestamp_a69ae90c_uniq'")

The above exception was the direct cause of the following exception:

Traceback (most recent call last):
  File "D:\Program Files\Python37\lib\site-packages\apscheduler\scheduler.py", line 512, in _run_job
    retval = job.func(*job.args, **job.kwargs)
  File "E:\1-program\11-LAMDataServer\lamdataserver\LAMProcessData\views.py", line 5249, in regulartime_task
    RT_FineData.Realtime_FineData.init_Tomorrow_rows()
  File "E:\1-program\11-LAMDataServer\lamdataserver\LAMProcessData\process_realtime_finedata.py", line 193, in init_Tomorrow_rows
    _model.objects.bulk_create(insert_data_list)
  File "D:\Program Files\Python37\lib\site-packages\django\db\models\manager.py", line 82, in manager_method
    return getattr(self.get_queryset(), name)(*args, **kwargs)
  File "D:\Program Files\Python37\lib\site-packages\django\db\models\query.py", line 474, in bulk_create
    ids = self._batched_insert(objs_without_pk, fields, batch_size, ignore_conflicts=ignore_conflicts)
  File "D:\Program Files\Python37\lib\site-packages\django\db\models\query.py", line 1211, in _batched_insert
    self._insert(item, fields=fields, using=self.db, ignore_conflicts=ignore_conflicts)
  File "D:\Program Files\Python37\lib\site-packages\django\db\models\query.py", line 1186, in _insert
    return query.get_compiler(using=using).execute_sql(return_id)
  File "D:\Program Files\Python37\lib\site-packages\django\db\models\sql\compiler.py", line 1332, in execute_sql
    cursor.execute(sql, params)
  File "D:\Program Files\Python37\lib\site-packages\django\db\backends\utils.py", line 99, in execute
    return super().execute(sql, params)
  File "D:\Program Files\Python37\lib\site-packages\django\db\backends\utils.py", line 67, in execute
    return self._execute_with_wrappers(sql, params, many=False, executor=self._execute)
  File "D:\Program Files\Python37\lib\site-packages\django\db\backends\utils.py", line 76, in _execute_with_wrappers
    return executor(sql, params, many, context)
  File "D:\Program Files\Python37\lib\site-packages\django\db\backends\utils.py", line 84, in _execute
    return self.cursor.execute(sql, params)
  File "D:\Program Files\Python37\lib\site-packages\django\db\utils.py", line 89, in __exit__
    raise dj_exc_value.with_traceback(traceback) from exc_value
  File "D:\Program Files\Python37\lib\site-packages\django\db\backends\utils.py", line 84, in _execute
    return self.cursor.execute(sql, params)
  File "D:\Program Files\Python37\lib\site-packages\django\db\backends\mysql\base.py", line 71, in execute
    return self.cursor.execute(query, args)
  File "D:\Program Files\Python37\lib\site-packages\MySQLdb\cursors.py", line 209, in execute
    res = self._query(query)
  File "D:\Program Files\Python37\lib\site-packages\MySQLdb\cursors.py", line 315, in _query
    db.query(q)
  File "D:\Program Files\Python37\lib\site-packages\MySQLdb\connections.py", line 239, in query
    _mysql.connection.query(self, query)
django.db.utils.IntegrityError: (1062, "Duplicate entry '1590076800' for key 'LAMProcessData_process_r_acquisition_timestamp_a69ae90c_uniq'")
2020-05-21 Thu 00:59:16 threadpool.py _run_jobs 94 - DEBUG - Exiting worker thread
2020-05-21 Thu 01:01:21 log.py log_response 228 - WARNING - Not Found: /favicon.ico
2020-05-21 Thu 01:11:56 threadpool.py __init__ 52 - INFO - Started thread pool with 0 core threads and 20 maximum threads
2020-05-21 Thu 01:11:56 scheduler.py add_job 287 - INFO - Adding job tentatively -- it will be properly scheduled when the scheduler starts
2020-05-21 Thu 01:11:56 scheduler.py add_job 287 - INFO - Adding job tentatively -- it will be properly scheduled when the scheduler starts
2020-05-21 Thu 01:11:56 scheduler.py add_job 287 - INFO - Adding job tentatively -- it will be properly scheduled when the scheduler starts
2020-05-21 Thu 01:11:56 scheduler.py _real_add_job 262 - INFO - Added job "regulartime_task (trigger: interval[1 day, 0:00:00], next run at: 2020-05-21 01:12:06.769253)" to job store "default"
2020-05-21 Thu 01:11:56 scheduler.py _real_add_job 262 - INFO - Added job "cleanup (trigger: cron[day_of_week='*', hour='3', minute='0', second='0'], next run at: 2020-05-21 03:00:00)" to job store "default"
2020-05-21 Thu 01:11:56 scheduler.py _real_add_job 262 - INFO - Added job "OpenLog (trigger: cron[hour='0'], next run at: 2020-05-22 00:00:00)" to job store "default"
2020-05-21 Thu 01:11:56 scheduler.py _main_loop 574 - INFO - Scheduler started
2020-05-21 Thu 01:11:56 scheduler.py _main_loop 579 - DEBUG - Looking for jobs to run
2020-05-21 Thu 01:11:56 scheduler.py _main_loop 588 - DEBUG - Next wakeup is due at 2020-05-21 01:12:06.769253 (in 9.994546 seconds)
2020-05-21 Thu 01:11:56 query_views.py <module> 64 - DEBUG - SendBefore_NotRecive : [<CNCProcessStatus: CNCProcessStatus object (2038721)>]
2020-05-21 Thu 01:11:56 query_views.py <module> 65 - DEBUG - Waitfor_Recive : [2038721]
2020-05-21 Thu 01:12:06 scheduler.py _main_loop 579 - DEBUG - Looking for jobs to run
2020-05-21 Thu 01:12:06 threadpool.py _run_jobs 69 - DEBUG - Started worker thread
2020-05-21 Thu 01:12:06 scheduler.py _run_job 509 - INFO - Running job "regulartime_task (trigger: interval[1 day, 0:00:00], next run at: 2020-05-21 01:12:06.769253)" (scheduled at 2020-05-21 01:12:06.769253)
2020-05-21 Thu 01:12:06 scheduler.py _main_loop 588 - DEBUG - Next wakeup is due at 2020-05-21 03:00:00 (in 6473.229334 seconds)
2020-05-21 Thu 01:12:07 scheduler.py _run_job 520 - ERROR - Job "regulartime_task (trigger: interval[1 day, 0:00:00], next run at: 2020-05-22 01:12:06.769253)" raised an exception
Traceback (most recent call last):
  File "D:\Program Files\Python37\lib\site-packages\django\db\backends\utils.py", line 84, in _execute
    return self.cursor.execute(sql, params)
  File "D:\Program Files\Python37\lib\site-packages\django\db\backends\mysql\base.py", line 71, in execute
    return self.cursor.execute(query, args)
  File "D:\Program Files\Python37\lib\site-packages\MySQLdb\cursors.py", line 209, in execute
    res = self._query(query)
  File "D:\Program Files\Python37\lib\site-packages\MySQLdb\cursors.py", line 315, in _query
    db.query(q)
  File "D:\Program Files\Python37\lib\site-packages\MySQLdb\connections.py", line 239, in query
    _mysql.connection.query(self, query)
MySQLdb._exceptions.IntegrityError: (1062, "Duplicate entry '1590076800' for key 'LAMProcessData_process_r_acquisition_timestamp_a69ae90c_uniq'")

The above exception was the direct cause of the following exception:

Traceback (most recent call last):
  File "D:\Program Files\Python37\lib\site-packages\apscheduler\scheduler.py", line 512, in _run_job
    retval = job.func(*job.args, **job.kwargs)
  File "E:\1-program\11-LAMDataServer\lamdataserver\LAMProcessData\views.py", line 5249, in regulartime_task
    RT_FineData.Realtime_FineData.init_Tomorrow_rows()
  File "E:\1-program\11-LAMDataServer\lamdataserver\LAMProcessData\process_realtime_finedata.py", line 193, in init_Tomorrow_rows
    _model.objects.bulk_create(insert_data_list)
  File "D:\Program Files\Python37\lib\site-packages\django\db\models\manager.py", line 82, in manager_method
    return getattr(self.get_queryset(), name)(*args, **kwargs)
  File "D:\Program Files\Python37\lib\site-packages\django\db\models\query.py", line 474, in bulk_create
    ids = self._batched_insert(objs_without_pk, fields, batch_size, ignore_conflicts=ignore_conflicts)
  File "D:\Program Files\Python37\lib\site-packages\django\db\models\query.py", line 1211, in _batched_insert
    self._insert(item, fields=fields, using=self.db, ignore_conflicts=ignore_conflicts)
  File "D:\Program Files\Python37\lib\site-packages\django\db\models\query.py", line 1186, in _insert
    return query.get_compiler(using=using).execute_sql(return_id)
  File "D:\Program Files\Python37\lib\site-packages\django\db\models\sql\compiler.py", line 1332, in execute_sql
    cursor.execute(sql, params)
  File "D:\Program Files\Python37\lib\site-packages\django\db\backends\utils.py", line 99, in execute
    return super().execute(sql, params)
  File "D:\Program Files\Python37\lib\site-packages\django\db\backends\utils.py", line 67, in execute
    return self._execute_with_wrappers(sql, params, many=False, executor=self._execute)
  File "D:\Program Files\Python37\lib\site-packages\django\db\backends\utils.py", line 76, in _execute_with_wrappers
    return executor(sql, params, many, context)
  File "D:\Program Files\Python37\lib\site-packages\django\db\backends\utils.py", line 84, in _execute
    return self.cursor.execute(sql, params)
  File "D:\Program Files\Python37\lib\site-packages\django\db\utils.py", line 89, in __exit__
    raise dj_exc_value.with_traceback(traceback) from exc_value
  File "D:\Program Files\Python37\lib\site-packages\django\db\backends\utils.py", line 84, in _execute
    return self.cursor.execute(sql, params)
  File "D:\Program Files\Python37\lib\site-packages\django\db\backends\mysql\base.py", line 71, in execute
    return self.cursor.execute(query, args)
  File "D:\Program Files\Python37\lib\site-packages\MySQLdb\cursors.py", line 209, in execute
    res = self._query(query)
  File "D:\Program Files\Python37\lib\site-packages\MySQLdb\cursors.py", line 315, in _query
    db.query(q)
  File "D:\Program Files\Python37\lib\site-packages\MySQLdb\connections.py", line 239, in query
    _mysql.connection.query(self, query)
django.db.utils.IntegrityError: (1062, "Duplicate entry '1590076800' for key 'LAMProcessData_process_r_acquisition_timestamp_a69ae90c_uniq'")
2020-05-21 Thu 01:12:08 threadpool.py _run_jobs 94 - DEBUG - Exiting worker thread
2020-05-21 Thu 01:21:05 autoreload.py trigger_reload 203 - INFO - E:\1-program\11-LAMDataServer\lamdataserver\LAMProcessData\views.py changed, reloading.
2020-05-21 Thu 01:21:05 threadpool.py shutdown 111 - INFO - Shutting down thread pool
2020-05-21 Thu 01:21:12 threadpool.py __init__ 52 - INFO - Started thread pool with 0 core threads and 20 maximum threads
2020-05-21 Thu 01:21:12 scheduler.py add_job 287 - INFO - Adding job tentatively -- it will be properly scheduled when the scheduler starts
2020-05-21 Thu 01:21:12 scheduler.py add_job 287 - INFO - Adding job tentatively -- it will be properly scheduled when the scheduler starts
2020-05-21 Thu 01:21:12 scheduler.py add_job 287 - INFO - Adding job tentatively -- it will be properly scheduled when the scheduler starts
2020-05-21 Thu 01:21:12 scheduler.py _real_add_job 262 - INFO - Added job "regulartime_task (trigger: interval[1 day, 0:00:00], next run at: 2020-05-21 01:21:22.057455)" to job store "default"
2020-05-21 Thu 01:21:12 scheduler.py _real_add_job 262 - INFO - Added job "cleanup (trigger: cron[day_of_week='*', hour='3', minute='0', second='0'], next run at: 2020-05-21 03:00:00)" to job store "default"
2020-05-21 Thu 01:21:12 scheduler.py _real_add_job 262 - INFO - Added job "OpenLog (trigger: cron[hour='0'], next run at: 2020-05-22 00:00:00)" to job store "default"
2020-05-21 Thu 01:21:12 scheduler.py _main_loop 574 - INFO - Scheduler started
2020-05-21 Thu 01:21:12 scheduler.py _main_loop 579 - DEBUG - Looking for jobs to run
2020-05-21 Thu 01:21:12 scheduler.py _main_loop 588 - DEBUG - Next wakeup is due at 2020-05-21 01:21:22.057455 (in 9.995014 seconds)
2020-05-21 Thu 01:21:12 query_views.py <module> 64 - DEBUG - SendBefore_NotRecive : [<CNCProcessStatus: CNCProcessStatus object (2038721)>]
2020-05-21 Thu 01:21:12 query_views.py <module> 65 - DEBUG - Waitfor_Recive : [2038721]
2020-05-21 Thu 01:21:22 scheduler.py _main_loop 579 - DEBUG - Looking for jobs to run
2020-05-21 Thu 01:21:22 threadpool.py _run_jobs 69 - DEBUG - Started worker thread
2020-05-21 Thu 01:21:22 scheduler.py _run_job 509 - INFO - Running job "regulartime_task (trigger: interval[1 day, 0:00:00], next run at: 2020-05-21 01:21:22.057455)" (scheduled at 2020-05-21 01:21:22.057455)
2020-05-21 Thu 01:21:22 scheduler.py _main_loop 588 - DEBUG - Next wakeup is due at 2020-05-21 03:00:00 (in 5917.935875 seconds)
2020-05-21 Thu 01:21:23 scheduler.py _run_job 520 - ERROR - Job "regulartime_task (trigger: interval[1 day, 0:00:00], next run at: 2020-05-22 01:21:22.057455)" raised an exception
Traceback (most recent call last):
  File "D:\Program Files\Python37\lib\site-packages\django\db\backends\utils.py", line 84, in _execute
    return self.cursor.execute(sql, params)
  File "D:\Program Files\Python37\lib\site-packages\django\db\backends\mysql\base.py", line 71, in execute
    return self.cursor.execute(query, args)
  File "D:\Program Files\Python37\lib\site-packages\MySQLdb\cursors.py", line 209, in execute
    res = self._query(query)
  File "D:\Program Files\Python37\lib\site-packages\MySQLdb\cursors.py", line 315, in _query
    db.query(q)
  File "D:\Program Files\Python37\lib\site-packages\MySQLdb\connections.py", line 239, in query
    _mysql.connection.query(self, query)
MySQLdb._exceptions.IntegrityError: (1062, "Duplicate entry '1590076800' for key 'LAMProcessData_process_r_acquisition_timestamp_a69ae90c_uniq'")

The above exception was the direct cause of the following exception:

Traceback (most recent call last):
  File "D:\Program Files\Python37\lib\site-packages\apscheduler\scheduler.py", line 512, in _run_job
    retval = job.func(*job.args, **job.kwargs)
  File "E:\1-program\11-LAMDataServer\lamdataserver\LAMProcessData\views.py", line 5260, in regulartime_task
    RT_FineData.Realtime_FineData.init_Tomorrow_rows()
  File "E:\1-program\11-LAMDataServer\lamdataserver\LAMProcessData\process_realtime_finedata.py", line 193, in init_Tomorrow_rows
    _model.objects.bulk_create(insert_data_list)
  File "D:\Program Files\Python37\lib\site-packages\django\db\models\manager.py", line 82, in manager_method
    return getattr(self.get_queryset(), name)(*args, **kwargs)
  File "D:\Program Files\Python37\lib\site-packages\django\db\models\query.py", line 474, in bulk_create
    ids = self._batched_insert(objs_without_pk, fields, batch_size, ignore_conflicts=ignore_conflicts)
  File "D:\Program Files\Python37\lib\site-packages\django\db\models\query.py", line 1211, in _batched_insert
    self._insert(item, fields=fields, using=self.db, ignore_conflicts=ignore_conflicts)
  File "D:\Program Files\Python37\lib\site-packages\django\db\models\query.py", line 1186, in _insert
    return query.get_compiler(using=using).execute_sql(return_id)
  File "D:\Program Files\Python37\lib\site-packages\django\db\models\sql\compiler.py", line 1332, in execute_sql
    cursor.execute(sql, params)
  File "D:\Program Files\Python37\lib\site-packages\django\db\backends\utils.py", line 99, in execute
    return super().execute(sql, params)
  File "D:\Program Files\Python37\lib\site-packages\django\db\backends\utils.py", line 67, in execute
    return self._execute_with_wrappers(sql, params, many=False, executor=self._execute)
  File "D:\Program Files\Python37\lib\site-packages\django\db\backends\utils.py", line 76, in _execute_with_wrappers
    return executor(sql, params, many, context)
  File "D:\Program Files\Python37\lib\site-packages\django\db\backends\utils.py", line 84, in _execute
    return self.cursor.execute(sql, params)
  File "D:\Program Files\Python37\lib\site-packages\django\db\utils.py", line 89, in __exit__
    raise dj_exc_value.with_traceback(traceback) from exc_value
  File "D:\Program Files\Python37\lib\site-packages\django\db\backends\utils.py", line 84, in _execute
    return self.cursor.execute(sql, params)
  File "D:\Program Files\Python37\lib\site-packages\django\db\backends\mysql\base.py", line 71, in execute
    return self.cursor.execute(query, args)
  File "D:\Program Files\Python37\lib\site-packages\MySQLdb\cursors.py", line 209, in execute
    res = self._query(query)
  File "D:\Program Files\Python37\lib\site-packages\MySQLdb\cursors.py", line 315, in _query
    db.query(q)
  File "D:\Program Files\Python37\lib\site-packages\MySQLdb\connections.py", line 239, in query
    _mysql.connection.query(self, query)
django.db.utils.IntegrityError: (1062, "Duplicate entry '1590076800' for key 'LAMProcessData_process_r_acquisition_timestamp_a69ae90c_uniq'")
2020-05-21 Thu 01:21:24 threadpool.py _run_jobs 94 - DEBUG - Exiting worker thread
2020-05-21 Thu 01:21:43 autoreload.py trigger_reload 203 - INFO - E:\1-program\11-LAMDataServer\lamdataserver\LAMProcessData\views.py changed, reloading.
2020-05-21 Thu 01:21:43 threadpool.py shutdown 111 - INFO - Shutting down thread pool
2020-05-21 Thu 01:21:55 threadpool.py __init__ 52 - INFO - Started thread pool with 0 core threads and 20 maximum threads
2020-05-21 Thu 01:21:55 scheduler.py add_job 287 - INFO - Adding job tentatively -- it will be properly scheduled when the scheduler starts
2020-05-21 Thu 01:21:55 scheduler.py add_job 287 - INFO - Adding job tentatively -- it will be properly scheduled when the scheduler starts
2020-05-21 Thu 01:21:55 scheduler.py add_job 287 - INFO - Adding job tentatively -- it will be properly scheduled when the scheduler starts
2020-05-21 Thu 01:21:55 scheduler.py _real_add_job 262 - INFO - Added job "regulartime_task (trigger: interval[1 day, 0:00:00], next run at: 2020-05-21 01:22:05.306414)" to job store "default"
2020-05-21 Thu 01:21:55 scheduler.py _real_add_job 262 - INFO - Added job "cleanup (trigger: cron[day_of_week='*', hour='3', minute='0', second='0'], next run at: 2020-05-21 03:00:00)" to job store "default"
2020-05-21 Thu 01:21:55 scheduler.py _real_add_job 262 - INFO - Added job "OpenLog (trigger: cron[hour='0'], next run at: 2020-05-22 00:00:00)" to job store "default"
2020-05-21 Thu 01:21:55 scheduler.py _main_loop 574 - INFO - Scheduler started
2020-05-21 Thu 01:21:55 scheduler.py _main_loop 579 - DEBUG - Looking for jobs to run
2020-05-21 Thu 01:21:55 scheduler.py _main_loop 588 - DEBUG - Next wakeup is due at 2020-05-21 01:22:05.306414 (in 9.995073 seconds)
2020-05-21 Thu 01:21:55 query_views.py <module> 64 - DEBUG - SendBefore_NotRecive : [<CNCProcessStatus: CNCProcessStatus object (2038721)>]
2020-05-21 Thu 01:21:55 query_views.py <module> 65 - DEBUG - Waitfor_Recive : [2038721]
2020-05-21 Thu 01:21:57 autoreload.py trigger_reload 203 - INFO - E:\1-program\11-LAMDataServer\lamdataserver\LAMProcessData\views.py changed, reloading.
2020-05-21 Thu 01:21:57 threadpool.py shutdown 111 - INFO - Shutting down thread pool
2020-05-21 Thu 01:22:06 threadpool.py __init__ 52 - INFO - Started thread pool with 0 core threads and 20 maximum threads
2020-05-21 Thu 01:22:06 scheduler.py add_job 287 - INFO - Adding job tentatively -- it will be properly scheduled when the scheduler starts
2020-05-21 Thu 01:22:06 scheduler.py add_job 287 - INFO - Adding job tentatively -- it will be properly scheduled when the scheduler starts
2020-05-21 Thu 01:22:06 scheduler.py add_job 287 - INFO - Adding job tentatively -- it will be properly scheduled when the scheduler starts
2020-05-21 Thu 01:22:06 scheduler.py _real_add_job 262 - INFO - Added job "regulartime_task (trigger: interval[1 day, 0:00:00], next run at: 2020-05-21 01:22:16.761513)" to job store "default"
2020-05-21 Thu 01:22:06 scheduler.py _real_add_job 262 - INFO - Added job "cleanup (trigger: cron[day_of_week='*', hour='3', minute='0', second='0'], next run at: 2020-05-21 03:00:00)" to job store "default"
2020-05-21 Thu 01:22:06 scheduler.py _real_add_job 262 - INFO - Added job "OpenLog (trigger: cron[hour='0'], next run at: 2020-05-22 00:00:00)" to job store "default"
2020-05-21 Thu 01:22:06 scheduler.py _main_loop 574 - INFO - Scheduler started
2020-05-21 Thu 01:22:06 scheduler.py _main_loop 579 - DEBUG - Looking for jobs to run
2020-05-21 Thu 01:22:06 scheduler.py _main_loop 588 - DEBUG - Next wakeup is due at 2020-05-21 01:22:16.761513 (in 9.995535 seconds)
2020-05-21 Thu 01:22:06 query_views.py <module> 64 - DEBUG - SendBefore_NotRecive : [<CNCProcessStatus: CNCProcessStatus object (2038721)>]
2020-05-21 Thu 01:22:06 query_views.py <module> 65 - DEBUG - Waitfor_Recive : [2038721]
2020-05-21 Thu 01:22:16 scheduler.py _main_loop 579 - DEBUG - Looking for jobs to run
2020-05-21 Thu 01:22:16 threadpool.py _run_jobs 69 - DEBUG - Started worker thread
2020-05-21 Thu 01:22:16 scheduler.py _run_job 509 - INFO - Running job "regulartime_task (trigger: interval[1 day, 0:00:00], next run at: 2020-05-21 01:22:16.761513)" (scheduled at 2020-05-21 01:22:16.761513)
2020-05-21 Thu 01:22:16 scheduler.py _main_loop 588 - DEBUG - Next wakeup is due at 2020-05-21 03:00:00 (in 5863.231293 seconds)
2020-05-21 Thu 01:22:18 scheduler.py _run_job 520 - ERROR - Job "regulartime_task (trigger: interval[1 day, 0:00:00], next run at: 2020-05-22 01:22:16.761513)" raised an exception
Traceback (most recent call last):
  File "D:\Program Files\Python37\lib\site-packages\django\db\backends\utils.py", line 84, in _execute
    return self.cursor.execute(sql, params)
  File "D:\Program Files\Python37\lib\site-packages\django\db\backends\mysql\base.py", line 71, in execute
    return self.cursor.execute(query, args)
  File "D:\Program Files\Python37\lib\site-packages\MySQLdb\cursors.py", line 209, in execute
    res = self._query(query)
  File "D:\Program Files\Python37\lib\site-packages\MySQLdb\cursors.py", line 315, in _query
    db.query(q)
  File "D:\Program Files\Python37\lib\site-packages\MySQLdb\connections.py", line 239, in query
    _mysql.connection.query(self, query)
MySQLdb._exceptions.IntegrityError: (1062, "Duplicate entry '1590076800' for key 'LAMProcessData_process_r_acquisition_timestamp_a69ae90c_uniq'")

The above exception was the direct cause of the following exception:

Traceback (most recent call last):
  File "D:\Program Files\Python37\lib\site-packages\apscheduler\scheduler.py", line 512, in _run_job
    retval = job.func(*job.args, **job.kwargs)
  File "E:\1-program\11-LAMDataServer\lamdataserver\LAMProcessData\views.py", line 5263, in regulartime_task
    RT_FineData.Realtime_FineData.init_Tomorrow_rows()
  File "E:\1-program\11-LAMDataServer\lamdataserver\LAMProcessData\process_realtime_finedata.py", line 193, in init_Tomorrow_rows
    _model.objects.bulk_create(insert_data_list)
  File "D:\Program Files\Python37\lib\site-packages\django\db\models\manager.py", line 82, in manager_method
    return getattr(self.get_queryset(), name)(*args, **kwargs)
  File "D:\Program Files\Python37\lib\site-packages\django\db\models\query.py", line 474, in bulk_create
    ids = self._batched_insert(objs_without_pk, fields, batch_size, ignore_conflicts=ignore_conflicts)
  File "D:\Program Files\Python37\lib\site-packages\django\db\models\query.py", line 1211, in _batched_insert
    self._insert(item, fields=fields, using=self.db, ignore_conflicts=ignore_conflicts)
  File "D:\Program Files\Python37\lib\site-packages\django\db\models\query.py", line 1186, in _insert
    return query.get_compiler(using=using).execute_sql(return_id)
  File "D:\Program Files\Python37\lib\site-packages\django\db\models\sql\compiler.py", line 1332, in execute_sql
    cursor.execute(sql, params)
  File "D:\Program Files\Python37\lib\site-packages\django\db\backends\utils.py", line 99, in execute
    return super().execute(sql, params)
  File "D:\Program Files\Python37\lib\site-packages\django\db\backends\utils.py", line 67, in execute
    return self._execute_with_wrappers(sql, params, many=False, executor=self._execute)
  File "D:\Program Files\Python37\lib\site-packages\django\db\backends\utils.py", line 76, in _execute_with_wrappers
    return executor(sql, params, many, context)
  File "D:\Program Files\Python37\lib\site-packages\django\db\backends\utils.py", line 84, in _execute
    return self.cursor.execute(sql, params)
  File "D:\Program Files\Python37\lib\site-packages\django\db\utils.py", line 89, in __exit__
    raise dj_exc_value.with_traceback(traceback) from exc_value
  File "D:\Program Files\Python37\lib\site-packages\django\db\backends\utils.py", line 84, in _execute
    return self.cursor.execute(sql, params)
  File "D:\Program Files\Python37\lib\site-packages\django\db\backends\mysql\base.py", line 71, in execute
    return self.cursor.execute(query, args)
  File "D:\Program Files\Python37\lib\site-packages\MySQLdb\cursors.py", line 209, in execute
    res = self._query(query)
  File "D:\Program Files\Python37\lib\site-packages\MySQLdb\cursors.py", line 315, in _query
    db.query(q)
  File "D:\Program Files\Python37\lib\site-packages\MySQLdb\connections.py", line 239, in query
    _mysql.connection.query(self, query)
django.db.utils.IntegrityError: (1062, "Duplicate entry '1590076800' for key 'LAMProcessData_process_r_acquisition_timestamp_a69ae90c_uniq'")
2020-05-21 Thu 01:22:19 threadpool.py _run_jobs 94 - DEBUG - Exiting worker thread
2020-05-21 Thu 01:23:46 autoreload.py trigger_reload 203 - INFO - E:\1-program\11-LAMDataServer\lamdataserver\LAMProcessData\views.py changed, reloading.
2020-05-21 Thu 01:23:46 threadpool.py shutdown 111 - INFO - Shutting down thread pool
2020-05-21 Thu 01:44:41 threadpool.py __init__ 52 - INFO - Started thread pool with 0 core threads and 20 maximum threads
2020-05-21 Thu 01:44:41 scheduler.py add_job 287 - INFO - Adding job tentatively -- it will be properly scheduled when the scheduler starts
2020-05-21 Thu 01:44:41 scheduler.py add_job 287 - INFO - Adding job tentatively -- it will be properly scheduled when the scheduler starts
2020-05-21 Thu 01:44:41 scheduler.py add_job 287 - INFO - Adding job tentatively -- it will be properly scheduled when the scheduler starts
2020-05-21 Thu 01:44:41 scheduler.py _real_add_job 262 - INFO - Added job "regulartime_task (trigger: interval[1 day, 0:00:00], next run at: 2020-05-21 01:44:51.102126)" to job store "default"
2020-05-21 Thu 01:44:41 scheduler.py _real_add_job 262 - INFO - Added job "cleanup (trigger: cron[day_of_week='*', hour='3', minute='0', second='0'], next run at: 2020-05-21 03:00:00)" to job store "default"
2020-05-21 Thu 01:44:41 scheduler.py _real_add_job 262 - INFO - Added job "OpenLog (trigger: cron[hour='0'], next run at: 2020-05-22 00:00:00)" to job store "default"
2020-05-21 Thu 01:44:41 scheduler.py _main_loop 574 - INFO - Scheduler started
2020-05-21 Thu 01:44:41 scheduler.py _main_loop 579 - DEBUG - Looking for jobs to run
2020-05-21 Thu 01:44:41 scheduler.py _main_loop 588 - DEBUG - Next wakeup is due at 2020-05-21 01:44:51.102126 (in 9.995590 seconds)
2020-05-21 Thu 01:44:41 query_views.py <module> 64 - DEBUG - SendBefore_NotRecive : [<CNCProcessStatus: CNCProcessStatus object (2038721)>]
2020-05-21 Thu 01:44:41 query_views.py <module> 65 - DEBUG - Waitfor_Recive : [2038721]
2020-05-21 Thu 01:44:51 scheduler.py _main_loop 579 - DEBUG - Looking for jobs to run
2020-05-21 Thu 01:44:51 threadpool.py _run_jobs 69 - DEBUG - Started worker thread
2020-05-21 Thu 01:44:51 scheduler.py _run_job 509 - INFO - Running job "regulartime_task (trigger: interval[1 day, 0:00:00], next run at: 2020-05-21 01:44:51.102126)" (scheduled at 2020-05-21 01:44:51.102126)
2020-05-21 Thu 01:44:51 scheduler.py _main_loop 588 - DEBUG - Next wakeup is due at 2020-05-21 03:00:00 (in 4508.889342 seconds)
2020-05-21 Thu 01:44:52 scheduler.py _run_job 520 - ERROR - Job "regulartime_task (trigger: interval[1 day, 0:00:00], next run at: 2020-05-22 01:44:51.102126)" raised an exception
Traceback (most recent call last):
  File "D:\Program Files\Python37\lib\site-packages\django\db\backends\utils.py", line 84, in _execute
    return self.cursor.execute(sql, params)
  File "D:\Program Files\Python37\lib\site-packages\django\db\backends\mysql\base.py", line 71, in execute
    return self.cursor.execute(query, args)
  File "D:\Program Files\Python37\lib\site-packages\MySQLdb\cursors.py", line 209, in execute
    res = self._query(query)
  File "D:\Program Files\Python37\lib\site-packages\MySQLdb\cursors.py", line 315, in _query
    db.query(q)
  File "D:\Program Files\Python37\lib\site-packages\MySQLdb\connections.py", line 239, in query
    _mysql.connection.query(self, query)
MySQLdb._exceptions.IntegrityError: (1062, "Duplicate entry '1590076800' for key 'LAMProcessData_process_r_acquisition_timestamp_a69ae90c_uniq'")

The above exception was the direct cause of the following exception:

Traceback (most recent call last):
  File "D:\Program Files\Python37\lib\site-packages\apscheduler\scheduler.py", line 512, in _run_job
    retval = job.func(*job.args, **job.kwargs)
  File "E:\1-program\11-LAMDataServer\lamdataserver\LAMProcessData\views.py", line 5270, in regulartime_task
    RT_FineData.Realtime_FineData.init_Tomorrow_rows()
  File "E:\1-program\11-LAMDataServer\lamdataserver\LAMProcessData\process_realtime_finedata.py", line 193, in init_Tomorrow_rows
    _model.objects.bulk_create(insert_data_list)
  File "D:\Program Files\Python37\lib\site-packages\django\db\models\manager.py", line 82, in manager_method
    return getattr(self.get_queryset(), name)(*args, **kwargs)
  File "D:\Program Files\Python37\lib\site-packages\django\db\models\query.py", line 474, in bulk_create
    ids = self._batched_insert(objs_without_pk, fields, batch_size, ignore_conflicts=ignore_conflicts)
  File "D:\Program Files\Python37\lib\site-packages\django\db\models\query.py", line 1211, in _batched_insert
    self._insert(item, fields=fields, using=self.db, ignore_conflicts=ignore_conflicts)
  File "D:\Program Files\Python37\lib\site-packages\django\db\models\query.py", line 1186, in _insert
    return query.get_compiler(using=using).execute_sql(return_id)
  File "D:\Program Files\Python37\lib\site-packages\django\db\models\sql\compiler.py", line 1332, in execute_sql
    cursor.execute(sql, params)
  File "D:\Program Files\Python37\lib\site-packages\django\db\backends\utils.py", line 99, in execute
    return super().execute(sql, params)
  File "D:\Program Files\Python37\lib\site-packages\django\db\backends\utils.py", line 67, in execute
    return self._execute_with_wrappers(sql, params, many=False, executor=self._execute)
  File "D:\Program Files\Python37\lib\site-packages\django\db\backends\utils.py", line 76, in _execute_with_wrappers
    return executor(sql, params, many, context)
  File "D:\Program Files\Python37\lib\site-packages\django\db\backends\utils.py", line 84, in _execute
    return self.cursor.execute(sql, params)
  File "D:\Program Files\Python37\lib\site-packages\django\db\utils.py", line 89, in __exit__
    raise dj_exc_value.with_traceback(traceback) from exc_value
  File "D:\Program Files\Python37\lib\site-packages\django\db\backends\utils.py", line 84, in _execute
    return self.cursor.execute(sql, params)
  File "D:\Program Files\Python37\lib\site-packages\django\db\backends\mysql\base.py", line 71, in execute
    return self.cursor.execute(query, args)
  File "D:\Program Files\Python37\lib\site-packages\MySQLdb\cursors.py", line 209, in execute
    res = self._query(query)
  File "D:\Program Files\Python37\lib\site-packages\MySQLdb\cursors.py", line 315, in _query
    db.query(q)
  File "D:\Program Files\Python37\lib\site-packages\MySQLdb\connections.py", line 239, in query
    _mysql.connection.query(self, query)
django.db.utils.IntegrityError: (1062, "Duplicate entry '1590076800' for key 'LAMProcessData_process_r_acquisition_timestamp_a69ae90c_uniq'")
2020-05-21 Thu 01:44:53 threadpool.py _run_jobs 94 - DEBUG - Exiting worker thread
2020-05-21 Thu 01:51:17 autoreload.py trigger_reload 203 - INFO - E:\1-program\11-LAMDataServer\lamdataserver\LAMProcessData\views.py changed, reloading.
2020-05-21 Thu 01:51:17 threadpool.py shutdown 111 - INFO - Shutting down thread pool
2020-05-21 Thu 01:51:23 threadpool.py __init__ 52 - INFO - Started thread pool with 0 core threads and 20 maximum threads
2020-05-21 Thu 01:51:23 scheduler.py add_job 287 - INFO - Adding job tentatively -- it will be properly scheduled when the scheduler starts
2020-05-21 Thu 01:51:23 scheduler.py add_job 287 - INFO - Adding job tentatively -- it will be properly scheduled when the scheduler starts
2020-05-21 Thu 01:51:23 scheduler.py add_job 287 - INFO - Adding job tentatively -- it will be properly scheduled when the scheduler starts
2020-05-21 Thu 01:51:23 scheduler.py _real_add_job 262 - INFO - Added job "regulartime_task (trigger: interval[1 day, 0:00:00], next run at: 2020-05-21 01:51:33.579087)" to job store "default"
2020-05-21 Thu 01:51:23 scheduler.py _real_add_job 262 - INFO - Added job "cleanup (trigger: cron[day_of_week='*', hour='3', minute='0', second='0'], next run at: 2020-05-21 03:00:00)" to job store "default"
2020-05-21 Thu 01:51:23 scheduler.py _real_add_job 262 - INFO - Added job "OpenLog (trigger: cron[hour='0'], next run at: 2020-05-22 00:00:00)" to job store "default"
2020-05-21 Thu 01:51:23 scheduler.py _main_loop 574 - INFO - Scheduler started
2020-05-21 Thu 01:51:23 scheduler.py _main_loop 579 - DEBUG - Looking for jobs to run
2020-05-21 Thu 01:51:23 scheduler.py _main_loop 588 - DEBUG - Next wakeup is due at 2020-05-21 01:51:33.579087 (in 9.997547 seconds)
2020-05-21 Thu 01:51:23 query_views.py <module> 63 - DEBUG - SendBefore_NotRecive : [<CNCProcessStatus: CNCProcessStatus object (2038721)>]
2020-05-21 Thu 01:51:23 query_views.py <module> 64 - DEBUG - Waitfor_Recive : [2038721]
2020-05-21 Thu 01:51:33 scheduler.py _main_loop 579 - DEBUG - Looking for jobs to run
2020-05-21 Thu 01:51:33 threadpool.py _run_jobs 69 - DEBUG - Started worker thread
2020-05-21 Thu 01:51:33 scheduler.py _main_loop 588 - DEBUG - Next wakeup is due at 2020-05-21 03:00:00 (in 4106.411466 seconds)
2020-05-21 Thu 01:51:33 scheduler.py _run_job 509 - INFO - Running job "regulartime_task (trigger: interval[1 day, 0:00:00], next run at: 2020-05-22 01:51:33.579087)" (scheduled at 2020-05-21 01:51:33.579087)
2020-05-21 Thu 01:51:33 scheduler.py _run_job 520 - ERROR - Job "regulartime_task (trigger: interval[1 day, 0:00:00], next run at: 2020-05-22 01:51:33.579087)" raised an exception
Traceback (most recent call last):
  File "D:\Program Files\Python37\lib\site-packages\django\db\backends\utils.py", line 84, in _execute
    return self.cursor.execute(sql, params)
  File "D:\Program Files\Python37\lib\site-packages\django\db\backends\mysql\base.py", line 71, in execute
    return self.cursor.execute(query, args)
  File "D:\Program Files\Python37\lib\site-packages\MySQLdb\cursors.py", line 209, in execute
    res = self._query(query)
  File "D:\Program Files\Python37\lib\site-packages\MySQLdb\cursors.py", line 315, in _query
    db.query(q)
  File "D:\Program Files\Python37\lib\site-packages\MySQLdb\connections.py", line 239, in query
    _mysql.connection.query(self, query)
MySQLdb._exceptions.IntegrityError: (1062, "Duplicate entry '1590076800' for key 'LAMProcessData_process_r_acquisition_timestamp_a69ae90c_uniq'")

The above exception was the direct cause of the following exception:

Traceback (most recent call last):
  File "D:\Program Files\Python37\lib\site-packages\apscheduler\scheduler.py", line 512, in _run_job
    retval = job.func(*job.args, **job.kwargs)
  File "E:\1-program\11-LAMDataServer\lamdataserver\LAMProcessData\views.py", line 5270, in regulartime_task
    RT_FineData.Realtime_FineData.init_Tomorrow_rows()
  File "E:\1-program\11-LAMDataServer\lamdataserver\LAMProcessData\process_realtime_finedata.py", line 193, in init_Tomorrow_rows
    _model.objects.bulk_create(insert_data_list)
  File "D:\Program Files\Python37\lib\site-packages\django\db\models\manager.py", line 82, in manager_method
    return getattr(self.get_queryset(), name)(*args, **kwargs)
  File "D:\Program Files\Python37\lib\site-packages\django\db\models\query.py", line 474, in bulk_create
    ids = self._batched_insert(objs_without_pk, fields, batch_size, ignore_conflicts=ignore_conflicts)
  File "D:\Program Files\Python37\lib\site-packages\django\db\models\query.py", line 1211, in _batched_insert
    self._insert(item, fields=fields, using=self.db, ignore_conflicts=ignore_conflicts)
  File "D:\Program Files\Python37\lib\site-packages\django\db\models\query.py", line 1186, in _insert
    return query.get_compiler(using=using).execute_sql(return_id)
  File "D:\Program Files\Python37\lib\site-packages\django\db\models\sql\compiler.py", line 1332, in execute_sql
    cursor.execute(sql, params)
  File "D:\Program Files\Python37\lib\site-packages\django\db\backends\utils.py", line 99, in execute
    return super().execute(sql, params)
  File "D:\Program Files\Python37\lib\site-packages\django\db\backends\utils.py", line 67, in execute
    return self._execute_with_wrappers(sql, params, many=False, executor=self._execute)
  File "D:\Program Files\Python37\lib\site-packages\django\db\backends\utils.py", line 76, in _execute_with_wrappers
    return executor(sql, params, many, context)
  File "D:\Program Files\Python37\lib\site-packages\django\db\backends\utils.py", line 84, in _execute
    return self.cursor.execute(sql, params)
  File "D:\Program Files\Python37\lib\site-packages\django\db\utils.py", line 89, in __exit__
    raise dj_exc_value.with_traceback(traceback) from exc_value
  File "D:\Program Files\Python37\lib\site-packages\django\db\backends\utils.py", line 84, in _execute
    return self.cursor.execute(sql, params)
  File "D:\Program Files\Python37\lib\site-packages\django\db\backends\mysql\base.py", line 71, in execute
    return self.cursor.execute(query, args)
  File "D:\Program Files\Python37\lib\site-packages\MySQLdb\cursors.py", line 209, in execute
    res = self._query(query)
  File "D:\Program Files\Python37\lib\site-packages\MySQLdb\cursors.py", line 315, in _query
    db.query(q)
  File "D:\Program Files\Python37\lib\site-packages\MySQLdb\connections.py", line 239, in query
    _mysql.connection.query(self, query)
django.db.utils.IntegrityError: (1062, "Duplicate entry '1590076800' for key 'LAMProcessData_process_r_acquisition_timestamp_a69ae90c_uniq'")
2020-05-21 Thu 01:51:34 threadpool.py _run_jobs 94 - DEBUG - Exiting worker thread
2020-05-21 Thu 01:54:26 autoreload.py trigger_reload 203 - INFO - E:\1-program\11-LAMDataServer\lamdataserver\LAMProcessData\views.py changed, reloading.
2020-05-21 Thu 01:54:26 threadpool.py shutdown 111 - INFO - Shutting down thread pool
2020-05-21 Thu 01:54:33 threadpool.py __init__ 52 - INFO - Started thread pool with 0 core threads and 20 maximum threads
2020-05-21 Thu 01:54:33 scheduler.py add_job 287 - INFO - Adding job tentatively -- it will be properly scheduled when the scheduler starts
2020-05-21 Thu 01:54:33 scheduler.py add_job 287 - INFO - Adding job tentatively -- it will be properly scheduled when the scheduler starts
2020-05-21 Thu 01:54:33 scheduler.py add_job 287 - INFO - Adding job tentatively -- it will be properly scheduled when the scheduler starts
2020-05-21 Thu 01:54:33 scheduler.py _real_add_job 262 - INFO - Added job "regulartime_task (trigger: interval[1 day, 0:00:00], next run at: 2020-05-21 01:54:43.546718)" to job store "default"
2020-05-21 Thu 01:54:33 scheduler.py _real_add_job 262 - INFO - Added job "cleanup (trigger: cron[day_of_week='*', hour='3', minute='0', second='0'], next run at: 2020-05-21 03:00:00)" to job store "default"
2020-05-21 Thu 01:54:33 scheduler.py _real_add_job 262 - INFO - Added job "OpenLog (trigger: cron[hour='0'], next run at: 2020-05-22 00:00:00)" to job store "default"
2020-05-21 Thu 01:54:33 scheduler.py _main_loop 574 - INFO - Scheduler started
2020-05-21 Thu 01:54:33 scheduler.py _main_loop 579 - DEBUG - Looking for jobs to run
2020-05-21 Thu 01:54:33 scheduler.py _main_loop 588 - DEBUG - Next wakeup is due at 2020-05-21 01:54:43.546718 (in 9.997519 seconds)
2020-05-21 Thu 01:54:33 query_views.py <module> 63 - DEBUG - SendBefore_NotRecive : [<CNCProcessStatus: CNCProcessStatus object (2038721)>]
2020-05-21 Thu 01:54:33 query_views.py <module> 64 - DEBUG - Waitfor_Recive : [2038721]
2020-05-21 Thu 01:54:43 scheduler.py _main_loop 579 - DEBUG - Looking for jobs to run
2020-05-21 Thu 01:54:43 threadpool.py _run_jobs 69 - DEBUG - Started worker thread
2020-05-21 Thu 01:54:43 scheduler.py _run_job 509 - INFO - Running job "regulartime_task (trigger: interval[1 day, 0:00:00], next run at: 2020-05-21 01:54:43.546718)" (scheduled at 2020-05-21 01:54:43.546718)
2020-05-21 Thu 01:54:43 scheduler.py _main_loop 588 - DEBUG - Next wakeup is due at 2020-05-21 03:00:00 (in 3916.436663 seconds)
2020-05-21 Thu 01:54:43 scheduler.py _run_job 520 - ERROR - Job "regulartime_task (trigger: interval[1 day, 0:00:00], next run at: 2020-05-22 01:54:43.546718)" raised an exception
Traceback (most recent call last):
  File "D:\Program Files\Python37\lib\site-packages\django\db\backends\utils.py", line 84, in _execute
    return self.cursor.execute(sql, params)
  File "D:\Program Files\Python37\lib\site-packages\django\db\backends\mysql\base.py", line 71, in execute
    return self.cursor.execute(query, args)
  File "D:\Program Files\Python37\lib\site-packages\MySQLdb\cursors.py", line 209, in execute
    res = self._query(query)
  File "D:\Program Files\Python37\lib\site-packages\MySQLdb\cursors.py", line 315, in _query
    db.query(q)
  File "D:\Program Files\Python37\lib\site-packages\MySQLdb\connections.py", line 239, in query
    _mysql.connection.query(self, query)
MySQLdb._exceptions.IntegrityError: (1062, "Duplicate entry '1590076800' for key 'LAMProcessData_process_r_acquisition_timestamp_a69ae90c_uniq'")

The above exception was the direct cause of the following exception:

Traceback (most recent call last):
  File "D:\Program Files\Python37\lib\site-packages\apscheduler\scheduler.py", line 512, in _run_job
    retval = job.func(*job.args, **job.kwargs)
  File "E:\1-program\11-LAMDataServer\lamdataserver\LAMProcessData\views.py", line 5269, in regulartime_task
    RT_FineData.Realtime_FineData.init_Tomorrow_rows()
  File "E:\1-program\11-LAMDataServer\lamdataserver\LAMProcessData\process_realtime_finedata.py", line 193, in init_Tomorrow_rows
    _model.objects.bulk_create(insert_data_list)
  File "D:\Program Files\Python37\lib\site-packages\django\db\models\manager.py", line 82, in manager_method
    return getattr(self.get_queryset(), name)(*args, **kwargs)
  File "D:\Program Files\Python37\lib\site-packages\django\db\models\query.py", line 474, in bulk_create
    ids = self._batched_insert(objs_without_pk, fields, batch_size, ignore_conflicts=ignore_conflicts)
  File "D:\Program Files\Python37\lib\site-packages\django\db\models\query.py", line 1211, in _batched_insert
    self._insert(item, fields=fields, using=self.db, ignore_conflicts=ignore_conflicts)
  File "D:\Program Files\Python37\lib\site-packages\django\db\models\query.py", line 1186, in _insert
    return query.get_compiler(using=using).execute_sql(return_id)
  File "D:\Program Files\Python37\lib\site-packages\django\db\models\sql\compiler.py", line 1332, in execute_sql
    cursor.execute(sql, params)
  File "D:\Program Files\Python37\lib\site-packages\django\db\backends\utils.py", line 99, in execute
    return super().execute(sql, params)
  File "D:\Program Files\Python37\lib\site-packages\django\db\backends\utils.py", line 67, in execute
    return self._execute_with_wrappers(sql, params, many=False, executor=self._execute)
  File "D:\Program Files\Python37\lib\site-packages\django\db\backends\utils.py", line 76, in _execute_with_wrappers
    return executor(sql, params, many, context)
  File "D:\Program Files\Python37\lib\site-packages\django\db\backends\utils.py", line 84, in _execute
    return self.cursor.execute(sql, params)
  File "D:\Program Files\Python37\lib\site-packages\django\db\utils.py", line 89, in __exit__
    raise dj_exc_value.with_traceback(traceback) from exc_value
  File "D:\Program Files\Python37\lib\site-packages\django\db\backends\utils.py", line 84, in _execute
    return self.cursor.execute(sql, params)
  File "D:\Program Files\Python37\lib\site-packages\django\db\backends\mysql\base.py", line 71, in execute
    return self.cursor.execute(query, args)
  File "D:\Program Files\Python37\lib\site-packages\MySQLdb\cursors.py", line 209, in execute
    res = self._query(query)
  File "D:\Program Files\Python37\lib\site-packages\MySQLdb\cursors.py", line 315, in _query
    db.query(q)
  File "D:\Program Files\Python37\lib\site-packages\MySQLdb\connections.py", line 239, in query
    _mysql.connection.query(self, query)
django.db.utils.IntegrityError: (1062, "Duplicate entry '1590076800' for key 'LAMProcessData_process_r_acquisition_timestamp_a69ae90c_uniq'")
2020-05-21 Thu 01:54:44 threadpool.py _run_jobs 94 - DEBUG - Exiting worker thread
2020-05-21 Thu 01:55:42 threadpool.py __init__ 52 - INFO - Started thread pool with 0 core threads and 20 maximum threads
2020-05-21 Thu 01:55:42 scheduler.py add_job 287 - INFO - Adding job tentatively -- it will be properly scheduled when the scheduler starts
2020-05-21 Thu 01:55:42 scheduler.py add_job 287 - INFO - Adding job tentatively -- it will be properly scheduled when the scheduler starts
2020-05-21 Thu 01:55:42 scheduler.py add_job 287 - INFO - Adding job tentatively -- it will be properly scheduled when the scheduler starts
2020-05-21 Thu 01:55:42 scheduler.py _real_add_job 262 - INFO - Added job "regulartime_task (trigger: interval[1 day, 0:00:00], next run at: 2020-05-21 01:55:52.284936)" to job store "default"
2020-05-21 Thu 01:55:42 scheduler.py _real_add_job 262 - INFO - Added job "cleanup (trigger: cron[day_of_week='*', hour='3', minute='0', second='0'], next run at: 2020-05-21 03:00:00)" to job store "default"
2020-05-21 Thu 01:55:42 scheduler.py _real_add_job 262 - INFO - Added job "OpenLog (trigger: cron[hour='0'], next run at: 2020-05-22 00:00:00)" to job store "default"
2020-05-21 Thu 01:55:42 scheduler.py _main_loop 574 - INFO - Scheduler started
2020-05-21 Thu 01:55:42 scheduler.py _main_loop 579 - DEBUG - Looking for jobs to run
2020-05-21 Thu 01:55:42 scheduler.py _main_loop 588 - DEBUG - Next wakeup is due at 2020-05-21 01:55:52.284936 (in 9.995536 seconds)
2020-05-21 Thu 01:55:42 query_views.py <module> 64 - DEBUG - SendBefore_NotRecive : [<CNCProcessStatus: CNCProcessStatus object (2038721)>]
2020-05-21 Thu 01:55:42 query_views.py <module> 65 - DEBUG - Waitfor_Recive : [2038721]
2020-05-21 Thu 01:55:52 scheduler.py _main_loop 579 - DEBUG - Looking for jobs to run
2020-05-21 Thu 01:55:52 threadpool.py _run_jobs 69 - DEBUG - Started worker thread
2020-05-21 Thu 01:55:52 scheduler.py _main_loop 588 - DEBUG - Next wakeup is due at 2020-05-21 03:00:00 (in 3847.698471 seconds)
2020-05-21 Thu 01:55:52 scheduler.py _run_job 509 - INFO - Running job "regulartime_task (trigger: interval[1 day, 0:00:00], next run at: 2020-05-22 01:55:52.284936)" (scheduled at 2020-05-21 01:55:52.284936)
2020-05-21 Thu 01:55:53 scheduler.py _run_job 520 - ERROR - Job "regulartime_task (trigger: interval[1 day, 0:00:00], next run at: 2020-05-22 01:55:52.284936)" raised an exception
Traceback (most recent call last):
  File "D:\Program Files\Python37\lib\site-packages\django\db\backends\utils.py", line 84, in _execute
    return self.cursor.execute(sql, params)
  File "D:\Program Files\Python37\lib\site-packages\django\db\backends\mysql\base.py", line 71, in execute
    return self.cursor.execute(query, args)
  File "D:\Program Files\Python37\lib\site-packages\MySQLdb\cursors.py", line 209, in execute
    res = self._query(query)
  File "D:\Program Files\Python37\lib\site-packages\MySQLdb\cursors.py", line 315, in _query
    db.query(q)
  File "D:\Program Files\Python37\lib\site-packages\MySQLdb\connections.py", line 239, in query
    _mysql.connection.query(self, query)
MySQLdb._exceptions.IntegrityError: (1062, "Duplicate entry '1590076800' for key 'LAMProcessData_process_r_acquisition_timestamp_a69ae90c_uniq'")

The above exception was the direct cause of the following exception:

Traceback (most recent call last):
  File "D:\Program Files\Python37\lib\site-packages\apscheduler\scheduler.py", line 512, in _run_job
    retval = job.func(*job.args, **job.kwargs)
  File "E:\1-program\11-LAMDataServer\lamdataserver\LAMProcessData\views.py", line 5269, in regulartime_task
    RT_FineData.Realtime_FineData.init_Tomorrow_rows()
  File "E:\1-program\11-LAMDataServer\lamdataserver\LAMProcessData\process_realtime_finedata.py", line 193, in init_Tomorrow_rows
    _model.objects.bulk_create(insert_data_list)
  File "D:\Program Files\Python37\lib\site-packages\django\db\models\manager.py", line 82, in manager_method
    return getattr(self.get_queryset(), name)(*args, **kwargs)
  File "D:\Program Files\Python37\lib\site-packages\django\db\models\query.py", line 474, in bulk_create
    ids = self._batched_insert(objs_without_pk, fields, batch_size, ignore_conflicts=ignore_conflicts)
  File "D:\Program Files\Python37\lib\site-packages\django\db\models\query.py", line 1211, in _batched_insert
    self._insert(item, fields=fields, using=self.db, ignore_conflicts=ignore_conflicts)
  File "D:\Program Files\Python37\lib\site-packages\django\db\models\query.py", line 1186, in _insert
    return query.get_compiler(using=using).execute_sql(return_id)
  File "D:\Program Files\Python37\lib\site-packages\django\db\models\sql\compiler.py", line 1332, in execute_sql
    cursor.execute(sql, params)
  File "D:\Program Files\Python37\lib\site-packages\django\db\backends\utils.py", line 99, in execute
    return super().execute(sql, params)
  File "D:\Program Files\Python37\lib\site-packages\django\db\backends\utils.py", line 67, in execute
    return self._execute_with_wrappers(sql, params, many=False, executor=self._execute)
  File "D:\Program Files\Python37\lib\site-packages\django\db\backends\utils.py", line 76, in _execute_with_wrappers
    return executor(sql, params, many, context)
  File "D:\Program Files\Python37\lib\site-packages\django\db\backends\utils.py", line 84, in _execute
    return self.cursor.execute(sql, params)
  File "D:\Program Files\Python37\lib\site-packages\django\db\utils.py", line 89, in __exit__
    raise dj_exc_value.with_traceback(traceback) from exc_value
  File "D:\Program Files\Python37\lib\site-packages\django\db\backends\utils.py", line 84, in _execute
    return self.cursor.execute(sql, params)
  File "D:\Program Files\Python37\lib\site-packages\django\db\backends\mysql\base.py", line 71, in execute
    return self.cursor.execute(query, args)
  File "D:\Program Files\Python37\lib\site-packages\MySQLdb\cursors.py", line 209, in execute
    res = self._query(query)
  File "D:\Program Files\Python37\lib\site-packages\MySQLdb\cursors.py", line 315, in _query
    db.query(q)
  File "D:\Program Files\Python37\lib\site-packages\MySQLdb\connections.py", line 239, in query
    _mysql.connection.query(self, query)
django.db.utils.IntegrityError: (1062, "Duplicate entry '1590076800' for key 'LAMProcessData_process_r_acquisition_timestamp_a69ae90c_uniq'")
2020-05-21 Thu 01:55:54 threadpool.py _run_jobs 94 - DEBUG - Exiting worker thread
2020-05-21 Thu 02:00:52 autoreload.py trigger_reload 203 - INFO - E:\1-program\11-LAMDataServer\lamdataserver\LAMProcessData\views.py changed, reloading.
2020-05-21 Thu 02:00:52 threadpool.py shutdown 111 - INFO - Shutting down thread pool
2020-05-21 Thu 02:00:57 threadpool.py __init__ 52 - INFO - Started thread pool with 0 core threads and 20 maximum threads
2020-05-21 Thu 02:00:57 scheduler.py add_job 287 - INFO - Adding job tentatively -- it will be properly scheduled when the scheduler starts
2020-05-21 Thu 02:00:57 scheduler.py add_job 287 - INFO - Adding job tentatively -- it will be properly scheduled when the scheduler starts
2020-05-21 Thu 02:00:57 scheduler.py add_job 287 - INFO - Adding job tentatively -- it will be properly scheduled when the scheduler starts
2020-05-21 Thu 02:00:57 scheduler.py _real_add_job 262 - INFO - Added job "regulartime_task (trigger: interval[1 day, 0:00:00], next run at: 2020-05-21 02:01:07.721619)" to job store "default"
2020-05-21 Thu 02:00:57 scheduler.py _real_add_job 262 - INFO - Added job "cleanup (trigger: cron[day_of_week='*', hour='3', minute='0', second='0'], next run at: 2020-05-21 03:00:00)" to job store "default"
2020-05-21 Thu 02:00:57 scheduler.py _real_add_job 262 - INFO - Added job "OpenLog (trigger: cron[hour='0'], next run at: 2020-05-22 00:00:00)" to job store "default"
2020-05-21 Thu 02:00:57 scheduler.py _main_loop 574 - INFO - Scheduler started
2020-05-21 Thu 02:00:57 scheduler.py _main_loop 579 - DEBUG - Looking for jobs to run
2020-05-21 Thu 02:00:57 scheduler.py _main_loop 588 - DEBUG - Next wakeup is due at 2020-05-21 02:01:07.721619 (in 9.995534 seconds)
2020-05-21 Thu 02:00:57 query_views.py <module> 64 - DEBUG - SendBefore_NotRecive : [<CNCProcessStatus: CNCProcessStatus object (2038721)>]
2020-05-21 Thu 02:00:57 query_views.py <module> 65 - DEBUG - Waitfor_Recive : [2038721]
2020-05-21 Thu 02:01:07 scheduler.py _main_loop 579 - DEBUG - Looking for jobs to run
2020-05-21 Thu 02:01:07 threadpool.py _run_jobs 69 - DEBUG - Started worker thread
2020-05-21 Thu 02:01:07 scheduler.py _main_loop 588 - DEBUG - Next wakeup is due at 2020-05-21 03:00:00 (in 3532.276588 seconds)
2020-05-21 Thu 02:01:07 scheduler.py _run_job 509 - INFO - Running job "regulartime_task (trigger: interval[1 day, 0:00:00], next run at: 2020-05-22 02:01:07.721619)" (scheduled at 2020-05-21 02:01:07.721619)
2020-05-21 Thu 02:01:09 scheduler.py _run_job 520 - ERROR - Job "regulartime_task (trigger: interval[1 day, 0:00:00], next run at: 2020-05-22 02:01:07.721619)" raised an exception
Traceback (most recent call last):
  File "D:\Program Files\Python37\lib\site-packages\django\db\backends\utils.py", line 84, in _execute
    return self.cursor.execute(sql, params)
  File "D:\Program Files\Python37\lib\site-packages\django\db\backends\mysql\base.py", line 71, in execute
    return self.cursor.execute(query, args)
  File "D:\Program Files\Python37\lib\site-packages\MySQLdb\cursors.py", line 209, in execute
    res = self._query(query)
  File "D:\Program Files\Python37\lib\site-packages\MySQLdb\cursors.py", line 315, in _query
    db.query(q)
  File "D:\Program Files\Python37\lib\site-packages\MySQLdb\connections.py", line 239, in query
    _mysql.connection.query(self, query)
MySQLdb._exceptions.IntegrityError: (1062, "Duplicate entry '1590076800' for key 'LAMProcessData_process_r_acquisition_timestamp_a69ae90c_uniq'")

The above exception was the direct cause of the following exception:

Traceback (most recent call last):
  File "D:\Program Files\Python37\lib\site-packages\apscheduler\scheduler.py", line 512, in _run_job
    retval = job.func(*job.args, **job.kwargs)
  File "E:\1-program\11-LAMDataServer\lamdataserver\LAMProcessData\views.py", line 5270, in regulartime_task
    RT_FineData.Realtime_FineData.init_Tomorrow_rows()
  File "E:\1-program\11-LAMDataServer\lamdataserver\LAMProcessData\process_realtime_finedata.py", line 193, in init_Tomorrow_rows
    _model.objects.bulk_create(insert_data_list)
  File "D:\Program Files\Python37\lib\site-packages\django\db\models\manager.py", line 82, in manager_method
    return getattr(self.get_queryset(), name)(*args, **kwargs)
  File "D:\Program Files\Python37\lib\site-packages\django\db\models\query.py", line 474, in bulk_create
    ids = self._batched_insert(objs_without_pk, fields, batch_size, ignore_conflicts=ignore_conflicts)
  File "D:\Program Files\Python37\lib\site-packages\django\db\models\query.py", line 1211, in _batched_insert
    self._insert(item, fields=fields, using=self.db, ignore_conflicts=ignore_conflicts)
  File "D:\Program Files\Python37\lib\site-packages\django\db\models\query.py", line 1186, in _insert
    return query.get_compiler(using=using).execute_sql(return_id)
  File "D:\Program Files\Python37\lib\site-packages\django\db\models\sql\compiler.py", line 1332, in execute_sql
    cursor.execute(sql, params)
  File "D:\Program Files\Python37\lib\site-packages\django\db\backends\utils.py", line 99, in execute
    return super().execute(sql, params)
  File "D:\Program Files\Python37\lib\site-packages\django\db\backends\utils.py", line 67, in execute
    return self._execute_with_wrappers(sql, params, many=False, executor=self._execute)
  File "D:\Program Files\Python37\lib\site-packages\django\db\backends\utils.py", line 76, in _execute_with_wrappers
    return executor(sql, params, many, context)
  File "D:\Program Files\Python37\lib\site-packages\django\db\backends\utils.py", line 84, in _execute
    return self.cursor.execute(sql, params)
  File "D:\Program Files\Python37\lib\site-packages\django\db\utils.py", line 89, in __exit__
    raise dj_exc_value.with_traceback(traceback) from exc_value
  File "D:\Program Files\Python37\lib\site-packages\django\db\backends\utils.py", line 84, in _execute
    return self.cursor.execute(sql, params)
  File "D:\Program Files\Python37\lib\site-packages\django\db\backends\mysql\base.py", line 71, in execute
    return self.cursor.execute(query, args)
  File "D:\Program Files\Python37\lib\site-packages\MySQLdb\cursors.py", line 209, in execute
    res = self._query(query)
  File "D:\Program Files\Python37\lib\site-packages\MySQLdb\cursors.py", line 315, in _query
    db.query(q)
  File "D:\Program Files\Python37\lib\site-packages\MySQLdb\connections.py", line 239, in query
    _mysql.connection.query(self, query)
django.db.utils.IntegrityError: (1062, "Duplicate entry '1590076800' for key 'LAMProcessData_process_r_acquisition_timestamp_a69ae90c_uniq'")
2020-05-21 Thu 02:01:10 threadpool.py _run_jobs 94 - DEBUG - Exiting worker thread
2020-05-21 Thu 02:02:59 autoreload.py trigger_reload 203 - INFO - E:\1-program\11-LAMDataServer\lamdataserver\LAMProcessData\views.py changed, reloading.
2020-05-21 Thu 02:02:59 threadpool.py shutdown 111 - INFO - Shutting down thread pool
2020-05-21 Thu 02:03:02 threadpool.py __init__ 52 - INFO - Started thread pool with 0 core threads and 20 maximum threads
2020-05-21 Thu 02:03:02 scheduler.py add_job 287 - INFO - Adding job tentatively -- it will be properly scheduled when the scheduler starts
2020-05-21 Thu 02:03:02 scheduler.py add_job 287 - INFO - Adding job tentatively -- it will be properly scheduled when the scheduler starts
2020-05-21 Thu 02:03:02 scheduler.py add_job 287 - INFO - Adding job tentatively -- it will be properly scheduled when the scheduler starts
2020-05-21 Thu 02:03:02 scheduler.py _real_add_job 262 - INFO - Added job "regulartime_task (trigger: interval[1 day, 0:00:00], next run at: 2020-05-21 02:03:12.865012)" to job store "default"
2020-05-21 Thu 02:03:02 scheduler.py _real_add_job 262 - INFO - Added job "cleanup (trigger: cron[day_of_week='*', hour='3', minute='0', second='0'], next run at: 2020-05-21 03:00:00)" to job store "default"
2020-05-21 Thu 02:03:02 scheduler.py _real_add_job 262 - INFO - Added job "OpenLog (trigger: cron[hour='0'], next run at: 2020-05-22 00:00:00)" to job store "default"
2020-05-21 Thu 02:03:02 scheduler.py _main_loop 574 - INFO - Scheduler started
2020-05-21 Thu 02:03:02 scheduler.py _main_loop 579 - DEBUG - Looking for jobs to run
2020-05-21 Thu 02:03:02 scheduler.py _main_loop 588 - DEBUG - Next wakeup is due at 2020-05-21 02:03:12.865012 (in 9.995531 seconds)
2020-05-21 Thu 02:03:02 query_views.py <module> 64 - DEBUG - SendBefore_NotRecive : [<CNCProcessStatus: CNCProcessStatus object (2038721)>]
2020-05-21 Thu 02:03:02 query_views.py <module> 65 - DEBUG - Waitfor_Recive : [2038721]
2020-05-21 Thu 02:03:12 scheduler.py _main_loop 579 - DEBUG - Looking for jobs to run
2020-05-21 Thu 02:03:12 threadpool.py _run_jobs 69 - DEBUG - Started worker thread
2020-05-21 Thu 02:03:12 scheduler.py _run_job 509 - INFO - Running job "regulartime_task (trigger: interval[1 day, 0:00:00], next run at: 2020-05-21 02:03:12.865012)" (scheduled at 2020-05-21 02:03:12.865012)
2020-05-21 Thu 02:03:12 scheduler.py _main_loop 588 - DEBUG - Next wakeup is due at 2020-05-21 03:00:00 (in 3407.120573 seconds)
2020-05-21 Thu 02:03:13 scheduler.py _run_job 520 - ERROR - Job "regulartime_task (trigger: interval[1 day, 0:00:00], next run at: 2020-05-22 02:03:12.865012)" raised an exception
Traceback (most recent call last):
  File "D:\Program Files\Python37\lib\site-packages\django\db\backends\utils.py", line 84, in _execute
    return self.cursor.execute(sql, params)
  File "D:\Program Files\Python37\lib\site-packages\django\db\backends\mysql\base.py", line 71, in execute
    return self.cursor.execute(query, args)
  File "D:\Program Files\Python37\lib\site-packages\MySQLdb\cursors.py", line 209, in execute
    res = self._query(query)
  File "D:\Program Files\Python37\lib\site-packages\MySQLdb\cursors.py", line 315, in _query
    db.query(q)
  File "D:\Program Files\Python37\lib\site-packages\MySQLdb\connections.py", line 239, in query
    _mysql.connection.query(self, query)
MySQLdb._exceptions.IntegrityError: (1062, "Duplicate entry '1590076800' for key 'LAMProcessData_process_r_acquisition_timestamp_a69ae90c_uniq'")

The above exception was the direct cause of the following exception:

Traceback (most recent call last):
  File "D:\Program Files\Python37\lib\site-packages\apscheduler\scheduler.py", line 512, in _run_job
    retval = job.func(*job.args, **job.kwargs)
  File "E:\1-program\11-LAMDataServer\lamdataserver\LAMProcessData\views.py", line 5271, in regulartime_task
    RT_FineData.Realtime_FineData.init_Tomorrow_rows()
  File "E:\1-program\11-LAMDataServer\lamdataserver\LAMProcessData\process_realtime_finedata.py", line 193, in init_Tomorrow_rows
    _model.objects.bulk_create(insert_data_list)
  File "D:\Program Files\Python37\lib\site-packages\django\db\models\manager.py", line 82, in manager_method
    return getattr(self.get_queryset(), name)(*args, **kwargs)
  File "D:\Program Files\Python37\lib\site-packages\django\db\models\query.py", line 474, in bulk_create
    ids = self._batched_insert(objs_without_pk, fields, batch_size, ignore_conflicts=ignore_conflicts)
  File "D:\Program Files\Python37\lib\site-packages\django\db\models\query.py", line 1211, in _batched_insert
    self._insert(item, fields=fields, using=self.db, ignore_conflicts=ignore_conflicts)
  File "D:\Program Files\Python37\lib\site-packages\django\db\models\query.py", line 1186, in _insert
    return query.get_compiler(using=using).execute_sql(return_id)
  File "D:\Program Files\Python37\lib\site-packages\django\db\models\sql\compiler.py", line 1332, in execute_sql
    cursor.execute(sql, params)
  File "D:\Program Files\Python37\lib\site-packages\django\db\backends\utils.py", line 99, in execute
    return super().execute(sql, params)
  File "D:\Program Files\Python37\lib\site-packages\django\db\backends\utils.py", line 67, in execute
    return self._execute_with_wrappers(sql, params, many=False, executor=self._execute)
  File "D:\Program Files\Python37\lib\site-packages\django\db\backends\utils.py", line 76, in _execute_with_wrappers
    return executor(sql, params, many, context)
  File "D:\Program Files\Python37\lib\site-packages\django\db\backends\utils.py", line 84, in _execute
    return self.cursor.execute(sql, params)
  File "D:\Program Files\Python37\lib\site-packages\django\db\utils.py", line 89, in __exit__
    raise dj_exc_value.with_traceback(traceback) from exc_value
  File "D:\Program Files\Python37\lib\site-packages\django\db\backends\utils.py", line 84, in _execute
    return self.cursor.execute(sql, params)
  File "D:\Program Files\Python37\lib\site-packages\django\db\backends\mysql\base.py", line 71, in execute
    return self.cursor.execute(query, args)
  File "D:\Program Files\Python37\lib\site-packages\MySQLdb\cursors.py", line 209, in execute
    res = self._query(query)
  File "D:\Program Files\Python37\lib\site-packages\MySQLdb\cursors.py", line 315, in _query
    db.query(q)
  File "D:\Program Files\Python37\lib\site-packages\MySQLdb\connections.py", line 239, in query
    _mysql.connection.query(self, query)
django.db.utils.IntegrityError: (1062, "Duplicate entry '1590076800' for key 'LAMProcessData_process_r_acquisition_timestamp_a69ae90c_uniq'")
2020-05-21 Thu 02:03:14 threadpool.py _run_jobs 94 - DEBUG - Exiting worker thread
2020-05-21 Thu 02:06:12 autoreload.py trigger_reload 203 - INFO - E:\1-program\11-LAMDataServer\lamdataserver\LAMProcessData\views.py changed, reloading.
2020-05-21 Thu 02:06:12 threadpool.py shutdown 111 - INFO - Shutting down thread pool
2020-05-21 Thu 02:06:17 threadpool.py __init__ 52 - INFO - Started thread pool with 0 core threads and 20 maximum threads
2020-05-21 Thu 02:06:17 scheduler.py add_job 287 - INFO - Adding job tentatively -- it will be properly scheduled when the scheduler starts
2020-05-21 Thu 02:06:17 scheduler.py add_job 287 - INFO - Adding job tentatively -- it will be properly scheduled when the scheduler starts
2020-05-21 Thu 02:06:17 scheduler.py add_job 287 - INFO - Adding job tentatively -- it will be properly scheduled when the scheduler starts
2020-05-21 Thu 02:06:17 scheduler.py _real_add_job 262 - INFO - Added job "regulartime_task (trigger: interval[1 day, 0:00:00], next run at: 2020-05-21 02:06:27.730633)" to job store "default"
2020-05-21 Thu 02:06:17 scheduler.py _real_add_job 262 - INFO - Added job "cleanup (trigger: cron[day_of_week='*', hour='3', minute='0', second='0'], next run at: 2020-05-21 03:00:00)" to job store "default"
2020-05-21 Thu 02:06:17 scheduler.py _real_add_job 262 - INFO - Added job "OpenLog (trigger: cron[hour='0'], next run at: 2020-05-22 00:00:00)" to job store "default"
2020-05-21 Thu 02:06:17 scheduler.py _main_loop 574 - INFO - Scheduler started
2020-05-21 Thu 02:06:17 scheduler.py _main_loop 579 - DEBUG - Looking for jobs to run
2020-05-21 Thu 02:06:17 scheduler.py _main_loop 588 - DEBUG - Next wakeup is due at 2020-05-21 02:06:27.730633 (in 9.996033 seconds)
2020-05-21 Thu 02:06:17 query_views.py <module> 64 - DEBUG - SendBefore_NotRecive : [<CNCProcessStatus: CNCProcessStatus object (2038721)>]
2020-05-21 Thu 02:06:17 query_views.py <module> 65 - DEBUG - Waitfor_Recive : [2038721]
2020-05-21 Thu 02:06:27 scheduler.py _main_loop 579 - DEBUG - Looking for jobs to run
2020-05-21 Thu 02:06:27 threadpool.py _run_jobs 69 - DEBUG - Started worker thread
2020-05-21 Thu 02:06:27 scheduler.py _run_job 509 - INFO - Running job "regulartime_task (trigger: interval[1 day, 0:00:00], next run at: 2020-05-21 02:06:27.730633)" (scheduled at 2020-05-21 02:06:27.730633)
2020-05-21 Thu 02:06:27 scheduler.py _main_loop 588 - DEBUG - Next wakeup is due at 2020-05-21 03:00:00 (in 3212.257770 seconds)
2020-05-21 Thu 02:06:28 scheduler.py _run_job 520 - ERROR - Job "regulartime_task (trigger: interval[1 day, 0:00:00], next run at: 2020-05-22 02:06:27.730633)" raised an exception
Traceback (most recent call last):
  File "D:\Program Files\Python37\lib\site-packages\django\db\backends\utils.py", line 84, in _execute
    return self.cursor.execute(sql, params)
  File "D:\Program Files\Python37\lib\site-packages\django\db\backends\mysql\base.py", line 71, in execute
    return self.cursor.execute(query, args)
  File "D:\Program Files\Python37\lib\site-packages\MySQLdb\cursors.py", line 209, in execute
    res = self._query(query)
  File "D:\Program Files\Python37\lib\site-packages\MySQLdb\cursors.py", line 315, in _query
    db.query(q)
  File "D:\Program Files\Python37\lib\site-packages\MySQLdb\connections.py", line 239, in query
    _mysql.connection.query(self, query)
MySQLdb._exceptions.IntegrityError: (1062, "Duplicate entry '1590076800' for key 'LAMProcessData_process_r_acquisition_timestamp_a69ae90c_uniq'")

The above exception was the direct cause of the following exception:

Traceback (most recent call last):
  File "D:\Program Files\Python37\lib\site-packages\apscheduler\scheduler.py", line 512, in _run_job
    retval = job.func(*job.args, **job.kwargs)
  File "E:\1-program\11-LAMDataServer\lamdataserver\LAMProcessData\views.py", line 5273, in regulartime_task
    RT_FineData.Realtime_FineData.init_Tomorrow_rows()
  File "E:\1-program\11-LAMDataServer\lamdataserver\LAMProcessData\process_realtime_finedata.py", line 193, in init_Tomorrow_rows
    _model.objects.bulk_create(insert_data_list)
  File "D:\Program Files\Python37\lib\site-packages\django\db\models\manager.py", line 82, in manager_method
    return getattr(self.get_queryset(), name)(*args, **kwargs)
  File "D:\Program Files\Python37\lib\site-packages\django\db\models\query.py", line 474, in bulk_create
    ids = self._batched_insert(objs_without_pk, fields, batch_size, ignore_conflicts=ignore_conflicts)
  File "D:\Program Files\Python37\lib\site-packages\django\db\models\query.py", line 1211, in _batched_insert
    self._insert(item, fields=fields, using=self.db, ignore_conflicts=ignore_conflicts)
  File "D:\Program Files\Python37\lib\site-packages\django\db\models\query.py", line 1186, in _insert
    return query.get_compiler(using=using).execute_sql(return_id)
  File "D:\Program Files\Python37\lib\site-packages\django\db\models\sql\compiler.py", line 1332, in execute_sql
    cursor.execute(sql, params)
  File "D:\Program Files\Python37\lib\site-packages\django\db\backends\utils.py", line 99, in execute
    return super().execute(sql, params)
  File "D:\Program Files\Python37\lib\site-packages\django\db\backends\utils.py", line 67, in execute
    return self._execute_with_wrappers(sql, params, many=False, executor=self._execute)
  File "D:\Program Files\Python37\lib\site-packages\django\db\backends\utils.py", line 76, in _execute_with_wrappers
    return executor(sql, params, many, context)
  File "D:\Program Files\Python37\lib\site-packages\django\db\backends\utils.py", line 84, in _execute
    return self.cursor.execute(sql, params)
  File "D:\Program Files\Python37\lib\site-packages\django\db\utils.py", line 89, in __exit__
    raise dj_exc_value.with_traceback(traceback) from exc_value
  File "D:\Program Files\Python37\lib\site-packages\django\db\backends\utils.py", line 84, in _execute
    return self.cursor.execute(sql, params)
  File "D:\Program Files\Python37\lib\site-packages\django\db\backends\mysql\base.py", line 71, in execute
    return self.cursor.execute(query, args)
  File "D:\Program Files\Python37\lib\site-packages\MySQLdb\cursors.py", line 209, in execute
    res = self._query(query)
  File "D:\Program Files\Python37\lib\site-packages\MySQLdb\cursors.py", line 315, in _query
    db.query(q)
  File "D:\Program Files\Python37\lib\site-packages\MySQLdb\connections.py", line 239, in query
    _mysql.connection.query(self, query)
django.db.utils.IntegrityError: (1062, "Duplicate entry '1590076800' for key 'LAMProcessData_process_r_acquisition_timestamp_a69ae90c_uniq'")
2020-05-21 Thu 02:06:29 threadpool.py _run_jobs 94 - DEBUG - Exiting worker thread
2020-05-21 Thu 02:08:02 threadpool.py __init__ 52 - INFO - Started thread pool with 0 core threads and 20 maximum threads
2020-05-21 Thu 02:08:02 scheduler.py add_job 287 - INFO - Adding job tentatively -- it will be properly scheduled when the scheduler starts
2020-05-21 Thu 02:08:02 scheduler.py add_job 287 - INFO - Adding job tentatively -- it will be properly scheduled when the scheduler starts
2020-05-21 Thu 02:08:02 scheduler.py add_job 287 - INFO - Adding job tentatively -- it will be properly scheduled when the scheduler starts
2020-05-21 Thu 02:08:02 scheduler.py _real_add_job 262 - INFO - Added job "regulartime_task (trigger: interval[1 day, 0:00:00], next run at: 2020-05-21 02:08:12.469093)" to job store "default"
2020-05-21 Thu 02:08:02 scheduler.py _real_add_job 262 - INFO - Added job "cleanup (trigger: cron[day_of_week='*', hour='3', minute='0', second='0'], next run at: 2020-05-21 03:00:00)" to job store "default"
2020-05-21 Thu 02:08:02 scheduler.py _real_add_job 262 - INFO - Added job "OpenLog (trigger: cron[hour='0'], next run at: 2020-05-22 00:00:00)" to job store "default"
2020-05-21 Thu 02:08:02 scheduler.py _main_loop 574 - INFO - Scheduler started
2020-05-21 Thu 02:08:02 scheduler.py _main_loop 579 - DEBUG - Looking for jobs to run
2020-05-21 Thu 02:08:02 scheduler.py _main_loop 588 - DEBUG - Next wakeup is due at 2020-05-21 02:08:12.469093 (in 9.996034 seconds)
2020-05-21 Thu 02:08:02 query_views.py <module> 63 - DEBUG - SendBefore_NotRecive : [<CNCProcessStatus: CNCProcessStatus object (2038721)>]
2020-05-21 Thu 02:08:02 query_views.py <module> 64 - DEBUG - Waitfor_Recive : [2038721]
2020-05-21 Thu 02:08:12 scheduler.py _main_loop 579 - DEBUG - Looking for jobs to run
2020-05-21 Thu 02:08:12 threadpool.py _run_jobs 69 - DEBUG - Started worker thread
2020-05-21 Thu 02:08:12 scheduler.py _main_loop 588 - DEBUG - Next wakeup is due at 2020-05-21 03:00:00 (in 3107.529082 seconds)
2020-05-21 Thu 02:08:12 scheduler.py _run_job 509 - INFO - Running job "regulartime_task (trigger: interval[1 day, 0:00:00], next run at: 2020-05-22 02:08:12.469093)" (scheduled at 2020-05-21 02:08:12.469093)
2020-05-21 Thu 02:08:12 scheduler.py _run_job 520 - ERROR - Job "regulartime_task (trigger: interval[1 day, 0:00:00], next run at: 2020-05-22 02:08:12.469093)" raised an exception
Traceback (most recent call last):
  File "D:\Program Files\Python37\lib\site-packages\django\db\backends\utils.py", line 84, in _execute
    return self.cursor.execute(sql, params)
  File "D:\Program Files\Python37\lib\site-packages\django\db\backends\mysql\base.py", line 71, in execute
    return self.cursor.execute(query, args)
  File "D:\Program Files\Python37\lib\site-packages\MySQLdb\cursors.py", line 209, in execute
    res = self._query(query)
  File "D:\Program Files\Python37\lib\site-packages\MySQLdb\cursors.py", line 315, in _query
    db.query(q)
  File "D:\Program Files\Python37\lib\site-packages\MySQLdb\connections.py", line 239, in query
    _mysql.connection.query(self, query)
MySQLdb._exceptions.IntegrityError: (1062, "Duplicate entry '1590076800' for key 'LAMProcessData_process_r_acquisition_timestamp_a69ae90c_uniq'")

The above exception was the direct cause of the following exception:

Traceback (most recent call last):
  File "D:\Program Files\Python37\lib\site-packages\apscheduler\scheduler.py", line 512, in _run_job
    retval = job.func(*job.args, **job.kwargs)
  File "E:\1-program\11-LAMDataServer\lamdataserver\LAMProcessData\views.py", line 5273, in regulartime_task
    RT_FineData.Realtime_FineData.init_Tomorrow_rows()
  File "E:\1-program\11-LAMDataServer\lamdataserver\LAMProcessData\process_realtime_finedata.py", line 193, in init_Tomorrow_rows
    _model.objects.bulk_create(insert_data_list)
  File "D:\Program Files\Python37\lib\site-packages\django\db\models\manager.py", line 82, in manager_method
    return getattr(self.get_queryset(), name)(*args, **kwargs)
  File "D:\Program Files\Python37\lib\site-packages\django\db\models\query.py", line 474, in bulk_create
    ids = self._batched_insert(objs_without_pk, fields, batch_size, ignore_conflicts=ignore_conflicts)
  File "D:\Program Files\Python37\lib\site-packages\django\db\models\query.py", line 1211, in _batched_insert
    self._insert(item, fields=fields, using=self.db, ignore_conflicts=ignore_conflicts)
  File "D:\Program Files\Python37\lib\site-packages\django\db\models\query.py", line 1186, in _insert
    return query.get_compiler(using=using).execute_sql(return_id)
  File "D:\Program Files\Python37\lib\site-packages\django\db\models\sql\compiler.py", line 1332, in execute_sql
    cursor.execute(sql, params)
  File "D:\Program Files\Python37\lib\site-packages\django\db\backends\utils.py", line 99, in execute
    return super().execute(sql, params)
  File "D:\Program Files\Python37\lib\site-packages\django\db\backends\utils.py", line 67, in execute
    return self._execute_with_wrappers(sql, params, many=False, executor=self._execute)
  File "D:\Program Files\Python37\lib\site-packages\django\db\backends\utils.py", line 76, in _execute_with_wrappers
    return executor(sql, params, many, context)
  File "D:\Program Files\Python37\lib\site-packages\django\db\backends\utils.py", line 84, in _execute
    return self.cursor.execute(sql, params)
  File "D:\Program Files\Python37\lib\site-packages\django\db\utils.py", line 89, in __exit__
    raise dj_exc_value.with_traceback(traceback) from exc_value
  File "D:\Program Files\Python37\lib\site-packages\django\db\backends\utils.py", line 84, in _execute
    return self.cursor.execute(sql, params)
  File "D:\Program Files\Python37\lib\site-packages\django\db\backends\mysql\base.py", line 71, in execute
    return self.cursor.execute(query, args)
  File "D:\Program Files\Python37\lib\site-packages\MySQLdb\cursors.py", line 209, in execute
    res = self._query(query)
  File "D:\Program Files\Python37\lib\site-packages\MySQLdb\cursors.py", line 315, in _query
    db.query(q)
  File "D:\Program Files\Python37\lib\site-packages\MySQLdb\connections.py", line 239, in query
    _mysql.connection.query(self, query)
django.db.utils.IntegrityError: (1062, "Duplicate entry '1590076800' for key 'LAMProcessData_process_r_acquisition_timestamp_a69ae90c_uniq'")
2020-05-21 Thu 02:08:13 threadpool.py _run_jobs 94 - DEBUG - Exiting worker thread
2020-05-21 Thu 02:13:23 autoreload.py trigger_reload 203 - INFO - E:\1-program\11-LAMDataServer\lamdataserver\LAMProcessData\views.py changed, reloading.
2020-05-21 Thu 02:13:23 threadpool.py shutdown 111 - INFO - Shutting down thread pool
2020-05-21 Thu 02:13:26 threadpool.py __init__ 52 - INFO - Started thread pool with 0 core threads and 20 maximum threads
2020-05-21 Thu 02:13:26 scheduler.py add_job 287 - INFO - Adding job tentatively -- it will be properly scheduled when the scheduler starts
2020-05-21 Thu 02:13:26 scheduler.py add_job 287 - INFO - Adding job tentatively -- it will be properly scheduled when the scheduler starts
2020-05-21 Thu 02:13:26 scheduler.py add_job 287 - INFO - Adding job tentatively -- it will be properly scheduled when the scheduler starts
2020-05-21 Thu 02:13:26 scheduler.py _real_add_job 262 - INFO - Added job "regulartime_task (trigger: interval[1 day, 0:00:00], next run at: 2020-05-21 02:13:36.178751)" to job store "default"
2020-05-21 Thu 02:13:26 scheduler.py _real_add_job 262 - INFO - Added job "cleanup (trigger: cron[day_of_week='*', hour='3', minute='0', second='0'], next run at: 2020-05-21 03:00:00)" to job store "default"
2020-05-21 Thu 02:13:26 scheduler.py _real_add_job 262 - INFO - Added job "OpenLog (trigger: cron[hour='0'], next run at: 2020-05-22 00:00:00)" to job store "default"
2020-05-21 Thu 02:13:26 scheduler.py _main_loop 574 - INFO - Scheduler started
2020-05-21 Thu 02:13:26 scheduler.py _main_loop 579 - DEBUG - Looking for jobs to run
2020-05-21 Thu 02:13:26 scheduler.py _main_loop 588 - DEBUG - Next wakeup is due at 2020-05-21 02:13:36.178751 (in 9.998017 seconds)
2020-05-21 Thu 02:13:26 query_views.py <module> 63 - DEBUG - SendBefore_NotRecive : [<CNCProcessStatus: CNCProcessStatus object (2038721)>]
2020-05-21 Thu 02:13:26 query_views.py <module> 64 - DEBUG - Waitfor_Recive : [2038721]
2020-05-21 Thu 02:13:36 scheduler.py _main_loop 579 - DEBUG - Looking for jobs to run
2020-05-21 Thu 02:13:36 threadpool.py _run_jobs 69 - DEBUG - Started worker thread
2020-05-21 Thu 02:13:36 scheduler.py _run_job 509 - INFO - Running job "regulartime_task (trigger: interval[1 day, 0:00:00], next run at: 2020-05-21 02:13:36.178751)" (scheduled at 2020-05-21 02:13:36.178751)
2020-05-21 Thu 02:13:36 scheduler.py _main_loop 588 - DEBUG - Next wakeup is due at 2020-05-21 03:00:00 (in 2783.818985 seconds)
2020-05-21 Thu 02:13:36 scheduler.py _run_job 520 - ERROR - Job "regulartime_task (trigger: interval[1 day, 0:00:00], next run at: 2020-05-22 02:13:36.178751)" raised an exception
Traceback (most recent call last):
  File "D:\Program Files\Python37\lib\site-packages\django\db\backends\utils.py", line 84, in _execute
    return self.cursor.execute(sql, params)
  File "D:\Program Files\Python37\lib\site-packages\django\db\backends\mysql\base.py", line 71, in execute
    return self.cursor.execute(query, args)
  File "D:\Program Files\Python37\lib\site-packages\MySQLdb\cursors.py", line 209, in execute
    res = self._query(query)
  File "D:\Program Files\Python37\lib\site-packages\MySQLdb\cursors.py", line 315, in _query
    db.query(q)
  File "D:\Program Files\Python37\lib\site-packages\MySQLdb\connections.py", line 239, in query
    _mysql.connection.query(self, query)
MySQLdb._exceptions.IntegrityError: (1062, "Duplicate entry '1590076800' for key 'LAMProcessData_process_r_acquisition_timestamp_a69ae90c_uniq'")

The above exception was the direct cause of the following exception:

Traceback (most recent call last):
  File "D:\Program Files\Python37\lib\site-packages\apscheduler\scheduler.py", line 512, in _run_job
    retval = job.func(*job.args, **job.kwargs)
  File "E:\1-program\11-LAMDataServer\lamdataserver\LAMProcessData\views.py", line 5270, in regulartime_task
    RT_FineData.Realtime_FineData.init_Tomorrow_rows()
  File "E:\1-program\11-LAMDataServer\lamdataserver\LAMProcessData\process_realtime_finedata.py", line 193, in init_Tomorrow_rows
    _model.objects.bulk_create(insert_data_list)
  File "D:\Program Files\Python37\lib\site-packages\django\db\models\manager.py", line 82, in manager_method
    return getattr(self.get_queryset(), name)(*args, **kwargs)
  File "D:\Program Files\Python37\lib\site-packages\django\db\models\query.py", line 474, in bulk_create
    ids = self._batched_insert(objs_without_pk, fields, batch_size, ignore_conflicts=ignore_conflicts)
  File "D:\Program Files\Python37\lib\site-packages\django\db\models\query.py", line 1211, in _batched_insert
    self._insert(item, fields=fields, using=self.db, ignore_conflicts=ignore_conflicts)
  File "D:\Program Files\Python37\lib\site-packages\django\db\models\query.py", line 1186, in _insert
    return query.get_compiler(using=using).execute_sql(return_id)
  File "D:\Program Files\Python37\lib\site-packages\django\db\models\sql\compiler.py", line 1332, in execute_sql
    cursor.execute(sql, params)
  File "D:\Program Files\Python37\lib\site-packages\django\db\backends\utils.py", line 99, in execute
    return super().execute(sql, params)
  File "D:\Program Files\Python37\lib\site-packages\django\db\backends\utils.py", line 67, in execute
    return self._execute_with_wrappers(sql, params, many=False, executor=self._execute)
  File "D:\Program Files\Python37\lib\site-packages\django\db\backends\utils.py", line 76, in _execute_with_wrappers
    return executor(sql, params, many, context)
  File "D:\Program Files\Python37\lib\site-packages\django\db\backends\utils.py", line 84, in _execute
    return self.cursor.execute(sql, params)
  File "D:\Program Files\Python37\lib\site-packages\django\db\utils.py", line 89, in __exit__
    raise dj_exc_value.with_traceback(traceback) from exc_value
  File "D:\Program Files\Python37\lib\site-packages\django\db\backends\utils.py", line 84, in _execute
    return self.cursor.execute(sql, params)
  File "D:\Program Files\Python37\lib\site-packages\django\db\backends\mysql\base.py", line 71, in execute
    return self.cursor.execute(query, args)
  File "D:\Program Files\Python37\lib\site-packages\MySQLdb\cursors.py", line 209, in execute
    res = self._query(query)
  File "D:\Program Files\Python37\lib\site-packages\MySQLdb\cursors.py", line 315, in _query
    db.query(q)
  File "D:\Program Files\Python37\lib\site-packages\MySQLdb\connections.py", line 239, in query
    _mysql.connection.query(self, query)
django.db.utils.IntegrityError: (1062, "Duplicate entry '1590076800' for key 'LAMProcessData_process_r_acquisition_timestamp_a69ae90c_uniq'")
2020-05-21 Thu 02:13:37 threadpool.py _run_jobs 94 - DEBUG - Exiting worker thread
2020-05-21 Thu 02:13:57 threadpool.py __init__ 52 - INFO - Started thread pool with 0 core threads and 20 maximum threads
2020-05-21 Thu 02:13:57 scheduler.py add_job 287 - INFO - Adding job tentatively -- it will be properly scheduled when the scheduler starts
2020-05-21 Thu 02:13:57 scheduler.py add_job 287 - INFO - Adding job tentatively -- it will be properly scheduled when the scheduler starts
2020-05-21 Thu 02:13:57 scheduler.py add_job 287 - INFO - Adding job tentatively -- it will be properly scheduled when the scheduler starts
2020-05-21 Thu 02:13:57 scheduler.py _real_add_job 262 - INFO - Added job "regulartime_task (trigger: interval[1 day, 0:00:00], next run at: 2020-05-21 02:14:07.555385)" to job store "default"
2020-05-21 Thu 02:13:57 scheduler.py _real_add_job 262 - INFO - Added job "cleanup (trigger: cron[day_of_week='*', hour='3', minute='0', second='0'], next run at: 2020-05-21 03:00:00)" to job store "default"
2020-05-21 Thu 02:13:57 scheduler.py _real_add_job 262 - INFO - Added job "OpenLog (trigger: cron[hour='0'], next run at: 2020-05-22 00:00:00)" to job store "default"
2020-05-21 Thu 02:13:57 scheduler.py _main_loop 574 - INFO - Scheduler started
2020-05-21 Thu 02:13:57 scheduler.py _main_loop 579 - DEBUG - Looking for jobs to run
2020-05-21 Thu 02:13:57 scheduler.py _main_loop 588 - DEBUG - Next wakeup is due at 2020-05-21 02:14:07.555385 (in 9.995045 seconds)
2020-05-21 Thu 02:13:57 query_views.py <module> 63 - DEBUG - SendBefore_NotRecive : [<CNCProcessStatus: CNCProcessStatus object (2038721)>]
2020-05-21 Thu 02:13:57 query_views.py <module> 64 - DEBUG - Waitfor_Recive : [2038721]
2020-05-21 Thu 02:14:07 scheduler.py _main_loop 579 - DEBUG - Looking for jobs to run
2020-05-21 Thu 02:14:07 threadpool.py _run_jobs 69 - DEBUG - Started worker thread
2020-05-21 Thu 02:14:07 scheduler.py _run_job 509 - INFO - Running job "regulartime_task (trigger: interval[1 day, 0:00:00], next run at: 2020-05-21 02:14:07.555385)" (scheduled at 2020-05-21 02:14:07.555385)
2020-05-21 Thu 02:14:07 scheduler.py _main_loop 588 - DEBUG - Next wakeup is due at 2020-05-21 03:00:00 (in 2752.442815 seconds)
2020-05-21 Thu 02:14:07 scheduler.py _run_job 520 - ERROR - Job "regulartime_task (trigger: interval[1 day, 0:00:00], next run at: 2020-05-22 02:14:07.555385)" raised an exception
Traceback (most recent call last):
  File "D:\Program Files\Python37\lib\site-packages\django\db\backends\utils.py", line 84, in _execute
    return self.cursor.execute(sql, params)
  File "D:\Program Files\Python37\lib\site-packages\django\db\backends\mysql\base.py", line 71, in execute
    return self.cursor.execute(query, args)
  File "D:\Program Files\Python37\lib\site-packages\MySQLdb\cursors.py", line 209, in execute
    res = self._query(query)
  File "D:\Program Files\Python37\lib\site-packages\MySQLdb\cursors.py", line 315, in _query
    db.query(q)
  File "D:\Program Files\Python37\lib\site-packages\MySQLdb\connections.py", line 239, in query
    _mysql.connection.query(self, query)
MySQLdb._exceptions.IntegrityError: (1062, "Duplicate entry '1590076800' for key 'LAMProcessData_process_r_acquisition_timestamp_a69ae90c_uniq'")

The above exception was the direct cause of the following exception:

Traceback (most recent call last):
  File "D:\Program Files\Python37\lib\site-packages\apscheduler\scheduler.py", line 512, in _run_job
    retval = job.func(*job.args, **job.kwargs)
  File "E:\1-program\11-LAMDataServer\lamdataserver\LAMProcessData\views.py", line 5270, in regulartime_task
    RT_FineData.Realtime_FineData.init_Tomorrow_rows()
  File "E:\1-program\11-LAMDataServer\lamdataserver\LAMProcessData\process_realtime_finedata.py", line 193, in init_Tomorrow_rows
    _model.objects.bulk_create(insert_data_list)
  File "D:\Program Files\Python37\lib\site-packages\django\db\models\manager.py", line 82, in manager_method
    return getattr(self.get_queryset(), name)(*args, **kwargs)
  File "D:\Program Files\Python37\lib\site-packages\django\db\models\query.py", line 474, in bulk_create
    ids = self._batched_insert(objs_without_pk, fields, batch_size, ignore_conflicts=ignore_conflicts)
  File "D:\Program Files\Python37\lib\site-packages\django\db\models\query.py", line 1211, in _batched_insert
    self._insert(item, fields=fields, using=self.db, ignore_conflicts=ignore_conflicts)
  File "D:\Program Files\Python37\lib\site-packages\django\db\models\query.py", line 1186, in _insert
    return query.get_compiler(using=using).execute_sql(return_id)
  File "D:\Program Files\Python37\lib\site-packages\django\db\models\sql\compiler.py", line 1332, in execute_sql
    cursor.execute(sql, params)
  File "D:\Program Files\Python37\lib\site-packages\django\db\backends\utils.py", line 99, in execute
    return super().execute(sql, params)
  File "D:\Program Files\Python37\lib\site-packages\django\db\backends\utils.py", line 67, in execute
    return self._execute_with_wrappers(sql, params, many=False, executor=self._execute)
  File "D:\Program Files\Python37\lib\site-packages\django\db\backends\utils.py", line 76, in _execute_with_wrappers
    return executor(sql, params, many, context)
  File "D:\Program Files\Python37\lib\site-packages\django\db\backends\utils.py", line 84, in _execute
    return self.cursor.execute(sql, params)
  File "D:\Program Files\Python37\lib\site-packages\django\db\utils.py", line 89, in __exit__
    raise dj_exc_value.with_traceback(traceback) from exc_value
  File "D:\Program Files\Python37\lib\site-packages\django\db\backends\utils.py", line 84, in _execute
    return self.cursor.execute(sql, params)
  File "D:\Program Files\Python37\lib\site-packages\django\db\backends\mysql\base.py", line 71, in execute
    return self.cursor.execute(query, args)
  File "D:\Program Files\Python37\lib\site-packages\MySQLdb\cursors.py", line 209, in execute
    res = self._query(query)
  File "D:\Program Files\Python37\lib\site-packages\MySQLdb\cursors.py", line 315, in _query
    db.query(q)
  File "D:\Program Files\Python37\lib\site-packages\MySQLdb\connections.py", line 239, in query
    _mysql.connection.query(self, query)
django.db.utils.IntegrityError: (1062, "Duplicate entry '1590076800' for key 'LAMProcessData_process_r_acquisition_timestamp_a69ae90c_uniq'")
2020-05-21 Thu 02:14:08 threadpool.py _run_jobs 94 - DEBUG - Exiting worker thread
2020-05-21 Thu 02:19:31 autoreload.py trigger_reload 203 - INFO - E:\1-program\11-LAMDataServer\lamdataserver\LAMProcessData\forms.py changed, reloading.
2020-05-21 Thu 02:19:31 threadpool.py shutdown 111 - INFO - Shutting down thread pool
2020-05-21 Thu 02:19:35 threadpool.py __init__ 52 - INFO - Started thread pool with 0 core threads and 20 maximum threads
2020-05-21 Thu 02:19:35 scheduler.py add_job 287 - INFO - Adding job tentatively -- it will be properly scheduled when the scheduler starts
2020-05-21 Thu 02:19:35 scheduler.py add_job 287 - INFO - Adding job tentatively -- it will be properly scheduled when the scheduler starts
2020-05-21 Thu 02:19:35 scheduler.py add_job 287 - INFO - Adding job tentatively -- it will be properly scheduled when the scheduler starts
2020-05-21 Thu 02:19:35 scheduler.py _real_add_job 262 - INFO - Added job "regulartime_task (trigger: interval[1 day, 0:00:00], next run at: 2020-05-21 02:19:45.546327)" to job store "default"
2020-05-21 Thu 02:19:35 scheduler.py _real_add_job 262 - INFO - Added job "cleanup (trigger: cron[day_of_week='*', hour='3', minute='0', second='0'], next run at: 2020-05-21 03:00:00)" to job store "default"
2020-05-21 Thu 02:19:35 scheduler.py _real_add_job 262 - INFO - Added job "OpenLog (trigger: cron[hour='0'], next run at: 2020-05-22 00:00:00)" to job store "default"
2020-05-21 Thu 02:19:35 scheduler.py _main_loop 574 - INFO - Scheduler started
2020-05-21 Thu 02:19:35 scheduler.py _main_loop 579 - DEBUG - Looking for jobs to run
2020-05-21 Thu 02:19:35 scheduler.py _main_loop 588 - DEBUG - Next wakeup is due at 2020-05-21 02:19:45.546327 (in 9.997024 seconds)
2020-05-21 Thu 02:19:35 query_views.py <module> 63 - DEBUG - SendBefore_NotRecive : [<CNCProcessStatus: CNCProcessStatus object (2038721)>]
2020-05-21 Thu 02:19:35 query_views.py <module> 64 - DEBUG - Waitfor_Recive : [2038721]
2020-05-21 Thu 02:19:38 autoreload.py trigger_reload 203 - INFO - E:\1-program\11-LAMDataServer\lamdataserver\LAMProcessData\forms.py changed, reloading.
2020-05-21 Thu 02:19:38 threadpool.py shutdown 111 - INFO - Shutting down thread pool
2020-05-21 Thu 02:19:41 threadpool.py __init__ 52 - INFO - Started thread pool with 0 core threads and 20 maximum threads
2020-05-21 Thu 02:19:41 scheduler.py add_job 287 - INFO - Adding job tentatively -- it will be properly scheduled when the scheduler starts
2020-05-21 Thu 02:19:41 scheduler.py add_job 287 - INFO - Adding job tentatively -- it will be properly scheduled when the scheduler starts
2020-05-21 Thu 02:19:41 scheduler.py add_job 287 - INFO - Adding job tentatively -- it will be properly scheduled when the scheduler starts
2020-05-21 Thu 02:19:41 scheduler.py _real_add_job 262 - INFO - Added job "regulartime_task (trigger: interval[1 day, 0:00:00], next run at: 2020-05-21 02:19:51.672107)" to job store "default"
2020-05-21 Thu 02:19:41 scheduler.py _real_add_job 262 - INFO - Added job "cleanup (trigger: cron[day_of_week='*', hour='3', minute='0', second='0'], next run at: 2020-05-21 03:00:00)" to job store "default"
2020-05-21 Thu 02:19:41 scheduler.py _real_add_job 262 - INFO - Added job "OpenLog (trigger: cron[hour='0'], next run at: 2020-05-22 00:00:00)" to job store "default"
2020-05-21 Thu 02:19:41 scheduler.py _main_loop 574 - INFO - Scheduler started
2020-05-21 Thu 02:19:41 scheduler.py _main_loop 579 - DEBUG - Looking for jobs to run
2020-05-21 Thu 02:19:41 scheduler.py _main_loop 588 - DEBUG - Next wakeup is due at 2020-05-21 02:19:51.672107 (in 9.998022 seconds)
2020-05-21 Thu 02:19:41 query_views.py <module> 63 - DEBUG - SendBefore_NotRecive : [<CNCProcessStatus: CNCProcessStatus object (2038721)>]
2020-05-21 Thu 02:19:41 query_views.py <module> 64 - DEBUG - Waitfor_Recive : [2038721]
2020-05-21 Thu 02:19:51 scheduler.py _main_loop 579 - DEBUG - Looking for jobs to run
2020-05-21 Thu 02:19:51 threadpool.py _run_jobs 69 - DEBUG - Started worker thread
2020-05-21 Thu 02:19:51 scheduler.py _main_loop 588 - DEBUG - Next wakeup is due at 2020-05-21 03:00:00 (in 2408.325528 seconds)
2020-05-21 Thu 02:19:51 scheduler.py _run_job 509 - INFO - Running job "regulartime_task (trigger: interval[1 day, 0:00:00], next run at: 2020-05-22 02:19:51.672107)" (scheduled at 2020-05-21 02:19:51.672107)
2020-05-21 Thu 02:19:52 scheduler.py _run_job 520 - ERROR - Job "regulartime_task (trigger: interval[1 day, 0:00:00], next run at: 2020-05-22 02:19:51.672107)" raised an exception
Traceback (most recent call last):
  File "D:\Program Files\Python37\lib\site-packages\django\db\backends\utils.py", line 84, in _execute
    return self.cursor.execute(sql, params)
  File "D:\Program Files\Python37\lib\site-packages\django\db\backends\mysql\base.py", line 71, in execute
    return self.cursor.execute(query, args)
  File "D:\Program Files\Python37\lib\site-packages\MySQLdb\cursors.py", line 209, in execute
    res = self._query(query)
  File "D:\Program Files\Python37\lib\site-packages\MySQLdb\cursors.py", line 315, in _query
    db.query(q)
  File "D:\Program Files\Python37\lib\site-packages\MySQLdb\connections.py", line 239, in query
    _mysql.connection.query(self, query)
MySQLdb._exceptions.IntegrityError: (1062, "Duplicate entry '1590076800' for key 'LAMProcessData_process_r_acquisition_timestamp_a69ae90c_uniq'")

The above exception was the direct cause of the following exception:

Traceback (most recent call last):
  File "D:\Program Files\Python37\lib\site-packages\apscheduler\scheduler.py", line 512, in _run_job
    retval = job.func(*job.args, **job.kwargs)
  File "E:\1-program\11-LAMDataServer\lamdataserver\LAMProcessData\views.py", line 5270, in regulartime_task
    RT_FineData.Realtime_FineData.init_Tomorrow_rows()
  File "E:\1-program\11-LAMDataServer\lamdataserver\LAMProcessData\process_realtime_finedata.py", line 193, in init_Tomorrow_rows
    _model.objects.bulk_create(insert_data_list)
  File "D:\Program Files\Python37\lib\site-packages\django\db\models\manager.py", line 82, in manager_method
    return getattr(self.get_queryset(), name)(*args, **kwargs)
  File "D:\Program Files\Python37\lib\site-packages\django\db\models\query.py", line 474, in bulk_create
    ids = self._batched_insert(objs_without_pk, fields, batch_size, ignore_conflicts=ignore_conflicts)
  File "D:\Program Files\Python37\lib\site-packages\django\db\models\query.py", line 1211, in _batched_insert
    self._insert(item, fields=fields, using=self.db, ignore_conflicts=ignore_conflicts)
  File "D:\Program Files\Python37\lib\site-packages\django\db\models\query.py", line 1186, in _insert
    return query.get_compiler(using=using).execute_sql(return_id)
  File "D:\Program Files\Python37\lib\site-packages\django\db\models\sql\compiler.py", line 1332, in execute_sql
    cursor.execute(sql, params)
  File "D:\Program Files\Python37\lib\site-packages\django\db\backends\utils.py", line 99, in execute
    return super().execute(sql, params)
  File "D:\Program Files\Python37\lib\site-packages\django\db\backends\utils.py", line 67, in execute
    return self._execute_with_wrappers(sql, params, many=False, executor=self._execute)
  File "D:\Program Files\Python37\lib\site-packages\django\db\backends\utils.py", line 76, in _execute_with_wrappers
    return executor(sql, params, many, context)
  File "D:\Program Files\Python37\lib\site-packages\django\db\backends\utils.py", line 84, in _execute
    return self.cursor.execute(sql, params)
  File "D:\Program Files\Python37\lib\site-packages\django\db\utils.py", line 89, in __exit__
    raise dj_exc_value.with_traceback(traceback) from exc_value
  File "D:\Program Files\Python37\lib\site-packages\django\db\backends\utils.py", line 84, in _execute
    return self.cursor.execute(sql, params)
  File "D:\Program Files\Python37\lib\site-packages\django\db\backends\mysql\base.py", line 71, in execute
    return self.cursor.execute(query, args)
  File "D:\Program Files\Python37\lib\site-packages\MySQLdb\cursors.py", line 209, in execute
    res = self._query(query)
  File "D:\Program Files\Python37\lib\site-packages\MySQLdb\cursors.py", line 315, in _query
    db.query(q)
  File "D:\Program Files\Python37\lib\site-packages\MySQLdb\connections.py", line 239, in query
    _mysql.connection.query(self, query)
django.db.utils.IntegrityError: (1062, "Duplicate entry '1590076800' for key 'LAMProcessData_process_r_acquisition_timestamp_a69ae90c_uniq'")
2020-05-21 Thu 02:19:53 threadpool.py _run_jobs 94 - DEBUG - Exiting worker thread
2020-05-21 Thu 02:21:05 autoreload.py trigger_reload 203 - INFO - E:\1-program\11-LAMDataServer\lamdataserver\LAMProcessData\views.py changed, reloading.
2020-05-21 Thu 02:21:05 threadpool.py shutdown 111 - INFO - Shutting down thread pool
2020-05-21 Thu 02:21:07 threadpool.py __init__ 52 - INFO - Started thread pool with 0 core threads and 20 maximum threads
2020-05-21 Thu 02:21:07 scheduler.py add_job 287 - INFO - Adding job tentatively -- it will be properly scheduled when the scheduler starts
2020-05-21 Thu 02:21:07 scheduler.py add_job 287 - INFO - Adding job tentatively -- it will be properly scheduled when the scheduler starts
2020-05-21 Thu 02:21:07 scheduler.py add_job 287 - INFO - Adding job tentatively -- it will be properly scheduled when the scheduler starts
2020-05-21 Thu 02:21:07 scheduler.py _real_add_job 262 - INFO - Added job "regulartime_task (trigger: interval[1 day, 0:00:00], next run at: 2020-05-21 02:21:17.626569)" to job store "default"
2020-05-21 Thu 02:21:07 scheduler.py _real_add_job 262 - INFO - Added job "cleanup (trigger: cron[day_of_week='*', hour='3', minute='0', second='0'], next run at: 2020-05-21 03:00:00)" to job store "default"
2020-05-21 Thu 02:21:07 scheduler.py _real_add_job 262 - INFO - Added job "OpenLog (trigger: cron[hour='0'], next run at: 2020-05-22 00:00:00)" to job store "default"
2020-05-21 Thu 02:21:07 scheduler.py _main_loop 574 - INFO - Scheduler started
2020-05-21 Thu 02:21:07 scheduler.py _main_loop 579 - DEBUG - Looking for jobs to run
2020-05-21 Thu 02:21:07 scheduler.py _main_loop 588 - DEBUG - Next wakeup is due at 2020-05-21 02:21:17.626569 (in 9.998042 seconds)
2020-05-21 Thu 02:21:07 query_views.py <module> 63 - DEBUG - SendBefore_NotRecive : [<CNCProcessStatus: CNCProcessStatus object (2038721)>]
2020-05-21 Thu 02:21:07 query_views.py <module> 64 - DEBUG - Waitfor_Recive : [2038721]
2020-05-21 Thu 02:21:17 scheduler.py _main_loop 579 - DEBUG - Looking for jobs to run
2020-05-21 Thu 02:21:17 threadpool.py _run_jobs 69 - DEBUG - Started worker thread
2020-05-21 Thu 02:21:17 scheduler.py _run_job 509 - INFO - Running job "regulartime_task (trigger: interval[1 day, 0:00:00], next run at: 2020-05-21 02:21:17.626569)" (scheduled at 2020-05-21 02:21:17.626569)
2020-05-21 Thu 02:21:17 scheduler.py _main_loop 588 - DEBUG - Next wakeup is due at 2020-05-21 03:00:00 (in 2322.371862 seconds)
2020-05-21 Thu 02:21:17 scheduler.py _run_job 520 - ERROR - Job "regulartime_task (trigger: interval[1 day, 0:00:00], next run at: 2020-05-22 02:21:17.626569)" raised an exception
Traceback (most recent call last):
  File "D:\Program Files\Python37\lib\site-packages\django\db\backends\utils.py", line 84, in _execute
    return self.cursor.execute(sql, params)
  File "D:\Program Files\Python37\lib\site-packages\django\db\backends\mysql\base.py", line 71, in execute
    return self.cursor.execute(query, args)
  File "D:\Program Files\Python37\lib\site-packages\MySQLdb\cursors.py", line 209, in execute
    res = self._query(query)
  File "D:\Program Files\Python37\lib\site-packages\MySQLdb\cursors.py", line 315, in _query
    db.query(q)
  File "D:\Program Files\Python37\lib\site-packages\MySQLdb\connections.py", line 239, in query
    _mysql.connection.query(self, query)
MySQLdb._exceptions.IntegrityError: (1062, "Duplicate entry '1590076800' for key 'LAMProcessData_process_r_acquisition_timestamp_a69ae90c_uniq'")

The above exception was the direct cause of the following exception:

Traceback (most recent call last):
  File "D:\Program Files\Python37\lib\site-packages\apscheduler\scheduler.py", line 512, in _run_job
    retval = job.func(*job.args, **job.kwargs)
  File "E:\1-program\11-LAMDataServer\lamdataserver\LAMProcessData\views.py", line 5271, in regulartime_task
    RT_FineData.Realtime_FineData.init_Tomorrow_rows()
  File "E:\1-program\11-LAMDataServer\lamdataserver\LAMProcessData\process_realtime_finedata.py", line 193, in init_Tomorrow_rows
    _model.objects.bulk_create(insert_data_list)
  File "D:\Program Files\Python37\lib\site-packages\django\db\models\manager.py", line 82, in manager_method
    return getattr(self.get_queryset(), name)(*args, **kwargs)
  File "D:\Program Files\Python37\lib\site-packages\django\db\models\query.py", line 474, in bulk_create
    ids = self._batched_insert(objs_without_pk, fields, batch_size, ignore_conflicts=ignore_conflicts)
  File "D:\Program Files\Python37\lib\site-packages\django\db\models\query.py", line 1211, in _batched_insert
    self._insert(item, fields=fields, using=self.db, ignore_conflicts=ignore_conflicts)
  File "D:\Program Files\Python37\lib\site-packages\django\db\models\query.py", line 1186, in _insert
    return query.get_compiler(using=using).execute_sql(return_id)
  File "D:\Program Files\Python37\lib\site-packages\django\db\models\sql\compiler.py", line 1332, in execute_sql
    cursor.execute(sql, params)
  File "D:\Program Files\Python37\lib\site-packages\django\db\backends\utils.py", line 99, in execute
    return super().execute(sql, params)
  File "D:\Program Files\Python37\lib\site-packages\django\db\backends\utils.py", line 67, in execute
    return self._execute_with_wrappers(sql, params, many=False, executor=self._execute)
  File "D:\Program Files\Python37\lib\site-packages\django\db\backends\utils.py", line 76, in _execute_with_wrappers
    return executor(sql, params, many, context)
  File "D:\Program Files\Python37\lib\site-packages\django\db\backends\utils.py", line 84, in _execute
    return self.cursor.execute(sql, params)
  File "D:\Program Files\Python37\lib\site-packages\django\db\utils.py", line 89, in __exit__
    raise dj_exc_value.with_traceback(traceback) from exc_value
  File "D:\Program Files\Python37\lib\site-packages\django\db\backends\utils.py", line 84, in _execute
    return self.cursor.execute(sql, params)
  File "D:\Program Files\Python37\lib\site-packages\django\db\backends\mysql\base.py", line 71, in execute
    return self.cursor.execute(query, args)
  File "D:\Program Files\Python37\lib\site-packages\MySQLdb\cursors.py", line 209, in execute
    res = self._query(query)
  File "D:\Program Files\Python37\lib\site-packages\MySQLdb\cursors.py", line 315, in _query
    db.query(q)
  File "D:\Program Files\Python37\lib\site-packages\MySQLdb\connections.py", line 239, in query
    _mysql.connection.query(self, query)
django.db.utils.IntegrityError: (1062, "Duplicate entry '1590076800' for key 'LAMProcessData_process_r_acquisition_timestamp_a69ae90c_uniq'")
2020-05-21 Thu 02:21:18 threadpool.py _run_jobs 94 - DEBUG - Exiting worker thread
2020-05-21 Thu 02:30:30 autoreload.py trigger_reload 203 - INFO - E:\1-program\11-LAMDataServer\lamdataserver\LAMProcessData\views.py changed, reloading.
2020-05-21 Thu 02:30:30 threadpool.py shutdown 111 - INFO - Shutting down thread pool
2020-05-21 Thu 02:30:32 threadpool.py __init__ 52 - INFO - Started thread pool with 0 core threads and 20 maximum threads
2020-05-21 Thu 02:30:32 scheduler.py add_job 287 - INFO - Adding job tentatively -- it will be properly scheduled when the scheduler starts
2020-05-21 Thu 02:30:32 scheduler.py add_job 287 - INFO - Adding job tentatively -- it will be properly scheduled when the scheduler starts
2020-05-21 Thu 02:30:32 scheduler.py add_job 287 - INFO - Adding job tentatively -- it will be properly scheduled when the scheduler starts
2020-05-21 Thu 02:30:32 scheduler.py _real_add_job 262 - INFO - Added job "regulartime_task (trigger: interval[1 day, 0:00:00], next run at: 2020-05-21 02:30:42.529268)" to job store "default"
2020-05-21 Thu 02:30:32 scheduler.py _real_add_job 262 - INFO - Added job "cleanup (trigger: cron[day_of_week='*', hour='3', minute='0', second='0'], next run at: 2020-05-21 03:00:00)" to job store "default"
2020-05-21 Thu 02:30:32 scheduler.py _real_add_job 262 - INFO - Added job "OpenLog (trigger: cron[hour='0'], next run at: 2020-05-22 00:00:00)" to job store "default"
2020-05-21 Thu 02:30:32 scheduler.py _main_loop 574 - INFO - Scheduler started
2020-05-21 Thu 02:30:32 scheduler.py _main_loop 579 - DEBUG - Looking for jobs to run
2020-05-21 Thu 02:30:32 scheduler.py _main_loop 588 - DEBUG - Next wakeup is due at 2020-05-21 02:30:42.529268 (in 9.998048 seconds)
2020-05-21 Thu 02:30:32 query_views.py <module> 63 - DEBUG - SendBefore_NotRecive : [<CNCProcessStatus: CNCProcessStatus object (2038721)>]
2020-05-21 Thu 02:30:32 query_views.py <module> 64 - DEBUG - Waitfor_Recive : [2038721]
2020-05-21 Thu 02:30:42 scheduler.py _main_loop 579 - DEBUG - Looking for jobs to run
2020-05-21 Thu 02:30:42 threadpool.py _run_jobs 69 - DEBUG - Started worker thread
2020-05-21 Thu 02:30:42 scheduler.py _main_loop 588 - DEBUG - Next wakeup is due at 2020-05-21 03:00:00 (in 1757.461232 seconds)
2020-05-21 Thu 02:30:42 scheduler.py _run_job 509 - INFO - Running job "regulartime_task (trigger: interval[1 day, 0:00:00], next run at: 2020-05-22 02:30:42.529268)" (scheduled at 2020-05-21 02:30:42.529268)
2020-05-21 Thu 02:30:42 scheduler.py _run_job 520 - ERROR - Job "regulartime_task (trigger: interval[1 day, 0:00:00], next run at: 2020-05-22 02:30:42.529268)" raised an exception
Traceback (most recent call last):
  File "D:\Program Files\Python37\lib\site-packages\django\db\backends\utils.py", line 84, in _execute
    return self.cursor.execute(sql, params)
  File "D:\Program Files\Python37\lib\site-packages\django\db\backends\mysql\base.py", line 71, in execute
    return self.cursor.execute(query, args)
  File "D:\Program Files\Python37\lib\site-packages\MySQLdb\cursors.py", line 209, in execute
    res = self._query(query)
  File "D:\Program Files\Python37\lib\site-packages\MySQLdb\cursors.py", line 315, in _query
    db.query(q)
  File "D:\Program Files\Python37\lib\site-packages\MySQLdb\connections.py", line 239, in query
    _mysql.connection.query(self, query)
MySQLdb._exceptions.IntegrityError: (1062, "Duplicate entry '1590076800' for key 'LAMProcessData_process_r_acquisition_timestamp_a69ae90c_uniq'")

The above exception was the direct cause of the following exception:

Traceback (most recent call last):
  File "D:\Program Files\Python37\lib\site-packages\apscheduler\scheduler.py", line 512, in _run_job
    retval = job.func(*job.args, **job.kwargs)
  File "E:\1-program\11-LAMDataServer\lamdataserver\LAMProcessData\views.py", line 5272, in regulartime_task
    RT_FineData.Realtime_FineData.init_Tomorrow_rows()
  File "E:\1-program\11-LAMDataServer\lamdataserver\LAMProcessData\process_realtime_finedata.py", line 193, in init_Tomorrow_rows
    _model.objects.bulk_create(insert_data_list)
  File "D:\Program Files\Python37\lib\site-packages\django\db\models\manager.py", line 82, in manager_method
    return getattr(self.get_queryset(), name)(*args, **kwargs)
  File "D:\Program Files\Python37\lib\site-packages\django\db\models\query.py", line 474, in bulk_create
    ids = self._batched_insert(objs_without_pk, fields, batch_size, ignore_conflicts=ignore_conflicts)
  File "D:\Program Files\Python37\lib\site-packages\django\db\models\query.py", line 1211, in _batched_insert
    self._insert(item, fields=fields, using=self.db, ignore_conflicts=ignore_conflicts)
  File "D:\Program Files\Python37\lib\site-packages\django\db\models\query.py", line 1186, in _insert
    return query.get_compiler(using=using).execute_sql(return_id)
  File "D:\Program Files\Python37\lib\site-packages\django\db\models\sql\compiler.py", line 1332, in execute_sql
    cursor.execute(sql, params)
  File "D:\Program Files\Python37\lib\site-packages\django\db\backends\utils.py", line 99, in execute
    return super().execute(sql, params)
  File "D:\Program Files\Python37\lib\site-packages\django\db\backends\utils.py", line 67, in execute
    return self._execute_with_wrappers(sql, params, many=False, executor=self._execute)
  File "D:\Program Files\Python37\lib\site-packages\django\db\backends\utils.py", line 76, in _execute_with_wrappers
    return executor(sql, params, many, context)
  File "D:\Program Files\Python37\lib\site-packages\django\db\backends\utils.py", line 84, in _execute
    return self.cursor.execute(sql, params)
  File "D:\Program Files\Python37\lib\site-packages\django\db\utils.py", line 89, in __exit__
    raise dj_exc_value.with_traceback(traceback) from exc_value
  File "D:\Program Files\Python37\lib\site-packages\django\db\backends\utils.py", line 84, in _execute
    return self.cursor.execute(sql, params)
  File "D:\Program Files\Python37\lib\site-packages\django\db\backends\mysql\base.py", line 71, in execute
    return self.cursor.execute(query, args)
  File "D:\Program Files\Python37\lib\site-packages\MySQLdb\cursors.py", line 209, in execute
    res = self._query(query)
  File "D:\Program Files\Python37\lib\site-packages\MySQLdb\cursors.py", line 315, in _query
    db.query(q)
  File "D:\Program Files\Python37\lib\site-packages\MySQLdb\connections.py", line 239, in query
    _mysql.connection.query(self, query)
django.db.utils.IntegrityError: (1062, "Duplicate entry '1590076800' for key 'LAMProcessData_process_r_acquisition_timestamp_a69ae90c_uniq'")
2020-05-21 Thu 02:30:43 threadpool.py _run_jobs 94 - DEBUG - Exiting worker thread
2020-05-21 Thu 02:36:45 threadpool.py __init__ 52 - INFO - Started thread pool with 0 core threads and 20 maximum threads
2020-05-21 Thu 02:36:45 scheduler.py add_job 287 - INFO - Adding job tentatively -- it will be properly scheduled when the scheduler starts
2020-05-21 Thu 02:36:45 scheduler.py add_job 287 - INFO - Adding job tentatively -- it will be properly scheduled when the scheduler starts
2020-05-21 Thu 02:36:45 scheduler.py add_job 287 - INFO - Adding job tentatively -- it will be properly scheduled when the scheduler starts
2020-05-21 Thu 02:36:45 scheduler.py _real_add_job 262 - INFO - Added job "regulartime_task (trigger: interval[1 day, 0:00:00], next run at: 2020-05-21 02:36:55.893021)" to job store "default"
2020-05-21 Thu 02:36:45 scheduler.py _real_add_job 262 - INFO - Added job "cleanup (trigger: cron[day_of_week='*', hour='3', minute='0', second='0'], next run at: 2020-05-21 03:00:00)" to job store "default"
2020-05-21 Thu 02:36:45 scheduler.py _real_add_job 262 - INFO - Added job "OpenLog (trigger: cron[hour='0'], next run at: 2020-05-22 00:00:00)" to job store "default"
2020-05-21 Thu 02:36:45 scheduler.py _main_loop 574 - INFO - Scheduler started
2020-05-21 Thu 02:36:45 scheduler.py _main_loop 579 - DEBUG - Looking for jobs to run
2020-05-21 Thu 02:36:45 scheduler.py _main_loop 588 - DEBUG - Next wakeup is due at 2020-05-21 02:36:55.893021 (in 9.997525 seconds)
2020-05-21 Thu 02:36:45 query_views.py <module> 63 - DEBUG - SendBefore_NotRecive : [<CNCProcessStatus: CNCProcessStatus object (2038721)>]
2020-05-21 Thu 02:36:45 query_views.py <module> 64 - DEBUG - Waitfor_Recive : [2038721]
2020-05-21 Thu 02:36:55 scheduler.py _main_loop 579 - DEBUG - Looking for jobs to run
2020-05-21 Thu 02:36:55 threadpool.py _run_jobs 69 - DEBUG - Started worker thread
2020-05-21 Thu 02:36:55 scheduler.py _run_job 509 - INFO - Running job "regulartime_task (trigger: interval[1 day, 0:00:00], next run at: 2020-05-21 02:36:55.893021)" (scheduled at 2020-05-21 02:36:55.893021)
2020-05-21 Thu 02:36:55 scheduler.py _main_loop 588 - DEBUG - Next wakeup is due at 2020-05-21 03:00:00 (in 1384.106157 seconds)
2020-05-21 Thu 02:36:56 scheduler.py _run_job 520 - ERROR - Job "regulartime_task (trigger: interval[1 day, 0:00:00], next run at: 2020-05-22 02:36:55.893021)" raised an exception
Traceback (most recent call last):
  File "D:\Program Files\Python37\lib\site-packages\django\db\backends\utils.py", line 84, in _execute
    return self.cursor.execute(sql, params)
  File "D:\Program Files\Python37\lib\site-packages\django\db\backends\mysql\base.py", line 71, in execute
    return self.cursor.execute(query, args)
  File "D:\Program Files\Python37\lib\site-packages\MySQLdb\cursors.py", line 209, in execute
    res = self._query(query)
  File "D:\Program Files\Python37\lib\site-packages\MySQLdb\cursors.py", line 315, in _query
    db.query(q)
  File "D:\Program Files\Python37\lib\site-packages\MySQLdb\connections.py", line 239, in query
    _mysql.connection.query(self, query)
MySQLdb._exceptions.IntegrityError: (1062, "Duplicate entry '1590076800' for key 'LAMProcessData_process_r_acquisition_timestamp_a69ae90c_uniq'")

The above exception was the direct cause of the following exception:

Traceback (most recent call last):
  File "D:\Program Files\Python37\lib\site-packages\apscheduler\scheduler.py", line 512, in _run_job
    retval = job.func(*job.args, **job.kwargs)
  File "E:\1-program\11-LAMDataServer\lamdataserver\LAMProcessData\views.py", line 5272, in regulartime_task
    RT_FineData.Realtime_FineData.init_Tomorrow_rows()
  File "E:\1-program\11-LAMDataServer\lamdataserver\LAMProcessData\process_realtime_finedata.py", line 193, in init_Tomorrow_rows
    _model.objects.bulk_create(insert_data_list)
  File "D:\Program Files\Python37\lib\site-packages\django\db\models\manager.py", line 82, in manager_method
    return getattr(self.get_queryset(), name)(*args, **kwargs)
  File "D:\Program Files\Python37\lib\site-packages\django\db\models\query.py", line 474, in bulk_create
    ids = self._batched_insert(objs_without_pk, fields, batch_size, ignore_conflicts=ignore_conflicts)
  File "D:\Program Files\Python37\lib\site-packages\django\db\models\query.py", line 1211, in _batched_insert
    self._insert(item, fields=fields, using=self.db, ignore_conflicts=ignore_conflicts)
  File "D:\Program Files\Python37\lib\site-packages\django\db\models\query.py", line 1186, in _insert
    return query.get_compiler(using=using).execute_sql(return_id)
  File "D:\Program Files\Python37\lib\site-packages\django\db\models\sql\compiler.py", line 1332, in execute_sql
    cursor.execute(sql, params)
  File "D:\Program Files\Python37\lib\site-packages\django\db\backends\utils.py", line 99, in execute
    return super().execute(sql, params)
  File "D:\Program Files\Python37\lib\site-packages\django\db\backends\utils.py", line 67, in execute
    return self._execute_with_wrappers(sql, params, many=False, executor=self._execute)
  File "D:\Program Files\Python37\lib\site-packages\django\db\backends\utils.py", line 76, in _execute_with_wrappers
    return executor(sql, params, many, context)
  File "D:\Program Files\Python37\lib\site-packages\django\db\backends\utils.py", line 84, in _execute
    return self.cursor.execute(sql, params)
  File "D:\Program Files\Python37\lib\site-packages\django\db\utils.py", line 89, in __exit__
    raise dj_exc_value.with_traceback(traceback) from exc_value
  File "D:\Program Files\Python37\lib\site-packages\django\db\backends\utils.py", line 84, in _execute
    return self.cursor.execute(sql, params)
  File "D:\Program Files\Python37\lib\site-packages\django\db\backends\mysql\base.py", line 71, in execute
    return self.cursor.execute(query, args)
  File "D:\Program Files\Python37\lib\site-packages\MySQLdb\cursors.py", line 209, in execute
    res = self._query(query)
  File "D:\Program Files\Python37\lib\site-packages\MySQLdb\cursors.py", line 315, in _query
    db.query(q)
  File "D:\Program Files\Python37\lib\site-packages\MySQLdb\connections.py", line 239, in query
    _mysql.connection.query(self, query)
django.db.utils.IntegrityError: (1062, "Duplicate entry '1590076800' for key 'LAMProcessData_process_r_acquisition_timestamp_a69ae90c_uniq'")
2020-05-21 Thu 02:36:57 threadpool.py _run_jobs 94 - DEBUG - Exiting worker thread
2020-05-21 Thu 02:38:46 threadpool.py __init__ 52 - INFO - Started thread pool with 0 core threads and 20 maximum threads
2020-05-21 Thu 02:38:46 scheduler.py add_job 287 - INFO - Adding job tentatively -- it will be properly scheduled when the scheduler starts
2020-05-21 Thu 02:38:46 scheduler.py add_job 287 - INFO - Adding job tentatively -- it will be properly scheduled when the scheduler starts
2020-05-21 Thu 02:38:46 scheduler.py add_job 287 - INFO - Adding job tentatively -- it will be properly scheduled when the scheduler starts
2020-05-21 Thu 02:38:46 scheduler.py _real_add_job 262 - INFO - Added job "regulartime_task (trigger: interval[1 day, 0:00:00], next run at: 2020-05-21 02:38:56.904284)" to job store "default"
2020-05-21 Thu 02:38:46 scheduler.py _real_add_job 262 - INFO - Added job "cleanup (trigger: cron[day_of_week='*', hour='3', minute='0', second='0'], next run at: 2020-05-21 03:00:00)" to job store "default"
2020-05-21 Thu 02:38:46 scheduler.py _real_add_job 262 - INFO - Added job "OpenLog (trigger: cron[hour='0'], next run at: 2020-05-22 00:00:00)" to job store "default"
2020-05-21 Thu 02:38:46 scheduler.py _main_loop 574 - INFO - Scheduler started
2020-05-21 Thu 02:38:46 scheduler.py _main_loop 579 - DEBUG - Looking for jobs to run
2020-05-21 Thu 02:38:46 scheduler.py _main_loop 588 - DEBUG - Next wakeup is due at 2020-05-21 02:38:56.904284 (in 9.996033 seconds)
2020-05-21 Thu 02:38:46 query_views.py <module> 63 - DEBUG - SendBefore_NotRecive : [<CNCProcessStatus: CNCProcessStatus object (2038721)>]
2020-05-21 Thu 02:38:46 query_views.py <module> 64 - DEBUG - Waitfor_Recive : [2038721]
2020-05-21 Thu 02:38:56 scheduler.py _main_loop 579 - DEBUG - Looking for jobs to run
2020-05-21 Thu 02:38:56 threadpool.py _run_jobs 69 - DEBUG - Started worker thread
2020-05-21 Thu 02:38:56 scheduler.py _main_loop 588 - DEBUG - Next wakeup is due at 2020-05-21 03:00:00 (in 1263.078905 seconds)
2020-05-21 Thu 02:38:56 scheduler.py _run_job 509 - INFO - Running job "regulartime_task (trigger: interval[1 day, 0:00:00], next run at: 2020-05-22 02:38:56.904284)" (scheduled at 2020-05-21 02:38:56.904284)
2020-05-21 Thu 02:38:57 scheduler.py _run_job 520 - ERROR - Job "regulartime_task (trigger: interval[1 day, 0:00:00], next run at: 2020-05-22 02:38:56.904284)" raised an exception
Traceback (most recent call last):
  File "D:\Program Files\Python37\lib\site-packages\django\db\backends\utils.py", line 84, in _execute
    return self.cursor.execute(sql, params)
  File "D:\Program Files\Python37\lib\site-packages\django\db\backends\mysql\base.py", line 71, in execute
    return self.cursor.execute(query, args)
  File "D:\Program Files\Python37\lib\site-packages\MySQLdb\cursors.py", line 209, in execute
    res = self._query(query)
  File "D:\Program Files\Python37\lib\site-packages\MySQLdb\cursors.py", line 315, in _query
    db.query(q)
  File "D:\Program Files\Python37\lib\site-packages\MySQLdb\connections.py", line 239, in query
    _mysql.connection.query(self, query)
MySQLdb._exceptions.IntegrityError: (1062, "Duplicate entry '1590076800' for key 'LAMProcessData_process_r_acquisition_timestamp_a69ae90c_uniq'")

The above exception was the direct cause of the following exception:

Traceback (most recent call last):
  File "D:\Program Files\Python37\lib\site-packages\apscheduler\scheduler.py", line 512, in _run_job
    retval = job.func(*job.args, **job.kwargs)
  File "E:\1-program\11-LAMDataServer\lamdataserver\LAMProcessData\views.py", line 5273, in regulartime_task
    RT_FineData.Realtime_FineData.init_Tomorrow_rows()
  File "E:\1-program\11-LAMDataServer\lamdataserver\LAMProcessData\process_realtime_finedata.py", line 193, in init_Tomorrow_rows
    _model.objects.bulk_create(insert_data_list)
  File "D:\Program Files\Python37\lib\site-packages\django\db\models\manager.py", line 82, in manager_method
    return getattr(self.get_queryset(), name)(*args, **kwargs)
  File "D:\Program Files\Python37\lib\site-packages\django\db\models\query.py", line 474, in bulk_create
    ids = self._batched_insert(objs_without_pk, fields, batch_size, ignore_conflicts=ignore_conflicts)
  File "D:\Program Files\Python37\lib\site-packages\django\db\models\query.py", line 1211, in _batched_insert
    self._insert(item, fields=fields, using=self.db, ignore_conflicts=ignore_conflicts)
  File "D:\Program Files\Python37\lib\site-packages\django\db\models\query.py", line 1186, in _insert
    return query.get_compiler(using=using).execute_sql(return_id)
  File "D:\Program Files\Python37\lib\site-packages\django\db\models\sql\compiler.py", line 1332, in execute_sql
    cursor.execute(sql, params)
  File "D:\Program Files\Python37\lib\site-packages\django\db\backends\utils.py", line 99, in execute
    return super().execute(sql, params)
  File "D:\Program Files\Python37\lib\site-packages\django\db\backends\utils.py", line 67, in execute
    return self._execute_with_wrappers(sql, params, many=False, executor=self._execute)
  File "D:\Program Files\Python37\lib\site-packages\django\db\backends\utils.py", line 76, in _execute_with_wrappers
    return executor(sql, params, many, context)
  File "D:\Program Files\Python37\lib\site-packages\django\db\backends\utils.py", line 84, in _execute
    return self.cursor.execute(sql, params)
  File "D:\Program Files\Python37\lib\site-packages\django\db\utils.py", line 89, in __exit__
    raise dj_exc_value.with_traceback(traceback) from exc_value
  File "D:\Program Files\Python37\lib\site-packages\django\db\backends\utils.py", line 84, in _execute
    return self.cursor.execute(sql, params)
  File "D:\Program Files\Python37\lib\site-packages\django\db\backends\mysql\base.py", line 71, in execute
    return self.cursor.execute(query, args)
  File "D:\Program Files\Python37\lib\site-packages\MySQLdb\cursors.py", line 209, in execute
    res = self._query(query)
  File "D:\Program Files\Python37\lib\site-packages\MySQLdb\cursors.py", line 315, in _query
    db.query(q)
  File "D:\Program Files\Python37\lib\site-packages\MySQLdb\connections.py", line 239, in query
    _mysql.connection.query(self, query)
django.db.utils.IntegrityError: (1062, "Duplicate entry '1590076800' for key 'LAMProcessData_process_r_acquisition_timestamp_a69ae90c_uniq'")
2020-05-21 Thu 02:38:58 threadpool.py _run_jobs 94 - DEBUG - Exiting worker thread
2020-05-21 Thu 03:00:00 scheduler.py _main_loop 579 - DEBUG - Looking for jobs to run
2020-05-21 Thu 03:00:00 threadpool.py _run_jobs 69 - DEBUG - Started worker thread
2020-05-21 Thu 03:00:00 scheduler.py _main_loop 588 - DEBUG - Next wakeup is due at 2020-05-22 00:00:00 (in 75599.990278 seconds)
2020-05-21 Thu 03:00:00 scheduler.py _run_job 509 - INFO - Running job "cleanup (trigger: cron[day_of_week='*', hour='3', minute='0', second='0'], next run at: 2020-05-22 03:00:00)" (scheduled at 2020-05-21 03:00:00)
2020-05-21 Thu 03:00:00 views.py cleanup 5279 - INFO - start cleanup!
2020-05-21 Thu 03:00:00 views.py cleanup 5311 - INFO - end cleanup!
2020-05-21 Thu 03:00:00 scheduler.py _run_job 527 - INFO - Job "cleanup (trigger: cron[day_of_week='*', hour='3', minute='0', second='0'], next run at: 2020-05-22 03:00:00)" executed successfully
2020-05-21 Thu 03:00:01 threadpool.py _run_jobs 94 - DEBUG - Exiting worker thread
