2020-05-06 Wed 22:21:32 threadpool.py __init__ 52 - INFO - Started thread pool with 0 core threads and 20 maximum threads
2020-05-06 Wed 22:21:32 scheduler.py add_job 287 - INFO - Adding job tentatively -- it will be properly scheduled when the scheduler starts
2020-05-06 Wed 22:21:32 scheduler.py add_job 287 - INFO - Adding job tentatively -- it will be properly scheduled when the scheduler starts
2020-05-06 Wed 22:21:32 scheduler.py add_job 287 - INFO - Adding job tentatively -- it will be properly scheduled when the scheduler starts
2020-05-06 Wed 22:21:32 scheduler.py _real_add_job 262 - INFO - Added job "regulartime_task (trigger: interval[1 day, 0:00:00], next run at: 2020-05-06 22:21:42.259714)" to job store "default"
2020-05-06 Wed 22:21:32 scheduler.py _real_add_job 262 - INFO - Added job "cleanup (trigger: cron[day_of_week='*', hour='3', minute='0', second='0'], next run at: 2020-05-07 03:00:00)" to job store "default"
2020-05-06 Wed 22:21:32 scheduler.py _real_add_job 262 - INFO - Added job "OpenLog (trigger: cron[hour='0'], next run at: 2020-05-07 00:00:00)" to job store "default"
2020-05-06 Wed 22:21:32 scheduler.py _main_loop 574 - INFO - Scheduler started
2020-05-06 Wed 22:21:32 scheduler.py _main_loop 579 - DEBUG - Looking for jobs to run
2020-05-06 Wed 22:21:32 scheduler.py _main_loop 588 - DEBUG - Next wakeup is due at 2020-05-06 22:21:42.259714 (in 9.998005 seconds)
2020-05-06 Wed 22:21:32 query_views.py <module> 63 - DEBUG - SendBefore_NotRecive : [<CNCProcessStatus: CNCProcessStatus object (2038721)>]
2020-05-06 Wed 22:21:32 query_views.py <module> 64 - DEBUG - Waitfor_Recive : [2038721]
2020-05-06 Wed 22:21:42 scheduler.py _main_loop 579 - DEBUG - Looking for jobs to run
2020-05-06 Wed 22:21:42 threadpool.py _run_jobs 69 - DEBUG - Started worker thread
2020-05-06 Wed 22:21:42 scheduler.py _main_loop 588 - DEBUG - Next wakeup is due at 2020-05-07 00:00:00 (in 5897.734291 seconds)
2020-05-06 Wed 22:21:42 scheduler.py _run_job 509 - INFO - Running job "regulartime_task (trigger: interval[1 day, 0:00:00], next run at: 2020-05-07 22:21:42.259714)" (scheduled at 2020-05-06 22:21:42.259714)
2020-05-06 Wed 22:21:43 scheduler.py _run_job 520 - ERROR - Job "regulartime_task (trigger: interval[1 day, 0:00:00], next run at: 2020-05-07 22:21:42.259714)" raised an exception
Traceback (most recent call last):
  File "D:\Program Files\Python37\lib\site-packages\django\db\backends\mysql\base.py", line 71, in execute
    return self.cursor.execute(query, args)
  File "D:\Program Files\Python37\lib\site-packages\MySQLdb\cursors.py", line 209, in execute
    res = self._query(query)
  File "D:\Program Files\Python37\lib\site-packages\MySQLdb\cursors.py", line 315, in _query
    db.query(q)
  File "D:\Program Files\Python37\lib\site-packages\MySQLdb\connections.py", line 239, in query
    _mysql.connection.query(self, query)
MySQLdb._exceptions.OperationalError: (1048, "Column 'laser_power' cannot be null")

During handling of the above exception, another exception occurred:

Traceback (most recent call last):
  File "D:\Program Files\Python37\lib\site-packages\apscheduler\scheduler.py", line 512, in _run_job
    retval = job.func(*job.args, **job.kwargs)
  File "E:\1-program\11-LAMDataServer\lamdataserver\LAMProcessData\views.py", line 5139, in regulartime_task
    RT_FineData.Realtime_FineData.init_Tomorrow_rows()
  File "E:\1-program\11-LAMDataServer\lamdataserver\LAMProcessData\process_realtime_finedata.py", line 193, in init_Tomorrow_rows
    _model.objects.bulk_create(insert_data_list)
  File "D:\Program Files\Python37\lib\site-packages\django\db\models\manager.py", line 82, in manager_method
    return getattr(self.get_queryset(), name)(*args, **kwargs)
  File "D:\Program Files\Python37\lib\site-packages\django\db\models\query.py", line 474, in bulk_create
    ids = self._batched_insert(objs_without_pk, fields, batch_size, ignore_conflicts=ignore_conflicts)
  File "D:\Program Files\Python37\lib\site-packages\django\db\models\query.py", line 1211, in _batched_insert
    self._insert(item, fields=fields, using=self.db, ignore_conflicts=ignore_conflicts)
  File "D:\Program Files\Python37\lib\site-packages\django\db\models\query.py", line 1186, in _insert
    return query.get_compiler(using=using).execute_sql(return_id)
  File "D:\Program Files\Python37\lib\site-packages\django\db\models\sql\compiler.py", line 1332, in execute_sql
    cursor.execute(sql, params)
  File "D:\Program Files\Python37\lib\site-packages\django\db\backends\utils.py", line 99, in execute
    return super().execute(sql, params)
  File "D:\Program Files\Python37\lib\site-packages\django\db\backends\utils.py", line 67, in execute
    return self._execute_with_wrappers(sql, params, many=False, executor=self._execute)
  File "D:\Program Files\Python37\lib\site-packages\django\db\backends\utils.py", line 76, in _execute_with_wrappers
    return executor(sql, params, many, context)
  File "D:\Program Files\Python37\lib\site-packages\django\db\backends\utils.py", line 84, in _execute
    return self.cursor.execute(sql, params)
  File "D:\Program Files\Python37\lib\site-packages\django\db\backends\mysql\base.py", line 76, in execute
    raise utils.IntegrityError(*tuple(e.args))
django.db.utils.IntegrityError: (1048, "Column 'laser_power' cannot be null")
2020-05-06 Wed 22:21:44 threadpool.py _run_jobs 94 - DEBUG - Exiting worker thread
2020-05-06 Wed 22:22:50 threadpool.py __init__ 52 - INFO - Started thread pool with 0 core threads and 20 maximum threads
2020-05-06 Wed 22:22:50 scheduler.py add_job 287 - INFO - Adding job tentatively -- it will be properly scheduled when the scheduler starts
2020-05-06 Wed 22:22:50 scheduler.py add_job 287 - INFO - Adding job tentatively -- it will be properly scheduled when the scheduler starts
2020-05-06 Wed 22:22:50 scheduler.py add_job 287 - INFO - Adding job tentatively -- it will be properly scheduled when the scheduler starts
2020-05-06 Wed 22:22:50 scheduler.py _real_add_job 262 - INFO - Added job "regulartime_task (trigger: interval[1 day, 0:00:00], next run at: 2020-05-06 22:23:00.548240)" to job store "default"
2020-05-06 Wed 22:22:50 scheduler.py _real_add_job 262 - INFO - Added job "cleanup (trigger: cron[day_of_week='*', hour='3', minute='0', second='0'], next run at: 2020-05-07 03:00:00)" to job store "default"
2020-05-06 Wed 22:22:50 scheduler.py _real_add_job 262 - INFO - Added job "OpenLog (trigger: cron[hour='0'], next run at: 2020-05-07 00:00:00)" to job store "default"
2020-05-06 Wed 22:22:50 scheduler.py _main_loop 574 - INFO - Scheduler started
2020-05-06 Wed 22:22:50 scheduler.py _main_loop 579 - DEBUG - Looking for jobs to run
2020-05-06 Wed 22:22:50 scheduler.py _main_loop 588 - DEBUG - Next wakeup is due at 2020-05-06 22:23:00.548240 (in 9.996013 seconds)
2020-05-06 Wed 22:22:50 query_views.py <module> 63 - DEBUG - SendBefore_NotRecive : [<CNCProcessStatus: CNCProcessStatus object (2038721)>]
2020-05-06 Wed 22:22:50 query_views.py <module> 64 - DEBUG - Waitfor_Recive : [2038721]
2020-05-06 Wed 22:23:00 scheduler.py _main_loop 579 - DEBUG - Looking for jobs to run
2020-05-06 Wed 22:23:00 threadpool.py _run_jobs 69 - DEBUG - Started worker thread
2020-05-06 Wed 22:23:00 scheduler.py _run_job 509 - INFO - Running job "regulartime_task (trigger: interval[1 day, 0:00:00], next run at: 2020-05-06 22:23:00.548240)" (scheduled at 2020-05-06 22:23:00.548240)
2020-05-06 Wed 22:23:00 scheduler.py _main_loop 588 - DEBUG - Next wakeup is due at 2020-05-07 00:00:00 (in 5819.450124 seconds)
2020-05-06 Wed 22:23:00 scheduler.py _run_job 520 - ERROR - Job "regulartime_task (trigger: interval[1 day, 0:00:00], next run at: 2020-05-07 22:23:00.548240)" raised an exception
Traceback (most recent call last):
  File "D:\Program Files\Python37\lib\site-packages\django\db\backends\utils.py", line 84, in _execute
    return self.cursor.execute(sql, params)
  File "D:\Program Files\Python37\lib\site-packages\django\db\backends\mysql\base.py", line 71, in execute
    return self.cursor.execute(query, args)
  File "D:\Program Files\Python37\lib\site-packages\MySQLdb\cursors.py", line 209, in execute
    res = self._query(query)
  File "D:\Program Files\Python37\lib\site-packages\MySQLdb\cursors.py", line 315, in _query
    db.query(q)
  File "D:\Program Files\Python37\lib\site-packages\MySQLdb\connections.py", line 239, in query
    _mysql.connection.query(self, query)
MySQLdb._exceptions.IntegrityError: (1062, "Duplicate entry '1588780800' for key 'LAMProcessData_process_r_acquisition_timestamp_a69ae90c_uniq'")

The above exception was the direct cause of the following exception:

Traceback (most recent call last):
  File "D:\Program Files\Python37\lib\site-packages\apscheduler\scheduler.py", line 512, in _run_job
    retval = job.func(*job.args, **job.kwargs)
  File "E:\1-program\11-LAMDataServer\lamdataserver\LAMProcessData\views.py", line 5142, in regulartime_task
    RT_FineData.Realtime_FineData.init_Tomorrow_rows()
  File "E:\1-program\11-LAMDataServer\lamdataserver\LAMProcessData\process_realtime_finedata.py", line 193, in init_Tomorrow_rows
    _model.objects.bulk_create(insert_data_list)
  File "D:\Program Files\Python37\lib\site-packages\django\db\models\manager.py", line 82, in manager_method
    return getattr(self.get_queryset(), name)(*args, **kwargs)
  File "D:\Program Files\Python37\lib\site-packages\django\db\models\query.py", line 474, in bulk_create
    ids = self._batched_insert(objs_without_pk, fields, batch_size, ignore_conflicts=ignore_conflicts)
  File "D:\Program Files\Python37\lib\site-packages\django\db\models\query.py", line 1211, in _batched_insert
    self._insert(item, fields=fields, using=self.db, ignore_conflicts=ignore_conflicts)
  File "D:\Program Files\Python37\lib\site-packages\django\db\models\query.py", line 1186, in _insert
    return query.get_compiler(using=using).execute_sql(return_id)
  File "D:\Program Files\Python37\lib\site-packages\django\db\models\sql\compiler.py", line 1332, in execute_sql
    cursor.execute(sql, params)
  File "D:\Program Files\Python37\lib\site-packages\django\db\backends\utils.py", line 99, in execute
    return super().execute(sql, params)
  File "D:\Program Files\Python37\lib\site-packages\django\db\backends\utils.py", line 67, in execute
    return self._execute_with_wrappers(sql, params, many=False, executor=self._execute)
  File "D:\Program Files\Python37\lib\site-packages\django\db\backends\utils.py", line 76, in _execute_with_wrappers
    return executor(sql, params, many, context)
  File "D:\Program Files\Python37\lib\site-packages\django\db\backends\utils.py", line 84, in _execute
    return self.cursor.execute(sql, params)
  File "D:\Program Files\Python37\lib\site-packages\django\db\utils.py", line 89, in __exit__
    raise dj_exc_value.with_traceback(traceback) from exc_value
  File "D:\Program Files\Python37\lib\site-packages\django\db\backends\utils.py", line 84, in _execute
    return self.cursor.execute(sql, params)
  File "D:\Program Files\Python37\lib\site-packages\django\db\backends\mysql\base.py", line 71, in execute
    return self.cursor.execute(query, args)
  File "D:\Program Files\Python37\lib\site-packages\MySQLdb\cursors.py", line 209, in execute
    res = self._query(query)
  File "D:\Program Files\Python37\lib\site-packages\MySQLdb\cursors.py", line 315, in _query
    db.query(q)
  File "D:\Program Files\Python37\lib\site-packages\MySQLdb\connections.py", line 239, in query
    _mysql.connection.query(self, query)
django.db.utils.IntegrityError: (1062, "Duplicate entry '1588780800' for key 'LAMProcessData_process_r_acquisition_timestamp_a69ae90c_uniq'")
2020-05-06 Wed 22:23:01 threadpool.py _run_jobs 94 - DEBUG - Exiting worker thread
2020-05-06 Wed 22:24:30 autoreload.py trigger_reload 203 - INFO - E:\1-program\11-LAMDataServer\lamdataserver\LAMProcessData\views.py changed, reloading.
2020-05-06 Wed 22:24:30 threadpool.py shutdown 111 - INFO - Shutting down thread pool
2020-05-06 Wed 22:24:34 threadpool.py __init__ 52 - INFO - Started thread pool with 0 core threads and 20 maximum threads
2020-05-06 Wed 22:24:34 scheduler.py add_job 287 - INFO - Adding job tentatively -- it will be properly scheduled when the scheduler starts
2020-05-06 Wed 22:24:34 scheduler.py add_job 287 - INFO - Adding job tentatively -- it will be properly scheduled when the scheduler starts
2020-05-06 Wed 22:24:34 scheduler.py add_job 287 - INFO - Adding job tentatively -- it will be properly scheduled when the scheduler starts
2020-05-06 Wed 22:24:34 scheduler.py _real_add_job 262 - INFO - Added job "regulartime_task (trigger: interval[1 day, 0:00:00], next run at: 2020-05-06 22:24:44.698858)" to job store "default"
2020-05-06 Wed 22:24:34 scheduler.py _real_add_job 262 - INFO - Added job "cleanup (trigger: cron[day_of_week='*', hour='3', minute='0', second='0'], next run at: 2020-05-07 03:00:00)" to job store "default"
2020-05-06 Wed 22:24:34 scheduler.py _real_add_job 262 - INFO - Added job "OpenLog (trigger: cron[hour='0'], next run at: 2020-05-07 00:00:00)" to job store "default"
2020-05-06 Wed 22:24:34 scheduler.py _main_loop 574 - INFO - Scheduler started
2020-05-06 Wed 22:24:34 scheduler.py _main_loop 579 - DEBUG - Looking for jobs to run
2020-05-06 Wed 22:24:34 scheduler.py _main_loop 588 - DEBUG - Next wakeup is due at 2020-05-06 22:24:44.698858 (in 9.998006 seconds)
2020-05-06 Wed 22:24:34 query_views.py <module> 63 - DEBUG - SendBefore_NotRecive : [<CNCProcessStatus: CNCProcessStatus object (2038721)>]
2020-05-06 Wed 22:24:34 query_views.py <module> 64 - DEBUG - Waitfor_Recive : [2038721]
2020-05-06 Wed 22:24:44 scheduler.py _main_loop 579 - DEBUG - Looking for jobs to run
2020-05-06 Wed 22:24:44 threadpool.py _run_jobs 69 - DEBUG - Started worker thread
2020-05-06 Wed 22:24:44 scheduler.py _main_loop 588 - DEBUG - Next wakeup is due at 2020-05-07 00:00:00 (in 5715.297921 seconds)
2020-05-06 Wed 22:24:44 scheduler.py _run_job 509 - INFO - Running job "regulartime_task (trigger: interval[1 day, 0:00:00], next run at: 2020-05-07 22:24:44.698858)" (scheduled at 2020-05-06 22:24:44.698858)
2020-05-06 Wed 22:24:45 scheduler.py _run_job 520 - ERROR - Job "regulartime_task (trigger: interval[1 day, 0:00:00], next run at: 2020-05-07 22:24:44.698858)" raised an exception
Traceback (most recent call last):
  File "D:\Program Files\Python37\lib\site-packages\django\db\backends\utils.py", line 84, in _execute
    return self.cursor.execute(sql, params)
  File "D:\Program Files\Python37\lib\site-packages\django\db\backends\mysql\base.py", line 71, in execute
    return self.cursor.execute(query, args)
  File "D:\Program Files\Python37\lib\site-packages\MySQLdb\cursors.py", line 209, in execute
    res = self._query(query)
  File "D:\Program Files\Python37\lib\site-packages\MySQLdb\cursors.py", line 315, in _query
    db.query(q)
  File "D:\Program Files\Python37\lib\site-packages\MySQLdb\connections.py", line 239, in query
    _mysql.connection.query(self, query)
MySQLdb._exceptions.IntegrityError: (1062, "Duplicate entry '1588780800' for key 'LAMProcessData_process_r_acquisition_timestamp_a69ae90c_uniq'")

The above exception was the direct cause of the following exception:

Traceback (most recent call last):
  File "D:\Program Files\Python37\lib\site-packages\apscheduler\scheduler.py", line 512, in _run_job
    retval = job.func(*job.args, **job.kwargs)
  File "E:\1-program\11-LAMDataServer\lamdataserver\LAMProcessData\views.py", line 5130, in regulartime_task
    RT_FineData.Realtime_FineData.init_Tomorrow_rows()
  File "E:\1-program\11-LAMDataServer\lamdataserver\LAMProcessData\process_realtime_finedata.py", line 193, in init_Tomorrow_rows
    _model.objects.bulk_create(insert_data_list)
  File "D:\Program Files\Python37\lib\site-packages\django\db\models\manager.py", line 82, in manager_method
    return getattr(self.get_queryset(), name)(*args, **kwargs)
  File "D:\Program Files\Python37\lib\site-packages\django\db\models\query.py", line 474, in bulk_create
    ids = self._batched_insert(objs_without_pk, fields, batch_size, ignore_conflicts=ignore_conflicts)
  File "D:\Program Files\Python37\lib\site-packages\django\db\models\query.py", line 1211, in _batched_insert
    self._insert(item, fields=fields, using=self.db, ignore_conflicts=ignore_conflicts)
  File "D:\Program Files\Python37\lib\site-packages\django\db\models\query.py", line 1186, in _insert
    return query.get_compiler(using=using).execute_sql(return_id)
  File "D:\Program Files\Python37\lib\site-packages\django\db\models\sql\compiler.py", line 1332, in execute_sql
    cursor.execute(sql, params)
  File "D:\Program Files\Python37\lib\site-packages\django\db\backends\utils.py", line 99, in execute
    return super().execute(sql, params)
  File "D:\Program Files\Python37\lib\site-packages\django\db\backends\utils.py", line 67, in execute
    return self._execute_with_wrappers(sql, params, many=False, executor=self._execute)
  File "D:\Program Files\Python37\lib\site-packages\django\db\backends\utils.py", line 76, in _execute_with_wrappers
    return executor(sql, params, many, context)
  File "D:\Program Files\Python37\lib\site-packages\django\db\backends\utils.py", line 84, in _execute
    return self.cursor.execute(sql, params)
  File "D:\Program Files\Python37\lib\site-packages\django\db\utils.py", line 89, in __exit__
    raise dj_exc_value.with_traceback(traceback) from exc_value
  File "D:\Program Files\Python37\lib\site-packages\django\db\backends\utils.py", line 84, in _execute
    return self.cursor.execute(sql, params)
  File "D:\Program Files\Python37\lib\site-packages\django\db\backends\mysql\base.py", line 71, in execute
    return self.cursor.execute(query, args)
  File "D:\Program Files\Python37\lib\site-packages\MySQLdb\cursors.py", line 209, in execute
    res = self._query(query)
  File "D:\Program Files\Python37\lib\site-packages\MySQLdb\cursors.py", line 315, in _query
    db.query(q)
  File "D:\Program Files\Python37\lib\site-packages\MySQLdb\connections.py", line 239, in query
    _mysql.connection.query(self, query)
django.db.utils.IntegrityError: (1062, "Duplicate entry '1588780800' for key 'LAMProcessData_process_r_acquisition_timestamp_a69ae90c_uniq'")
2020-05-06 Wed 22:24:46 threadpool.py _run_jobs 94 - DEBUG - Exiting worker thread
2020-05-06 Wed 22:38:37 autoreload.py trigger_reload 203 - INFO - E:\1-program\11-LAMDataServer\lamdataserver\LAMProcessData\forms.py changed, reloading.
2020-05-06 Wed 22:38:37 threadpool.py shutdown 111 - INFO - Shutting down thread pool
2020-05-06 Wed 22:38:39 threadpool.py __init__ 52 - INFO - Started thread pool with 0 core threads and 20 maximum threads
2020-05-06 Wed 22:38:39 scheduler.py add_job 287 - INFO - Adding job tentatively -- it will be properly scheduled when the scheduler starts
2020-05-06 Wed 22:38:39 scheduler.py add_job 287 - INFO - Adding job tentatively -- it will be properly scheduled when the scheduler starts
2020-05-06 Wed 22:38:39 scheduler.py add_job 287 - INFO - Adding job tentatively -- it will be properly scheduled when the scheduler starts
2020-05-06 Wed 22:38:39 scheduler.py _real_add_job 262 - INFO - Added job "regulartime_task (trigger: interval[1 day, 0:00:00], next run at: 2020-05-06 22:38:49.834086)" to job store "default"
2020-05-06 Wed 22:38:39 scheduler.py _real_add_job 262 - INFO - Added job "cleanup (trigger: cron[day_of_week='*', hour='3', minute='0', second='0'], next run at: 2020-05-07 03:00:00)" to job store "default"
2020-05-06 Wed 22:38:39 scheduler.py _real_add_job 262 - INFO - Added job "OpenLog (trigger: cron[hour='0'], next run at: 2020-05-07 00:00:00)" to job store "default"
2020-05-06 Wed 22:38:39 scheduler.py _main_loop 574 - INFO - Scheduler started
2020-05-06 Wed 22:38:39 scheduler.py _main_loop 579 - DEBUG - Looking for jobs to run
2020-05-06 Wed 22:38:39 scheduler.py _main_loop 588 - DEBUG - Next wakeup is due at 2020-05-06 22:38:49.834086 (in 9.998006 seconds)
2020-05-06 Wed 22:38:39 query_views.py <module> 63 - DEBUG - SendBefore_NotRecive : [<CNCProcessStatus: CNCProcessStatus object (2038721)>]
2020-05-06 Wed 22:38:39 query_views.py <module> 64 - DEBUG - Waitfor_Recive : [2038721]
2020-05-06 Wed 22:38:49 scheduler.py _main_loop 579 - DEBUG - Looking for jobs to run
2020-05-06 Wed 22:38:49 threadpool.py _run_jobs 69 - DEBUG - Started worker thread
2020-05-06 Wed 22:38:49 scheduler.py _run_job 509 - INFO - Running job "regulartime_task (trigger: interval[1 day, 0:00:00], next run at: 2020-05-06 22:38:49.834086)" (scheduled at 2020-05-06 22:38:49.834086)
2020-05-06 Wed 22:38:49 scheduler.py _main_loop 588 - DEBUG - Next wakeup is due at 2020-05-07 00:00:00 (in 4870.163699 seconds)
2020-05-06 Wed 22:38:50 scheduler.py _run_job 520 - ERROR - Job "regulartime_task (trigger: interval[1 day, 0:00:00], next run at: 2020-05-07 22:38:49.834086)" raised an exception
Traceback (most recent call last):
  File "D:\Program Files\Python37\lib\site-packages\django\db\backends\utils.py", line 84, in _execute
    return self.cursor.execute(sql, params)
  File "D:\Program Files\Python37\lib\site-packages\django\db\backends\mysql\base.py", line 71, in execute
    return self.cursor.execute(query, args)
  File "D:\Program Files\Python37\lib\site-packages\MySQLdb\cursors.py", line 209, in execute
    res = self._query(query)
  File "D:\Program Files\Python37\lib\site-packages\MySQLdb\cursors.py", line 315, in _query
    db.query(q)
  File "D:\Program Files\Python37\lib\site-packages\MySQLdb\connections.py", line 239, in query
    _mysql.connection.query(self, query)
MySQLdb._exceptions.IntegrityError: (1062, "Duplicate entry '1588780800' for key 'LAMProcessData_process_r_acquisition_timestamp_a69ae90c_uniq'")

The above exception was the direct cause of the following exception:

Traceback (most recent call last):
  File "D:\Program Files\Python37\lib\site-packages\apscheduler\scheduler.py", line 512, in _run_job
    retval = job.func(*job.args, **job.kwargs)
  File "E:\1-program\11-LAMDataServer\lamdataserver\LAMProcessData\views.py", line 5130, in regulartime_task
    RT_FineData.Realtime_FineData.init_Tomorrow_rows()
  File "E:\1-program\11-LAMDataServer\lamdataserver\LAMProcessData\process_realtime_finedata.py", line 193, in init_Tomorrow_rows
    _model.objects.bulk_create(insert_data_list)
  File "D:\Program Files\Python37\lib\site-packages\django\db\models\manager.py", line 82, in manager_method
    return getattr(self.get_queryset(), name)(*args, **kwargs)
  File "D:\Program Files\Python37\lib\site-packages\django\db\models\query.py", line 474, in bulk_create
    ids = self._batched_insert(objs_without_pk, fields, batch_size, ignore_conflicts=ignore_conflicts)
  File "D:\Program Files\Python37\lib\site-packages\django\db\models\query.py", line 1211, in _batched_insert
    self._insert(item, fields=fields, using=self.db, ignore_conflicts=ignore_conflicts)
  File "D:\Program Files\Python37\lib\site-packages\django\db\models\query.py", line 1186, in _insert
    return query.get_compiler(using=using).execute_sql(return_id)
  File "D:\Program Files\Python37\lib\site-packages\django\db\models\sql\compiler.py", line 1332, in execute_sql
    cursor.execute(sql, params)
  File "D:\Program Files\Python37\lib\site-packages\django\db\backends\utils.py", line 99, in execute
    return super().execute(sql, params)
  File "D:\Program Files\Python37\lib\site-packages\django\db\backends\utils.py", line 67, in execute
    return self._execute_with_wrappers(sql, params, many=False, executor=self._execute)
  File "D:\Program Files\Python37\lib\site-packages\django\db\backends\utils.py", line 76, in _execute_with_wrappers
    return executor(sql, params, many, context)
  File "D:\Program Files\Python37\lib\site-packages\django\db\backends\utils.py", line 84, in _execute
    return self.cursor.execute(sql, params)
  File "D:\Program Files\Python37\lib\site-packages\django\db\utils.py", line 89, in __exit__
    raise dj_exc_value.with_traceback(traceback) from exc_value
  File "D:\Program Files\Python37\lib\site-packages\django\db\backends\utils.py", line 84, in _execute
    return self.cursor.execute(sql, params)
  File "D:\Program Files\Python37\lib\site-packages\django\db\backends\mysql\base.py", line 71, in execute
    return self.cursor.execute(query, args)
  File "D:\Program Files\Python37\lib\site-packages\MySQLdb\cursors.py", line 209, in execute
    res = self._query(query)
  File "D:\Program Files\Python37\lib\site-packages\MySQLdb\cursors.py", line 315, in _query
    db.query(q)
  File "D:\Program Files\Python37\lib\site-packages\MySQLdb\connections.py", line 239, in query
    _mysql.connection.query(self, query)
django.db.utils.IntegrityError: (1062, "Duplicate entry '1588780800' for key 'LAMProcessData_process_r_acquisition_timestamp_a69ae90c_uniq'")
2020-05-06 Wed 22:38:51 threadpool.py _run_jobs 94 - DEBUG - Exiting worker thread
2020-05-06 Wed 22:41:05 autoreload.py trigger_reload 203 - INFO - E:\1-program\11-LAMDataServer\lamdataserver\LAMProcessData\forms.py changed, reloading.
2020-05-06 Wed 22:41:05 threadpool.py shutdown 111 - INFO - Shutting down thread pool
2020-05-06 Wed 22:41:08 threadpool.py __init__ 52 - INFO - Started thread pool with 0 core threads and 20 maximum threads
2020-05-06 Wed 22:41:08 scheduler.py add_job 287 - INFO - Adding job tentatively -- it will be properly scheduled when the scheduler starts
2020-05-06 Wed 22:41:08 scheduler.py add_job 287 - INFO - Adding job tentatively -- it will be properly scheduled when the scheduler starts
2020-05-06 Wed 22:41:08 scheduler.py add_job 287 - INFO - Adding job tentatively -- it will be properly scheduled when the scheduler starts
2020-05-06 Wed 22:41:08 scheduler.py _real_add_job 262 - INFO - Added job "regulartime_task (trigger: interval[1 day, 0:00:00], next run at: 2020-05-06 22:41:18.314245)" to job store "default"
2020-05-06 Wed 22:41:08 scheduler.py _real_add_job 262 - INFO - Added job "cleanup (trigger: cron[day_of_week='*', hour='3', minute='0', second='0'], next run at: 2020-05-07 03:00:00)" to job store "default"
2020-05-06 Wed 22:41:08 scheduler.py _real_add_job 262 - INFO - Added job "OpenLog (trigger: cron[hour='0'], next run at: 2020-05-07 00:00:00)" to job store "default"
2020-05-06 Wed 22:41:08 scheduler.py _main_loop 574 - INFO - Scheduler started
2020-05-06 Wed 22:41:08 scheduler.py _main_loop 579 - DEBUG - Looking for jobs to run
2020-05-06 Wed 22:41:08 scheduler.py _main_loop 588 - DEBUG - Next wakeup is due at 2020-05-06 22:41:18.314245 (in 9.997009 seconds)
2020-05-06 Wed 22:41:08 query_views.py <module> 63 - DEBUG - SendBefore_NotRecive : [<CNCProcessStatus: CNCProcessStatus object (2038721)>]
2020-05-06 Wed 22:41:08 query_views.py <module> 64 - DEBUG - Waitfor_Recive : [2038721]
2020-05-06 Wed 22:41:18 scheduler.py _main_loop 579 - DEBUG - Looking for jobs to run
2020-05-06 Wed 22:41:18 threadpool.py _run_jobs 69 - DEBUG - Started worker thread
2020-05-06 Wed 22:41:18 scheduler.py _run_job 509 - INFO - Running job "regulartime_task (trigger: interval[1 day, 0:00:00], next run at: 2020-05-06 22:41:18.314245)" (scheduled at 2020-05-06 22:41:18.314245)
2020-05-06 Wed 22:41:18 scheduler.py _main_loop 588 - DEBUG - Next wakeup is due at 2020-05-07 00:00:00 (in 4721.684535 seconds)
2020-05-06 Wed 22:41:18 scheduler.py _run_job 520 - ERROR - Job "regulartime_task (trigger: interval[1 day, 0:00:00], next run at: 2020-05-07 22:41:18.314245)" raised an exception
Traceback (most recent call last):
  File "D:\Program Files\Python37\lib\site-packages\django\db\backends\utils.py", line 84, in _execute
    return self.cursor.execute(sql, params)
  File "D:\Program Files\Python37\lib\site-packages\django\db\backends\mysql\base.py", line 71, in execute
    return self.cursor.execute(query, args)
  File "D:\Program Files\Python37\lib\site-packages\MySQLdb\cursors.py", line 209, in execute
    res = self._query(query)
  File "D:\Program Files\Python37\lib\site-packages\MySQLdb\cursors.py", line 315, in _query
    db.query(q)
  File "D:\Program Files\Python37\lib\site-packages\MySQLdb\connections.py", line 239, in query
    _mysql.connection.query(self, query)
MySQLdb._exceptions.IntegrityError: (1062, "Duplicate entry '1588780800' for key 'LAMProcessData_process_r_acquisition_timestamp_a69ae90c_uniq'")

The above exception was the direct cause of the following exception:

Traceback (most recent call last):
  File "D:\Program Files\Python37\lib\site-packages\apscheduler\scheduler.py", line 512, in _run_job
    retval = job.func(*job.args, **job.kwargs)
  File "E:\1-program\11-LAMDataServer\lamdataserver\LAMProcessData\views.py", line 5130, in regulartime_task
    RT_FineData.Realtime_FineData.init_Tomorrow_rows()
  File "E:\1-program\11-LAMDataServer\lamdataserver\LAMProcessData\process_realtime_finedata.py", line 193, in init_Tomorrow_rows
    _model.objects.bulk_create(insert_data_list)
  File "D:\Program Files\Python37\lib\site-packages\django\db\models\manager.py", line 82, in manager_method
    return getattr(self.get_queryset(), name)(*args, **kwargs)
  File "D:\Program Files\Python37\lib\site-packages\django\db\models\query.py", line 474, in bulk_create
    ids = self._batched_insert(objs_without_pk, fields, batch_size, ignore_conflicts=ignore_conflicts)
  File "D:\Program Files\Python37\lib\site-packages\django\db\models\query.py", line 1211, in _batched_insert
    self._insert(item, fields=fields, using=self.db, ignore_conflicts=ignore_conflicts)
  File "D:\Program Files\Python37\lib\site-packages\django\db\models\query.py", line 1186, in _insert
    return query.get_compiler(using=using).execute_sql(return_id)
  File "D:\Program Files\Python37\lib\site-packages\django\db\models\sql\compiler.py", line 1332, in execute_sql
    cursor.execute(sql, params)
  File "D:\Program Files\Python37\lib\site-packages\django\db\backends\utils.py", line 99, in execute
    return super().execute(sql, params)
  File "D:\Program Files\Python37\lib\site-packages\django\db\backends\utils.py", line 67, in execute
    return self._execute_with_wrappers(sql, params, many=False, executor=self._execute)
  File "D:\Program Files\Python37\lib\site-packages\django\db\backends\utils.py", line 76, in _execute_with_wrappers
    return executor(sql, params, many, context)
  File "D:\Program Files\Python37\lib\site-packages\django\db\backends\utils.py", line 84, in _execute
    return self.cursor.execute(sql, params)
  File "D:\Program Files\Python37\lib\site-packages\django\db\utils.py", line 89, in __exit__
    raise dj_exc_value.with_traceback(traceback) from exc_value
  File "D:\Program Files\Python37\lib\site-packages\django\db\backends\utils.py", line 84, in _execute
    return self.cursor.execute(sql, params)
  File "D:\Program Files\Python37\lib\site-packages\django\db\backends\mysql\base.py", line 71, in execute
    return self.cursor.execute(query, args)
  File "D:\Program Files\Python37\lib\site-packages\MySQLdb\cursors.py", line 209, in execute
    res = self._query(query)
  File "D:\Program Files\Python37\lib\site-packages\MySQLdb\cursors.py", line 315, in _query
    db.query(q)
  File "D:\Program Files\Python37\lib\site-packages\MySQLdb\connections.py", line 239, in query
    _mysql.connection.query(self, query)
django.db.utils.IntegrityError: (1062, "Duplicate entry '1588780800' for key 'LAMProcessData_process_r_acquisition_timestamp_a69ae90c_uniq'")
2020-05-06 Wed 22:41:19 threadpool.py _run_jobs 94 - DEBUG - Exiting worker thread
2020-05-06 Wed 22:42:06 autoreload.py trigger_reload 203 - INFO - E:\1-program\11-LAMDataServer\lamdataserver\LAMProcessData\forms.py changed, reloading.
2020-05-06 Wed 22:42:06 threadpool.py shutdown 111 - INFO - Shutting down thread pool
2020-05-06 Wed 22:42:08 threadpool.py __init__ 52 - INFO - Started thread pool with 0 core threads and 20 maximum threads
2020-05-06 Wed 22:42:08 scheduler.py add_job 287 - INFO - Adding job tentatively -- it will be properly scheduled when the scheduler starts
2020-05-06 Wed 22:42:08 scheduler.py add_job 287 - INFO - Adding job tentatively -- it will be properly scheduled when the scheduler starts
2020-05-06 Wed 22:42:08 scheduler.py add_job 287 - INFO - Adding job tentatively -- it will be properly scheduled when the scheduler starts
2020-05-06 Wed 22:42:08 scheduler.py _real_add_job 262 - INFO - Added job "regulartime_task (trigger: interval[1 day, 0:00:00], next run at: 2020-05-06 22:42:18.411846)" to job store "default"
2020-05-06 Wed 22:42:08 scheduler.py _real_add_job 262 - INFO - Added job "cleanup (trigger: cron[day_of_week='*', hour='3', minute='0', second='0'], next run at: 2020-05-07 03:00:00)" to job store "default"
2020-05-06 Wed 22:42:08 scheduler.py _real_add_job 262 - INFO - Added job "OpenLog (trigger: cron[hour='0'], next run at: 2020-05-07 00:00:00)" to job store "default"
2020-05-06 Wed 22:42:08 scheduler.py _main_loop 574 - INFO - Scheduler started
2020-05-06 Wed 22:42:08 scheduler.py _main_loop 579 - DEBUG - Looking for jobs to run
2020-05-06 Wed 22:42:08 scheduler.py _main_loop 588 - DEBUG - Next wakeup is due at 2020-05-06 22:42:18.411846 (in 9.996982 seconds)
2020-05-06 Wed 22:42:08 query_views.py <module> 63 - DEBUG - SendBefore_NotRecive : [<CNCProcessStatus: CNCProcessStatus object (2038721)>]
2020-05-06 Wed 22:42:08 query_views.py <module> 64 - DEBUG - Waitfor_Recive : [2038721]
2020-05-06 Wed 22:42:17 autoreload.py trigger_reload 203 - INFO - E:\1-program\11-LAMDataServer\lamdataserver\LAMProcessData\forms.py changed, reloading.
2020-05-06 Wed 22:42:17 threadpool.py shutdown 111 - INFO - Shutting down thread pool
2020-05-06 Wed 22:42:20 threadpool.py __init__ 52 - INFO - Started thread pool with 0 core threads and 20 maximum threads
2020-05-06 Wed 22:42:20 scheduler.py add_job 287 - INFO - Adding job tentatively -- it will be properly scheduled when the scheduler starts
2020-05-06 Wed 22:42:20 scheduler.py add_job 287 - INFO - Adding job tentatively -- it will be properly scheduled when the scheduler starts
2020-05-06 Wed 22:42:20 scheduler.py add_job 287 - INFO - Adding job tentatively -- it will be properly scheduled when the scheduler starts
2020-05-06 Wed 22:42:20 scheduler.py _real_add_job 262 - INFO - Added job "regulartime_task (trigger: interval[1 day, 0:00:00], next run at: 2020-05-06 22:42:30.846921)" to job store "default"
2020-05-06 Wed 22:42:20 scheduler.py _real_add_job 262 - INFO - Added job "cleanup (trigger: cron[day_of_week='*', hour='3', minute='0', second='0'], next run at: 2020-05-07 03:00:00)" to job store "default"
2020-05-06 Wed 22:42:20 scheduler.py _real_add_job 262 - INFO - Added job "OpenLog (trigger: cron[hour='0'], next run at: 2020-05-07 00:00:00)" to job store "default"
2020-05-06 Wed 22:42:20 scheduler.py _main_loop 574 - INFO - Scheduler started
2020-05-06 Wed 22:42:20 scheduler.py _main_loop 579 - DEBUG - Looking for jobs to run
2020-05-06 Wed 22:42:20 scheduler.py _main_loop 588 - DEBUG - Next wakeup is due at 2020-05-06 22:42:30.846921 (in 9.998008 seconds)
2020-05-06 Wed 22:42:20 query_views.py <module> 63 - DEBUG - SendBefore_NotRecive : [<CNCProcessStatus: CNCProcessStatus object (2038721)>]
2020-05-06 Wed 22:42:20 query_views.py <module> 64 - DEBUG - Waitfor_Recive : [2038721]
2020-05-06 Wed 22:42:30 scheduler.py _main_loop 579 - DEBUG - Looking for jobs to run
2020-05-06 Wed 22:42:30 threadpool.py _run_jobs 69 - DEBUG - Started worker thread
2020-05-06 Wed 22:42:30 scheduler.py _main_loop 588 - DEBUG - Next wakeup is due at 2020-05-07 00:00:00 (in 4649.150979 seconds)
2020-05-06 Wed 22:42:30 scheduler.py _run_job 509 - INFO - Running job "regulartime_task (trigger: interval[1 day, 0:00:00], next run at: 2020-05-07 22:42:30.846921)" (scheduled at 2020-05-06 22:42:30.846921)
2020-05-06 Wed 22:42:31 scheduler.py _run_job 520 - ERROR - Job "regulartime_task (trigger: interval[1 day, 0:00:00], next run at: 2020-05-07 22:42:30.846921)" raised an exception
Traceback (most recent call last):
  File "D:\Program Files\Python37\lib\site-packages\django\db\backends\utils.py", line 84, in _execute
    return self.cursor.execute(sql, params)
  File "D:\Program Files\Python37\lib\site-packages\django\db\backends\mysql\base.py", line 71, in execute
    return self.cursor.execute(query, args)
  File "D:\Program Files\Python37\lib\site-packages\MySQLdb\cursors.py", line 209, in execute
    res = self._query(query)
  File "D:\Program Files\Python37\lib\site-packages\MySQLdb\cursors.py", line 315, in _query
    db.query(q)
  File "D:\Program Files\Python37\lib\site-packages\MySQLdb\connections.py", line 239, in query
    _mysql.connection.query(self, query)
MySQLdb._exceptions.IntegrityError: (1062, "Duplicate entry '1588780800' for key 'LAMProcessData_process_r_acquisition_timestamp_a69ae90c_uniq'")

The above exception was the direct cause of the following exception:

Traceback (most recent call last):
  File "D:\Program Files\Python37\lib\site-packages\apscheduler\scheduler.py", line 512, in _run_job
    retval = job.func(*job.args, **job.kwargs)
  File "E:\1-program\11-LAMDataServer\lamdataserver\LAMProcessData\views.py", line 5130, in regulartime_task
    RT_FineData.Realtime_FineData.init_Tomorrow_rows()
  File "E:\1-program\11-LAMDataServer\lamdataserver\LAMProcessData\process_realtime_finedata.py", line 193, in init_Tomorrow_rows
    _model.objects.bulk_create(insert_data_list)
  File "D:\Program Files\Python37\lib\site-packages\django\db\models\manager.py", line 82, in manager_method
    return getattr(self.get_queryset(), name)(*args, **kwargs)
  File "D:\Program Files\Python37\lib\site-packages\django\db\models\query.py", line 474, in bulk_create
    ids = self._batched_insert(objs_without_pk, fields, batch_size, ignore_conflicts=ignore_conflicts)
  File "D:\Program Files\Python37\lib\site-packages\django\db\models\query.py", line 1211, in _batched_insert
    self._insert(item, fields=fields, using=self.db, ignore_conflicts=ignore_conflicts)
  File "D:\Program Files\Python37\lib\site-packages\django\db\models\query.py", line 1186, in _insert
    return query.get_compiler(using=using).execute_sql(return_id)
  File "D:\Program Files\Python37\lib\site-packages\django\db\models\sql\compiler.py", line 1332, in execute_sql
    cursor.execute(sql, params)
  File "D:\Program Files\Python37\lib\site-packages\django\db\backends\utils.py", line 99, in execute
    return super().execute(sql, params)
  File "D:\Program Files\Python37\lib\site-packages\django\db\backends\utils.py", line 67, in execute
    return self._execute_with_wrappers(sql, params, many=False, executor=self._execute)
  File "D:\Program Files\Python37\lib\site-packages\django\db\backends\utils.py", line 76, in _execute_with_wrappers
    return executor(sql, params, many, context)
  File "D:\Program Files\Python37\lib\site-packages\django\db\backends\utils.py", line 84, in _execute
    return self.cursor.execute(sql, params)
  File "D:\Program Files\Python37\lib\site-packages\django\db\utils.py", line 89, in __exit__
    raise dj_exc_value.with_traceback(traceback) from exc_value
  File "D:\Program Files\Python37\lib\site-packages\django\db\backends\utils.py", line 84, in _execute
    return self.cursor.execute(sql, params)
  File "D:\Program Files\Python37\lib\site-packages\django\db\backends\mysql\base.py", line 71, in execute
    return self.cursor.execute(query, args)
  File "D:\Program Files\Python37\lib\site-packages\MySQLdb\cursors.py", line 209, in execute
    res = self._query(query)
  File "D:\Program Files\Python37\lib\site-packages\MySQLdb\cursors.py", line 315, in _query
    db.query(q)
  File "D:\Program Files\Python37\lib\site-packages\MySQLdb\connections.py", line 239, in query
    _mysql.connection.query(self, query)
django.db.utils.IntegrityError: (1062, "Duplicate entry '1588780800' for key 'LAMProcessData_process_r_acquisition_timestamp_a69ae90c_uniq'")
2020-05-06 Wed 22:42:32 threadpool.py _run_jobs 94 - DEBUG - Exiting worker thread
2020-05-06 Wed 22:44:41 autoreload.py trigger_reload 203 - INFO - E:\1-program\11-LAMDataServer\lamdataserver\LAMProcessData\forms.py changed, reloading.
2020-05-06 Wed 22:44:41 threadpool.py shutdown 111 - INFO - Shutting down thread pool
2020-05-06 Wed 22:44:43 threadpool.py __init__ 52 - INFO - Started thread pool with 0 core threads and 20 maximum threads
2020-05-06 Wed 22:44:43 scheduler.py add_job 287 - INFO - Adding job tentatively -- it will be properly scheduled when the scheduler starts
2020-05-06 Wed 22:44:43 scheduler.py add_job 287 - INFO - Adding job tentatively -- it will be properly scheduled when the scheduler starts
2020-05-06 Wed 22:44:43 scheduler.py add_job 287 - INFO - Adding job tentatively -- it will be properly scheduled when the scheduler starts
2020-05-06 Wed 22:44:43 scheduler.py _real_add_job 262 - INFO - Added job "regulartime_task (trigger: interval[1 day, 0:00:00], next run at: 2020-05-06 22:44:53.549690)" to job store "default"
2020-05-06 Wed 22:44:43 scheduler.py _real_add_job 262 - INFO - Added job "cleanup (trigger: cron[day_of_week='*', hour='3', minute='0', second='0'], next run at: 2020-05-07 03:00:00)" to job store "default"
2020-05-06 Wed 22:44:43 scheduler.py _real_add_job 262 - INFO - Added job "OpenLog (trigger: cron[hour='0'], next run at: 2020-05-07 00:00:00)" to job store "default"
2020-05-06 Wed 22:44:43 scheduler.py _main_loop 574 - INFO - Scheduler started
2020-05-06 Wed 22:44:43 scheduler.py _main_loop 579 - DEBUG - Looking for jobs to run
2020-05-06 Wed 22:44:43 scheduler.py _main_loop 588 - DEBUG - Next wakeup is due at 2020-05-06 22:44:53.549690 (in 9.998024 seconds)
2020-05-06 Wed 22:44:43 query_views.py <module> 63 - DEBUG - SendBefore_NotRecive : [<CNCProcessStatus: CNCProcessStatus object (2038721)>]
2020-05-06 Wed 22:44:43 query_views.py <module> 64 - DEBUG - Waitfor_Recive : [2038721]
2020-05-06 Wed 22:44:51 autoreload.py trigger_reload 203 - INFO - E:\1-program\11-LAMDataServer\lamdataserver\LAMProcessData\forms.py changed, reloading.
2020-05-06 Wed 22:44:51 threadpool.py shutdown 111 - INFO - Shutting down thread pool
2020-05-06 Wed 22:50:34 threadpool.py __init__ 52 - INFO - Started thread pool with 0 core threads and 20 maximum threads
2020-05-06 Wed 22:50:34 scheduler.py add_job 287 - INFO - Adding job tentatively -- it will be properly scheduled when the scheduler starts
2020-05-06 Wed 22:50:34 scheduler.py add_job 287 - INFO - Adding job tentatively -- it will be properly scheduled when the scheduler starts
2020-05-06 Wed 22:50:34 scheduler.py add_job 287 - INFO - Adding job tentatively -- it will be properly scheduled when the scheduler starts
2020-05-06 Wed 22:50:34 scheduler.py _real_add_job 262 - INFO - Added job "regulartime_task (trigger: interval[1 day, 0:00:00], next run at: 2020-05-06 22:50:44.259872)" to job store "default"
2020-05-06 Wed 22:50:34 scheduler.py _real_add_job 262 - INFO - Added job "cleanup (trigger: cron[day_of_week='*', hour='3', minute='0', second='0'], next run at: 2020-05-07 03:00:00)" to job store "default"
2020-05-06 Wed 22:50:34 scheduler.py _real_add_job 262 - INFO - Added job "OpenLog (trigger: cron[hour='0'], next run at: 2020-05-07 00:00:00)" to job store "default"
2020-05-06 Wed 22:50:34 scheduler.py _main_loop 574 - INFO - Scheduler started
2020-05-06 Wed 22:50:34 scheduler.py _main_loop 579 - DEBUG - Looking for jobs to run
2020-05-06 Wed 22:50:34 scheduler.py _main_loop 588 - DEBUG - Next wakeup is due at 2020-05-06 22:50:44.259872 (in 9.998038 seconds)
2020-05-06 Wed 22:50:34 query_views.py <module> 63 - DEBUG - SendBefore_NotRecive : [<CNCProcessStatus: CNCProcessStatus object (2038721)>]
2020-05-06 Wed 22:50:34 query_views.py <module> 64 - DEBUG - Waitfor_Recive : [2038721]
2020-05-06 Wed 22:50:44 scheduler.py _main_loop 579 - DEBUG - Looking for jobs to run
2020-05-06 Wed 22:50:44 threadpool.py _run_jobs 69 - DEBUG - Started worker thread
2020-05-06 Wed 22:50:44 scheduler.py _main_loop 588 - DEBUG - Next wakeup is due at 2020-05-07 00:00:00 (in 4155.739083 seconds)
2020-05-06 Wed 22:50:44 scheduler.py _run_job 509 - INFO - Running job "regulartime_task (trigger: interval[1 day, 0:00:00], next run at: 2020-05-07 22:50:44.259872)" (scheduled at 2020-05-06 22:50:44.259872)
2020-05-06 Wed 22:50:44 scheduler.py _run_job 520 - ERROR - Job "regulartime_task (trigger: interval[1 day, 0:00:00], next run at: 2020-05-07 22:50:44.259872)" raised an exception
Traceback (most recent call last):
  File "D:\Program Files\Python37\lib\site-packages\django\db\backends\utils.py", line 84, in _execute
    return self.cursor.execute(sql, params)
  File "D:\Program Files\Python37\lib\site-packages\django\db\backends\mysql\base.py", line 71, in execute
    return self.cursor.execute(query, args)
  File "D:\Program Files\Python37\lib\site-packages\MySQLdb\cursors.py", line 209, in execute
    res = self._query(query)
  File "D:\Program Files\Python37\lib\site-packages\MySQLdb\cursors.py", line 315, in _query
    db.query(q)
  File "D:\Program Files\Python37\lib\site-packages\MySQLdb\connections.py", line 239, in query
    _mysql.connection.query(self, query)
MySQLdb._exceptions.IntegrityError: (1062, "Duplicate entry '1588780800' for key 'LAMProcessData_process_r_acquisition_timestamp_a69ae90c_uniq'")

The above exception was the direct cause of the following exception:

Traceback (most recent call last):
  File "D:\Program Files\Python37\lib\site-packages\apscheduler\scheduler.py", line 512, in _run_job
    retval = job.func(*job.args, **job.kwargs)
  File "E:\1-program\11-LAMDataServer\lamdataserver\LAMProcessData\views.py", line 5130, in regulartime_task
    RT_FineData.Realtime_FineData.init_Tomorrow_rows()
  File "E:\1-program\11-LAMDataServer\lamdataserver\LAMProcessData\process_realtime_finedata.py", line 193, in init_Tomorrow_rows
    _model.objects.bulk_create(insert_data_list)
  File "D:\Program Files\Python37\lib\site-packages\django\db\models\manager.py", line 82, in manager_method
    return getattr(self.get_queryset(), name)(*args, **kwargs)
  File "D:\Program Files\Python37\lib\site-packages\django\db\models\query.py", line 474, in bulk_create
    ids = self._batched_insert(objs_without_pk, fields, batch_size, ignore_conflicts=ignore_conflicts)
  File "D:\Program Files\Python37\lib\site-packages\django\db\models\query.py", line 1211, in _batched_insert
    self._insert(item, fields=fields, using=self.db, ignore_conflicts=ignore_conflicts)
  File "D:\Program Files\Python37\lib\site-packages\django\db\models\query.py", line 1186, in _insert
    return query.get_compiler(using=using).execute_sql(return_id)
  File "D:\Program Files\Python37\lib\site-packages\django\db\models\sql\compiler.py", line 1332, in execute_sql
    cursor.execute(sql, params)
  File "D:\Program Files\Python37\lib\site-packages\django\db\backends\utils.py", line 99, in execute
    return super().execute(sql, params)
  File "D:\Program Files\Python37\lib\site-packages\django\db\backends\utils.py", line 67, in execute
    return self._execute_with_wrappers(sql, params, many=False, executor=self._execute)
  File "D:\Program Files\Python37\lib\site-packages\django\db\backends\utils.py", line 76, in _execute_with_wrappers
    return executor(sql, params, many, context)
  File "D:\Program Files\Python37\lib\site-packages\django\db\backends\utils.py", line 84, in _execute
    return self.cursor.execute(sql, params)
  File "D:\Program Files\Python37\lib\site-packages\django\db\utils.py", line 89, in __exit__
    raise dj_exc_value.with_traceback(traceback) from exc_value
  File "D:\Program Files\Python37\lib\site-packages\django\db\backends\utils.py", line 84, in _execute
    return self.cursor.execute(sql, params)
  File "D:\Program Files\Python37\lib\site-packages\django\db\backends\mysql\base.py", line 71, in execute
    return self.cursor.execute(query, args)
  File "D:\Program Files\Python37\lib\site-packages\MySQLdb\cursors.py", line 209, in execute
    res = self._query(query)
  File "D:\Program Files\Python37\lib\site-packages\MySQLdb\cursors.py", line 315, in _query
    db.query(q)
  File "D:\Program Files\Python37\lib\site-packages\MySQLdb\connections.py", line 239, in query
    _mysql.connection.query(self, query)
django.db.utils.IntegrityError: (1062, "Duplicate entry '1588780800' for key 'LAMProcessData_process_r_acquisition_timestamp_a69ae90c_uniq'")
2020-05-06 Wed 22:50:45 threadpool.py _run_jobs 94 - DEBUG - Exiting worker thread
2020-05-06 Wed 23:02:50 threadpool.py __init__ 52 - INFO - Started thread pool with 0 core threads and 20 maximum threads
2020-05-06 Wed 23:02:50 scheduler.py add_job 287 - INFO - Adding job tentatively -- it will be properly scheduled when the scheduler starts
2020-05-06 Wed 23:02:50 scheduler.py add_job 287 - INFO - Adding job tentatively -- it will be properly scheduled when the scheduler starts
2020-05-06 Wed 23:02:50 scheduler.py add_job 287 - INFO - Adding job tentatively -- it will be properly scheduled when the scheduler starts
2020-05-06 Wed 23:02:50 scheduler.py _real_add_job 262 - INFO - Added job "regulartime_task (trigger: interval[1 day, 0:00:00], next run at: 2020-05-06 23:03:00.427047)" to job store "default"
2020-05-06 Wed 23:02:50 scheduler.py _real_add_job 262 - INFO - Added job "cleanup (trigger: cron[day_of_week='*', hour='3', minute='0', second='0'], next run at: 2020-05-07 03:00:00)" to job store "default"
2020-05-06 Wed 23:02:50 scheduler.py _real_add_job 262 - INFO - Added job "OpenLog (trigger: cron[hour='0'], next run at: 2020-05-07 00:00:00)" to job store "default"
2020-05-06 Wed 23:02:50 scheduler.py _main_loop 574 - INFO - Scheduler started
2020-05-06 Wed 23:02:50 scheduler.py _main_loop 579 - DEBUG - Looking for jobs to run
2020-05-06 Wed 23:02:50 scheduler.py _main_loop 588 - DEBUG - Next wakeup is due at 2020-05-06 23:03:00.427047 (in 9.997008 seconds)
2020-05-06 Wed 23:02:50 query_views.py <module> 63 - DEBUG - SendBefore_NotRecive : [<CNCProcessStatus: CNCProcessStatus object (2038721)>]
2020-05-06 Wed 23:02:50 query_views.py <module> 64 - DEBUG - Waitfor_Recive : [2038721]
2020-05-06 Wed 23:03:00 scheduler.py _main_loop 579 - DEBUG - Looking for jobs to run
2020-05-06 Wed 23:03:00 threadpool.py _run_jobs 69 - DEBUG - Started worker thread
2020-05-06 Wed 23:03:00 scheduler.py _run_job 509 - INFO - Running job "regulartime_task (trigger: interval[1 day, 0:00:00], next run at: 2020-05-06 23:03:00.427047)" (scheduled at 2020-05-06 23:03:00.427047)
2020-05-06 Wed 23:03:00 scheduler.py _main_loop 588 - DEBUG - Next wakeup is due at 2020-05-07 00:00:00 (in 3419.570989 seconds)
2020-05-06 Wed 23:03:00 scheduler.py _run_job 520 - ERROR - Job "regulartime_task (trigger: interval[1 day, 0:00:00], next run at: 2020-05-07 23:03:00.427047)" raised an exception
Traceback (most recent call last):
  File "D:\Program Files\Python37\lib\site-packages\django\db\backends\utils.py", line 84, in _execute
    return self.cursor.execute(sql, params)
  File "D:\Program Files\Python37\lib\site-packages\django\db\backends\mysql\base.py", line 71, in execute
    return self.cursor.execute(query, args)
  File "D:\Program Files\Python37\lib\site-packages\MySQLdb\cursors.py", line 209, in execute
    res = self._query(query)
  File "D:\Program Files\Python37\lib\site-packages\MySQLdb\cursors.py", line 315, in _query
    db.query(q)
  File "D:\Program Files\Python37\lib\site-packages\MySQLdb\connections.py", line 239, in query
    _mysql.connection.query(self, query)
MySQLdb._exceptions.IntegrityError: (1062, "Duplicate entry '1588780800' for key 'LAMProcessData_process_r_acquisition_timestamp_a69ae90c_uniq'")

The above exception was the direct cause of the following exception:

Traceback (most recent call last):
  File "D:\Program Files\Python37\lib\site-packages\apscheduler\scheduler.py", line 512, in _run_job
    retval = job.func(*job.args, **job.kwargs)
  File "E:\1-program\11-LAMDataServer\lamdataserver\LAMProcessData\views.py", line 5130, in regulartime_task
    RT_FineData.Realtime_FineData.init_Tomorrow_rows()
  File "E:\1-program\11-LAMDataServer\lamdataserver\LAMProcessData\process_realtime_finedata.py", line 193, in init_Tomorrow_rows
    _model.objects.bulk_create(insert_data_list)
  File "D:\Program Files\Python37\lib\site-packages\django\db\models\manager.py", line 82, in manager_method
    return getattr(self.get_queryset(), name)(*args, **kwargs)
  File "D:\Program Files\Python37\lib\site-packages\django\db\models\query.py", line 474, in bulk_create
    ids = self._batched_insert(objs_without_pk, fields, batch_size, ignore_conflicts=ignore_conflicts)
  File "D:\Program Files\Python37\lib\site-packages\django\db\models\query.py", line 1211, in _batched_insert
    self._insert(item, fields=fields, using=self.db, ignore_conflicts=ignore_conflicts)
  File "D:\Program Files\Python37\lib\site-packages\django\db\models\query.py", line 1186, in _insert
    return query.get_compiler(using=using).execute_sql(return_id)
  File "D:\Program Files\Python37\lib\site-packages\django\db\models\sql\compiler.py", line 1332, in execute_sql
    cursor.execute(sql, params)
  File "D:\Program Files\Python37\lib\site-packages\django\db\backends\utils.py", line 99, in execute
    return super().execute(sql, params)
  File "D:\Program Files\Python37\lib\site-packages\django\db\backends\utils.py", line 67, in execute
    return self._execute_with_wrappers(sql, params, many=False, executor=self._execute)
  File "D:\Program Files\Python37\lib\site-packages\django\db\backends\utils.py", line 76, in _execute_with_wrappers
    return executor(sql, params, many, context)
  File "D:\Program Files\Python37\lib\site-packages\django\db\backends\utils.py", line 84, in _execute
    return self.cursor.execute(sql, params)
  File "D:\Program Files\Python37\lib\site-packages\django\db\utils.py", line 89, in __exit__
    raise dj_exc_value.with_traceback(traceback) from exc_value
  File "D:\Program Files\Python37\lib\site-packages\django\db\backends\utils.py", line 84, in _execute
    return self.cursor.execute(sql, params)
  File "D:\Program Files\Python37\lib\site-packages\django\db\backends\mysql\base.py", line 71, in execute
    return self.cursor.execute(query, args)
  File "D:\Program Files\Python37\lib\site-packages\MySQLdb\cursors.py", line 209, in execute
    res = self._query(query)
  File "D:\Program Files\Python37\lib\site-packages\MySQLdb\cursors.py", line 315, in _query
    db.query(q)
  File "D:\Program Files\Python37\lib\site-packages\MySQLdb\connections.py", line 239, in query
    _mysql.connection.query(self, query)
django.db.utils.IntegrityError: (1062, "Duplicate entry '1588780800' for key 'LAMProcessData_process_r_acquisition_timestamp_a69ae90c_uniq'")
2020-05-06 Wed 23:03:01 threadpool.py _run_jobs 94 - DEBUG - Exiting worker thread
2020-05-06 Wed 23:23:57 autoreload.py trigger_reload 203 - INFO - E:\1-program\11-LAMDataServer\lamdataserver\LAMProcessData\views.py changed, reloading.
2020-05-06 Wed 23:23:57 threadpool.py shutdown 111 - INFO - Shutting down thread pool
2020-05-06 Wed 23:24:02 threadpool.py __init__ 52 - INFO - Started thread pool with 0 core threads and 20 maximum threads
2020-05-06 Wed 23:24:02 scheduler.py add_job 287 - INFO - Adding job tentatively -- it will be properly scheduled when the scheduler starts
2020-05-06 Wed 23:24:02 scheduler.py add_job 287 - INFO - Adding job tentatively -- it will be properly scheduled when the scheduler starts
2020-05-06 Wed 23:24:02 scheduler.py add_job 287 - INFO - Adding job tentatively -- it will be properly scheduled when the scheduler starts
2020-05-06 Wed 23:24:02 scheduler.py _real_add_job 262 - INFO - Added job "regulartime_task (trigger: interval[1 day, 0:00:00], next run at: 2020-05-06 23:24:12.219587)" to job store "default"
2020-05-06 Wed 23:24:02 scheduler.py _real_add_job 262 - INFO - Added job "cleanup (trigger: cron[day_of_week='*', hour='3', minute='0', second='0'], next run at: 2020-05-07 03:00:00)" to job store "default"
2020-05-06 Wed 23:24:02 scheduler.py _real_add_job 262 - INFO - Added job "OpenLog (trigger: cron[hour='0'], next run at: 2020-05-07 00:00:00)" to job store "default"
2020-05-06 Wed 23:24:02 scheduler.py _main_loop 574 - INFO - Scheduler started
2020-05-06 Wed 23:24:02 scheduler.py _main_loop 579 - DEBUG - Looking for jobs to run
2020-05-06 Wed 23:24:02 scheduler.py _main_loop 588 - DEBUG - Next wakeup is due at 2020-05-06 23:24:12.219587 (in 9.997010 seconds)
2020-05-06 Wed 23:24:02 query_views.py <module> 63 - DEBUG - SendBefore_NotRecive : [<CNCProcessStatus: CNCProcessStatus object (2038721)>]
2020-05-06 Wed 23:24:02 query_views.py <module> 64 - DEBUG - Waitfor_Recive : [2038721]
2020-05-06 Wed 23:24:12 scheduler.py _main_loop 579 - DEBUG - Looking for jobs to run
2020-05-06 Wed 23:24:12 threadpool.py _run_jobs 69 - DEBUG - Started worker thread
2020-05-06 Wed 23:24:12 scheduler.py _run_job 509 - INFO - Running job "regulartime_task (trigger: interval[1 day, 0:00:00], next run at: 2020-05-06 23:24:12.219587)" (scheduled at 2020-05-06 23:24:12.219587)
2020-05-06 Wed 23:24:12 scheduler.py _main_loop 588 - DEBUG - Next wakeup is due at 2020-05-07 00:00:00 (in 2147.779169 seconds)
2020-05-06 Wed 23:24:12 scheduler.py _run_job 520 - ERROR - Job "regulartime_task (trigger: interval[1 day, 0:00:00], next run at: 2020-05-07 23:24:12.219587)" raised an exception
Traceback (most recent call last):
  File "D:\Program Files\Python37\lib\site-packages\django\db\backends\utils.py", line 84, in _execute
    return self.cursor.execute(sql, params)
  File "D:\Program Files\Python37\lib\site-packages\django\db\backends\mysql\base.py", line 71, in execute
    return self.cursor.execute(query, args)
  File "D:\Program Files\Python37\lib\site-packages\MySQLdb\cursors.py", line 209, in execute
    res = self._query(query)
  File "D:\Program Files\Python37\lib\site-packages\MySQLdb\cursors.py", line 315, in _query
    db.query(q)
  File "D:\Program Files\Python37\lib\site-packages\MySQLdb\connections.py", line 239, in query
    _mysql.connection.query(self, query)
MySQLdb._exceptions.IntegrityError: (1062, "Duplicate entry '1588780800' for key 'LAMProcessData_process_r_acquisition_timestamp_a69ae90c_uniq'")

The above exception was the direct cause of the following exception:

Traceback (most recent call last):
  File "D:\Program Files\Python37\lib\site-packages\apscheduler\scheduler.py", line 512, in _run_job
    retval = job.func(*job.args, **job.kwargs)
  File "E:\1-program\11-LAMDataServer\lamdataserver\LAMProcessData\views.py", line 5137, in regulartime_task
    RT_FineData.Realtime_FineData.init_Tomorrow_rows()
  File "E:\1-program\11-LAMDataServer\lamdataserver\LAMProcessData\process_realtime_finedata.py", line 193, in init_Tomorrow_rows
    _model.objects.bulk_create(insert_data_list)
  File "D:\Program Files\Python37\lib\site-packages\django\db\models\manager.py", line 82, in manager_method
    return getattr(self.get_queryset(), name)(*args, **kwargs)
  File "D:\Program Files\Python37\lib\site-packages\django\db\models\query.py", line 474, in bulk_create
    ids = self._batched_insert(objs_without_pk, fields, batch_size, ignore_conflicts=ignore_conflicts)
  File "D:\Program Files\Python37\lib\site-packages\django\db\models\query.py", line 1211, in _batched_insert
    self._insert(item, fields=fields, using=self.db, ignore_conflicts=ignore_conflicts)
  File "D:\Program Files\Python37\lib\site-packages\django\db\models\query.py", line 1186, in _insert
    return query.get_compiler(using=using).execute_sql(return_id)
  File "D:\Program Files\Python37\lib\site-packages\django\db\models\sql\compiler.py", line 1332, in execute_sql
    cursor.execute(sql, params)
  File "D:\Program Files\Python37\lib\site-packages\django\db\backends\utils.py", line 99, in execute
    return super().execute(sql, params)
  File "D:\Program Files\Python37\lib\site-packages\django\db\backends\utils.py", line 67, in execute
    return self._execute_with_wrappers(sql, params, many=False, executor=self._execute)
  File "D:\Program Files\Python37\lib\site-packages\django\db\backends\utils.py", line 76, in _execute_with_wrappers
    return executor(sql, params, many, context)
  File "D:\Program Files\Python37\lib\site-packages\django\db\backends\utils.py", line 84, in _execute
    return self.cursor.execute(sql, params)
  File "D:\Program Files\Python37\lib\site-packages\django\db\utils.py", line 89, in __exit__
    raise dj_exc_value.with_traceback(traceback) from exc_value
  File "D:\Program Files\Python37\lib\site-packages\django\db\backends\utils.py", line 84, in _execute
    return self.cursor.execute(sql, params)
  File "D:\Program Files\Python37\lib\site-packages\django\db\backends\mysql\base.py", line 71, in execute
    return self.cursor.execute(query, args)
  File "D:\Program Files\Python37\lib\site-packages\MySQLdb\cursors.py", line 209, in execute
    res = self._query(query)
  File "D:\Program Files\Python37\lib\site-packages\MySQLdb\cursors.py", line 315, in _query
    db.query(q)
  File "D:\Program Files\Python37\lib\site-packages\MySQLdb\connections.py", line 239, in query
    _mysql.connection.query(self, query)
django.db.utils.IntegrityError: (1062, "Duplicate entry '1588780800' for key 'LAMProcessData_process_r_acquisition_timestamp_a69ae90c_uniq'")
2020-05-06 Wed 23:24:13 threadpool.py _run_jobs 94 - DEBUG - Exiting worker thread
2020-05-06 Wed 23:24:54 autoreload.py trigger_reload 203 - INFO - E:\1-program\11-LAMDataServer\lamdataserver\LAMProcessData\views.py changed, reloading.
2020-05-06 Wed 23:24:54 threadpool.py shutdown 111 - INFO - Shutting down thread pool
2020-05-06 Wed 23:24:58 threadpool.py __init__ 52 - INFO - Started thread pool with 0 core threads and 20 maximum threads
2020-05-06 Wed 23:24:58 scheduler.py add_job 287 - INFO - Adding job tentatively -- it will be properly scheduled when the scheduler starts
2020-05-06 Wed 23:24:58 scheduler.py add_job 287 - INFO - Adding job tentatively -- it will be properly scheduled when the scheduler starts
2020-05-06 Wed 23:24:58 scheduler.py add_job 287 - INFO - Adding job tentatively -- it will be properly scheduled when the scheduler starts
2020-05-06 Wed 23:24:58 scheduler.py _real_add_job 262 - INFO - Added job "regulartime_task (trigger: interval[1 day, 0:00:00], next run at: 2020-05-06 23:25:08.522700)" to job store "default"
2020-05-06 Wed 23:24:58 scheduler.py _real_add_job 262 - INFO - Added job "cleanup (trigger: cron[day_of_week='*', hour='3', minute='0', second='0'], next run at: 2020-05-07 03:00:00)" to job store "default"
2020-05-06 Wed 23:24:58 scheduler.py _real_add_job 262 - INFO - Added job "OpenLog (trigger: cron[hour='0'], next run at: 2020-05-07 00:00:00)" to job store "default"
2020-05-06 Wed 23:24:58 scheduler.py _main_loop 574 - INFO - Scheduler started
2020-05-06 Wed 23:24:58 scheduler.py _main_loop 579 - DEBUG - Looking for jobs to run
2020-05-06 Wed 23:24:58 scheduler.py _main_loop 588 - DEBUG - Next wakeup is due at 2020-05-06 23:25:08.522700 (in 9.998005 seconds)
2020-05-06 Wed 23:24:58 query_views.py <module> 63 - DEBUG - SendBefore_NotRecive : [<CNCProcessStatus: CNCProcessStatus object (2038721)>]
2020-05-06 Wed 23:24:58 query_views.py <module> 64 - DEBUG - Waitfor_Recive : [2038721]
2020-05-06 Wed 23:25:08 scheduler.py _main_loop 579 - DEBUG - Looking for jobs to run
2020-05-06 Wed 23:25:08 threadpool.py _run_jobs 69 - DEBUG - Started worker thread
2020-05-06 Wed 23:25:08 scheduler.py _run_job 509 - INFO - Running job "regulartime_task (trigger: interval[1 day, 0:00:00], next run at: 2020-05-06 23:25:08.522700)" (scheduled at 2020-05-06 23:25:08.522700)
2020-05-06 Wed 23:25:08 scheduler.py _main_loop 588 - DEBUG - Next wakeup is due at 2020-05-07 00:00:00 (in 2091.476055 seconds)
2020-05-06 Wed 23:25:08 scheduler.py _run_job 520 - ERROR - Job "regulartime_task (trigger: interval[1 day, 0:00:00], next run at: 2020-05-07 23:25:08.522700)" raised an exception
Traceback (most recent call last):
  File "D:\Program Files\Python37\lib\site-packages\django\db\backends\utils.py", line 84, in _execute
    return self.cursor.execute(sql, params)
  File "D:\Program Files\Python37\lib\site-packages\django\db\backends\mysql\base.py", line 71, in execute
    return self.cursor.execute(query, args)
  File "D:\Program Files\Python37\lib\site-packages\MySQLdb\cursors.py", line 209, in execute
    res = self._query(query)
  File "D:\Program Files\Python37\lib\site-packages\MySQLdb\cursors.py", line 315, in _query
    db.query(q)
  File "D:\Program Files\Python37\lib\site-packages\MySQLdb\connections.py", line 239, in query
    _mysql.connection.query(self, query)
MySQLdb._exceptions.IntegrityError: (1062, "Duplicate entry '1588780800' for key 'LAMProcessData_process_r_acquisition_timestamp_a69ae90c_uniq'")

The above exception was the direct cause of the following exception:

Traceback (most recent call last):
  File "D:\Program Files\Python37\lib\site-packages\apscheduler\scheduler.py", line 512, in _run_job
    retval = job.func(*job.args, **job.kwargs)
  File "E:\1-program\11-LAMDataServer\lamdataserver\LAMProcessData\views.py", line 5149, in regulartime_task
    RT_FineData.Realtime_FineData.init_Tomorrow_rows()
  File "E:\1-program\11-LAMDataServer\lamdataserver\LAMProcessData\process_realtime_finedata.py", line 193, in init_Tomorrow_rows
    _model.objects.bulk_create(insert_data_list)
  File "D:\Program Files\Python37\lib\site-packages\django\db\models\manager.py", line 82, in manager_method
    return getattr(self.get_queryset(), name)(*args, **kwargs)
  File "D:\Program Files\Python37\lib\site-packages\django\db\models\query.py", line 474, in bulk_create
    ids = self._batched_insert(objs_without_pk, fields, batch_size, ignore_conflicts=ignore_conflicts)
  File "D:\Program Files\Python37\lib\site-packages\django\db\models\query.py", line 1211, in _batched_insert
    self._insert(item, fields=fields, using=self.db, ignore_conflicts=ignore_conflicts)
  File "D:\Program Files\Python37\lib\site-packages\django\db\models\query.py", line 1186, in _insert
    return query.get_compiler(using=using).execute_sql(return_id)
  File "D:\Program Files\Python37\lib\site-packages\django\db\models\sql\compiler.py", line 1332, in execute_sql
    cursor.execute(sql, params)
  File "D:\Program Files\Python37\lib\site-packages\django\db\backends\utils.py", line 99, in execute
    return super().execute(sql, params)
  File "D:\Program Files\Python37\lib\site-packages\django\db\backends\utils.py", line 67, in execute
    return self._execute_with_wrappers(sql, params, many=False, executor=self._execute)
  File "D:\Program Files\Python37\lib\site-packages\django\db\backends\utils.py", line 76, in _execute_with_wrappers
    return executor(sql, params, many, context)
  File "D:\Program Files\Python37\lib\site-packages\django\db\backends\utils.py", line 84, in _execute
    return self.cursor.execute(sql, params)
  File "D:\Program Files\Python37\lib\site-packages\django\db\utils.py", line 89, in __exit__
    raise dj_exc_value.with_traceback(traceback) from exc_value
  File "D:\Program Files\Python37\lib\site-packages\django\db\backends\utils.py", line 84, in _execute
    return self.cursor.execute(sql, params)
  File "D:\Program Files\Python37\lib\site-packages\django\db\backends\mysql\base.py", line 71, in execute
    return self.cursor.execute(query, args)
  File "D:\Program Files\Python37\lib\site-packages\MySQLdb\cursors.py", line 209, in execute
    res = self._query(query)
  File "D:\Program Files\Python37\lib\site-packages\MySQLdb\cursors.py", line 315, in _query
    db.query(q)
  File "D:\Program Files\Python37\lib\site-packages\MySQLdb\connections.py", line 239, in query
    _mysql.connection.query(self, query)
django.db.utils.IntegrityError: (1062, "Duplicate entry '1588780800' for key 'LAMProcessData_process_r_acquisition_timestamp_a69ae90c_uniq'")
2020-05-06 Wed 23:25:09 threadpool.py _run_jobs 94 - DEBUG - Exiting worker thread
2020-05-06 Wed 23:30:31 autoreload.py trigger_reload 203 - INFO - E:\1-program\11-LAMDataServer\lamdataserver\LAMProcessData\urls.py changed, reloading.
2020-05-06 Wed 23:30:31 threadpool.py shutdown 111 - INFO - Shutting down thread pool
2020-05-06 Wed 23:30:33 threadpool.py __init__ 52 - INFO - Started thread pool with 0 core threads and 20 maximum threads
2020-05-06 Wed 23:30:33 scheduler.py add_job 287 - INFO - Adding job tentatively -- it will be properly scheduled when the scheduler starts
2020-05-06 Wed 23:30:33 scheduler.py add_job 287 - INFO - Adding job tentatively -- it will be properly scheduled when the scheduler starts
2020-05-06 Wed 23:30:33 scheduler.py add_job 287 - INFO - Adding job tentatively -- it will be properly scheduled when the scheduler starts
2020-05-06 Wed 23:30:33 scheduler.py _real_add_job 262 - INFO - Added job "regulartime_task (trigger: interval[1 day, 0:00:00], next run at: 2020-05-06 23:30:43.984323)" to job store "default"
2020-05-06 Wed 23:30:33 scheduler.py _real_add_job 262 - INFO - Added job "cleanup (trigger: cron[day_of_week='*', hour='3', minute='0', second='0'], next run at: 2020-05-07 03:00:00)" to job store "default"
2020-05-06 Wed 23:30:33 scheduler.py _real_add_job 262 - INFO - Added job "OpenLog (trigger: cron[hour='0'], next run at: 2020-05-07 00:00:00)" to job store "default"
2020-05-06 Wed 23:30:33 scheduler.py _main_loop 574 - INFO - Scheduler started
2020-05-06 Wed 23:30:33 scheduler.py _main_loop 579 - DEBUG - Looking for jobs to run
2020-05-06 Wed 23:30:33 scheduler.py _main_loop 588 - DEBUG - Next wakeup is due at 2020-05-06 23:30:43.984323 (in 9.996011 seconds)
2020-05-06 Wed 23:30:33 query_views.py <module> 63 - DEBUG - SendBefore_NotRecive : [<CNCProcessStatus: CNCProcessStatus object (2038721)>]
2020-05-06 Wed 23:30:33 query_views.py <module> 64 - DEBUG - Waitfor_Recive : [2038721]
2020-05-06 Wed 23:30:34 threadpool.py shutdown 111 - INFO - Shutting down thread pool
2020-05-06 Wed 23:52:26 threadpool.py __init__ 52 - INFO - Started thread pool with 0 core threads and 20 maximum threads
2020-05-06 Wed 23:52:26 scheduler.py add_job 287 - INFO - Adding job tentatively -- it will be properly scheduled when the scheduler starts
2020-05-06 Wed 23:52:26 scheduler.py add_job 287 - INFO - Adding job tentatively -- it will be properly scheduled when the scheduler starts
2020-05-06 Wed 23:52:26 scheduler.py add_job 287 - INFO - Adding job tentatively -- it will be properly scheduled when the scheduler starts
2020-05-06 Wed 23:52:26 scheduler.py _real_add_job 262 - INFO - Added job "regulartime_task (trigger: interval[1 day, 0:00:00], next run at: 2020-05-06 23:52:36.723524)" to job store "default"
2020-05-06 Wed 23:52:26 scheduler.py _real_add_job 262 - INFO - Added job "cleanup (trigger: cron[day_of_week='*', hour='3', minute='0', second='0'], next run at: 2020-05-07 03:00:00)" to job store "default"
2020-05-06 Wed 23:52:26 scheduler.py _real_add_job 262 - INFO - Added job "OpenLog (trigger: cron[hour='0'], next run at: 2020-05-07 00:00:00)" to job store "default"
2020-05-06 Wed 23:52:26 scheduler.py _main_loop 574 - INFO - Scheduler started
2020-05-06 Wed 23:52:26 scheduler.py _main_loop 579 - DEBUG - Looking for jobs to run
2020-05-06 Wed 23:52:26 scheduler.py _main_loop 588 - DEBUG - Next wakeup is due at 2020-05-06 23:52:36.723524 (in 9.998004 seconds)
2020-05-06 Wed 23:52:26 query_views.py <module> 63 - DEBUG - SendBefore_NotRecive : [<CNCProcessStatus: CNCProcessStatus object (2038721)>]
2020-05-06 Wed 23:52:26 query_views.py <module> 64 - DEBUG - Waitfor_Recive : [2038721]
2020-05-06 Wed 23:52:29 autoreload.py trigger_reload 203 - INFO - E:\1-program\11-LAMDataServer\lamdataserver\LAMProcessData\views.py changed, reloading.
2020-05-06 Wed 23:52:29 threadpool.py shutdown 111 - INFO - Shutting down thread pool
2020-05-06 Wed 23:52:39 threadpool.py __init__ 52 - INFO - Started thread pool with 0 core threads and 20 maximum threads
2020-05-06 Wed 23:52:39 scheduler.py add_job 287 - INFO - Adding job tentatively -- it will be properly scheduled when the scheduler starts
2020-05-06 Wed 23:52:39 scheduler.py add_job 287 - INFO - Adding job tentatively -- it will be properly scheduled when the scheduler starts
2020-05-06 Wed 23:52:39 scheduler.py add_job 287 - INFO - Adding job tentatively -- it will be properly scheduled when the scheduler starts
2020-05-06 Wed 23:52:39 scheduler.py _real_add_job 262 - INFO - Added job "regulartime_task (trigger: interval[1 day, 0:00:00], next run at: 2020-05-06 23:52:49.924560)" to job store "default"
2020-05-06 Wed 23:52:39 scheduler.py _real_add_job 262 - INFO - Added job "cleanup (trigger: cron[day_of_week='*', hour='3', minute='0', second='0'], next run at: 2020-05-07 03:00:00)" to job store "default"
2020-05-06 Wed 23:52:39 scheduler.py _real_add_job 262 - INFO - Added job "OpenLog (trigger: cron[hour='0'], next run at: 2020-05-07 00:00:00)" to job store "default"
2020-05-06 Wed 23:52:39 scheduler.py _main_loop 574 - INFO - Scheduler started
2020-05-06 Wed 23:52:39 scheduler.py _main_loop 579 - DEBUG - Looking for jobs to run
2020-05-06 Wed 23:52:39 scheduler.py _main_loop 588 - DEBUG - Next wakeup is due at 2020-05-06 23:52:49.924560 (in 9.998006 seconds)
2020-05-06 Wed 23:52:39 query_views.py <module> 63 - DEBUG - SendBefore_NotRecive : [<CNCProcessStatus: CNCProcessStatus object (2038721)>]
2020-05-06 Wed 23:52:39 query_views.py <module> 64 - DEBUG - Waitfor_Recive : [2038721]
2020-05-06 Wed 23:52:49 scheduler.py _main_loop 579 - DEBUG - Looking for jobs to run
2020-05-06 Wed 23:52:49 threadpool.py _run_jobs 69 - DEBUG - Started worker thread
2020-05-06 Wed 23:52:49 scheduler.py _main_loop 588 - DEBUG - Next wakeup is due at 2020-05-07 00:00:00 (in 430.072543 seconds)
2020-05-06 Wed 23:52:49 scheduler.py _run_job 509 - INFO - Running job "regulartime_task (trigger: interval[1 day, 0:00:00], next run at: 2020-05-07 23:52:49.924560)" (scheduled at 2020-05-06 23:52:49.924560)
2020-05-06 Wed 23:52:50 scheduler.py _run_job 520 - ERROR - Job "regulartime_task (trigger: interval[1 day, 0:00:00], next run at: 2020-05-07 23:52:49.924560)" raised an exception
Traceback (most recent call last):
  File "D:\Program Files\Python37\lib\site-packages\django\db\backends\utils.py", line 84, in _execute
    return self.cursor.execute(sql, params)
  File "D:\Program Files\Python37\lib\site-packages\django\db\backends\mysql\base.py", line 71, in execute
    return self.cursor.execute(query, args)
  File "D:\Program Files\Python37\lib\site-packages\MySQLdb\cursors.py", line 209, in execute
    res = self._query(query)
  File "D:\Program Files\Python37\lib\site-packages\MySQLdb\cursors.py", line 315, in _query
    db.query(q)
  File "D:\Program Files\Python37\lib\site-packages\MySQLdb\connections.py", line 239, in query
    _mysql.connection.query(self, query)
MySQLdb._exceptions.IntegrityError: (1062, "Duplicate entry '1588780800' for key 'LAMProcessData_process_r_acquisition_timestamp_a69ae90c_uniq'")

The above exception was the direct cause of the following exception:

Traceback (most recent call last):
  File "D:\Program Files\Python37\lib\site-packages\apscheduler\scheduler.py", line 512, in _run_job
    retval = job.func(*job.args, **job.kwargs)
  File "E:\1-program\11-LAMDataServer\lamdataserver\LAMProcessData\views.py", line 5157, in regulartime_task
    RT_FineData.Realtime_FineData.init_Tomorrow_rows()
  File "E:\1-program\11-LAMDataServer\lamdataserver\LAMProcessData\process_realtime_finedata.py", line 193, in init_Tomorrow_rows
    _model.objects.bulk_create(insert_data_list)
  File "D:\Program Files\Python37\lib\site-packages\django\db\models\manager.py", line 82, in manager_method
    return getattr(self.get_queryset(), name)(*args, **kwargs)
  File "D:\Program Files\Python37\lib\site-packages\django\db\models\query.py", line 474, in bulk_create
    ids = self._batched_insert(objs_without_pk, fields, batch_size, ignore_conflicts=ignore_conflicts)
  File "D:\Program Files\Python37\lib\site-packages\django\db\models\query.py", line 1211, in _batched_insert
    self._insert(item, fields=fields, using=self.db, ignore_conflicts=ignore_conflicts)
  File "D:\Program Files\Python37\lib\site-packages\django\db\models\query.py", line 1186, in _insert
    return query.get_compiler(using=using).execute_sql(return_id)
  File "D:\Program Files\Python37\lib\site-packages\django\db\models\sql\compiler.py", line 1332, in execute_sql
    cursor.execute(sql, params)
  File "D:\Program Files\Python37\lib\site-packages\django\db\backends\utils.py", line 99, in execute
    return super().execute(sql, params)
  File "D:\Program Files\Python37\lib\site-packages\django\db\backends\utils.py", line 67, in execute
    return self._execute_with_wrappers(sql, params, many=False, executor=self._execute)
  File "D:\Program Files\Python37\lib\site-packages\django\db\backends\utils.py", line 76, in _execute_with_wrappers
    return executor(sql, params, many, context)
  File "D:\Program Files\Python37\lib\site-packages\django\db\backends\utils.py", line 84, in _execute
    return self.cursor.execute(sql, params)
  File "D:\Program Files\Python37\lib\site-packages\django\db\utils.py", line 89, in __exit__
    raise dj_exc_value.with_traceback(traceback) from exc_value
  File "D:\Program Files\Python37\lib\site-packages\django\db\backends\utils.py", line 84, in _execute
    return self.cursor.execute(sql, params)
  File "D:\Program Files\Python37\lib\site-packages\django\db\backends\mysql\base.py", line 71, in execute
    return self.cursor.execute(query, args)
  File "D:\Program Files\Python37\lib\site-packages\MySQLdb\cursors.py", line 209, in execute
    res = self._query(query)
  File "D:\Program Files\Python37\lib\site-packages\MySQLdb\cursors.py", line 315, in _query
    db.query(q)
  File "D:\Program Files\Python37\lib\site-packages\MySQLdb\connections.py", line 239, in query
    _mysql.connection.query(self, query)
django.db.utils.IntegrityError: (1062, "Duplicate entry '1588780800' for key 'LAMProcessData_process_r_acquisition_timestamp_a69ae90c_uniq'")
2020-05-06 Wed 23:52:51 threadpool.py _run_jobs 94 - DEBUG - Exiting worker thread
2020-05-06 Wed 23:53:25 autoreload.py trigger_reload 203 - INFO - E:\1-program\11-LAMDataServer\lamdataserver\LAMProcessData\forms.py changed, reloading.
2020-05-06 Wed 23:53:25 threadpool.py shutdown 111 - INFO - Shutting down thread pool
2020-05-06 Wed 23:53:27 threadpool.py __init__ 52 - INFO - Started thread pool with 0 core threads and 20 maximum threads
2020-05-06 Wed 23:53:27 scheduler.py add_job 287 - INFO - Adding job tentatively -- it will be properly scheduled when the scheduler starts
2020-05-06 Wed 23:53:27 scheduler.py add_job 287 - INFO - Adding job tentatively -- it will be properly scheduled when the scheduler starts
2020-05-06 Wed 23:53:27 scheduler.py add_job 287 - INFO - Adding job tentatively -- it will be properly scheduled when the scheduler starts
2020-05-06 Wed 23:53:27 scheduler.py _real_add_job 262 - INFO - Added job "regulartime_task (trigger: interval[1 day, 0:00:00], next run at: 2020-05-06 23:53:37.975327)" to job store "default"
2020-05-06 Wed 23:53:27 scheduler.py _real_add_job 262 - INFO - Added job "cleanup (trigger: cron[day_of_week='*', hour='3', minute='0', second='0'], next run at: 2020-05-07 03:00:00)" to job store "default"
2020-05-06 Wed 23:53:27 scheduler.py _real_add_job 262 - INFO - Added job "OpenLog (trigger: cron[hour='0'], next run at: 2020-05-07 00:00:00)" to job store "default"
2020-05-06 Wed 23:53:27 scheduler.py _main_loop 574 - INFO - Scheduler started
2020-05-06 Wed 23:53:27 scheduler.py _main_loop 579 - DEBUG - Looking for jobs to run
2020-05-06 Wed 23:53:27 scheduler.py _main_loop 588 - DEBUG - Next wakeup is due at 2020-05-06 23:53:37.975327 (in 9.997049 seconds)
2020-05-06 Wed 23:53:27 query_views.py <module> 63 - DEBUG - SendBefore_NotRecive : [<CNCProcessStatus: CNCProcessStatus object (2038721)>]
2020-05-06 Wed 23:53:27 query_views.py <module> 64 - DEBUG - Waitfor_Recive : [2038721]
2020-05-06 Wed 23:53:31 threadpool.py __init__ 52 - INFO - Started thread pool with 0 core threads and 20 maximum threads
2020-05-06 Wed 23:53:31 scheduler.py add_job 287 - INFO - Adding job tentatively -- it will be properly scheduled when the scheduler starts
2020-05-06 Wed 23:53:31 scheduler.py add_job 287 - INFO - Adding job tentatively -- it will be properly scheduled when the scheduler starts
2020-05-06 Wed 23:53:31 scheduler.py add_job 287 - INFO - Adding job tentatively -- it will be properly scheduled when the scheduler starts
2020-05-06 Wed 23:53:31 scheduler.py _real_add_job 262 - INFO - Added job "regulartime_task (trigger: interval[1 day, 0:00:00], next run at: 2020-05-06 23:53:41.897025)" to job store "default"
2020-05-06 Wed 23:53:31 scheduler.py _real_add_job 262 - INFO - Added job "cleanup (trigger: cron[day_of_week='*', hour='3', minute='0', second='0'], next run at: 2020-05-07 03:00:00)" to job store "default"
2020-05-06 Wed 23:53:31 scheduler.py _real_add_job 262 - INFO - Added job "OpenLog (trigger: cron[hour='0'], next run at: 2020-05-07 00:00:00)" to job store "default"
2020-05-06 Wed 23:53:31 scheduler.py _main_loop 574 - INFO - Scheduler started
2020-05-06 Wed 23:53:31 scheduler.py _main_loop 579 - DEBUG - Looking for jobs to run
2020-05-06 Wed 23:53:31 scheduler.py _main_loop 588 - DEBUG - Next wakeup is due at 2020-05-06 23:53:41.897025 (in 9.998007 seconds)
2020-05-06 Wed 23:53:31 query_views.py <module> 63 - DEBUG - SendBefore_NotRecive : [<CNCProcessStatus: CNCProcessStatus object (2038721)>]
2020-05-06 Wed 23:53:31 query_views.py <module> 64 - DEBUG - Waitfor_Recive : [2038721]
2020-05-06 Wed 23:53:41 scheduler.py _main_loop 579 - DEBUG - Looking for jobs to run
2020-05-06 Wed 23:53:41 threadpool.py _run_jobs 69 - DEBUG - Started worker thread
2020-05-06 Wed 23:53:41 scheduler.py _run_job 509 - INFO - Running job "regulartime_task (trigger: interval[1 day, 0:00:00], next run at: 2020-05-06 23:53:41.897025)" (scheduled at 2020-05-06 23:53:41.897025)
2020-05-06 Wed 23:53:41 scheduler.py _main_loop 588 - DEBUG - Next wakeup is due at 2020-05-07 00:00:00 (in 378.101044 seconds)
2020-05-06 Wed 23:53:42 scheduler.py _run_job 520 - ERROR - Job "regulartime_task (trigger: interval[1 day, 0:00:00], next run at: 2020-05-07 23:53:41.897025)" raised an exception
Traceback (most recent call last):
  File "D:\Program Files\Python37\lib\site-packages\django\db\backends\utils.py", line 84, in _execute
    return self.cursor.execute(sql, params)
  File "D:\Program Files\Python37\lib\site-packages\django\db\backends\mysql\base.py", line 71, in execute
    return self.cursor.execute(query, args)
  File "D:\Program Files\Python37\lib\site-packages\MySQLdb\cursors.py", line 209, in execute
    res = self._query(query)
  File "D:\Program Files\Python37\lib\site-packages\MySQLdb\cursors.py", line 315, in _query
    db.query(q)
  File "D:\Program Files\Python37\lib\site-packages\MySQLdb\connections.py", line 239, in query
    _mysql.connection.query(self, query)
MySQLdb._exceptions.IntegrityError: (1062, "Duplicate entry '1588780800' for key 'LAMProcessData_process_r_acquisition_timestamp_a69ae90c_uniq'")

The above exception was the direct cause of the following exception:

Traceback (most recent call last):
  File "D:\Program Files\Python37\lib\site-packages\apscheduler\scheduler.py", line 512, in _run_job
    retval = job.func(*job.args, **job.kwargs)
  File "E:\1-program\11-LAMDataServer\lamdataserver\LAMProcessData\views.py", line 5157, in regulartime_task
    RT_FineData.Realtime_FineData.init_Tomorrow_rows()
  File "E:\1-program\11-LAMDataServer\lamdataserver\LAMProcessData\process_realtime_finedata.py", line 193, in init_Tomorrow_rows
    _model.objects.bulk_create(insert_data_list)
  File "D:\Program Files\Python37\lib\site-packages\django\db\models\manager.py", line 82, in manager_method
    return getattr(self.get_queryset(), name)(*args, **kwargs)
  File "D:\Program Files\Python37\lib\site-packages\django\db\models\query.py", line 474, in bulk_create
    ids = self._batched_insert(objs_without_pk, fields, batch_size, ignore_conflicts=ignore_conflicts)
  File "D:\Program Files\Python37\lib\site-packages\django\db\models\query.py", line 1211, in _batched_insert
    self._insert(item, fields=fields, using=self.db, ignore_conflicts=ignore_conflicts)
  File "D:\Program Files\Python37\lib\site-packages\django\db\models\query.py", line 1186, in _insert
    return query.get_compiler(using=using).execute_sql(return_id)
  File "D:\Program Files\Python37\lib\site-packages\django\db\models\sql\compiler.py", line 1332, in execute_sql
    cursor.execute(sql, params)
  File "D:\Program Files\Python37\lib\site-packages\django\db\backends\utils.py", line 99, in execute
    return super().execute(sql, params)
  File "D:\Program Files\Python37\lib\site-packages\django\db\backends\utils.py", line 67, in execute
    return self._execute_with_wrappers(sql, params, many=False, executor=self._execute)
  File "D:\Program Files\Python37\lib\site-packages\django\db\backends\utils.py", line 76, in _execute_with_wrappers
    return executor(sql, params, many, context)
  File "D:\Program Files\Python37\lib\site-packages\django\db\backends\utils.py", line 84, in _execute
    return self.cursor.execute(sql, params)
  File "D:\Program Files\Python37\lib\site-packages\django\db\utils.py", line 89, in __exit__
    raise dj_exc_value.with_traceback(traceback) from exc_value
  File "D:\Program Files\Python37\lib\site-packages\django\db\backends\utils.py", line 84, in _execute
    return self.cursor.execute(sql, params)
  File "D:\Program Files\Python37\lib\site-packages\django\db\backends\mysql\base.py", line 71, in execute
    return self.cursor.execute(query, args)
  File "D:\Program Files\Python37\lib\site-packages\MySQLdb\cursors.py", line 209, in execute
    res = self._query(query)
  File "D:\Program Files\Python37\lib\site-packages\MySQLdb\cursors.py", line 315, in _query
    db.query(q)
  File "D:\Program Files\Python37\lib\site-packages\MySQLdb\connections.py", line 239, in query
    _mysql.connection.query(self, query)
django.db.utils.IntegrityError: (1062, "Duplicate entry '1588780800' for key 'LAMProcessData_process_r_acquisition_timestamp_a69ae90c_uniq'")
2020-05-06 Wed 23:53:43 threadpool.py _run_jobs 94 - DEBUG - Exiting worker thread
2020-05-06 Wed 23:55:11 threadpool.py __init__ 52 - INFO - Started thread pool with 0 core threads and 20 maximum threads
2020-05-06 Wed 23:55:11 scheduler.py add_job 287 - INFO - Adding job tentatively -- it will be properly scheduled when the scheduler starts
2020-05-06 Wed 23:55:11 scheduler.py add_job 287 - INFO - Adding job tentatively -- it will be properly scheduled when the scheduler starts
2020-05-06 Wed 23:55:11 scheduler.py add_job 287 - INFO - Adding job tentatively -- it will be properly scheduled when the scheduler starts
2020-05-06 Wed 23:55:11 scheduler.py _real_add_job 262 - INFO - Added job "regulartime_task (trigger: interval[1 day, 0:00:00], next run at: 2020-05-06 23:55:21.482060)" to job store "default"
2020-05-06 Wed 23:55:11 scheduler.py _real_add_job 262 - INFO - Added job "cleanup (trigger: cron[day_of_week='*', hour='3', minute='0', second='0'], next run at: 2020-05-07 03:00:00)" to job store "default"
2020-05-06 Wed 23:55:11 scheduler.py _real_add_job 262 - INFO - Added job "OpenLog (trigger: cron[hour='0'], next run at: 2020-05-07 00:00:00)" to job store "default"
2020-05-06 Wed 23:55:11 scheduler.py _main_loop 574 - INFO - Scheduler started
2020-05-06 Wed 23:55:11 scheduler.py _main_loop 579 - DEBUG - Looking for jobs to run
2020-05-06 Wed 23:55:11 scheduler.py _main_loop 588 - DEBUG - Next wakeup is due at 2020-05-06 23:55:21.482060 (in 9.998012 seconds)
2020-05-06 Wed 23:55:11 query_views.py <module> 63 - DEBUG - SendBefore_NotRecive : [<CNCProcessStatus: CNCProcessStatus object (2038721)>]
2020-05-06 Wed 23:55:11 query_views.py <module> 64 - DEBUG - Waitfor_Recive : [2038721]
2020-05-06 Wed 23:55:21 scheduler.py _main_loop 579 - DEBUG - Looking for jobs to run
2020-05-06 Wed 23:55:21 threadpool.py _run_jobs 69 - DEBUG - Started worker thread
2020-05-06 Wed 23:55:21 scheduler.py _run_job 509 - INFO - Running job "regulartime_task (trigger: interval[1 day, 0:00:00], next run at: 2020-05-06 23:55:21.482060)" (scheduled at 2020-05-06 23:55:21.482060)
2020-05-06 Wed 23:55:21 scheduler.py _main_loop 588 - DEBUG - Next wakeup is due at 2020-05-07 00:00:00 (in 278.515325 seconds)
2020-05-06 Wed 23:55:21 scheduler.py _run_job 520 - ERROR - Job "regulartime_task (trigger: interval[1 day, 0:00:00], next run at: 2020-05-07 23:55:21.482060)" raised an exception
Traceback (most recent call last):
  File "D:\Program Files\Python37\lib\site-packages\django\db\backends\utils.py", line 84, in _execute
    return self.cursor.execute(sql, params)
  File "D:\Program Files\Python37\lib\site-packages\django\db\backends\mysql\base.py", line 71, in execute
    return self.cursor.execute(query, args)
  File "D:\Program Files\Python37\lib\site-packages\MySQLdb\cursors.py", line 209, in execute
    res = self._query(query)
  File "D:\Program Files\Python37\lib\site-packages\MySQLdb\cursors.py", line 315, in _query
    db.query(q)
  File "D:\Program Files\Python37\lib\site-packages\MySQLdb\connections.py", line 239, in query
    _mysql.connection.query(self, query)
MySQLdb._exceptions.IntegrityError: (1062, "Duplicate entry '1588780800' for key 'LAMProcessData_process_r_acquisition_timestamp_a69ae90c_uniq'")

The above exception was the direct cause of the following exception:

Traceback (most recent call last):
  File "D:\Program Files\Python37\lib\site-packages\apscheduler\scheduler.py", line 512, in _run_job
    retval = job.func(*job.args, **job.kwargs)
  File "E:\1-program\11-LAMDataServer\lamdataserver\LAMProcessData\views.py", line 5157, in regulartime_task
    RT_FineData.Realtime_FineData.init_Tomorrow_rows()
  File "E:\1-program\11-LAMDataServer\lamdataserver\LAMProcessData\process_realtime_finedata.py", line 193, in init_Tomorrow_rows
    _model.objects.bulk_create(insert_data_list)
  File "D:\Program Files\Python37\lib\site-packages\django\db\models\manager.py", line 82, in manager_method
    return getattr(self.get_queryset(), name)(*args, **kwargs)
  File "D:\Program Files\Python37\lib\site-packages\django\db\models\query.py", line 474, in bulk_create
    ids = self._batched_insert(objs_without_pk, fields, batch_size, ignore_conflicts=ignore_conflicts)
  File "D:\Program Files\Python37\lib\site-packages\django\db\models\query.py", line 1211, in _batched_insert
    self._insert(item, fields=fields, using=self.db, ignore_conflicts=ignore_conflicts)
  File "D:\Program Files\Python37\lib\site-packages\django\db\models\query.py", line 1186, in _insert
    return query.get_compiler(using=using).execute_sql(return_id)
  File "D:\Program Files\Python37\lib\site-packages\django\db\models\sql\compiler.py", line 1332, in execute_sql
    cursor.execute(sql, params)
  File "D:\Program Files\Python37\lib\site-packages\django\db\backends\utils.py", line 99, in execute
    return super().execute(sql, params)
  File "D:\Program Files\Python37\lib\site-packages\django\db\backends\utils.py", line 67, in execute
    return self._execute_with_wrappers(sql, params, many=False, executor=self._execute)
  File "D:\Program Files\Python37\lib\site-packages\django\db\backends\utils.py", line 76, in _execute_with_wrappers
    return executor(sql, params, many, context)
  File "D:\Program Files\Python37\lib\site-packages\django\db\backends\utils.py", line 84, in _execute
    return self.cursor.execute(sql, params)
  File "D:\Program Files\Python37\lib\site-packages\django\db\utils.py", line 89, in __exit__
    raise dj_exc_value.with_traceback(traceback) from exc_value
  File "D:\Program Files\Python37\lib\site-packages\django\db\backends\utils.py", line 84, in _execute
    return self.cursor.execute(sql, params)
  File "D:\Program Files\Python37\lib\site-packages\django\db\backends\mysql\base.py", line 71, in execute
    return self.cursor.execute(query, args)
  File "D:\Program Files\Python37\lib\site-packages\MySQLdb\cursors.py", line 209, in execute
    res = self._query(query)
  File "D:\Program Files\Python37\lib\site-packages\MySQLdb\cursors.py", line 315, in _query
    db.query(q)
  File "D:\Program Files\Python37\lib\site-packages\MySQLdb\connections.py", line 239, in query
    _mysql.connection.query(self, query)
django.db.utils.IntegrityError: (1062, "Duplicate entry '1588780800' for key 'LAMProcessData_process_r_acquisition_timestamp_a69ae90c_uniq'")
2020-05-06 Wed 23:55:22 threadpool.py _run_jobs 94 - DEBUG - Exiting worker thread
2020-05-06 Wed 23:58:24 log.py log_response 228 - WARNING - Not Found: /favicon.ico
