2020-04-21 Tue 23:02:01 threadpool.py __init__ 52 - INFO - Started thread pool with 0 core threads and 20 maximum threads
2020-04-21 Tue 23:02:01 scheduler.py add_job 287 - INFO - Adding job tentatively -- it will be properly scheduled when the scheduler starts
2020-04-21 Tue 23:02:01 scheduler.py add_job 287 - INFO - Adding job tentatively -- it will be properly scheduled when the scheduler starts
2020-04-21 Tue 23:02:01 scheduler.py add_job 287 - INFO - Adding job tentatively -- it will be properly scheduled when the scheduler starts
2020-04-21 Tue 23:02:01 scheduler.py _real_add_job 262 - INFO - Added job "regulartime_task (trigger: interval[1 day, 0:00:00], next run at: 2020-04-21 23:02:11.866507)" to job store "default"
2020-04-21 Tue 23:02:01 scheduler.py _real_add_job 262 - INFO - Added job "cleanup (trigger: cron[day_of_week='*', hour='3', minute='0', second='0'], next run at: 2020-04-22 03:00:00)" to job store "default"
2020-04-21 Tue 23:02:01 scheduler.py _real_add_job 262 - INFO - Added job "OpenLog (trigger: cron[hour='0'], next run at: 2020-04-22 00:00:00)" to job store "default"
2020-04-21 Tue 23:02:01 scheduler.py _main_loop 574 - INFO - Scheduler started
2020-04-21 Tue 23:02:01 scheduler.py _main_loop 579 - DEBUG - Looking for jobs to run
2020-04-21 Tue 23:02:01 scheduler.py _main_loop 588 - DEBUG - Next wakeup is due at 2020-04-21 23:02:11.866507 (in 9.997040 seconds)
2020-04-21 Tue 23:02:01 query_views.py <module> 59 - DEBUG - SendBefore_NotRecive : [<CNCProcessStatus: CNCProcessStatus object (2038721)>]
2020-04-21 Tue 23:02:01 query_views.py <module> 60 - DEBUG - Waitfor_Recive : [2038721]
2020-04-21 Tue 23:02:11 scheduler.py _main_loop 579 - DEBUG - Looking for jobs to run
2020-04-21 Tue 23:02:11 threadpool.py _run_jobs 69 - DEBUG - Started worker thread
2020-04-21 Tue 23:02:11 scheduler.py _main_loop 588 - DEBUG - Next wakeup is due at 2020-04-22 00:00:00 (in 3468.130847 seconds)
2020-04-21 Tue 23:02:11 scheduler.py _run_job 509 - INFO - Running job "regulartime_task (trigger: interval[1 day, 0:00:00], next run at: 2020-04-22 23:02:11.866507)" (scheduled at 2020-04-21 23:02:11.866507)
2020-04-21 Tue 23:02:12 scheduler.py _run_job 520 - ERROR - Job "regulartime_task (trigger: interval[1 day, 0:00:00], next run at: 2020-04-22 23:02:11.866507)" raised an exception
Traceback (most recent call last):
  File "D:\Program Files\Python37\lib\site-packages\django\db\backends\mysql\base.py", line 71, in execute
    return self.cursor.execute(query, args)
  File "D:\Program Files\Python37\lib\site-packages\MySQLdb\cursors.py", line 209, in execute
    res = self._query(query)
  File "D:\Program Files\Python37\lib\site-packages\MySQLdb\cursors.py", line 315, in _query
    db.query(q)
  File "D:\Program Files\Python37\lib\site-packages\MySQLdb\connections.py", line 239, in query
    _mysql.connection.query(self, query)
MySQLdb._exceptions.OperationalError: (1048, "Column 'laser_power' cannot be null")

During handling of the above exception, another exception occurred:

Traceback (most recent call last):
  File "D:\Program Files\Python37\lib\site-packages\apscheduler\scheduler.py", line 512, in _run_job
    retval = job.func(*job.args, **job.kwargs)
  File "E:\1-program\11-LAMDataServer\lamdataserver\LAMProcessData\views.py", line 4988, in regulartime_task
    RT_FineData.Realtime_FineData.init_Tomorrow_rows()
  File "E:\1-program\11-LAMDataServer\lamdataserver\LAMProcessData\process_realtime_finedata.py", line 193, in init_Tomorrow_rows
    _model.objects.bulk_create(insert_data_list)
  File "D:\Program Files\Python37\lib\site-packages\django\db\models\manager.py", line 82, in manager_method
    return getattr(self.get_queryset(), name)(*args, **kwargs)
  File "D:\Program Files\Python37\lib\site-packages\django\db\models\query.py", line 474, in bulk_create
    ids = self._batched_insert(objs_without_pk, fields, batch_size, ignore_conflicts=ignore_conflicts)
  File "D:\Program Files\Python37\lib\site-packages\django\db\models\query.py", line 1211, in _batched_insert
    self._insert(item, fields=fields, using=self.db, ignore_conflicts=ignore_conflicts)
  File "D:\Program Files\Python37\lib\site-packages\django\db\models\query.py", line 1186, in _insert
    return query.get_compiler(using=using).execute_sql(return_id)
  File "D:\Program Files\Python37\lib\site-packages\django\db\models\sql\compiler.py", line 1332, in execute_sql
    cursor.execute(sql, params)
  File "D:\Program Files\Python37\lib\site-packages\django\db\backends\utils.py", line 99, in execute
    return super().execute(sql, params)
  File "D:\Program Files\Python37\lib\site-packages\django\db\backends\utils.py", line 67, in execute
    return self._execute_with_wrappers(sql, params, many=False, executor=self._execute)
  File "D:\Program Files\Python37\lib\site-packages\django\db\backends\utils.py", line 76, in _execute_with_wrappers
    return executor(sql, params, many, context)
  File "D:\Program Files\Python37\lib\site-packages\django\db\backends\utils.py", line 84, in _execute
    return self.cursor.execute(sql, params)
  File "D:\Program Files\Python37\lib\site-packages\django\db\backends\mysql\base.py", line 76, in execute
    raise utils.IntegrityError(*tuple(e.args))
django.db.utils.IntegrityError: (1048, "Column 'laser_power' cannot be null")
2020-04-21 Tue 23:02:13 threadpool.py _run_jobs 94 - DEBUG - Exiting worker thread
2020-04-21 Tue 23:02:33 log.py log_response 228 - WARNING - Not Found: /favicon.ico
2020-04-21 Tue 23:02:33 log.py log_response 228 - WARNING - Not Found: /favicon.ico
2020-04-21 Tue 23:30:33 autoreload.py trigger_reload 203 - INFO - E:\1-program\11-LAMDataServer\lamdataserver\LAMProcessData\query_views.py changed, reloading.
2020-04-21 Tue 23:30:33 threadpool.py shutdown 111 - INFO - Shutting down thread pool
2020-04-21 Tue 23:30:36 threadpool.py __init__ 52 - INFO - Started thread pool with 0 core threads and 20 maximum threads
2020-04-21 Tue 23:30:36 scheduler.py add_job 287 - INFO - Adding job tentatively -- it will be properly scheduled when the scheduler starts
2020-04-21 Tue 23:30:36 scheduler.py add_job 287 - INFO - Adding job tentatively -- it will be properly scheduled when the scheduler starts
2020-04-21 Tue 23:30:36 scheduler.py add_job 287 - INFO - Adding job tentatively -- it will be properly scheduled when the scheduler starts
2020-04-21 Tue 23:30:36 scheduler.py _real_add_job 262 - INFO - Added job "regulartime_task (trigger: interval[1 day, 0:00:00], next run at: 2020-04-21 23:30:46.414070)" to job store "default"
2020-04-21 Tue 23:30:36 scheduler.py _real_add_job 262 - INFO - Added job "cleanup (trigger: cron[day_of_week='*', hour='3', minute='0', second='0'], next run at: 2020-04-22 03:00:00)" to job store "default"
2020-04-21 Tue 23:30:36 scheduler.py _real_add_job 262 - INFO - Added job "OpenLog (trigger: cron[hour='0'], next run at: 2020-04-22 00:00:00)" to job store "default"
2020-04-21 Tue 23:30:36 scheduler.py _main_loop 574 - INFO - Scheduler started
2020-04-21 Tue 23:30:36 scheduler.py _main_loop 579 - DEBUG - Looking for jobs to run
2020-04-21 Tue 23:30:36 scheduler.py _main_loop 588 - DEBUG - Next wakeup is due at 2020-04-21 23:30:46.414070 (in 9.998041 seconds)
2020-04-21 Tue 23:30:36 query_views.py <module> 59 - DEBUG - SendBefore_NotRecive : [<CNCProcessStatus: CNCProcessStatus object (2038721)>]
2020-04-21 Tue 23:30:36 query_views.py <module> 60 - DEBUG - Waitfor_Recive : [2038721]
2020-04-21 Tue 23:30:46 scheduler.py _main_loop 579 - DEBUG - Looking for jobs to run
2020-04-21 Tue 23:30:46 threadpool.py _run_jobs 69 - DEBUG - Started worker thread
2020-04-21 Tue 23:30:46 scheduler.py _run_job 509 - INFO - Running job "regulartime_task (trigger: interval[1 day, 0:00:00], next run at: 2020-04-21 23:30:46.414070)" (scheduled at 2020-04-21 23:30:46.414070)
2020-04-21 Tue 23:30:46 scheduler.py _main_loop 588 - DEBUG - Next wakeup is due at 2020-04-22 00:00:00 (in 1753.584323 seconds)
2020-04-21 Tue 23:30:46 scheduler.py _run_job 520 - ERROR - Job "regulartime_task (trigger: interval[1 day, 0:00:00], next run at: 2020-04-22 23:30:46.414070)" raised an exception
Traceback (most recent call last):
  File "D:\Program Files\Python37\lib\site-packages\django\db\backends\utils.py", line 84, in _execute
    return self.cursor.execute(sql, params)
  File "D:\Program Files\Python37\lib\site-packages\django\db\backends\mysql\base.py", line 71, in execute
    return self.cursor.execute(query, args)
  File "D:\Program Files\Python37\lib\site-packages\MySQLdb\cursors.py", line 209, in execute
    res = self._query(query)
  File "D:\Program Files\Python37\lib\site-packages\MySQLdb\cursors.py", line 315, in _query
    db.query(q)
  File "D:\Program Files\Python37\lib\site-packages\MySQLdb\connections.py", line 239, in query
    _mysql.connection.query(self, query)
MySQLdb._exceptions.IntegrityError: (1062, "Duplicate entry '1587484800' for key 'LAMProcessData_process_r_acquisition_timestamp_a69ae90c_uniq'")

The above exception was the direct cause of the following exception:

Traceback (most recent call last):
  File "D:\Program Files\Python37\lib\site-packages\apscheduler\scheduler.py", line 512, in _run_job
    retval = job.func(*job.args, **job.kwargs)
  File "E:\1-program\11-LAMDataServer\lamdataserver\LAMProcessData\views.py", line 4988, in regulartime_task
    RT_FineData.Realtime_FineData.init_Tomorrow_rows()
  File "E:\1-program\11-LAMDataServer\lamdataserver\LAMProcessData\process_realtime_finedata.py", line 193, in init_Tomorrow_rows
    _model.objects.bulk_create(insert_data_list)
  File "D:\Program Files\Python37\lib\site-packages\django\db\models\manager.py", line 82, in manager_method
    return getattr(self.get_queryset(), name)(*args, **kwargs)
  File "D:\Program Files\Python37\lib\site-packages\django\db\models\query.py", line 474, in bulk_create
    ids = self._batched_insert(objs_without_pk, fields, batch_size, ignore_conflicts=ignore_conflicts)
  File "D:\Program Files\Python37\lib\site-packages\django\db\models\query.py", line 1211, in _batched_insert
    self._insert(item, fields=fields, using=self.db, ignore_conflicts=ignore_conflicts)
  File "D:\Program Files\Python37\lib\site-packages\django\db\models\query.py", line 1186, in _insert
    return query.get_compiler(using=using).execute_sql(return_id)
  File "D:\Program Files\Python37\lib\site-packages\django\db\models\sql\compiler.py", line 1332, in execute_sql
    cursor.execute(sql, params)
  File "D:\Program Files\Python37\lib\site-packages\django\db\backends\utils.py", line 99, in execute
    return super().execute(sql, params)
  File "D:\Program Files\Python37\lib\site-packages\django\db\backends\utils.py", line 67, in execute
    return self._execute_with_wrappers(sql, params, many=False, executor=self._execute)
  File "D:\Program Files\Python37\lib\site-packages\django\db\backends\utils.py", line 76, in _execute_with_wrappers
    return executor(sql, params, many, context)
  File "D:\Program Files\Python37\lib\site-packages\django\db\backends\utils.py", line 84, in _execute
    return self.cursor.execute(sql, params)
  File "D:\Program Files\Python37\lib\site-packages\django\db\utils.py", line 89, in __exit__
    raise dj_exc_value.with_traceback(traceback) from exc_value
  File "D:\Program Files\Python37\lib\site-packages\django\db\backends\utils.py", line 84, in _execute
    return self.cursor.execute(sql, params)
  File "D:\Program Files\Python37\lib\site-packages\django\db\backends\mysql\base.py", line 71, in execute
    return self.cursor.execute(query, args)
  File "D:\Program Files\Python37\lib\site-packages\MySQLdb\cursors.py", line 209, in execute
    res = self._query(query)
  File "D:\Program Files\Python37\lib\site-packages\MySQLdb\cursors.py", line 315, in _query
    db.query(q)
  File "D:\Program Files\Python37\lib\site-packages\MySQLdb\connections.py", line 239, in query
    _mysql.connection.query(self, query)
django.db.utils.IntegrityError: (1062, "Duplicate entry '1587484800' for key 'LAMProcessData_process_r_acquisition_timestamp_a69ae90c_uniq'")
2020-04-21 Tue 23:30:47 threadpool.py _run_jobs 94 - DEBUG - Exiting worker thread
2020-04-21 Tue 23:31:41 threadpool.py __init__ 52 - INFO - Started thread pool with 0 core threads and 20 maximum threads
2020-04-21 Tue 23:31:41 scheduler.py add_job 287 - INFO - Adding job tentatively -- it will be properly scheduled when the scheduler starts
2020-04-21 Tue 23:31:41 scheduler.py add_job 287 - INFO - Adding job tentatively -- it will be properly scheduled when the scheduler starts
2020-04-21 Tue 23:31:41 scheduler.py add_job 287 - INFO - Adding job tentatively -- it will be properly scheduled when the scheduler starts
2020-04-21 Tue 23:31:41 scheduler.py _real_add_job 262 - INFO - Added job "regulartime_task (trigger: interval[1 day, 0:00:00], next run at: 2020-04-21 23:31:51.412265)" to job store "default"
2020-04-21 Tue 23:31:41 scheduler.py _real_add_job 262 - INFO - Added job "cleanup (trigger: cron[day_of_week='*', hour='3', minute='0', second='0'], next run at: 2020-04-22 03:00:00)" to job store "default"
2020-04-21 Tue 23:31:41 scheduler.py _real_add_job 262 - INFO - Added job "OpenLog (trigger: cron[hour='0'], next run at: 2020-04-22 00:00:00)" to job store "default"
2020-04-21 Tue 23:31:41 scheduler.py _main_loop 574 - INFO - Scheduler started
2020-04-21 Tue 23:31:41 scheduler.py _main_loop 579 - DEBUG - Looking for jobs to run
2020-04-21 Tue 23:31:41 scheduler.py _main_loop 588 - DEBUG - Next wakeup is due at 2020-04-21 23:31:51.412265 (in 9.997261 seconds)
2020-04-21 Tue 23:31:41 query_views.py <module> 59 - DEBUG - SendBefore_NotRecive : [<CNCProcessStatus: CNCProcessStatus object (2038721)>]
2020-04-21 Tue 23:31:41 query_views.py <module> 60 - DEBUG - Waitfor_Recive : [2038721]
2020-04-21 Tue 23:31:51 scheduler.py _main_loop 579 - DEBUG - Looking for jobs to run
2020-04-21 Tue 23:31:51 threadpool.py _run_jobs 69 - DEBUG - Started worker thread
2020-04-21 Tue 23:31:51 scheduler.py _main_loop 588 - DEBUG - Next wakeup is due at 2020-04-22 00:00:00 (in 1688.585756 seconds)
2020-04-21 Tue 23:31:51 scheduler.py _run_job 509 - INFO - Running job "regulartime_task (trigger: interval[1 day, 0:00:00], next run at: 2020-04-22 23:31:51.412265)" (scheduled at 2020-04-21 23:31:51.412265)
2020-04-21 Tue 23:31:52 scheduler.py _run_job 520 - ERROR - Job "regulartime_task (trigger: interval[1 day, 0:00:00], next run at: 2020-04-22 23:31:51.412265)" raised an exception
Traceback (most recent call last):
  File "D:\Program Files\Python37\lib\site-packages\django\db\backends\utils.py", line 84, in _execute
    return self.cursor.execute(sql, params)
  File "D:\Program Files\Python37\lib\site-packages\django\db\backends\mysql\base.py", line 71, in execute
    return self.cursor.execute(query, args)
  File "D:\Program Files\Python37\lib\site-packages\MySQLdb\cursors.py", line 209, in execute
    res = self._query(query)
  File "D:\Program Files\Python37\lib\site-packages\MySQLdb\cursors.py", line 315, in _query
    db.query(q)
  File "D:\Program Files\Python37\lib\site-packages\MySQLdb\connections.py", line 239, in query
    _mysql.connection.query(self, query)
MySQLdb._exceptions.IntegrityError: (1062, "Duplicate entry '1587484800' for key 'LAMProcessData_process_r_acquisition_timestamp_a69ae90c_uniq'")

The above exception was the direct cause of the following exception:

Traceback (most recent call last):
  File "D:\Program Files\Python37\lib\site-packages\apscheduler\scheduler.py", line 512, in _run_job
    retval = job.func(*job.args, **job.kwargs)
  File "E:\1-program\11-LAMDataServer\lamdataserver\LAMProcessData\views.py", line 4988, in regulartime_task
    RT_FineData.Realtime_FineData.init_Tomorrow_rows()
  File "E:\1-program\11-LAMDataServer\lamdataserver\LAMProcessData\process_realtime_finedata.py", line 193, in init_Tomorrow_rows
    _model.objects.bulk_create(insert_data_list)
  File "D:\Program Files\Python37\lib\site-packages\django\db\models\manager.py", line 82, in manager_method
    return getattr(self.get_queryset(), name)(*args, **kwargs)
  File "D:\Program Files\Python37\lib\site-packages\django\db\models\query.py", line 474, in bulk_create
    ids = self._batched_insert(objs_without_pk, fields, batch_size, ignore_conflicts=ignore_conflicts)
  File "D:\Program Files\Python37\lib\site-packages\django\db\models\query.py", line 1211, in _batched_insert
    self._insert(item, fields=fields, using=self.db, ignore_conflicts=ignore_conflicts)
  File "D:\Program Files\Python37\lib\site-packages\django\db\models\query.py", line 1186, in _insert
    return query.get_compiler(using=using).execute_sql(return_id)
  File "D:\Program Files\Python37\lib\site-packages\django\db\models\sql\compiler.py", line 1332, in execute_sql
    cursor.execute(sql, params)
  File "D:\Program Files\Python37\lib\site-packages\django\db\backends\utils.py", line 99, in execute
    return super().execute(sql, params)
  File "D:\Program Files\Python37\lib\site-packages\django\db\backends\utils.py", line 67, in execute
    return self._execute_with_wrappers(sql, params, many=False, executor=self._execute)
  File "D:\Program Files\Python37\lib\site-packages\django\db\backends\utils.py", line 76, in _execute_with_wrappers
    return executor(sql, params, many, context)
  File "D:\Program Files\Python37\lib\site-packages\django\db\backends\utils.py", line 84, in _execute
    return self.cursor.execute(sql, params)
  File "D:\Program Files\Python37\lib\site-packages\django\db\utils.py", line 89, in __exit__
    raise dj_exc_value.with_traceback(traceback) from exc_value
  File "D:\Program Files\Python37\lib\site-packages\django\db\backends\utils.py", line 84, in _execute
    return self.cursor.execute(sql, params)
  File "D:\Program Files\Python37\lib\site-packages\django\db\backends\mysql\base.py", line 71, in execute
    return self.cursor.execute(query, args)
  File "D:\Program Files\Python37\lib\site-packages\MySQLdb\cursors.py", line 209, in execute
    res = self._query(query)
  File "D:\Program Files\Python37\lib\site-packages\MySQLdb\cursors.py", line 315, in _query
    db.query(q)
  File "D:\Program Files\Python37\lib\site-packages\MySQLdb\connections.py", line 239, in query
    _mysql.connection.query(self, query)
django.db.utils.IntegrityError: (1062, "Duplicate entry '1587484800' for key 'LAMProcessData_process_r_acquisition_timestamp_a69ae90c_uniq'")
2020-04-21 Tue 23:31:53 threadpool.py _run_jobs 94 - DEBUG - Exiting worker thread
2020-04-21 Tue 23:31:54 log.py log_response 228 - WARNING - Not Found: /favicon.ico
2020-04-21 Tue 23:32:07 threadpool.py __init__ 52 - INFO - Started thread pool with 0 core threads and 20 maximum threads
2020-04-21 Tue 23:32:07 scheduler.py add_job 287 - INFO - Adding job tentatively -- it will be properly scheduled when the scheduler starts
2020-04-21 Tue 23:32:07 scheduler.py add_job 287 - INFO - Adding job tentatively -- it will be properly scheduled when the scheduler starts
2020-04-21 Tue 23:32:07 scheduler.py add_job 287 - INFO - Adding job tentatively -- it will be properly scheduled when the scheduler starts
2020-04-21 Tue 23:32:07 scheduler.py _real_add_job 262 - INFO - Added job "regulartime_task (trigger: interval[1 day, 0:00:00], next run at: 2020-04-21 23:32:17.254383)" to job store "default"
2020-04-21 Tue 23:32:07 scheduler.py _real_add_job 262 - INFO - Added job "cleanup (trigger: cron[day_of_week='*', hour='3', minute='0', second='0'], next run at: 2020-04-22 03:00:00)" to job store "default"
2020-04-21 Tue 23:32:07 scheduler.py _real_add_job 262 - INFO - Added job "OpenLog (trigger: cron[hour='0'], next run at: 2020-04-22 00:00:00)" to job store "default"
2020-04-21 Tue 23:32:07 scheduler.py _main_loop 574 - INFO - Scheduler started
2020-04-21 Tue 23:32:07 scheduler.py _main_loop 579 - DEBUG - Looking for jobs to run
2020-04-21 Tue 23:32:07 scheduler.py _main_loop 588 - DEBUG - Next wakeup is due at 2020-04-21 23:32:17.254383 (in 9.995040 seconds)
2020-04-21 Tue 23:32:07 query_views.py <module> 60 - DEBUG - SendBefore_NotRecive : [<CNCProcessStatus: CNCProcessStatus object (2038721)>]
2020-04-21 Tue 23:32:07 query_views.py <module> 61 - DEBUG - Waitfor_Recive : [2038721]
2020-04-21 Tue 23:32:17 scheduler.py _main_loop 579 - DEBUG - Looking for jobs to run
2020-04-21 Tue 23:32:17 threadpool.py _run_jobs 69 - DEBUG - Started worker thread
2020-04-21 Tue 23:32:17 scheduler.py _run_job 509 - INFO - Running job "regulartime_task (trigger: interval[1 day, 0:00:00], next run at: 2020-04-21 23:32:17.254383)" (scheduled at 2020-04-21 23:32:17.254383)
2020-04-21 Tue 23:32:17 scheduler.py _main_loop 588 - DEBUG - Next wakeup is due at 2020-04-22 00:00:00 (in 1662.742029 seconds)
2020-04-21 Tue 23:32:18 scheduler.py _run_job 520 - ERROR - Job "regulartime_task (trigger: interval[1 day, 0:00:00], next run at: 2020-04-22 23:32:17.254383)" raised an exception
Traceback (most recent call last):
  File "D:\Program Files\Python37\lib\site-packages\django\db\backends\utils.py", line 84, in _execute
    return self.cursor.execute(sql, params)
  File "D:\Program Files\Python37\lib\site-packages\django\db\backends\mysql\base.py", line 71, in execute
    return self.cursor.execute(query, args)
  File "D:\Program Files\Python37\lib\site-packages\MySQLdb\cursors.py", line 209, in execute
    res = self._query(query)
  File "D:\Program Files\Python37\lib\site-packages\MySQLdb\cursors.py", line 315, in _query
    db.query(q)
  File "D:\Program Files\Python37\lib\site-packages\MySQLdb\connections.py", line 239, in query
    _mysql.connection.query(self, query)
MySQLdb._exceptions.IntegrityError: (1062, "Duplicate entry '1587484800' for key 'LAMProcessData_process_r_acquisition_timestamp_a69ae90c_uniq'")

The above exception was the direct cause of the following exception:

Traceback (most recent call last):
  File "D:\Program Files\Python37\lib\site-packages\apscheduler\scheduler.py", line 512, in _run_job
    retval = job.func(*job.args, **job.kwargs)
  File "E:\1-program\11-LAMDataServer\lamdataserver\LAMProcessData\views.py", line 4988, in regulartime_task
    RT_FineData.Realtime_FineData.init_Tomorrow_rows()
  File "E:\1-program\11-LAMDataServer\lamdataserver\LAMProcessData\process_realtime_finedata.py", line 193, in init_Tomorrow_rows
    _model.objects.bulk_create(insert_data_list)
  File "D:\Program Files\Python37\lib\site-packages\django\db\models\manager.py", line 82, in manager_method
    return getattr(self.get_queryset(), name)(*args, **kwargs)
  File "D:\Program Files\Python37\lib\site-packages\django\db\models\query.py", line 474, in bulk_create
    ids = self._batched_insert(objs_without_pk, fields, batch_size, ignore_conflicts=ignore_conflicts)
  File "D:\Program Files\Python37\lib\site-packages\django\db\models\query.py", line 1211, in _batched_insert
    self._insert(item, fields=fields, using=self.db, ignore_conflicts=ignore_conflicts)
  File "D:\Program Files\Python37\lib\site-packages\django\db\models\query.py", line 1186, in _insert
    return query.get_compiler(using=using).execute_sql(return_id)
  File "D:\Program Files\Python37\lib\site-packages\django\db\models\sql\compiler.py", line 1332, in execute_sql
    cursor.execute(sql, params)
  File "D:\Program Files\Python37\lib\site-packages\django\db\backends\utils.py", line 99, in execute
    return super().execute(sql, params)
  File "D:\Program Files\Python37\lib\site-packages\django\db\backends\utils.py", line 67, in execute
    return self._execute_with_wrappers(sql, params, many=False, executor=self._execute)
  File "D:\Program Files\Python37\lib\site-packages\django\db\backends\utils.py", line 76, in _execute_with_wrappers
    return executor(sql, params, many, context)
  File "D:\Program Files\Python37\lib\site-packages\django\db\backends\utils.py", line 84, in _execute
    return self.cursor.execute(sql, params)
  File "D:\Program Files\Python37\lib\site-packages\django\db\utils.py", line 89, in __exit__
    raise dj_exc_value.with_traceback(traceback) from exc_value
  File "D:\Program Files\Python37\lib\site-packages\django\db\backends\utils.py", line 84, in _execute
    return self.cursor.execute(sql, params)
  File "D:\Program Files\Python37\lib\site-packages\django\db\backends\mysql\base.py", line 71, in execute
    return self.cursor.execute(query, args)
  File "D:\Program Files\Python37\lib\site-packages\MySQLdb\cursors.py", line 209, in execute
    res = self._query(query)
  File "D:\Program Files\Python37\lib\site-packages\MySQLdb\cursors.py", line 315, in _query
    db.query(q)
  File "D:\Program Files\Python37\lib\site-packages\MySQLdb\connections.py", line 239, in query
    _mysql.connection.query(self, query)
django.db.utils.IntegrityError: (1062, "Duplicate entry '1587484800' for key 'LAMProcessData_process_r_acquisition_timestamp_a69ae90c_uniq'")
2020-04-21 Tue 23:32:19 threadpool.py _run_jobs 94 - DEBUG - Exiting worker thread
2020-04-21 Tue 23:36:15 autoreload.py trigger_reload 203 - INFO - E:\1-program\11-LAMDataServer\lamdataserver\LAMProcessData\query_views.py changed, reloading.
2020-04-21 Tue 23:36:15 threadpool.py shutdown 111 - INFO - Shutting down thread pool
2020-04-21 Tue 23:36:22 threadpool.py __init__ 52 - INFO - Started thread pool with 0 core threads and 20 maximum threads
2020-04-21 Tue 23:36:22 scheduler.py add_job 287 - INFO - Adding job tentatively -- it will be properly scheduled when the scheduler starts
2020-04-21 Tue 23:36:22 scheduler.py add_job 287 - INFO - Adding job tentatively -- it will be properly scheduled when the scheduler starts
2020-04-21 Tue 23:36:22 scheduler.py add_job 287 - INFO - Adding job tentatively -- it will be properly scheduled when the scheduler starts
2020-04-21 Tue 23:36:22 scheduler.py _real_add_job 262 - INFO - Added job "regulartime_task (trigger: interval[1 day, 0:00:00], next run at: 2020-04-21 23:36:32.203687)" to job store "default"
2020-04-21 Tue 23:36:22 scheduler.py _real_add_job 262 - INFO - Added job "cleanup (trigger: cron[day_of_week='*', hour='3', minute='0', second='0'], next run at: 2020-04-22 03:00:00)" to job store "default"
2020-04-21 Tue 23:36:22 scheduler.py _real_add_job 262 - INFO - Added job "OpenLog (trigger: cron[hour='0'], next run at: 2020-04-22 00:00:00)" to job store "default"
2020-04-21 Tue 23:36:22 scheduler.py _main_loop 574 - INFO - Scheduler started
2020-04-21 Tue 23:36:22 scheduler.py _main_loop 579 - DEBUG - Looking for jobs to run
2020-04-21 Tue 23:36:22 scheduler.py _main_loop 588 - DEBUG - Next wakeup is due at 2020-04-21 23:36:32.203687 (in 9.990027 seconds)
2020-04-21 Tue 23:36:22 query_views.py <module> 60 - DEBUG - SendBefore_NotRecive : [<CNCProcessStatus: CNCProcessStatus object (2038721)>]
2020-04-21 Tue 23:36:22 query_views.py <module> 61 - DEBUG - Waitfor_Recive : [2038721]
2020-04-21 Tue 23:36:32 scheduler.py _main_loop 579 - DEBUG - Looking for jobs to run
2020-04-21 Tue 23:36:32 threadpool.py _run_jobs 69 - DEBUG - Started worker thread
2020-04-21 Tue 23:36:32 scheduler.py _run_job 509 - INFO - Running job "regulartime_task (trigger: interval[1 day, 0:00:00], next run at: 2020-04-21 23:36:32.203687)" (scheduled at 2020-04-21 23:36:32.203687)
2020-04-21 Tue 23:36:32 scheduler.py _main_loop 588 - DEBUG - Next wakeup is due at 2020-04-22 00:00:00 (in 1407.788080 seconds)
2020-04-21 Tue 23:36:34 scheduler.py _run_job 520 - ERROR - Job "regulartime_task (trigger: interval[1 day, 0:00:00], next run at: 2020-04-22 23:36:32.203687)" raised an exception
Traceback (most recent call last):
  File "D:\Program Files\Python37\lib\site-packages\django\db\backends\utils.py", line 84, in _execute
    return self.cursor.execute(sql, params)
  File "D:\Program Files\Python37\lib\site-packages\django\db\backends\mysql\base.py", line 71, in execute
    return self.cursor.execute(query, args)
  File "D:\Program Files\Python37\lib\site-packages\MySQLdb\cursors.py", line 209, in execute
    res = self._query(query)
  File "D:\Program Files\Python37\lib\site-packages\MySQLdb\cursors.py", line 315, in _query
    db.query(q)
  File "D:\Program Files\Python37\lib\site-packages\MySQLdb\connections.py", line 239, in query
    _mysql.connection.query(self, query)
MySQLdb._exceptions.IntegrityError: (1062, "Duplicate entry '1587484800' for key 'LAMProcessData_process_r_acquisition_timestamp_a69ae90c_uniq'")

The above exception was the direct cause of the following exception:

Traceback (most recent call last):
  File "D:\Program Files\Python37\lib\site-packages\apscheduler\scheduler.py", line 512, in _run_job
    retval = job.func(*job.args, **job.kwargs)
  File "E:\1-program\11-LAMDataServer\lamdataserver\LAMProcessData\views.py", line 4988, in regulartime_task
    RT_FineData.Realtime_FineData.init_Tomorrow_rows()
  File "E:\1-program\11-LAMDataServer\lamdataserver\LAMProcessData\process_realtime_finedata.py", line 193, in init_Tomorrow_rows
    _model.objects.bulk_create(insert_data_list)
  File "D:\Program Files\Python37\lib\site-packages\django\db\models\manager.py", line 82, in manager_method
    return getattr(self.get_queryset(), name)(*args, **kwargs)
  File "D:\Program Files\Python37\lib\site-packages\django\db\models\query.py", line 474, in bulk_create
    ids = self._batched_insert(objs_without_pk, fields, batch_size, ignore_conflicts=ignore_conflicts)
  File "D:\Program Files\Python37\lib\site-packages\django\db\models\query.py", line 1211, in _batched_insert
    self._insert(item, fields=fields, using=self.db, ignore_conflicts=ignore_conflicts)
  File "D:\Program Files\Python37\lib\site-packages\django\db\models\query.py", line 1186, in _insert
    return query.get_compiler(using=using).execute_sql(return_id)
  File "D:\Program Files\Python37\lib\site-packages\django\db\models\sql\compiler.py", line 1332, in execute_sql
    cursor.execute(sql, params)
  File "D:\Program Files\Python37\lib\site-packages\django\db\backends\utils.py", line 99, in execute
    return super().execute(sql, params)
  File "D:\Program Files\Python37\lib\site-packages\django\db\backends\utils.py", line 67, in execute
    return self._execute_with_wrappers(sql, params, many=False, executor=self._execute)
  File "D:\Program Files\Python37\lib\site-packages\django\db\backends\utils.py", line 76, in _execute_with_wrappers
    return executor(sql, params, many, context)
  File "D:\Program Files\Python37\lib\site-packages\django\db\backends\utils.py", line 84, in _execute
    return self.cursor.execute(sql, params)
  File "D:\Program Files\Python37\lib\site-packages\django\db\utils.py", line 89, in __exit__
    raise dj_exc_value.with_traceback(traceback) from exc_value
  File "D:\Program Files\Python37\lib\site-packages\django\db\backends\utils.py", line 84, in _execute
    return self.cursor.execute(sql, params)
  File "D:\Program Files\Python37\lib\site-packages\django\db\backends\mysql\base.py", line 71, in execute
    return self.cursor.execute(query, args)
  File "D:\Program Files\Python37\lib\site-packages\MySQLdb\cursors.py", line 209, in execute
    res = self._query(query)
  File "D:\Program Files\Python37\lib\site-packages\MySQLdb\cursors.py", line 315, in _query
    db.query(q)
  File "D:\Program Files\Python37\lib\site-packages\MySQLdb\connections.py", line 239, in query
    _mysql.connection.query(self, query)
django.db.utils.IntegrityError: (1062, "Duplicate entry '1587484800' for key 'LAMProcessData_process_r_acquisition_timestamp_a69ae90c_uniq'")
2020-04-21 Tue 23:36:35 threadpool.py _run_jobs 94 - DEBUG - Exiting worker thread
2020-04-21 Tue 23:41:18 autoreload.py trigger_reload 203 - INFO - E:\1-program\11-LAMDataServer\lamdataserver\LAMProcessData\query_views.py changed, reloading.
2020-04-21 Tue 23:41:18 threadpool.py shutdown 111 - INFO - Shutting down thread pool
2020-04-21 Tue 23:41:24 threadpool.py __init__ 52 - INFO - Started thread pool with 0 core threads and 20 maximum threads
2020-04-21 Tue 23:41:24 scheduler.py add_job 287 - INFO - Adding job tentatively -- it will be properly scheduled when the scheduler starts
2020-04-21 Tue 23:41:24 scheduler.py add_job 287 - INFO - Adding job tentatively -- it will be properly scheduled when the scheduler starts
2020-04-21 Tue 23:41:24 scheduler.py add_job 287 - INFO - Adding job tentatively -- it will be properly scheduled when the scheduler starts
2020-04-21 Tue 23:41:24 scheduler.py _real_add_job 262 - INFO - Added job "regulartime_task (trigger: interval[1 day, 0:00:00], next run at: 2020-04-21 23:41:34.629068)" to job store "default"
2020-04-21 Tue 23:41:24 scheduler.py _real_add_job 262 - INFO - Added job "cleanup (trigger: cron[day_of_week='*', hour='3', minute='0', second='0'], next run at: 2020-04-22 03:00:00)" to job store "default"
2020-04-21 Tue 23:41:24 scheduler.py _real_add_job 262 - INFO - Added job "OpenLog (trigger: cron[hour='0'], next run at: 2020-04-22 00:00:00)" to job store "default"
2020-04-21 Tue 23:41:24 scheduler.py _main_loop 574 - INFO - Scheduler started
2020-04-21 Tue 23:41:24 scheduler.py _main_loop 579 - DEBUG - Looking for jobs to run
2020-04-21 Tue 23:41:24 scheduler.py _main_loop 588 - DEBUG - Next wakeup is due at 2020-04-21 23:41:34.629068 (in 9.993016 seconds)
2020-04-21 Tue 23:41:34 scheduler.py _main_loop 579 - DEBUG - Looking for jobs to run
2020-04-21 Tue 23:41:34 threadpool.py _run_jobs 69 - DEBUG - Started worker thread
2020-04-21 Tue 23:41:34 scheduler.py _run_job 509 - INFO - Running job "regulartime_task (trigger: interval[1 day, 0:00:00], next run at: 2020-04-21 23:41:34.629068)" (scheduled at 2020-04-21 23:41:34.629068)
2020-04-21 Tue 23:41:34 scheduler.py _main_loop 588 - DEBUG - Next wakeup is due at 2020-04-22 00:00:00 (in 1105.368265 seconds)
2020-04-21 Tue 23:41:36 scheduler.py _run_job 520 - ERROR - Job "regulartime_task (trigger: interval[1 day, 0:00:00], next run at: 2020-04-22 23:41:34.629068)" raised an exception
Traceback (most recent call last):
  File "D:\Program Files\Python37\lib\site-packages\django\db\backends\utils.py", line 84, in _execute
    return self.cursor.execute(sql, params)
  File "D:\Program Files\Python37\lib\site-packages\django\db\backends\mysql\base.py", line 71, in execute
    return self.cursor.execute(query, args)
  File "D:\Program Files\Python37\lib\site-packages\MySQLdb\cursors.py", line 209, in execute
    res = self._query(query)
  File "D:\Program Files\Python37\lib\site-packages\MySQLdb\cursors.py", line 315, in _query
    db.query(q)
  File "D:\Program Files\Python37\lib\site-packages\MySQLdb\connections.py", line 239, in query
    _mysql.connection.query(self, query)
MySQLdb._exceptions.IntegrityError: (1062, "Duplicate entry '1587484800' for key 'LAMProcessData_process_r_acquisition_timestamp_a69ae90c_uniq'")

The above exception was the direct cause of the following exception:

Traceback (most recent call last):
  File "D:\Program Files\Python37\lib\site-packages\apscheduler\scheduler.py", line 512, in _run_job
    retval = job.func(*job.args, **job.kwargs)
  File "E:\1-program\11-LAMDataServer\lamdataserver\LAMProcessData\views.py", line 4988, in regulartime_task
    RT_FineData.Realtime_FineData.init_Tomorrow_rows()
  File "E:\1-program\11-LAMDataServer\lamdataserver\LAMProcessData\process_realtime_finedata.py", line 193, in init_Tomorrow_rows
    _model.objects.bulk_create(insert_data_list)
  File "D:\Program Files\Python37\lib\site-packages\django\db\models\manager.py", line 82, in manager_method
    return getattr(self.get_queryset(), name)(*args, **kwargs)
  File "D:\Program Files\Python37\lib\site-packages\django\db\models\query.py", line 474, in bulk_create
    ids = self._batched_insert(objs_without_pk, fields, batch_size, ignore_conflicts=ignore_conflicts)
  File "D:\Program Files\Python37\lib\site-packages\django\db\models\query.py", line 1211, in _batched_insert
    self._insert(item, fields=fields, using=self.db, ignore_conflicts=ignore_conflicts)
  File "D:\Program Files\Python37\lib\site-packages\django\db\models\query.py", line 1186, in _insert
    return query.get_compiler(using=using).execute_sql(return_id)
  File "D:\Program Files\Python37\lib\site-packages\django\db\models\sql\compiler.py", line 1332, in execute_sql
    cursor.execute(sql, params)
  File "D:\Program Files\Python37\lib\site-packages\django\db\backends\utils.py", line 99, in execute
    return super().execute(sql, params)
  File "D:\Program Files\Python37\lib\site-packages\django\db\backends\utils.py", line 67, in execute
    return self._execute_with_wrappers(sql, params, many=False, executor=self._execute)
  File "D:\Program Files\Python37\lib\site-packages\django\db\backends\utils.py", line 76, in _execute_with_wrappers
    return executor(sql, params, many, context)
  File "D:\Program Files\Python37\lib\site-packages\django\db\backends\utils.py", line 84, in _execute
    return self.cursor.execute(sql, params)
  File "D:\Program Files\Python37\lib\site-packages\django\db\utils.py", line 89, in __exit__
    raise dj_exc_value.with_traceback(traceback) from exc_value
  File "D:\Program Files\Python37\lib\site-packages\django\db\backends\utils.py", line 84, in _execute
    return self.cursor.execute(sql, params)
  File "D:\Program Files\Python37\lib\site-packages\django\db\backends\mysql\base.py", line 71, in execute
    return self.cursor.execute(query, args)
  File "D:\Program Files\Python37\lib\site-packages\MySQLdb\cursors.py", line 209, in execute
    res = self._query(query)
  File "D:\Program Files\Python37\lib\site-packages\MySQLdb\cursors.py", line 315, in _query
    db.query(q)
  File "D:\Program Files\Python37\lib\site-packages\MySQLdb\connections.py", line 239, in query
    _mysql.connection.query(self, query)
django.db.utils.IntegrityError: (1062, "Duplicate entry '1587484800' for key 'LAMProcessData_process_r_acquisition_timestamp_a69ae90c_uniq'")
2020-04-21 Tue 23:41:37 threadpool.py _run_jobs 94 - DEBUG - Exiting worker thread
2020-04-21 Tue 23:56:30 threadpool.py __init__ 52 - INFO - Started thread pool with 0 core threads and 20 maximum threads
2020-04-21 Tue 23:56:30 scheduler.py add_job 287 - INFO - Adding job tentatively -- it will be properly scheduled when the scheduler starts
2020-04-21 Tue 23:56:30 scheduler.py add_job 287 - INFO - Adding job tentatively -- it will be properly scheduled when the scheduler starts
2020-04-21 Tue 23:56:30 scheduler.py add_job 287 - INFO - Adding job tentatively -- it will be properly scheduled when the scheduler starts
2020-04-21 Tue 23:56:30 scheduler.py _real_add_job 262 - INFO - Added job "regulartime_task (trigger: interval[1 day, 0:00:00], next run at: 2020-04-21 23:56:40.932157)" to job store "default"
2020-04-21 Tue 23:56:30 scheduler.py _real_add_job 262 - INFO - Added job "cleanup (trigger: cron[day_of_week='*', hour='3', minute='0', second='0'], next run at: 2020-04-22 03:00:00)" to job store "default"
2020-04-21 Tue 23:56:30 scheduler.py _real_add_job 262 - INFO - Added job "OpenLog (trigger: cron[hour='0'], next run at: 2020-04-22 00:00:00)" to job store "default"
2020-04-21 Tue 23:56:30 scheduler.py _main_loop 574 - INFO - Scheduler started
2020-04-21 Tue 23:56:30 scheduler.py _main_loop 579 - DEBUG - Looking for jobs to run
2020-04-21 Tue 23:56:30 scheduler.py _main_loop 588 - DEBUG - Next wakeup is due at 2020-04-21 23:56:40.932157 (in 9.996027 seconds)
2020-04-21 Tue 23:56:30 query_views.py <module> 60 - DEBUG - SendBefore_NotRecive : [<CNCProcessStatus: CNCProcessStatus object (2038721)>]
2020-04-21 Tue 23:56:30 query_views.py <module> 61 - DEBUG - Waitfor_Recive : [2038721]
2020-04-21 Tue 23:56:40 scheduler.py _main_loop 579 - DEBUG - Looking for jobs to run
2020-04-21 Tue 23:56:40 threadpool.py _run_jobs 69 - DEBUG - Started worker thread
2020-04-21 Tue 23:56:40 scheduler.py _run_job 509 - INFO - Running job "regulartime_task (trigger: interval[1 day, 0:00:00], next run at: 2020-04-21 23:56:40.932157)" (scheduled at 2020-04-21 23:56:40.932157)
2020-04-21 Tue 23:56:40 scheduler.py _main_loop 588 - DEBUG - Next wakeup is due at 2020-04-22 00:00:00 (in 199.065643 seconds)
2020-04-21 Tue 23:56:42 scheduler.py _run_job 520 - ERROR - Job "regulartime_task (trigger: interval[1 day, 0:00:00], next run at: 2020-04-22 23:56:40.932157)" raised an exception
Traceback (most recent call last):
  File "D:\Program Files\Python37\lib\site-packages\django\db\backends\utils.py", line 84, in _execute
    return self.cursor.execute(sql, params)
  File "D:\Program Files\Python37\lib\site-packages\django\db\backends\mysql\base.py", line 71, in execute
    return self.cursor.execute(query, args)
  File "D:\Program Files\Python37\lib\site-packages\MySQLdb\cursors.py", line 209, in execute
    res = self._query(query)
  File "D:\Program Files\Python37\lib\site-packages\MySQLdb\cursors.py", line 315, in _query
    db.query(q)
  File "D:\Program Files\Python37\lib\site-packages\MySQLdb\connections.py", line 239, in query
    _mysql.connection.query(self, query)
MySQLdb._exceptions.IntegrityError: (1062, "Duplicate entry '1587484800' for key 'LAMProcessData_process_r_acquisition_timestamp_a69ae90c_uniq'")

The above exception was the direct cause of the following exception:

Traceback (most recent call last):
  File "D:\Program Files\Python37\lib\site-packages\apscheduler\scheduler.py", line 512, in _run_job
    retval = job.func(*job.args, **job.kwargs)
  File "E:\1-program\11-LAMDataServer\lamdataserver\LAMProcessData\views.py", line 4988, in regulartime_task
    RT_FineData.Realtime_FineData.init_Tomorrow_rows()
  File "E:\1-program\11-LAMDataServer\lamdataserver\LAMProcessData\process_realtime_finedata.py", line 193, in init_Tomorrow_rows
    _model.objects.bulk_create(insert_data_list)
  File "D:\Program Files\Python37\lib\site-packages\django\db\models\manager.py", line 82, in manager_method
    return getattr(self.get_queryset(), name)(*args, **kwargs)
  File "D:\Program Files\Python37\lib\site-packages\django\db\models\query.py", line 474, in bulk_create
    ids = self._batched_insert(objs_without_pk, fields, batch_size, ignore_conflicts=ignore_conflicts)
  File "D:\Program Files\Python37\lib\site-packages\django\db\models\query.py", line 1211, in _batched_insert
    self._insert(item, fields=fields, using=self.db, ignore_conflicts=ignore_conflicts)
  File "D:\Program Files\Python37\lib\site-packages\django\db\models\query.py", line 1186, in _insert
    return query.get_compiler(using=using).execute_sql(return_id)
  File "D:\Program Files\Python37\lib\site-packages\django\db\models\sql\compiler.py", line 1332, in execute_sql
    cursor.execute(sql, params)
  File "D:\Program Files\Python37\lib\site-packages\django\db\backends\utils.py", line 99, in execute
    return super().execute(sql, params)
  File "D:\Program Files\Python37\lib\site-packages\django\db\backends\utils.py", line 67, in execute
    return self._execute_with_wrappers(sql, params, many=False, executor=self._execute)
  File "D:\Program Files\Python37\lib\site-packages\django\db\backends\utils.py", line 76, in _execute_with_wrappers
    return executor(sql, params, many, context)
  File "D:\Program Files\Python37\lib\site-packages\django\db\backends\utils.py", line 84, in _execute
    return self.cursor.execute(sql, params)
  File "D:\Program Files\Python37\lib\site-packages\django\db\utils.py", line 89, in __exit__
    raise dj_exc_value.with_traceback(traceback) from exc_value
  File "D:\Program Files\Python37\lib\site-packages\django\db\backends\utils.py", line 84, in _execute
    return self.cursor.execute(sql, params)
  File "D:\Program Files\Python37\lib\site-packages\django\db\backends\mysql\base.py", line 71, in execute
    return self.cursor.execute(query, args)
  File "D:\Program Files\Python37\lib\site-packages\MySQLdb\cursors.py", line 209, in execute
    res = self._query(query)
  File "D:\Program Files\Python37\lib\site-packages\MySQLdb\cursors.py", line 315, in _query
    db.query(q)
  File "D:\Program Files\Python37\lib\site-packages\MySQLdb\connections.py", line 239, in query
    _mysql.connection.query(self, query)
django.db.utils.IntegrityError: (1062, "Duplicate entry '1587484800' for key 'LAMProcessData_process_r_acquisition_timestamp_a69ae90c_uniq'")
2020-04-21 Tue 23:56:43 threadpool.py _run_jobs 94 - DEBUG - Exiting worker thread
2020-04-21 Tue 23:57:09 autoreload.py trigger_reload 203 - INFO - E:\1-program\11-LAMDataServer\lamdataserver\LAMProcessData\query_views.py changed, reloading.
2020-04-21 Tue 23:57:09 threadpool.py shutdown 111 - INFO - Shutting down thread pool
2020-04-21 Tue 23:57:14 threadpool.py __init__ 52 - INFO - Started thread pool with 0 core threads and 20 maximum threads
2020-04-21 Tue 23:57:14 scheduler.py add_job 287 - INFO - Adding job tentatively -- it will be properly scheduled when the scheduler starts
2020-04-21 Tue 23:57:14 scheduler.py add_job 287 - INFO - Adding job tentatively -- it will be properly scheduled when the scheduler starts
2020-04-21 Tue 23:57:14 scheduler.py add_job 287 - INFO - Adding job tentatively -- it will be properly scheduled when the scheduler starts
2020-04-21 Tue 23:57:14 scheduler.py _real_add_job 262 - INFO - Added job "regulartime_task (trigger: interval[1 day, 0:00:00], next run at: 2020-04-21 23:57:24.434897)" to job store "default"
2020-04-21 Tue 23:57:14 scheduler.py _real_add_job 262 - INFO - Added job "cleanup (trigger: cron[day_of_week='*', hour='3', minute='0', second='0'], next run at: 2020-04-22 03:00:00)" to job store "default"
2020-04-21 Tue 23:57:14 scheduler.py _real_add_job 262 - INFO - Added job "OpenLog (trigger: cron[hour='0'], next run at: 2020-04-22 00:00:00)" to job store "default"
2020-04-21 Tue 23:57:14 scheduler.py _main_loop 574 - INFO - Scheduler started
2020-04-21 Tue 23:57:14 scheduler.py _main_loop 579 - DEBUG - Looking for jobs to run
2020-04-21 Tue 23:57:14 scheduler.py _main_loop 588 - DEBUG - Next wakeup is due at 2020-04-21 23:57:24.434897 (in 9.994976 seconds)
2020-04-21 Tue 23:57:14 query_views.py <module> 60 - DEBUG - SendBefore_NotRecive : [<CNCProcessStatus: CNCProcessStatus object (2038721)>]
2020-04-21 Tue 23:57:14 query_views.py <module> 61 - DEBUG - Waitfor_Recive : [2038721]
2020-04-21 Tue 23:57:24 scheduler.py _main_loop 579 - DEBUG - Looking for jobs to run
2020-04-21 Tue 23:57:24 threadpool.py _run_jobs 69 - DEBUG - Started worker thread
2020-04-21 Tue 23:57:24 scheduler.py _run_job 509 - INFO - Running job "regulartime_task (trigger: interval[1 day, 0:00:00], next run at: 2020-04-21 23:57:24.434897)" (scheduled at 2020-04-21 23:57:24.434897)
2020-04-21 Tue 23:57:24 scheduler.py _main_loop 588 - DEBUG - Next wakeup is due at 2020-04-22 00:00:00 (in 155.552649 seconds)
2020-04-21 Tue 23:57:25 scheduler.py _run_job 520 - ERROR - Job "regulartime_task (trigger: interval[1 day, 0:00:00], next run at: 2020-04-22 23:57:24.434897)" raised an exception
Traceback (most recent call last):
  File "D:\Program Files\Python37\lib\site-packages\django\db\backends\utils.py", line 84, in _execute
    return self.cursor.execute(sql, params)
  File "D:\Program Files\Python37\lib\site-packages\django\db\backends\mysql\base.py", line 71, in execute
    return self.cursor.execute(query, args)
  File "D:\Program Files\Python37\lib\site-packages\MySQLdb\cursors.py", line 209, in execute
    res = self._query(query)
  File "D:\Program Files\Python37\lib\site-packages\MySQLdb\cursors.py", line 315, in _query
    db.query(q)
  File "D:\Program Files\Python37\lib\site-packages\MySQLdb\connections.py", line 239, in query
    _mysql.connection.query(self, query)
MySQLdb._exceptions.IntegrityError: (1062, "Duplicate entry '1587484800' for key 'LAMProcessData_process_r_acquisition_timestamp_a69ae90c_uniq'")

The above exception was the direct cause of the following exception:

Traceback (most recent call last):
  File "D:\Program Files\Python37\lib\site-packages\apscheduler\scheduler.py", line 512, in _run_job
    retval = job.func(*job.args, **job.kwargs)
  File "E:\1-program\11-LAMDataServer\lamdataserver\LAMProcessData\views.py", line 4988, in regulartime_task
    RT_FineData.Realtime_FineData.init_Tomorrow_rows()
  File "E:\1-program\11-LAMDataServer\lamdataserver\LAMProcessData\process_realtime_finedata.py", line 193, in init_Tomorrow_rows
    _model.objects.bulk_create(insert_data_list)
  File "D:\Program Files\Python37\lib\site-packages\django\db\models\manager.py", line 82, in manager_method
    return getattr(self.get_queryset(), name)(*args, **kwargs)
  File "D:\Program Files\Python37\lib\site-packages\django\db\models\query.py", line 474, in bulk_create
    ids = self._batched_insert(objs_without_pk, fields, batch_size, ignore_conflicts=ignore_conflicts)
  File "D:\Program Files\Python37\lib\site-packages\django\db\models\query.py", line 1211, in _batched_insert
    self._insert(item, fields=fields, using=self.db, ignore_conflicts=ignore_conflicts)
  File "D:\Program Files\Python37\lib\site-packages\django\db\models\query.py", line 1186, in _insert
    return query.get_compiler(using=using).execute_sql(return_id)
  File "D:\Program Files\Python37\lib\site-packages\django\db\models\sql\compiler.py", line 1332, in execute_sql
    cursor.execute(sql, params)
  File "D:\Program Files\Python37\lib\site-packages\django\db\backends\utils.py", line 99, in execute
    return super().execute(sql, params)
  File "D:\Program Files\Python37\lib\site-packages\django\db\backends\utils.py", line 67, in execute
    return self._execute_with_wrappers(sql, params, many=False, executor=self._execute)
  File "D:\Program Files\Python37\lib\site-packages\django\db\backends\utils.py", line 76, in _execute_with_wrappers
    return executor(sql, params, many, context)
  File "D:\Program Files\Python37\lib\site-packages\django\db\backends\utils.py", line 84, in _execute
    return self.cursor.execute(sql, params)
  File "D:\Program Files\Python37\lib\site-packages\django\db\utils.py", line 89, in __exit__
    raise dj_exc_value.with_traceback(traceback) from exc_value
  File "D:\Program Files\Python37\lib\site-packages\django\db\backends\utils.py", line 84, in _execute
    return self.cursor.execute(sql, params)
  File "D:\Program Files\Python37\lib\site-packages\django\db\backends\mysql\base.py", line 71, in execute
    return self.cursor.execute(query, args)
  File "D:\Program Files\Python37\lib\site-packages\MySQLdb\cursors.py", line 209, in execute
    res = self._query(query)
  File "D:\Program Files\Python37\lib\site-packages\MySQLdb\cursors.py", line 315, in _query
    db.query(q)
  File "D:\Program Files\Python37\lib\site-packages\MySQLdb\connections.py", line 239, in query
    _mysql.connection.query(self, query)
django.db.utils.IntegrityError: (1062, "Duplicate entry '1587484800' for key 'LAMProcessData_process_r_acquisition_timestamp_a69ae90c_uniq'")
2020-04-21 Tue 23:57:26 threadpool.py _run_jobs 94 - DEBUG - Exiting worker thread
2020-04-22 Wed 00:00:00 scheduler.py _main_loop 579 - DEBUG - Looking for jobs to run
2020-04-22 Wed 00:00:00 threadpool.py _run_jobs 69 - DEBUG - Started worker thread
2020-04-22 Wed 00:00:00 scheduler.py _main_loop 588 - DEBUG - Next wakeup is due at 2020-04-22 03:00:00 (in 10799.987820 seconds)
2020-04-22 Wed 00:00:00 scheduler.py _run_job 509 - INFO - Running job "OpenLog (trigger: cron[hour='0'], next run at: 2020-04-23 00:00:00)" (scheduled at 2020-04-22 00:00:00)
2020-04-22 Wed 00:00:00 scheduler.py _run_job 527 - INFO - Job "OpenLog (trigger: cron[hour='0'], next run at: 2020-04-23 00:00:00)" executed successfully
2020-04-22 Wed 00:00:01 threadpool.py _run_jobs 94 - DEBUG - Exiting worker thread
2020-04-22 Wed 00:00:11 autoreload.py trigger_reload 203 - INFO - E:\1-program\11-LAMDataServer\lamdataserver\LAMProcessData\query_views.py changed, reloading.
2020-04-22 Wed 00:00:11 threadpool.py shutdown 111 - INFO - Shutting down thread pool
